Workbook

Sheet EVENTOS
B3: martes, 22 de Abril del 2025
B5: INFORMACIÓN DE EVENTOS PRINCIPALES EN SUS INSTALACIONES
B6: TIPO DE EVENTO | C6: EMPRESA | D6: UBICACIÓN | E6: TIPO DE EQUIPO | F6: EQUIPO | G6: INICIO | H6: FINAL | I6: DESCRIPCIÓN | J6: MW INDISP. | K6: INTERRUPCIÓN (SI/NO) | L6: TENSIÓN DE FALLA (kV)
B7: FALLA | C7: CONELSUR LT SAC | D7: MOYOPAMPA - SALAMANCA | E7: LINEA DE TRANSMISION | F7: L-6060 | G7: 22/04/2025 07:57:00 | H7: 22/04/2025 13:16:00 | I7: DESCONEXIÓN DE LA LÍNEA L-6060 (MOYOPAMPA - SALAMANCA) DE 60 kV POR FALLA | K7: NO | L7: 60
B8: EVENTO | C8: CONELSUR LT SAC | D8: PORTILLO | E8: SUBESTACION | F8: SS.EE. | G8: 22/04/2025 00:00:00 | H8: 23/04/2025 00:00:00 | I8: DECLARACIÓN DE SITUACIÓN EXCEPCIONAL EN LA S.E. PORTILLO DE 60 kV | K8: NO
B9: FALLA | C9: EGEJUNIN | D9: SANTA CRUZ II | E9: GENERADOR HIDROELÉCTRICO | F9: G1 | G9: 22/04/2025 13:39:00 | H9: 22/04/2025 13:39:00 | I9: DESCONEXIÓN DEL GENERADOR G1 DE LA CH SANTA CRUZ II POR FALLA | K9: NO | L9: 2.3
B10: FALLA | C10: ELECTRO ORIENTE | D10: BELAUNDE TERRY - TARAPOTO | E10: LINEA DE TRANSMISION | F10: L-1018 | G10: 22/04/2025 12:21:00 | H10: 22/04/2025 12:38:00 | I10: DESCONEXIÓN DE LA LÍNEA L-1018 (BELAUNDE TERRY - TARAPOTO) DE 138 kV POR FALLA | K10: SI | L10: 138
B11: P.ENERG | C11: HYDRO GLOBAL PERÚ S.A.C. | D11: SAN GABAN III | E11: GENERADOR HIDROELÉCTRICO | F11: G2 | G11: 22/04/2025 17:40:00 | H11: 22/04/2025 17:40:00 | I11: PRIMERA SINCRONIZACIÓN DEL GENERADOR G2 DE LA C.H. SAN GABAN III POR PRUEBAS | K11: NO
B12: FALLA | C12: ISA PERU | D12: AGUAYTÍA - TINGO MARÍA | E12: LINEA DE TRANSMISION | F12: L-2251 | G12: 22/04/2025 03:23:00 | H12: 22/04/2025 03:23:00 | I12: RECIERRE MONOFASICO EXITOSO DE LA LÍNEA L-2251 (TINGO MARIA - AGUAYTIA) DE 220 kV POR FALLA | K12: NO | L12: 220
B13: FALLA | C13: ORYGEN PERU S.A.A. | D13: HUINCO | E13: GENERADOR HIDROELÉCTRICO | F13: G2 | G13: 22/04/2025 12:21:00 | H13: 22/04/2025 16:35:00 | I13: DESCONEXIÓN DE LA UNIDAD G2 DE LA C.H. HUINCO POR FALLA | K13: NO | L13: 12.5
B14: EVENTO | C14: RED DE ENERGIA DEL PERU S.A. | D14: TINGO MARÍA - AUCAYACU | E14: LINEA DE TRANSMISION | F14: L-1122 | G14: 22/04/2025 09:20:00 | H14: 22/04/2025 12:22:00 | I14: DECLARACIÓN DE SITUACIÓN EXCEPCIONAL EN LA LÍNEA L-1122 (TINGO MARÍA - AUCAYACU) DE 138 kV | K14: NO
B15: EVENTO | C15: RED DE ENERGIA DEL PERU S.A. | D15: TINGO MARÍA - AUCAYACU | E15: LINEA DE TRANSMISION | F15: L-1122 | G15: 22/04/2025 14:06:00 | H15: 22/04/2025 17:11:00 | I15: DECLARACIÓN DE SITUACIÓN EXCEPCIONAL EN LA LÍNEA L-1122 (TINGO MARÍA - AUCAYACU) DE 138 kV | K15: NO
B16: EVENTO | C16: RED DE ENERGIA DEL PERU S.A. | D16: TINGO MARÍA - AUCAYACU | E16: LINEA DE TRANSMISION | F16: L-1122 | G16: 22/04/2025 18:10:00 | H16: 22/04/2025 21:30:00 | I16: DECLARACIÓN DE SITUACIÓN EXCEPCIONAL EN LA LÍNEA L-1122 (TINGO MARÍA - AUCAYACU) DE 138 kV | K16: NO

Sheet RESTRIC_OPE
B3: martes, 22 de Abril del 2025
B5: RESTRICCIONES OPERATIVAS
B6: FECHA | C6: HORA INICIO | D6: HORA FINAL | E6: EMPRESA | F6: UBICACIÓN | G6: T.Eq. | H6: EQUIPO | I6: DESCRIPCIÓN
B7: 22/04/2025 | C7: 00:00 | D7: 24:00 | E7: CELEPSA | F7: C.H. EL PLATANAL | G7: CH | H7: CENTRAL | I7: Debido al incremento del caudal del rio cañete y establecimiento de la temporada de avenida, se declara la C.H. El Platanal como CENTRAL HIDRÁULICA DE PASADA (correo 03/01/2025).
B8: 22/04/2025 | C8: 00:00 | D8: 24:00 | E8: EGASA | F8: C.H. CHARCANI II | G8: GH | H8: G2 | I8: El Grupo N°02 esta operando con una potencia no mayor a 0.07MW en referencia a 0.18MW de su potencia efectiva, con el fin de no generar daños mayores hasta la reparación de su cojinete.
B9: 22/04/2025 | C9: 00:00 | D9: 24:00 | E9: EGASA | F9: S.E. CONVERTIDOR | G9: BARRA | H9: BARRA138KV | I9: EGASA limitó la capacidad del transformador 138 kV/33 kV a 50 MVA por deterioro del aislamiento.
B10: 22/04/2025 | C10: 00:00 | D10: 24:00 | E10: ENEL GENERACION PIURA S.A. | F10: C.T. MALACAS | G10: CT | H10: CENTRAL | I10: De acuerdo con la comunicación vía correo del día 24.10.2024. ENEL GENERACIÓN PIURA informa una restricción de potencia para alcanzar 105 MW en simultaneo (TG6+TGN4).
B11: 22/04/2025 | C11: 00:00 | D11: 24:00 | E11: ENEL GENERACION PIURA S.A. | F11: C.T. MALACAS | G11: CT | H11: CENTRAL | I11: La unidad TGN4 de la CT Malacas está limitada a 35 MW y no puede operar en conjunto con la TG6. Esto debido a que el ducto estará en mantenimiento, así como su compresor de GAS hasta el 05/05/2025.
B12: 22/04/2025 | C12: 00:00 | D12: 24:00 | E12: ENGIE | F12: C.E. PUNTA LOMITAS | G12: CE | H12: CENTRAL | I12: De acuerdo a la carta ENG/737-2024 (Exp:202400007555). Limitación de cables de media tensión a 100 MW de los transformadores PLT1 y PLT2 de la CE Punta Lomitas. Quedan limitados a 200 MW la generación de CE Punta Lomitas y Punta Lomitas Extensión.
B13: 22/04/2025 | C13: 00:00 | D13: 24:00 | E13: ENGIE | F13: C.H. QUITARACSA | G13: CH | H13: CENTRAL | I13: De acuerdo con el correo del 23.04 se considera la operación continua de la CH Quitaracsa debido a que el sistema de refrigeración de la CH Cañón del Pato se alimenta desde la descarga del caudal turbinado por la CH Quitaracsa.
B14: 22/04/2025 | C14: 00:00 | D14: 24:00 | E14: ENGIE | F14: C.H. YUNCÁN | G14: GH | H14: G3 | I14: Según la carta N° ENG/ 198-2024 enviada por su representada, se opera de forma continua el G3 de la CH Yuncán, debido a la ejecución de mantenimientos necesarios para evitar daños en los sellos de seguridad de la válvula esférica del grupo.
B15: 22/04/2025 | C15: 00:00 | D15: 24:00 | E15: ENGIE | F15: C.T. CHILCA 1 | G15: CT | H15: CENTRAL | I15: Con carta ENG/971-2023, indica que no puede cumplir con las IO considerada en el PDO_17122023 dado que vulneran la seguridad de sus activos. Indican que se debe tomar TMO=168h.
B16: 22/04/2025 | C16: 00:00 | D16: 24:00 | E16: ENGIE | F16: C.T. CHILCA 1 | G16: CT | H16: CENTRAL | I16: Restricción de temperatura de la C.T Chilca, ver valor en el modelo de despacho.
B17: 22/04/2025 | C17: 00:00 | D17: 24:00 | E17: ENGIE | F17: C.T. CHILCA 2 | G17: CT | H17: CENTRAL | I17: Restricción de temperatura de la C.T Chilca2, ver valor en el modelo de despacho.
... B50: 22/04/2025 | C50: 00:00 | D50: 24:00 | E50: TRANSMANTARO | F50: S.E. SOCABAYA | G50: SSEE | H50: S.E. | I50: Opera en simple barra en 220 kV por indisponibilidad de la protección diferencial de barras por alarma.

Sheet INGRESO OC
A3: martes, 22 de Abril del 2025
A5: INGRESO A OPERACIÓN COMERCIAL
A6: EMPRESA | B6: TIPO DE EQUIPO | C6: UBICACIÓN | D6: EQUIPO | E6: Fecha y hora de Ingreso a Operación Comercial

Sheet MANTENIMIENTO EJECUTADOS
B3: martes, 22 de Abril del 2025
B5: Mantenimiento Ejecutado
B6: Empresa | C6: Ubicación | D6: Equipo | E6: Inicio | F6: Final | G6: Descripción | H6: MW Indisp. | I6: Prog. | J6: Dispon | K6: Interrupc. | L6: Tipo | M6: CodEq | N6: TipoEq_Osinerg
B7: AGROAURORA S.A.C. | C7: MAPLE ETANOL | D7: CENTRAL | E7: 22/04/2025 00:00 | F7: 23/04/2025 00:00 | G7: MANTENIMIENTO PREVENTIVO PROGRAMADO DE LA CENTRAL TERMOELECTRICA Y EQUIPOS AUXILIARES. | H7: 14 | I7: P | J7: F/S | K7: N | L7: PREV. | M7: 13417 | N7: G
B8: AGROAURORA S.A.C. | C8: MAPLE ETANOL | D8: CENTRAL | E8: 22/04/2025 00:00 | F8: 23/04/2025 00:00 | G8: CENTRAL TERMOELECTRICA FUERA DE SERVICIO POR FALTA DE MATERIA PRIMA PARA LOS REQUERIMIENTOS DE CALOR UTIL EN FABRICA. | H8: 14 | I8: P | J8: F/S | K8: N | L8: OTROS | M8: 13417 | N8: G
B9: AGROINDUSTRIAS SAN JACINTO S.A.A. | C9: SAN JACINTO | D9: CENTRAL | E9: 22/04/2025 00:00 | F9: 23/04/2025 00:00 | G9: Mantenimiento Anual. | H9: 8.15 | I9: P | J9: F/S | K9: N | L9: PREV. | M9: 19865 | N9: G
B10: ATLANTICA TRANSMISION SUR S.A. | C10: CHILCA-CTM | D10: INT-5261 | E10: 22/04/2025 00:00 | F10: 23/04/2025 00:00 | G10: Seccionador SBB-5261 fase S indisponible para maniobras de apertura y cierre por anomalia en tapa de tanque de compresion, el seccionador permanece cerrado y bloqueado. | H10: 0 | I10: P | J10: E/S | K10: N | L10: OTROS | M10: 13854 | N10: T
B11: ATLANTICA TRANSMISION SUR S.A. | C11: MONTALVO | D11: ACOPLE 220 | E11: 22/04/2025 00:00 | F11: 23/04/2025 00:00 | G11: Proyecto Refuerzos: Reemplazo del HMI existente, Pruebas y Configuracion. No se contara con nivel 1 de operacion. | H11: 0 | I11: P | J11: E/S | K11: N | L11: P.ENERG | M11: 14767 | N11: T
B12: ATLANTICA TRANSMISION SUR S.A. | C12: MONTALVO | D12: CL-2057 | E12: 22/04/2025 00:00 | F12: 23/04/2025 00:00 | G12: Proyecto Refuerzos: Reemplazo del HMI existente, Pruebas y Configuracion. No se contara con nivel 1 de operacion. | H12: 0 | I12: P | J12: E/S | K12: N | L12: P.ENERG | M12: 13812 | N12: T
B13: ATLANTICA TRANSMISION SUR S.A. | C13: MONTALVO | D13: CL-AUT-5671_500 | E13: 22/04/2025 00:00 | F13: 23/04/2025 00:00 | G13: Proyecto Refuerzos: Reemplazo del HMI existente, Pruebas y Configuracion. No se contara con nivel 1 de operacion en INT-5671, INT-5652 y SAT-5671. | H13: 0 | I13: P | J13: E/S | K13: N | L13: P.ENERG | M13: 13809 | N13: T
B14: ATLANTICA TRANSMISION SUR S.A. | C14: MONTALVO | D14: INT-5652 | E14: 22/04/2025 00:00 | F14: 23/04/2025 00:00 | G14: Proyecto Refuerzos:Indisponible por Implementacion de conexion de corrientes, disparos, posiciones, enclavamientos hacia los equipos del nuevos Autotransformador. AUT-5671 en servicio solo por Barra A 500kV. | H14: 0 | I14: P | J14: F/S | K14: N | L14: P.ENERG | M14: 13765 | N14: T
B15: ATLANTICA TRANSMISION SUR S.A. | C15: OCONA | D15: INT-5450 | E15: 22/04/2025 00:00 | F15: 23/04/2025 00:00 | G15: Interruptor INT-5450 cerrado con restriccion operativa, REB-5450 en servicio y suministrando los SS.AA. de la S.E. Oco?a. | H15: 0 | I15: P | J15: E/S | K15: N | L15: OTROS | M15: 13761 | N15: T
B16: ATLANTICA TRANSMISION SUR S.A. | C16: OCONA | D16: INT-5462 | E16: 22/04/2025 00:00 | F16: 23/04/2025 00:00 | G16: Seccionador SBA-5462 fase T indisponible por problemas mecanicos, el seccionador permanece cerrado y bloqueado | H16: 0 | I16: P | J16: E/S | K16: N | L16: OTROS | M16: 13758 | N16: T
B17: ATLANTICA TRANSMISION SUR S.A. | C17: OCONA | D17: SE OCOÑA | E17: 22/04/2025 08:42 | F17: 22/04/2025 15:40 | G17: MANTENIMIENTO PREVENTIVO EN SUBESTACION | H17: 0 | I17: P | J17: F/S | K17: N | L17: PREV. | M17: 13741 | N17: T
B18: ATLANTICA TRANSMISION SUR S.A. | C18: OCONA - SAN JOSE | D18: L-5036 | E18: 22/04/2025 07:57 | F18: 22/04/2025 16:03 | G18: INDISPONIBLE POR MANTENIMIENTO EN SUBESTACION OCO?A | H18: 0 | I18: P | J18: F/S | K18: N | L18: OTROS | M18: 14961 | N18: T
... B168: TRANSMANTARO | C168: YARABAMBA | D168: IN-5120 | E168: 22/04/2025 00:00 | F168: 23/04/2025 00:00 | G168: INTERRUPTOR INDISPONIBLE POR FALLA EN LOS MANDOS DE CONTROL DE N1, N2 Y N3. | H168: 0 | I168: P | J168: F/S | K168: N | L168: OTROS | M168: 17437 | N168: T

Sheet DESPACHO_EJECUTADO
B3: martes, 22 de Abril del 2025
A5: POTENCIA ACTIVA EJECUTADA DE LAS UNIDADES DE GENERACIÓN DEL SEIN (MW) | FL5: CENTRALES NO INTEGRANTES COES
A6: FECHA | B6: HORA | C6: 337 | D6: 338 | E6: 65333 | F6: 101 | G6: 102 | H6: 42667 | I6: 42668 | J6: 126 | K6: 127 | L6: 138 | M6: 139 | N6: 197 | O6: 203 | P6: 204 | Q6: 230 | R6: 209 | S6: 56677 | T6: 796 | U6: 2146 | V6: 142 | W6: 143 | X6: 125 | Y6: 187 | Z6: 163 | AA6: 298 | AB6: 299 | AC6: 219 | AD6: 151 | AE6: 152 | AF6: 153 | AG6: 154 | AH6: 756 | AI6: 156 | AJ6: 155 | AK6: 182 | AL6: 212 | AM6: 758 | AN6: 263 | AO6: 265 | AP6: 775 | AQ6: 777 | AR6: 2154 | AS6: 150 | AT6: 149 | AU6: 188 | AV6: 2131 | AW6: 755 | AX6: 252 | AY6: 249 | AZ6: 250 | BA6: 117 | BB6: 267 | BC6: 268 | BD6: 119 | BE6: 120 | BF6: 189 | BG6: 122 | BH6: 266 | BI6: 251 | BJ6: 115 | BK6: 239 | BL6: 288 | BM6: 240 | BN6: 241 | BO6: 242 | BP6: 191 | BQ6: 194 | BR6: 196 | BS6: 207 | BT6: 236 | BU6: 795 | BV6: 285 | BW6: 995 | BX6: 996 | BY6: 997 | BZ6: 766 | CA6: 926 | CB6: 924 | CC6: 121 | CD6: 103 | CE6: 104 | CF6: 106 | CG6: 105 | CH6: 107 | CI6: 110 | CJ6: 109 | CK6: 144 | CL6: 113 | CM6: 114 | CN6: 193 | CO6: 208 | CP6: 786 | CQ6: 787 | CR6: 788 | CS6: 789 | CT6: 248 | CU6: 2159 | CV6: 303 | CW6: 59715 | CX6: 62255 | CY6: 1263 | CZ6: 61800 | DA6: 2194 | DB6: 216 | DC6: 198 | DD6: 49607 | DE6: 214 | DF6: 260 | DG6: 2152 | DH6: 2128 | DI6: 247 | DJ6: 228 | DK6: 2135 | DL6: 261 | DM6: 237 | DN6: 253 | DO6: 770 | DP6: 225 | DQ6: 2201 | DR6: 2171 | DS6: 760 | DT6: 235 | DU6: 238 | DV6: 2184 | DW6: 61855 | DX6: 223 | DY6: 226 | DZ6: 201 | EA6: 258 | EB6: 259 | EC6: 920 | ED6: 257 | EE6: 256 | EF6: 2148 | EG6: 58288 | EH6: 58289 | EI6: 58839 | EJ6: 58840 | EK6: 296 | EL6: 297 | EM6: 211 | EN6: 2175 | EO6: 2178 | EP6: 2181 | EQ6: 1262 | ER6: 63425 | ES6: 233 | ET6: 2150 | EU6: 2165 | EV6: 2161 | EW6: 61197 | EX6: 58851 | EY6: 234 | EZ6: 215 | FA6: 917 | FB6: 289 | FC6: 58333 | FD6: 58336 | FE6: 202 | FF6: 58487 | FG6: 213 | FH6: 232 | FI6: 2190 | FJ6: TOTAL COES | FL6: 221 | FM6: 222 | FN6: 224 | FO6: 2187 | FP6: 227 | FQ6: 49400 | FR6: 199 | FS6: 200 | FT6: TOTAL NO COES
C7: CENTRO | D7: CENTRO | E7: SUR | F7: CENTRO | G7: CENTRO | H7: NORTE | I7: NORTE | J7: NORTE | K7: NORTE | L7: CENTRO | M7: CENTRO | N7: CENTRO | O7: CENTRO | P7: CENTRO | Q7: CENTRO | R7: CENTRO | S7: CENTRO | T7: CENTRO | U7: CENTRO | V7: CENTRO | W7: CENTRO | X7: CENTRO | Y7: CENTRO | Z7: SUR | AA7: SUR | AB7: SUR | AC7: CENTRO | AD7: SUR | AE7: SUR | AF7: SUR | AG7: SUR | AH7: SUR | AI7: SUR | AJ7: SUR | AK7: SUR | AL7: CENTRO | AM7: NORTE | AN7: NORTE | AO7: NORTE | AP7: CENTRO | AQ7: CENTRO | AR7: CENTRO | AS7: CENTRO | AT7: CENTRO | AU7: CENTRO | AV7: CENTRO | AW7: SUR | AX7: CENTRO | AY7: CENTRO | AZ7: CENTRO | BA7: CENTRO | BB7: CENTRO | BC7: CENTRO | BD7: CENTRO | BE7: CENTRO | BF7: SUR | BG7: NORTE | BH7: CENTRO | BI7: CENTRO | BJ7: NORTE | BK7: NORTE | BL7: NORTE | BM7: SUR | BN7: SUR | BO7: SUR | BP7: CENTRO | BQ7: CENTRO | BR7: CENTRO | BS7: CENTRO | BT7: CENTRO | BU7: CENTRO | BV7: CENTRO | BW7: SUR | BX7: SUR | BY7: SUR | BZ7: NORTE | CA7: SUR | CB7: CENTRO | CC7: NORTE | CD7: CENTRO | CE7: CENTRO | CF7: CENTRO | CG7: CENTRO | CH7: CENTRO | CI7: CENTRO | CJ7: CENTRO | CK7: CENTRO | CL7: CENTRO | CM7: CENTRO | CN7: CENTRO | CO7: CENTRO | CP7: SUR | CQ7: SUR | CR7: SUR | CS7: SUR | CT7: CENTRO | CU7: CENTRO | CV7: CENTRO | CW7: CENTRO | CX7: SUR | CY7: NORTE | CZ7: NORTE | DA7: NORTE | DB7: NORTE | DC7: NORTE | DD7: SUR | DE7: CENTRO | DF7: CENTRO | DG7: CENTRO | DH7: NORTE | DI7: NORTE | DJ7: CENTRO | DK7: CENTRO | DL7: SUR | DM7: SUR | DN7: CENTRO | DO7: CENTRO | DP7: CENTRO | DQ7: CENTRO | DR7: CENTRO | DS7: CENTRO | DT7: SUR | DU7: CENTRO | DV7: CENTRO | DW7: NORTE | DX7: CENTRO | DY7: CENTRO | DZ7: NORTE | EA7: CENTRO | EB7: CENTRO | EC7: CENTRO | ED7: NORTE | EE7: NORTE | EF7: SUR | EG7: CENTRO | EH7: CENTRO | EI7: CENTRO | EJ7: CENTRO | EK7: CENTRO | EL7: CENTRO | EM7: SUR | EN7: SUR | EO7: SUR | EP7: SUR | EQ7: NORTE | ER7: SUR | ES7: SUR | ET7: SUR | EU7: CENTRO | EV7: CENTRO | EW7: CENTRO | EX7: SUR | EY7: SUR | EZ7: NORTE | FA7: CENTRO | FB7: NORTE | FC7: NORTE | FD7: NORTE | FE7: CENTRO | FF7: CENTRO | FG7: CENTRO | FH7: NORTE | FI7: NORTE | FL7: NORTE | FM7: CENTRO | FN7: NORTE | FO7: NORTE | FP7: NORTE | FQ7: NORTE | FR7: NORTE | FS7: NORTE
C8: HIDROELÉCTRICA | D8: HIDROELÉCTRICA | E8: HIDROELÉCTRICA | F8: HIDROELÉCTRICA | G8: HIDROELÉCTRICA | H8: TERMOELÉCTRICA | I8: TERMOELÉCTRICA | J8: HIDROELÉCTRICA | K8: HIDROELÉCTRICA | L8: TERMOELÉCTRICA | M8: TERMOELÉCTRICA | N8: TERMOELÉCTRICA | O8: TERMOELÉCTRICA | P8: TERMOELÉCTRICA | Q8: TERMOELÉCTRICA | R8: TERMOELÉCTRICA | S8: TERMOELÉCTRICA | T8: HIDROELÉCTRICA | U8: HIDROELÉCTRICA | V8: TERMOELÉCTRICA | W8: TERMOELÉCTRICA | X8: TERMOELÉCTRICA | Y8: TERMOELÉCTRICA | Z8: HIDROELÉCTRICA | AA8: HIDROELÉCTRICA | AB8: HIDROELÉCTRICA | AC8: TERMOELÉCTRICA | AD8: HIDROELÉCTRICA | AE8: HIDROELÉCTRICA | AF8: HIDROELÉCTRICA | AG8: HIDROELÉCTRICA | AH8: TERMOELÉCTRICA | AI8: TERMOELÉCTRICA | AJ8: TERMOELÉCTRICA | AK8: HIDROELÉCTRICA | AL8: HIDROELÉCTRICA | AM8: TERMOELÉCTRICA | AN8: TERMOELÉCTRICA | AO8: TERMOELÉCTRICA | AP8: HIDROELÉCTRICA | AQ8: HIDROELÉCTRICA | AR8: HIDROELÉCTRICA | AS8: HIDROELÉCTRICA | AT8: HIDROELÉCTRICA | AU8: HIDROELÉCTRICA | AV8: HIDROELÉCTRICA | AW8: HIDROELÉCTRICA | AX8: TERMOELÉCTRICA | AY8: TERMOELÉCTRICA | AZ8: TERMOELÉCTRICA | BA8: HIDROELÉCTRICA | BB8: HIDROELÉCTRICA | BC8: HIDROELÉCTRICA | BD8: HIDROELÉCTRICA | BE8: HIDROELÉCTRICA | BF8: HIDROELÉCTRICA | BG8: HIDROELÉCTRICA | BH8: HIDROELÉCTRICA | BI8: HIDROELÉCTRICA | BJ8: TERMOELÉCTRICA | BK8: TERMOELÉCTRICA | BL8: TERMOELÉCTRICA | BM8: TERMOELÉCTRICA | BN8: TERMOELÉCTRICA | BO8: TERMOELÉCTRICA | BP8: HIDROELÉCTRICA | BQ8: TERMOELÉCTRICA | BR8: TERMOELÉCTRICA | BS8: TERMOELÉCTRICA | BT8: TERMOELÉCTRICA | BU8: TERMOELÉCTRICA | BV8: TERMOELÉCTRICA | BW8: TERMOELÉCTRICA | BX8: TERMOELÉCTRICA | BY8: TERMOELÉCTRICA | BZ8: HIDROELÉCTRICA | CA8: TERMOELÉCTRICA | CB8: TERMOELÉCTRICA | CC8: HIDROELÉCTRICA | CD8: HIDROELÉCTRICA | CE8: HIDROELÉCTRICA | CF8: HIDROELÉCTRICA | CG8: HIDROELÉCTRICA | CH8: HIDROELÉCTRICA | CI8: TERMOELÉCTRICA | CJ8: TERMOELÉCTRICA | CK8: TERMOELÉCTRICA | CL8: TERMOELÉCTRICA | CM8: TERMOELÉCTRICA | CN8: TERMOELÉCTRICA | CO8: TERMOELÉCTRICA | CP8: TERMOELÉCTRICA | CQ8: TERMOELÉCTRICA | CR8: TERMOELÉCTRICA | CS8: TERMOELÉCTRICA | CT8: TERMOELÉCTRICA | CU8: TERMOELÉCTRICA | CV8: SOLAR | CW8: EÓLICA | CX8: SOLAR | CY8: EÓLICA | CZ8: SOLAR | DA8: HIDROELÉCTRICA | DB8: HIDROELÉCTRICA | DC8: HIDROELÉCTRICA | DD8: HIDROELÉCTRICA | DE8: HIDROELÉCTRICA | DF8: HIDROELÉCTRICA | DG8: HIDROELÉCTRICA | DH8: HIDROELÉCTRICA | DI8: HIDROELÉCTRICA | DJ8: HIDROELÉCTRICA | DK8: HIDROELÉCTRICA | DL8: SOLAR | DM8: SOLAR | DN8: EÓLICA | DO8: EÓLICA | DP8: TERMOELÉCTRICA | DQ8: TERMOELÉCTRICA | DR8: TERMOELÉCTRICA | DS8: TERMOELÉCTRICA | DT8: SOLAR | DU8: HIDROELÉCTRICA | DV8: HIDROELÉCTRICA | DW8: HIDROELÉCTRICA | DX8: HIDROELÉCTRICA | DY8: HIDROELÉCTRICA | DZ8: HIDROELÉCTRICA | EA8: HIDROELÉCTRICA | EB8: HIDROELÉCTRICA | EC8: HIDROELÉCTRICA | ED8: EÓLICA | EE8: EÓLICA | EF8: SOLAR | EG8: EÓLICA | EH8: EÓLICA | EI8: EÓLICA | EJ8: EÓLICA | EK8: HIDROELÉCTRICA | EL8: HIDROELÉCTRICA | EM8: HIDROELÉCTRICA | EN8: HIDROELÉCTRICA | EO8: HIDROELÉCTRICA | EP8: HIDROELÉCTRICA | EQ8: EÓLICA | ER8: SOLAR | ES8: SOLAR | ET8: SOLAR | EU8: HIDROELÉCTRICA | EV8: EÓLICA | EW8: EÓLICA | EX8: SOLAR | EY8: SOLAR | EZ8: HIDROELÉCTRICA | FA8: HIDROELÉCTRICA | FB8: TERMOELÉCTRICA | FC8: TERMOELÉCTRICA | FD8: TERMOELÉCTRICA | FE8: TERMOELÉCTRICA | FF8: TERMOELÉCTRICA | FG8: TERMOELÉCTRICA | FH8: TERMOELÉCTRICA | FI8: TERMOELÉCTRICA | FL8: HIDROELÉCTRICA | FM8: HIDROELÉCTRICA | FN8: HIDROELÉCTRICA | FO8: HIDROELÉCTRICA | FP8: TERMOELÉCTRICA | FQ8: TERMOELÉCTRICA | FR8: HIDROELÉCTRICA | FS8: HIDROELÉCTRICA
C9: CENTRALES SANTA ROSA S.A.C. | D9: CENTRALES SANTA ROSA S.A.C. | E9: HYDRO GLOBAL PERÚ S.A.C. | F9: ELECTROPERU | G9: ELECTROPERU | H9: ELECTROPERU | I9: ELECTROPERU | J9: ORAZUL ENERGY PERÚ | K9: ORAZUL ENERGY PERÚ | L9: TERMOSELVA | M9: TERMOSELVA | N9: KALLPA GENERACION S.A. | O9: KALLPA GENERACION S.A. | P9: KALLPA GENERACION S.A. | Q9: KALLPA GENERACION S.A. | R9: KALLPA GENERACION S.A. | S9: KALLPA GENERACION S.A. | T9: KALLPA GENERACION S.A. | U9: KALLPA GENERACION S.A. | V9: SHOUGESA | W9: SHOUGESA | X9: SHOUGESA | Y9: SHOUGESA | Z9: EGEMSA | AA9: EGESUR | AB9: EGESUR | AC9: EGESUR | AD9: EGASA | AE9: EGASA | AF9: EGASA | AG9: EGASA | AH9: EGASA | AI9: EGASA | AJ9: EGASA | AK9: SAN GABAN | AL9: CELEPSA | AM9: MINERA CERRO VERDE | AN9: PLANTA DE RESERVA FRIA DE GENERACION DE ETEN S.A. | AO9: PLANTA DE RESERVA FRIA DE GENERACION DE ETEN S.A. | AP9: EMPRESA DE GENERACION HUALLAGA | AQ9: EMPRESA DE GENERACION HUALLAGA | AR9: LA VIRGEN | AS9: CHINANGO S.A.C. | AT9: CHINANGO S.A.C. | AU9: HIDROELECTRICA HUANCHOR S.A.C. | AV9: CELEPSA RENOVABLES S.R.L. | AW9: INLAND ENERGY SAC | AX9: FENIX POWER PERÚ | AY9: FENIX POWER PERÚ | AZ9: FENIX POWER PERÚ | BA9: STATKRAFT S.A | BB9: STATKRAFT S.A | BC9: STATKRAFT S.A | BD9: STATKRAFT S.A | BE9: STATKRAFT S.A | BF9: STATKRAFT S.A | BG9: STATKRAFT S.A | BH9: STATKRAFT S.A | BI9: EMPRESA DE GENERACION HUANZA | BJ9: ENEL GENERACION PIURA S.A. | BK9: ENEL GENERACION PIURA S.A. | BL9: ENEL GENERACION PIURA S.A. | BM9: ENGIE | BN9: ENGIE | BO9: ENGIE | BP9: ENGIE | BQ9: ENGIE | BR9: ENGIE | BS9: ENGIE | BT9: ENGIE | BU9: ENGIE | BV9: ENGIE | BW9: ENGIE | BX9: ENGIE | BY9: ENGIE | BZ9: ENGIE | CA9: INFRAESTRUCTURAS Y ENERGIAS DEL PERU S.A.C. | CB9: INFRAESTRUCTURAS Y ENERGIAS DEL PERU S.A.C. | CC9: INVERSIONES SHAQSHA S.A.C. | CD9: ORYGEN PERU S.A.A. | CE9: ORYGEN PERU S.A.A. | CF9: ORYGEN PERU S.A.A. | CG9: ORYGEN PERU S.A.A. | CH9: ORYGEN PERU S.A.A. | CI9: ORYGEN PERU S.A.A. | CJ9: ORYGEN PERU S.A.A. | CK9: ORYGEN PERU S.A.A. | CL9: ORYGEN PERU S.A.A. | CM9: ORYGEN PERU S.A.A. | CN9: ORYGEN PERU S.A.A. | CO9: ORYGEN PERU S.A.A. | CP9: SAMAY I S.A.C | CQ9: SAMAY I S.A.C | CR9: SAMAY I S.A.C | CS9: SAMAY I S.A.C | CT9: TERMOCHILCA S.A.C. | CU9: TERMOCHILCA S.A.C. | CV9: COLCA SOLAR S.A.C. | CW9: ENERGIA RENOVABLE DEL SUR S.A. | CX9: GR CORTARRAMA SOCIEDAD ANONIMA CERRADA | CY9: GR TARUCA SOCIEDAD ANONIMA CERRADA | CZ9: KONDU SAC | DA9: PERUANA DE INVERSIONES EN ENERGIAS RENOVABLES S.A. | DB9: ORAZUL ENERGY PERÚ | DC9: ORAZUL ENERGY PERÚ | DD9: SAN GABAN | DE9: MAJA ENERGIA S.A.C. | DF9: EMPRESA DE GENERACION ELECTRICA CANCHAYLLO SAC | DG9: EMPRESA DE GENERACION ELECTRICA SANTA ANA S.A.C. | DH9: EMPRESA ELECTRICA AGUA AZUL | DI9: EMPRESA ELECTRICA RIO DOBLE | DJ9: HIDROCAÑETE S.A. | DK9: HUAURA POWER GROUP S.A. | DL9: MOQUEGUA FV S.A.C. | DM9: PANAMERICANA SOLAR SAC. | DN9: PARQUE EOLICO MARCONA S.A.C. | DO9: PARQUE EOLICO TRES HERMANAS S.A.C. | DP9: PETRAMAS | DQ9: PETRAMAS | DR9: PETRAMAS | DS9: PETRAMAS | DT9: TACNA SOLAR SAC. | DU9: ELECTRICA YANAPAMPA SAC | DV9: ANDEAN POWER S.A.C. | DW9: ASOCIACIÓN SANTA LUCIA DE CHACAS | DX9: ATRIA ENERGIA S.A.C. | DY9: EGEJUNIN | DZ9: EGEJUNIN | EA9: EGEJUNIN | EB9: EGEJUNIN | EC9: EMPRESA DE GENERACION ELECTRICA RIO BAÑOS S.A.C. | ED9: ENERGÍA EÓLICA S.A. | EE9: ENERGÍA EÓLICA S.A. | EF9: ENGIE | EG9: ENGIE | EH9: ENGIE | EI9: ENGIE | EJ9: ENGIE | EK9: GENERACIÓN ANDINA S.A.C. | EL9: GENERACIÓN ANDINA S.A.C. | EM9: GENERADORA DE ENERGÍA DEL PERÚ | EN9: GENERADORA DE ENERGÍA DEL PERÚ | EO9: GENERADORA DE ENERGÍA DEL PERÚ | EP9: GENERADORA DE ENERGÍA DEL PERÚ | EQ9: GR PAINO SOCIEDAD ANONIMA CERRADA | ER9: JOYA SOLAR S.A.C. | ES9: MAJES ARCUS S.A.C. | ET9: ORYGEN PERU S.A.A. | EU9: ORYGEN PERU S.A.A. | EV9: ORYGEN PERU S.A.A. | EW9: ORYGEN PERU S.A.A. | EX9: ORYGEN PERU S.A.A. | EY9: REPARTICIÓN ARCUS S.A.C. | EZ9: SINERSA | FA9: SINERSA | FB9: BIOENERGIA DEL CHIRA S.A. | FC9: GM OPERACIONES S.A.C. | FD9: GM OPERACIONES S.A.C. | FE9: SDF ENERGIA SAC | FF9: SDF ENERGIA SAC | FG9: AGRO INDUSTRIAL PARAMONGA S.A. | FH9: AGROAURORA S.A.C. | FI9: AGROINDUSTRIAS SAN JACINTO S.A.A. | FL9: UNACEM PERU S.A. | FM9: ELECTRO ORIENTE | FN9: AGUAS Y ENERGIA PERU | FO9: ELECTRO ZAÑA S.A.C. | FP9: ELECTRONOROESTE S.A. | FQ9: SDE PIURA | FR9: SINERSA | FS9: SINERSA
C10: SANTA ROSA 1 | D10: SANTA ROSA 2 | E10: SAN GABAN III | F10: MANTARO | G10: RESTITUCION | H10: TUMBES MAK 1 | I10: TUMBES MAK 2 | J10: CARHUAQUERO | K10: CAÑON DEL PATO | L10: AGUAYTIA TG1 | M10: AGUAYTIA TG2 | N10: KALLPA TG1 | O10: KALLPA TG2 | P10: KALLPA TG3 | Q10: KALLPA TV | R10: LFLORES TG1 | S10: LFLORES TV | T10: CERRO DEL AGUILA | U10: CERRODELAGUILAG4 | V10: SHOUGESA TV1 | W10: SHOUGESA TV2 | X10: SHOUGESA TV3 | Y10: SHOUGESA CUMMINS | Z10: MACHUPICCHU | AA10: ARICOTA 1 | AB10: ARICOTA 2 | AC10: INDEPENDENCIA | AD10: CHARCANI I,II,III | AE10: CHARCANI IV | AF10: CHARCANI V | AG10: CHARCANI VI | AH10: CHILINA TG | AI10: MOLLENDO 1, 2, 3 | AJ10: CHILINA (SULZ 1,2) | AK10: SAN GABAN II | AL10: PLATANAL | AM10: RECKA | AN10: RF ETEN TG1 | AO10: RF ETEN TG2 | AP10: CHAGLLA GP1 | AQ10: CHAGLLA | AR10: LA VIRGEN | AS10: CHIMAY | AT10: YANANGO | AU10: HUANCHOR | AV10: MARAÑON | AW10: STA TERESA | AX10: FENIX GT11 | AY10: FENIX GT12 | AZ10: FENIX TV10 | BA10: YAUPI | BB10: OROYA | BC10: PACHACHACA | BD10: MALPASO | BE10: CAHUA | BF10: ARCATA | BG10: GALLITO CIEGO | BH10: CHEVES | BI10: HUANZA | BJ10: MALACAS2 TG4 | BK10: MALACAS3 TG 5 | BL10: MALACAS1 TG6 | BM10: RF ILO2 TG1 | BN10: RF ILO2 TG2 | BO10: RF ILO2 TG3 | BP10: YUNCAN | BQ10: CHILCA1 TG1 | BR10: CHILCA1 TG2 | BS10: CHILCA1 TG3 | BT10: CHILCA-TV | BU10: CHILCA2 TG41 | BV10: CHILCA2-TV | BW10: CTNEPI_TG41 | BX10: CTNEPI_TG42 | BY10: CTNEPI_TG43 | BZ10: QUITARACSA | CA10: RF PTO MALDONADO | CB10: RF PUCALLPA | CC10: PARIAC | CD10: HUINCO | CE10: MATUCANA | CF10: MOYOPAMPA | CG10: CALLAHUANCA | CH10: HUAMPANI | CI10: STA ROSA WEST TG7 | CJ10: UTI_5 | CK10: UTI_6 | CL10: VENTANILLA 3 | CM10: VENTANILLA 4 | CN10: VENTANILLA TV | CO10: STAROSA TG8 | CP10: PTO_BRVO TG1 | CQ10: PTO_BRVO TG2 | CR10: PTO_BRVO TG3 | CS10: PTO_BRVO TG4 | CT10: OLLEROS TG1 | CU10: OLLEROS TV | CV10: CS YARUCAYA | CW10: SAN JUAN | CX10: MATARANI | CY10: DUNA | CZ10: CARHUAQUERO (CS) | DA10: MANTA I | DB10: CARHUAQUERO4 | DC10: CAÑA BRAVA | DD10: TUPURI | DE10: RONCADOR | DF10: CANCHAYLLO | DG10: RENOVANDESH1 | DH10: POTRERO | DI10: PIZARRAS | DJ10: NIMPERIAL | DK10: YARUCAYA | DL10: MOQUEGUA-SOLAR | DM10: PANAMERICANA-SOLAR | DN10: PQE-EOLICO-MARCONA | DO10: PQE-EOLICO-3-HERMANAS | DP10: HUAYCOLORO | DQ10: CALLAO | DR10: DONA_CATALINA | DS10: LAGRINGAV | DT10: TACNA-SOLAR | DU10: YANAPAMPA | DV10: CARHUAC | DW10: HUALLIN | DX10: PURMACANA | DY10: HUASAHUASI | DZ10: STACRUZ_1_2 | EA10: RUNATULLO_II | EB10: RUNATULLO_III | EC10: RUCUY | ED10: PQE-EOLICO-TALARA | EE10: PQE-EOLICO-CUPISNIQUE | EF10: INTIPAMPA | EG10: PUNTA LOMITAS-BL1 | EH10: PUNTA LOMITAS-BL2 | EI10: PUN LOMITAS_EXP-BL1 | EJ10: PUN LOMITAS_EXP-BL2 | EK10: 8AGOSTO | EL10: EL CARMEN | EM10: LA JOYA | EN10: ANGEL_I | EO10: ANGEL_II | EP10: ANGEL_III | EQ10: HUAMBOS | ER10: SAN MARTIN SOLAR | ES10: MAJES | ET10: RUBI | EU10: CH_HER1 | EV10: WAYRA-I | EW10: WAYRA EXTENSION | EX10: CLEMESI | EY10: REPARTICION | EZ10: POECHOS2 | FA10: CHANCAY | FB10: CANA BRAVA | FC10: REFINERIA TALARA TV1 | FD10: REFINERÍA TALARA TV2 | FE10: OQUENDO TG1 | FF10: OQUENDO TV1 | FG10: PARAMONGA | FH10: MAPLE | FI10: SAN_JACINTO | FJ10: MW | FL10: CARPAPATA | FM10: CENTRALES ELOR | FN10: PIAS1 | FO10: ZANA | FP10: TABLAZO | FQ10: TALLANCA | FR10: CURUMUY | FS10: POECHOS1 | FT10: MW
A11: 22/04/2025 | B11: 00:30 | E11: 0 | F11: 587.1 | G11: 195.3 | J11: 59.5 | K11: 228.2 | N11: 105.8 | O11: 105.8 | P11: 105.7 | Q11: 207.7 | R11: 108.8 | S11: 66.7 | T11: 533.4 | U11: 10.2 | Z11: 163.5 | AA11: 7.2 | AB11: 3.1 | AD11: 6.8 | AE11: 10.2 | AF11: 86.6 | AG11: 6.2 | AK11: 109.4 | AL11: 219.6 | AP11: 6.4 | AQ11: 298.4 | AR11: 81.6 | AS11: 123.6 | AT11: 42 | AU11: 18.5 | AV11: 19.7 | AW11: 87.7 | AX11: 0 | AY11: 92.8 | BA11: 107.5 | BB11: 7.3 | BC11: 6.7 | BD11: 45.9 | BE11: 22.1 | BF11: 0 | BG11: 37.2 | BH11: 170.2 | BI11: 0 | BL11: 47.8 | BP11: 85.4 | BQ11: 110 | BS11: 115.1 | BT11: 137.9 | CC11: 4.6 | CD11: 79.2 | CE11: 131.3 | CF11: 62.1 | CG11: 79 | CH11: 29.5 | CL11: 104.1 | CM11: 103.9 | CN11: 120.9 | CQ11: 0 | CV11: 0 | CW11: 108.2 | CX11: 0 | CY11: 0 | CZ11: 0 | DA11: 20 | DB11: 9.9 | DC11: 4.8 | DD11: 1.2 | DE11: 3.3 | DF11: 4.9 | DG11: 19.9 | DH11: 20 | DI11: 19.1 | DJ11: 3.6 | DK11: 9.3 | DL11: 0 | DM11: 0 | DN11: 25.6 | DO11: 64.3 | DP11: 4.6 | DQ11: 2.4 | DR11: 2.4 | DT11: 0 | DU11: 3.3 | DV11: 9.3 | DW11: 3.1 | DY11: 19.8 | DZ11: 9.7 | EA11: 18.5 | EB11: 20.2 | EC11: 19.8 | ED11: 18.8 | EE11: 35.4 | EF11: 0 | EG11: 67.6 | EH11: 85.7 | EI11: 8.2 | EJ11: 0.7 | EK11: 21 | EL11: 6.9 | EM11: 5.2 | EN11: 20.4 | EO11: 20.4 | EP11: 20.2 | EQ11: 0 | ER11: 0 | ES11: 0 | ET11: 0 | EU11: 0.6 | EV11: 87.2 | EW11: 68.3 | EX11: 0 | EY11: 0 | EZ11: 8.6 | FA11: 19.8 | FC11: 43.1 | FD11: 31.8 | FE11: 29.1 | FF11: 3.4 | FG11: 16 | FJ11: 6350.8 | FL11: 23.14369 | FM11: 0 | FO11: 13.2 | FQ11: 9.43433 | FR11: 10.2 | FS11: 15.4 | FT11: 71.37802
A12: 22/04/2025 | B12: 01:00 | E12: 0 | F12: 599.2 | G12: 201.5 | J12: 60.2 | K12: 231.5 | N12: 105.3 | O12: 105.2 | P12: 105.4 | Q12: 208.1 | R12: 107.6 | S12: 66 | T12: 561.1 | U12: 10.4 | Z12: 165.8 | AA12: 7.8 | AB12: 3.4 | AD12: 6.8 | AE12: 10.2 | AF12: 89.8 | AG12: 6 | AK12: 110.8 | AL12: 223.2 | AP12: 6.5 | AQ12: 464.4 | AR12: 81.8 | AS12: 148.7 | AT12: 42.2 | AU12: 18.7 | AV12: 19.7 | AW12: 85.4 | AX12: 0 | AY12: 35.1 | BA12: 108.7 | BB12: 7.3 | BC12: 6.6 | BD12: 47 | BE12: 22 | BF12: 0 | BG12: 38.1 | BH12: 174.8 | BI12: 0 | BL12: 24.9 | BP12: 86.4 | BQ12: 83.9 | BS12: 83.7 | BT12: 107.3 | CC12: 4.6 | CD12: 32.4 | CE12: 134.4 | CF12: 63.4 | CG12: 79.5 | CH12: 30.1 | CL12: 104 | CM12: 103.9 | CN12: 120.2 | CQ12: 0 | CV12: 0 | CW12: 108.1 | CX12: 0 | CY12: 0 | CZ12: 0 | DA12: 20 | DB12: 9.9 | DC12: 4.7 | DD12: 1.2 | DE12: 3.4 | DF12: 5 | DG12: 20.4 | DH12: 20 | DI12: 19.1 | DJ12: 3.6 | DK12: 9.3 | DL12: 0 | DM12: 0 | DN12: 27.3 | DO12: 69.8 | DP12: 4.6 | DQ12: 2.4 | DR12: 2.4 | DT12: 0 | DU12: 3.3 | DV12: 5.9 | DW12: 3.1 | DY12: 19.8 | DZ12: 9.6 | EA12: 18.7 | EB12: 20.3 | EC12: 19.8 | ED12: 23.6 | EE12: 46 | EF12: 0 | EG12: 101.8 | EH12: 90.8 | EI12: 9.2 | EJ12: 3.1 | EK12: 21 | EL12: 6.9 | EM12: 5.5 | EN12: 20.4 | EO12: 20.4 | EP12: 20.2 | EQ12: 0 | ER12: 0 | ES12: 0 | ET12: 0 | EU12: 0.6 | EV12: 96 | EW12: 85.5 | EX12: 0 | EY12: 0 | EZ12: 8.5 | FA12: 19.9 | FC12: 41.5 | FD12: 31.8 | FE12: 29.1 | FF12: 3.2 | FG12: 16 | FJ12: 6483.7 | FL12: 23.14725 | FM12: 0 | FO12: 13.2 | FQ12: 9.43416 | FR12: 10.2 | FS12: 15.4 | FT12: 71.38141
A13: 22/04/2025 | B13: 01:30 | E13: 0 | F13: 599.2 | G13: 199.7 | J13: 60 | K13: 231.5 | N13: 106.2 | O13: 106.5 | P13: 107.1 | Q13: 208.1 | R13: 107.9 | S13: 65.6 | T13: 565.6 | U13: 10.5 | Z13: 166.2 | AA13: 7.6 | AB13: 3.5 | AD13: 6.8 | AE13: 10.2 | AF13: 89.8 | AG13: 5.8 | AK13: 110.9 | AL13: 224.1 | AP13: 6.5 | AQ13: 467 | AR13: 81.8 | AS13: 148.9 | AT13: 42.2 | AU13: 18.7 | AV13: 19.7 | AW13: 92.2 | AX13: 0 | AY13: 35.1 | BA13: 108.7 | BB13: 7.3 | BC13: 6.5 | BD13: 47.1 | BE13: 22 | BF13: 0 | BG13: 37.9 | BH13: 174.2 | BI13: 0 | BL13: 24.7 | BP13: 86.4 | BQ13: 83.8 | BS13: 83.5 | BT13: 109.4 | CC13: 4.6 | CD13: 27.2 | CE13: 132 | CF13: 63.5 | CG13: 79.4 | CH13: 30.1 | CL13: 104.1 | CM13: 103.9 | CN13: 120.4 | CQ13: 0 | CV13: 0 | CW13: 102.2 | CX13: 0 | CY13: 0 | CZ13: 0 | DA13: 20 | DB13: 9.9 | DC13: 4.7 | DD13: 1.2 | DE13: 3.4 | DF13: 5 | DG13: 20.2 | DH13: 20 | DI13: 19.1 | DJ13: 3.6 | DK13: 9.3 | DL13: 0 | DM13: 0 | DN13: 25.2 | DO13: 71 | DP13: 4.6 | DQ13: 2.4 | DR13: 2.4 | DT13: 0 | DU13: 3.3 | DV13: 6 | DW13: 3.1 | DY13: 19.8 | DZ13: 9.6 | EA13: 18.6 | EB13: 20.3 | EC13: 20 | ED13: 16.9 | EE13: 39.4 | EF13: 0 | EG13: 88.8 | EH13: 91.9 | EI13: 8.4 | EJ13: 5 | EK13: 21 | EL13: 6.9 | EM13: 5.5 | EN13: 20.4 | EO13: 20.4 | EP13: 20.2 | EQ13: 0 | ER13: 0 | ES13: 0 | ET13: 0 | EU13: 0.6 | EV13: 100.7 | EW13: 88.1 | EX13: 0 | EY13: 0 | EZ13: 8.6 | FA13: 20 | FC13: 41.5 | FD13: 31.4 | FE13: 29.2 | FF13: 3.2 | FG13: 16 | FJ13: 6470.6 | FL13: 23.14646 | FM13: 0 | FO13: 13.2 | FQ13: 9.43426 | FR13: 10.2 | FS13: 15.4 | FT13: 71.38072
A14: 22/04/2025 | B14: 02:00 | E14: 0 | F14: 592.2 | G14: 197.5 | J14: 59.1 | K14: 237.2 | N14: 105.1 | O14: 103.7 | P14: 104.5 | Q14: 213.8 | R14: 108.6 | S14: 67.4 | T14: 550.5 | U14: 10.3 | Z14: 159.6 | AA14: 6.8 | AB14: 3.2 | AD14: 6.8 | AE14: 10.2 | AF14: 90.2 | AG14: 5.8 | AK14: 108.9 | AL14: 223.4 | AP14: 6.4 | AQ14: 427.2 | AR14: 81.8 | AS14: 140.3 | AT14: 42.1 | AU14: 18.7 | AV14: 19.7 | AW14: 88.8 | AX14: 0 | AY14: 30.5 | BA14: 105.8 | BB14: 7.4 | BC14: 6.6 | BD14: 44.2 | BE14: 22.1 | BF14: 0 | BG14: 36.3 | BH14: 171.2 | BI14: 0 | BL14: 24.5 | BP14: 85.6 | BQ14: 84.1 | BS14: 83.1 | BT14: 108 | CC14: 4.6 | CD14: 20.1 | CE14: 126.2 | CF14: 61.7 | CG14: 78.5 | CH14: 29 | CL14: 103.7 | CM14: 104.7 | CN14: 119.9 | CQ14: 0 | CV14: 0 | CW14: 96.9 | CX14: 0 | CY14: 0.6 | CZ14: 0 | DA14: 20 | DB14: 9.9 | DC14: 4.7 | DD14: 1.2 | DE14: 3.4 | DF14: 5 | DG14: 19.8 | DH14: 20 | DI14: 19.1 | DJ14: 3.6 | DK14: 9.3 | DL14: 0 | DM14: 0 | DN14: 27 | DO14: 69.2 | DP14: 4.6 | DQ14: 2.4 | DR14: 2.4 | DT14: 0 | DU14: 3.3 | DV14: 5.9 | DW14: 3.1 | DY14: 19.8 | DZ14: 9.6 | EA14: 18.5 | EB14: 20.2 | EC14: 20 | ED14: 11.3 | EE14: 22.5 | EF14: 0 | EG14: 86.2 | EH14: 92.2 | EI14: 7.9 | EJ14: 1.7 | EK14: 21 | EL14: 6.9 | EM14: 5.5 | EN14: 20.4 | EO14: 20.4 | EP14: 20.2 | EQ14: 0 | ER14: 0 | ES14: 0 | ET14: 0 | EU14: 0.6 | EV14: 81.4 | EW14: 70.5 | EX14: 0 | EY14: 0 | EZ14: 8.7 | FA14: 20 | FC14: 42.7 | FD14: 31.4 | FE14: 29.2 | FF14: 3.1 | FG14: 17 | FJ14: 6287.9 | FL14: 23.14213 | FM14: 0 | FO14: 13.2 | FQ14: 9.43451 | FR14: 10.2 | FS14: 15.5 | FT14: 71.47664
A15: 22/04/2025 | B15: 02:30 | E15: 0 | F15: 599.8 | G15: 201.8 | J15: 57.7 | K15: 230.9 | N15: 121.5 | O15: 122.1 | P15: 121.8 | Q15: 216.8 | R15: 109.3 | S15: 67.8 | T15: 564.3 | U15: 10 | Z15: 163.1 | AA15: 7.1 | AB15: 3.6 | AD15: 6.8 | AE15: 10.2 | AF15: 89.8 | AG15: 5.8 | AK15: 110.3 | AL15: 224 | AP15: 6.5 | AQ15: 465.3 | AR15: 81.9 | AS15: 143.5 | AT15: 42.2 | AU15: 18.7 | AV15: 19.7 | AW15: 89.3 | AX15: 0 | AY15: 33 | BA15: 108.2 | BB15: 7.4 | BC15: 6.7 | BD15: 46.6 | BE15: 22.2 | BF15: 0 | BG15: 36.5 | BH15: 174.4 | BI15: 0 | BL15: 24.8 | BP15: 85 | BQ15: 86.2 | BS15: 84.7 | BT15: 108.8 | CC15: 4.6 | CD15: 20.2 | CE15: 129.6 | CF15: 62.6 | CG15: 78.8 | CH15: 29.6 | CL15: 106.1 | CM15: 105.8 | CN15: 123 | CQ15: 0 | CV15: 0 | CW15: 88.6 | CX15: 0 | CY15: 0.3 | CZ15: 0 | DA15: 20 | DB15: 9.8 | DC15: 4.8 | DD15: 1.2 | DE15: 3.4 | DF15: 5 | DG15: 20.4 | DH15: 20 | DI15: 19.1 | DJ15: 3.6 | DK15: 9.3 | DL15: 0 | DM15: 0 | DN15: 24.7 | DO15: 66.7 | DP15: 4.6 | DQ15: 2.4 | DR15: 2.4 | DT15: 0 | DU15: 3.3 | DV15: 5.7 | DW15: 3.1 | DY15: 19.8 | DZ15: 9.6 | EA15: 18.5 | EB15: 20.3 | EC15: 20 | ED15: 11.4 | EE15: 19.9 | EF15: 0 | EG15: 90.3 | EH15: 88 | EI15: 8.1 | EJ15: 3.3 | EK15: 21 | EL15: 6.9 | EM15: 5.5 | EN15: 20.4 | EO15: 20.4 | EP15: 20.2 | EQ15: 0 | ER15: 0 | ES15: 0 | ET15: 0 | EU15: 0.6 | EV15: 61.1 | EW15: 55.5 | EX15: 0 | EY15: 0 | EZ15: 8.6 | FA15: 20 | FC15: 42.6 | FD15: 31.4 | FE15: 29.1 | FF15: 3.2 | FG15: 17 | FJ15: 6387.5 | FL15: 23.14456 | FM15: 0 | FO15: 13.2 | FQ15: 9.43441 | FR15: 10.4 | FS15: 15.5 | FT15: 71.67897
A16: 22/04/2025 | B16: 03:00 | E16: 0 | F16: 597.7 | G16: 200.4 | J16: 59.4 | K16: 231.3 | N16: 114 | O16: 113.1 | P16: 113.1 | Q16: 213.6 | R16: 108.6 | S16: 66.5 | T16: 559 | U16: 10.3 | Z16: 161.4 | AA16: 6.9 | AB16: 3.6 | AD16: 6.8 | AE16: 10.2 | AF16: 90.2 | AG16: 5.8 | AK16: 110.2 | AL16: 223.8 | AP16: 6.5 | AQ16: 429.1 | AR16: 81.8 | AS16: 147.7 | AT16: 42.2 | AU16: 18.7 | AV16: 19.7 | AW16: 90 | AX16: 0 | AY16: 32.7 | BA16: 108.2 | BB16: 7.4 | BC16: 6.5 | BD16: 46.5 | BE16: 22 | BF16: 0 | BG16: 37.3 | BH16: 173.3 | BI16: 0 | BL16: 24.5 | BP16: 85.7 | BQ16: 84 | BS16: 83.8 | BT16: 107.4 | CC16: 4.6 | CD16: 19.6 | CE16: 130.5 | CF16: 62.8 | CG16: 79.2 | CH16: 29.7 | CL16: 104.2 | CM16: 104.3 | CN16: 120.4 | CQ16: 0 | CV16: 0 | CW16: 89.4 | CX16: 0 | CY16: 0 | CZ16: 0 | DA16: 20 | DB16: 9.9 | DC16: 4.8 | DD16: 1.2 | DE16: 3.4 | DF16: 4.9 | DG16: 20 | DH16: 20 | DI16: 19.1 | DJ16: 3.6 | DK16: 9.3 | DL16: 0 | DM16: 0 | DN16: 21.6 | DO16: 60 | DP16: 4.6 | DQ16: 2.4 | DR16: 2.4 | DT16: 0 | DU16: 3.3 | DV16: 5.7 | DW16: 3.1 | DY16: 19.8 | DZ16: 9.6 | EA16: 18.4 | EB16: 20.2 | EC16: 20 | ED16: 16 | EE16: 25.1 | EF16: 0 | EG16: 100.4 | EH16: 89.4 | EI16: 11.8 | EJ16: 3.5 | EK16: 21 | EL16: 6.9 | EM16: 5.5 | EN16: 20.4 | EO16: 20.4 | EP16: 20.2 | EQ16: 0 | ER16: 0 | ES16: 0 | ET16: 0 | EU16: 0.6 | EV16: 57.3 | EW16: 67.7 | EX16: 0 | EY16: 0 | EZ16: 8.7 | FA16: 20 | FC16: 43.2 | FD16: 31.4 | FE16: 29.2 | FF16: 3.3 | FG16: 16.7 | FJ16: 6331.6 | FL16: 23.1421 | FM16: 0 | FO16: 13.2 | FQ16: 9.43434 | FR16: 10.4 | FS16: 15.4 | FT16: 71.57644
A17: 22/04/2025 | B17: 03:30 | E17: 0 | F17: 597.7 | G17: 199.9 | J17: 59.8 | K17: 231.4 | N17: 106.4 | O17: 105.8 | P17: 106.2 | Q17: 207.3 | R17: 108.4 | S17: 67 | T17: 561.5 | U17: 10.3 | Z17: 161.4 | AA17: 7.1 | AB17: 3.7 | AD17: 6.8 | AE17: 10.2 | AF17: 89.4 | AG17: 5.8 | AK17: 110.5 | AL17: 223.7 | AP17: 6.5 | AQ17: 423.7 | AR17: 81.9 | AS17: 140.9 | AT17: 42.2 | AU17: 18.7 | AV17: 19.7 | AW17: 90.2 | AX17: 32 | AY17: 33.7 | BA17: 106.4 | BB17: 7.4 | BC17: 6.6 | BD17: 45.8 | BE17: 22.1 | BF17: 0 | BG17: 36.8 | BH17: 173.5 | BI17: 0 | BL17: 24.8 | BP17: 86.1 | BQ17: 83.4 | BS17: 83.1 | BT17: 108.7 | CC17: 4.6 | CD17: 21.8 | CE17: 126.2 | CF17: 63 | CG17: 76.2 | CH17: 29.6 | CL17: 103.8 | CM17: 104.3 | CN17: 120.5 | CQ17: 0 | CV17: 0 | CW17: 95.5 | CX17: 0 | CY17: 0 | CZ17: 0 | DA17: 20 | DB17: 9.9 | DC17: 4.6 | DD17: 1.2 | DE17: 3.4 | DF17: 4.9 | DG17: 20.2 | DH17: 20 | DI17: 19.1 | DJ17: 3.6 | DK17: 9.3 | DL17: 0 | DM17: 0 | DN17: 20.7 | DO17: 59.8 | DP17: 4.6 | DQ17: 2.4 | DR17: 2.4 | DT17: 0 | DU17: 3.3 | DV17: 5.7 | DW17: 3.1 | DY17: 19.8 | DZ17: 9.6 | EA17: 18.3 | EB17: 20.3 | EC17: 20 | ED17: 27.5 | EE17: 26.7 | EF17: 0 | EG17: 94.1 | EH17: 88.5 | EI17: 14.9 | EJ17: 3 | EK17: 21 | EL17: 6.9 | EM17: 5 | EN17: 20.4 | EO17: 20.4 | EP17: 20.2 | EQ17: 0 | ER17: 0 | ES17: 0 | ET17: 0 | EU17: 0.6 | EV17: 63 | EW17: 57.2 | EX17: 0 | EY17: 0 | EZ17: 8.6 | FA17: 20 | FC17: 42.5 | FD17: 32.1 | FE17: 29.2 | FF17: 3.2 | FG17: 16.9 | FJ17: 6328.1 | FL17: 23.13819 | FM17: 0 | FO17: 13.2 | FQ17: 9.43435 | FR17: 10.2 | FS17: 15.4 | FT17: 71.37254
A18: 22/04/2025 | B18: 04:00 | E18: 0 | F18: 601.5 | G18: 199.3 | J18: 60.2 | K18: 233.6 | N18: 107.4 | O18: 106 | P18: 106.1 | Q18: 208 | R18: 109.7 | S18: 67.4 | T18: 563.8 | U18: 10.5 | Z18: 167.5 | AA18: 7.3 | AB18: 3.6 | AD18: 6.8 | AE18: 10.2 | AF18: 90 | AG18: 5.8 | AK18: 111.1 | AL18: 223.3 | AP18: 6.5 | AQ18: 436.8 | AR18: 81.8 | AS18: 144.1 | AT18: 42.1 | AU18: 18.7 | AV18: 19.7 | AW18: 90.4 | AX18: 35.4 | AY18: 36.8 | BA18: 108.8 | BB18: 7.6 | BC18: 6.6 | BD18: 46.8 | BE18: 22.1 | BF18: 0 | BG18: 37.9 | BH18: 174.7 | BI18: 0 | BL18: 25.3 | BP18: 86.6 | BQ18: 84.1 | BS18: 83.8 | BT18: 107 | CC18: 4.6 | CD18: 22.4 | CE18: 128.7 | CF18: 63.6 | CG18: 76.5 | CH18: 30.1 | CL18: 104.2 | CM18: 104.2 | CN18: 121 | CQ18: 0 | CV18: 0 | CW18: 92.8 | CX18: 0 | CY18: 0 | CZ18: 0 | DA18: 20 | DB18: 9.9 | DC18: 4.8 | DD18: 1.2 | DE18: 3.4 | DF18: 4.9 | DG18: 20.3 | DH18: 20 | DI18: 19.1 | DJ18: 3.6 | DK18: 9.3 | DL18: 0 | DM18: 0 | DN18: 23.2 | DO18: 57.4 | DP18: 4.6 | DQ18: 2.4 | DR18: 2.4 | DT18: 0 | DU18: 3.3 | DV18: 5.8 | DW18: 3.1 | DY18: 19.8 | DZ18: 9.6 | EA18: 18.4 | EB18: 20.3 | EC18: 19.9 | ED18: 23.2 | EE18: 36.3 | EF18: 0 | EG18: 93.1 | EH18: 88.5 | EI18: 12.2 | EJ18: 2.8 | EK18: 21 | EL18: 6.8 | EM18: 5.1 | EN18: 20.4 | EO18: 20.4 | EP18: 20.2 | EQ18: 0 | ER18: 0 | ES18: 0 | ET18: 0 | EU18: 0.6 | EV18: 58.7 | EW18: 49.8 | EX18: 0 | EY18: 0 | EZ18: 8.7 | FA18: 20 | FC18: 42.9 | FD18: 31.1 | FE18: 29.2 | FF18: 3.2 | FG18: 17 | FJ18: 6368.7 | FL18: 23.14311 | FM18: 0 | FO18: 13.2 | FQ18: 9.43464 | FR18: 10.4 | FS18: 15.4 | FT18: 71.57775
A19: 22/04/2025 | B19: 04:30 | E19: 0 | F19: 595.6 | G19: 198.5 | J19: 60 | K19: 231.3 | N19: 107 | O19: 107.5 | P19: 107 | Q19: 223.6 | R19: 109.5 | S19: 66.6 | T19: 555.7 | U19: 10.4 | Z19: 164.6 | AA19: 6.9 | AB19: 3.2 | AD19: 6.8 | AE19: 10.2 | AF19: 90.9 | AG19: 5.6 | AK19: 110.6 | AL19: 223.5 | AP19: 6.4 | AQ19: 463.1 | AR19: 81.9 | AS19: 148.7 | AT19: 42.2 | AU19: 18.7 | AV19: 19.7 | AW19: 88.9 | AX19: 34.8 | AY19: 0 | BA19: 108.4 | BB19: 7.7 | BC19: 6.5 | BD19: 46.4 | BE19: 22.1 | BF19: 0 | BG19: 37.5 | BH19: 172.7 | BI19: 0 | BL19: 25 | BP19: 86.2 | BQ19: 83.5 | BS19: 83.5 | BT19: 108.1 | CC19: 4.6 | CD19: 19.5 | CE19: 131.6 | CF19: 63.2 | CG19: 76.5 | CH19: 29.9 | CL19: 104 | CM19: 104 | CN19: 120.7 | CQ19: 0 | CV19: 0 | CW19: 96.5 | CX19: 0 | CY19: 0 | CZ19: 0 | DA19: 20 | DB19: 9.9 | DC19: 4.8 | DD19: 1.2 | DE19: 3.4 | DF19: 4.9 | DG19: 20.1 | DH19: 20 | DI19: 19.1 | DJ19: 3.6 | DK19: 9.3 | DL19: 0 | DM19: 0 | DN19: 23.2 | DO19: 52.4 | DP19: 4.6 | DQ19: 2.4 | DR19: 2.4 | DT19: 0 | DU19: 2.8 | DV19: 5.8 | DW19: 3.1 | DY19: 19.8 | DZ19: 9.7 | EA19: 18.2 | EB19: 20.2 | EC19: 20 | ED19: 28.2 | EE19: 34.6 | EF19: 0 | EG19: 62.4 | EH19: 79.7 | EI19: 6.5 | EJ19: 2 | EK19: 21 | EL19: 6.8 | EM19: 5 | EN19: 20.4 | EO19: 20.4 | EP19: 20.2 | EQ19: 0 | ER19: 0 | ES19: 0 | ET19: 0 | EU19: 0.6 | EV19: 37.1 | EW19: 35.9 | EX19: 0 | EY19: 0 | EZ19: 8.6 | FA19: 20 | FC19: 43 | FD19: 31.4 | FE19: 29.2 | FF19: 3.3 | FG19: 16 | FJ19: 6270.7 | FL19: 23.14071 | FM19: 0 | FO19: 13.2 | FQ19: 9.4349 | FR19: 10.3 | FS19: 15.4 | FT19: 71.47561
A20: 22/04/2025 | B20: 05:00 | E20: 0 | F20: 601.2 | G20: 202.2 | J20: 60.2 | K20: 231.6 | N20: 131.3 | O20: 131.6 | P20: 131.5 | Q20: 221.7 | R20: 106.9 | S20: 66.2 | T20: 566.3 | U20: 10.5 | Z20: 166.8 | AA20: 7.3 | AB20: 3.4 | AD20: 6.8 | AE20: 10.2 | AF20: 90.1 | AG20: 5.8 | AK20: 111 | AL20: 223.2 | AP20: 6.5 | AQ20: 465.4 | AR20: 81.9 | AS20: 148.4 | AT20: 42.2 | AU20: 18.7 | AV20: 19.7 | AW20: 90.8 | AX20: 32.4 | AY20: 0 | BA20: 108.6 | BB20: 8.3 | BC20: 6.6 | BD20: 46.4 | BE20: 22.1 | BF20: 0 | BG20: 38.1 | BH20: 174.1 | BI20: 0 | BL20: 47 | BP20: 86.5 | BQ20: 144 | BS20: 127.6 | BT20: 139.6 | CC20: 4.6 | CD20: 43.5 | CE20: 132.4 | CF20: 63.5 | CG20: 76.6 | CH20: 30.1 | CL20: 103.8 | CM20: 103.9 | CN20: 120 | CQ20: 0 | CV20: 0 | CW20: 100.8 | CX20: 0 | CY20: 0 | CZ20: 0 | DA20: 20 | DB20: 9.9 | DC20: 4.7 | DD20: 1.2 | DE20: 3.4 | DF20: 5.1 | DG20: 20.4 | DH20: 20 | DI20: 19.1 | DJ20: 3.7 | DK20: 9.3 | DL20: 0 | DM20: 0 | DN20: 22.1 | DO20: 53.6 | DP20: 4.6 | DQ20: 2.4 | DR20: 2.4 | DT20: 0 | DU20: 3.2 | DV20: 5.8 | DW20: 3.1 | DY20: 19.8 | DZ20: 9.7 | EA20: 18 | EB20: 20.3 | EC20: 20 | ED20: 30.2 | EE20: 42.3 | EF20: 0 | EG20: 54.7 | EH20: 81.4 | EI20: 6.7 | EJ20: 1.9 | EK20: 21 | EL20: 6.8 | EM20: 4.9 | EN20: 20.4 | EO20: 20.4 | EP20: 20.2 | EQ20: 0 | ER20: 0 | ES20: 0 | ET20: 0 | EU20: 0.6 | EV20: 17.8 | EW20: 16.2 | EX20: 0 | EY20: 0 | EZ20: 8.6 | FA20: 20 | FC20: 42.8 | FD20: 31.3 | FE20: 29.3 | FF20: 3.3 | FG20: 16 | FJ20: 6518.5 | FL20: 23.14089 | FM20: 0 | FO20: 13.2 | FQ20: 9.4348 | FR20: 10.2 | FS20: 15.5 | FT20: 71.47569
A21: 22/04/2025 | B21: 05:30 | E21: 0 | F21: 599.2 | G21: 201.9 | J21: 91.5 | K21: 233.9 | N21: 111.9 | O21: 111.6 | P21: 111.3 | Q21: 213.1 | R21: 108 | S21: 66.5 | T21: 553.3 | U21: 10.7 | Z21: 166 | AA21: 7.5 | AB21: 3.3 | AD21: 6.7 | AE21: 10.2 | AF21: 90 | AG21: 5.9 | AK21: 111.2 | AL21: 224 | AP21: 6.5 | AQ21: 465.5 | AR21: 81.8 | AS21: 149.6 | AT21: 42.1 | AU21: 18.7 | AV21: 19.7 | AW21: 91 | AX21: 31.9 | AY21: 0 | BA21: 108.9 | BB21: 0 | BC21: 6.5 | BD21: 46 | BE21: 20.5 | BF21: 0 | BG21: 38 | BH21: 174.8 | BI21: 0 | BL21: 47 | BP21: 87.2 | BQ21: 171.8 | BS21: 200 | BT21: 181.9 | CC21: 4.6 | CD21: 34.7 | CE21: 133.7 | CF21: 61.2 | CG21: 76.7 | CH21: 30.3 | CL21: 102.7 | CM21: 102.5 | CN21: 119 | CQ21: 0 | CV21: 0 | CW21: 95.4 | CX21: 0 | CY21: 0 | CZ21: 0 | DA21: 20 | DB21: 9.9 | DC21: 5.4 | DD21: 1.2 | DE21: 3.3 | DF21: 5 | DG21: 20.3 | DH21: 20 | DI21: 19.1 | DJ21: 3.6 | DK21: 9.3 | DL21: 0 | DM21: 0 | DN21: 21.1 | DO21: 50.2 | DP21: 4.6 | DQ21: 2.4 | DR21: 2.4 | DT21: 0 | DU21: 3.2 | DV21: 5.7 | DW21: 3 | DY21: 19.8 | DZ21: 9.7 | EA21: 18.2 | EB21: 20.3 | EC21: 19.9 | ED21: 30.2 | EE21: 39.1 | EF21: 0 | EG21: 39.8 | EH21: 68.6 | EI21: 3.6 | EJ21: 1.9 | EK21: 21 | EL21: 6.8 | EM21: 4.9 | EN21: 20.4 | EO21: 20.4 | EP21: 20.2 | EQ21: 0 | ER21: 0 | ES21: 0 | ET21: 0 | EU21: 0.6 | EV21: 10 | EW21: 12 | EX21: 0 | EY21: 0 | EZ21: 8.6 | FA21: 20 | FC21: 42.1 | FD21: 31.4 | FE21: 29.3 | FF21: 3.3 | FG21: 16 | FJ21: 6535.7 | FL21: 23.1428 | FM21: 0 | FO21: 13.2 | FQ21: 9.43483 | FR21: 10.2 | FS21: 15.5 | FT21: 71.47763
A22: 22/04/2025 | B22: 06:00 | E22: 0 | F22: 601.1 | G22: 201.4 | J22: 90.1 | K22: 232.4 | N22: 139.5 | O22: 139.2 | P22: 138.8 | Q22: 235.4 | R22: 113.5 | S22: 66.5 | T22: 562.1 | U22: 10.5 | Z22: 164.6 | AA22: 7.5 | AB22: 3.3 | AD22: 6.6 | AE22: 10.1 | AF22: 88.3 | AG22: 5.9 | AK22: 111 | AL22: 223.9 | AP22: 6.4 | AQ22: 466.4 | AR22: 81.9 | AS22: 148.7 | AT22: 42.2 | AU22: 18.7 | AV22: 19.7 | AW22: 90.7 | AX22: 32.3 | AY22: 0 | BA22: 108.9 | BB22: 0 | BC22: 6.6 | BD22: 46 | BE22: 20.1 | BF22: 0 | BG22: 38 | BH22: 175.4 | BI22: 0 | BL22: 46.9 | BP22: 86.6 | BQ22: 173.7 | BS22: 200 | BT22: 183.2 | CC22: 4.6 | CD22: 85.5 | CE22: 132.6 | CF22: 57.1 | CG22: 76.6 | CH22: 30.2 | CL22: 103.5 | CM22: 104.1 | CN22: 119.6 | CQ22: 0 | CV22: 0 | CW22: 107 | CX22: 0 | CY22: 0 | CZ22: 0 | DA22: 20 | DB22: 9.9 | DC22: 5.3 | DD22: 1.2 | DE22: 3.3 | DF22: 5 | DG22: 20.4 | DH22: 20 | DI22: 19.1 | DJ22: 3.6 | DK22: 9.3 | DL22: 0.4 | DM22: 0.3 | DN22: 20.4 | DO22: 51.9 | DP22: 4.6 | DQ22: 2.4 | DR22: 2.4 | DT22: 0 | DU22: 3.3 | DV22: 5.8 | DW22: 3.1 | DY22: 19.8 | DZ22: 9.7 | EA22: 18.2 | EB22: 20.3 | EC22: 20 | ED22: 30.2 | EE22: 35.1 | EF22: 0 | EG22: 24.7 | EH22: 45.8 | EI22: 4 | EJ22: 0.5 | EK22: 21 | EL22: 6.8 | EM22: 4.9 | EN22: 20.4 | EO22: 20.4 | EP22: 20.2 | EQ22: 0 | ER22: 0 | ES22: 0 | ET22: 0.8 | EU22: 0.6 | EV22: 5.9 | EW22: 13.4 | EX22: 0.6 | EY22: 0 | EZ22: 8.7 | FA22: 20 | FC22: 42.1 | FD22: 31.4 | FE22: 29.3 | FF22: 3.3 | FG22: 16.5 | FJ22: 6671.2 | FL22: 23.1413 | FM22: 0 | FO22: 13.2 | FQ22: 9.43471 | FR22: 10.2 | FS22: 15.4 | FT22: 71.37601
... A58: 23/04/2025 | B58: 00:00 | E58: 62.02 | F58: 640 | G58: 214.7 | J58: 89.8 | K58: 231.1 | N58: 106.4 | O58: 105.3 | P58: 106.6 | Q58: 208.9 | R58: 108.5 | S58: 67.5 | T58: 542.1 | U58: 10.4 | Z58: 166.8 | AA58: 7.1 | AB58: 3.3 | AD58: 6.7 | AE58: 10.1 | AF58: 75.9 | AG58: 4.4 | AK58: 110.4 | AL58: 221.3 | AP58: 6.4 | AQ58: 383 | AR58: 81.8 | AS58: 123.2 | AT58: 42.1 | AU58: 18.5 | AV58: 19.7 | AW58: 86.3 | AX58: 0 | AY58: 0 | BA58: 108.4 | BB58: 7.7 | BC58: 5.9 | BD58: 46.6 | BE58: 11.6 | BF58: 3.8 | BG58: 38.2 | BH58: 172.4 | BI58: 93.2 | BL58: 0 | BP58: 86 | BQ58: 120.2 | BS58: 122.4 | BT58: 143.5 | CC58: 4.6 | CD58: 187.2 | CE58: 111.1 | CF58: 65.5 | CG58: 79.3 | CH58: 30.8 | CL58: 103 | CM58: 103 | CN58: 119.9 | CQ58: 0 | CV58: 0 | CW58: 101.4 | CX58: 0 | CY58: 0 | CZ58: 0 | DA58: 19.8 | DB58: 9.8 | DC58: 5.3 | DD58: 1.2 | DE58: 3.4 | DF58: 4.9 | DG58: 20.3 | DH58: 20 | DI58: 19.1 | DJ58: 3.6 | DK58: 9.3 | DL58: 0 | DM58: 0 | DN58: 28.7 | DO58: 68.3 | DP58: 4.5 | DQ58: 2.4 | DR58: 2.4 | DT58: 0 | DU58: 3.3 | DV58: 20.3 | DW58: 3.1 | DY58: 19.8 | DZ58: 9.6 | EA58: 17.9 | EB58: 20.2 | EC58: 19.9 | ED58: 28.3 | EE58: 40.3 | EF58: 0 | EG58: 80.2 | EH58: 104.5 | EI58: 8.6 | EJ58: 6.4 | EK58: 21 | EL58: 7.9 | EM58: 7.8 | EN58: 20.4 | EO58: 20.4 | EP58: 20.2 | EQ58: 0 | ER58: 0 | ES58: 0 | ET58: 0 | EU58: 0.6 | EV58: 40.6 | EW58: 48.7 | EX58: 0 | EY58: 0 | EZ58: 8.8 | FA58: 19.9 | FC58: 43 | FD58: 32 | FE58: 29 | FF58: 3.2 | FG58: 16.2 | FJ58: 6671.12 | FL58: 23.31108 | FM58: 0 | FO58: 13.2 | FQ58: 9.43556 | FR58: 10.3 | FS58: 15.8 | FT58: 72.04664
A59: EJEC | C59: 0 | D59: 0 | E59: 679.245 | F59: 15029.5 | G59: 5001.4 | H59: 0 | I59: 0 | J59: 2014 | K59: 5564.05 | L59: 0 | M59: 0 | N59: 2795.45 | O59: 2789.75 | P59: 2792.45 | Q59: 5172.1 | R59: 3933.35 | S59: 2188.3 | T59: 13420.95 | U59: 250.45 | V59: 0 | W59: 0 | X59: 0 | Y59: 0 | Z59: 3955.4 | AA59: 177.6 | AB59: 83.4 | AC59: 0 | AD59: 160.6 | AE59: 244.35 | AF59: 2156.8 | AG59: 141.6 | AH59: 0 | AI59: 0 | AJ59: 0 | AK59: 2656.3 | AL59: 4993.45 | AM59: 0 | AN59: 0 | AO59: 0 | AP59: 155.3 | AQ59: 10824.75 | AR59: 1963.7 | AS59: 3392 | AT59: 1011.55 | AU59: 448.05 | AV59: 472.8 | AW59: 2169.55 | AX59: 1681.25 | AY59: 164.85 | AZ59: 0 | BA59: 2603.6 | BB59: 110.3 | BC59: 150.55 | BD59: 1114.45 | BE59: 314.45 | BF59: 49.4 | BG59: 905.9 | BH59: 4176.85 | BI59: 822.85 | BJ59: 0 | BK59: 0 | BL59: 968.4 | BM59: 0 | BN59: 0 | BO59: 0 | BP59: 2071.25 | BQ59: 3586.1 | BR59: 0 | BS59: 4035 | BT59: 3889.4 | BU59: 0 | BV59: 0 | BW59: 0 | BX59: 0 | BY59: 0 | BZ59: 0 | CA59: 0 | CB59: 0 | CC59: 110.4 | CD59: 2947.4 | CE59: 3114.95 | CF59: 1514.35 | CG59: 1900.7 | CH59: 725.65 | CI59: 0 | CJ59: 0 | CK59: 0 | CL59: 2647 | CM59: 2655 | CN59: 2995.7 | CO59: 0 | CP59: 0 | CQ59: 372.85 | CR59: 0 | CS59: 0 | CT59: 0 | CU59: 0 | CV59: 9.05 | CW59: 2367.55 | CX59: 575.8 | CY59: 22.8 | CZ59: 2.1 | DA59: 479.65 | DB59: 237.35 | DC59: 126.65 | DD59: 28.8 | DE59: 79.05 | DF59: 118 | DG59: 486.85 | DH59: 480 | DI59: 458.25 | DJ59: 85.95 | DK59: 222.75 | DL59: 87.25 | DM59: 103.1 | DN59: 552.4 | DO59: 1535.9 | DP59: 108.55 | DQ59: 57.6 | DR59: 50.5 | DS59: 0 | DT59: 133.6 | DU59: 75.5 | DV59: 283.4 | DW59: 74 | DX59: 0 | DY59: 475.3 | DZ59: 225.25 | EA59: 437 | EB59: 486.5 | EC59: 478.45 | ED59: 562.45 | EE59: 1254.4 | EF59: 303.9 | EG59: 1747.4 | EH59: 1985.75 | EI59: 244.55 | EJ59: 136.55 | EK59: 504 | EL59: 187.35 | EM59: 171.5 | EN59: 489.6 | EO59: 489.6 | EP59: 484.8 | EQ59: 20.25 | ER59: 1783.075 | ES59: 105.6 | ET59: 903.15 | EU59: 14.4 | EV59: 1819.45 | EW59: 1981.1 | EX59: 670.5 | EY59: 123.65 | EZ59: 209.1 | FA59: 478.8 | FB59: 0 | FC59: 1020.2 | FD59: 758.7 | FE59: 694.3 | FF59: 77.5 | FG59: 359.3 | FH59: 0 | FI59: 0 | FJ59: 172792.62 | FL59: 559.07709 | FM59: 58.275 | FN59: 0 | FO59: 316.8 | FP59: 0 | FQ59: 205.25288 | FR59: 239.7 | FS59: 376.8 | FT59: 1755.905

Sheet REACTIVA
B3: martes, 22 de Abril del 2025
A5: POTENCIA REACTIVA EJECUTADA DE LAS UNIDADES DE GENERACIÓN DEL COES (MVAR) | FK5: CENTRALES NO INTEGRANTES COES
A6: FECHA | B6: HORA | C6: 337 | D6: 338 | E6: 65333 | F6: 101 | G6: 102 | H6: 42667 | I6: 42668 | J6: 126 | K6: 127 | L6: 138 | M6: 139 | N6: 197 | O6: 203 | P6: 204 | Q6: 230 | R6: 209 | S6: 56677 | T6: 796 | U6: 2146 | V6: 142 | W6: 143 | X6: 125 | Y6: 187 | Z6: 163 | AA6: 298 | AB6: 219 | AC6: 151 | AD6: 152 | AE6: 153 | AF6: 154 | AG6: 756 | AH6: 156 | AI6: 155 | AJ6: 182 | AK6: 212 | AL6: 758 | AM6: 263 | AN6: 265 | AO6: 775 | AP6: 777 | AQ6: 2154 | AR6: 150 | AS6: 149 | AT6: 188 | AU6: 2131 | AV6: 755 | AW6: 252 | AX6: 249 | AY6: 250 | AZ6: 117 | BA6: 267 | BB6: 268 | BC6: 119 | BD6: 120 | BE6: 189 | BF6: 122 | BG6: 266 | BH6: 251 | BI6: 115 | BJ6: 239 | BK6: 288 | BL6: 240 | BM6: 241 | BN6: 242 | BO6: 191 | BP6: 194 | BQ6: 196 | BR6: 207 | BS6: 236 | BT6: 795 | BU6: 285 | BV6: 995 | BW6: 996 | BX6: 997 | BY6: 766 | BZ6: 926 | CA6: 924 | CB6: 121 | CC6: 103 | CD6: 104 | CE6: 106 | CF6: 105 | CG6: 107 | CH6: 110 | CI6: 109 | CJ6: 144 | CK6: 113 | CL6: 114 | CM6: 193 | CN6: 208 | CO6: 786 | CP6: 787 | CQ6: 788 | CR6: 789 | CS6: 248 | CT6: 2159 | CU6: 303 | CV6: 59715 | CW6: 62255 | CX6: 1263 | CY6: 61800 | CZ6: 2194 | DA6: 216 | DB6: 198 | DC6: 49607 | DD6: 214 | DE6: 260 | DF6: 2152 | DG6: 2128 | DH6: 247 | DI6: 228 | DJ6: 2135 | DK6: 261 | DL6: 237 | DM6: 253 | DN6: 770 | DO6: 225 | DP6: 2201 | DQ6: 2171 | DR6: 760 | DS6: 235 | DT6: 238 | DU6: 2184 | DV6: 61855 | DW6: 223 | DX6: 226 | DY6: 201 | DZ6: 258 | EA6: 259 | EB6: 920 | EC6: 257 | ED6: 256 | EE6: 2148 | EF6: 58288 | EG6: 58289 | EH6: 58839 | EI6: 58840 | EJ6: 296 | EK6: 297 | EL6: 211 | EM6: 2175 | EN6: 2178 | EO6: 2181 | EP6: 1262 | EQ6: 63425 | ER6: 233 | ES6: 2150 | ET6: 2165 | EU6: 2161 | EV6: 61197 | EW6: 58851 | EX6: 234 | EY6: 215 | EZ6: 917 | FA6: 289 | FB6: 58333 | FC6: 58336 | FD6: 202 | FE6: 58487 | FF6: 213 | FG6: 232 | FH6: 2190 | FI6: TOTAL COES | FK6: 221 | FL6: 222 | FM6: 224 | FN6: 2187 | FO6: 227 | FP6: 49400 | FQ6: 199 | FR6: 200 | FS6: TOTAL NO COES
C7: CENTRO | D7: CENTRO | E7: SUR | F7: CENTRO | G7: CENTRO | H7: NORTE | I7: NORTE | J7: NORTE | K7: NORTE | L7: CENTRO | M7: CENTRO | N7: CENTRO | O7: CENTRO | P7: CENTRO | Q7: CENTRO | R7: CENTRO | S7: CENTRO | T7: CENTRO | U7: CENTRO | V7: CENTRO | W7: CENTRO | X7: CENTRO | Y7: CENTRO | Z7: SUR | AA7: SUR | AB7: CENTRO | AC7: SUR | AD7: SUR | AE7: SUR | AF7: SUR | AG7: SUR | AH7: SUR | AI7: SUR | AJ7: SUR | AK7: CENTRO | AL7: NORTE | AM7: NORTE | AN7: NORTE | AO7: CENTRO | AP7: CENTRO | AQ7: CENTRO | AR7: CENTRO | AS7: CENTRO | AT7: CENTRO | AU7: CENTRO | AV7: SUR | AW7: CENTRO | AX7: CENTRO | AY7: CENTRO | AZ7: CENTRO | BA7: CENTRO | BB7: CENTRO | BC7: CENTRO | BD7: CENTRO | BE7: SUR | BF7: NORTE | BG7: CENTRO | BH7: CENTRO | BI7: NORTE | BJ7: NORTE | BK7: NORTE | BL7: SUR | BM7: SUR | BN7: SUR | BO7: CENTRO | BP7: CENTRO | BQ7: CENTRO | BR7: CENTRO | BS7: CENTRO | BT7: CENTRO | BU7: CENTRO | BV7: SUR | BW7: SUR | BX7: SUR | BY7: NORTE | BZ7: SUR | CA7: CENTRO | CB7: NORTE | CC7: CENTRO | CD7: CENTRO | CE7: CENTRO | CF7: CENTRO | CG7: CENTRO | CH7: CENTRO | CI7: CENTRO | CJ7: CENTRO | CK7: CENTRO | CL7: CENTRO | CM7: CENTRO | CN7: CENTRO | CO7: SUR | CP7: SUR | CQ7: SUR | CR7: SUR | CS7: CENTRO | CT7: CENTRO | CU7: CENTRO | CV7: CENTRO | CW7: SUR | CX7: NORTE | CY7: NORTE | CZ7: NORTE | DA7: NORTE | DB7: NORTE | DC7: SUR | DD7: CENTRO | DE7: CENTRO | DF7: CENTRO | DG7: NORTE | DH7: NORTE | DI7: CENTRO | DJ7: CENTRO | DK7: SUR | DL7: SUR | DM7: CENTRO | DN7: CENTRO | DO7: CENTRO | DP7: CENTRO | DQ7: CENTRO | DR7: CENTRO | DS7: SUR | DT7: CENTRO | DU7: CENTRO | DV7: NORTE | DW7: CENTRO | DX7: CENTRO | DY7: NORTE | DZ7: CENTRO | EA7: CENTRO | EB7: CENTRO | EC7: NORTE | ED7: NORTE | EE7: SUR | EF7: CENTRO | EG7: CENTRO | EH7: CENTRO | EI7: CENTRO | EJ7: CENTRO | EK7: CENTRO | EL7: SUR | EM7: SUR | EN7: SUR | EO7: SUR | EP7: NORTE | EQ7: SUR | ER7: SUR | ES7: SUR | ET7: CENTRO | EU7: CENTRO | EV7: CENTRO | EW7: SUR | EX7: SUR | EY7: NORTE | EZ7: CENTRO | FA7: NORTE | FB7: NORTE | FC7: NORTE | FD7: CENTRO | FE7: CENTRO | FF7: CENTRO | FG7: NORTE | FH7: NORTE | FK7: NORTE | FL7: CENTRO | FM7: NORTE | FN7: NORTE | FO7: NORTE | FP7: NORTE | FQ7: NORTE | FR7: NORTE
C8: HIDROELÉCTRICA | D8: HIDROELÉCTRICA | E8: HIDROELÉCTRICA | F8: HIDROELÉCTRICA | G8: HIDROELÉCTRICA | H8: TERMOELÉCTRICA | I8: TERMOELÉCTRICA | J8: HIDROELÉCTRICA | K8: HIDROELÉCTRICA | L8: TERMOELÉCTRICA | M8: TERMOELÉCTRICA | N8: TERMOELÉCTRICA | O8: TERMOELÉCTRICA | P8: TERMOELÉCTRICA | Q8: TERMOELÉCTRICA | R8: TERMOELÉCTRICA | S8: TERMOELÉCTRICA | T8: HIDROELÉCTRICA | U8: HIDROELÉCTRICA | V8: TERMOELÉCTRICA | W8: TERMOELÉCTRICA | X8: TERMOELÉCTRICA | Y8: TERMOELÉCTRICA | Z8: HIDROELÉCTRICA | AA8: HIDROELÉCTRICA | AB8: TERMOELÉCTRICA | AC8: HIDROELÉCTRICA | AD8: HIDROELÉCTRICA | AE8: HIDROELÉCTRICA | AF8: HIDROELÉCTRICA | AG8: TERMOELÉCTRICA | AH8: TERMOELÉCTRICA | AI8: TERMOELÉCTRICA | AJ8: HIDROELÉCTRICA | AK8: HIDROELÉCTRICA | AL8: TERMOELÉCTRICA | AM8: TERMOELÉCTRICA | AN8: TERMOELÉCTRICA | AO8: HIDROELÉCTRICA | AP8: HIDROELÉCTRICA | AQ8: HIDROELÉCTRICA | AR8: HIDROELÉCTRICA | AS8: HIDROELÉCTRICA | AT8: HIDROELÉCTRICA | AU8: HIDROELÉCTRICA | AV8: HIDROELÉCTRICA | AW8: TERMOELÉCTRICA | AX8: TERMOELÉCTRICA | AY8: TERMOELÉCTRICA | AZ8: HIDROELÉCTRICA | BA8: HIDROELÉCTRICA | BB8: HIDROELÉCTRICA | BC8: HIDROELÉCTRICA | BD8: HIDROELÉCTRICA | BE8: HIDROELÉCTRICA | BF8: HIDROELÉCTRICA | BG8: HIDROELÉCTRICA | BH8: HIDROELÉCTRICA | BI8: TERMOELÉCTRICA | BJ8: TERMOELÉCTRICA | BK8: TERMOELÉCTRICA | BL8: TERMOELÉCTRICA | BM8: TERMOELÉCTRICA | BN8: TERMOELÉCTRICA | BO8: HIDROELÉCTRICA | BP8: TERMOELÉCTRICA | BQ8: TERMOELÉCTRICA | BR8: TERMOELÉCTRICA | BS8: TERMOELÉCTRICA | BT8: TERMOELÉCTRICA | BU8: TERMOELÉCTRICA | BV8: TERMOELÉCTRICA | BW8: TERMOELÉCTRICA | BX8: TERMOELÉCTRICA | BY8: HIDROELÉCTRICA | BZ8: TERMOELÉCTRICA | CA8: TERMOELÉCTRICA | CB8: HIDROELÉCTRICA | CC8: HIDROELÉCTRICA | CD8: HIDROELÉCTRICA | CE8: HIDROELÉCTRICA | CF8: HIDROELÉCTRICA | CG8: HIDROELÉCTRICA | CH8: TERMOELÉCTRICA | CI8: TERMOELÉCTRICA | CJ8: TERMOELÉCTRICA | CK8: TERMOELÉCTRICA | CL8: TERMOELÉCTRICA | CM8: TERMOELÉCTRICA | CN8: TERMOELÉCTRICA | CO8: TERMOELÉCTRICA | CP8: TERMOELÉCTRICA | CQ8: TERMOELÉCTRICA | CR8: TERMOELÉCTRICA | CS8: TERMOELÉCTRICA | CT8: TERMOELÉCTRICA | CU8: SOLAR | CV8: EÓLICA | CW8: SOLAR | CX8: EÓLICA | CY8: SOLAR | CZ8: HIDROELÉCTRICA | DA8: HIDROELÉCTRICA | DB8: HIDROELÉCTRICA | DC8: HIDROELÉCTRICA | DD8: HIDROELÉCTRICA | DE8: HIDROELÉCTRICA | DF8: HIDROELÉCTRICA | DG8: HIDROELÉCTRICA | DH8: HIDROELÉCTRICA | DI8: HIDROELÉCTRICA | DJ8: HIDROELÉCTRICA | DK8: SOLAR | DL8: SOLAR | DM8: EÓLICA | DN8: EÓLICA | DO8: TERMOELÉCTRICA | DP8: TERMOELÉCTRICA | DQ8: TERMOELÉCTRICA | DR8: TERMOELÉCTRICA | DS8: SOLAR | DT8: HIDROELÉCTRICA | DU8: HIDROELÉCTRICA | DV8: HIDROELÉCTRICA | DW8: HIDROELÉCTRICA | DX8: HIDROELÉCTRICA | DY8: HIDROELÉCTRICA | DZ8: HIDROELÉCTRICA | EA8: HIDROELÉCTRICA | EB8: HIDROELÉCTRICA | EC8: EÓLICA | ED8: EÓLICA | EE8: SOLAR | EF8: EÓLICA | EG8: EÓLICA | EH8: EÓLICA | EI8: EÓLICA | EJ8: HIDROELÉCTRICA | EK8: HIDROELÉCTRICA | EL8: HIDROELÉCTRICA | EM8: HIDROELÉCTRICA | EN8: HIDROELÉCTRICA | EO8: HIDROELÉCTRICA | EP8: EÓLICA | EQ8: SOLAR | ER8: SOLAR | ES8: SOLAR | ET8: HIDROELÉCTRICA | EU8: EÓLICA | EV8: EÓLICA | EW8: SOLAR | EX8: SOLAR | EY8: HIDROELÉCTRICA | EZ8: HIDROELÉCTRICA | FA8: TERMOELÉCTRICA | FB8: TERMOELÉCTRICA | FC8: TERMOELÉCTRICA | FD8: TERMOELÉCTRICA | FE8: TERMOELÉCTRICA | FF8: TERMOELÉCTRICA | FG8: TERMOELÉCTRICA | FH8: TERMOELÉCTRICA | FK8: HIDROELÉCTRICA | FL8: HIDROELÉCTRICA | FM8: HIDROELÉCTRICA | FN8: HIDROELÉCTRICA | FO8: TERMOELÉCTRICA | FP8: TERMOELÉCTRICA | FQ8: HIDROELÉCTRICA | FR8: HIDROELÉCTRICA
