Workbook

Sheet EVENTOS
B3: miércoles, 15 de Enero del 2025
B5: INFORMACIÓN DE EVENTOS PRINCIPALES EN SUS INSTALACIONES
B6: TIPO DE EVENTO | C6: EMPRESA | D6: UBICACIÓN | E6: TIPO DE EQUIPO | F6: EQUIPO | G6: INICIO | H6: FINAL | I6: DESCRIPCIÓN | J6: MW INDISP. | K6: INTERRUPCIÓN (SI/NO) | L6: TENSIÓN DE FALLA (kV)
B7: FALLA | C7: CONCESIONARIA LINEA DE TRANSMISION CCNCM S.A.C. | D7: CAJAMARCA NORTE - CACLIC | E7: LINEA DE TRANSMISION | F7: L-2192 | G7: 15/01/2025 13:57:00 | H7: 15/01/2025 13:57:00 | I7: RECIERRE EXITOSO EN LA LÍNEA L-2192 (CAJAMARCA NORTE - CÁCLIC) DE 220 kV | K7: NO | L7: 220
B8: EVENTO | C8: CONELSUR LT SAC | D8: PORTILLO | E8: SUBESTACION | F8: SS.EE. | G8: 15/01/2025 00:00:00 | H8: 16/01/2025 00:00:00 | I8: DECLARACIÓN DE SITUACIÓN EXCEPCIONAL EN LA S.E. PORTILLO DE 60 kV | K8: NO
B9: FALLA | C9: EMPRESA DE GENERACION ELECTRICA SANTA ANA S.A.C. | D9: Derv. PUNTAYACU - LA VIRGEN | E9: LINEA DE TRANSMISION | F9: L-6089 | G9: 15/01/2025 12:54:00 | H9: 15/01/2025 13:02:00 | I9: DESCONEXIÓN DE LA LÍNEA L-6089 (CHANCHAMAYO -PUNTAYACU- LA VIRGEN) DE 60 kV | J9: 5.81 | K9: SI | L9: 138
B10: FALLA | C10: LUZ DEL SUR | D10: PORTILLO-ÑAÑA | E10: LINEA DE TRANSMISION | F10: L-6577 | G10: 15/01/2025 17:13:09 | H10: 15/01/2025 20:47:09 | I10: DESCONEXIÓN DE LA LÍNEA L-6577 (PORTILLO - NAÑA) 60KV | K10: NO | L10: 60
B11: FALLA | C11: RED DE ENERGIA DEL PERU S.A. | D11: AMARILIS - PARAGSHA II | E11: LINEA DE TRANSMISION | F11: L-1120 | G11: 15/01/2025 18:42:25 | H11: 15/01/2025 18:42:25 | I11: RECIERRE EXITOSO EN LA LÍNEA L-1120 ( AMARILIS - PARAGSHA II) 138 KV | K11: NO | L11: 138
B12: EVENTO | C12: RED DE ENERGIA DEL PERU S.A. | D12: TINGO MARÍA - AUCAYACU | E12: LINEA DE TRANSMISION | F12: L-1122 | G12: 15/01/2025 19:03:00 | H12: 15/01/2025 20:08:00 | I12: DECLARACIÓN DE SITUACIÓN EXCEPCIONAL EN LA LÍNEA L-1122 (TINGO MARÍA - AUCAYACU) DE 138 KV | K12: NO
B13: FALLA | C13: RED DE ENERGIA DEL PERU S.A. | D13: CHICLAYO OESTE | E13: SVC | F13: SVC-2 | G13: 15/01/2025 04:09:08 | H13: 15/01/2025 06:21:00 | I13: DESCONEXIÓN DEL SVC-2 DE LA S.E. CHICLAYO OESTE | K13: NO | L13: 0
B14: FALLA | C14: STATKRAFT S.A | D14: HUARÓN - EXCELSIOR | E14: LINEA DE TRANSMISION | F14: L-6516 | G14: 15/01/2025 09:29:12 | H14: 15/01/2025 15:30:00 | I14: DESCONEXIÓN DE LA LÍNEA L-6516 (CARHUAMAYO - EXCELSIOR) DE 50 kV | K14: NO | L14: 50

Sheet RESTRIC_OPE
B3: miércoles, 15 de Enero del 2025
B5: RESTRICCIONES OPERATIVAS
B6: FECHA | C6: HORA INICIO | D6: HORA FINAL | E6: EMPRESA | F6: UBICACIÓN | G6: T.Eq. | H6: EQUIPO | I6: DESCRIPCIÓN
B7: 15/01/2025 | C7: 00:00 | D7: 24:00 | E7: CELEPSA | F7: C.H. EL PLATANAL | G7: CH | H7: CENTRAL | I7: Debido al incremento del caudal del rio cañete y establecimiento de la temporada de avenida, se declara la C.H. El Platanal como CENTRAL HIDRÁULICA DE PASADA (correo 03/01/2025).
B8: 15/01/2025 | C8: 00:00 | D8: 24:00 | E8: CHINANGO S.A.C. | F8: C.H. CHIMAY | G8: GH | H8: G2 | I8: De acuerdo con el correo enviado el 27/12/2024 el grupo G2 de CH Chimay está habilitada con un límite de oferta de 72 MW.
B9: 15/01/2025 | C9: 00:00 | D9: 24:00 | E9: EGASA | F9: S.E. CONVERTIDOR | G9: BARRA | H9: BARRA138KV | I9: EGASA limitó la capacidad del transformador 138 kV/33 kV a 50 MVA por deterioro del aislamiento.
B10: 15/01/2025 | C10: 00:00 | D10: 24:00 | E10: ENEL GENERACION PIURA S.A. | F10: C.T. MALACAS | G10: CT | H10: CENTRAL | I10: De acuerdo con la comunicación vía correo del día 24.10.2024. ENEL GENERACIÓN PIURA informa una restricción de potencia para alcanzar 105 MW en simultaneo (TG6+TGN4).
B11: 15/01/2025 | C11: 00:00 | D11: 24:00 | E11: ENGIE | F11: C.E. PUNTA LOMITAS | G11: CE | H11: CENTRAL | I11: De acuerdo a la carta ENG/737-2024 (Exp:202400007555). Limitación de cables de media tensión a 100 MW de los transformadores PLT1 y PLT2 de la CE Punta Lomitas. Quedan limitados a 200 MW la generación de CE Punta Lomitas y Punta Lomitas Extensión.
B12: 15/01/2025 | C12: 00:00 | D12: 24:00 | E12: ENGIE | F12: C.H. QUITARACSA | G12: CH | H12: CENTRAL | I12: De acuerdo con el correo del 23.04 se considera la operación continua de la CH Quitaracsa debido a que el sistema de refrigeración de la CH Cañón del Pato se alimenta desde la descarga del caudal turbinado por la CH Quitaracsa.
B13: 15/01/2025 | C13: 00:00 | D13: 24:00 | E13: ENGIE | F13: C.H. YUNCÁN | G13: GH | H13: G3 | I13: Según la carta N° ENG/ 198-2024 enviada por su representada, se opera de forma continua el G3 de la CH Yuncán, debido a la ejecución de mantenimientos necesarios para evitar daños en los sellos de seguridad de la válvula esférica del grupo.
B14: 15/01/2025 | C14: 00:00 | D14: 24:00 | E14: ENGIE | F14: C.T. CHILCA 1 | G14: CT | H14: CENTRAL | I14: Restricción de temperatura de la C.T Chilca, ver valor en el modelo de despacho.
B15: 15/01/2025 | C15: 00:00 | D15: 24:00 | E15: ENGIE | F15: C.T. CHILCA 1 | G15: CT | H15: CENTRAL | I15: De acuerdo con el correo del 05/03 la CT Chilca 1 se encuentra indisponible para dar RSF.
B16: 15/01/2025 | C16: 00:00 | D16: 24:00 | E16: ENGIE | F16: C.T. CHILCA 1 | G16: CT | H16: CENTRAL | I16: Con carta ENG/971-2023, indica que no puede cumplir con las IO considerada en el PDO_17122023 dado que vulneran la seguridad de sus activos. Indican que se debe tomar TMO=168h.
B17: 15/01/2025 | C17: 00:00 | D17: 24:00 | E17: ENGIE | F17: C.T. CHILCA 2 | G17: CT | H17: CENTRAL | I17: Restricción de temperatura de la C.T Chilca2, ver valor en el modelo de despacho.
... B38: 15/01/2025 | C38: 00:00 | D38: 24:00 | E38: TRANSMANTARO | F38: S.E. SOCABAYA | G38: SSEE | H38: S.E. | I38: Opera en simple barra en 220 kV por indisponibilidad de la protección diferencial de barras por alarma.

Sheet MANTENIMIENTO EJECUTADOS
B3: miércoles, 15 de Enero del 2025
B5: Mantenimiento Ejecutado
B6: Empresa | C6: Ubicación | D6: Equipo | E6: Inicio | F6: Final | G6: Descripción | H6: MW Indisp. | I6: Prog. | J6: Dispon | K6: Interrupc. | L6: Tipo | M6: CodEq | N6: TipoEq_Osinerg
B7: ATLANTICA TRANSMISION SUR S.A. | C7: CHILCA-CTM | D7: INT-5261 | E7: 15/01/2025 00:00 | F7: 16/01/2025 00:00 | G7: Seccionador SBB-5261 fase S indisponible para maniobras de apertura y cierre por anomalia en tapa de tanque de compresion, el seccionador permanece cerrado y bloqueado. | H7: 0 | I7: P | J7: E/S | K7: N | L7: OTROS | M7: 13854 | N7: T
B8: ATLANTICA TRANSMISION SUR S.A. | C8: OCONA | D8: INT-5450 | E8: 15/01/2025 00:00 | F8: 16/01/2025 00:00 | G8: RESTRICCION OPERATIVA EN INTERRUPTOR INT-5450, POSICION CERRADA, REB-5450 EN SERVICIO SUMINISTRANDO LOS SS.AA. DE S.E. OCO?A | H8: 0 | I8: P | J8: E/S | K8: N | L8: OTROS | M8: 13761 | N8: T
B9: ATLANTICA TRANSMISION SUR S.A. | C9: OCONA | D9: INT-5462 | E9: 15/01/2025 00:00 | F9: 16/01/2025 00:00 | G9: Seccionador SBA-5462 fase T indisponible por problemas mecanicos, el seccionador permanece cerrado y bloqueado | H9: 0 | I9: P | J9: E/S | K9: N | L9: OTROS | M9: 13758 | N9: T
B10: ATLANTICA TRANSMISION SUR S.A. | C10: POROMA | D10: INT-5361 | E10: 15/01/2025 00:00 | F10: 16/01/2025 00:00 | G10: Seccionador SBA-5361 fase R indisponible por problemas mecanicos, el seccionador permanece cerrado y bloqueado | H10: 0 | I10: P | J10: E/S | K10: N | L10: OTROS | M10: 13746 | N10: T
B11: ATLANTICA TRANSMISION SUR S.A. | C11: POROMA | D11: REB-5350 | E11: 15/01/2025 00:00 | F11: 16/01/2025 00:00 | G11: FUERA DE SERVICIO POR FALLA EN EL EQUIPO. | H11: 0 | I11: P | J11: F/S | K11: N | L11: OTROS | M11: 13771 | N11: T
B12: ATRIA ENERGIA S.A.C. | C12: PURMACANA | D12: G1 | E12: 15/01/2025 00:00 | F12: 16/01/2025 00:00 | G12: OVERHAUL DE TURBINA | H12: 0.7 | I12: P | J12: F/S | K12: N | L12: PREV. | M12: 13133 | N12: G
B13: CONELSUR LT SAC | C13: CAJAMARQUILLA | D13: BARRA B 220kV | E13: 15/01/2025 00:00 | F13: 16/01/2025 00:00 | G13: CIERRE DE ACOPLE PARA ENERGIZAR LA BARRA B POR SEGURIDAD POR MANTENIMIENTO ANTICORROSIVO DE PORTICOS Y ESTRUCTURAS EN CL-2014, CL-2015 Y CL-TR1 | H13: 0 | I13: P | J13: E/S | K13: N | L13: SEG.PER | M13: 1104 | N13: T
B14: CONELSUR LT SAC | C14: CAJAMARQUILLA | D14: CL-2015 | E14: 15/01/2025 00:00 | F14: 15/01/2025 07:30 | G14: POR SEGURIDAD POR MANTENIMIENTO ANTICORROSIVO DE PORTICOS Y ESTRUCTURAS. SE REQUIERE AMBOS SECCIONADORES DE BARRA CERRADOS POR SEGURIDAD. | H14: 0 | I14: P | J14: E/S | K14: N | L14: SEG.PER | M14: 1535 | N14: T
B15: CONELSUR LT SAC | C15: CAJAMARQUILLA | D15: BARRA B 220kV | E15: 15/01/2025 05:07 | F15: 15/01/2025 07:35 | G15: CORONOGRAFIA DE EQUIPOS DE CONELSUR. SE REQUIERE LA BARRA B ENERGIZADO | H15: 0 | I15: P | J15: E/S | K15: N | L15: PREV. | M15: 1104 | N15: T
B16: CONELSUR LT SAC | C16: CAJAMARQUILLA | D16: CL-TRAFO | E16: 15/01/2025 07:35 | F16: 16/01/2025 00:00 | G16: POR SEGURIDAD POR MANTENIMIENTO ANTICORROSIVO DE PORTICOS Y ESTRUCTURAS. SE REQUIERE AMBOS SECCIONADORES DE BARRA CERRADOS POR SEGURIDAD. | H16: 0 | I16: P | J16: E/S | K16: N | L16: SEG.PER | M16: 1906 | N16: T
B17: CONELSUR LT SAC | C17: CALLALLI | D17: CL-1040 | E17: 15/01/2025 09:48 | F17: 15/01/2025 13:11 | G17: LEVANTAMIENTO DE INFORMACION, REVISION Y RETIRO DEL REGISTRADOR DE FALLAS DE LA CELDA CL-1040 DE LA S.E. CALLALLI. | H17: 0 | I17: P | J17: E/S | K17: N | L17: CORR. | M17: 12786 | N17: T
B18: CONELSUR LT SAC | C18: LOMERA | D18: BARRA A 220 kV | E18: 15/01/2025 00:00 | F18: 16/01/2025 00:00 | G18: POR REEMPLAZO DE COMPONENTES Y GAS SF6 EN CL2117. LOMERA OPERA EN BARRA SIMPLE | H18: 0 | I18: P | J18: F/S | K18: N | L18: OTROS | M18: 16951 | N18: T
... B91: TRANSMANTARO | C91: YARABAMBA | D91: IN-5120 | E91: 15/01/2025 00:00 | F91: 16/01/2025 00:00 | G91: INSTALACION DE CAPACITORES EN INTERRUPTOR IN-5120, ACTIVIDAD CON CORTE CONTINUO. (EL REACTOR R-31 DISPONIBLE PARA LA OPERACION CON MANDO SINCRONIZADO MEDIANTE EL INTERRUPTOR IN-5116). (R0097959) | H91: 0 | I91: P | J91: F/S | K91: N | L91: PREV. | M91: 17437 | N91: T

Sheet INGRESO OC
A3: miércoles, 15 de Enero del 2025
A5: INGRESO A OPERACIÓN COMERCIAL
A6: EMPRESA | B6: TIPO DE EQUIPO | C6: UBICACIÓN | D6: EQUIPO | E6: Fecha y hora de Ingreso a Operación Comercial

Sheet DESPACHO_EJECUTADO
B3: miércoles, 15 de Enero del 2025
A5: POTENCIA ACTIVA EJECUTADA DE LAS UNIDADES DE GENERACIÓN DEL SEIN (MW) | FH5: CENTRALES NO INTEGRANTES COES
A6: FECHA | B6: HORA | C6: 337 | D6: 338 | E6: 121 | F6: 101 | G6: 102 | H6: 42667 | I6: 42668 | J6: 126 | K6: 127 | L6: 138 | M6: 139 | N6: 197 | O6: 203 | P6: 204 | Q6: 230 | R6: 209 | S6: 56677 | T6: 796 | U6: 2146 | V6: 142 | W6: 143 | X6: 125 | Y6: 187 | Z6: 163 | AA6: 298 | AB6: 219 | AC6: 151 | AD6: 152 | AE6: 153 | AF6: 154 | AG6: 756 | AH6: 156 | AI6: 155 | AJ6: 182 | AK6: 212 | AL6: 758 | AM6: 263 | AN6: 265 | AO6: 775 | AP6: 777 | AQ6: 2154 | AR6: 150 | AS6: 149 | AT6: 188 | AU6: 2131 | AV6: 755 | AW6: 252 | AX6: 249 | AY6: 250 | AZ6: 117 | BA6: 267 | BB6: 268 | BC6: 119 | BD6: 120 | BE6: 189 | BF6: 122 | BG6: 266 | BH6: 251 | BI6: 115 | BJ6: 239 | BK6: 288 | BL6: 240 | BM6: 241 | BN6: 242 | BO6: 191 | BP6: 194 | BQ6: 196 | BR6: 207 | BS6: 236 | BT6: 795 | BU6: 285 | BV6: 995 | BW6: 996 | BX6: 997 | BY6: 766 | BZ6: 926 | CA6: 924 | CB6: 103 | CC6: 104 | CD6: 106 | CE6: 105 | CF6: 107 | CG6: 110 | CH6: 109 | CI6: 144 | CJ6: 113 | CK6: 114 | CL6: 193 | CM6: 208 | CN6: 786 | CO6: 787 | CP6: 788 | CQ6: 789 | CR6: 248 | CS6: 2159 | CT6: 303 | CU6: 59715 | CV6: 62255 | CW6: 1263 | CX6: 61800 | CY6: 2194 | CZ6: 216 | DA6: 198 | DB6: 214 | DC6: 260 | DD6: 2152 | DE6: 2128 | DF6: 247 | DG6: 228 | DH6: 2135 | DI6: 261 | DJ6: 237 | DK6: 253 | DL6: 770 | DM6: 225 | DN6: 2201 | DO6: 2171 | DP6: 760 | DQ6: 235 | DR6: 238 | DS6: 2184 | DT6: 61855 | DU6: 223 | DV6: 226 | DW6: 201 | DX6: 258 | DY6: 259 | DZ6: 920 | EA6: 257 | EB6: 256 | EC6: 2148 | ED6: 58288 | EE6: 58289 | EF6: 58839 | EG6: 58840 | EH6: 296 | EI6: 297 | EJ6: 211 | EK6: 2175 | EL6: 2178 | EM6: 2181 | EN6: 1262 | EO6: 233 | EP6: 2150 | EQ6: 2165 | ER6: 2161 | ES6: 61197 | ET6: 58851 | EU6: 234 | EV6: 215 | EW6: 917 | EX6: 289 | EY6: 58333 | EZ6: 58336 | FA6: 202 | FB6: 58487 | FC6: 213 | FD6: 232 | FE6: 2190 | FF6: TOTAL COES | FH6: 221 | FI6: 49607 | FJ6: 222 | FK6: 224 | FL6: 2187 | FM6: 227 | FN6: 49400 | FO6: 199 | FP6: 200 | FQ6: TOTAL NO COES
C7: CENTRO | D7: CENTRO | E7: NORTE | F7: CENTRO | G7: CENTRO | H7: NORTE | I7: NORTE | J7: NORTE | K7: NORTE | L7: CENTRO | M7: CENTRO | N7: CENTRO | O7: CENTRO | P7: CENTRO | Q7: CENTRO | R7: CENTRO | S7: CENTRO | T7: CENTRO | U7: CENTRO | V7: CENTRO | W7: CENTRO | X7: CENTRO | Y7: CENTRO | Z7: SUR | AA7: SUR | AB7: CENTRO | AC7: SUR | AD7: SUR | AE7: SUR | AF7: SUR | AG7: SUR | AH7: SUR | AI7: SUR | AJ7: SUR | AK7: CENTRO | AL7: NORTE | AM7: NORTE | AN7: NORTE | AO7: CENTRO | AP7: CENTRO | AQ7: CENTRO | AR7: CENTRO | AS7: CENTRO | AT7: CENTRO | AU7: CENTRO | AV7: SUR | AW7: CENTRO | AX7: CENTRO | AY7: CENTRO | AZ7: CENTRO | BA7: CENTRO | BB7: CENTRO | BC7: CENTRO | BD7: CENTRO | BE7: SUR | BF7: NORTE | BG7: CENTRO | BH7: CENTRO | BI7: NORTE | BJ7: NORTE | BK7: NORTE | BL7: SUR | BM7: SUR | BN7: SUR | BO7: CENTRO | BP7: CENTRO | BQ7: CENTRO | BR7: CENTRO | BS7: CENTRO | BT7: CENTRO | BU7: CENTRO | BV7: SUR | BW7: SUR | BX7: SUR | BY7: NORTE | BZ7: SUR | CA7: CENTRO | CB7: CENTRO | CC7: CENTRO | CD7: CENTRO | CE7: CENTRO | CF7: CENTRO | CG7: CENTRO | CH7: CENTRO | CI7: CENTRO | CJ7: CENTRO | CK7: CENTRO | CL7: CENTRO | CM7: CENTRO | CN7: SUR | CO7: SUR | CP7: SUR | CQ7: SUR | CR7: CENTRO | CS7: CENTRO | CT7: CENTRO | CU7: CENTRO | CV7: SUR | CW7: NORTE | CX7: NORTE | CY7: NORTE | CZ7: NORTE | DA7: NORTE | DB7: CENTRO | DC7: CENTRO | DD7: CENTRO | DE7: NORTE | DF7: NORTE | DG7: CENTRO | DH7: CENTRO | DI7: SUR | DJ7: SUR | DK7: CENTRO | DL7: CENTRO | DM7: CENTRO | DN7: CENTRO | DO7: CENTRO | DP7: CENTRO | DQ7: SUR | DR7: CENTRO | DS7: CENTRO | DT7: NORTE | DU7: CENTRO | DV7: CENTRO | DW7: NORTE | DX7: CENTRO | DY7: CENTRO | DZ7: CENTRO | EA7: NORTE | EB7: NORTE | EC7: SUR | ED7: CENTRO | EE7: CENTRO | EF7: CENTRO | EG7: CENTRO | EH7: CENTRO | EI7: CENTRO | EJ7: SUR | EK7: SUR | EL7: SUR | EM7: SUR | EN7: NORTE | EO7: SUR | EP7: SUR | EQ7: CENTRO | ER7: CENTRO | ES7: CENTRO | ET7: SUR | EU7: SUR | EV7: NORTE | EW7: CENTRO | EX7: NORTE | EY7: NORTE | EZ7: NORTE | FA7: CENTRO | FB7: CENTRO | FC7: CENTRO | FD7: NORTE | FE7: NORTE | FH7: NORTE | FI7: SUR | FJ7: CENTRO | FK7: NORTE | FL7: NORTE | FM7: NORTE | FN7: NORTE | FO7: NORTE | FP7: NORTE
C8: HIDROELÉCTRICA | D8: HIDROELÉCTRICA | E8: HIDROELÉCTRICA | F8: HIDROELÉCTRICA | G8: HIDROELÉCTRICA | H8: TERMOELÉCTRICA | I8: TERMOELÉCTRICA | J8: HIDROELÉCTRICA | K8: HIDROELÉCTRICA | L8: TERMOELÉCTRICA | M8: TERMOELÉCTRICA | N8: TERMOELÉCTRICA | O8: TERMOELÉCTRICA | P8: TERMOELÉCTRICA | Q8: TERMOELÉCTRICA | R8: TERMOELÉCTRICA | S8: TERMOELÉCTRICA | T8: HIDROELÉCTRICA | U8: HIDROELÉCTRICA | V8: TERMOELÉCTRICA | W8: TERMOELÉCTRICA | X8: TERMOELÉCTRICA | Y8: TERMOELÉCTRICA | Z8: HIDROELÉCTRICA | AA8: HIDROELÉCTRICA | AB8: TERMOELÉCTRICA | AC8: HIDROELÉCTRICA | AD8: HIDROELÉCTRICA | AE8: HIDROELÉCTRICA | AF8: HIDROELÉCTRICA | AG8: TERMOELÉCTRICA | AH8: TERMOELÉCTRICA | AI8: TERMOELÉCTRICA | AJ8: HIDROELÉCTRICA | AK8: HIDROELÉCTRICA | AL8: TERMOELÉCTRICA | AM8: TERMOELÉCTRICA | AN8: TERMOELÉCTRICA | AO8: HIDROELÉCTRICA | AP8: HIDROELÉCTRICA | AQ8: HIDROELÉCTRICA | AR8: HIDROELÉCTRICA | AS8: HIDROELÉCTRICA | AT8: HIDROELÉCTRICA | AU8: HIDROELÉCTRICA | AV8: HIDROELÉCTRICA | AW8: TERMOELÉCTRICA | AX8: TERMOELÉCTRICA | AY8: TERMOELÉCTRICA | AZ8: HIDROELÉCTRICA | BA8: HIDROELÉCTRICA | BB8: HIDROELÉCTRICA | BC8: HIDROELÉCTRICA | BD8: HIDROELÉCTRICA | BE8: HIDROELÉCTRICA | BF8: HIDROELÉCTRICA | BG8: HIDROELÉCTRICA | BH8: HIDROELÉCTRICA | BI8: TERMOELÉCTRICA | BJ8: TERMOELÉCTRICA | BK8: TERMOELÉCTRICA | BL8: TERMOELÉCTRICA | BM8: TERMOELÉCTRICA | BN8: TERMOELÉCTRICA | BO8: HIDROELÉCTRICA | BP8: TERMOELÉCTRICA | BQ8: TERMOELÉCTRICA | BR8: TERMOELÉCTRICA | BS8: TERMOELÉCTRICA | BT8: TERMOELÉCTRICA | BU8: TERMOELÉCTRICA | BV8: TERMOELÉCTRICA | BW8: TERMOELÉCTRICA | BX8: TERMOELÉCTRICA | BY8: HIDROELÉCTRICA | BZ8: TERMOELÉCTRICA | CA8: TERMOELÉCTRICA | CB8: HIDROELÉCTRICA | CC8: HIDROELÉCTRICA | CD8: HIDROELÉCTRICA | CE8: HIDROELÉCTRICA | CF8: HIDROELÉCTRICA | CG8: TERMOELÉCTRICA | CH8: TERMOELÉCTRICA | CI8: TERMOELÉCTRICA | CJ8: TERMOELÉCTRICA | CK8: TERMOELÉCTRICA | CL8: TERMOELÉCTRICA | CM8: TERMOELÉCTRICA | CN8: TERMOELÉCTRICA | CO8: TERMOELÉCTRICA | CP8: TERMOELÉCTRICA | CQ8: TERMOELÉCTRICA | CR8: TERMOELÉCTRICA | CS8: TERMOELÉCTRICA | CT8: SOLAR | CU8: EÓLICA | CV8: SOLAR | CW8: EÓLICA | CX8: SOLAR | CY8: HIDROELÉCTRICA | CZ8: HIDROELÉCTRICA | DA8: HIDROELÉCTRICA | DB8: HIDROELÉCTRICA | DC8: HIDROELÉCTRICA | DD8: HIDROELÉCTRICA | DE8: HIDROELÉCTRICA | DF8: HIDROELÉCTRICA | DG8: HIDROELÉCTRICA | DH8: HIDROELÉCTRICA | DI8: SOLAR | DJ8: SOLAR | DK8: EÓLICA | DL8: EÓLICA | DM8: TERMOELÉCTRICA | DN8: TERMOELÉCTRICA | DO8: TERMOELÉCTRICA | DP8: TERMOELÉCTRICA | DQ8: SOLAR | DR8: HIDROELÉCTRICA | DS8: HIDROELÉCTRICA | DT8: HIDROELÉCTRICA | DU8: HIDROELÉCTRICA | DV8: HIDROELÉCTRICA | DW8: HIDROELÉCTRICA | DX8: HIDROELÉCTRICA | DY8: HIDROELÉCTRICA | DZ8: HIDROELÉCTRICA | EA8: EÓLICA | EB8: EÓLICA | EC8: SOLAR | ED8: EÓLICA | EE8: EÓLICA | EF8: EÓLICA | EG8: EÓLICA | EH8: HIDROELÉCTRICA | EI8: HIDROELÉCTRICA | EJ8: HIDROELÉCTRICA | EK8: HIDROELÉCTRICA | EL8: HIDROELÉCTRICA | EM8: HIDROELÉCTRICA | EN8: EÓLICA | EO8: SOLAR | EP8: SOLAR | EQ8: HIDROELÉCTRICA | ER8: EÓLICA | ES8: EÓLICA | ET8: SOLAR | EU8: SOLAR | EV8: HIDROELÉCTRICA | EW8: HIDROELÉCTRICA | EX8: TERMOELÉCTRICA | EY8: TERMOELÉCTRICA | EZ8: TERMOELÉCTRICA | FA8: TERMOELÉCTRICA | FB8: TERMOELÉCTRICA | FC8: TERMOELÉCTRICA | FD8: TERMOELÉCTRICA | FE8: TERMOELÉCTRICA | FH8: HIDROELÉCTRICA | FI8: HIDROELÉCTRICA | FJ8: HIDROELÉCTRICA | FK8: HIDROELÉCTRICA | FL8: HIDROELÉCTRICA | FM8: TERMOELÉCTRICA | FN8: TERMOELÉCTRICA | FO8: HIDROELÉCTRICA | FP8: HIDROELÉCTRICA
C9: CENTRALES SANTA ROSA S.A.C. | D9: CENTRALES SANTA ROSA S.A.C. | E9: INVERSIONES SHAQSHA S.A.C. | F9: ELECTROPERU | G9: ELECTROPERU | H9: ELECTROPERU | I9: ELECTROPERU | J9: ORAZUL ENERGY PERÚ | K9: ORAZUL ENERGY PERÚ | L9: TERMOSELVA | M9: TERMOSELVA | N9: KALLPA GENERACION S.A. | O9: KALLPA GENERACION S.A. | P9: KALLPA GENERACION S.A. | Q9: KALLPA GENERACION S.A. | R9: KALLPA GENERACION S.A. | S9: KALLPA GENERACION S.A. | T9: KALLPA GENERACION S.A. | U9: KALLPA GENERACION S.A. | V9: SHOUGESA | W9: SHOUGESA | X9: SHOUGESA | Y9: SHOUGESA | Z9: EGEMSA | AA9: EGESUR | AB9: EGESUR | AC9: EGASA | AD9: EGASA | AE9: EGASA | AF9: EGASA | AG9: EGASA | AH9: EGASA | AI9: EGASA | AJ9: SAN GABAN | AK9: CELEPSA | AL9: MINERA CERRO VERDE | AM9: PLANTA DE RESERVA FRIA DE GENERACION DE ETEN S.A. | AN9: PLANTA DE RESERVA FRIA DE GENERACION DE ETEN S.A. | AO9: EMPRESA DE GENERACION HUALLAGA | AP9: EMPRESA DE GENERACION HUALLAGA | AQ9: LA VIRGEN | AR9: CHINANGO S.A.C. | AS9: CHINANGO S.A.C. | AT9: HIDROELECTRICA HUANCHOR S.A.C. | AU9: CELEPSA RENOVABLES S.R.L. | AV9: INLAND ENERGY SAC | AW9: FENIX POWER PERÚ | AX9: FENIX POWER PERÚ | AY9: FENIX POWER PERÚ | AZ9: STATKRAFT S.A | BA9: STATKRAFT S.A | BB9: STATKRAFT S.A | BC9: STATKRAFT S.A | BD9: STATKRAFT S.A | BE9: STATKRAFT S.A | BF9: STATKRAFT S.A | BG9: STATKRAFT S.A | BH9: EMPRESA DE GENERACION HUANZA | BI9: ENEL GENERACION PIURA S.A. | BJ9: ENEL GENERACION PIURA S.A. | BK9: ENEL GENERACION PIURA S.A. | BL9: ENGIE | BM9: ENGIE | BN9: ENGIE | BO9: ENGIE | BP9: ENGIE | BQ9: ENGIE | BR9: ENGIE | BS9: ENGIE | BT9: ENGIE | BU9: ENGIE | BV9: ENGIE | BW9: ENGIE | BX9: ENGIE | BY9: ENGIE | BZ9: INFRAESTRUCTURAS Y ENERGIAS DEL PERU S.A.C. | CA9: INFRAESTRUCTURAS Y ENERGIAS DEL PERU S.A.C. | CB9: ORYGEN PERU S.A.A. | CC9: ORYGEN PERU S.A.A. | CD9: ORYGEN PERU S.A.A. | CE9: ORYGEN PERU S.A.A. | CF9: ORYGEN PERU S.A.A. | CG9: ORYGEN PERU S.A.A. | CH9: ORYGEN PERU S.A.A. | CI9: ORYGEN PERU S.A.A. | CJ9: ORYGEN PERU S.A.A. | CK9: ORYGEN PERU S.A.A. | CL9: ORYGEN PERU S.A.A. | CM9: ORYGEN PERU S.A.A. | CN9: SAMAY I S.A.C | CO9: SAMAY I S.A.C | CP9: SAMAY I S.A.C | CQ9: SAMAY I S.A.C | CR9: TERMOCHILCA S.A.C. | CS9: TERMOCHILCA S.A.C. | CT9: COLCA SOLAR S.A.C. | CU9: ENERGIA RENOVABLE DEL SUR S.A. | CV9: GR CORTARRAMA SOCIEDAD ANONIMA CERRADA | CW9: GR TARUCA SOCIEDAD ANONIMA CERRADA | CX9: KONDU SAC | CY9: PERUANA DE INVERSIONES EN ENERGIAS RENOVABLES S.A. | CZ9: ORAZUL ENERGY PERÚ | DA9: ORAZUL ENERGY PERÚ | DB9: MAJA ENERGIA S.A.C. | DC9: EMPRESA DE GENERACION ELECTRICA CANCHAYLLO SAC | DD9: EMPRESA DE GENERACION ELECTRICA SANTA ANA S.A.C. | DE9: EMPRESA ELECTRICA AGUA AZUL | DF9: EMPRESA ELECTRICA RIO DOBLE | DG9: HIDROCAÑETE S.A. | DH9: HUAURA POWER GROUP S.A. | DI9: MOQUEGUA FV S.A.C. | DJ9: PANAMERICANA SOLAR SAC. | DK9: PARQUE EOLICO MARCONA S.A.C. | DL9: PARQUE EOLICO TRES HERMANAS S.A.C. | DM9: PETRAMAS | DN9: PETRAMAS | DO9: PETRAMAS | DP9: PETRAMAS | DQ9: TACNA SOLAR SAC. | DR9: ELECTRICA YANAPAMPA SAC | DS9: ANDEAN POWER S.A.C. | DT9: ASOCIACIÓN SANTA LUCIA DE CHACAS | DU9: ATRIA ENERGIA S.A.C. | DV9: EGEJUNIN | DW9: EGEJUNIN | DX9: EGEJUNIN | DY9: EGEJUNIN | DZ9: EMPRESA DE GENERACION ELECTRICA RIO BAÑOS S.A.C. | EA9: ENERGÍA EÓLICA S.A. | EB9: ENERGÍA EÓLICA S.A. | EC9: ENGIE | ED9: ENGIE | EE9: ENGIE | EF9: ENGIE | EG9: ENGIE | EH9: GENERACIÓN ANDINA S.A.C. | EI9: GENERACIÓN ANDINA S.A.C. | EJ9: GENERADORA DE ENERGÍA DEL PERÚ | EK9: GENERADORA DE ENERGÍA DEL PERÚ | EL9: GENERADORA DE ENERGÍA DEL PERÚ | EM9: GENERADORA DE ENERGÍA DEL PERÚ | EN9: GR PAINO SOCIEDAD ANONIMA CERRADA | EO9: MAJES ARCUS S.A.C. | EP9: ORYGEN PERU S.A.A. | EQ9: ORYGEN PERU S.A.A. | ER9: ORYGEN PERU S.A.A. | ES9: ORYGEN PERU S.A.A. | ET9: ORYGEN PERU S.A.A. | EU9: REPARTICIÓN ARCUS S.A.C. | EV9: SINERSA | EW9: SINERSA | EX9: BIOENERGIA DEL CHIRA S.A. | EY9: GM OPERACIONES S.A.C. | EZ9: GM OPERACIONES S.A.C. | FA9: SDF ENERGIA SAC | FB9: SDF ENERGIA SAC | FC9: AGRO INDUSTRIAL PARAMONGA S.A. | FD9: AGROAURORA S.A.C. | FE9: AGROINDUSTRIAS SAN JACINTO S.A.A. | FH9: UNACEM PERU S.A. | FI9: SAN GABAN | FJ9: ELECTRO ORIENTE | FK9: AGUAS Y ENERGIA PERU | FL9: ELECTRO ZAÑA S.A.C. | FM9: ELECTRONOROESTE S.A. | FN9: SDE PIURA | FO9: SINERSA | FP9: SINERSA
C10: SANTA ROSA 1 | D10: SANTA ROSA 2 | E10: PARIAC | F10: MANTARO | G10: RESTITUCION | H10: TUMBES MAK 1 | I10: TUMBES MAK 2 | J10: CARHUAQUERO | K10: CAÑON DEL PATO | L10: AGUAYTIA TG1 | M10: AGUAYTIA TG2 | N10: KALLPA TG1 | O10: KALLPA TG2 | P10: KALLPA TG3 | Q10: KALLPA TV | R10: LFLORES TG1 | S10: LFLORES TV | T10: CERRO DEL AGUILA | U10: CERRODELAGUILAG4 | V10: SHOUGESA TV1 | W10: SHOUGESA TV2 | X10: SHOUGESA TV3 | Y10: SHOUGESA CUMMINS | Z10: MACHUPICCHU | AA10: ARICOTA 1 | AB10: INDEPENDENCIA | AC10: CHARCANI I,II,III | AD10: CHARCANI IV | AE10: CHARCANI V | AF10: CHARCANI VI | AG10: CHILINA TG | AH10: MOLLENDO 1, 2, 3 | AI10: CHILINA (SULZ 1,2) | AJ10: SAN GABAN II | AK10: PLATANAL | AL10: RECKA | AM10: RF ETEN TG1 | AN10: RF ETEN TG2 | AO10: CHAGLLA GP1 | AP10: CHAGLLA | AQ10: LA VIRGEN | AR10: CHIMAY | AS10: YANANGO | AT10: HUANCHOR | AU10: MARAÑON | AV10: STA TERESA | AW10: FENIX GT11 | AX10: FENIX GT12 | AY10: FENIX TV10 | AZ10: YAUPI | BA10: OROYA | BB10: PACHACHACA | BC10: MALPASO | BD10: CAHUA | BE10: ARCATA | BF10: GALLITO CIEGO | BG10: CHEVES | BH10: HUANZA | BI10: MALACAS2 TG4 | BJ10: MALACAS3 TG 5 | BK10: MALACAS1 TG6 | BL10: RF ILO2 TG1 | BM10: RF ILO2 TG2 | BN10: RF ILO2 TG3 | BO10: YUNCAN | BP10: CHILCA1 TG1 | BQ10: CHILCA1 TG2 | BR10: CHILCA1 TG3 | BS10: CHILCA-TV | BT10: CHILCA2 TG41 | BU10: CHILCA2-TV | BV10: CTNEPI_TG41 | BW10: CTNEPI_TG42 | BX10: CTNEPI_TG43 | BY10: QUITARACSA | BZ10: RF PTO MALDONADO | CA10: RF PUCALLPA | CB10: HUINCO | CC10: MATUCANA | CD10: MOYOPAMPA | CE10: CALLAHUANCA | CF10: HUAMPANI | CG10: STA ROSA WEST TG7 | CH10: UTI_5 | CI10: UTI_6 | CJ10: VENTANILLA 3 | CK10: VENTANILLA 4 | CL10: VENTANILLA TV | CM10: STAROSA TG8 | CN10: PTO_BRVO TG1 | CO10: PTO_BRVO TG2 | CP10: PTO_BRVO TG3 | CQ10: PTO_BRVO TG4 | CR10: OLLEROS TG1 | CS10: OLLEROS TV | CT10: CS YARUCAYA | CU10: SAN JUAN | CV10: MATARANI | CW10: DUNA | CX10: CARHUAQUERO (CS) | CY10: MANTA I | CZ10: CARHUAQUERO4 | DA10: CAÑA BRAVA | DB10: RONCADOR | DC10: CANCHAYLLO | DD10: RENOVANDESH1 | DE10: POTRERO | DF10: PIZARRAS | DG10: NIMPERIAL | DH10: YARUCAYA | DI10: MOQUEGUA-SOLAR | DJ10: PANAMERICANA-SOLAR | DK10: PQE-EOLICO-MARCONA | DL10: PQE-EOLICO-3-HERMANAS | DM10: HUAYCOLORO | DN10: CALLAO | DO10: DONA_CATALINA | DP10: LAGRINGAV | DQ10: TACNA-SOLAR | DR10: YANAPAMPA | DS10: CARHUAC | DT10: HUALLIN | DU10: PURMACANA | DV10: HUASAHUASI | DW10: STACRUZ_1_2 | DX10: RUNATULLO_II | DY10: RUNATULLO_III | DZ10: RUCUY | EA10: PQE-EOLICO-TALARA | EB10: PQE-EOLICO-CUPISNIQUE | EC10: INTIPAMPA | ED10: PUNTA LOMITAS-BL1 | EE10: PUNTA LOMITAS-BL2 | EF10: PUN LOMITAS_EXP-BL1 | EG10: PUN LOMITAS_EXP-BL2 | EH10: 8AGOSTO | EI10: EL CARMEN | EJ10: LA JOYA | EK10: ANGEL_I | EL10: ANGEL_II | EM10: ANGEL_III | EN10: HUAMBOS | EO10: MAJES | EP10: RUBI | EQ10: CH_HER1 | ER10: WAYRA-I | ES10: WAYRA EXTENSION | ET10: CLEMESI | EU10: REPARTICION | EV10: POECHOS2 | EW10: CHANCAY | EX10: CANA BRAVA | EY10: REFINERIA TALARA TV1 | EZ10: REFINERÍA TALARA TV2 | FA10: OQUENDO TG1 | FB10: OQUENDO TV1 | FC10: PARAMONGA | FD10: MAPLE | FE10: SAN_JACINTO | FF10: MW | FH10: CARPAPATA | FI10: TUPURI | FJ10: CENTRALES ELOR | FK10: PIAS1 | FL10: ZANA | FM10: TABLAZO | FN10: TALLANCA | FO10: CURUMUY | FP10: POECHOS1 | FQ10: MW
A11: 15/01/2025 | B11: 00:30 | C11: 1 | D11: 1.7 | E11: 4.2 | F11: 647.8 | G11: 219.3 | J11: 90.6 | K11: 238.6 | L11: 0 | M11: 0 | N11: 108.1 | O11: 108.4 | P11: 109 | Q11: 211.1 | R11: 205.8 | S11: 109.3 | T11: 560.7 | U11: 10.5 | Z11: 162.7 | AA11: 8.1 | AB11: 0 | AC11: 6.5 | AD11: 10 | AE11: 40.7 | AF11: 6 | AJ11: 110.9 | AK11: 222.2 | AL11: 0 | AO11: 6.5 | AP11: 467.9 | AQ11: 54 | AR11: 148.7 | AS11: 36.6 | AT11: 18.3 | AU11: 19.7 | AV11: 93.4 | AW11: 170.1 | AX11: 170.4 | AY11: 177.1 | AZ11: 108.5 | BA11: 7.8 | BB11: 6.2 | BC11: 36 | BD11: 46.9 | BE11: 3.1 | BF11: 30.9 | BG11: 173.8 | BH11: 57.5 | BK11: 47.6 | BO11: 131.2 | BQ11: 0 | BY11: 112.5 | CB11: 93.5 | CC11: 132.3 | CD11: 64.3 | CE11: 77.2 | CF11: 30 | CJ11: 114.3 | CL11: 56.1 | CN11: 0 | CT11: 0 | CU11: 72.9 | CV11: 0 | CW11: 3.2 | CX11: 0 | CY11: 20 | CZ11: 9.9 | DA11: 5.5 | DB11: 3.6 | DC11: 4.8 | DD11: 20.2 | DE11: 20 | DF11: 18.8 | DG11: 3.5 | DH11: 18.7 | DI11: 0 | DJ11: 0 | DK11: 14.8 | DL11: 26.5 | DM11: 4.8 | DN11: 2.4 | DO11: 2.4 | DP11: 2.8 | DQ11: 0 | DR11: 3.6 | DS11: 17.3 | DT11: 2 | DV11: 14.7 | DW11: 12 | DX11: 20 | DY11: 20.4 | DZ11: 19.8 | EA11: 7.1 | EB11: 21.2 | EC11: 0 | ED11: 35.4 | EE11: 56.9 | EF11: 2.6 | EG11: 1.6 | EH11: 20.1 | EI11: 5.7 | EJ11: 5.6 | EK11: 20.4 | EL11: 20.4 | EM11: 0 | EN11: 3.6 | EO11: 0 | EP11: 0 | EQ11: 0.6 | ER11: 13.8 | ES11: 8 | ET11: 0 | EU11: 0 | EV11: 4.7 | EW11: 19.8 | EX11: 11.1 | EY11: 25.6 | EZ11: 34.3 | FA11: 29.2 | FB11: 3.5 | FC11: 15 | FD11: 14.6 | FE11: 7.7 | FF11: 6638.7 | FH11: 24.19245 | FI11: 1.3 | FJ11: 8.1 | FK11: 11.6265 | FL11: 12.2 | FN11: 18.91303 | FO11: 2.4 | FP11: 3.8 | FQ11: 82.53198
A12: 15/01/2025 | B12: 01:00 | C12: 1.1 | D12: 1.7 | E12: 4.2 | F12: 642.5 | G12: 217.8 | J12: 89.7 | K12: 237.8 | L12: 0 | M12: 0 | N12: 107.6 | O12: 108 | P12: 108.1 | Q12: 210.8 | R12: 206.2 | S12: 109.4 | T12: 551.3 | U12: 10.5 | Z12: 165.8 | AA12: 7.7 | AB12: 0 | AC12: 6.5 | AD12: 9.8 | AE12: 39.4 | AF12: 6 | AJ12: 109.8 | AK12: 221.2 | AL12: 0 | AO12: 6.5 | AP12: 338.3 | AQ12: 53.7 | AR12: 130.2 | AS12: 36.6 | AT12: 18.3 | AU12: 19.7 | AV12: 90.3 | AW12: 166.2 | AX12: 166.4 | AY12: 170.7 | AZ12: 107.5 | BA12: 7.8 | BB12: 6.2 | BC12: 35.1 | BD12: 46.6 | BE12: 3.1 | BF12: 31 | BG12: 172.7 | BH12: 56.5 | BK12: 47.7 | BO12: 130.5 | BQ12: 0 | BY12: 110.8 | CB12: 140.6 | CC12: 118 | CD12: 63.9 | CE12: 75.8 | CF12: 29.8 | CJ12: 115 | CL12: 55.3 | CN12: 0 | CT12: 0 | CU12: 74.4 | CV12: 0 | CW12: 1.9 | CX12: 0 | CY12: 20 | CZ12: 9.9 | DA12: 5.5 | DB12: 3.6 | DC12: 4.8 | DD12: 19.9 | DE12: 20 | DF12: 18.8 | DG12: 3.5 | DH12: 18.7 | DI12: 0 | DJ12: 0 | DK12: 11 | DL12: 20.9 | DM12: 4.8 | DN12: 2.4 | DO12: 2.4 | DP12: 2.8 | DQ12: 0 | DR12: 3.6 | DS12: 17.1 | DT12: 2 | DV12: 14.7 | DW12: 12 | DX12: 19.8 | DY12: 20.4 | DZ12: 19.8 | EA12: 9.2 | EB12: 26.8 | EC12: 0 | ED12: 19 | EE12: 38.8 | EF12: 1.1 | EG12: 0 | EH12: 20.2 | EI12: 5.7 | EJ12: 5.9 | EK12: 20.4 | EL12: 20.4 | EM12: 0 | EN12: 2.4 | EO12: 0 | EP12: 0 | EQ12: 0.6 | ER12: 9.1 | ES12: 5.2 | ET12: 0 | EU12: 0 | EV12: 4.7 | EW12: 19.8 | EX12: 10.2 | EY12: 25.2 | EZ12: 34.2 | FA12: 29.2 | FB12: 3.4 | FC12: 15.2 | FD12: 14.6 | FE12: 7.3 | FF12: 6427 | FH12: 24.18951 | FI12: 1.3 | FJ12: 8.1 | FK12: 11.32581 | FL12: 12.2 | FN12: 18.91209 | FO12: 2.8 | FP12: 3.8 | FQ12: 82.62741
A13: 15/01/2025 | B13: 01:30 | C13: 1.1 | D13: 1.6 | E13: 4.2 | F13: 647 | G13: 218.9 | J13: 90.2 | K13: 238.3 | L13: 0 | M13: 0 | N13: 109.9 | O13: 110.2 | P13: 110.6 | Q13: 210.6 | R13: 205.6 | S13: 109.3 | T13: 561.1 | U13: 10.5 | Z13: 168.8 | AA13: 8 | AB13: 0 | AC13: 6.5 | AD13: 9.8 | AE13: 40.4 | AF13: 6 | AJ13: 110.9 | AK13: 222.1 | AL13: 0 | AO13: 6.5 | AP13: 466.2 | AQ13: 53.7 | AR13: 149 | AS13: 35.8 | AT13: 18.3 | AU13: 19.7 | AV13: 89.5 | AW13: 126.1 | AX13: 126.2 | AY13: 152.8 | AZ13: 107.4 | BA13: 7.8 | BB13: 6.2 | BC13: 36.1 | BD13: 47 | BE13: 3.1 | BF13: 29.9 | BG13: 173.8 | BH13: 57.4 | BK13: 47.7 | BO13: 131.1 | BQ13: 0 | BY13: 112.5 | CB13: 87.1 | CC13: 132.1 | CD13: 64.4 | CE13: 76 | CF13: 30 | CJ13: 115 | CL13: 54.6 | CN13: 0 | CT13: 0 | CU13: 78.3 | CV13: 0 | CW13: 0.5 | CX13: 0 | CY13: 20 | CZ13: 9.9 | DA13: 5.4 | DB13: 3.6 | DC13: 4.8 | DD13: 20.3 | DE13: 20 | DF13: 18.9 | DG13: 3.5 | DH13: 18.7 | DI13: 0 | DJ13: 0 | DK13: 10.1 | DL13: 25.6 | DM13: 4.8 | DN13: 2.4 | DO13: 2.4 | DP13: 2.8 | DQ13: 0 | DR13: 3.6 | DS13: 17.1 | DT13: 2 | DV13: 14.6 | DW13: 12 | DX13: 19.7 | DY13: 20.4 | DZ13: 19.8 | EA13: 11.1 | EB13: 30.9 | EC13: 0 | ED13: 12.7 | EE13: 28 | EF13: 0.4 | EG13: 0.1 | EH13: 20.2 | EI13: 5.7 | EJ13: 5.9 | EK13: 20.4 | EL13: 20.4 | EM13: 0 | EN13: 0.7 | EO13: 0 | EP13: 0 | EQ13: 0.6 | ER13: 2.5 | ES13: 0.5 | ET13: 0 | EU13: 0 | EV13: 4.7 | EW13: 19.8 | EX13: 9.9 | EY13: 25 | EZ13: 33.8 | FA13: 29.2 | FB13: 3.4 | FC13: 15 | FD13: 14.6 | FE13: 8.7 | FF13: 6450 | FH13: 24.15002 | FI13: 1.3 | FJ13: 8.1 | FK13: 11.73875 | FL13: 12.2 | FN13: 18.91143 | FO13: 2.8 | FP13: 3.8 | FQ13: 83.0002
A14: 15/01/2025 | B14: 02:00 | C14: 1.1 | D14: 1.7 | E14: 4.2 | F14: 646.7 | G14: 219.5 | J14: 90.1 | K14: 237.7 | L14: 0 | M14: 0 | N14: 107.5 | O14: 108.2 | P14: 107.2 | Q14: 209.4 | R14: 206.1 | S14: 109.5 | T14: 557.7 | U14: 10.5 | Z14: 165.3 | AA14: 7.8 | AB14: 0 | AC14: 6.5 | AD14: 9.8 | AE14: 40.2 | AF14: 5.8 | AJ14: 110.9 | AK14: 222.1 | AL14: 0 | AO14: 6.5 | AP14: 441 | AQ14: 53.1 | AR14: 145.4 | AS14: 36.3 | AT14: 18.3 | AU14: 19.7 | AV14: 89.7 | AW14: 123.5 | AX14: 123.7 | AY14: 152.6 | AZ14: 108.8 | BA14: 7.8 | BB14: 6.2 | BC14: 35.8 | BD14: 46.9 | BE14: 3.1 | BF14: 31.5 | BG14: 173.7 | BH14: 57.5 | BK14: 0 | BO14: 131.1 | BQ14: 0 | BY14: 112.4 | CB14: 94.4 | CC14: 129 | CD14: 63.9 | CE14: 73.9 | CF14: 30.1 | CJ14: 117.4 | CL14: 53.8 | CN14: 0 | CT14: 0 | CU14: 68.1 | CV14: 0 | CW14: 0.8 | CX14: 0 | CY14: 20 | CZ14: 9.9 | DA14: 5.3 | DB14: 3.6 | DC14: 4.7 | DD14: 20.2 | DE14: 19.3 | DF14: 19 | DG14: 3.5 | DH14: 18.7 | DI14: 0 | DJ14: 0 | DK14: 9 | DL14: 20.4 | DM14: 4.8 | DN14: 2.4 | DO14: 2.4 | DP14: 2.8 | DQ14: 0 | DR14: 3.6 | DS14: 17.2 | DT14: 2 | DV14: 14.6 | DW14: 12 | DX14: 19.4 | DY14: 20.4 | DZ14: 19.8 | EA14: 11.7 | EB14: 25.4 | EC14: 0 | ED14: 9.1 | EE14: 24 | EF14: 0.6 | EG14: 0.1 | EH14: 20.2 | EI14: 5.7 | EJ14: 6.1 | EK14: 20.4 | EL14: 20.4 | EM14: 0 | EN14: 1 | EO14: 0 | EP14: 0 | EQ14: 0.6 | ER14: 0 | ES14: 0 | ET14: 0 | EU14: 0 | EV14: 4.7 | EW14: 19.8 | EX14: 9.2 | EY14: 24.4 | EZ14: 34.9 | FA14: 29.3 | FB14: 3.4 | FC14: 15 | FD14: 14.6 | FE14: 9 | FF14: 6326.1 | FH14: 24.10385 | FI14: 1.3 | FJ14: 8.1 | FK14: 11.84559 | FL14: 12.2 | FN14: 18.91074 | FO14: 2.7 | FP14: 3.9 | FQ14: 83.06018
A15: 15/01/2025 | B15: 02:30 | C15: 1.1 | D15: 1.7 | E15: 4.2 | F15: 649.8 | G15: 220.2 | J15: 90.4 | K15: 239.8 | L15: 0 | M15: 0 | N15: 107.2 | O15: 107.8 | P15: 107.4 | Q15: 209.8 | R15: 207.9 | S15: 109.5 | T15: 555.7 | U15: 10.5 | Z15: 167.9 | AA15: 7.9 | AB15: 0 | AC15: 6.4 | AD15: 9.8 | AE15: 40.1 | AF15: 5.9 | AJ15: 111.2 | AK15: 213.7 | AL15: 0 | AO15: 6.5 | AP15: 434.9 | AQ15: 52.1 | AR15: 149.7 | AS15: 37.9 | AT15: 18.3 | AU15: 19.7 | AV15: 88.9 | AW15: 124.5 | AX15: 125 | AY15: 152.5 | AZ15: 109.5 | BA15: 7.7 | BB15: 6.2 | BC15: 35.8 | BD15: 47.3 | BE15: 3.1 | BF15: 30.8 | BG15: 174.5 | BH15: 57.7 | BK15: 0 | BO15: 131.7 | BQ15: 0 | BY15: 113.2 | CB15: 88.9 | CC15: 132.8 | CD15: 64.2 | CE15: 77 | CF15: 30.3 | CJ15: 115.2 | CL15: 53.3 | CN15: 0 | CT15: 0 | CU15: 54 | CV15: 0 | CW15: 1.5 | CX15: 0 | CY15: 20 | CZ15: 9.9 | DA15: 5.5 | DB15: 3.6 | DC15: 4.8 | DD15: 20.5 | DE15: 20 | DF15: 18.9 | DG15: 3.5 | DH15: 18.7 | DI15: 0 | DJ15: 0 | DK15: 8.5 | DL15: 16.6 | DM15: 4.8 | DN15: 2.4 | DO15: 2.4 | DP15: 2.8 | DQ15: 0 | DR15: 3.6 | DS15: 17.2 | DT15: 2 | DV15: 14.6 | DW15: 12 | DX15: 19.6 | DY15: 20.4 | DZ15: 19.8 | EA15: 11 | EB15: 16.7 | EC15: 0 | ED15: 12.1 | EE15: 23.3 | EF15: 0.4 | EG15: 0 | EH15: 20.2 | EI15: 5.7 | EJ15: 6 | EK15: 20.4 | EL15: 20.4 | EM15: 0 | EN15: 1.7 | EO15: 0 | EP15: 0 | EQ15: 0.6 | ER15: 0 | ES15: 0 | ET15: 0 | EU15: 0 | EV15: 4.7 | EW15: 19.8 | EX15: 9.8 | EY15: 24.5 | EZ15: 35.4 | FA15: 29.3 | FB15: 3.4 | FC15: 15 | FD15: 14.6 | FE15: 8.5 | FF15: 6306.2 | FH15: 24.10269 | FI15: 1.3 | FJ15: 8.1 | FK15: 11.53931 | FL15: 12.2 | FN15: 18.91054 | FO15: 2.6 | FP15: 3.8 | FQ15: 82.55254
A16: 15/01/2025 | B16: 03:00 | C16: 1.1 | D16: 1.7 | E16: 4.2 | F16: 648.4 | G16: 219.7 | J16: 89.8 | K16: 238.2 | L16: 0 | M16: 0 | N16: 107.8 | O16: 108.8 | P16: 108.8 | Q16: 211.9 | R16: 208.1 | S16: 109.3 | T16: 560.4 | U16: 10.5 | Z16: 164.7 | AA16: 7.7 | AB16: 0 | AC16: 6.5 | AD16: 9.8 | AE16: 40.3 | AF16: 5.8 | AJ16: 110.9 | AK16: 169.2 | AL16: 0 | AO16: 6.5 | AP16: 465 | AQ16: 53.6 | AR16: 149.7 | AS16: 36.1 | AT16: 18.3 | AU16: 19.7 | AV16: 91.2 | AW16: 156.5 | AX16: 157 | AY16: 165.3 | AZ16: 109.1 | BA16: 7.8 | BB16: 6.5 | BC16: 28.5 | BD16: 47 | BE16: 3.1 | BF16: 30.3 | BG16: 152.3 | BH16: 57.9 | BK16: 0 | BO16: 119.3 | BQ16: 0 | BY16: 112.7 | CB16: 66.6 | CC16: 132.4 | CD16: 63.9 | CE16: 75 | CF16: 30.2 | CJ16: 115.4 | CL16: 55.3 | CN16: 0 | CT16: 0 | CU16: 34.9 | CV16: 0 | CW16: 3 | CX16: 0 | CY16: 20 | CZ16: 9.9 | DA16: 5.4 | DB16: 3.6 | DC16: 4.8 | DD16: 20.4 | DE16: 20 | DF16: 18.9 | DG16: 3.5 | DH16: 18.7 | DI16: 0 | DJ16: 0 | DK16: 3.6 | DL16: 5.8 | DM16: 4.8 | DN16: 2.4 | DO16: 2.4 | DP16: 2.8 | DQ16: 0 | DR16: 3.6 | DS16: 17.2 | DT16: 2 | DV16: 14.6 | DW16: 12 | DX16: 19.4 | DY16: 20.4 | DZ16: 19.8 | EA16: 16.9 | EB16: 22.8 | EC16: 0 | ED16: 10.2 | EE16: 22.7 | EF16: 0.3 | EG16: 0 | EH16: 20 | EI16: 5.7 | EJ16: 5.7 | EK16: 20.4 | EL16: 20.4 | EM16: 0 | EN16: 3.5 | EO16: 0 | EP16: 0 | EQ16: 0.6 | ER16: 0 | ES16: 0 | ET16: 0 | EU16: 0 | EV16: 4.7 | EW16: 19.9 | EX16: 9.3 | EY16: 24.6 | EZ16: 35.4 | FA16: 29.4 | FB16: 3.5 | FC16: 15.1 | FD16: 14.1 | FE16: 8.2 | FF16: 6283.1 | FH16: 24.10117 | FI16: 1.3 | FJ16: 8.1 | FK16: 11.48931 | FL16: 12.2 | FN16: 18.91011 | FO16: 2.5 | FP16: 3.8 | FQ16: 82.40059
A17: 15/01/2025 | B17: 03:30 | C17: 1.1 | D17: 1.7 | E17: 4.2 | F17: 644.9 | G17: 218.7 | J17: 90.1 | K17: 237.9 | L17: 0 | M17: 0 | N17: 108.5 | O17: 107.7 | P17: 108.3 | Q17: 214.9 | R17: 205.7 | S17: 108.8 | T17: 557.3 | U17: 10.6 | Z17: 164.4 | AA17: 7.5 | AB17: 0 | AC17: 6.5 | AD17: 9.8 | AE17: 40 | AF17: 5.8 | AJ17: 110.7 | AK17: 222 | AL17: 0 | AO17: 6.5 | AP17: 467.2 | AQ17: 54 | AR17: 147.7 | AS17: 36.7 | AT17: 18.3 | AU17: 19.7 | AV17: 93.2 | AW17: 139.8 | AX17: 141.3 | AY17: 162.9 | AZ17: 108.5 | BA17: 7.7 | BB17: 6.3 | BC17: 25.5 | BD17: 46.9 | BE17: 3.1 | BF17: 30.8 | BG17: 153.6 | BH17: 57.1 | BK17: 0 | BO17: 101.6 | BQ17: 0 | BY17: 111.9 | CB17: 67.2 | CC17: 130.8 | CD17: 63.7 | CE17: 74.9 | CF17: 30.1 | CJ17: 115.4 | CL17: 52.7 | CN17: 0 | CT17: 0 | CU17: 31.3 | CV17: 0 | CW17: 3.9 | CX17: 0 | CY17: 20 | CZ17: 9.9 | DA17: 5.4 | DB17: 3.6 | DC17: 4.8 | DD17: 20 | DE17: 20 | DF17: 18.9 | DG17: 3.5 | DH17: 18.7 | DI17: 0 | DJ17: 0 | DK17: 1.7 | DL17: 1.3 | DM17: 4.8 | DN17: 2.4 | DO17: 2.4 | DP17: 2.8 | DQ17: 0 | DR17: 3.6 | DS17: 17.2 | DT17: 2 | DV17: 14.6 | DW17: 12.2 | DX17: 19.3 | DY17: 20.3 | DZ17: 19.8 | EA17: 17 | EB17: 27.6 | EC17: 0 | ED17: 4.3 | EE17: 12.5 | EF17: 0 | EG17: 0 | EH17: 20 | EI17: 5.7 | EJ17: 5.7 | EK17: 20.4 | EL17: 20.4 | EM17: 0 | EN17: 5.5 | EO17: 0 | EP17: 0 | EQ17: 0.6 | ER17: 0 | ES17: 0 | ET17: 0 | EU17: 0 | EV17: 4.7 | EW17: 19.9 | EX17: 9.8 | EY17: 25.1 | EZ17: 35.3 | FA17: 29.4 | FB17: 3.4 | FC17: 15.2 | FD17: 14.6 | FE17: 7.7 | FF17: 6251.4 | FH17: 24.10307 | FI17: 1.3 | FJ17: 8.1 | FK17: 11.92919 | FL17: 11.8 | FN17: 18.90966 | FO17: 2.5 | FP17: 3.8 | FQ17: 82.44192
A18: 15/01/2025 | B18: 04:00 | C18: 1.1 | D18: 1.7 | E18: 4.2 | F18: 642 | G18: 217.4 | J18: 89.7 | K18: 237.5 | L18: 0 | M18: 0 | N18: 108.2 | O18: 108.5 | P18: 108.3 | Q18: 210 | R18: 210.5 | S18: 109.3 | T18: 551.7 | U18: 10.4 | Z18: 164.9 | AA18: 7.1 | AB18: 0 | AC18: 6.5 | AD18: 9.8 | AE18: 39.6 | AF18: 6 | AJ18: 110 | AK18: 221.9 | AL18: 0 | AO18: 6.5 | AP18: 364.7 | AQ18: 54 | AR18: 147.4 | AS18: 37.3 | AT18: 18.3 | AU18: 19.7 | AV18: 92.4 | AW18: 161.7 | AX18: 161.9 | AY18: 172.6 | AZ18: 107.5 | BA18: 7.8 | BB18: 6.3 | BC18: 24.7 | BD18: 46.5 | BE18: 3.1 | BF18: 30.8 | BG18: 153.1 | BH18: 56.5 | BK18: 0 | BO18: 101.3 | BQ18: 0 | BY18: 111 | CB18: 72.4 | CC18: 121.6 | CD18: 63.4 | CE18: 74.9 | CF18: 29.9 | CJ18: 116.8 | CL18: 55.4 | CN18: 0 | CT18: 0 | CU18: 40.6 | CV18: 0 | CW18: 2.7 | CX18: 0 | CY18: 20 | CZ18: 9.9 | DA18: 5.4 | DB18: 3.6 | DC18: 4.8 | DD18: 20 | DE18: 20 | DF18: 18.9 | DG18: 3.5 | DH18: 18.7 | DI18: 0 | DJ18: 0 | DK18: 4.9 | DL18: 2 | DM18: 4.8 | DN18: 2.4 | DO18: 2.4 | DP18: 2.8 | DQ18: 0 | DR18: 3.6 | DS18: 17.3 | DT18: 2 | DV18: 14.6 | DW18: 12.2 | DX18: 19.2 | DY18: 20.3 | DZ18: 19.9 | EA18: 18.4 | EB18: 26.1 | EC18: 0 | ED18: 3.6 | EE18: 10.3 | EF18: 0 | EG18: 0 | EH18: 20 | EI18: 5.7 | EJ18: 5.8 | EK18: 20.4 | EL18: 20.4 | EM18: 0 | EN18: 2.7 | EO18: 0 | EP18: 0 | EQ18: 0.6 | ER18: 0 | ES18: 0 | ET18: 0 | EU18: 0 | EV18: 4.7 | EW18: 19.9 | EX18: 9.6 | EY18: 25 | EZ18: 34.8 | FA18: 29.4 | FB18: 3.3 | FC18: 15.4 | FD18: 14.7 | FE18: 7.8 | FF18: 6190.9 | FH18: 24.1 | FI18: 1.3 | FJ18: 8.1 | FK18: 11.3565 | FL18: 11.4 | FN18: 18.90903 | FO18: 2.5 | FP18: 3.8 | FQ18: 81.46553
A19: 15/01/2025 | B19: 04:30 | C19: 1.1 | D19: 1.6 | E19: 4.2 | F19: 645.9 | G19: 218.7 | J19: 91.6 | K19: 238.8 | L19: 0 | M19: 0 | N19: 119.6 | O19: 119.8 | P19: 119.8 | Q19: 221.8 | R19: 207.3 | S19: 109.2 | T19: 557.9 | U19: 10.5 | Z19: 167.7 | AA19: 7.9 | AB19: 0 | AC19: 6.5 | AD19: 9.8 | AE19: 40.5 | AF19: 5.9 | AJ19: 111 | AK19: 222.3 | AL19: 0 | AO19: 6.5 | AP19: 465.9 | AQ19: 54.3 | AR19: 148.7 | AS19: 37.8 | AT19: 18.3 | AU19: 19.7 | AV19: 87.5 | AW19: 128.1 | AX19: 128.7 | AY19: 153.5 | AZ19: 108.5 | BA19: 7.7 | BB19: 6.6 | BC19: 26.3 | BD19: 47.2 | BE19: 3.1 | BF19: 30.4 | BG19: 156 | BH19: 57.4 | BK19: 0 | BO19: 102 | BQ19: 0 | BY19: 112.2 | CB19: 103.2 | CC19: 132.3 | CD19: 63.8 | CE19: 72 | CF19: 30.1 | CJ19: 114.2 | CL19: 55.2 | CN19: 0 | CT19: 0 | CU19: 47.7 | CV19: 0 | CW19: 1.4 | CX19: 0 | CY19: 20 | CZ19: 9.9 | DA19: 5.5 | DB19: 3.6 | DC19: 4.8 | DD19: 20.1 | DE19: 19.4 | DF19: 19 | DG19: 3.5 | DH19: 18.7 | DI19: 0 | DJ19: 0 | DK19: 6.8 | DL19: 4.9 | DM19: 4.8 | DN19: 2.4 | DO19: 2.4 | DP19: 2.8 | DQ19: 0 | DR19: 3.6 | DS19: 17.3 | DT19: 2 | DV19: 14.6 | DW19: 12.2 | DX19: 19.4 | DY19: 20.4 | DZ19: 19.8 | EA19: 14.4 | EB19: 17.9 | EC19: 0 | ED19: 3.2 | EE19: 10 | EF19: 0 | EG19: 0 | EH19: 20 | EI19: 5.7 | EJ19: 6 | EK19: 20.4 | EL19: 20.4 | EM19: 0 | EN19: 1.1 | EO19: 0 | EP19: 0 | EQ19: 0.6 | ER19: 0 | ES19: 0 | ET19: 0 | EU19: 0 | EV19: 4.7 | EW19: 19.8 | EX19: 9.5 | EY19: 24.9 | EZ19: 35 | FA19: 29.4 | FB19: 3.4 | FC19: 15.1 | FD19: 14.6 | FE19: 7.8 | FF19: 6307.5 | FH19: 24.10246 | FI19: 1.3 | FJ19: 8.1 | FK19: 11.07825 | FL19: 11.4 | FN19: 18.90872 | FO19: 2.5 | FP19: 3.8 | FQ19: 81.18943
A20: 15/01/2025 | B20: 05:00 | C20: 1.1 | D20: 1.7 | E20: 4.2 | F20: 649.6 | G20: 219.5 | J20: 91.2 | K20: 238.6 | L20: 0 | M20: 0 | N20: 129.9 | O20: 128.9 | P20: 129.4 | Q20: 229 | R20: 206.8 | S20: 109 | T20: 564.9 | U20: 10.6 | Z20: 168.3 | AA20: 8.2 | AB20: 0 | AC20: 6.5 | AD20: 9.8 | AE20: 40.5 | AF20: 5.9 | AJ20: 111.1 | AK20: 222.2 | AL20: 0 | AO20: 6.5 | AP20: 465.8 | AQ20: 55 | AR20: 148.9 | AS20: 38.3 | AT20: 18.3 | AU20: 19.7 | AV20: 86.1 | AW20: 124.6 | AX20: 124.9 | AY20: 152.9 | AZ20: 109.9 | BA20: 7.7 | BB20: 6.4 | BC20: 25.8 | BD20: 47.1 | BE20: 3.1 | BF20: 32.1 | BG20: 155.9 | BH20: 57.9 | BK20: 0 | BO20: 102 | BQ20: 0 | BY20: 112.9 | CB20: 66.9 | CC20: 132.8 | CD20: 64.1 | CE20: 69 | CF20: 30.4 | CJ20: 115.4 | CL20: 54.7 | CN20: 0 | CT20: 0 | CU20: 57.4 | CV20: 0 | CW20: 0.7 | CX20: 0 | CY20: 20 | CZ20: 9.9 | DA20: 5.4 | DB20: 3.6 | DC20: 4.7 | DD20: 20.4 | DE20: 20 | DF20: 19 | DG20: 3.5 | DH20: 18.7 | DI20: 0 | DJ20: 0 | DK20: 7.7 | DL20: 7.7 | DM20: 4.8 | DN20: 2.4 | DO20: 2.4 | DP20: 2.8 | DQ20: 0 | DR20: 3.6 | DS20: 17.2 | DT20: 2 | DV20: 14.6 | DW20: 12.2 | DX20: 19.5 | DY20: 20.4 | DZ20: 19.8 | EA20: 10.6 | EB20: 8.3 | EC20: 0 | ED20: 4.3 | EE20: 13.3 | EF20: 0 | EG20: 0 | EH20: 20 | EI20: 5.7 | EJ20: 6 | EK20: 20.4 | EL20: 20.4 | EM20: 0 | EN20: 1.9 | EO20: 0 | EP20: 0 | EQ20: 0.6 | ER20: 0 | ES20: 0 | ET20: 0 | EU20: 0 | EV20: 4.7 | EW20: 20 | EX20: 9.4 | EY20: 24.9 | EZ20: 35 | FA20: 29.5 | FB20: 3.3 | FC20: 15 | FD20: 14.7 | FE20: 6.6 | FF20: 6317 | FH20: 24.09817 | FI20: 1.3 | FJ20: 8.1 | FK20: 10.84091 | FL20: 11.4 | FN20: 18.9083 | FO20: 2.5 | FP20: 3.8 | FQ20: 80.94738
A21: 15/01/2025 | B21: 05:30 | C21: 1.1 | D21: 1.7 | E21: 4.2 | F21: 635.4 | G21: 215.7 | J21: 88.7 | K21: 233.6 | L21: 0 | M21: 0 | N21: 114.6 | O21: 115.2 | P21: 115.3 | Q21: 215.4 | R21: 207.2 | S21: 109.6 | T21: 540.7 | U21: 10.3 | Z21: 155.2 | AA21: 7 | AB21: 0 | AC21: 6.5 | AD21: 9.8 | AE21: 38.8 | AF21: 5.8 | AJ21: 108.5 | AK21: 222.1 | AL21: 0 | AO21: 6.5 | AP21: 445.7 | AQ21: 55 | AR21: 140.8 | AS21: 35.8 | AT21: 18.3 | AU21: 19.7 | AV21: 90.1 | AW21: 160.6 | AX21: 160.9 | AY21: 173.6 | AZ21: 108.1 | BA21: 7.7 | BB21: 6.6 | BC21: 23.2 | BD21: 46 | BE21: 3.1 | BF21: 30.6 | BG21: 153.1 | BH21: 54.2 | BK21: 0 | BO21: 99.8 | BQ21: 0 | BY21: 109.5 | CB21: 56.7 | CC21: 126.3 | CD21: 61.7 | CE21: 68.3 | CF21: 29.2 | CJ21: 114.2 | CL21: 54.2 | CN21: 0 | CT21: 0 | CU21: 60 | CV21: 0 | CW21: 0.7 | CX21: 0 | CY21: 20 | CZ21: 9.9 | DA21: 5.3 | DB21: 3.6 | DC21: 4.7 | DD21: 19.7 | DE21: 20 | DF21: 18.9 | DG21: 3.5 | DH21: 18.7 | DI21: 0.9 | DJ21: 1.1 | DK21: 9 | DL21: 11.3 | DM21: 4.8 | DN21: 2.4 | DO21: 2.4 | DP21: 2.9 | DQ21: 1.7 | DR21: 3.6 | DS21: 17.2 | DT21: 2 | DV21: 14.6 | DW21: 12.2 | DX21: 19.1 | DY21: 20.3 | DZ21: 19.8 | EA21: 10.8 | EB21: 7.9 | EC21: 0.1 | ED21: 6.6 | EE21: 19.4 | EF21: 0 | EG21: 0 | EH21: 20 | EI21: 5.7 | EJ21: 5.7 | EK21: 20.4 | EL21: 20.4 | EM21: 0 | EN21: 1.6 | EO21: 0 | EP21: 1 | EQ21: 0.6 | ER21: 0 | ES21: 0 | ET21: 0.9 | EU21: 0 | EV21: 4.8 | EW21: 19.8 | EX21: 9.7 | EY21: 24.9 | EZ21: 34.4 | FA21: 29.5 | FB21: 3.3 | FC21: 15 | FD21: 14.7 | FE21: 6.7 | FF21: 6236.1 | FH21: 24.09891 | FI21: 1.3 | FJ21: 8.1 | FK21: 9.92553 | FL21: 11.4 | FN21: 18.90792 | FO21: 2.4 | FP21: 3.8 | FQ21: 79.93236
A22: 15/01/2025 | B22: 06:00 | C22: 1.1 | D22: 1.7 | E22: 4.2 | F22: 646.6 | G22: 218.6 | J22: 90 | K22: 238.9 | L22: 0 | M22: 0 | N22: 108.4 | O22: 108.9 | P22: 108.7 | Q22: 212.1 | R22: 206 | S22: 109.6 | T22: 557.6 | U22: 10.5 | Z22: 166.9 | AA22: 7.6 | AB22: 0 | AC22: 6.5 | AD22: 9.7 | AE22: 40 | AF22: 5.8 | AJ22: 110.5 | AK22: 221.8 | AL22: 0 | AO22: 6.5 | AP22: 390.6 | AQ22: 55 | AR22: 137.6 | AS22: 38 | AT22: 18.3 | AU22: 19.7 | AV22: 93.7 | AW22: 169.3 | AX22: 169.6 | AY22: 175.9 | AZ22: 108.7 | BA22: 7.8 | BB22: 6.6 | BC22: 25.3 | BD22: 44.2 | BE22: 3.1 | BF22: 31.6 | BG22: 155.3 | BH22: 57.1 | BK22: 0 | BO22: 101.6 | BQ22: 0 | BY22: 111.8 | CB22: 64.8 | CC22: 124.1 | CD22: 63.6 | CE22: 69 | CF22: 29.9 | CJ22: 115.2 | CL22: 55.3 | CN22: 0 | CT22: 0 | CU22: 56.9 | CV22: 7.6 | CW22: 2.1 | CX22: 0 | CY22: 19.9 | CZ22: 9.9 | DA22: 5.4 | DB22: 3.6 | DC22: 4.7 | DD22: 20 | DE22: 19.4 | DF22: 18.9 | DG22: 3.5 | DH22: 18.7 | DI22: 6.3 | DJ22: 6.9 | DK22: 9.2 | DL22: 12.7 | DM22: 4.8 | DN22: 2.4 | DO22: 2.4 | DP22: 2.9 | DQ22: 8.1 | DR22: 3.6 | DS22: 17.2 | DT22: 2 | DV22: 14.6 | DW22: 12.2 | DX22: 19.4 | DY22: 20.3 | DZ22: 19.8 | EA22: 12.8 | EB22: 16.2 | EC22: 4.1 | ED22: 3.7 | EE22: 11.8 | EF22: 0 | EG22: 0 | EH22: 20 | EI22: 5.7 | EJ22: 5.5 | EK22: 20.4 | EL22: 20.4 | EM22: 0 | EN22: 2.4 | EO22: 0 | EP22: 17 | EQ22: 0.6 | ER22: 0 | ES22: 0 | ET22: 14.4 | EU22: 0.2 | EV22: 4.8 | EW22: 19.9 | EX22: 9.5 | EY22: 25 | EZ22: 34.9 | FA22: 29.5 | FB22: 3.2 | FC22: 15 | FD22: 14.7 | FE22: 6.5 | FF22: 6314.5 | FH22: 24.0989 | FI22: 1.3 | FJ22: 8.1 | FK22: 10.01938 | FL22: 11.4 | FN22: 18.90716 | FO22: 2.5 | FP22: 3.8 | FQ22: 80.12544
... A58: 16/01/2025 | B58: 00:00 | C58: 1 | D58: 1.6 | E58: 4.2 | F58: 645 | G58: 218.7 | J58: 87.1 | K58: 237.5 | L58: 27.2 | M58: 59.4 | N58: 110.7 | O58: 110.1 | P58: 110.1 | Q58: 213.7 | R58: 110.8 | S58: 70.1 | T58: 558.3 | U58: 10.3 | Z58: 162.7 | AA58: 7.7 | AB58: 0 | AC58: 6.5 | AD58: 9.6 | AE58: 71.8 | AF58: 6 | AJ58: 109.8 | AK58: 204.9 | AL58: 58.8 | AO58: 6.5 | AP58: 457 | AQ58: 47 | AR58: 146.2 | AS58: 32.1 | AT58: 18.4 | AU58: 19.7 | AV58: 91.2 | AW58: 15 | AX58: 120.6 | AY58: 94.1 | AZ58: 108.4 | BA58: 7.6 | BB58: 6.5 | BC58: 43 | BD58: 46.5 | BE58: 3 | BF58: 31.2 | BG58: 148 | BH58: 90.5 | BK58: 47.7 | BO58: 128.9 | BQ58: 0 | BY58: 111.1 | CB58: 172.9 | CC58: 129.4 | CD58: 63.3 | CE58: 80.3 | CF58: 29.7 | CJ58: 116.2 | CL58: 55.8 | CN58: 29.4 | CT58: 0 | CU58: 57.6 | CV58: 0 | CW58: 5.2 | CX58: 0 | CY58: 20 | CZ58: 9.9 | DA58: 5.4 | DB58: 3.5 | DC58: 4.6 | DD58: 19.9 | DE58: 20 | DF58: 18.9 | DG58: 3.6 | DH58: 18.7 | DI58: 0 | DJ58: 0 | DK58: 12.8 | DL58: 46.9 | DM58: 4.8 | DN58: 2.4 | DO58: 2.4 | DP58: 2.9 | DQ58: 0 | DR58: 3.5 | DS58: 20.2 | DT58: 2 | DV58: 12.3 | DW58: 12.2 | DX58: 20.2 | DY58: 20.4 | DZ58: 19.8 | EA58: 6.3 | EB58: 17.4 | EC58: 0 | ED58: 43.5 | EE58: 74.3 | EF58: 0.9 | EG58: 1.8 | EH58: 19.7 | EI58: 7.6 | EJ58: 5.8 | EK58: 20.4 | EL58: 20.4 | EM58: 10.2 | EN58: 6 | EO58: 0 | EP58: 0 | EQ58: 0.6 | ER58: 46.7 | ES58: 48.3 | ET58: 0 | EU58: 0 | EV58: 4.9 | EW58: 19.9 | EX58: 9.8 | EY58: 25.6 | EZ58: 34.2 | FA58: 29.3 | FB58: 3.3 | FC58: 14.9 | FD58: 15.5 | FE58: 7.8 | FF58: 6576 | FH58: 24.00606 | FI58: 1.3 | FJ58: 8.1 | FK58: 11.59662 | FL58: 10.4 | FN58: 18.91033 | FO58: 2.4 | FP58: 7 | FQ58: 83.71301
A59: EJEC | C59: 14.65 | D59: 22.3 | E59: 101.2 | F59: 15518.25 | G59: 5260.2 | H59: 0 | I59: 0 | J59: 2159.3 | K59: 5714.1 | L59: 69.6 | M59: 107.15 | N59: 3131.8 | O59: 3135.95 | P59: 3138 | Q59: 5514.1 | R59: 4816.85 | S59: 2567.7 | T59: 13388.45 | U59: 251.7 | V59: 0 | W59: 0 | X59: 0 | Y59: 0 | Z59: 3981.75 | AA59: 187.3 | AB59: 123.85 | AC59: 154.45 | AD59: 229.7 | AE59: 1515.85 | AF59: 137.25 | AG59: 0 | AH59: 0 | AI59: 0 | AJ59: 2656.15 | AK59: 5167.65 | AL59: 29.4 | AM59: 0 | AN59: 0 | AO59: 156 | AP59: 10715.3 | AQ59: 1235.7 | AR59: 3447 | AS59: 853.8 | AT59: 439.25 | AU59: 472.8 | AV59: 2069 | AW59: 3804.9 | AX59: 3866.3 | AY59: 4122.1 | AZ59: 2605.05 | BA59: 184.7 | BB59: 156.55 | BC59: 661.15 | BD59: 1118.4 | BE59: 73.6 | BF59: 740.25 | BG59: 3746.85 | BH59: 1343.3 | BI59: 0 | BJ59: 0 | BK59: 816.45 | BL59: 0 | BM59: 0 | BN59: 0 | BO59: 2892.7 | BP59: 0 | BQ59: 525.55 | BR59: 0 | BS59: 0 | BT59: 0 | BU59: 0 | BV59: 0 | BW59: 0 | BX59: 0 | BY59: 2690.35 | BZ59: 0 | CA59: 0 | CB59: 3037 | CC59: 3095.55 | CD59: 1522.75 | CE59: 1855.6 | CF59: 721.35 | CG59: 0 | CH59: 0 | CI59: 0 | CJ59: 2953 | CK59: 0 | CL59: 1386.7 | CM59: 0 | CN59: 14.7 | CO59: 0 | CP59: 0 | CQ59: 0 | CR59: 0 | CS59: 0 | CT59: 8.85 | CU59: 1889.8 | CV59: 802.55 | CW59: 141.35 | CX59: 2.45 | CY59: 479.8 | CZ59: 238.1 | DA59: 129.8 | DB59: 86 | DC59: 114.7 | DD59: 464.4 | DE59: 477.65 | DF59: 453.3 | DG59: 85.3 | DH59: 448.8 | DI59: 156.75 | DJ59: 197.7 | DK59: 422.25 | DL59: 1146.1 | DM59: 113.3 | DN59: 56.2 | DO59: 57.6 | DP59: 66.25 | DQ59: 188.25 | DR59: 85.9 | DS59: 360.5 | DT59: 48 | DU59: 0 | DV59: 325.1 | DW59: 289.7 | DX59: 478.8 | DY59: 489.05 | DZ59: 477.7 | EA59: 349.75 | EB59: 845.9 | EC59: 363.05 | ED59: 1134.95 | EE59: 1469.25 | EF59: 110.1 | EG59: 90.25 | EH59: 467.65 | EI59: 136.05 | EJ59: 140.45 | EK59: 489.6 | EL59: 489.6 | EM59: 122.4 | EN59: 160.25 | EO59: 38.85 | EP59: 1121.55 | EQ59: 14.4 | ER59: 1090.45 | ES59: 1105.4 | ET59: 909.3 | EU59: 133.25 | EV59: 114.7 | EW59: 478.2 | EX59: 240.05 | EY59: 606.3 | EZ59: 830.8 | FA59: 696.1 | FB59: 79.7 | FC59: 354.05 | FD59: 325.2 | FE59: 187.3 | FF59: 167895.2 | FH59: 573.5579 | FI59: 31.2 | FJ59: 194.2 | FK59: 260.37379 | FL59: 269.7 | FM59: 0 | FN59: 453.85152 | FO59: 39.65 | FP59: 152.4 | FQ59: 1974.9332

Sheet REACTIVA
B3: miércoles, 15 de Enero del 2025
A5: POTENCIA REACTIVA EJECUTADA DE LAS UNIDADES DE GENERACIÓN DEL COES (MVAR) | FH5: CENTRALES NO INTEGRANTES COES
A6: FECHA | B6: HORA | C6: 337 | D6: 338 | E6: 121 | F6: 101 | G6: 102 | H6: 42667 | I6: 42668 | J6: 126 | K6: 127 | L6: 138 | M6: 139 | N6: 197 | O6: 203 | P6: 204 | Q6: 230 | R6: 209 | S6: 56677 | T6: 796 | U6: 2146 | V6: 142 | W6: 143 | X6: 125 | Y6: 187 | Z6: 163 | AA6: 298 | AB6: 219 | AC6: 151 | AD6: 152 | AE6: 153 | AF6: 154 | AG6: 756 | AH6: 156 | AI6: 155 | AJ6: 182 | AK6: 212 | AL6: 758 | AM6: 263 | AN6: 265 | AO6: 775 | AP6: 777 | AQ6: 2154 | AR6: 150 | AS6: 149 | AT6: 188 | AU6: 2131 | AV6: 755 | AW6: 252 | AX6: 249 | AY6: 250 | AZ6: 117 | BA6: 267 | BB6: 268 | BC6: 119 | BD6: 120 | BE6: 189 | BF6: 122 | BG6: 266 | BH6: 251 | BI6: 115 | BJ6: 239 | BK6: 288 | BL6: 240 | BM6: 241 | BN6: 242 | BO6: 191 | BP6: 194 | BQ6: 196 | BR6: 207 | BS6: 236 | BT6: 795 | BU6: 285 | BV6: 995 | BW6: 996 | BX6: 997 | BY6: 766 | BZ6: 926 | CA6: 924 | CB6: 103 | CC6: 104 | CD6: 106 | CE6: 105 | CF6: 107 | CG6: 110 | CH6: 109 | CI6: 144 | CJ6: 113 | CK6: 114 | CL6: 193 | CM6: 208 | CN6: 786 | CO6: 787 | CP6: 788 | CQ6: 789 | CR6: 248 | CS6: 2159 | CT6: 303 | CU6: 59715 | CV6: 62255 | CW6: 1263 | CX6: 61800 | CY6: 2194 | CZ6: 216 | DA6: 198 | DB6: 214 | DC6: 260 | DD6: 2152 | DE6: 2128 | DF6: 247 | DG6: 228 | DH6: 2135 | DI6: 261 | DJ6: 237 | DK6: 253 | DL6: 770 | DM6: 225 | DN6: 2201 | DO6: 2171 | DP6: 760 | DQ6: 235 | DR6: 238 | DS6: 2184 | DT6: 61855 | DU6: 223 | DV6: 226 | DW6: 201 | DX6: 258 | DY6: 259 | DZ6: 920 | EA6: 257 | EB6: 256 | EC6: 2148 | ED6: 58288 | EE6: 58289 | EF6: 58839 | EG6: 58840 | EH6: 296 | EI6: 297 | EJ6: 211 | EK6: 2175 | EL6: 2178 | EM6: 2181 | EN6: 1262 | EO6: 233 | EP6: 2150 | EQ6: 2165 | ER6: 2161 | ES6: 61197 | ET6: 58851 | EU6: 234 | EV6: 215 | EW6: 917 | EX6: 289 | EY6: 58333 | EZ6: 58336 | FA6: 202 | FB6: 58487 | FC6: 213 | FD6: 232 | FE6: 2190 | FF6: TOTAL COES | FH6: 221 | FI6: 49607 | FJ6: 222 | FK6: 224 | FL6: 2187 | FM6: 227 | FN6: 49400 | FO6: 199 | FP6: 200 | FQ6: TOTAL NO COES
C7: CENTRO | D7: CENTRO | E7: NORTE | F7: CENTRO | G7: CENTRO | H7: NORTE | I7: NORTE | J7: NORTE | K7: NORTE | L7: CENTRO | M7: CENTRO | N7: CENTRO | O7: CENTRO | P7: CENTRO | Q7: CENTRO | R7: CENTRO | S7: CENTRO | T7: CENTRO | U7: CENTRO | V7: CENTRO | W7: CENTRO | X7: CENTRO | Y7: CENTRO | Z7: SUR | AA7: SUR | AB7: CENTRO | AC7: SUR | AD7: SUR | AE7: SUR | AF7: SUR | AG7: SUR | AH7: SUR | AI7: SUR | AJ7: SUR | AK7: CENTRO | AL7: NORTE | AM7: NORTE | AN7: NORTE | AO7: CENTRO | AP7: CENTRO | AQ7: CENTRO | AR7: CENTRO | AS7: CENTRO | AT7: CENTRO | AU7: CENTRO | AV7: SUR | AW7: CENTRO | AX7: CENTRO | AY7: CENTRO | AZ7: CENTRO | BA7: CENTRO | BB7: CENTRO | BC7: CENTRO | BD7: CENTRO | BE7: SUR | BF7: NORTE | BG7: CENTRO | BH7: CENTRO | BI7: NORTE | BJ7: NORTE | BK7: NORTE | BL7: SUR | BM7: SUR | BN7: SUR | BO7: CENTRO | BP7: CENTRO | BQ7: CENTRO | BR7: CENTRO | BS7: CENTRO | BT7: CENTRO | BU7: CENTRO | BV7: SUR | BW7: SUR | BX7: SUR | BY7: NORTE | BZ7: SUR | CA7: CENTRO | CB7: CENTRO | CC7: CENTRO | CD7: CENTRO | CE7: CENTRO | CF7: CENTRO | CG7: CENTRO | CH7: CENTRO | CI7: CENTRO | CJ7: CENTRO | CK7: CENTRO | CL7: CENTRO | CM7: CENTRO | CN7: SUR | CO7: SUR | CP7: SUR | CQ7: SUR | CR7: CENTRO | CS7: CENTRO | CT7: CENTRO | CU7: CENTRO | CV7: SUR | CW7: NORTE | CX7: NORTE | CY7: NORTE | CZ7: NORTE | DA7: NORTE | DB7: CENTRO | DC7: CENTRO | DD7: CENTRO | DE7: NORTE | DF7: NORTE | DG7: CENTRO | DH7: CENTRO | DI7: SUR | DJ7: SUR | DK7: CENTRO | DL7: CENTRO | DM7: CENTRO | DN7: CENTRO | DO7: CENTRO | DP7: CENTRO | DQ7: SUR | DR7: CENTRO | DS7: CENTRO | DT7: NORTE | DU7: CENTRO | DV7: CENTRO | DW7: NORTE | DX7: CENTRO | DY7: CENTRO | DZ7: CENTRO | EA7: NORTE | EB7: NORTE | EC7: SUR | ED7: CENTRO | EE7: CENTRO | EF7: CENTRO | EG7: CENTRO | EH7: CENTRO | EI7: CENTRO | EJ7: SUR | EK7: SUR | EL7: SUR | EM7: SUR | EN7: NORTE | EO7: SUR | EP7: SUR | EQ7: CENTRO | ER7: CENTRO | ES7: CENTRO | ET7: SUR | EU7: SUR | EV7: NORTE | EW7: CENTRO | EX7: NORTE | EY7: NORTE | EZ7: NORTE | FA7: CENTRO | FB7: CENTRO | FC7: CENTRO | FD7: NORTE | FE7: NORTE | FH7: NORTE | FI7: SUR | FJ7: CENTRO | FK7: NORTE | FL7: NORTE | FM7: NORTE | FN7: NORTE | FO7: NORTE | FP7: NORTE
C8: HIDROELÉCTRICA | D8: HIDROELÉCTRICA | E8: HIDROELÉCTRICA | F8: HIDROELÉCTRICA | G8: HIDROELÉCTRICA | H8: TERMOELÉCTRICA | I8: TERMOELÉCTRICA | J8: HIDROELÉCTRICA | K8: HIDROELÉCTRICA | L8: TERMOELÉCTRICA | M8: TERMOELÉCTRICA | N8: TERMOELÉCTRICA | O8: TERMOELÉCTRICA | P8: TERMOELÉCTRICA | Q8: TERMOELÉCTRICA | R8: TERMOELÉCTRICA | S8: TERMOELÉCTRICA | T8: HIDROELÉCTRICA | U8: HIDROELÉCTRICA | V8: TERMOELÉCTRICA | W8: TERMOELÉCTRICA | X8: TERMOELÉCTRICA | Y8: TERMOELÉCTRICA | Z8: HIDROELÉCTRICA | AA8: HIDROELÉCTRICA | AB8: TERMOELÉCTRICA | AC8: HIDROELÉCTRICA | AD8: HIDROELÉCTRICA | AE8: HIDROELÉCTRICA | AF8: HIDROELÉCTRICA | AG8: TERMOELÉCTRICA | AH8: TERMOELÉCTRICA | AI8: TERMOELÉCTRICA | AJ8: HIDROELÉCTRICA | AK8: HIDROELÉCTRICA | AL8: TERMOELÉCTRICA | AM8: TERMOELÉCTRICA | AN8: TERMOELÉCTRICA | AO8: HIDROELÉCTRICA | AP8: HIDROELÉCTRICA | AQ8: HIDROELÉCTRICA | AR8: HIDROELÉCTRICA | AS8: HIDROELÉCTRICA | AT8: HIDROELÉCTRICA | AU8: HIDROELÉCTRICA | AV8: HIDROELÉCTRICA | AW8: TERMOELÉCTRICA | AX8: TERMOELÉCTRICA | AY8: TERMOELÉCTRICA | AZ8: HIDROELÉCTRICA | BA8: HIDROELÉCTRICA | BB8: HIDROELÉCTRICA | BC8: HIDROELÉCTRICA | BD8: HIDROELÉCTRICA | BE8: HIDROELÉCTRICA | BF8: HIDROELÉCTRICA | BG8: HIDROELÉCTRICA | BH8: HIDROELÉCTRICA | BI8: TERMOELÉCTRICA | BJ8: TERMOELÉCTRICA | BK8: TERMOELÉCTRICA | BL8: TERMOELÉCTRICA | BM8: TERMOELÉCTRICA | BN8: TERMOELÉCTRICA | BO8: HIDROELÉCTRICA | BP8: TERMOELÉCTRICA | BQ8: TERMOELÉCTRICA | BR8: TERMOELÉCTRICA | BS8: TERMOELÉCTRICA | BT8: TERMOELÉCTRICA | BU8: TERMOELÉCTRICA | BV8: TERMOELÉCTRICA | BW8: TERMOELÉCTRICA | BX8: TERMOELÉCTRICA | BY8: HIDROELÉCTRICA | BZ8: TERMOELÉCTRICA | CA8: TERMOELÉCTRICA | CB8: HIDROELÉCTRICA | CC8: HIDROELÉCTRICA | CD8: HIDROELÉCTRICA | CE8: HIDROELÉCTRICA | CF8: HIDROELÉCTRICA | CG8: TERMOELÉCTRICA | CH8: TERMOELÉCTRICA | CI8: TERMOELÉCTRICA | CJ8: TERMOELÉCTRICA | CK8: TERMOELÉCTRICA | CL8: TERMOELÉCTRICA | CM8: TERMOELÉCTRICA | CN8: TERMOELÉCTRICA | CO8: TERMOELÉCTRICA | CP8: TERMOELÉCTRICA | CQ8: TERMOELÉCTRICA | CR8: TERMOELÉCTRICA | CS8: TERMOELÉCTRICA | CT8: SOLAR | CU8: EÓLICA | CV8: SOLAR | CW8: EÓLICA | CX8: SOLAR | CY8: HIDROELÉCTRICA | CZ8: HIDROELÉCTRICA | DA8: HIDROELÉCTRICA | DB8: HIDROELÉCTRICA | DC8: HIDROELÉCTRICA | DD8: HIDROELÉCTRICA | DE8: HIDROELÉCTRICA | DF8: HIDROELÉCTRICA | DG8: HIDROELÉCTRICA | DH8: HIDROELÉCTRICA | DI8: SOLAR | DJ8: SOLAR | DK8: EÓLICA | DL8: EÓLICA | DM8: TERMOELÉCTRICA | DN8: TERMOELÉCTRICA | DO8: TERMOELÉCTRICA | DP8: TERMOELÉCTRICA | DQ8: SOLAR | DR8: HIDROELÉCTRICA | DS8: HIDROELÉCTRICA | DT8: HIDROELÉCTRICA | DU8: HIDROELÉCTRICA | DV8: HIDROELÉCTRICA | DW8: HIDROELÉCTRICA | DX8: HIDROELÉCTRICA | DY8: HIDROELÉCTRICA | DZ8: HIDROELÉCTRICA | EA8: EÓLICA | EB8: EÓLICA | EC8: SOLAR | ED8: EÓLICA | EE8: EÓLICA | EF8: EÓLICA | EG8: EÓLICA | EH8: HIDROELÉCTRICA | EI8: HIDROELÉCTRICA | EJ8: HIDROELÉCTRICA | EK8: HIDROELÉCTRICA | EL8: HIDROELÉCTRICA | EM8: HIDROELÉCTRICA | EN8: EÓLICA | EO8: SOLAR | EP8: SOLAR | EQ8: HIDROELÉCTRICA | ER8: EÓLICA | ES8: EÓLICA | ET8: SOLAR | EU8: SOLAR | EV8: HIDROELÉCTRICA | EW8: HIDROELÉCTRICA | EX8: TERMOELÉCTRICA | EY8: TERMOELÉCTRICA | EZ8: TERMOELÉCTRICA | FA8: TERMOELÉCTRICA | FB8: TERMOELÉCTRICA | FC8: TERMOELÉCTRICA | FD8: TERMOELÉCTRICA | FE8: TERMOELÉCTRICA | FH8: HIDROELÉCTRICA | FI8: HIDROELÉCTRICA | FJ8: HIDROELÉCTRICA | FK8: HIDROELÉCTRICA | FL8: HIDROELÉCTRICA | FM8: TERMOELÉCTRICA | FN8: TERMOELÉCTRICA | FO8: HIDROELÉCTRICA | FP8: HIDROELÉCTRICA
