Workbook

Sheet EVENTOS
B3: jueves, 20 de Marzo del 2025
B5: INFORMACIÓN DE EVENTOS PRINCIPALES EN SUS INSTALACIONES
B6: TIPO DE EVENTO | C6: EMPRESA | D6: UBICACIÓN | E6: TIPO DE EQUIPO | F6: EQUIPO | G6: INICIO | H6: FINAL | I6: DESCRIPCIÓN | J6: MW INDISP. | K6: INTERRUPCIÓN (SI/NO) | L6: TENSIÓN DE FALLA (kV)
B7: FALLA | C7: ATN 2 S.A. | D7: COTARUSE - LAS BAMBAS | E7: LINEA DE TRANSMISION | F7: L-2055 | G7: 20/03/2025 14:51:00 | H7: 20/03/2025 14:51:00 | I7: RECIERRE EXITOSO EN LAS LÍNEAS L-2055 Y L-2056 (COTARUSE - LAS BAMBAS) EN 220 KV | J7: 94.08 | K7: SI | L7: 220
B8: EVENTO | C8: CONELSUR LT SAC | D8: PORTILLO | E8: SUBESTACION | F8: SS.EE. | G8: 20/03/2025 00:00:00 | H8: 21/03/2025 00:00:00 | I8: DECLARACIÓN DE SITUACIÓN EXCEPCIONAL EN LA S.E. PORTILLO DE 60 kV | K8: NO
B9: EVENTO | C9: RED DE ENERGIA DEL PERU S.A. | D9: TINGO MARÍA - AUCAYACU | E9: LINEA DE TRANSMISION | F9: L-1122 | G9: 20/03/2025 10:03:00 | H9: 20/03/2025 13:06:00 | I9: DECLARACIÓN DE SITUACIÓN EXCEPCIONAL EN LA LÍNEA L-1122 (TINGO MARÍA - AUCAYACU) DE 138 kV | K9: NO
B10: EVENTO | C10: RED DE ENERGIA DEL PERU S.A. | D10: TINGO MARÍA - AUCAYACU | E10: LINEA DE TRANSMISION | F10: L-1122 | G10: 20/03/2025 18:29:00 | H10: 20/03/2025 21:42:00 | I10: DECLARACIÓN DE SITUACIÓN EXCEPCIONAL EN LA LÍNEA L-1122 (TINGO MARÍA - AUCAYACU) DE 138 kV | K10: NO
B11: FALLA | C11: RED DE ENERGIA DEL PERU S.A. | D11: SAN JUAN | E11: BANCO DE CONDENSADOR PARALELO | F11: BC-08 | G11: 20/03/2025 15:12:19 | H11: 20/03/2025 15:30:26 | I11: DESCONEXIÓN DEL BANCO BC-08 DE LA S.E. SAN JUAN | K11: NO | L11: 60
B12: FALLA | C12: SAN GABAN | D12: MCH TUPURI | E12: CENTRAL HIDROELÉCTRICA | F12: CENTRAL | G12: 20/03/2025 08:36:00 | H12: 20/03/2025 09:41:00 | I12: DESCONEXIÓN DE LA C.H. TUPURI | K12: NO | L12: 2.4
B13: FALLA | C13: STATKRAFT S.A | D13: MISAPUQUIO | E13: CENTRAL HIDROELÉCTRICA | F13: CENTRAL | G13: 20/03/2025 16:06:12 | H13: 21/03/2025 00:00:00 | I13: DESCONEXIÓN DE LA C.H. MISAPUQUIO | K13: NO | L13: 0
B14: FALLA | C14: TRANSMANTARO | D14: COTARUSE - SOCABAYA | E14: LINEA DE TRANSMISION | F14: L-2054 | G14: 20/03/2025 13:03:16 | H14: 20/03/2025 13:03:16 | I14: RECIERRE EN LA LÍNEA L-2054 (COTARUSE - SOCABAYA) DE 220 kV | K14: NO | L14: 220

Sheet RESTRIC_OPE
B3: jueves, 20 de Marzo del 2025
B5: RESTRICCIONES OPERATIVAS
B6: FECHA | C6: HORA INICIO | D6: HORA FINAL | E6: EMPRESA | F6: UBICACIÓN | G6: T.Eq. | H6: EQUIPO | I6: DESCRIPCIÓN
B7: 20/03/2025 | C7: 00:00 | D7: 24:00 | E7: CELEPSA | F7: C.H. EL PLATANAL | G7: CH | H7: CENTRAL | I7: Debido al incremento del caudal del rio cañete y establecimiento de la temporada de avenida, se declara la C.H. El Platanal como CENTRAL HIDRÁULICA DE PASADA (correo 03/01/2025).
B8: 20/03/2025 | C8: 00:00 | D8: 24:00 | E8: EGASA | F8: C.H. CHARCANI II | G8: GH | H8: G2 | I8: El Grupo N°02 esta operando con una potencia no mayor a 0.07MW en referencia a 0.18MW de su potencia efectiva, con el fin de no generar daños mayores hasta la reparación de su cojinete.
B9: 20/03/2025 | C9: 00:00 | D9: 24:00 | E9: EGASA | F9: S.E. CONVERTIDOR | G9: BARRA | H9: BARRA138KV | I9: EGASA limitó la capacidad del transformador 138 kV/33 kV a 50 MVA por deterioro del aislamiento.
B10: 20/03/2025 | C10: 00:00 | D10: 24:00 | E10: ENEL GENERACION PIURA S.A. | F10: C.T. MALACAS | G10: CT | H10: CENTRAL | I10: De acuerdo con la comunicación vía correo del día 24.10.2024. ENEL GENERACIÓN PIURA informa una restricción de potencia para alcanzar 105 MW en simultaneo (TG6+TGN4).
B11: 20/03/2025 | C11: 00:00 | D11: 24:00 | E11: ENGIE | F11: C.E. PUNTA LOMITAS | G11: CE | H11: CENTRAL | I11: De acuerdo a la carta ENG/737-2024 (Exp:202400007555). Limitación de cables de media tensión a 100 MW de los transformadores PLT1 y PLT2 de la CE Punta Lomitas. Quedan limitados a 200 MW la generación de CE Punta Lomitas y Punta Lomitas Extensión.
B12: 20/03/2025 | C12: 00:00 | D12: 24:00 | E12: ENGIE | F12: C.H. QUITARACSA | G12: CH | H12: CENTRAL | I12: De acuerdo con el correo del 23.04 se considera la operación continua de la CH Quitaracsa debido a que el sistema de refrigeración de la CH Cañón del Pato se alimenta desde la descarga del caudal turbinado por la CH Quitaracsa.
B13: 20/03/2025 | C13: 00:00 | D13: 24:00 | E13: ENGIE | F13: C.H. YUNCÁN | G13: GH | H13: G3 | I13: Según la carta N° ENG/ 198-2024 enviada por su representada, se opera de forma continua el G3 de la CH Yuncán, debido a la ejecución de mantenimientos necesarios para evitar daños en los sellos de seguridad de la válvula esférica del grupo.
B14: 20/03/2025 | C14: 00:00 | D14: 24:00 | E14: ENGIE | F14: C.T. CHILCA 1 | G14: CT | H14: CENTRAL | I14: Restricción de temperatura de la C.T Chilca, ver valor en el modelo de despacho.
B15: 20/03/2025 | C15: 00:00 | D15: 24:00 | E15: ENGIE | F15: C.T. CHILCA 1 | G15: CT | H15: CENTRAL | I15: Con carta ENG/971-2023, indica que no puede cumplir con las IO considerada en el PDO_17122023 dado que vulneran la seguridad de sus activos. Indican que se debe tomar TMO=168h.
B16: 20/03/2025 | C16: 00:00 | D16: 24:00 | E16: ENGIE | F16: C.T. CHILCA 2 | G16: CT | H16: CENTRAL | I16: Restricción de temperatura de la C.T Chilca2, ver valor en el modelo de despacho.
B17: 20/03/2025 | C17: 00:00 | D17: 24:00 | E17: ENGIE | F17: C.T. CHILCA 2 | G17: CT | H17: CENTRAL | I17: Con carta ENG/971-2023, indica que no puede cumplir con las IO considerada en el PDO_17122023 dado que vulneran la seguridad de sus activos. Indican que se debe tomar TMO=168h.
... B50: 20/03/2025 | C50: 00:00 | D50: 24:00 | E50: TRANSMANTARO | F50: S.E. SOCABAYA | G50: SSEE | H50: S.E. | I50: Opera en simple barra en 220 kV por indisponibilidad de la protección diferencial de barras por alarma.

Sheet MANTENIMIENTO EJECUTADOS
B3: jueves, 20 de Marzo del 2025
B5: Mantenimiento Ejecutado
B6: Empresa | C6: Ubicación | D6: Equipo | E6: Inicio | F6: Final | G6: Descripción | H6: MW Indisp. | I6: Prog. | J6: Dispon | K6: Interrupc. | L6: Tipo | M6: CodEq | N6: TipoEq_Osinerg
B7: ASOCIACION SANTA LUCIA DE CHACAS | C7: CH HUALLIN | D7: CENTRAL | E7: 20/03/2025 10:00 | F7: 20/03/2025 14:01 | G7: DESARENADO DE BOCATOMA | H7: 3 | I7: P | J7: F/S | K7: N | L7: PREV. | M7: 23678 | N7: G
B8: ATLANTICA TRANSMISION SUR S.A. | C8: CHILCA-CTM | D8: INT-5261 | E8: 20/03/2025 00:00 | F8: 21/03/2025 00:00 | G8: Seccionador SBB-5261 fase S indisponible para maniobras de apertura y cierre por anomalia en tapa de tanque de compresion, el seccionador permanece cerrado y bloqueado. | H8: 0 | I8: P | J8: E/S | K8: N | L8: OTROS | M8: 13854 | N8: T
B9: ATLANTICA TRANSMISION SUR S.A. | C9: CHILCA-CTM | D9: INT-5251 | E9: 20/03/2025 08:00 | F9: 20/03/2025 16:56 | G9: Reparacion de Fuga de gas SF6 en INT-5251 fase T | H9: 0 | I9: P | J9: F/S | K9: N | L9: CORR. | M9: 13855 | N9: T
B10: ATLANTICA TRANSMISION SUR S.A. | C10: MONTALVO | D10: ACOPLE 220 | E10: 20/03/2025 00:00 | F10: 21/03/2025 00:00 | G10: Proyecto Refuerzos: Reemplazo del HMI existente, Pruebas y Configuracion. No se contara con nivel 1 de operacion. | H10: 0 | I10: P | J10: E/S | K10: N | L10: P.ENERG | M10: 14767 | N10: T
B11: ATLANTICA TRANSMISION SUR S.A. | C11: MONTALVO | D11: CL-2057 | E11: 20/03/2025 00:00 | F11: 21/03/2025 00:00 | G11: Proyecto Refuerzos: Reemplazo del HMI existente, Pruebas y Configuracion. No se contara con nivel 1 de operacion. | H11: 0 | I11: P | J11: E/S | K11: N | L11: P.ENERG | M11: 13812 | N11: T
B12: ATLANTICA TRANSMISION SUR S.A. | C12: MONTALVO | D12: CL-AUT-5671_500 | E12: 20/03/2025 00:00 | F12: 21/03/2025 00:00 | G12: Proyecto Refuerzos: Reemplazo del HMI existente, Pruebas y Configuracion. No se contara con nivel 1 de operacion en INT-5671, INT-5652 y SAT-5671. | H12: 0 | I12: P | J12: E/S | K12: N | L12: P.ENERG | M12: 13809 | N12: T
B13: ATLANTICA TRANSMISION SUR S.A. | C13: MONTALVO | D13: INT-5652 | E13: 20/03/2025 00:00 | F13: 21/03/2025 00:00 | G13: Proyecto Refuerzos:Indisponible por Implementacion de conexion de corrientes, disparos, posiciones, enclavamientos hacia los nuevos equipos del transformador. Pruebas y Puesta en servicio. AUT-5671 en servicio solo por Barra A 500kV. | H13: 0 | I13: P | J13: F/S | K13: N | L13: P.ENERG | M13: 13765 | N13: T
B14: ATLANTICA TRANSMISION SUR S.A. | C14: MONTALVO | D14: AUT-5671 | E14: 20/03/2025 08:34 | F14: 20/03/2025 17:38 | G14: Cambio de rele de mando sincronizado. Prueba de Interruptor INT-5671 | H14: 0 | I14: P | J14: F/S | K14: N | L14: CORR. | M14: 13784 | N14: T
B15: ATLANTICA TRANSMISION SUR S.A. | C15: OCONA | D15: INT-5450 | E15: 20/03/2025 00:00 | F15: 21/03/2025 00:00 | G15: RESTRICCION OPERATIVA EN INTERRUPTOR INT-5450, POSICION CERRADA, REB-5450 EN SERVICIO SUMINISTRANDO LOS SS.AA. DE S.E. OCO?A | H15: 0 | I15: P | J15: E/S | K15: N | L15: OTROS | M15: 13761 | N15: T
B16: ATLANTICA TRANSMISION SUR S.A. | C16: OCONA | D16: INT-5462 | E16: 20/03/2025 00:00 | F16: 21/03/2025 00:00 | G16: Seccionador SBA-5462 fase T indisponible por problemas mecanicos, el seccionador permanece cerrado y bloqueado | H16: 0 | I16: P | J16: E/S | K16: N | L16: OTROS | M16: 13758 | N16: T
B17: ATLANTICA TRANSMISION SUR S.A. | C17: POROMA | D17: ACOPLE 220 | E17: 20/03/2025 00:00 | F17: 21/03/2025 00:00 | G17: Proyecto Refuerzos: Reemplazo del HMI existente, Pruebas y Configuracion. No se contara con nivel 1 de operacion. | H17: 0 | I17: P | J17: E/S | K17: N | L17: P.ENERG | M17: 13797 | N17: T
B18: ATLANTICA TRANSMISION SUR S.A. | C18: POROMA | D18: CL-2292 | E18: 20/03/2025 00:00 | F18: 21/03/2025 00:00 | G18: Proyecto Refuerzos: Reemplazo del HMI existente, Pruebas y Configuracion. No se contara con nivel 1 de operacion. | H18: 0 | I18: P | J18: E/S | K18: N | L18: P.ENERG | M18: 13798 | N18: T
... B127: TRANSMANTARO | C127: YARABAMBA | D127: IN-5120 | E127: 20/03/2025 00:00 | F127: 21/03/2025 00:00 | G127: INTERRUPTOR INDISPONIBLE POR FALLA EN LOS MANDOS DE CONTROL DE N1, N2 Y N3. | H127: 0 | I127: P | J127: F/S | K127: N | L127: OTROS | M127: 17437 | N127: T

Sheet INGRESO OC
A3: jueves, 20 de Marzo del 2025
A5: INGRESO A OPERACIÓN COMERCIAL
A6: EMPRESA | B6: TIPO DE EQUIPO | C6: UBICACIÓN | D6: EQUIPO | E6: Fecha y hora de Ingreso a Operación Comercial

Sheet DESPACHO_EJECUTADO
B3: jueves, 20 de Marzo del 2025
A5: POTENCIA ACTIVA EJECUTADA DE LAS UNIDADES DE GENERACIÓN DEL SEIN (MW) | FJ5: CENTRALES NO INTEGRANTES COES
A6: FECHA | B6: HORA | C6: 337 | D6: 338 | E6: 101 | F6: 102 | G6: 42667 | H6: 42668 | I6: 126 | J6: 127 | K6: 138 | L6: 139 | M6: 197 | N6: 203 | O6: 204 | P6: 230 | Q6: 209 | R6: 56677 | S6: 796 | T6: 2146 | U6: 142 | V6: 143 | W6: 125 | X6: 187 | Y6: 163 | Z6: 298 | AA6: 299 | AB6: 219 | AC6: 151 | AD6: 152 | AE6: 153 | AF6: 154 | AG6: 756 | AH6: 156 | AI6: 155 | AJ6: 182 | AK6: 212 | AL6: 758 | AM6: 263 | AN6: 265 | AO6: 775 | AP6: 777 | AQ6: 2154 | AR6: 150 | AS6: 149 | AT6: 188 | AU6: 2131 | AV6: 755 | AW6: 252 | AX6: 249 | AY6: 250 | AZ6: 117 | BA6: 267 | BB6: 268 | BC6: 119 | BD6: 120 | BE6: 189 | BF6: 122 | BG6: 266 | BH6: 251 | BI6: 115 | BJ6: 239 | BK6: 288 | BL6: 240 | BM6: 241 | BN6: 242 | BO6: 191 | BP6: 194 | BQ6: 196 | BR6: 207 | BS6: 236 | BT6: 795 | BU6: 285 | BV6: 995 | BW6: 996 | BX6: 997 | BY6: 766 | BZ6: 926 | CA6: 924 | CB6: 121 | CC6: 103 | CD6: 104 | CE6: 106 | CF6: 105 | CG6: 107 | CH6: 110 | CI6: 109 | CJ6: 144 | CK6: 113 | CL6: 114 | CM6: 193 | CN6: 208 | CO6: 786 | CP6: 787 | CQ6: 788 | CR6: 789 | CS6: 248 | CT6: 2159 | CU6: 303 | CV6: 59715 | CW6: 62255 | CX6: 1263 | CY6: 61800 | CZ6: 2194 | DA6: 216 | DB6: 198 | DC6: 49607 | DD6: 214 | DE6: 260 | DF6: 2152 | DG6: 2128 | DH6: 247 | DI6: 228 | DJ6: 2135 | DK6: 261 | DL6: 237 | DM6: 253 | DN6: 770 | DO6: 225 | DP6: 2201 | DQ6: 2171 | DR6: 760 | DS6: 235 | DT6: 238 | DU6: 2184 | DV6: 61855 | DW6: 223 | DX6: 226 | DY6: 201 | DZ6: 258 | EA6: 259 | EB6: 920 | EC6: 257 | ED6: 256 | EE6: 2148 | EF6: 58288 | EG6: 58289 | EH6: 58839 | EI6: 58840 | EJ6: 296 | EK6: 297 | EL6: 211 | EM6: 2175 | EN6: 2178 | EO6: 2181 | EP6: 1262 | EQ6: 233 | ER6: 2150 | ES6: 2165 | ET6: 2161 | EU6: 61197 | EV6: 58851 | EW6: 234 | EX6: 215 | EY6: 917 | EZ6: 289 | FA6: 58333 | FB6: 58336 | FC6: 202 | FD6: 58487 | FE6: 213 | FF6: 232 | FG6: 2190 | FH6: TOTAL COES | FJ6: 221 | FK6: 222 | FL6: 224 | FM6: 2187 | FN6: 227 | FO6: 49400 | FP6: 199 | FQ6: 200 | FR6: TOTAL NO COES
C7: CENTRO | D7: CENTRO | E7: CENTRO | F7: CENTRO | G7: NORTE | H7: NORTE | I7: NORTE | J7: NORTE | K7: CENTRO | L7: CENTRO | M7: CENTRO | N7: CENTRO | O7: CENTRO | P7: CENTRO | Q7: CENTRO | R7: CENTRO | S7: CENTRO | T7: CENTRO | U7: CENTRO | V7: CENTRO | W7: CENTRO | X7: CENTRO | Y7: SUR | Z7: SUR | AA7: SUR | AB7: CENTRO | AC7: SUR | AD7: SUR | AE7: SUR | AF7: SUR | AG7: SUR | AH7: SUR | AI7: SUR | AJ7: SUR | AK7: CENTRO | AL7: NORTE | AM7: NORTE | AN7: NORTE | AO7: CENTRO | AP7: CENTRO | AQ7: CENTRO | AR7: CENTRO | AS7: CENTRO | AT7: CENTRO | AU7: CENTRO | AV7: SUR | AW7: CENTRO | AX7: CENTRO | AY7: CENTRO | AZ7: CENTRO | BA7: CENTRO | BB7: CENTRO | BC7: CENTRO | BD7: CENTRO | BE7: SUR | BF7: NORTE | BG7: CENTRO | BH7: CENTRO | BI7: NORTE | BJ7: NORTE | BK7: NORTE | BL7: SUR | BM7: SUR | BN7: SUR | BO7: CENTRO | BP7: CENTRO | BQ7: CENTRO | BR7: CENTRO | BS7: CENTRO | BT7: CENTRO | BU7: CENTRO | BV7: SUR | BW7: SUR | BX7: SUR | BY7: NORTE | BZ7: SUR | CA7: CENTRO | CB7: NORTE | CC7: CENTRO | CD7: CENTRO | CE7: CENTRO | CF7: CENTRO | CG7: CENTRO | CH7: CENTRO | CI7: CENTRO | CJ7: CENTRO | CK7: CENTRO | CL7: CENTRO | CM7: CENTRO | CN7: CENTRO | CO7: SUR | CP7: SUR | CQ7: SUR | CR7: SUR | CS7: CENTRO | CT7: CENTRO | CU7: CENTRO | CV7: CENTRO | CW7: SUR | CX7: NORTE | CY7: NORTE | CZ7: NORTE | DA7: NORTE | DB7: NORTE | DC7: SUR | DD7: CENTRO | DE7: CENTRO | DF7: CENTRO | DG7: NORTE | DH7: NORTE | DI7: CENTRO | DJ7: CENTRO | DK7: SUR | DL7: SUR | DM7: CENTRO | DN7: CENTRO | DO7: CENTRO | DP7: CENTRO | DQ7: CENTRO | DR7: CENTRO | DS7: SUR | DT7: CENTRO | DU7: CENTRO | DV7: NORTE | DW7: CENTRO | DX7: CENTRO | DY7: NORTE | DZ7: CENTRO | EA7: CENTRO | EB7: CENTRO | EC7: NORTE | ED7: NORTE | EE7: SUR | EF7: CENTRO | EG7: CENTRO | EH7: CENTRO | EI7: CENTRO | EJ7: CENTRO | EK7: CENTRO | EL7: SUR | EM7: SUR | EN7: SUR | EO7: SUR | EP7: NORTE | EQ7: SUR | ER7: SUR | ES7: CENTRO | ET7: CENTRO | EU7: CENTRO | EV7: SUR | EW7: SUR | EX7: NORTE | EY7: CENTRO | EZ7: NORTE | FA7: NORTE | FB7: NORTE | FC7: CENTRO | FD7: CENTRO | FE7: CENTRO | FF7: NORTE | FG7: NORTE | FJ7: NORTE | FK7: CENTRO | FL7: NORTE | FM7: NORTE | FN7: NORTE | FO7: NORTE | FP7: NORTE | FQ7: NORTE
C8: HIDROELÉCTRICA | D8: HIDROELÉCTRICA | E8: HIDROELÉCTRICA | F8: HIDROELÉCTRICA | G8: TERMOELÉCTRICA | H8: TERMOELÉCTRICA | I8: HIDROELÉCTRICA | J8: HIDROELÉCTRICA | K8: TERMOELÉCTRICA | L8: TERMOELÉCTRICA | M8: TERMOELÉCTRICA | N8: TERMOELÉCTRICA | O8: TERMOELÉCTRICA | P8: TERMOELÉCTRICA | Q8: TERMOELÉCTRICA | R8: TERMOELÉCTRICA | S8: HIDROELÉCTRICA | T8: HIDROELÉCTRICA | U8: TERMOELÉCTRICA | V8: TERMOELÉCTRICA | W8: TERMOELÉCTRICA | X8: TERMOELÉCTRICA | Y8: HIDROELÉCTRICA | Z8: HIDROELÉCTRICA | AA8: HIDROELÉCTRICA | AB8: TERMOELÉCTRICA | AC8: HIDROELÉCTRICA | AD8: HIDROELÉCTRICA | AE8: HIDROELÉCTRICA | AF8: HIDROELÉCTRICA | AG8: TERMOELÉCTRICA | AH8: TERMOELÉCTRICA | AI8: TERMOELÉCTRICA | AJ8: HIDROELÉCTRICA | AK8: HIDROELÉCTRICA | AL8: TERMOELÉCTRICA | AM8: TERMOELÉCTRICA | AN8: TERMOELÉCTRICA | AO8: HIDROELÉCTRICA | AP8: HIDROELÉCTRICA | AQ8: HIDROELÉCTRICA | AR8: HIDROELÉCTRICA | AS8: HIDROELÉCTRICA | AT8: HIDROELÉCTRICA | AU8: HIDROELÉCTRICA | AV8: HIDROELÉCTRICA | AW8: TERMOELÉCTRICA | AX8: TERMOELÉCTRICA | AY8: TERMOELÉCTRICA | AZ8: HIDROELÉCTRICA | BA8: HIDROELÉCTRICA | BB8: HIDROELÉCTRICA | BC8: HIDROELÉCTRICA | BD8: HIDROELÉCTRICA | BE8: HIDROELÉCTRICA | BF8: HIDROELÉCTRICA | BG8: HIDROELÉCTRICA | BH8: HIDROELÉCTRICA | BI8: TERMOELÉCTRICA | BJ8: TERMOELÉCTRICA | BK8: TERMOELÉCTRICA | BL8: TERMOELÉCTRICA | BM8: TERMOELÉCTRICA | BN8: TERMOELÉCTRICA | BO8: HIDROELÉCTRICA | BP8: TERMOELÉCTRICA | BQ8: TERMOELÉCTRICA | BR8: TERMOELÉCTRICA | BS8: TERMOELÉCTRICA | BT8: TERMOELÉCTRICA | BU8: TERMOELÉCTRICA | BV8: TERMOELÉCTRICA | BW8: TERMOELÉCTRICA | BX8: TERMOELÉCTRICA | BY8: HIDROELÉCTRICA | BZ8: TERMOELÉCTRICA | CA8: TERMOELÉCTRICA | CB8: HIDROELÉCTRICA | CC8: HIDROELÉCTRICA | CD8: HIDROELÉCTRICA | CE8: HIDROELÉCTRICA | CF8: HIDROELÉCTRICA | CG8: HIDROELÉCTRICA | CH8: TERMOELÉCTRICA | CI8: TERMOELÉCTRICA | CJ8: TERMOELÉCTRICA | CK8: TERMOELÉCTRICA | CL8: TERMOELÉCTRICA | CM8: TERMOELÉCTRICA | CN8: TERMOELÉCTRICA | CO8: TERMOELÉCTRICA | CP8: TERMOELÉCTRICA | CQ8: TERMOELÉCTRICA | CR8: TERMOELÉCTRICA | CS8: TERMOELÉCTRICA | CT8: TERMOELÉCTRICA | CU8: SOLAR | CV8: EÓLICA | CW8: SOLAR | CX8: EÓLICA | CY8: SOLAR | CZ8: HIDROELÉCTRICA | DA8: HIDROELÉCTRICA | DB8: HIDROELÉCTRICA | DC8: HIDROELÉCTRICA | DD8: HIDROELÉCTRICA | DE8: HIDROELÉCTRICA | DF8: HIDROELÉCTRICA | DG8: HIDROELÉCTRICA | DH8: HIDROELÉCTRICA | DI8: HIDROELÉCTRICA | DJ8: HIDROELÉCTRICA | DK8: SOLAR | DL8: SOLAR | DM8: EÓLICA | DN8: EÓLICA | DO8: TERMOELÉCTRICA | DP8: TERMOELÉCTRICA | DQ8: TERMOELÉCTRICA | DR8: TERMOELÉCTRICA | DS8: SOLAR | DT8: HIDROELÉCTRICA | DU8: HIDROELÉCTRICA | DV8: HIDROELÉCTRICA | DW8: HIDROELÉCTRICA | DX8: HIDROELÉCTRICA | DY8: HIDROELÉCTRICA | DZ8: HIDROELÉCTRICA | EA8: HIDROELÉCTRICA | EB8: HIDROELÉCTRICA | EC8: EÓLICA | ED8: EÓLICA | EE8: SOLAR | EF8: EÓLICA | EG8: EÓLICA | EH8: EÓLICA | EI8: EÓLICA | EJ8: HIDROELÉCTRICA | EK8: HIDROELÉCTRICA | EL8: HIDROELÉCTRICA | EM8: HIDROELÉCTRICA | EN8: HIDROELÉCTRICA | EO8: HIDROELÉCTRICA | EP8: EÓLICA | EQ8: SOLAR | ER8: SOLAR | ES8: HIDROELÉCTRICA | ET8: EÓLICA | EU8: EÓLICA | EV8: SOLAR | EW8: SOLAR | EX8: HIDROELÉCTRICA | EY8: HIDROELÉCTRICA | EZ8: TERMOELÉCTRICA | FA8: TERMOELÉCTRICA | FB8: TERMOELÉCTRICA | FC8: TERMOELÉCTRICA | FD8: TERMOELÉCTRICA | FE8: TERMOELÉCTRICA | FF8: TERMOELÉCTRICA | FG8: TERMOELÉCTRICA | FJ8: HIDROELÉCTRICA | FK8: HIDROELÉCTRICA | FL8: HIDROELÉCTRICA | FM8: HIDROELÉCTRICA | FN8: TERMOELÉCTRICA | FO8: TERMOELÉCTRICA | FP8: HIDROELÉCTRICA | FQ8: HIDROELÉCTRICA
C9: CENTRALES SANTA ROSA S.A.C. | D9: CENTRALES SANTA ROSA S.A.C. | E9: ELECTROPERU | F9: ELECTROPERU | G9: ELECTROPERU | H9: ELECTROPERU | I9: ORAZUL ENERGY PERÚ | J9: ORAZUL ENERGY PERÚ | K9: TERMOSELVA | L9: TERMOSELVA | M9: KALLPA GENERACION S.A. | N9: KALLPA GENERACION S.A. | O9: KALLPA GENERACION S.A. | P9: KALLPA GENERACION S.A. | Q9: KALLPA GENERACION S.A. | R9: KALLPA GENERACION S.A. | S9: KALLPA GENERACION S.A. | T9: KALLPA GENERACION S.A. | U9: SHOUGESA | V9: SHOUGESA | W9: SHOUGESA | X9: SHOUGESA | Y9: EGEMSA | Z9: EGESUR | AA9: EGESUR | AB9: EGESUR | AC9: EGASA | AD9: EGASA | AE9: EGASA | AF9: EGASA | AG9: EGASA | AH9: EGASA | AI9: EGASA | AJ9: SAN GABAN | AK9: CELEPSA | AL9: MINERA CERRO VERDE | AM9: PLANTA DE RESERVA FRIA DE GENERACION DE ETEN S.A. | AN9: PLANTA DE RESERVA FRIA DE GENERACION DE ETEN S.A. | AO9: EMPRESA DE GENERACION HUALLAGA | AP9: EMPRESA DE GENERACION HUALLAGA | AQ9: LA VIRGEN | AR9: CHINANGO S.A.C. | AS9: CHINANGO S.A.C. | AT9: HIDROELECTRICA HUANCHOR S.A.C. | AU9: CELEPSA RENOVABLES S.R.L. | AV9: INLAND ENERGY SAC | AW9: FENIX POWER PERÚ | AX9: FENIX POWER PERÚ | AY9: FENIX POWER PERÚ | AZ9: STATKRAFT S.A | BA9: STATKRAFT S.A | BB9: STATKRAFT S.A | BC9: STATKRAFT S.A | BD9: STATKRAFT S.A | BE9: STATKRAFT S.A | BF9: STATKRAFT S.A | BG9: STATKRAFT S.A | BH9: EMPRESA DE GENERACION HUANZA | BI9: ENEL GENERACION PIURA S.A. | BJ9: ENEL GENERACION PIURA S.A. | BK9: ENEL GENERACION PIURA S.A. | BL9: ENGIE | BM9: ENGIE | BN9: ENGIE | BO9: ENGIE | BP9: ENGIE | BQ9: ENGIE | BR9: ENGIE | BS9: ENGIE | BT9: ENGIE | BU9: ENGIE | BV9: ENGIE | BW9: ENGIE | BX9: ENGIE | BY9: ENGIE | BZ9: INFRAESTRUCTURAS Y ENERGIAS DEL PERU S.A.C. | CA9: INFRAESTRUCTURAS Y ENERGIAS DEL PERU S.A.C. | CB9: INVERSIONES SHAQSHA S.A.C. | CC9: ORYGEN PERU S.A.A. | CD9: ORYGEN PERU S.A.A. | CE9: ORYGEN PERU S.A.A. | CF9: ORYGEN PERU S.A.A. | CG9: ORYGEN PERU S.A.A. | CH9: ORYGEN PERU S.A.A. | CI9: ORYGEN PERU S.A.A. | CJ9: ORYGEN PERU S.A.A. | CK9: ORYGEN PERU S.A.A. | CL9: ORYGEN PERU S.A.A. | CM9: ORYGEN PERU S.A.A. | CN9: ORYGEN PERU S.A.A. | CO9: SAMAY I S.A.C | CP9: SAMAY I S.A.C | CQ9: SAMAY I S.A.C | CR9: SAMAY I S.A.C | CS9: TERMOCHILCA S.A.C. | CT9: TERMOCHILCA S.A.C. | CU9: COLCA SOLAR S.A.C. | CV9: ENERGIA RENOVABLE DEL SUR S.A. | CW9: GR CORTARRAMA SOCIEDAD ANONIMA CERRADA | CX9: GR TARUCA SOCIEDAD ANONIMA CERRADA | CY9: KONDU SAC | CZ9: PERUANA DE INVERSIONES EN ENERGIAS RENOVABLES S.A. | DA9: ORAZUL ENERGY PERÚ | DB9: ORAZUL ENERGY PERÚ | DC9: SAN GABAN | DD9: MAJA ENERGIA S.A.C. | DE9: EMPRESA DE GENERACION ELECTRICA CANCHAYLLO SAC | DF9: EMPRESA DE GENERACION ELECTRICA SANTA ANA S.A.C. | DG9: EMPRESA ELECTRICA AGUA AZUL | DH9: EMPRESA ELECTRICA RIO DOBLE | DI9: HIDROCAÑETE S.A. | DJ9: HUAURA POWER GROUP S.A. | DK9: MOQUEGUA FV S.A.C. | DL9: PANAMERICANA SOLAR SAC. | DM9: PARQUE EOLICO MARCONA S.A.C. | DN9: PARQUE EOLICO TRES HERMANAS S.A.C. | DO9: PETRAMAS | DP9: PETRAMAS | DQ9: PETRAMAS | DR9: PETRAMAS | DS9: TACNA SOLAR SAC. | DT9: ELECTRICA YANAPAMPA SAC | DU9: ANDEAN POWER S.A.C. | DV9: ASOCIACIÓN SANTA LUCIA DE CHACAS | DW9: ATRIA ENERGIA S.A.C. | DX9: EGEJUNIN | DY9: EGEJUNIN | DZ9: EGEJUNIN | EA9: EGEJUNIN | EB9: EMPRESA DE GENERACION ELECTRICA RIO BAÑOS S.A.C. | EC9: ENERGÍA EÓLICA S.A. | ED9: ENERGÍA EÓLICA S.A. | EE9: ENGIE | EF9: ENGIE | EG9: ENGIE | EH9: ENGIE | EI9: ENGIE | EJ9: GENERACIÓN ANDINA S.A.C. | EK9: GENERACIÓN ANDINA S.A.C. | EL9: GENERADORA DE ENERGÍA DEL PERÚ | EM9: GENERADORA DE ENERGÍA DEL PERÚ | EN9: GENERADORA DE ENERGÍA DEL PERÚ | EO9: GENERADORA DE ENERGÍA DEL PERÚ | EP9: GR PAINO SOCIEDAD ANONIMA CERRADA | EQ9: MAJES ARCUS S.A.C. | ER9: ORYGEN PERU S.A.A. | ES9: ORYGEN PERU S.A.A. | ET9: ORYGEN PERU S.A.A. | EU9: ORYGEN PERU S.A.A. | EV9: ORYGEN PERU S.A.A. | EW9: REPARTICIÓN ARCUS S.A.C. | EX9: SINERSA | EY9: SINERSA | EZ9: BIOENERGIA DEL CHIRA S.A. | FA9: GM OPERACIONES S.A.C. | FB9: GM OPERACIONES S.A.C. | FC9: SDF ENERGIA SAC | FD9: SDF ENERGIA SAC | FE9: AGRO INDUSTRIAL PARAMONGA S.A. | FF9: AGROAURORA S.A.C. | FG9: AGROINDUSTRIAS SAN JACINTO S.A.A. | FJ9: UNACEM PERU S.A. | FK9: ELECTRO ORIENTE | FL9: AGUAS Y ENERGIA PERU | FM9: ELECTRO ZAÑA S.A.C. | FN9: ELECTRONOROESTE S.A. | FO9: SDE PIURA | FP9: SINERSA | FQ9: SINERSA
C10: SANTA ROSA 1 | D10: SANTA ROSA 2 | E10: MANTARO | F10: RESTITUCION | G10: TUMBES MAK 1 | H10: TUMBES MAK 2 | I10: CARHUAQUERO | J10: CAÑON DEL PATO | K10: AGUAYTIA TG1 | L10: AGUAYTIA TG2 | M10: KALLPA TG1 | N10: KALLPA TG2 | O10: KALLPA TG3 | P10: KALLPA TV | Q10: LFLORES TG1 | R10: LFLORES TV | S10: CERRO DEL AGUILA | T10: CERRODELAGUILAG4 | U10: SHOUGESA TV1 | V10: SHOUGESA TV2 | W10: SHOUGESA TV3 | X10: SHOUGESA CUMMINS | Y10: MACHUPICCHU | Z10: ARICOTA 1 | AA10: ARICOTA 2 | AB10: INDEPENDENCIA | AC10: CHARCANI I,II,III | AD10: CHARCANI IV | AE10: CHARCANI V | AF10: CHARCANI VI | AG10: CHILINA TG | AH10: MOLLENDO 1, 2, 3 | AI10: CHILINA (SULZ 1,2) | AJ10: SAN GABAN II | AK10: PLATANAL | AL10: RECKA | AM10: RF ETEN TG1 | AN10: RF ETEN TG2 | AO10: CHAGLLA GP1 | AP10: CHAGLLA | AQ10: LA VIRGEN | AR10: CHIMAY | AS10: YANANGO | AT10: HUANCHOR | AU10: MARAÑON | AV10: STA TERESA | AW10: FENIX GT11 | AX10: FENIX GT12 | AY10: FENIX TV10 | AZ10: YAUPI | BA10: OROYA | BB10: PACHACHACA | BC10: MALPASO | BD10: CAHUA | BE10: ARCATA | BF10: GALLITO CIEGO | BG10: CHEVES | BH10: HUANZA | BI10: MALACAS2 TG4 | BJ10: MALACAS3 TG 5 | BK10: MALACAS1 TG6 | BL10: RF ILO2 TG1 | BM10: RF ILO2 TG2 | BN10: RF ILO2 TG3 | BO10: YUNCAN | BP10: CHILCA1 TG1 | BQ10: CHILCA1 TG2 | BR10: CHILCA1 TG3 | BS10: CHILCA-TV | BT10: CHILCA2 TG41 | BU10: CHILCA2-TV | BV10: CTNEPI_TG41 | BW10: CTNEPI_TG42 | BX10: CTNEPI_TG43 | BY10: QUITARACSA | BZ10: RF PTO MALDONADO | CA10: RF PUCALLPA | CB10: PARIAC | CC10: HUINCO | CD10: MATUCANA | CE10: MOYOPAMPA | CF10: CALLAHUANCA | CG10: HUAMPANI | CH10: STA ROSA WEST TG7 | CI10: UTI_5 | CJ10: UTI_6 | CK10: VENTANILLA 3 | CL10: VENTANILLA 4 | CM10: VENTANILLA TV | CN10: STAROSA TG8 | CO10: PTO_BRVO TG1 | CP10: PTO_BRVO TG2 | CQ10: PTO_BRVO TG3 | CR10: PTO_BRVO TG4 | CS10: OLLEROS TG1 | CT10: OLLEROS TV | CU10: CS YARUCAYA | CV10: SAN JUAN | CW10: MATARANI | CX10: DUNA | CY10: CARHUAQUERO (CS) | CZ10: MANTA I | DA10: CARHUAQUERO4 | DB10: CAÑA BRAVA | DC10: TUPURI | DD10: RONCADOR | DE10: CANCHAYLLO | DF10: RENOVANDESH1 | DG10: POTRERO | DH10: PIZARRAS | DI10: NIMPERIAL | DJ10: YARUCAYA | DK10: MOQUEGUA-SOLAR | DL10: PANAMERICANA-SOLAR | DM10: PQE-EOLICO-MARCONA | DN10: PQE-EOLICO-3-HERMANAS | DO10: HUAYCOLORO | DP10: CALLAO | DQ10: DONA_CATALINA | DR10: LAGRINGAV | DS10: TACNA-SOLAR | DT10: YANAPAMPA | DU10: CARHUAC | DV10: HUALLIN | DW10: PURMACANA | DX10: HUASAHUASI | DY10: STACRUZ_1_2 | DZ10: RUNATULLO_II | EA10: RUNATULLO_III | EB10: RUCUY | EC10: PQE-EOLICO-TALARA | ED10: PQE-EOLICO-CUPISNIQUE | EE10: INTIPAMPA | EF10: PUNTA LOMITAS-BL1 | EG10: PUNTA LOMITAS-BL2 | EH10: PUN LOMITAS_EXP-BL1 | EI10: PUN LOMITAS_EXP-BL2 | EJ10: 8AGOSTO | EK10: EL CARMEN | EL10: LA JOYA | EM10: ANGEL_I | EN10: ANGEL_II | EO10: ANGEL_III | EP10: HUAMBOS | EQ10: MAJES | ER10: RUBI | ES10: CH_HER1 | ET10: WAYRA-I | EU10: WAYRA EXTENSION | EV10: CLEMESI | EW10: REPARTICION | EX10: POECHOS2 | EY10: CHANCAY | EZ10: CANA BRAVA | FA10: REFINERIA TALARA TV1 | FB10: REFINERÍA TALARA TV2 | FC10: OQUENDO TG1 | FD10: OQUENDO TV1 | FE10: PARAMONGA | FF10: MAPLE | FG10: SAN_JACINTO | FH10: MW | FJ10: CARPAPATA | FK10: CENTRALES ELOR | FL10: PIAS1 | FM10: ZANA | FN10: TABLAZO | FO10: TALLANCA | FP10: CURUMUY | FQ10: POECHOS1 | FR10: MW
A11: 20/03/2025 | B11: 00:30 | C11: 0 | D11: 0 | E11: 593 | F11: 181.5 | I11: 90.2 | J11: 226.8 | M11: 116.5 | N11: 116.7 | O11: 116.7 | P11: 214.5 | Q11: 107.7 | R11: 67.7 | S11: 368.9 | T11: 10.5 | Y11: 162.9 | Z11: 7.5 | AA11: 2.9 | AB11: 0 | AC11: 6.2 | AD11: 10 | AE11: 143.4 | AF11: 9 | AJ11: 110.3 | AK11: 223.1 | AO11: 6.5 | AP11: 461.5 | AQ11: 81.9 | AR11: 129.9 | AS11: 42.3 | AT11: 18.5 | AU11: 19.7 | AV11: 89.5 | AW11: 121.6 | AX11: 121.5 | AY11: 151.7 | AZ11: 105.4 | BB11: 0 | BC11: 44.8 | BD11: 46.5 | BE11: 3.8 | BF11: 37.8 | BG11: 172.8 | BH11: 95.2 | BI11: 24.9 | BN11: 0 | BO11: 86.7 | BP11: 84.7 | BQ11: 0 | BR11: 84.7 | BS11: 109.4 | CB11: 1.5 | CC11: 221.7 | CD11: 117.4 | CE11: 64.4 | CF11: 78.5 | CG11: 30.2 | CL11: 120.5 | CM11: 57 | CU11: 0 | CV11: 95.3 | CW11: 0 | CX11: 17 | CY11: 0 | DA11: 10.3 | DB11: 5.5 | DC11: 1.3 | DD11: 1.8 | DE11: 5.1 | DF11: 20 | DG11: 18.2 | DH11: 19 | DI11: 3.4 | DJ11: 18.6 | DK11: 0 | DL11: 0 | DM11: 30.1 | DN11: 71.5 | DO11: 4.8 | DP11: 2.4 | DQ11: 2.4 | DR11: 2.3 | DS11: 0 | DT11: 3.3 | DU11: 20.3 | DV11: 3 | DW11: 0 | DX11: 19.8 | DY11: 13 | DZ11: 20.1 | EA11: 20.2 | EB11: 20 | EC11: 13.9 | ED11: 12.1 | EE11: 0 | EF11: 41.8 | EG11: 67 | EH11: 1.1 | EI11: 1 | EJ11: 21 | EK11: 4 | EL11: 6.7 | EM11: 20.4 | EN11: 20.4 | EO11: 20.2 | EP11: 13.4 | EQ11: 0 | ER11: 0 | ES11: 0.6 | ET11: 22.1 | EU11: 15.9 | EV11: 0 | EW11: 0 | EX11: 9 | EY11: 20 | FA11: 44 | FB11: 24.3 | FC11: 28.9 | FD11: 3.4 | FE11: 15.5 | FF11: 9.6 | FG11: 7.2 | FH11: 6610.7 | FJ11: 24.45276 | FK11: 8.068 | FM11: 13.2 | FO11: 9.47073 | FP11: 10.4 | FQ11: 16.1 | FR11: 81.69149
A12: 20/03/2025 | B12: 01:00 | C12: 0 | D12: 0 | E12: 598.5 | F12: 182.3 | I12: 85.2 | J12: 227.6 | M12: 107 | N12: 106.8 | O12: 106.9 | P12: 207.6 | Q12: 108 | R12: 68 | S12: 367.6 | T12: 10.5 | Y12: 165.3 | Z12: 7.5 | AA12: 3 | AB12: 0 | AC12: 6.1 | AD12: 10.2 | AE12: 143.4 | AF12: 9 | AJ12: 111.4 | AK12: 222.7 | AO12: 6.5 | AP12: 350.6 | AQ12: 81.9 | AR12: 124.9 | AS12: 42.2 | AT12: 18.5 | AU12: 19.7 | AV12: 90.1 | AW12: 122.9 | AX12: 122.8 | AY12: 151.8 | AZ12: 105.4 | BB12: 0 | BC12: 44.7 | BD12: 47.1 | BE12: 3.8 | BF12: 38.1 | BG12: 174.4 | BH12: 95.8 | BI12: 24.9 | BN12: 0 | BO12: 87.3 | BP12: 85.9 | BQ12: 0 | BR12: 85.5 | BS12: 108.5 | CB12: 1.5 | CC12: 207.4 | CD12: 112.8 | CE12: 65 | CF12: 79.6 | CG12: 30.7 | CL12: 120.7 | CM12: 57.5 | CU12: 0 | CV12: 94.5 | CW12: 0 | CX12: 14.6 | CY12: 0 | DA12: 10.3 | DB12: 5.4 | DC12: 1.3 | DD12: 1.8 | DE12: 5.2 | DF12: 20.4 | DG12: 18.4 | DH12: 19 | DI12: 3.5 | DJ12: 18.6 | DK12: 0 | DL12: 0 | DM12: 30.6 | DN12: 73.5 | DO12: 4.8 | DP12: 2.4 | DQ12: 2.4 | DR12: 2.3 | DS12: 0 | DT12: 3.1 | DU12: 20.3 | DV12: 3 | DW12: 0 | DX12: 19.8 | DY12: 13 | DZ12: 19.9 | EA12: 20.3 | EB12: 19.9 | EC12: 12 | ED12: 19.4 | EE12: 0 | EF12: 43.7 | EG12: 61.6 | EH12: 1.7 | EI12: 1.1 | EJ12: 21 | EK12: 4.2 | EL12: 6.7 | EM12: 20.4 | EN12: 20.4 | EO12: 20.2 | EP12: 9.4 | EQ12: 0 | ER12: 0 | ES12: 0.6 | ET12: 25.3 | EU12: 18.6 | EV12: 0 | EW12: 0 | EX12: 9 | EY12: 19.9 | FA12: 44.1 | FB12: 24.4 | FC12: 28.9 | FD12: 3.3 | FE12: 15.4 | FF12: 9.6 | FG12: 6.7 | FH12: 6459 | FJ12: 24.45244 | FK12: 8.067 | FM12: 13.2 | FO12: 9.47059 | FP12: 10.5 | FQ12: 16.2 | FR12: 81.89003
A13: 20/03/2025 | B13: 01:30 | C13: 0 | D13: 0 | E13: 598.5 | F13: 200 | I13: 87.1 | J13: 227.7 | M13: 114.6 | N13: 114 | O13: 114 | P13: 210.8 | Q13: 108.3 | R13: 68 | S13: 374.9 | T13: 10.5 | Y13: 163.1 | Z13: 7 | AA13: 3.2 | AB13: 0 | AC13: 6 | AD13: 10 | AE13: 143.6 | AF13: 8.9 | AJ13: 111 | AK13: 222.7 | AO13: 6.5 | AP13: 297.2 | AQ13: 81.9 | AR13: 133.8 | AS13: 42.2 | AT13: 18.5 | AU13: 19.7 | AV13: 90.2 | AW13: 122.2 | AX13: 122.2 | AY13: 151.7 | AZ13: 105.3 | BB13: 0 | BC13: 44.9 | BD13: 46.8 | BE13: 3.8 | BF13: 37.9 | BG13: 173.8 | BH13: 95.4 | BI13: 24.8 | BN13: 0 | BO13: 87 | BP13: 84.5 | BQ13: 0 | BR13: 84.3 | BS13: 109.1 | CB13: 1.5 | CC13: 230.6 | CD13: 120.4 | CE13: 64.6 | CF13: 79.6 | CG13: 30.8 | CL13: 120.2 | CM13: 56.6 | CU13: 0 | CV13: 94.5 | CW13: 0 | CX13: 12.7 | CY13: 0 | DA13: 10.3 | DB13: 5.4 | DC13: 1.3 | DD13: 1.7 | DE13: 5.2 | DF13: 20.3 | DG13: 18.9 | DH13: 18.9 | DI13: 3.5 | DJ13: 18.6 | DK13: 0 | DL13: 0 | DM13: 31.4 | DN13: 76.3 | DO13: 4.8 | DP13: 2.4 | DQ13: 2.4 | DR13: 2.5 | DS13: 0 | DT13: 3.2 | DU13: 20.3 | DV13: 3 | DW13: 0 | DX13: 19.8 | DY13: 13.1 | DZ13: 19.6 | EA13: 20.3 | EB13: 20 | EC13: 15.1 | ED13: 29.6 | EE13: 0 | EF13: 26.3 | EG13: 48.7 | EH13: 0.7 | EI13: 0 | EJ13: 21 | EK13: 4.3 | EL13: 6.7 | EM13: 20.4 | EN13: 20.4 | EO13: 20.2 | EP13: 8 | EQ13: 0 | ER13: 0 | ES13: 0.6 | ET13: 30 | EU13: 29.3 | EV13: 0 | EW13: 0 | EX13: 9 | EY13: 20 | FA13: 44.4 | FB13: 24.4 | FC13: 29 | FD13: 3.4 | FE13: 15.5 | FF13: 9.5 | FG13: 7 | FH13: 6485.8 | FJ13: 24.45051 | FK13: 8.068 | FM13: 13.2 | FO13: 9.47069 | FP13: 10.5 | FQ13: 16.1 | FR13: 81.7892
A14: 20/03/2025 | B14: 02:00 | C14: 0 | D14: 0 | E14: 598.6 | F14: 199.6 | I14: 87.5 | J14: 227.3 | M14: 113.3 | N14: 113.8 | O14: 115.1 | P14: 213.7 | Q14: 109.4 | R14: 68.4 | S14: 378.2 | T14: 10.5 | Y14: 165.9 | Z14: 7.1 | AA14: 3.8 | AB14: 0 | AC14: 6 | AD14: 10.1 | AE14: 144.3 | AF14: 8.9 | AJ14: 82.6 | AK14: 222.9 | AO14: 6.5 | AP14: 302.5 | AQ14: 47.4 | AR14: 132.4 | AS14: 42.3 | AT14: 18.5 | AU14: 19.7 | AV14: 90.7 | AW14: 123.7 | AX14: 124.8 | AY14: 152.5 | AZ14: 72.6 | BB14: 0 | BC14: 44.7 | BD14: 47.4 | BE14: 3.8 | BF14: 38.4 | BG14: 174.8 | BH14: 95.9 | BI14: 24.8 | BN14: 0 | BO14: 87.3 | BP14: 86.1 | BQ14: 0 | BR14: 86 | BS14: 108.5 | CB14: 1.5 | CC14: 230.7 | CD14: 120.5 | CE14: 65 | CF14: 79.6 | CG14: 30.8 | CL14: 120.9 | CM14: 57.6 | CU14: 0 | CV14: 92.6 | CW14: 0 | CX14: 12.7 | CY14: 0 | DA14: 10.3 | DB14: 5.4 | DC14: 1.2 | DD14: 1.7 | DE14: 5.1 | DF14: 20.4 | DG14: 18 | DH14: 18.9 | DI14: 3.5 | DJ14: 18.6 | DK14: 0 | DL14: 0 | DM14: 30.1 | DN14: 71.7 | DO14: 4.8 | DP14: 2.4 | DQ14: 2.4 | DR14: 2.5 | DS14: 0 | DT14: 3.3 | DU14: 20.3 | DV14: 3 | DW14: 0 | DX14: 19.8 | DY14: 13 | DZ14: 19.5 | EA14: 20.3 | EB14: 19.8 | EC14: 14.6 | ED14: 32.1 | EE14: 0 | EF14: 23.6 | EG14: 49.9 | EH14: 0.6 | EI14: 0.1 | EJ14: 21 | EK14: 4.3 | EL14: 6.6 | EM14: 20.4 | EN14: 20.4 | EO14: 20.2 | EP14: 9.7 | EQ14: 0 | ER14: 0 | ES14: 0.6 | ET14: 40.6 | EU14: 29.1 | EV14: 0 | EW14: 0 | EX14: 9 | EY14: 19.9 | FA14: 43.3 | FB14: 23.8 | FC14: 29 | FD14: 3.4 | FE14: 15.5 | FF14: 9.6 | FG14: 7.3 | FH14: 6420.8 | FJ14: 24.44629 | FK14: 8.066 | FM14: 13.2 | FO14: 9.4709 | FP14: 10.5 | FQ14: 16 | FR14: 81.68319
A15: 20/03/2025 | B15: 02:30 | C15: 0 | D15: 0 | E15: 599.7 | F15: 149 | I15: 91 | J15: 227.8 | M15: 108 | N15: 107.9 | O15: 107.8 | P15: 204.2 | Q15: 109.5 | R15: 67.2 | S15: 378.9 | T15: 10.4 | Y15: 164.9 | Z15: 7.7 | AA15: 3 | AB15: 0 | AC15: 5.9 | AD15: 10.1 | AE15: 144.2 | AF15: 8.9 | AJ15: 82.2 | AK15: 222.6 | AO15: 6.5 | AP15: 340.3 | AQ15: 40 | AR15: 135.1 | AS15: 42.3 | AT15: 18.5 | AU15: 19.7 | AV15: 88.1 | AW15: 121.3 | AX15: 121.6 | AY15: 152.2 | AZ15: 71.9 | BB15: 0 | BC15: 43.9 | BD15: 47 | BE15: 3.8 | BF15: 37.4 | BG15: 173.6 | BH15: 95.4 | BI15: 25.5 | BN15: 0 | BO15: 87.1 | BP15: 86.3 | BQ15: 0 | BR15: 85.6 | BS15: 109.3 | CB15: 1.5 | CC15: 236.7 | CD15: 135.9 | CE15: 64.6 | CF15: 79.6 | CG15: 30.2 | CL15: 122.5 | CM15: 58.4 | CU15: 0 | CV15: 92.6 | CW15: 0 | CX15: 14.4 | CY15: 0 | DA15: 10.3 | DB15: 5.5 | DC15: 1.2 | DD15: 1.7 | DE15: 5.1 | DF15: 20.1 | DG15: 18.4 | DH15: 19 | DI15: 3.5 | DJ15: 18.6 | DK15: 0 | DL15: 0 | DM15: 29.7 | DN15: 65.5 | DO15: 4.8 | DP15: 2.4 | DQ15: 2.4 | DR15: 2.5 | DS15: 0 | DT15: 3.3 | DU15: 20.3 | DV15: 3 | DW15: 0 | DX15: 19.8 | DY15: 13 | DZ15: 19.6 | EA15: 20.3 | EB15: 19.9 | EC15: 13.4 | ED15: 23.9 | EE15: 0 | EF15: 24.8 | EG15: 45.8 | EH15: 0.8 | EI15: 0.1 | EJ15: 21 | EK15: 4.3 | EL15: 6.6 | EM15: 20.4 | EN15: 20.4 | EO15: 20.2 | EP15: 11.8 | EQ15: 0 | ER15: 0 | ES15: 0.6 | ET15: 25.5 | EU15: 12.6 | EV15: 0 | EW15: 0 | EX15: 9.1 | EY15: 19.8 | FA15: 44.5 | FB15: 23.5 | FC15: 29.1 | FD15: 3.4 | FE15: 15.5 | FF15: 9.6 | FG15: 6.3 | FH15: 6342.6 | FJ15: 24.449 | FK15: 8.067 | FM15: 13.2 | FO15: 9.47089 | FP15: 10.5 | FQ15: 16.1 | FR15: 81.78689
A16: 20/03/2025 | B16: 03:00 | C16: 0 | D16: 0 | E16: 590 | F16: 148.4 | I16: 90.1 | J16: 225.1 | M16: 107.4 | N16: 107.3 | O16: 108 | P16: 205 | Q16: 108.5 | R16: 66.1 | S16: 367.6 | T16: 10.3 | Y16: 160.1 | Z16: 7.3 | AA16: 2.8 | AB16: 0 | AC16: 5.9 | AD16: 10.1 | AE16: 141.7 | AF16: 8.9 | AJ16: 81.1 | AK16: 221.6 | AO16: 6.5 | AP16: 296.7 | AQ16: 40 | AR16: 127.9 | AS16: 42.3 | AT16: 18.5 | AU16: 19.7 | AV16: 87.8 | AW16: 117.5 | AX16: 118 | AY16: 151.1 | AZ16: 72 | BB16: 0 | BC16: 44.3 | BD16: 46.5 | BE16: 3.8 | BF16: 37.4 | BG16: 171.3 | BH16: 95 | BI16: 25.4 | BN16: 0 | BO16: 85.8 | BP16: 86.2 | BQ16: 0 | BR16: 86.2 | BS16: 109.1 | CB16: 1.5 | CC16: 256.7 | CD16: 133.7 | CE16: 63.4 | CF16: 79.2 | CG16: 30 | CL16: 120.9 | CM16: 58.7 | CU16: 0 | CV16: 92 | CW16: 0 | CX16: 15 | CY16: 0 | DA16: 10.4 | DB16: 5.5 | DC16: 1.2 | DD16: 1.7 | DE16: 5.2 | DF16: 19.9 | DG16: 18.2 | DH16: 19 | DI16: 3.5 | DJ16: 18.6 | DK16: 0 | DL16: 0 | DM16: 31.6 | DN16: 65 | DO16: 4.8 | DP16: 2.4 | DQ16: 2.4 | DR16: 2.5 | DS16: 0 | DT16: 3.3 | DU16: 20.3 | DV16: 3 | DW16: 0 | DX16: 19.8 | DY16: 12.9 | DZ16: 19.4 | EA16: 20.2 | EB16: 19.8 | EC16: 11 | ED16: 22.4 | EE16: 0 | EF16: 23.4 | EG16: 48.9 | EH16: 0.7 | EI16: 0 | EJ16: 21 | EK16: 4.3 | EL16: 6.6 | EM16: 20.4 | EN16: 20.4 | EO16: 20.2 | EP16: 13.8 | EQ16: 0 | ER16: 0 | ES16: 0.6 | ET16: 24.8 | EU16: 12.1 | EV16: 0 | EW16: 0 | EX16: 9 | EY16: 19.8 | FA16: 44.4 | FB16: 23.6 | FC16: 29.1 | FD16: 3.4 | FE16: 15.5 | FF16: 9.6 | FG16: 6.9 | FH16: 6255.9 | FJ16: 24.44496 | FK16: 8.058 | FM16: 13.2 | FO16: 9.47079 | FP16: 10.5 | FQ16: 16 | FR16: 81.67375
A17: 20/03/2025 | B17: 03:30 | C17: 0 | D17: 0 | E17: 599.3 | F17: 165.2 | I17: 90.7 | J17: 226.6 | M17: 112.4 | N17: 112.6 | O17: 112.9 | P17: 209.3 | Q17: 107 | R17: 67.2 | S17: 398.6 | T17: 10.5 | Y17: 161.6 | Z17: 7.8 | AA17: 2.7 | AB17: 0 | AC17: 5.7 | AD17: 10 | AE17: 143.7 | AF17: 8.9 | AJ17: 82.5 | AK17: 223.2 | AO17: 6.5 | AP17: 394.2 | AQ17: 14.7 | AR17: 148.6 | AS17: 42.3 | AT17: 18.5 | AU17: 19.7 | AV17: 91.5 | AW17: 122.8 | AX17: 122.9 | AY17: 151.5 | AZ17: 30.4 | BB17: 0 | BC17: 44.4 | BD17: 47.1 | BE17: 3.8 | BF17: 37.7 | BG17: 174.3 | BH17: 95.7 | BI17: 25.1 | BN17: 0 | BO17: 61 | BP17: 85.1 | BQ17: 0 | BR17: 85 | BS17: 108.3 | CB17: 1.5 | CC17: 262.5 | CD17: 136.3 | CE17: 65.7 | CF17: 79.6 | CG17: 30.5 | CL17: 120.8 | CM17: 56.8 | CU17: 0 | CV17: 92 | CW17: 0 | CX17: 16 | CY17: 0 | DA17: 10.3 | DB17: 5.5 | DC17: 1.2 | DD17: 1.7 | DE17: 5.2 | DF17: 20.4 | DG17: 19.5 | DH17: 19 | DI17: 3.5 | DJ17: 18.6 | DK17: 0 | DL17: 0 | DM17: 30.5 | DN17: 60.9 | DO17: 4.8 | DP17: 2.4 | DQ17: 2.4 | DR17: 2.5 | DS17: 0 | DT17: 3.3 | DU17: 20.3 | DV17: 3 | DW17: 0 | DX17: 19.8 | DY17: 12.9 | DZ17: 19.4 | EA17: 20.3 | EB17: 20 | EC17: 8.3 | ED17: 16.5 | EE17: 0 | EF17: 15.7 | EG17: 36 | EH17: 0.4 | EI17: 0 | EJ17: 21 | EK17: 4.3 | EL17: 6.6 | EM17: 20.4 | EN17: 20.4 | EO17: 20.2 | EP17: 13.1 | EQ17: 0 | ER17: 0 | ES17: 0.6 | ET17: 12.2 | EU17: 6.1 | EV17: 0 | EW17: 0 | EX17: 9 | EY17: 20 | FA17: 44 | FB17: 23.3 | FC17: 29.1 | FD17: 3.3 | FE17: 15.4 | FF17: 9.6 | FG17: 7.2 | FH17: 6341.3 | FJ17: 24.44565 | FK17: 8.057 | FM17: 13.2 | FO17: 9.47039 | FP17: 10.5 | FQ17: 16 | FR17: 81.67304
A18: 20/03/2025 | B18: 04:00 | C18: 0 | D18: 0 | E18: 595.6 | F18: 202.7 | I18: 91.1 | J18: 225.7 | M18: 106.9 | N18: 106.4 | O18: 106.7 | P18: 207.2 | Q18: 107.3 | R18: 66.2 | S18: 395.2 | T18: 10.5 | Y18: 160.8 | Z18: 7.5 | AA18: 2.7 | AB18: 0 | AC18: 5.8 | AD18: 10.1 | AE18: 143.6 | AF18: 8.9 | AJ18: 81.8 | AK18: 223.2 | AO18: 6.5 | AP18: 354.2 | AQ18: 10 | AR18: 137.6 | AS18: 42.3 | AT18: 18.5 | AU18: 19.7 | AV18: 89.6 | AW18: 121.7 | AX18: 122.2 | AY18: 152.1 | AZ18: 30 | BB18: 0 | BC18: 44.3 | BD18: 46.8 | BE18: 3.8 | BF18: 38.4 | BG18: 172.6 | BH18: 95.1 | BI18: 0 | BN18: 0 | BO18: 60.9 | BP18: 85.6 | BQ18: 0 | BR18: 85.5 | BS18: 109.2 | CB18: 1.5 | CC18: 241.4 | CD18: 131.8 | CE18: 63.4 | CF18: 77.5 | CG18: 29.9 | CL18: 120.3 | CM18: 58.1 | CU18: 0 | CV18: 90.8 | CW18: 0 | CX18: 14 | CY18: 0 | DA18: 10.5 | DB18: 5.6 | DC18: 1.2 | DD18: 1.7 | DE18: 5.2 | DF18: 20 | DG18: 17.3 | DH18: 19 | DI18: 3.5 | DJ18: 18.6 | DK18: 0 | DL18: 0 | DM18: 29.4 | DN18: 64.4 | DO18: 4.8 | DP18: 2.4 | DQ18: 2.4 | DR18: 2.5 | DS18: 0 | DT18: 3.3 | DU18: 20.3 | DV18: 3 | DW18: 0 | DX18: 19.8 | DY18: 13 | DZ18: 19.3 | EA18: 20.3 | EB18: 20 | EC18: 6.9 | ED18: 21.7 | EE18: 0 | EF18: 18.6 | EG18: 37.3 | EH18: 0.2 | EI18: 0 | EJ18: 21 | EK18: 4.3 | EL18: 6.6 | EM18: 20.4 | EN18: 20.4 | EO18: 20.2 | EP18: 9.7 | EQ18: 0 | ER18: 0 | ES18: 0.6 | ET18: 9.4 | EU18: 5 | EV18: 0 | EW18: 0 | EX18: 9 | EY18: 20 | FA18: 44.1 | FB18: 23.3 | FC18: 29.1 | FD18: 3.3 | FE18: 15.5 | FF18: 9.6 | FG18: 6.4 | FH18: 6231.3 | FJ18: 24.44899 | FK18: 8.059 | FM18: 13.2 | FO18: 9.47016 | FP18: 10.6 | FQ18: 16.1 | FR18: 81.87815
A19: 20/03/2025 | B19: 04:30 | C19: 0 | D19: 0 | E19: 599.6 | F19: 195.3 | I19: 91.1 | J19: 227.2 | M19: 110 | N19: 109.3 | O19: 109.6 | P19: 207.3 | Q19: 108.6 | R19: 66.7 | S19: 404.2 | T19: 10.5 | Y19: 163.9 | Z19: 7.8 | AA19: 2.8 | AB19: 0 | AC19: 5.8 | AD19: 10.1 | AE19: 144.2 | AF19: 8.9 | AJ19: 82.1 | AK19: 223.2 | AO19: 6.5 | AP19: 412.4 | AQ19: 10 | AR19: 147.8 | AS19: 42.3 | AT19: 18.5 | AU19: 19.7 | AV19: 90.2 | AW19: 123.1 | AX19: 124 | AY19: 152.8 | AZ19: 30.3 | BB19: 0 | BC19: 44.7 | BD19: 46.7 | BE19: 3.8 | BF19: 37.8 | BG19: 174.3 | BH19: 95.6 | BI19: 0 | BN19: 0 | BO19: 61.2 | BP19: 85.8 | BQ19: 0 | BR19: 85.6 | BS19: 108.7 | CB19: 1.5 | CC19: 268.4 | CD19: 132 | CE19: 63.6 | CF19: 77.7 | CG19: 30.2 | CL19: 121.1 | CM19: 57.6 | CU19: 0 | CV19: 90.8 | CW19: 0 | CX19: 16.5 | CY19: 0 | DA19: 10.4 | DB19: 5.5 | DC19: 1.2 | DD19: 1.8 | DE19: 5.1 | DF19: 20.2 | DG19: 18 | DH19: 19 | DI19: 3.5 | DJ19: 18.6 | DK19: 0 | DL19: 0 | DM19: 30 | DN19: 71.4 | DO19: 4.8 | DP19: 2.4 | DQ19: 2.4 | DR19: 2.5 | DS19: 0 | DT19: 3.3 | DU19: 20.3 | DV19: 3 | DW19: 0 | DX19: 19.8 | DY19: 13 | DZ19: 19.3 | EA19: 20.3 | EB19: 20 | EC19: 6.2 | ED19: 22.1 | EE19: 0 | EF19: 13.8 | EG19: 32.2 | EH19: 0 | EI19: 0 | EJ19: 21 | EK19: 4.3 | EL19: 7.7 | EM19: 20.4 | EN19: 20.4 | EO19: 20.2 | EP19: 11.7 | EQ19: 0 | ER19: 0 | ES19: 0.6 | ET19: 5.4 | EU19: 4.5 | EV19: 0 | EW19: 0 | EX19: 9 | EY19: 20 | FA19: 44 | FB19: 23.5 | FC19: 29.2 | FD19: 3.3 | FE19: 15.5 | FF19: 9.6 | FG19: 6.7 | FH19: 6356.5 | FJ19: 24.44834 | FK19: 8.056 | FM19: 13.2 | FO19: 9.46997 | FP19: 10.5 | FQ19: 16.1 | FR19: 81.77431
A20: 20/03/2025 | B20: 05:00 | C20: 0 | D20: 0 | E20: 602.2 | F20: 148.5 | I20: 91.2 | J20: 228.2 | M20: 106.6 | N20: 107.1 | O20: 106.7 | P20: 203.4 | Q20: 107.8 | R20: 66.1 | S20: 414.5 | T20: 10.5 | Y20: 168.1 | Z20: 7.3 | AA20: 4.1 | AB20: 0 | AC20: 5.8 | AD20: 10.1 | AE20: 144 | AF20: 8.9 | AJ20: 111.2 | AK20: 222.3 | AO20: 6.5 | AP20: 376.8 | AQ20: 22 | AR20: 141.5 | AS20: 42.2 | AT20: 18.5 | AU20: 19.7 | AV20: 92.3 | AW20: 123.5 | AX20: 123.4 | AY20: 151.8 | AZ20: 61.5 | BB20: 0 | BC20: 45.5 | BD20: 47.4 | BE20: 3.8 | BF20: 38.3 | BG20: 174.9 | BH20: 96.2 | BI20: 0 | BN20: 0 | BO20: 87.4 | BP20: 85.5 | BQ20: 0 | BR20: 85.2 | BS20: 108 | CB20: 1.5 | CC20: 250.4 | CD20: 133.6 | CE20: 64.2 | CF20: 77.7 | CG20: 30.5 | CL20: 120.7 | CM20: 57.4 | CU20: 0 | CV20: 93.6 | CW20: 0 | CX20: 13.1 | CY20: 0 | DA20: 10.4 | DB20: 5.5 | DC20: 1.3 | DD20: 1.8 | DE20: 5.1 | DF20: 20.6 | DG20: 18.6 | DH20: 19 | DI20: 3.5 | DJ20: 18.6 | DK20: 0 | DL20: 0 | DM20: 30.7 | DN20: 76 | DO20: 4.8 | DP20: 2.4 | DQ20: 2.4 | DR20: 2.5 | DS20: 0 | DT20: 3.3 | DU20: 20.3 | DV20: 3 | DW20: 0 | DX20: 19.8 | DY20: 13 | DZ20: 19.5 | EA20: 20.3 | EB20: 20 | EC20: 9.3 | ED20: 18.4 | EE20: 0 | EF20: 19.4 | EG20: 42.3 | EH20: 0.3 | EI20: 0 | EJ20: 21 | EK20: 4.3 | EL20: 8 | EM20: 20.4 | EN20: 20.4 | EO20: 20.2 | EP20: 8.5 | EQ20: 0 | ER20: 0 | ES20: 0.6 | ET20: 6.3 | EU20: 4.6 | EV20: 0 | EW20: 0 | EX20: 9 | EY20: 20 | FA20: 43.7 | FB20: 23.3 | FC20: 29.1 | FD20: 3.2 | FE20: 15.6 | FF20: 9.6 | FG20: 6.8 | FH20: 6375.9 | FJ20: 24.4495 | FK20: 8.055 | FM20: 13.2 | FO20: 9.46997 | FP20: 10.3 | FQ20: 16 | FR20: 81.47447
A21: 20/03/2025 | B21: 05:30 | C21: 0.2 | D21: 0.3 | E21: 588.7 | F21: 148.5 | I21: 88.4 | J21: 223.9 | M21: 130.2 | N21: 130.7 | O21: 130.8 | P21: 240.2 | Q21: 107.8 | R21: 66.2 | S21: 389.5 | T21: 10.3 | Y21: 159.7 | Z21: 6.6 | AA21: 3.2 | AB21: 0 | AC21: 5.2 | AD21: 10 | AE21: 142.3 | AF21: 8.6 | AJ21: 109 | AK21: 222.1 | AO21: 6.5 | AP21: 350 | AQ21: 42.9 | AR21: 137.7 | AS21: 42.1 | AT21: 18.5 | AU21: 19.7 | AV21: 87.9 | AW21: 118.4 | AX21: 118.9 | AY21: 150.9 | AZ21: 103.5 | BB21: 0 | BC21: 44 | BD21: 46 | BE21: 3.8 | BF21: 37.1 | BG21: 169.8 | BH21: 94.4 | BI21: 0 | BN21: 0 | BO21: 86.1 | BP21: 85.5 | BQ21: 0 | BR21: 85.3 | BS21: 108.3 | CB21: 1.5 | CC21: 239.9 | CD21: 122.9 | CE21: 62.1 | CF21: 76.9 | CG21: 29.5 | CL21: 120.3 | CM21: 57.2 | CU21: 0 | CV21: 115.7 | CW21: 0 | CX21: 15.7 | CY21: 0 | DA21: 10.4 | DB21: 5.5 | DC21: 1.2 | DD21: 1.7 | DE21: 5.1 | DF21: 19.8 | DG21: 17.6 | DH21: 19 | DI21: 3.5 | DJ21: 18.6 | DK21: 0 | DL21: 0 | DM21: 30 | DN21: 75.5 | DO21: 4.8 | DP21: 2.4 | DQ21: 2.4 | DR21: 2.5 | DS21: 0 | DT21: 3.3 | DU21: 20.3 | DV21: 3 | DW21: 0 | DX21: 19.8 | DY21: 12.9 | DZ21: 19.8 | EA21: 20.2 | EB21: 20 | EC21: 9 | ED21: 15.1 | EE21: 0 | EF21: 17.1 | EG21: 36.8 | EH21: 0.1 | EI21: 0 | EJ21: 21 | EK21: 4.3 | EL21: 8.2 | EM21: 20.4 | EN21: 20.4 | EO21: 20.2 | EP21: 10.9 | EQ21: 0 | ER21: 0 | ES21: 0.6 | ET21: 18.3 | EU21: 17.9 | EV21: 0 | EW21: 0 | EX21: 8.9 | EY21: 20 | FA21: 43.8 | FB21: 23.4 | FC21: 29.2 | FD21: 3.3 | FE21: 15.5 | FF21: 9.6 | FG21: 6.7 | FH21: 6441.4 | FJ21: 24.44664 | FK21: 8.053 | FM21: 13.2 | FO21: 9.46952 | FP21: 10.4 | FQ21: 16 | FR21: 81.56916
A22: 20/03/2025 | B22: 06:00 | C22: 0.3 | D22: 1.1 | E22: 599.8 | F22: 148.3 | I22: 90.2 | J22: 227.9 | M22: 120.3 | N22: 120.6 | O22: 120.6 | P22: 217.5 | Q22: 107.5 | R22: 66.1 | S22: 435.4 | T22: 10.7 | Y22: 166.9 | Z22: 8.1 | AA22: 3.2 | AB22: 0 | AC22: 4.6 | AD22: 10 | AE22: 144.2 | AF22: 8.6 | AJ22: 111.2 | AK22: 223.1 | AO22: 6.5 | AP22: 423.9 | AQ22: 69.2 | AR22: 143.8 | AS22: 42.2 | AT22: 18.3 | AU22: 19.7 | AV22: 92.6 | AW22: 124.3 | AX22: 124.9 | AY22: 152 | AZ22: 106.5 | BB22: 0 | BC22: 45.5 | BD22: 47.1 | BE22: 3.8 | BF22: 38.3 | BG22: 175.1 | BH22: 95.9 | BI22: 0 | BN22: 0 | BO22: 87.8 | BP22: 85.2 | BQ22: 0 | BR22: 85.3 | BS22: 108.3 | CB22: 1.5 | CC22: 254.1 | CD22: 127.7 | CE22: 64.3 | CF22: 77.7 | CG22: 30.5 | CL22: 120.5 | CM22: 56.9 | CU22: 0 | CV22: 118.5 | CW22: 0 | CX22: 16.4 | CY22: 0 | DA22: 10.4 | DB22: 5.4 | DC22: 1.3 | DD22: 1.8 | DE22: 5.1 | DF22: 20.3 | DG22: 18.8 | DH22: 19 | DI22: 3.5 | DJ22: 18.6 | DK22: 1.8 | DL22: 1.9 | DM22: 31.5 | DN22: 74.1 | DO22: 4.8 | DP22: 2.4 | DQ22: 2.4 | DR22: 2.5 | DS22: 0 | DT22: 3.3 | DU22: 20.3 | DV22: 3 | DW22: 0 | DX22: 19.8 | DY22: 12.8 | DZ22: 20.1 | EA22: 20.3 | EB22: 19.8 | EC22: 10.2 | ED22: 17.5 | EE22: 0.2 | EF22: 24.1 | EG22: 50.6 | EH22: 0.4 | EI22: 0.5 | EJ22: 21 | EK22: 4.3 | EL22: 7.8 | EM22: 20.4 | EN22: 20.4 | EO22: 20.2 | EP22: 13.7 | EQ22: 0 | ER22: 1.4 | ES22: 0.6 | ET22: 34.8 | EU22: 28.3 | EV22: 1.3 | EW22: 0 | EX22: 9 | EY22: 19.8 | FA22: 44.2 | FB22: 23.3 | FC22: 29.2 | FD22: 3.2 | FE22: 15.6 | FF22: 9.6 | FG22: 7.1 | FH22: 6694.2 | FJ22: 24.45245 | FK22: 8.054 | FM22: 13.2 | FO22: 9.46928 | FP22: 10.4 | FQ22: 16 | FR22: 81.57573
... A58: 21/03/2025 | B58: 00:00 | C58: 0.3 | D58: 0.5 | E58: 642.5 | F58: 148.1 | I58: 89.8 | J58: 226.2 | M58: 104.9 | N58: 105.2 | O58: 105.1 | P58: 214.3 | Q58: 108.2 | R58: 68.4 | S58: 550.1 | T58: 10.4 | Y58: 166 | Z58: 7.6 | AA58: 2.7 | AB58: 0 | AC58: 6.7 | AD58: 10 | AE58: 142.7 | AF58: 8.8 | AJ58: 110.1 | AK58: 221.9 | AO58: 6.5 | AP58: 456.2 | AQ58: 81.9 | AR58: 121.5 | AS58: 39.9 | AT58: 18.5 | AU58: 19.7 | AV58: 91.2 | AW58: 0 | AX58: 121.1 | AY58: 72.7 | AZ58: 104.4 | BB58: 8.3 | BC58: 44.1 | BD58: 46.5 | BE58: 0 | BF58: 37.5 | BG58: 171.5 | BH58: 94.5 | BI58: 0 | BN58: 0 | BO58: 86.9 | BP58: 147.2 | BQ58: 0 | BR58: 147.1 | BS58: 155 | CB58: 0 | CC58: 198.8 | CD58: 108.8 | CE58: 63.4 | CF58: 77.8 | CG58: 29.8 | CL58: 142.2 | CM58: 65.7 | CU58: 0 | CV58: 90.3 | CW58: 0 | CX58: 13.8 | CY58: 0 | DA58: 10.4 | DB58: 5.5 | DC58: 1.3 | DD58: 1.8 | DE58: 5 | DF58: 20 | DG58: 20 | DH58: 19.1 | DI58: 3.5 | DJ58: 18.6 | DK58: 0 | DL58: 0 | DM58: 18.2 | DN58: 50.3 | DO58: 4.8 | DP58: 2.4 | DQ58: 2.4 | DR58: 2.6 | DS58: 0 | DT58: 3.5 | DU58: 20.3 | DV58: 2 | DW58: 0.3 | DX58: 19.8 | DY58: 13 | DZ58: 20.3 | EA58: 20.3 | EB58: 20 | EC58: 0.6 | ED58: 25.9 | EE58: 0 | EF58: 41.5 | EG58: 72.6 | EH58: 2.1 | EI58: 2.1 | EJ58: 21 | EK58: 8.4 | EL58: 6.6 | EM58: 20.4 | EN58: 20.4 | EO58: 20.2 | EP58: 9.6 | EQ58: 0 | ER58: 0 | ES58: 0.6 | ET58: 42.7 | EU58: 32.2 | EV58: 0 | EW58: 0 | EX58: 8.9 | EY58: 20 | FA58: 44.7 | FB58: 24.9 | FC58: 29 | FD58: 3.1 | FE58: 16 | FF58: 9.3 | FG58: 7 | FH58: 6708.5 | FJ58: 24.4133 | FK58: 8.051 | FM58: 0 | FO58: 9.47466 | FP58: 10.2 | FQ58: 16 | FR58: 68.13896
A59: EJEC | C59: 4.05 | D59: 14.3 | E59: 15035 | F59: 4432.15 | G59: 0 | H59: 0 | I59: 2149.35 | J59: 5443.9 | K59: 0 | L59: 0 | M59: 3024.95 | N59: 3025.1 | O59: 3027.3 | P59: 5302.8 | Q59: 3176.75 | R59: 1858.55 | S59: 12231.45 | T59: 250.55 | U59: 0 | V59: 0 | W59: 0 | X59: 0 | Y59: 3937.45 | Z59: 177.45 | AA59: 72.85 | AB59: 21.1 | AC59: 154.4 | AD59: 241.4 | AE59: 3444.35 | AF59: 211.85 | AG59: 0 | AH59: 0 | AI59: 0 | AJ59: 2568.55 | AK59: 5344 | AL59: 0 | AM59: 0 | AN59: 0 | AO59: 155.9 | AP59: 10351.65 | AQ59: 1323.8 | AR59: 3303.4 | AS59: 632.2 | AT59: 442.7 | AU59: 472.75 | AV59: 2164.25 | AW59: 3182.2 | AX59: 3368.65 | AY59: 3779.85 | AZ59: 2272.15 | BA59: 0 | BB59: 49.8 | BC59: 1067.6 | BD59: 1118.8 | BE59: 60.8 | BF59: 890.3 | BG59: 4159.6 | BH59: 2177.75 | BI59: 87.7 | BJ59: 0 | BK59: 0 | BL59: 0 | BM59: 0 | BN59: 211.805 | BO59: 2046.8 | BP59: 3035.7 | BQ59: 278.5 | BR59: 3334.75 | BS59: 3424.5 | BT59: 0 | BU59: 0 | BV59: 0 | BW59: 0 | BX59: 0 | BY59: 0 | BZ59: 0 | CA59: 0 | CB59: 27.9 | CC59: 5811.2 | CD59: 3048.95 | CE59: 1535.1 | CF59: 1890.05 | CG59: 721.55 | CH59: 0 | CI59: 0 | CJ59: 0 | CK59: 0 | CL59: 3210.3 | CM59: 1500.65 | CN59: 0 | CO59: 0 | CP59: 0 | CQ59: 0 | CR59: 0 | CS59: 0 | CT59: 0 | CU59: 6.5 | CV59: 2515.75 | CW59: 706.85 | CX59: 365.15 | CY59: 2.55 | CZ59: 0 | DA59: 248.85 | DB59: 131.15 | DC59: 28.4 | DD59: 32.7 | DE59: 123.2 | DF59: 484.85 | DG59: 462.45 | DH59: 456.15 | DI59: 84.35 | DJ59: 446.35 | DK59: 149.75 | DL59: 179.7 | DM59: 658.15 | DN59: 1816.05 | DO59: 115.15 | DP59: 57.6 | DQ59: 57.6 | DR59: 58.55 | DS59: 156.3 | DT59: 78.55 | DU59: 487.95 | DV59: 57.65 | DW59: 5.2 | DX59: 475.3 | DY59: 308.6 | DZ59: 482.7 | EA59: 486.7 | EB59: 478.5 | EC59: 81.25 | ED59: 947.85 | EE59: 320.4 | EF59: 1215.4 | EG59: 1579.6 | EH59: 76.25 | EI59: 94.85 | EJ59: 504 | EK59: 148.35 | EL59: 176.75 | EM59: 489.6 | EN59: 489.6 | EO59: 484.8 | EP59: 282 | EQ59: 127.8 | ER59: 1270.55 | ES59: 14.4 | ET59: 1733.45 | EU59: 1588.45 | EV59: 961.9 | EW59: 132.7 | EX59: 215.1 | EY59: 479 | EZ59: 0 | FA59: 1070.5 | FB59: 575.15 | FC59: 688.8 | FD59: 78.6 | FE59: 378.35 | FF59: 228.2 | FG59: 162.35 | FH59: 175090.45 | FJ59: 583.40444 | FK59: 193.2525 | FL59: 0 | FM59: 264 | FN59: 0 | FO59: 219.2935 | FP59: 241.9 | FQ59: 385.5 | FR59: 1887.3504

Sheet REACTIVA
B3: jueves, 20 de Marzo del 2025
A5: POTENCIA REACTIVA EJECUTADA DE LAS UNIDADES DE GENERACIÓN DEL COES (MVAR) | FI5: CENTRALES NO INTEGRANTES COES
A6: FECHA | B6: HORA | C6: 337 | D6: 338 | E6: 101 | F6: 102 | G6: 42667 | H6: 42668 | I6: 126 | J6: 127 | K6: 138 | L6: 139 | M6: 197 | N6: 203 | O6: 204 | P6: 230 | Q6: 209 | R6: 56677 | S6: 796 | T6: 2146 | U6: 142 | V6: 143 | W6: 125 | X6: 187 | Y6: 163 | Z6: 298 | AA6: 219 | AB6: 151 | AC6: 152 | AD6: 153 | AE6: 154 | AF6: 756 | AG6: 156 | AH6: 155 | AI6: 182 | AJ6: 212 | AK6: 758 | AL6: 263 | AM6: 265 | AN6: 775 | AO6: 777 | AP6: 2154 | AQ6: 150 | AR6: 149 | AS6: 188 | AT6: 2131 | AU6: 755 | AV6: 252 | AW6: 249 | AX6: 250 | AY6: 117 | AZ6: 267 | BA6: 268 | BB6: 119 | BC6: 120 | BD6: 189 | BE6: 122 | BF6: 266 | BG6: 251 | BH6: 115 | BI6: 239 | BJ6: 288 | BK6: 240 | BL6: 241 | BM6: 242 | BN6: 191 | BO6: 194 | BP6: 196 | BQ6: 207 | BR6: 236 | BS6: 795 | BT6: 285 | BU6: 995 | BV6: 996 | BW6: 997 | BX6: 766 | BY6: 926 | BZ6: 924 | CA6: 121 | CB6: 103 | CC6: 104 | CD6: 106 | CE6: 105 | CF6: 107 | CG6: 110 | CH6: 109 | CI6: 144 | CJ6: 113 | CK6: 114 | CL6: 193 | CM6: 208 | CN6: 786 | CO6: 787 | CP6: 788 | CQ6: 789 | CR6: 248 | CS6: 2159 | CT6: 303 | CU6: 59715 | CV6: 62255 | CW6: 1263 | CX6: 61800 | CY6: 2194 | CZ6: 216 | DA6: 198 | DB6: 49607 | DC6: 214 | DD6: 260 | DE6: 2152 | DF6: 2128 | DG6: 247 | DH6: 228 | DI6: 2135 | DJ6: 261 | DK6: 237 | DL6: 253 | DM6: 770 | DN6: 225 | DO6: 2201 | DP6: 2171 | DQ6: 760 | DR6: 235 | DS6: 238 | DT6: 2184 | DU6: 61855 | DV6: 223 | DW6: 226 | DX6: 201 | DY6: 258 | DZ6: 259 | EA6: 920 | EB6: 257 | EC6: 256 | ED6: 2148 | EE6: 58288 | EF6: 58289 | EG6: 58839 | EH6: 58840 | EI6: 296 | EJ6: 297 | EK6: 211 | EL6: 2175 | EM6: 2178 | EN6: 2181 | EO6: 1262 | EP6: 233 | EQ6: 2150 | ER6: 2165 | ES6: 2161 | ET6: 61197 | EU6: 58851 | EV6: 234 | EW6: 215 | EX6: 917 | EY6: 289 | EZ6: 58333 | FA6: 58336 | FB6: 202 | FC6: 58487 | FD6: 213 | FE6: 232 | FF6: 2190 | FG6: TOTAL COES | FI6: 221 | FJ6: 222 | FK6: 224 | FL6: 2187 | FM6: 227 | FN6: 49400 | FO6: 199 | FP6: 200 | FQ6: TOTAL NO COES
C7: CENTRO | D7: CENTRO | E7: CENTRO | F7: CENTRO | G7: NORTE | H7: NORTE | I7: NORTE | J7: NORTE | K7: CENTRO | L7: CENTRO | M7: CENTRO | N7: CENTRO | O7: CENTRO | P7: CENTRO | Q7: CENTRO | R7: CENTRO | S7: CENTRO | T7: CENTRO | U7: CENTRO | V7: CENTRO | W7: CENTRO | X7: CENTRO | Y7: SUR | Z7: SUR | AA7: CENTRO | AB7: SUR | AC7: SUR | AD7: SUR | AE7: SUR | AF7: SUR | AG7: SUR | AH7: SUR | AI7: SUR | AJ7: CENTRO | AK7: NORTE | AL7: NORTE | AM7: NORTE | AN7: CENTRO | AO7: CENTRO | AP7: CENTRO | AQ7: CENTRO | AR7: CENTRO | AS7: CENTRO | AT7: CENTRO | AU7: SUR | AV7: CENTRO | AW7: CENTRO | AX7: CENTRO | AY7: CENTRO | AZ7: CENTRO | BA7: CENTRO | BB7: CENTRO | BC7: CENTRO | BD7: SUR | BE7: NORTE | BF7: CENTRO | BG7: CENTRO | BH7: NORTE | BI7: NORTE | BJ7: NORTE | BK7: SUR | BL7: SUR | BM7: SUR | BN7: CENTRO | BO7: CENTRO | BP7: CENTRO | BQ7: CENTRO | BR7: CENTRO | BS7: CENTRO | BT7: CENTRO | BU7: SUR | BV7: SUR | BW7: SUR | BX7: NORTE | BY7: SUR | BZ7: CENTRO | CA7: NORTE | CB7: CENTRO | CC7: CENTRO | CD7: CENTRO | CE7: CENTRO | CF7: CENTRO | CG7: CENTRO | CH7: CENTRO | CI7: CENTRO | CJ7: CENTRO | CK7: CENTRO | CL7: CENTRO | CM7: CENTRO | CN7: SUR | CO7: SUR | CP7: SUR | CQ7: SUR | CR7: CENTRO | CS7: CENTRO | CT7: CENTRO | CU7: CENTRO | CV7: SUR | CW7: NORTE | CX7: NORTE | CY7: NORTE | CZ7: NORTE | DA7: NORTE | DB7: SUR | DC7: CENTRO | DD7: CENTRO | DE7: CENTRO | DF7: NORTE | DG7: NORTE | DH7: CENTRO | DI7: CENTRO | DJ7: SUR | DK7: SUR | DL7: CENTRO | DM7: CENTRO | DN7: CENTRO | DO7: CENTRO | DP7: CENTRO | DQ7: CENTRO | DR7: SUR | DS7: CENTRO | DT7: CENTRO | DU7: NORTE | DV7: CENTRO | DW7: CENTRO | DX7: NORTE | DY7: CENTRO | DZ7: CENTRO | EA7: CENTRO | EB7: NORTE | EC7: NORTE | ED7: SUR | EE7: CENTRO | EF7: CENTRO | EG7: CENTRO | EH7: CENTRO | EI7: CENTRO | EJ7: CENTRO | EK7: SUR | EL7: SUR | EM7: SUR | EN7: SUR | EO7: NORTE | EP7: SUR | EQ7: SUR | ER7: CENTRO | ES7: CENTRO | ET7: CENTRO | EU7: SUR | EV7: SUR | EW7: NORTE | EX7: CENTRO | EY7: NORTE | EZ7: NORTE | FA7: NORTE | FB7: CENTRO | FC7: CENTRO | FD7: CENTRO | FE7: NORTE | FF7: NORTE | FI7: NORTE | FJ7: CENTRO | FK7: NORTE | FL7: NORTE | FM7: NORTE | FN7: NORTE | FO7: NORTE | FP7: NORTE
C8: HIDROELÉCTRICA | D8: HIDROELÉCTRICA | E8: HIDROELÉCTRICA | F8: HIDROELÉCTRICA | G8: TERMOELÉCTRICA | H8: TERMOELÉCTRICA | I8: HIDROELÉCTRICA | J8: HIDROELÉCTRICA | K8: TERMOELÉCTRICA | L8: TERMOELÉCTRICA | M8: TERMOELÉCTRICA | N8: TERMOELÉCTRICA | O8: TERMOELÉCTRICA | P8: TERMOELÉCTRICA | Q8: TERMOELÉCTRICA | R8: TERMOELÉCTRICA | S8: HIDROELÉCTRICA | T8: HIDROELÉCTRICA | U8: TERMOELÉCTRICA | V8: TERMOELÉCTRICA | W8: TERMOELÉCTRICA | X8: TERMOELÉCTRICA | Y8: HIDROELÉCTRICA | Z8: HIDROELÉCTRICA | AA8: TERMOELÉCTRICA | AB8: HIDROELÉCTRICA | AC8: HIDROELÉCTRICA | AD8: HIDROELÉCTRICA | AE8: HIDROELÉCTRICA | AF8: TERMOELÉCTRICA | AG8: TERMOELÉCTRICA | AH8: TERMOELÉCTRICA | AI8: HIDROELÉCTRICA | AJ8: HIDROELÉCTRICA | AK8: TERMOELÉCTRICA | AL8: TERMOELÉCTRICA | AM8: TERMOELÉCTRICA | AN8: HIDROELÉCTRICA | AO8: HIDROELÉCTRICA | AP8: HIDROELÉCTRICA | AQ8: HIDROELÉCTRICA | AR8: HIDROELÉCTRICA | AS8: HIDROELÉCTRICA | AT8: HIDROELÉCTRICA | AU8: HIDROELÉCTRICA | AV8: TERMOELÉCTRICA | AW8: TERMOELÉCTRICA | AX8: TERMOELÉCTRICA | AY8: HIDROELÉCTRICA | AZ8: HIDROELÉCTRICA | BA8: HIDROELÉCTRICA | BB8: HIDROELÉCTRICA | BC8: HIDROELÉCTRICA | BD8: HIDROELÉCTRICA | BE8: HIDROELÉCTRICA | BF8: HIDROELÉCTRICA | BG8: HIDROELÉCTRICA | BH8: TERMOELÉCTRICA | BI8: TERMOELÉCTRICA | BJ8: TERMOELÉCTRICA | BK8: TERMOELÉCTRICA | BL8: TERMOELÉCTRICA | BM8: TERMOELÉCTRICA | BN8: HIDROELÉCTRICA | BO8: TERMOELÉCTRICA | BP8: TERMOELÉCTRICA | BQ8: TERMOELÉCTRICA | BR8: TERMOELÉCTRICA | BS8: TERMOELÉCTRICA | BT8: TERMOELÉCTRICA | BU8: TERMOELÉCTRICA | BV8: TERMOELÉCTRICA | BW8: TERMOELÉCTRICA | BX8: HIDROELÉCTRICA | BY8: TERMOELÉCTRICA | BZ8: TERMOELÉCTRICA | CA8: HIDROELÉCTRICA | CB8: HIDROELÉCTRICA | CC8: HIDROELÉCTRICA | CD8: HIDROELÉCTRICA | CE8: HIDROELÉCTRICA | CF8: HIDROELÉCTRICA | CG8: TERMOELÉCTRICA | CH8: TERMOELÉCTRICA | CI8: TERMOELÉCTRICA | CJ8: TERMOELÉCTRICA | CK8: TERMOELÉCTRICA | CL8: TERMOELÉCTRICA | CM8: TERMOELÉCTRICA | CN8: TERMOELÉCTRICA | CO8: TERMOELÉCTRICA | CP8: TERMOELÉCTRICA | CQ8: TERMOELÉCTRICA | CR8: TERMOELÉCTRICA | CS8: TERMOELÉCTRICA | CT8: SOLAR | CU8: EÓLICA | CV8: SOLAR | CW8: EÓLICA | CX8: SOLAR | CY8: HIDROELÉCTRICA | CZ8: HIDROELÉCTRICA | DA8: HIDROELÉCTRICA | DB8: HIDROELÉCTRICA | DC8: HIDROELÉCTRICA | DD8: HIDROELÉCTRICA | DE8: HIDROELÉCTRICA | DF8: HIDROELÉCTRICA | DG8: HIDROELÉCTRICA | DH8: HIDROELÉCTRICA | DI8: HIDROELÉCTRICA | DJ8: SOLAR | DK8: SOLAR | DL8: EÓLICA | DM8: EÓLICA | DN8: TERMOELÉCTRICA | DO8: TERMOELÉCTRICA | DP8: TERMOELÉCTRICA | DQ8: TERMOELÉCTRICA | DR8: SOLAR | DS8: HIDROELÉCTRICA | DT8: HIDROELÉCTRICA | DU8: HIDROELÉCTRICA | DV8: HIDROELÉCTRICA | DW8: HIDROELÉCTRICA | DX8: HIDROELÉCTRICA | DY8: HIDROELÉCTRICA | DZ8: HIDROELÉCTRICA | EA8: HIDROELÉCTRICA | EB8: EÓLICA | EC8: EÓLICA | ED8: SOLAR | EE8: EÓLICA | EF8: EÓLICA | EG8: EÓLICA | EH8: EÓLICA | EI8: HIDROELÉCTRICA | EJ8: HIDROELÉCTRICA | EK8: HIDROELÉCTRICA | EL8: HIDROELÉCTRICA | EM8: HIDROELÉCTRICA | EN8: HIDROELÉCTRICA | EO8: EÓLICA | EP8: SOLAR | EQ8: SOLAR | ER8: HIDROELÉCTRICA | ES8: EÓLICA | ET8: EÓLICA | EU8: SOLAR | EV8: SOLAR | EW8: HIDROELÉCTRICA | EX8: HIDROELÉCTRICA | EY8: TERMOELÉCTRICA | EZ8: TERMOELÉCTRICA | FA8: TERMOELÉCTRICA | FB8: TERMOELÉCTRICA | FC8: TERMOELÉCTRICA | FD8: TERMOELÉCTRICA | FE8: TERMOELÉCTRICA | FF8: TERMOELÉCTRICA | FI8: HIDROELÉCTRICA | FJ8: HIDROELÉCTRICA | FK8: HIDROELÉCTRICA | FL8: HIDROELÉCTRICA | FM8: TERMOELÉCTRICA | FN8: TERMOELÉCTRICA | FO8: HIDROELÉCTRICA | FP8: HIDROELÉCTRICA
