Workbook

Sheet EVENTOS
B3: sábado, 26 de Julio del 2025
B5: INFORMACIÓN DE EVENTOS PRINCIPALES EN SUS INSTALACIONES
B6: TIPO DE EVENTO | C6: EMPRESA | D6: UBICACIÓN | E6: TIPO DE EQUIPO | F6: EQUIPO | G6: INICIO | H6: FINAL | I6: DESCRIPCIÓN | J6: MW INDISP. | K6: INTERRUPCIÓN (SI/NO) | L6: TENSIÓN DE FALLA (kV)
B7: EVENTO | C7: CONELSUR LT SAC | D7: PORTILLO | E7: SUBESTACION | F7: SS.EE. | G7: 26/07/2025 00:00:00 | H7: 27/07/2025 00:00:00 | I7: DECLARACIÓN DE SITUACIÓN EXCEPCIONAL EN LA S.E. PORTILLO DE 60 kV | K7: NO
B8: FALLA | C8: LUZ DEL SUR | D8: BALNEARIOS | E8: SVC | F8: SVC-BALNEARIOS | G8: 26/07/2025 19:07:00 | H8: 27/07/2025 00:00:00 | I8: DESCONEXIÓN DEL SVC DE LA S.E. BALNEARIOS | K8: NO | L8: 0
B9: FALLA | C9: RED DE ENERGIA DEL PERU S.A. | D9: TINGO MARÍA | E9: TRANSFORMADOR 3D | F9: AT82-211 | G9: 26/07/2025 15:14:00 | H9: 26/07/2025 15:27:00 | I9: DESCONEXIÓN DEL TRANSFORMADOR AT82-211 DE 220/138 KV DE LA S.E. TINGO MARIA | K9: NO | L9: 220

Sheet RESTRIC_OPE
B3: sábado, 26 de Julio del 2025
B5: RESTRICCIONES OPERATIVAS
B6: FECHA | C6: HORA INICIO | D6: HORA FINAL | E6: EMPRESA | F6: UBICACIÓN | G6: T.Eq. | H6: EQUIPO | I6: DESCRIPCIÓN
B7: 26/07/2025 | C7: 00:00 | D7: 24:00 | E7: EGASA | F7: S.E. CONVERTIDOR | G7: BARRA | H7: BARRA138KV | I7: EGASA limitó la capacidad del transformador 138 kV/33 kV a 50 MVA por deterioro del aislamiento.
B8: 26/07/2025 | C8: 00:00 | D8: 24:00 | E8: ENEL GENERACION PIURA S.A. | F8: C.T. MALACAS | G8: CT | H8: CENTRAL | I8: De acuerdo con la comunicación vía correo del día 24.10.2024. ENEL GENERACIÓN PIURA informa una restricción de potencia para alcanzar 105 MW en simultaneo (TG6+TGN4).
B9: 26/07/2025 | C9: 00:00 | D9: 24:00 | E9: ENEL GENERACION PIURA S.A. | F9: C.T. MALACAS | G9: GT | H9: TG4 | I9: De acuerdo a lo informado mediante correo electronico el día 04.07, la uniadTG4 puede operar a potencia efectiva durante 3 horas o con 80MW durante 4 horas, y el resto de los periodos a mínima generación.
B10: 26/07/2025 | C10: 00:00 | D10: 24:00 | E10: ENGIE | F10: C.E. PUNTA LOMITAS | G10: CE | H10: CENTRAL | I10: De acuerdo a la carta ENG/737-2024 (Exp:202400007555). Limitación de cables de media tensión a 100 MW de los transformadores PLT1 y PLT2 de la CE Punta Lomitas. Quedan limitados a 200 MW la generación de CE Punta Lomitas y Punta Lomitas Extensión.
B11: 26/07/2025 | C11: 00:00 | D11: 24:00 | E11: ENGIE | F11: C.H. YUNCÁN | G11: GH | H11: G3 | I11: Según la carta N° ENG/ 198-2024 enviada por su representada, se opera de forma continua el G3 de la CH Yuncán, debido a la ejecución de mantenimientos necesarios para evitar daños en los sellos de seguridad de la válvula esférica del grupo.
B12: 26/07/2025 | C12: 00:00 | D12: 24:00 | E12: ENGIE | F12: C.T. CHILCA 1 | G12: CT | H12: CENTRAL | I12: Con carta ENG/971-2023, indica que no puede cumplir con las IO considerada en el PDO_17122023 dado que vulneran la seguridad de sus activos. Indican que se debe tomar TMO=168h.
B13: 26/07/2025 | C13: 00:00 | D13: 24:00 | E13: ENGIE | F13: C.T. CHILCA 1 | G13: CT | H13: CENTRAL | I13: Restricción de temperatura de la C.T Chilca, ver valor en el modelo de despacho.
B14: 26/07/2025 | C14: 00:00 | D14: 24:00 | E14: ENGIE | F14: C.T. CHILCA 2 | G14: CT | H14: CENTRAL | I14: Restricción de temperatura de la C.T Chilca2, ver valor en el modelo de despacho.
B15: 26/07/2025 | C15: 00:00 | D15: 24:00 | E15: ENGIE | F15: C.T. CHILCA 2 | G15: CT | H15: CENTRAL | I15: Con carta ENG/971-2023, indica que no puede cumplir con las IO considerada en el PDO_17122023 dado que vulneran la seguridad de sus activos. Indican que se debe tomar TMO=168h.
B16: 26/07/2025 | C16: 00:00 | D16: 24:00 | E16: FENIX POWER PERÚ | F16: C.T. FENIX | G16: CT | H16: CENTRAL | I16: Restricción de temperatura de la CT FENIX, ver valor en el modelo de despacho
B17: 26/07/2025 | C17: 00:00 | D17: 24:00 | E17: FENIX POWER PERÚ | F17: C.T. FENIX | G17: CT | H17: CENTRAL | I17: De acuerdo con lo comunicado en el correo del día 06.05.2024, la CT Fenix cuenta con TMO de 168 hrs en todos su modos de operación.
... B40: 26/07/2025 | C40: 00:00 | D40: 24:00 | E40: TERMOSELVA | F40: C.T. AGUAYTÍA | G40: CT | H40: CENTRAL | I40: Disponibilidad de 23.5 MMSCF para la CT Aguaytía.

Sheet MANTENIMIENTO EJECUTADOS
B3: sábado, 26 de Julio del 2025
B5: Mantenimiento Ejecutado
B6: Empresa | C6: Ubicación | D6: Equipo | E6: Inicio | F6: Final | G6: Descripción | H6: MW Indisp. | I6: Prog. | J6: Dispon | K6: Interrupc. | L6: Tipo | M6: CodEq | N6: TipoEq_Osinerg
B7: ATLANTICA TRANSMISION SUR S.A. | C7: MONTALVO | D7: AUT-5672 | E7: 26/07/2025 00:00 | F7: 26/07/2025 18:00 | G7: Proyecto Refuerzos: Energizacion en vacio por 34 horas de AUT-5672 a traves del INT-5622 (INT-5652 e INT-5672 abiertos) | H7: 0 | I7: P | J7: E/S | K7: N | L7: P.ENERG | M7: 24276 | N7: T
B8: ATLANTICA TRANSMISION SUR S.A. | C8: MONTALVO | D8: BARRA A_220KV | E8: 26/07/2025 00:00 | F8: 27/07/2025 00:00 | G8: Proyecto Refuerzos: Indisponibilidad de la proteccion diferencial de barras 220 kV por Conexion de la nueva UB-87B hacia la UC existente,Configuracion y Pruebas. | H8: 0 | I8: P | J8: E/S | K8: N | L8: P.ENERG | M8: 13869 | N8: T
B9: ATLANTICA TRANSMISION SUR S.A. | C9: MONTALVO | D9: BARRA A_500KV | E9: 26/07/2025 00:00 | F9: 27/07/2025 00:00 | G9: Proyecto Refuerzos: Indisponibilidad de la proteccion diferencial de barras 500kV por conexion de nueva UB-87B hacia la UC existente, Configuracion y Pruebas. | H9: 0 | I9: P | J9: E/S | K9: N | L9: P.ENERG | M9: 13870 | N9: T
B10: ATLANTICA TRANSMISION SUR S.A. | C10: MONTALVO | D10: BARRA B_220kV | E10: 26/07/2025 00:00 | F10: 27/07/2025 00:00 | G10: Proyecto Refuerzos: Indisponibilidad de la proteccion diferencial de barras 220 kV por Conexion de la nueva UB-87B hacia la UC existente,Configuracion y Pruebas. | H10: 0 | I10: P | J10: E/S | K10: N | L10: P.ENERG | M10: 14765 | N10: T
B11: ATLANTICA TRANSMISION SUR S.A. | C11: MONTALVO | D11: BARRA B_500KV | E11: 26/07/2025 00:00 | F11: 27/07/2025 00:00 | G11: Proyecto Refuerzos: Indisponibilidad de la proteccion diferencial de barras 500kV por conexion de nueva UB-87B hacia la UC existente, Configuracion y Pruebas. | H11: 0 | I11: P | J11: E/S | K11: N | L11: P.ENERG | M11: 13871 | N11: T
B12: ATLANTICA TRANSMISION SUR S.A. | C12: MONTALVO | D12: INT-5622 | E12: 26/07/2025 00:00 | F12: 26/07/2025 18:00 | G12: Proyecto Refuerzos: Puesta en servicio de nueva celda INT-5622. Energizacion en vacio por 34 horas de AUT-5672. Prueba con nuevo rele de mando sincronizado PSD | H12: 0 | I12: P | J12: E/S | K12: N | L12: P.ENERG | M12: 24278 | N12: T
B13: ATLANTICA TRANSMISION SUR S.A. | C13: MONTALVO | D13: AUT-5672 | E13: 26/07/2025 08:00 | F13: 26/07/2025 18:00 | G13: Proyecto Refuerzos: verificacion de maestro-seguidor, subir / bajar taps del AUT5671 (1 Tap hacia arriba y 1 Tap hacia abajo, desde Tap en operacion) AUT-5672 energizado en vacio por el lado 220kV | H13: 0 | I13: P | J13: E/S | K13: N | L13: P.ENERG | M13: 24276 | N13: T
B14: ATLANTICA TRANSMISION SUR S.A. | C14: OCONA | D14: INT-5450 | E14: 26/07/2025 00:00 | F14: 27/07/2025 00:00 | G14: Interruptor INT-5450 cerrado con restriccion operativa, REB-5450 en servicio y suministrando los SS.AA. de la S.E. Oco?a. | H14: 0 | I14: P | J14: E/S | K14: N | L14: OTROS | M14: 13761 | N14: T
B15: ATLANTICA TRANSMISION SUR S.A. | C15: OCONA | D15: INT-5462 | E15: 26/07/2025 00:00 | F15: 27/07/2025 00:00 | G15: Seccionador SBA-5462 fase T indisponible por problemas mecanicos, el seccionador permanece cerrado y bloqueado | H15: 0 | I15: P | J15: E/S | K15: N | L15: OTROS | M15: 13758 | N15: T
B16: ATLANTICA TRANSMISION SUR S.A. | C16: POROMA | D16: AUT-5372 | E16: 26/07/2025 00:00 | F16: 27/07/2025 00:00 | G16: Energizado por pruebas de puesta de servicio previo a su integracion. | H16: 0 | I16: P | J16: E/S | K16: N | L16: PRUEBA | M16: 24298 | N16: T
B17: ATLANTICA TRANSMISION SUR S.A. | C17: POROMA | D17: INT-5361 | E17: 26/07/2025 00:00 | F17: 27/07/2025 00:00 | G17: Seccionador SBA-5361 fase R indisponible por problemas mecanicos, el seccionador permanece cerrado y bloqueado | H17: 0 | I17: P | J17: E/S | K17: N | L17: OTROS | M17: 13746 | N17: T
B18: ATLANTICA TRANSMISION SUR S.A. | C18: POROMA | D18: REB-5350 | E18: 26/07/2025 00:00 | F18: 27/07/2025 00:00 | G18: Fuera de servicio po falla en el equipo. | H18: 0 | I18: P | J18: F/S | K18: N | L18: OTROS | M18: 13771 | N18: T
... B123: TRANSMANTARO | C123: YARABAMBA | D123: IN-5120 | E123: 26/07/2025 00:00 | F123: 27/07/2025 00:00 | G123: INTERRUPTOR INDISPONIBLE POR FALLA EN LOS MANDOS DE CONTROL DE N1, N2 Y N3. | H123: 0 | I123: P | J123: F/S | K123: N | L123: OTROS | M123: 17437 | N123: T

Sheet INGRESO OC
A3: sábado, 26 de Julio del 2025
A5: INGRESO A OPERACIÓN COMERCIAL
A6: EMPRESA | B6: TIPO DE EQUIPO | C6: UBICACIÓN | D6: EQUIPO | E6: Fecha y hora de Ingreso a Operación Comercial

Sheet DESPACHO_EJECUTADO
B3: sábado, 26 de Julio del 2025
A5: POTENCIA ACTIVA EJECUTADA DE LAS UNIDADES DE GENERACIÓN DEL SEIN (MW) | FM5: CENTRALES NO INTEGRANTES COES
A6: FECHA | B6: HORA | C6: 65333 | D6: 101 | E6: 102 | F6: 42667 | G6: 42668 | H6: 126 | I6: 127 | J6: 138 | K6: 139 | L6: 197 | M6: 203 | N6: 204 | O6: 230 | P6: 209 | Q6: 56677 | R6: 796 | S6: 2146 | T6: 142 | U6: 143 | V6: 125 | W6: 187 | X6: 163 | Y6: 298 | Z6: 299 | AA6: 219 | AB6: 151 | AC6: 152 | AD6: 153 | AE6: 154 | AF6: 756 | AG6: 156 | AH6: 155 | AI6: 182 | AJ6: 212 | AK6: 758 | AL6: 263 | AM6: 265 | AN6: 775 | AO6: 777 | AP6: 2154 | AQ6: 150 | AR6: 149 | AS6: 188 | AT6: 2131 | AU6: 755 | AV6: 252 | AW6: 249 | AX6: 250 | AY6: 117 | AZ6: 267 | BA6: 268 | BB6: 119 | BC6: 120 | BD6: 189 | BE6: 122 | BF6: 266 | BG6: 337 | BH6: 338 | BI6: 251 | BJ6: 115 | BK6: 239 | BL6: 288 | BM6: 240 | BN6: 241 | BO6: 242 | BP6: 191 | BQ6: 194 | BR6: 196 | BS6: 207 | BT6: 236 | BU6: 795 | BV6: 285 | BW6: 995 | BX6: 996 | BY6: 997 | BZ6: 766 | CA6: 926 | CB6: 924 | CC6: 121 | CD6: 103 | CE6: 104 | CF6: 106 | CG6: 105 | CH6: 107 | CI6: 110 | CJ6: 109 | CK6: 144 | CL6: 113 | CM6: 114 | CN6: 193 | CO6: 208 | CP6: 786 | CQ6: 787 | CR6: 788 | CS6: 789 | CT6: 248 | CU6: 2159 | CV6: 303 | CW6: 59715 | CX6: 62255 | CY6: 1263 | CZ6: 61800 | DA6: 2194 | DB6: 69125 | DC6: 216 | DD6: 198 | DE6: 49607 | DF6: 214 | DG6: 260 | DH6: 2152 | DI6: 2128 | DJ6: 247 | DK6: 228 | DL6: 2135 | DM6: 261 | DN6: 237 | DO6: 253 | DP6: 770 | DQ6: 225 | DR6: 2201 | DS6: 2171 | DT6: 760 | DU6: 235 | DV6: 238 | DW6: 2184 | DX6: 61855 | DY6: 223 | DZ6: 226 | EA6: 201 | EB6: 258 | EC6: 259 | ED6: 920 | EE6: 257 | EF6: 256 | EG6: 2148 | EH6: 58288 | EI6: 58289 | EJ6: 58839 | EK6: 58840 | EL6: 296 | EM6: 297 | EN6: 211 | EO6: 2175 | EP6: 2178 | EQ6: 2181 | ER6: 1262 | ES6: 63425 | ET6: 233 | EU6: 2150 | EV6: 2165 | EW6: 2161 | EX6: 61197 | EY6: 58851 | EZ6: 234 | FA6: 215 | FB6: 917 | FC6: 289 | FD6: 58333 | FE6: 58336 | FF6: 213 | FG6: 232 | FH6: 2190 | FI6: 202 | FJ6: 58487 | FK6: TOTAL COES | FM6: 221 | FN6: 222 | FO6: 224 | FP6: 2187 | FQ6: 227 | FR6: 49400 | FS6: 199 | FT6: 200 | FU6: TOTAL NO COES
C7: SUR | D7: CENTRO | E7: CENTRO | F7: NORTE | G7: NORTE | H7: NORTE | I7: NORTE | J7: CENTRO | K7: CENTRO | L7: CENTRO | M7: CENTRO | N7: CENTRO | O7: CENTRO | P7: CENTRO | Q7: CENTRO | R7: CENTRO | S7: CENTRO | T7: CENTRO | U7: CENTRO | V7: CENTRO | W7: CENTRO | X7: SUR | Y7: SUR | Z7: SUR | AA7: CENTRO | AB7: SUR | AC7: SUR | AD7: SUR | AE7: SUR | AF7: SUR | AG7: SUR | AH7: SUR | AI7: SUR | AJ7: CENTRO | AK7: NORTE | AL7: NORTE | AM7: NORTE | AN7: CENTRO | AO7: CENTRO | AP7: CENTRO | AQ7: CENTRO | AR7: CENTRO | AS7: CENTRO | AT7: CENTRO | AU7: SUR | AV7: CENTRO | AW7: CENTRO | AX7: CENTRO | AY7: CENTRO | AZ7: CENTRO | BA7: CENTRO | BB7: CENTRO | BC7: CENTRO | BD7: SUR | BE7: NORTE | BF7: CENTRO | BG7: CENTRO | BH7: CENTRO | BI7: CENTRO | BJ7: NORTE | BK7: NORTE | BL7: NORTE | BM7: SUR | BN7: SUR | BO7: SUR | BP7: CENTRO | BQ7: CENTRO | BR7: CENTRO | BS7: CENTRO | BT7: CENTRO | BU7: CENTRO | BV7: CENTRO | BW7: SUR | BX7: SUR | BY7: SUR | BZ7: NORTE | CA7: SUR | CB7: CENTRO | CC7: NORTE | CD7: CENTRO | CE7: CENTRO | CF7: CENTRO | CG7: CENTRO | CH7: CENTRO | CI7: CENTRO | CJ7: CENTRO | CK7: CENTRO | CL7: CENTRO | CM7: CENTRO | CN7: CENTRO | CO7: CENTRO | CP7: SUR | CQ7: SUR | CR7: SUR | CS7: SUR | CT7: CENTRO | CU7: CENTRO | CV7: CENTRO | CW7: CENTRO | CX7: SUR | CY7: NORTE | CZ7: NORTE | DA7: NORTE | DB7: CENTRO | DC7: NORTE | DD7: NORTE | DE7: SUR | DF7: CENTRO | DG7: CENTRO | DH7: CENTRO | DI7: NORTE | DJ7: NORTE | DK7: CENTRO | DL7: CENTRO | DM7: SUR | DN7: SUR | DO7: CENTRO | DP7: CENTRO | DQ7: CENTRO | DR7: CENTRO | DS7: CENTRO | DT7: CENTRO | DU7: SUR | DV7: CENTRO | DW7: CENTRO | DX7: NORTE | DY7: CENTRO | DZ7: CENTRO | EA7: NORTE | EB7: CENTRO | EC7: CENTRO | ED7: CENTRO | EE7: NORTE | EF7: NORTE | EG7: SUR | EH7: CENTRO | EI7: CENTRO | EJ7: CENTRO | EK7: CENTRO | EL7: CENTRO | EM7: CENTRO | EN7: SUR | EO7: SUR | EP7: SUR | EQ7: SUR | ER7: NORTE | ES7: SUR | ET7: SUR | EU7: SUR | EV7: CENTRO | EW7: CENTRO | EX7: CENTRO | EY7: SUR | EZ7: SUR | FA7: NORTE | FB7: CENTRO | FC7: NORTE | FD7: NORTE | FE7: NORTE | FF7: CENTRO | FG7: NORTE | FH7: NORTE | FI7: CENTRO | FJ7: CENTRO | FM7: NORTE | FN7: CENTRO | FO7: NORTE | FP7: NORTE | FQ7: NORTE | FR7: NORTE | FS7: NORTE | FT7: NORTE
C8: HIDROELÉCTRICA | D8: HIDROELÉCTRICA | E8: HIDROELÉCTRICA | F8: TERMOELÉCTRICA | G8: TERMOELÉCTRICA | H8: HIDROELÉCTRICA | I8: HIDROELÉCTRICA | J8: TERMOELÉCTRICA | K8: TERMOELÉCTRICA | L8: TERMOELÉCTRICA | M8: TERMOELÉCTRICA | N8: TERMOELÉCTRICA | O8: TERMOELÉCTRICA | P8: TERMOELÉCTRICA | Q8: TERMOELÉCTRICA | R8: HIDROELÉCTRICA | S8: HIDROELÉCTRICA | T8: TERMOELÉCTRICA | U8: TERMOELÉCTRICA | V8: TERMOELÉCTRICA | W8: TERMOELÉCTRICA | X8: HIDROELÉCTRICA | Y8: HIDROELÉCTRICA | Z8: HIDROELÉCTRICA | AA8: TERMOELÉCTRICA | AB8: HIDROELÉCTRICA | AC8: HIDROELÉCTRICA | AD8: HIDROELÉCTRICA | AE8: HIDROELÉCTRICA | AF8: TERMOELÉCTRICA | AG8: TERMOELÉCTRICA | AH8: TERMOELÉCTRICA | AI8: HIDROELÉCTRICA | AJ8: HIDROELÉCTRICA | AK8: TERMOELÉCTRICA | AL8: TERMOELÉCTRICA | AM8: TERMOELÉCTRICA | AN8: HIDROELÉCTRICA | AO8: HIDROELÉCTRICA | AP8: HIDROELÉCTRICA | AQ8: HIDROELÉCTRICA | AR8: HIDROELÉCTRICA | AS8: HIDROELÉCTRICA | AT8: HIDROELÉCTRICA | AU8: HIDROELÉCTRICA | AV8: TERMOELÉCTRICA | AW8: TERMOELÉCTRICA | AX8: TERMOELÉCTRICA | AY8: HIDROELÉCTRICA | AZ8: HIDROELÉCTRICA | BA8: HIDROELÉCTRICA | BB8: HIDROELÉCTRICA | BC8: HIDROELÉCTRICA | BD8: HIDROELÉCTRICA | BE8: HIDROELÉCTRICA | BF8: HIDROELÉCTRICA | BG8: HIDROELÉCTRICA | BH8: HIDROELÉCTRICA | BI8: HIDROELÉCTRICA | BJ8: TERMOELÉCTRICA | BK8: TERMOELÉCTRICA | BL8: TERMOELÉCTRICA | BM8: TERMOELÉCTRICA | BN8: TERMOELÉCTRICA | BO8: TERMOELÉCTRICA | BP8: HIDROELÉCTRICA | BQ8: TERMOELÉCTRICA | BR8: TERMOELÉCTRICA | BS8: TERMOELÉCTRICA | BT8: TERMOELÉCTRICA | BU8: TERMOELÉCTRICA | BV8: TERMOELÉCTRICA | BW8: TERMOELÉCTRICA | BX8: TERMOELÉCTRICA | BY8: TERMOELÉCTRICA | BZ8: HIDROELÉCTRICA | CA8: TERMOELÉCTRICA | CB8: TERMOELÉCTRICA | CC8: HIDROELÉCTRICA | CD8: HIDROELÉCTRICA | CE8: HIDROELÉCTRICA | CF8: HIDROELÉCTRICA | CG8: HIDROELÉCTRICA | CH8: HIDROELÉCTRICA | CI8: TERMOELÉCTRICA | CJ8: TERMOELÉCTRICA | CK8: TERMOELÉCTRICA | CL8: TERMOELÉCTRICA | CM8: TERMOELÉCTRICA | CN8: TERMOELÉCTRICA | CO8: TERMOELÉCTRICA | CP8: TERMOELÉCTRICA | CQ8: TERMOELÉCTRICA | CR8: TERMOELÉCTRICA | CS8: TERMOELÉCTRICA | CT8: TERMOELÉCTRICA | CU8: TERMOELÉCTRICA | CV8: SOLAR | CW8: EÓLICA | CX8: SOLAR | CY8: EÓLICA | CZ8: SOLAR | DA8: HIDROELÉCTRICA | DB8: HIDROELÉCTRICA | DC8: HIDROELÉCTRICA | DD8: HIDROELÉCTRICA | DE8: HIDROELÉCTRICA | DF8: HIDROELÉCTRICA | DG8: HIDROELÉCTRICA | DH8: HIDROELÉCTRICA | DI8: HIDROELÉCTRICA | DJ8: HIDROELÉCTRICA | DK8: HIDROELÉCTRICA | DL8: HIDROELÉCTRICA | DM8: SOLAR | DN8: SOLAR | DO8: EÓLICA | DP8: EÓLICA | DQ8: TERMOELÉCTRICA | DR8: TERMOELÉCTRICA | DS8: TERMOELÉCTRICA | DT8: TERMOELÉCTRICA | DU8: SOLAR | DV8: HIDROELÉCTRICA | DW8: HIDROELÉCTRICA | DX8: HIDROELÉCTRICA | DY8: HIDROELÉCTRICA | DZ8: HIDROELÉCTRICA | EA8: HIDROELÉCTRICA | EB8: HIDROELÉCTRICA | EC8: HIDROELÉCTRICA | ED8: HIDROELÉCTRICA | EE8: EÓLICA | EF8: EÓLICA | EG8: SOLAR | EH8: EÓLICA | EI8: EÓLICA | EJ8: EÓLICA | EK8: EÓLICA | EL8: HIDROELÉCTRICA | EM8: HIDROELÉCTRICA | EN8: HIDROELÉCTRICA | EO8: HIDROELÉCTRICA | EP8: HIDROELÉCTRICA | EQ8: HIDROELÉCTRICA | ER8: EÓLICA | ES8: SOLAR | ET8: SOLAR | EU8: SOLAR | EV8: HIDROELÉCTRICA | EW8: EÓLICA | EX8: EÓLICA | EY8: SOLAR | EZ8: SOLAR | FA8: HIDROELÉCTRICA | FB8: HIDROELÉCTRICA | FC8: TERMOELÉCTRICA | FD8: TERMOELÉCTRICA | FE8: TERMOELÉCTRICA | FF8: TERMOELÉCTRICA | FG8: TERMOELÉCTRICA | FH8: TERMOELÉCTRICA | FI8: TERMOELÉCTRICA | FJ8: TERMOELÉCTRICA | FM8: HIDROELÉCTRICA | FN8: HIDROELÉCTRICA | FO8: HIDROELÉCTRICA | FP8: HIDROELÉCTRICA | FQ8: TERMOELÉCTRICA | FR8: TERMOELÉCTRICA | FS8: HIDROELÉCTRICA | FT8: HIDROELÉCTRICA
C9: HYDRO GLOBAL PERÚ S.A.C. | D9: ELECTROPERU | E9: ELECTROPERU | F9: ELECTROPERU | G9: ELECTROPERU | H9: ORAZUL ENERGY PERÚ | I9: ORAZUL ENERGY PERÚ | J9: TERMOSELVA | K9: TERMOSELVA | L9: KALLPA GENERACION S.A. | M9: KALLPA GENERACION S.A. | N9: KALLPA GENERACION S.A. | O9: KALLPA GENERACION S.A. | P9: KALLPA GENERACION S.A. | Q9: KALLPA GENERACION S.A. | R9: KALLPA GENERACION S.A. | S9: KALLPA GENERACION S.A. | T9: SHOUGESA | U9: SHOUGESA | V9: SHOUGESA | W9: SHOUGESA | X9: EGEMSA | Y9: EGESUR | Z9: EGESUR | AA9: EGESUR | AB9: EGASA | AC9: EGASA | AD9: EGASA | AE9: EGASA | AF9: EGASA | AG9: EGASA | AH9: EGASA | AI9: SAN GABAN | AJ9: CELEPSA | AK9: MINERA CERRO VERDE | AL9: PLANTA DE RESERVA FRIA DE GENERACION DE ETEN S.A. | AM9: PLANTA DE RESERVA FRIA DE GENERACION DE ETEN S.A. | AN9: EMPRESA DE GENERACION HUALLAGA | AO9: EMPRESA DE GENERACION HUALLAGA | AP9: LA VIRGEN | AQ9: CHINANGO S.A.C. | AR9: CHINANGO S.A.C. | AS9: HIDROELECTRICA HUANCHOR S.A.C. | AT9: CELEPSA RENOVABLES S.R.L. | AU9: INLAND ENERGY SAC | AV9: FENIX POWER PERÚ | AW9: FENIX POWER PERÚ | AX9: FENIX POWER PERÚ | AY9: STATKRAFT S.A | AZ9: STATKRAFT S.A | BA9: STATKRAFT S.A | BB9: STATKRAFT S.A | BC9: STATKRAFT S.A | BD9: STATKRAFT S.A | BE9: STATKRAFT S.A | BF9: STATKRAFT S.A | BG9: CENTRALES SANTA ROSA S.A.C. | BH9: CENTRALES SANTA ROSA S.A.C. | BI9: EMPRESA DE GENERACION HUANZA | BJ9: ENEL GENERACION PIURA S.A. | BK9: ENEL GENERACION PIURA S.A. | BL9: ENEL GENERACION PIURA S.A. | BM9: ENGIE | BN9: ENGIE | BO9: ENGIE | BP9: ENGIE | BQ9: ENGIE | BR9: ENGIE | BS9: ENGIE | BT9: ENGIE | BU9: ENGIE | BV9: ENGIE | BW9: ENGIE | BX9: ENGIE | BY9: ENGIE | BZ9: ENGIE | CA9: INFRAESTRUCTURAS Y ENERGIAS DEL PERU S.A.C. | CB9: INFRAESTRUCTURAS Y ENERGIAS DEL PERU S.A.C. | CC9: INVERSIONES SHAQSHA S.A.C. | CD9: ORYGEN PERU S.A.A. | CE9: ORYGEN PERU S.A.A. | CF9: ORYGEN PERU S.A.A. | CG9: ORYGEN PERU S.A.A. | CH9: ORYGEN PERU S.A.A. | CI9: ORYGEN PERU S.A.A. | CJ9: ORYGEN PERU S.A.A. | CK9: ORYGEN PERU S.A.A. | CL9: ORYGEN PERU S.A.A. | CM9: ORYGEN PERU S.A.A. | CN9: ORYGEN PERU S.A.A. | CO9: ORYGEN PERU S.A.A. | CP9: SAMAY I S.A.C | CQ9: SAMAY I S.A.C | CR9: SAMAY I S.A.C | CS9: SAMAY I S.A.C | CT9: TERMOCHILCA S.A.C. | CU9: TERMOCHILCA S.A.C. | CV9: COLCA SOLAR S.A.C. | CW9: ENERGIA RENOVABLE DEL SUR S.A. | CX9: GR CORTARRAMA SOCIEDAD ANONIMA CERRADA | CY9: GR TARUCA SOCIEDAD ANONIMA CERRADA | CZ9: KONDU SAC | DA9: PERUANA DE INVERSIONES EN ENERGIAS RENOVABLES S.A. | DB9: VARI ENERGIA S.A.C. | DC9: ORAZUL ENERGY PERÚ | DD9: ORAZUL ENERGY PERÚ | DE9: SAN GABAN | DF9: MAJA ENERGIA S.A.C. | DG9: EMPRESA DE GENERACION ELECTRICA CANCHAYLLO SAC | DH9: EMPRESA DE GENERACION ELECTRICA SANTA ANA S.A.C. | DI9: EMPRESA ELECTRICA AGUA AZUL | DJ9: EMPRESA ELECTRICA RIO DOBLE | DK9: HIDROCAÑETE S.A. | DL9: HUAURA POWER GROUP S.A. | DM9: MOQUEGUA FV S.A.C. | DN9: PANAMERICANA SOLAR SAC. | DO9: PARQUE EOLICO MARCONA S.A.C. | DP9: PARQUE EOLICO TRES HERMANAS S.A.C. | DQ9: PETRAMAS | DR9: PETRAMAS | DS9: PETRAMAS | DT9: PETRAMAS | DU9: TACNA SOLAR SAC. | DV9: ELECTRICA YANAPAMPA SAC | DW9: ANDEAN POWER S.A.C. | DX9: ASOCIACIÓN SANTA LUCIA DE CHACAS | DY9: ATRIA ENERGIA S.A.C. | DZ9: EGEJUNIN | EA9: EGEJUNIN | EB9: EGEJUNIN | EC9: EGEJUNIN | ED9: EMPRESA DE GENERACION ELECTRICA RIO BAÑOS S.A.C. | EE9: ENERGÍA EÓLICA S.A. | EF9: ENERGÍA EÓLICA S.A. | EG9: ENGIE | EH9: ENGIE | EI9: ENGIE | EJ9: ENGIE | EK9: ENGIE | EL9: GENERACIÓN ANDINA S.A.C. | EM9: GENERACIÓN ANDINA S.A.C. | EN9: GENERADORA DE ENERGÍA DEL PERÚ | EO9: GENERADORA DE ENERGÍA DEL PERÚ | EP9: GENERADORA DE ENERGÍA DEL PERÚ | EQ9: GENERADORA DE ENERGÍA DEL PERÚ | ER9: GR PAINO SOCIEDAD ANONIMA CERRADA | ES9: JOYA SOLAR S.A.C. | ET9: MAJES ARCUS S.A.C. | EU9: ORYGEN PERU S.A.A. | EV9: ORYGEN PERU S.A.A. | EW9: ORYGEN PERU S.A.A. | EX9: ORYGEN PERU S.A.A. | EY9: ORYGEN PERU S.A.A. | EZ9: REPARTICIÓN ARCUS S.A.C. | FA9: SINERSA | FB9: SINERSA | FC9: BIOENERGIA DEL CHIRA S.A. | FD9: GM OPERACIONES S.A.C. | FE9: GM OPERACIONES S.A.C. | FF9: AGRO INDUSTRIAL PARAMONGA S.A. | FG9: AGROAURORA S.A.C. | FH9: AGROINDUSTRIAS SAN JACINTO S.A.A. | FI9: SDF ENERGIA SAC | FJ9: SDF ENERGIA SAC | FM9: UNACEM PERU S.A. | FN9: ELECTRO ORIENTE | FO9: AGUAS Y ENERGIA PERU | FP9: ELECTRO ZAÑA S.A.C. | FQ9: ELECTRONOROESTE S.A. | FR9: SDE PIURA | FS9: SINERSA | FT9: SINERSA
C10: SAN GABAN III | D10: MANTARO | E10: RESTITUCION | F10: TUMBES MAK 1 | G10: TUMBES MAK 2 | H10: CARHUAQUERO | I10: CAÑON DEL PATO | J10: AGUAYTIA TG1 | K10: AGUAYTIA TG2 | L10: KALLPA TG1 | M10: KALLPA TG2 | N10: KALLPA TG3 | O10: KALLPA TV | P10: LFLORES TG1 | Q10: LFLORES TV | R10: CERRO DEL AGUILA | S10: CERRODELAGUILAG4 | T10: SHOUGESA TV1 | U10: SHOUGESA TV2 | V10: SHOUGESA TV3 | W10: SHOUGESA CUMMINS | X10: MACHUPICCHU | Y10: ARICOTA 1 | Z10: ARICOTA 2 | AA10: INDEPENDENCIA | AB10: CHARCANI I,II,III | AC10: CHARCANI IV | AD10: CHARCANI V | AE10: CHARCANI VI | AF10: CHILINA TG | AG10: MOLLENDO 1, 2, 3 | AH10: CHILINA (SULZ 1,2) | AI10: SAN GABAN II | AJ10: PLATANAL | AK10: RECKA | AL10: RF ETEN TG1 | AM10: RF ETEN TG2 | AN10: CHAGLLA GP1 | AO10: CHAGLLA | AP10: LA VIRGEN | AQ10: CHIMAY | AR10: YANANGO | AS10: HUANCHOR | AT10: MARAÑON | AU10: STA TERESA | AV10: FENIX GT11 | AW10: FENIX GT12 | AX10: FENIX TV10 | AY10: YAUPI | AZ10: OROYA | BA10: PACHACHACA | BB10: MALPASO | BC10: CAHUA | BD10: ARCATA | BE10: GALLITO CIEGO | BF10: CHEVES | BG10: SANTA ROSA 1 | BH10: SANTA ROSA 2 | BI10: HUANZA | BJ10: MALACAS2 TG4 | BK10: MALACAS3 TG 5 | BL10: MALACAS1 TG6 | BM10: RF ILO2 TG1 | BN10: RF ILO2 TG2 | BO10: RF ILO2 TG3 | BP10: YUNCAN | BQ10: CHILCA1 TG1 | BR10: CHILCA1 TG2 | BS10: CHILCA1 TG3 | BT10: CHILCA-TV | BU10: CHILCA2 TG41 | BV10: CHILCA2-TV | BW10: CTNEPI_TG41 | BX10: CTNEPI_TG42 | BY10: CTNEPI_TG43 | BZ10: QUITARACSA | CA10: RF PTO MALDONADO | CB10: RF PUCALLPA | CC10: PARIAC | CD10: HUINCO | CE10: MATUCANA | CF10: MOYOPAMPA | CG10: CALLAHUANCA | CH10: HUAMPANI | CI10: STA ROSA WEST TG7 | CJ10: UTI_5 | CK10: UTI_6 | CL10: VENTANILLA 3 | CM10: VENTANILLA 4 | CN10: VENTANILLA TV | CO10: STAROSA TG8 | CP10: PTO_BRVO TG1 | CQ10: PTO_BRVO TG2 | CR10: PTO_BRVO TG3 | CS10: PTO_BRVO TG4 | CT10: OLLEROS TG1 | CU10: OLLEROS TV | CV10: CS YARUCAYA | CW10: SAN JUAN | CX10: MATARANI | CY10: DUNA | CZ10: CARHUAQUERO (CS) | DA10: MANTA I | DB10: ANASHIRONI | DC10: CARHUAQUERO4 | DD10: CAÑA BRAVA | DE10: TUPURI | DF10: RONCADOR | DG10: CANCHAYLLO | DH10: RENOVANDESH1 | DI10: POTRERO | DJ10: PIZARRAS | DK10: NIMPERIAL | DL10: YARUCAYA | DM10: MOQUEGUA-SOLAR | DN10: PANAMERICANA-SOLAR | DO10: PQE-EOLICO-MARCONA | DP10: PQE-EOLICO-3-HERMANAS | DQ10: HUAYCOLORO | DR10: CALLAO | DS10: DONA_CATALINA | DT10: LAGRINGAV | DU10: TACNA-SOLAR | DV10: YANAPAMPA | DW10: CARHUAC | DX10: HUALLIN | DY10: PURMACANA | DZ10: HUASAHUASI | EA10: STACRUZ_1_2 | EB10: RUNATULLO_II | EC10: RUNATULLO_III | ED10: RUCUY | EE10: PQE-EOLICO-TALARA | EF10: PQE-EOLICO-CUPISNIQUE | EG10: INTIPAMPA | EH10: PUNTA LOMITAS-BL1 | EI10: PUNTA LOMITAS-BL2 | EJ10: PUN LOMITAS_EXP-BL1 | EK10: PUN LOMITAS_EXP-BL2 | EL10: 8AGOSTO | EM10: EL CARMEN | EN10: LA JOYA | EO10: ANGEL_I | EP10: ANGEL_II | EQ10: ANGEL_III | ER10: HUAMBOS | ES10: SAN MARTIN SOLAR | ET10: MAJES | EU10: RUBI | EV10: CH_HER1 | EW10: WAYRA-I | EX10: WAYRA EXTENSION | EY10: CLEMESI | EZ10: REPARTICION | FA10: POECHOS2 | FB10: CHANCAY | FC10: CANA BRAVA | FD10: REFINERIA TALARA TV1 | FE10: REFINERÍA TALARA TV2 | FF10: PARAMONGA | FG10: MAPLE | FH10: SAN_JACINTO | FI10: OQUENDO TG1 | FJ10: OQUENDO TV1 | FK10: MW | FM10: CARPAPATA | FN10: CENTRALES ELOR | FO10: PIAS1 | FP10: ZANA | FQ10: TABLAZO | FR10: TALLANCA | FS10: CURUMUY | FT10: POECHOS1 | FU10: MW
A11: 26/07/2025 | B11: 00:30 | C11: 146.1 | D11: 641 | E11: 215.4 | H11: 59.9 | I11: 76 | J11: 67.2 | L11: 0 | M11: 205.2 | N11: 205.7 | O11: 181.2 | P11: 216 | Q11: 111.3 | R11: 443.8 | S11: 4.2 | X11: 104.4 | Y11: 7.7 | Z11: 5.3 | AA11: 0 | AB11: 6.8 | AC11: 11.8 | AD11: 74.2 | AI11: 60.1 | AJ11: 164.5 | AN11: 6.5 | AO11: 185.3 | AP11: 28.3 | AQ11: 30.6 | AR11: 18.5 | AS11: 18.6 | AT11: 12.6 | AU11: 56.7 | AV11: 181 | AW11: 181 | AX11: 183.4 | AY11: 81.5 | AZ11: 4.6 | BA11: 0 | BB11: 36 | BC11: 30.8 | BD11: 2 | BE11: 17.2 | BF11: 49.6 | BI11: 21.5 | BL11: 47.3 | BP11: 65.8 | BQ11: 177.5 | BR11: 175.1 | BS11: 200 | BT11: 273.5 | CC11: 1 | CD11: 107.7 | CE11: 75 | CF11: 64 | CG11: 73.9 | CH11: 29.9 | CL11: 146.2 | CM11: 148.7 | CN11: 150 | CO11: 0 | CT11: 217.8 | CU11: 104.3 | CV11: 0 | CW11: 15.9 | CX11: 0 | CY11: 9 | CZ11: 0 | DA11: 7.4 | DB11: 5 | DC11: 9.9 | DD11: 4.9 | DE11: 0.3 | DF11: 1.5 | DG11: 1.9 | DH11: 18.5 | DI11: 7.2 | DJ11: 4 | DK11: 3.4 | DL11: 18.5 | DM11: 0 | DN11: 0 | DO11: 5 | DP11: 15.8 | DQ11: 4.5 | DR11: 1.2 | DS11: 2.4 | DT11: 2.6 | DU11: 0 | DV11: 1.9 | DW11: 7.2 | DX11: 1.5 | DY11: 0.4 | DZ11: 4 | EA11: 3.9 | EB11: 3.4 | EC11: 4.7 | ED11: 11 | EE11: 11.8 | EF11: 20.8 | EG11: 0 | EH11: 28 | EI11: 44.6 | EJ11: 2.8 | EK11: 1.4 | EL11: 5 | EM11: 2 | EN11: 7.4 | EO11: 3.8 | EP11: 4.4 | EQ11: 4.6 | ER11: 5.1 | ES11: 0 | ET11: 0 | EU11: 0 | EV11: 0.6 | EW11: 10.4 | EX11: 18.3 | EY11: 0 | EZ11: 0 | FA11: 6.6 | FB11: 19.7 | FC11: 8.9 | FD11: 36.3 | FE11: 18.4 | FF11: 14.5 | FG11: 19 | FH11: 8.4 | FK11: 6690.9 | FM11: 19.08728 | FN11: 0 | FO11: 6.076 | FP11: 7.5 | FQ11: 27.30137 | FR11: 18.9 | FS11: 3.6 | FT11: 6.9 | FU11: 89.36465
A12: 26/07/2025 | B12: 01:00 | C12: 24.2 | D12: 641.6 | E12: 215.1 | H12: 59.7 | I12: 77.3 | J12: 40.4 | L12: 0 | M12: 208.7 | N12: 211.2 | O12: 199.5 | P12: 217.7 | Q12: 110.9 | R12: 452.3 | S12: 4.2 | X12: 104.3 | Y12: 7.5 | Z12: 5.3 | AA12: 0 | AB12: 6.8 | AC12: 10.9 | AD12: 39.2 | AI12: 56.1 | AJ12: 133.7 | AN12: 6.5 | AO12: 229.2 | AP12: 28 | AQ12: 0 | AR12: 17.6 | AS12: 18.6 | AT12: 12.6 | AU12: 55.9 | AV12: 181.1 | AW12: 180.7 | AX12: 183.4 | AY12: 83.1 | AZ12: 4.4 | BA12: 0 | BB12: 32.6 | BC12: 33 | BD12: 2 | BE12: 0 | BF12: 49.4 | BI12: 47.5 | BL12: 47.4 | BP12: 65.3 | BQ12: 178.8 | BR12: 176.2 | BS12: 200 | BT12: 274.1 | CC12: 1 | CD12: 71 | CE12: 72.7 | CF12: 63.8 | CG12: 74.1 | CH12: 29.9 | CL12: 147.5 | CM12: 149.7 | CN12: 151.5 | CO12: 0 | CT12: 216.9 | CU12: 104.3 | CV12: 0 | CW12: 14.6 | CX12: 0 | CY12: 7.1 | CZ12: 0 | DA12: 7.4 | DB12: 5.1 | DC12: 9.9 | DD12: 4.9 | DE12: 0.3 | DF12: 1.5 | DG12: 1.9 | DH12: 18.4 | DI12: 7.2 | DJ12: 4 | DK12: 3.4 | DL12: 18.5 | DM12: 0 | DN12: 0 | DO12: 3.2 | DP12: 11.8 | DQ12: 4.5 | DR12: 1.2 | DS12: 2.4 | DT12: 2.6 | DU12: 0 | DV12: 1.9 | DW12: 7.7 | DX12: 1.4 | DY12: 0.4 | DZ12: 4 | EA12: 4 | EB12: 3.3 | EC12: 4.7 | ED12: 10 | EE12: 13.9 | EF12: 20.3 | EG12: 0 | EH12: 31.1 | EI12: 45.9 | EJ12: 4.1 | EK12: 2.5 | EL12: 5 | EM12: 2 | EN12: 7.4 | EO12: 3.8 | EP12: 4.4 | EQ12: 4.6 | ER12: 5.8 | ES12: 0 | ET12: 0 | EU12: 0 | EV12: 0.6 | EW12: 16.5 | EX12: 20.1 | EY12: 0 | EZ12: 0 | FA12: 6.6 | FB12: 20 | FC12: 9.4 | FD12: 35.6 | FE12: 17.9 | FF12: 14.2 | FG12: 19.1 | FH12: 7.6 | FK12: 6502.1 | FM12: 19.50009 | FN12: 0 | FO12: 6.076 | FP12: 7.5 | FQ12: 27.33749 | FR12: 18.54942 | FS12: 3.6 | FT12: 7 | FU12: 89.563
A13: 26/07/2025 | B13: 01:30 | C13: 26 | D13: 638.8 | E13: 214.4 | H13: 0 | I13: 78.9 | J13: 41.5 | L13: 0 | M13: 208 | N13: 211.2 | O13: 200.3 | P13: 217 | Q13: 111.4 | R13: 482.9 | S13: 4.2 | X13: 104.5 | Y13: 7.5 | Z13: 4.8 | AA13: 0 | AB13: 6.9 | AC13: 10.2 | AD13: 40 | AI13: 56.1 | AJ13: 0 | AN13: 6.4 | AO13: 230.4 | AP13: 28 | AQ13: 0 | AR13: 18.6 | AS13: 18.6 | AT13: 12.6 | AU13: 56.6 | AV13: 183.4 | AW13: 183.9 | AX13: 183.8 | AY13: 81.7 | AZ13: 4.3 | BA13: 0 | BB13: 34.6 | BC13: 35.5 | BD13: 2 | BE13: 0 | BF13: 48.6 | BI13: 47.4 | BL13: 47.3 | BP13: 66 | BQ13: 178 | BR13: 175.5 | BS13: 200 | BT13: 272.9 | CC13: 1.1 | CD13: 75.3 | CE13: 78.9 | CF13: 63.9 | CG13: 74 | CH13: 29.9 | CL13: 147.3 | CM13: 149.3 | CN13: 151.3 | CO13: 0 | CT13: 217.7 | CU13: 104.3 | CV13: 0 | CW13: 13.4 | CX13: 0 | CY13: 5.7 | CZ13: 0 | DA13: 7.3 | DB13: 5.1 | DC13: 0 | DD13: 0.6 | DE13: 0.3 | DF13: 1.5 | DG13: 1.8 | DH13: 18.6 | DI13: 7.2 | DJ13: 4 | DK13: 3.4 | DL13: 18.5 | DM13: 0 | DN13: 0 | DO13: 3.1 | DP13: 9.7 | DQ13: 4.5 | DR13: 1.2 | DS13: 2.4 | DT13: 2.6 | DU13: 0 | DV13: 1.9 | DW13: 10.3 | DX13: 1.5 | DY13: 0.4 | DZ13: 4 | EA13: 3.9 | EB13: 3.2 | EC13: 4.6 | ED13: 10 | EE13: 16.3 | EF13: 18.8 | EG13: 0 | EH13: 37.3 | EI13: 55.3 | EJ13: 3.7 | EK13: 2.7 | EL13: 5 | EM13: 2 | EN13: 7.4 | EO13: 3.8 | EP13: 4.4 | EQ13: 4.5 | ER13: 3 | ES13: 0 | ET13: 0 | EU13: 0 | EV13: 0.6 | EW13: 20.6 | EX13: 17.2 | EY13: 0 | EZ13: 0 | FA13: 6.7 | FB13: 20 | FC13: 9.3 | FD13: 36.7 | FE13: 17.7 | FF13: 13.7 | FG13: 19.1 | FH13: 7.4 | FK13: 6357.6 | FM13: 20.02708 | FN13: 0 | FO13: 6.072 | FP13: 7.5 | FQ13: 27.35258 | FR13: 18.54998 | FS13: 3.6 | FT13: 7 | FU13: 90.10164
A14: 26/07/2025 | B14: 02:00 | C14: 22.5 | D14: 644.2 | E14: 216.6 | H14: 0 | I14: 81.1 | J14: 41.9 | L14: 0 | M14: 206.5 | N14: 211.2 | O14: 198.5 | P14: 216.3 | Q14: 111.2 | R14: 527.8 | S14: 4.2 | X14: 102.2 | Y14: 7.9 | Z14: 4.9 | AA14: 0 | AB14: 7.1 | AC14: 10.2 | AD14: 40.8 | AI14: 56.6 | AJ14: 0 | AN14: 6.5 | AO14: 230.3 | AP14: 28 | AQ14: 0 | AR14: 20.2 | AS14: 18.6 | AT14: 12.6 | AU14: 57 | AV14: 183.2 | AW14: 183.9 | AX14: 184.2 | AY14: 81.9 | AZ14: 4.3 | BA14: 0 | BB14: 34.3 | BC14: 36.4 | BD14: 2 | BE14: 0 | BF14: 63.2 | BI14: 47.6 | BL14: 47.5 | BP14: 66.3 | BQ14: 177.8 | BR14: 175.1 | BS14: 200 | BT14: 273.2 | CC14: 1 | CD14: 72.5 | CE14: 77.1 | CF14: 64.3 | CG14: 74 | CH14: 29 | CL14: 146.5 | CM14: 149 | CN14: 149.5 | CO14: 0 | CT14: 217.8 | CU14: 104.5 | CV14: 0 | CW14: 9.9 | CX14: 0 | CY14: 4.6 | CZ14: 0 | DA14: 7.4 | DB14: 5.1 | DC14: 0 | DD14: 0 | DE14: 0.3 | DF14: 1.5 | DG14: 1.9 | DH14: 18.6 | DI14: 7.2 | DJ14: 4 | DK14: 3.4 | DL14: 18.5 | DM14: 0 | DN14: 0 | DO14: 3.6 | DP14: 10.5 | DQ14: 4.5 | DR14: 1.2 | DS14: 2.4 | DT14: 2.6 | DU14: 0 | DV14: 1.8 | DW14: 10.3 | DX14: 1.4 | DY14: 0.4 | DZ14: 4 | EA14: 4 | EB14: 3.5 | EC14: 4.8 | ED14: 13.7 | EE14: 15.4 | EF14: 19.3 | EG14: 0 | EH14: 35.8 | EI14: 49.2 | EJ14: 3.8 | EK14: 2.4 | EL14: 5 | EM14: 2 | EN14: 7.4 | EO14: 3.8 | EP14: 4.4 | EQ14: 4.5 | ER14: 2.9 | ES14: 0 | ET14: 0 | EU14: 0 | EV14: 0.6 | EW14: 17.3 | EX14: 19.8 | EY14: 0 | EZ14: 0 | FA14: 6.7 | FB14: 20 | FC14: 9 | FD14: 36.6 | FE14: 17.5 | FF14: 13.5 | FG14: 19.1 | FH14: 7.4 | FK14: 6405.5 | FM14: 20.48264 | FN14: 0 | FO14: 6.072 | FP14: 7.5 | FQ14: 27.34445 | FR14: 18.54976 | FS14: 3.7 | FT14: 6.9 | FU14: 90.54885
A15: 26/07/2025 | B15: 02:30 | C15: 24.1 | D15: 646.6 | E15: 217.7 | H15: 0 | I15: 82.8 | J15: 37.1 | L15: 0 | M15: 208.1 | N15: 209 | O15: 198.4 | P15: 215.6 | Q15: 111.3 | R15: 412.6 | S15: 4.3 | X15: 106.3 | Y15: 8.3 | Z15: 5 | AA15: 0 | AB15: 7 | AC15: 10.2 | AD15: 41.1 | AI15: 33 | AJ15: 0 | AN15: 6.5 | AO15: 229.7 | AP15: 30.9 | AQ15: 0 | AR15: 22.4 | AS15: 18.6 | AT15: 12.6 | AU15: 57.8 | AV15: 184.2 | AW15: 184.4 | AX15: 183.4 | AY15: 82.2 | AZ15: 4.1 | BA15: 0 | BB15: 34.2 | BC15: 33.7 | BD15: 2 | BE15: 0 | BF15: 53.2 | BI15: 47.6 | BL15: 47.2 | BP15: 66.2 | BQ15: 177.1 | BR15: 173.8 | BS15: 200 | BT15: 272.4 | CC15: 1.1 | CD15: 112.8 | CE15: 90 | CF15: 65.6 | CG15: 70.9 | CH15: 28.7 | CL15: 146 | CM15: 147.8 | CN15: 149.8 | CO15: 0 | CT15: 217.5 | CU15: 104.4 | CV15: 0 | CW15: 8.6 | CX15: 0 | CY15: 7.9 | CZ15: 0 | DA15: 7.4 | DB15: 5.1 | DC15: 0 | DD15: 0 | DE15: 0.3 | DF15: 1.5 | DG15: 2.1 | DH15: 18.9 | DI15: 7.2 | DJ15: 4 | DK15: 3.4 | DL15: 18.5 | DM15: 0 | DN15: 0 | DO15: 3 | DP15: 9.3 | DQ15: 4.5 | DR15: 1.2 | DS15: 2.4 | DT15: 2.6 | DU15: 0 | DV15: 1.8 | DW15: 10.3 | DX15: 1.4 | DY15: 0.4 | DZ15: 4 | EA15: 4 | EB15: 3.6 | EC15: 5 | ED15: 14 | EE15: 18.3 | EF15: 20.5 | EG15: 0 | EH15: 37.4 | EI15: 52.7 | EJ15: 3.9 | EK15: 3.9 | EL15: 5 | EM15: 2 | EN15: 7.7 | EO15: 3.6 | EP15: 4.4 | EQ15: 4.3 | ER15: 4.9 | ES15: 0 | ET15: 0 | EU15: 0 | EV15: 0.6 | EW15: 24.7 | EX15: 31.9 | EY15: 0 | EZ15: 0 | FA15: 6.7 | FB15: 18.8 | FC15: 8.7 | FD15: 36.3 | FE15: 17.6 | FF15: 14.1 | FG15: 19 | FH15: 6.7 | FK15: 6343.4 | FM15: 20.62182 | FN15: 0 | FO15: 6.076 | FP15: 7.5 | FQ15: 27.32882 | FR15: 18.54934 | FS15: 3.6 | FT15: 6.9 | FU15: 90.57598
A16: 26/07/2025 | B16: 03:00 | C16: 29.2 | D16: 642.8 | E16: 216.6 | H16: 0 | I16: 81.8 | J16: 35.1 | L16: 0 | M16: 208.5 | N16: 210.8 | O16: 199.1 | P16: 217.7 | Q16: 111.1 | R16: 445.8 | S16: 4.3 | X16: 106.1 | Y16: 8 | Z16: 4.9 | AA16: 0 | AB16: 6.9 | AC16: 10.4 | AD16: 40.3 | AI16: 33 | AJ16: 0 | AN16: 6.5 | AO16: 229.2 | AP16: 32 | AQ16: 0 | AR16: 22.3 | AS16: 18.6 | AT16: 12.6 | AU16: 56.9 | AV16: 184.6 | AW16: 185 | AX16: 183.4 | AY16: 82.6 | AZ16: 4 | BA16: 0 | BB16: 19.1 | BC16: 35.3 | BD16: 2 | BE16: 0 | BF16: 52.8 | BI16: 47.6 | BL16: 47.5 | BP16: 66.2 | BQ16: 177.4 | BR16: 175 | BS16: 200 | BT16: 274.2 | CC16: 1.1 | CD16: 111.1 | CE16: 112.1 | CF16: 65.4 | CG16: 69.9 | CH16: 28.7 | CL16: 146.4 | CM16: 148.7 | CN16: 150.1 | CO16: 0 | CT16: 218.1 | CU16: 104.4 | CV16: 0 | CW16: 12 | CX16: 0 | CY16: 7 | CZ16: 0 | DA16: 7.4 | DB16: 5.2 | DC16: 0 | DD16: 0 | DE16: 0.3 | DF16: 1.5 | DG16: 2.1 | DH16: 18.8 | DI16: 7.2 | DJ16: 4 | DK16: 3.4 | DL16: 18.5 | DM16: 0 | DN16: 0 | DO16: 2.9 | DP16: 13.2 | DQ16: 4.5 | DR16: 1.2 | DS16: 2.4 | DT16: 2.6 | DU16: 0 | DV16: 1.9 | DW16: 10.3 | DX16: 1.4 | DY16: 0.4 | DZ16: 4 | EA16: 4 | EB16: 3.5 | EC16: 4.9 | ED16: 13.6 | EE16: 20.1 | EF16: 17 | EG16: 0 | EH16: 26.4 | EI16: 40.9 | EJ16: 2.2 | EK16: 1.2 | EL16: 5 | EM16: 2 | EN16: 7.6 | EO16: 3.6 | EP16: 4.4 | EQ16: 4.3 | ER16: 4.2 | ES16: 0 | ET16: 0 | EU16: 0 | EV16: 0.6 | EW16: 18 | EX16: 19.1 | EY16: 0 | EZ16: 0 | FA16: 6.6 | FB16: 18.7 | FC16: 9.3 | FD16: 35.7 | FE16: 21 | FF16: 14 | FG16: 19.1 | FH16: 8 | FK16: 6350.4 | FM16: 20.72309 | FN16: 0 | FO16: 6.072 | FP16: 7.5 | FQ16: 27.26492 | FR16: 18.54968 | FS16: 3.5 | FT16: 6.9 | FU16: 90.50969
A17: 26/07/2025 | B17: 03:30 | C17: 16.6 | D17: 645.8 | E17: 217.3 | H17: 0 | I17: 82.2 | J17: 35.6 | L17: 0 | M17: 209.2 | N17: 212.4 | O17: 200.5 | P17: 217.2 | Q17: 112.3 | R17: 493.3 | S17: 4.1 | X17: 104.7 | Y17: 7.8 | Z17: 5.2 | AA17: 0 | AB17: 7.1 | AC17: 10.4 | AD17: 40.2 | AI17: 34.2 | AJ17: 0 | AN17: 6.5 | AO17: 227.6 | AP17: 32 | AQ17: 0 | AR17: 21.2 | AS17: 18.6 | AT17: 12.6 | AU17: 56.1 | AV17: 180.7 | AW17: 180.9 | AX17: 185.1 | AY17: 81.2 | AZ17: 4.1 | BA17: 0 | BB17: 33.6 | BC17: 24.1 | BD17: 2 | BE17: 0 | BF17: 51 | BI17: 47.3 | BL17: 47.6 | BP17: 64.6 | BQ17: 179.2 | BR17: 176.7 | BS17: 200 | BT17: 273.9 | CC17: 1 | CD17: 64.6 | CE17: 107 | CF17: 64.7 | CG17: 66.9 | CH17: 28.1 | CL17: 148 | CM17: 150.3 | CN17: 151.5 | CO17: 0 | CT17: 217.9 | CU17: 104.4 | CV17: 0 | CW17: 20.4 | CX17: 0 | CY17: 8.1 | CZ17: 0 | DA17: 7.4 | DB17: 5 | DC17: 0 | DD17: 0 | DE17: 0.3 | DF17: 1.5 | DG17: 2.1 | DH17: 18.9 | DI17: 7.2 | DJ17: 4 | DK17: 3.4 | DL17: 18.5 | DM17: 0 | DN17: 0 | DO17: 5 | DP17: 19.8 | DQ17: 4.5 | DR17: 1.2 | DS17: 2.4 | DT17: 2.6 | DU17: 0 | DV17: 2.3 | DW17: 10.3 | DX17: 1.4 | DY17: 0.4 | DZ17: 4 | EA17: 4 | EB17: 3.5 | EC17: 4.8 | ED17: 13.6 | EE17: 19.6 | EF17: 18.4 | EG17: 0 | EH17: 26.2 | EI17: 40.6 | EJ17: 3 | EK17: 2.4 | EL17: 5 | EM17: 2 | EN17: 7.6 | EO17: 3.6 | EP17: 4.4 | EQ17: 4.1 | ER17: 4.2 | ES17: 0 | ET17: 0 | EU17: 0 | EV17: 0.6 | EW17: 11.9 | EX17: 7.7 | EY17: 0 | EZ17: 0 | FA17: 6.8 | FB17: 18.7 | FC17: 9.4 | FD17: 36.4 | FE17: 19.5 | FF17: 13.5 | FG17: 19.1 | FH17: 8 | FK17: 6336.4 | FM17: 20.52331 | FN17: 0 | FO17: 6.076 | FP17: 7.5 | FQ17: 27.18441 | FR17: 18.54965 | FS17: 3.6 | FT17: 7 | FU17: 90.43337
A18: 26/07/2025 | B18: 04:00 | C18: 25 | D18: 648.5 | E18: 218.2 | H18: 0 | I18: 81 | J18: 29.6 | L18: 0 | M18: 209.8 | N18: 210.4 | O18: 198.7 | P18: 217.5 | Q18: 111.5 | R18: 475.9 | S18: 4.3 | X18: 105.6 | Y18: 8.1 | Z18: 5.2 | AA18: 0 | AB18: 7 | AC18: 10.4 | AD18: 41.6 | AI18: 34.8 | AJ18: 0 | AN18: 6.5 | AO18: 229.2 | AP18: 32 | AQ18: 0 | AR18: 22.4 | AS18: 18.6 | AT18: 12.6 | AU18: 56.9 | AV18: 184.5 | AW18: 184.8 | AX18: 184.6 | AY18: 83 | AZ18: 4 | BA18: 0 | BB18: 34.5 | BC18: 24.5 | BD18: 2 | BE18: 0 | BF18: 52.7 | BI18: 45.9 | BL18: 47.4 | BP18: 66.3 | BQ18: 177.8 | BR18: 175.6 | BS18: 200 | BT18: 274 | CC18: 1 | CD18: 46.8 | CE18: 105.6 | CF18: 65.7 | CG18: 67 | CH18: 29.3 | CL18: 147 | CM18: 149.2 | CN18: 150.7 | CO18: 0 | CT18: 217.7 | CU18: 104.4 | CV18: 0 | CW18: 17.9 | CX18: 0 | CY18: 7.3 | CZ18: 0 | DA18: 7.4 | DB18: 5.2 | DC18: 0 | DD18: 0 | DE18: 0.3 | DF18: 1.5 | DG18: 2.1 | DH18: 18.8 | DI18: 7.2 | DJ18: 4 | DK18: 3.4 | DL18: 18.5 | DM18: 0 | DN18: 0 | DO18: 5.5 | DP18: 19.3 | DQ18: 4.5 | DR18: 1.2 | DS18: 2.4 | DT18: 2.6 | DU18: 0 | DV18: 2.3 | DW18: 10.3 | DX18: 1.4 | DY18: 0.4 | DZ18: 4 | EA18: 4 | EB18: 3.6 | EC18: 4.9 | ED18: 13.8 | EE18: 18.7 | EF18: 12.9 | EG18: 0 | EH18: 25.9 | EI18: 49.7 | EJ18: 2.1 | EK18: 1.7 | EL18: 5 | EM18: 2 | EN18: 7.6 | EO18: 3.6 | EP18: 4.2 | EQ18: 4.1 | ER18: 6.8 | ES18: 0 | ET18: 0 | EU18: 0 | EV18: 0.6 | EW18: 12 | EX18: 6.3 | EY18: 0 | EZ18: 0 | FA18: 6.6 | FB18: 18.5 | FC18: 8.3 | FD18: 36.2 | FE18: 20.1 | FF18: 13.6 | FG18: 19.1 | FH18: 8.2 | FK18: 6314.9 | FM18: 20.94337 | FN18: 0 | FO18: 6.072 | FP18: 7.5 | FQ18: 27.11903 | FR18: 18.55034 | FS18: 3.5 | FT18: 7 | FU18: 90.68474
A19: 26/07/2025 | B19: 04:30 | C19: 59.5 | D19: 643 | E19: 216.5 | H19: 0 | I19: 81.1 | J19: 27.2 | L19: 0 | M19: 206.4 | N19: 210.4 | O19: 199.5 | P19: 215.3 | Q19: 111.7 | R19: 492.5 | S19: 4.3 | X19: 106.1 | Y19: 7.1 | Z19: 5.4 | AA19: 0 | AB19: 7 | AC19: 10.4 | AD19: 40.4 | AI19: 60.4 | AJ19: 0 | AN19: 6.5 | AO19: 227.5 | AP19: 32 | AQ19: 0 | AR19: 22.1 | AS19: 18.6 | AT19: 12.5 | AU19: 55.9 | AV19: 182.2 | AW19: 182.5 | AX19: 184.5 | AY19: 81.6 | AZ19: 4.2 | BA19: 0 | BB19: 35.9 | BC19: 31.9 | BD19: 2 | BE19: 0 | BF19: 50.5 | BI19: 22.3 | BL19: 47.3 | BP19: 65.9 | BQ19: 177.2 | BR19: 174.7 | BS19: 200 | BT19: 273.5 | CC19: 1 | CD19: 53.2 | CE19: 108 | CF19: 65.1 | CG19: 67 | CH19: 29.2 | CL19: 146.5 | CM19: 148.9 | CN19: 149.8 | CO19: 0 | CT19: 217.9 | CU19: 104.4 | CV19: 0 | CW19: 16 | CX19: 0 | CY19: 9.5 | CZ19: 0 | DA19: 7.6 | DB19: 5.1 | DC19: 0 | DD19: 0 | DE19: 0.3 | DF19: 1.5 | DG19: 2 | DH19: 18.5 | DI19: 7.2 | DJ19: 4 | DK19: 3.4 | DL19: 18.5 | DM19: 0 | DN19: 0 | DO19: 4.7 | DP19: 11.7 | DQ19: 4.5 | DR19: 1.2 | DS19: 2.4 | DT19: 2.6 | DU19: 0 | DV19: 2.2 | DW19: 7.9 | DX19: 1.4 | DY19: 0.4 | DZ19: 4 | EA19: 4 | EB19: 3.5 | EC19: 4.8 | ED19: 13.8 | EE19: 21.8 | EF19: 6.1 | EG19: 0 | EH19: 24.6 | EI19: 43.7 | EJ19: 2.7 | EK19: 2.4 | EL19: 5 | EM19: 2 | EN19: 7.6 | EO19: 3.6 | EP19: 4.1 | EQ19: 4.1 | ER19: 5.3 | ES19: 0 | ET19: 0 | EU19: 0 | EV19: 0.6 | EW19: 18.1 | EX19: 9.8 | EY19: 0 | EZ19: 0 | FA19: 6.7 | FB19: 18.5 | FC19: 8.9 | FD19: 36.7 | FE19: 22.2 | FF19: 13.7 | FG19: 19.1 | FH19: 8.4 | FK19: 6344.9 | FM19: 21.00848 | FN19: 0 | FO19: 6.072 | FP19: 7.5 | FQ19: 27.1004 | FR19: 18.55023 | FS19: 3.6 | FT19: 6.9 | FU19: 90.73111
A20: 26/07/2025 | B20: 05:00 | C20: 58.1 | D20: 644.7 | E20: 217 | H20: 11.2 | I20: 81 | J20: 26.8 | L20: 0 | M20: 206.4 | N20: 209.6 | O20: 199.2 | P20: 217.2 | Q20: 111.3 | R20: 449.8 | S20: 4.3 | X20: 107 | Y20: 7.1 | Z20: 5.1 | AA20: 0 | AB20: 6.8 | AC20: 10.4 | AD20: 70.8 | AI20: 60.5 | AJ20: 0 | AN20: 6.5 | AO20: 0 | AP20: 32.5 | AQ20: 45.1 | AR20: 23.1 | AS20: 18.6 | AT20: 12.6 | AU20: 57 | AV20: 182.8 | AW20: 183.8 | AX20: 184.5 | AY20: 81.5 | AZ20: 4.5 | BA20: 0 | BB20: 33.8 | BC20: 30 | BD20: 2 | BE20: 0 | BF20: 50.9 | BI20: 22.4 | BL20: 46.7 | BP20: 66.1 | BQ20: 177.5 | BR20: 174.9 | BS20: 200 | BT20: 273.6 | CC20: 1.1 | CD20: 55.4 | CE20: 98.6 | CF20: 65.2 | CG20: 72 | CH20: 29.3 | CL20: 146.7 | CM20: 149.2 | CN20: 150.2 | CO20: 0 | CT20: 217.8 | CU20: 104.4 | CV20: 0 | CW20: 11.9 | CX20: 0 | CY20: 9.8 | CZ20: 0 | DA20: 7.6 | DB20: 5.1 | DC20: 9.9 | DD20: 0 | DE20: 0.3 | DF20: 1.5 | DG20: 2 | DH20: 18.4 | DI20: 7.4 | DJ20: 4 | DK20: 3.4 | DL20: 18.5 | DM20: 0 | DN20: 0 | DO20: 4.4 | DP20: 9.8 | DQ20: 4.5 | DR20: 1.2 | DS20: 2.4 | DT20: 2.6 | DU20: 0 | DV20: 1.5 | DW20: 7.3 | DX20: 1.3 | DY20: 0.4 | DZ20: 4 | EA20: 3.9 | EB20: 3.5 | EC20: 4.8 | ED20: 14 | EE20: 22.4 | EF20: 2.6 | EG20: 0 | EH20: 22.9 | EI20: 43.7 | EJ20: 1.9 | EK20: 1.8 | EL20: 5 | EM20: 2 | EN20: 7.7 | EO20: 3.6 | EP20: 4.1 | EQ20: 4.1 | ER20: 7.1 | ES20: 0 | ET20: 0 | EU20: 0 | EV20: 0.6 | EW20: 24.5 | EX20: 29.7 | EY20: 0 | EZ20: 0 | FA20: 6.8 | FB20: 18.5 | FC20: 10.3 | FD20: 36.4 | FE20: 22.8 | FF20: 14.2 | FG20: 19.1 | FH20: 8 | FK20: 6189.8 | FM20: 20.75343 | FN20: 0 | FO20: 6.072 | FP20: 7.5 | FQ20: 27.1496 | FR20: 18.55013 | FS20: 3.5 | FT20: 7 | FU20: 90.52516
A21: 26/07/2025 | B21: 05:30 | C21: 64.9 | D21: 645.6 | E21: 217.2 | H21: 11.5 | I21: 84 | J21: 27 | L21: 0 | M21: 200.6 | N21: 210.8 | O21: 196.1 | P21: 215 | Q21: 111.2 | R21: 450.3 | S21: 4.4 | X21: 108.6 | Y21: 7.4 | Z21: 4.8 | AA21: 0 | AB21: 7 | AC21: 10.4 | AD21: 71 | AI21: 61.5 | AJ21: 5.8 | AN21: 6.4 | AO21: 0 | AP21: 34 | AQ21: 45.9 | AR21: 22.7 | AS21: 18.6 | AT21: 12.6 | AU21: 57.8 | AV21: 184.7 | AW21: 185.1 | AX21: 183.7 | AY21: 82.7 | AZ21: 4.5 | BA21: 0 | BB21: 34.6 | BC21: 30.5 | BD21: 2 | BE21: 0 | BF21: 52.4 | BI21: 22.8 | BL21: 47 | BP21: 66.8 | BQ21: 177 | BR21: 174.6 | BS21: 200 | BT21: 273.1 | CC21: 1.1 | CD21: 57.4 | CE21: 101.6 | CF21: 62.8 | CG21: 72 | CH21: 30.3 | CL21: 146.3 | CM21: 148.8 | CN21: 149.7 | CO21: 0 | CT21: 218 | CU21: 104.4 | CV21: 0 | CW21: 13.7 | CX21: 0 | CY21: 10 | CZ21: 0 | DA21: 7.5 | DB21: 5.3 | DC21: 9.9 | DD21: 0.5 | DE21: 0.3 | DF21: 1.5 | DG21: 2 | DH21: 18.6 | DI21: 7.7 | DJ21: 4 | DK21: 3.4 | DL21: 18.5 | DM21: 0 | DN21: 0 | DO21: 3.5 | DP21: 8.1 | DQ21: 4.5 | DR21: 1.2 | DS21: 2.4 | DT21: 2.6 | DU21: 0 | DV21: 1.4 | DW21: 7.3 | DX21: 1.4 | DY21: 0.4 | DZ21: 4 | EA21: 2.3 | EB21: 3.5 | EC21: 4.9 | ED21: 14 | EE21: 20.2 | EF21: 5.1 | EG21: 0 | EH21: 25.4 | EI21: 42.9 | EJ21: 2.1 | EK21: 2.8 | EL21: 5 | EM21: 2 | EN21: 7.7 | EO21: 3.6 | EP21: 4.1 | EQ21: 4.1 | ER21: 5.2 | ES21: 0 | ET21: 0 | EU21: 0 | EV21: 0.6 | EW21: 78 | EX21: 109.4 | EY21: 0 | EZ21: 0 | FA21: 6.7 | FB21: 18.5 | FC21: 9.9 | FD21: 36.3 | FE21: 22.3 | FF21: 13.8 | FG21: 19.1 | FH21: 7.8 | FK21: 6344 | FM21: 20.95507 | FN21: 0 | FO21: 6.076 | FP21: 7.5 | FQ21: 27.18495 | FR21: 18.55006 | FS21: 3.6 | FT21: 6.9 | FU21: 90.76608
A22: 26/07/2025 | B22: 06:00 | C22: 52.7 | D22: 643.4 | E22: 216.4 | H22: 11 | I22: 84.9 | J22: 27.2 | L22: 0 | M22: 205.9 | N22: 207.3 | O22: 195 | P22: 217.3 | Q22: 111.3 | R22: 436.6 | S22: 4.2 | X22: 109.1 | Y22: 7.3 | Z22: 4.7 | AA22: 0 | AB22: 6.9 | AC22: 10.5 | AD22: 49.6 | AI22: 40.1 | AJ22: 52.5 | AN22: 6.4 | AO22: 0 | AP22: 33.1 | AQ22: 39.5 | AR22: 21.7 | AS22: 18.6 | AT22: 12.6 | AU22: 56.5 | AV22: 181.6 | AW22: 182 | AX22: 183.7 | AY22: 81.6 | AZ22: 4.8 | BA22: 0 | BB22: 31.2 | BC22: 29.7 | BD22: 2 | BE22: 0 | BF22: 48.9 | BI22: 22.2 | BL22: 46.9 | BP22: 65.9 | BQ22: 177.6 | BR22: 175.1 | BS22: 200 | BT22: 273.6 | CC22: 1 | CD22: 51.5 | CE22: 100.3 | CF22: 61.9 | CG22: 75.4 | CH22: 29.5 | CL22: 146.5 | CM22: 149 | CN22: 149.9 | CO22: 0 | CT22: 217.8 | CU22: 104.4 | CV22: 0 | CW22: 17.4 | CX22: 0 | CY22: 9.4 | CZ22: 0 | DA22: 7.6 | DB22: 5.1 | DC22: 9.9 | DD22: 1.6 | DE22: 0.3 | DF22: 1.5 | DG22: 2 | DH22: 18.3 | DI22: 8.1 | DJ22: 4 | DK22: 3.4 | DL22: 18.5 | DM22: 0.1 | DN22: 0 | DO22: 6.9 | DP22: 14.4 | DQ22: 4.5 | DR22: 1.2 | DS22: 2.4 | DT22: 2.6 | DU22: 0 | DV22: 1.4 | DW22: 7.3 | DX22: 1.4 | DY22: 0.4 | DZ22: 4 | EA22: 0.4 | EB22: 3.4 | EC22: 4.8 | ED22: 14 | EE22: 21 | EF22: 7 | EG22: 0 | EH22: 25.5 | EI22: 39.8 | EJ22: 2.6 | EK22: 2.3 | EL22: 5 | EM22: 2 | EN22: 7.7 | EO22: 3.6 | EP22: 4.1 | EQ22: 4.1 | ER22: 4.8 | ES22: 0 | ET22: 0 | EU22: 0 | EV22: 0.6 | EW22: 104.7 | EX22: 125.1 | EY22: 0 | EZ22: 0 | FA22: 6.6 | FB22: 18.5 | FC22: 9.6 | FD22: 36.7 | FE22: 22.5 | FF22: 13.6 | FG22: 19.1 | FH22: 8.7 | FK22: 6347.8 | FM22: 20.8285 | FN22: 0 | FO22: 6.072 | FP22: 7.5 | FQ22: 27.24554 | FR22: 18.54963 | FS22: 3.6 | FT22: 6.9 | FU22: 90.69567
... A58: 27/07/2025 | B58: 00:00 | C58: 125.1 | D58: 603.9 | E58: 205.6 | H58: 25.3 | I58: 80.5 | J58: 50.2 | L58: 104.9 | M58: 105 | N58: 104.9 | O58: 205.2 | P58: 214.4 | Q58: 110.9 | R58: 338.7 | S58: 4.1 | X58: 108.8 | Y58: 7.9 | Z58: 5.1 | AA58: 0 | AB58: 7 | AC58: 12.6 | AD58: 140.7 | AI58: 57.2 | AJ58: 105.2 | AN58: 6.4 | AO58: 0 | AP58: 29.3 | AQ58: 73.8 | AR58: 19.8 | AS58: 18.6 | AT58: 12.4 | AU58: 56.6663 | AV58: 125.2 | AW58: 125.7 | AX58: 157.4 | AY58: 83.1 | AZ58: 6 | BA58: 1.9 | BB58: 31.5 | BC58: 31.4 | BD58: 2 | BE58: 0 | BF58: 53.3 | BI58: 52.5 | BL58: 47.3 | BP58: 65.7 | BQ58: 149.7 | BR58: 174.6 | BS58: 200 | BT58: 261.9 | CC58: 1 | CD58: 193.7 | CE58: 96.1 | CF58: 65.5 | CG58: 71.4 | CH58: 30.3 | CL58: 111.5 | CM58: 111.2 | CN58: 126.8 | CO58: 0 | CT58: 137.1 | CU58: 77.5 | CV58: 0 | CW58: 118.2 | CX58: 0 | CY58: 14.3 | CZ58: 0 | DA58: 7.3 | DB58: 5.3 | DC58: 10 | DD58: 2.2 | DE58: 0.3 | DF58: 1.5 | DG58: 2 | DH58: 18.6 | DI58: 6.3 | DJ58: 3.9 | DK58: 3.4 | DL58: 18.5 | DM58: 0 | DN58: 0 | DO58: 31.8 | DP58: 86.1 | DQ58: 4.5 | DR58: 1.1 | DS58: 2.4 | DT58: 2.6 | DU58: 0 | DV58: 2.1 | DW58: 13.7 | DX58: 1.4 | DY58: 0.4 | DZ58: 4.5 | EA58: 0 | EB58: 3.5 | EC58: 5.1 | ED58: 14 | EE58: 20.2 | EF58: 26.9 | EG58: 0 | EH58: 101.6 | EI58: 104.7 | EJ58: 16.4 | EK58: 9.6 | EL58: 5 | EM58: 2.2 | EN58: 7.4 | EO58: 3.8 | EP58: 4.2 | EQ58: 4.4 | ER58: 11.3 | ES58: 0 | ET58: 0 | EU58: 0 | EV58: 0.6 | EW58: 105.1 | EX58: 90.8 | EY58: 0 | EZ58: 0 | FA58: 6.6 | FB58: 18.3 | FC58: 9.1 | FD58: 36.7 | FE58: 27.9 | FF58: 13.7 | FG58: 18.9 | FH58: 8.6 | FK58: 6570.4663 | FM58: 19.53428 | FN58: 0 | FO58: 6.148 | FP58: 7.5 | FQ58: 27.24754 | FR58: 18.55647 | FS58: 4 | FT58: 16 | FU58: 98.98629
A59: EJEC | C59: 1777.3 | D59: 14697.5 | E59: 4972.2 | F59: 0 | G59: 0 | H59: 582.65 | I59: 1977.45 | J59: 1287.75 | K59: 0 | L59: 555.05 | M59: 4243.8 | N59: 4290.5 | O59: 4573.1 | P59: 5140.45 | Q59: 2660.6 | R59: 7540.25 | S59: 100.1 | T59: 0 | U59: 0 | V59: 0 | W59: 0 | X59: 2598.45 | Y59: 180.45 | Z59: 120.1 | AA59: 235 | AB59: 167.3 | AC59: 283.8 | AD59: 1800.3 | AE59: 0 | AF59: 0 | AG59: 0 | AH59: 0 | AI59: 1472.55 | AJ59: 2146.8 | AK59: 0 | AL59: 0 | AM59: 0 | AN59: 155.5 | AO59: 1009.2 | AP59: 724.7 | AQ59: 967.15 | AR59: 467.05 | AS59: 446.15 | AT59: 300.45 | AU59: 1359.6328 | AV59: 4341.15 | AW59: 4350.4 | AX59: 4396.4 | AY59: 1732.4 | AZ59: 114.7 | BA59: 16.9 | BB59: 707.1 | BC59: 747.25 | BD59: 47.65 | BE59: 219.55 | BF59: 1536.4 | BG59: 0 | BH59: 0 | BI59: 1179.7 | BJ59: 0 | BK59: 0 | BL59: 1118.25 | BM59: 0 | BN59: 0 | BO59: 0 | BP59: 1419.5 | BQ59: 4229.8 | BR59: 4181 | BS59: 4800 | BT59: 6528.8 | BU59: 0 | BV59: 0 | BW59: 0 | BX59: 0 | BY59: 0 | BZ59: 0 | CA59: 0 | CB59: 0 | CC59: 26.2 | CD59: 2600.45 | CE59: 2251.15 | CF59: 1530.8 | CG59: 1737.4 | CH59: 698.7 | CI59: 0 | CJ59: 0 | CK59: 0 | CL59: 3470.75 | CM59: 3523.6 | CN59: 3700.65 | CO59: 2032 | CP59: 0 | CQ59: 0 | CR59: 0 | CS59: 0 | CT59: 5052.2 | CU59: 2442.1 | CV59: 8.3 | CW59: 1712.85 | CX59: 598.85 | CY59: 267.85 | CZ59: 2.85 | DA59: 177.25 | DB59: 122.9 | DC59: 203.15 | DD59: 48.8 | DE59: 6.7 | DF59: 36 | DG59: 46 | DH59: 441.8 | DI59: 172.15 | DJ59: 101 | DK59: 80.55 | DL59: 444 | DM59: 121.25 | DN59: 147.1 | DO59: 432.3 | DP59: 1243.5 | DQ59: 108 | DR59: 27.25 | DS59: 57.6 | DT59: 61.85 | DU59: 137.85 | DV59: 49.35 | DW59: 311.4 | DX59: 32.4 | DY59: 9.5 | DZ59: 108.3 | EA59: 21.2 | EB59: 82.6 | EC59: 117.4 | ED59: 329.7 | EE59: 476.55 | EF59: 788.4 | EG59: 267.65 | EH59: 1638.4 | EI59: 1875.9 | EJ59: 258.55 | EK59: 177.6 | EL59: 120.65 | EM59: 51.25 | EN59: 186.2 | EO59: 87.3 | EP59: 98.9 | EQ59: 100.6 | ER59: 215.2 | ES59: 1998.4 | ET59: 117.5 | EU59: 1119.6 | EV59: 14.4 | EW59: 1596.2 | EX59: 1784.85 | EY59: 812.65 | EZ59: 117.8 | FA59: 160.6 | FB59: 444.5 | FC59: 222.15 | FD59: 868.75 | FE59: 549.1 | FF59: 334.05 | FG59: 433.8 | FH59: 191.55 | FI59: 0 | FJ59: 0 | FK59: 164544.83 | FM59: 478.48568 | FN59: 39.994 | FO59: 141.626 | FP59: 179.85 | FQ59: 644.35898 | FR59: 445.4479 | FS59: 78.75 | FT59: 224.6 | FU59: 2233.1126

Sheet REACTIVA
B3: sábado, 26 de Julio del 2025
A5: POTENCIA REACTIVA EJECUTADA DE LAS UNIDADES DE GENERACIÓN DEL COES (MVAR) | FM5: CENTRALES NO INTEGRANTES COES
A6: FECHA | B6: HORA | C6: 65333 | D6: 101 | E6: 102 | F6: 42667 | G6: 42668 | H6: 126 | I6: 127 | J6: 138 | K6: 139 | L6: 197 | M6: 203 | N6: 204 | O6: 230 | P6: 209 | Q6: 56677 | R6: 796 | S6: 2146 | T6: 142 | U6: 143 | V6: 125 | W6: 187 | X6: 163 | Y6: 298 | Z6: 299 | AA6: 219 | AB6: 151 | AC6: 152 | AD6: 153 | AE6: 154 | AF6: 756 | AG6: 156 | AH6: 155 | AI6: 182 | AJ6: 212 | AK6: 758 | AL6: 263 | AM6: 265 | AN6: 775 | AO6: 777 | AP6: 2154 | AQ6: 150 | AR6: 149 | AS6: 188 | AT6: 2131 | AU6: 755 | AV6: 252 | AW6: 249 | AX6: 250 | AY6: 117 | AZ6: 267 | BA6: 268 | BB6: 119 | BC6: 120 | BD6: 189 | BE6: 122 | BF6: 266 | BG6: 337 | BH6: 338 | BI6: 251 | BJ6: 115 | BK6: 239 | BL6: 288 | BM6: 240 | BN6: 241 | BO6: 242 | BP6: 191 | BQ6: 194 | BR6: 196 | BS6: 207 | BT6: 236 | BU6: 795 | BV6: 285 | BW6: 995 | BX6: 996 | BY6: 997 | BZ6: 766 | CA6: 926 | CB6: 924 | CC6: 121 | CD6: 103 | CE6: 104 | CF6: 106 | CG6: 105 | CH6: 107 | CI6: 110 | CJ6: 109 | CK6: 144 | CL6: 113 | CM6: 114 | CN6: 193 | CO6: 208 | CP6: 786 | CQ6: 787 | CR6: 788 | CS6: 789 | CT6: 248 | CU6: 2159 | CV6: 303 | CW6: 59715 | CX6: 62255 | CY6: 1263 | CZ6: 61800 | DA6: 2194 | DB6: 69125 | DC6: 216 | DD6: 198 | DE6: 49607 | DF6: 214 | DG6: 260 | DH6: 2152 | DI6: 2128 | DJ6: 247 | DK6: 228 | DL6: 2135 | DM6: 261 | DN6: 237 | DO6: 253 | DP6: 770 | DQ6: 225 | DR6: 2201 | DS6: 2171 | DT6: 760 | DU6: 235 | DV6: 238 | DW6: 2184 | DX6: 61855 | DY6: 223 | DZ6: 226 | EA6: 201 | EB6: 258 | EC6: 259 | ED6: 920 | EE6: 257 | EF6: 256 | EG6: 2148 | EH6: 58288 | EI6: 58289 | EJ6: 58839 | EK6: 58840 | EL6: 296 | EM6: 297 | EN6: 211 | EO6: 2175 | EP6: 2178 | EQ6: 2181 | ER6: 1262 | ES6: 63425 | ET6: 233 | EU6: 2150 | EV6: 2165 | EW6: 2161 | EX6: 61197 | EY6: 58851 | EZ6: 234 | FA6: 215 | FB6: 917 | FC6: 289 | FD6: 58333 | FE6: 58336 | FF6: 213 | FG6: 232 | FH6: 2190 | FI6: 202 | FJ6: 58487 | FK6: TOTAL COES | FM6: 221 | FN6: 222 | FO6: 224 | FP6: 2187 | FQ6: 227 | FR6: 49400 | FS6: 199 | FT6: 200 | FU6: TOTAL NO COES
C7: SUR | D7: CENTRO | E7: CENTRO | F7: NORTE | G7: NORTE | H7: NORTE | I7: NORTE | J7: CENTRO | K7: CENTRO | L7: CENTRO | M7: CENTRO | N7: CENTRO | O7: CENTRO | P7: CENTRO | Q7: CENTRO | R7: CENTRO | S7: CENTRO | T7: CENTRO | U7: CENTRO | V7: CENTRO | W7: CENTRO | X7: SUR | Y7: SUR | Z7: SUR | AA7: CENTRO | AB7: SUR | AC7: SUR | AD7: SUR | AE7: SUR | AF7: SUR | AG7: SUR | AH7: SUR | AI7: SUR | AJ7: CENTRO | AK7: NORTE | AL7: NORTE | AM7: NORTE | AN7: CENTRO | AO7: CENTRO | AP7: CENTRO | AQ7: CENTRO | AR7: CENTRO | AS7: CENTRO | AT7: CENTRO | AU7: SUR | AV7: CENTRO | AW7: CENTRO | AX7: CENTRO | AY7: CENTRO | AZ7: CENTRO | BA7: CENTRO | BB7: CENTRO | BC7: CENTRO | BD7: SUR | BE7: NORTE | BF7: CENTRO | BG7: CENTRO | BH7: CENTRO | BI7: CENTRO | BJ7: NORTE | BK7: NORTE | BL7: NORTE | BM7: SUR | BN7: SUR | BO7: SUR | BP7: CENTRO | BQ7: CENTRO | BR7: CENTRO | BS7: CENTRO | BT7: CENTRO | BU7: CENTRO | BV7: CENTRO | BW7: SUR | BX7: SUR | BY7: SUR | BZ7: NORTE | CA7: SUR | CB7: CENTRO | CC7: NORTE | CD7: CENTRO | CE7: CENTRO | CF7: CENTRO | CG7: CENTRO | CH7: CENTRO | CI7: CENTRO | CJ7: CENTRO | CK7: CENTRO | CL7: CENTRO | CM7: CENTRO | CN7: CENTRO | CO7: CENTRO | CP7: SUR | CQ7: SUR | CR7: SUR | CS7: SUR | CT7: CENTRO | CU7: CENTRO | CV7: CENTRO | CW7: CENTRO | CX7: SUR | CY7: NORTE | CZ7: NORTE | DA7: NORTE | DB7: CENTRO | DC7: NORTE | DD7: NORTE | DE7: SUR | DF7: CENTRO | DG7: CENTRO | DH7: CENTRO | DI7: NORTE | DJ7: NORTE | DK7: CENTRO | DL7: CENTRO | DM7: SUR | DN7: SUR | DO7: CENTRO | DP7: CENTRO | DQ7: CENTRO | DR7: CENTRO | DS7: CENTRO | DT7: CENTRO | DU7: SUR | DV7: CENTRO | DW7: CENTRO | DX7: NORTE | DY7: CENTRO | DZ7: CENTRO | EA7: NORTE | EB7: CENTRO | EC7: CENTRO | ED7: CENTRO | EE7: NORTE | EF7: NORTE | EG7: SUR | EH7: CENTRO | EI7: CENTRO | EJ7: CENTRO | EK7: CENTRO | EL7: CENTRO | EM7: CENTRO | EN7: SUR | EO7: SUR | EP7: SUR | EQ7: SUR | ER7: NORTE | ES7: SUR | ET7: SUR | EU7: SUR | EV7: CENTRO | EW7: CENTRO | EX7: CENTRO | EY7: SUR | EZ7: SUR | FA7: NORTE | FB7: CENTRO | FC7: NORTE | FD7: NORTE | FE7: NORTE | FF7: CENTRO | FG7: NORTE | FH7: NORTE | FI7: CENTRO | FJ7: CENTRO | FM7: NORTE | FN7: CENTRO | FO7: NORTE | FP7: NORTE | FQ7: NORTE | FR7: NORTE | FS7: NORTE | FT7: NORTE
C8: HIDROELÉCTRICA | D8: HIDROELÉCTRICA | E8: HIDROELÉCTRICA | F8: TERMOELÉCTRICA | G8: TERMOELÉCTRICA | H8: HIDROELÉCTRICA | I8: HIDROELÉCTRICA | J8: TERMOELÉCTRICA | K8: TERMOELÉCTRICA | L8: TERMOELÉCTRICA | M8: TERMOELÉCTRICA | N8: TERMOELÉCTRICA | O8: TERMOELÉCTRICA | P8: TERMOELÉCTRICA | Q8: TERMOELÉCTRICA | R8: HIDROELÉCTRICA | S8: HIDROELÉCTRICA | T8: TERMOELÉCTRICA | U8: TERMOELÉCTRICA | V8: TERMOELÉCTRICA | W8: TERMOELÉCTRICA | X8: HIDROELÉCTRICA | Y8: HIDROELÉCTRICA | Z8: HIDROELÉCTRICA | AA8: TERMOELÉCTRICA | AB8: HIDROELÉCTRICA | AC8: HIDROELÉCTRICA | AD8: HIDROELÉCTRICA | AE8: HIDROELÉCTRICA | AF8: TERMOELÉCTRICA | AG8: TERMOELÉCTRICA | AH8: TERMOELÉCTRICA | AI8: HIDROELÉCTRICA | AJ8: HIDROELÉCTRICA | AK8: TERMOELÉCTRICA | AL8: TERMOELÉCTRICA | AM8: TERMOELÉCTRICA | AN8: HIDROELÉCTRICA | AO8: HIDROELÉCTRICA | AP8: HIDROELÉCTRICA | AQ8: HIDROELÉCTRICA | AR8: HIDROELÉCTRICA | AS8: HIDROELÉCTRICA | AT8: HIDROELÉCTRICA | AU8: HIDROELÉCTRICA | AV8: TERMOELÉCTRICA | AW8: TERMOELÉCTRICA | AX8: TERMOELÉCTRICA | AY8: HIDROELÉCTRICA | AZ8: HIDROELÉCTRICA | BA8: HIDROELÉCTRICA | BB8: HIDROELÉCTRICA | BC8: HIDROELÉCTRICA | BD8: HIDROELÉCTRICA | BE8: HIDROELÉCTRICA | BF8: HIDROELÉCTRICA | BG8: HIDROELÉCTRICA | BH8: HIDROELÉCTRICA | BI8: HIDROELÉCTRICA | BJ8: TERMOELÉCTRICA | BK8: TERMOELÉCTRICA | BL8: TERMOELÉCTRICA | BM8: TERMOELÉCTRICA | BN8: TERMOELÉCTRICA | BO8: TERMOELÉCTRICA | BP8: HIDROELÉCTRICA | BQ8: TERMOELÉCTRICA | BR8: TERMOELÉCTRICA | BS8: TERMOELÉCTRICA | BT8: TERMOELÉCTRICA | BU8: TERMOELÉCTRICA | BV8: TERMOELÉCTRICA | BW8: TERMOELÉCTRICA | BX8: TERMOELÉCTRICA | BY8: TERMOELÉCTRICA | BZ8: HIDROELÉCTRICA | CA8: TERMOELÉCTRICA | CB8: TERMOELÉCTRICA | CC8: HIDROELÉCTRICA | CD8: HIDROELÉCTRICA | CE8: HIDROELÉCTRICA | CF8: HIDROELÉCTRICA | CG8: HIDROELÉCTRICA | CH8: HIDROELÉCTRICA | CI8: TERMOELÉCTRICA | CJ8: TERMOELÉCTRICA | CK8: TERMOELÉCTRICA | CL8: TERMOELÉCTRICA | CM8: TERMOELÉCTRICA | CN8: TERMOELÉCTRICA | CO8: TERMOELÉCTRICA | CP8: TERMOELÉCTRICA | CQ8: TERMOELÉCTRICA | CR8: TERMOELÉCTRICA | CS8: TERMOELÉCTRICA | CT8: TERMOELÉCTRICA | CU8: TERMOELÉCTRICA | CV8: SOLAR | CW8: EÓLICA | CX8: SOLAR | CY8: EÓLICA | CZ8: SOLAR | DA8: HIDROELÉCTRICA | DB8: HIDROELÉCTRICA | DC8: HIDROELÉCTRICA | DD8: HIDROELÉCTRICA | DE8: HIDROELÉCTRICA | DF8: HIDROELÉCTRICA | DG8: HIDROELÉCTRICA | DH8: HIDROELÉCTRICA | DI8: HIDROELÉCTRICA | DJ8: HIDROELÉCTRICA | DK8: HIDROELÉCTRICA | DL8: HIDROELÉCTRICA | DM8: SOLAR | DN8: SOLAR | DO8: EÓLICA | DP8: EÓLICA | DQ8: TERMOELÉCTRICA | DR8: TERMOELÉCTRICA | DS8: TERMOELÉCTRICA | DT8: TERMOELÉCTRICA | DU8: SOLAR | DV8: HIDROELÉCTRICA | DW8: HIDROELÉCTRICA | DX8: HIDROELÉCTRICA | DY8: HIDROELÉCTRICA | DZ8: HIDROELÉCTRICA | EA8: HIDROELÉCTRICA | EB8: HIDROELÉCTRICA | EC8: HIDROELÉCTRICA | ED8: HIDROELÉCTRICA | EE8: EÓLICA | EF8: EÓLICA | EG8: SOLAR | EH8: EÓLICA | EI8: EÓLICA | EJ8: EÓLICA | EK8: EÓLICA | EL8: HIDROELÉCTRICA | EM8: HIDROELÉCTRICA | EN8: HIDROELÉCTRICA | EO8: HIDROELÉCTRICA | EP8: HIDROELÉCTRICA | EQ8: HIDROELÉCTRICA | ER8: EÓLICA | ES8: SOLAR | ET8: SOLAR | EU8: SOLAR | EV8: HIDROELÉCTRICA | EW8: EÓLICA | EX8: EÓLICA | EY8: SOLAR | EZ8: SOLAR | FA8: HIDROELÉCTRICA | FB8: HIDROELÉCTRICA | FC8: TERMOELÉCTRICA | FD8: TERMOELÉCTRICA | FE8: TERMOELÉCTRICA | FF8: TERMOELÉCTRICA | FG8: TERMOELÉCTRICA | FH8: TERMOELÉCTRICA | FI8: TERMOELÉCTRICA | FJ8: TERMOELÉCTRICA | FM8: HIDROELÉCTRICA | FN8: HIDROELÉCTRICA | FO8: HIDROELÉCTRICA | FP8: HIDROELÉCTRICA | FQ8: TERMOELÉCTRICA | FR8: TERMOELÉCTRICA | FS8: HIDROELÉCTRICA | FT8: HIDROELÉCTRICA
