Workbook

Sheet EVENTOS
B3: jueves, 15 de Mayo del 2025
B5: INFORMACIÓN DE EVENTOS PRINCIPALES EN SUS INSTALACIONES
B6: TIPO DE EVENTO | C6: EMPRESA | D6: UBICACIÓN | E6: TIPO DE EQUIPO | F6: EQUIPO | G6: INICIO | H6: FINAL | I6: DESCRIPCIÓN | J6: MW INDISP. | K6: INTERRUPCIÓN (SI/NO) | L6: TENSIÓN DE FALLA (kV)
B7: P.ENERG | C7: CONCESIONARIA LINEA DE TRANSMISIÓN LA NIÑA S.A.C. | D7: LA NIÑA - MIGUEL GRAU | E7: LINEA DE TRANSMISION | F7: L-5012 | G7: 15/05/2025 17:46:00 | H7: 15/05/2025 17:46:00 | I7: PRIMERA ENERGIZACIÓN DE LA LÍNEA L-5012 (LA NIÑA - MIGUEL GRAU) DE 500 KV Y DE LA S.E. MIGUEL GRAU 500 KV | K7: NO
B8: EVENTO | C8: CONELSUR LT SAC | D8: PORTILLO | E8: SUBESTACION | F8: SS.EE. | G8: 15/05/2025 00:00:00 | H8: 16/05/2025 00:00:00 | I8: DECLARACIÓN DE SITUACIÓN EXCEPCIONAL EN LA S.E. PORTILLO DE 60 kV | K8: NO
B9: FALLA | C9: ELECTRONOROESTE S.A. | D9: PIURA OESTE - CATACAOS | E9: LINEA DE TRANSMISION | F9: L-6560 | G9: 15/05/2025 12:40:08 | H9: 15/05/2025 18:11:00 | I9: DESCONEXION DE LA LÍNEA L-6560 (PIURA OESTE - CATACAOS) 60 KV | J9: 17.79 | K9: SI | L9: 60
B10: FALLA | C10: EMPRESA DE GENERACION HUALLAGA | D10: CHAGLLA | E10: GENERADOR HIDROELÉCTRICO | F10: G1 | G10: 15/05/2025 08:56:19 | H10: 15/05/2025 09:24:43 | I10: DESCONEXIÓN DEL GRUPO G1 DE LA C.H. CHAGLLA | K10: NO | L10: 13.8

Sheet RESTRIC_OPE
B3: jueves, 15 de Mayo del 2025
B5: RESTRICCIONES OPERATIVAS
B6: FECHA | C6: HORA INICIO | D6: HORA FINAL | E6: EMPRESA | F6: UBICACIÓN | G6: T.Eq. | H6: EQUIPO | I6: DESCRIPCIÓN
B7: 15/05/2025 | C7: 00:00 | D7: 24:00 | E7: CELEPSA | F7: C.H. EL PLATANAL | G7: CH | H7: CENTRAL | I7: Debido al incremento del caudal del rio cañete y establecimiento de la temporada de avenida, se declara la C.H. El Platanal como CENTRAL HIDRÁULICA DE PASADA (correo 03/01/2025).
B8: 15/05/2025 | C8: 00:00 | D8: 24:00 | E8: EGASA | F8: C.H. CHARCANI II | G8: GH | H8: G2 | I8: El Grupo N°02 esta operando con una potencia no mayor a 0.07MW en referencia a 0.18MW de su potencia efectiva, con el fin de no generar daños mayores hasta la reparación de su cojinete.
B9: 15/05/2025 | C9: 00:00 | D9: 24:00 | E9: EGASA | F9: C.H. CHARCANI V | G9: EMB | H9: CAMPANARIO | I9: La CH Charcani V no puede despachar menor a 70 MW aprox. dado que debe controlar el caudal de salida del dique de Campanario, de acuerdo con lo comunicado el día 12.05.2025
B10: 15/05/2025 | C10: 00:00 | D10: 24:00 | E10: EGASA | F10: S.E. CONVERTIDOR | G10: BARRA | H10: BARRA138KV | I10: EGASA limitó la capacidad del transformador 138 kV/33 kV a 50 MVA por deterioro del aislamiento.
B11: 15/05/2025 | C11: 00:00 | D11: 24:00 | E11: ENEL GENERACION PIURA S.A. | F11: C.T. MALACAS | G11: CT | H11: CENTRAL | I11: De acuerdo con la comunicación vía correo del día 24.10.2024. ENEL GENERACIÓN PIURA informa una restricción de potencia para alcanzar 105 MW en simultaneo (TG6+TGN4).
B12: 15/05/2025 | C12: 00:00 | D12: 24:00 | E12: ENGIE | F12: C.E. PUNTA LOMITAS | G12: CE | H12: CENTRAL | I12: De acuerdo a la carta ENG/737-2024 (Exp:202400007555). Limitación de cables de media tensión a 100 MW de los transformadores PLT1 y PLT2 de la CE Punta Lomitas. Quedan limitados a 200 MW la generación de CE Punta Lomitas y Punta Lomitas Extensión.
B13: 15/05/2025 | C13: 00:00 | D13: 24:00 | E13: ENGIE | F13: C.H. QUITARACSA | G13: CH | H13: CENTRAL | I13: De acuerdo con el correo del 23.04 se considera la operación continua de la CH Quitaracsa debido a que el sistema de refrigeración de la CH Cañón del Pato se alimenta desde la descarga del caudal turbinado por la CH Quitaracsa.
B14: 15/05/2025 | C14: 00:00 | D14: 24:00 | E14: ENGIE | F14: C.H. YUNCÁN | G14: GH | H14: G3 | I14: Según la carta N° ENG/ 198-2024 enviada por su representada, se opera de forma continua el G3 de la CH Yuncán, debido a la ejecución de mantenimientos necesarios para evitar daños en los sellos de seguridad de la válvula esférica del grupo.
B15: 15/05/2025 | C15: 00:00 | D15: 24:00 | E15: ENGIE | F15: C.T. CHILCA 1 | G15: CT | H15: CENTRAL | I15: Restricción de temperatura de la C.T Chilca, ver valor en el modelo de despacho.
B16: 15/05/2025 | C16: 00:00 | D16: 24:00 | E16: ENGIE | F16: C.T. CHILCA 1 | G16: CT | H16: CENTRAL | I16: Con carta ENG/971-2023, indica que no puede cumplir con las IO considerada en el PDO_17122023 dado que vulneran la seguridad de sus activos. Indican que se debe tomar TMO=168h.
B17: 15/05/2025 | C17: 00:00 | D17: 24:00 | E17: ENGIE | F17: C.T. CHILCA 2 | G17: CT | H17: CENTRAL | I17: Con carta ENG/971-2023, indica que no puede cumplir con las IO considerada en el PDO_17122023 dado que vulneran la seguridad de sus activos. Indican que se debe tomar TMO=168h.
... B52: 15/05/2025 | C52: 00:00 | D52: 24:00 | E52: TERMOSELVA | F52: C.T. AGUAYTÍA | G52: CT | H52: CENTRAL | I52: Restricción de 19 MMPCD de GN para la CT Aguaytía.

Sheet MANTENIMIENTO EJECUTADOS
B3: jueves, 15 de Mayo del 2025
B5: Mantenimiento Ejecutado
B6: Empresa | C6: Ubicación | D6: Equipo | E6: Inicio | F6: Final | G6: Descripción | H6: MW Indisp. | I6: Prog. | J6: Dispon | K6: Interrupc. | L6: Tipo | M6: CodEq | N6: TipoEq_Osinerg
B7: AGROAURORA S.A.C. | C7: MAPLE ETANOL | D7: CENTRAL | E7: 15/05/2025 00:00 | F7: 16/05/2025 00:00 | G7: CENTRAL TERMOELECTRICA FUERA DE SERVICIO POR FALTA DE MATERIA PRIMA PARA LOS REQUERIMIENTOS DE CALOR UTIL EN FABRICA. | H7: 17 | I7: P | J7: F/S | K7: N | L7: OTROS | M7: 13417 | N7: G
B8: AGROAURORA S.A.C. | C8: MAPLE ETANOL | D8: CENTRAL | E8: 15/05/2025 00:00 | F8: 16/05/2025 00:00 | G8: MANTENIMIENTO PREVENTIVO PROGRAMADO DE LA CENTRAL TERMOELECTRICA Y EQUIPOS AUXILIARES. | H8: 17 | I8: P | J8: F/S | K8: N | L8: PREV. | M8: 13417 | N8: G
B9: AGROINDUSTRIAS SAN JACINTO S.A.A. | C9: SAN JACINTO | D9: CENTRAL | E9: 15/05/2025 00:00 | F9: 16/05/2025 00:00 | G9: Mantenimiento Anual. | H9: 8.15 | I9: P | J9: F/S | K9: N | L9: PREV. | M9: 19865 | N9: G
B10: ASOCIACION SANTA LUCIA DE CHACAS | C10: CH HUALLIN | D10: CENTRAL | E10: 15/05/2025 08:00 | F10: 15/05/2025 10:07 | G10: DESARENADO DE BOCATOMA | H10: 2.7 | I10: P | J10: F/S | K10: N | L10: PREV. | M10: 23678 | N10: G
B11: ATLANTICA TRANSMISION SUR S.A. | C11: MONTALVO | D11: ACOPLE 220 | E11: 15/05/2025 00:00 | F11: 16/05/2025 00:00 | G11: Proyecto Refuerzos: Reemplazo del HMI existente, Pruebas y Configuracion. No se contara con nivel 1 de operacion. | H11: 0 | I11: P | J11: E/S | K11: N | L11: P.ENERG | M11: 14767 | N11: T
B12: ATLANTICA TRANSMISION SUR S.A. | C12: MONTALVO | D12: BARRA A_220KV | E12: 15/05/2025 00:00 | F12: 16/05/2025 00:00 | G12: Proyecto Refuerzos: Indisponibilidad de la proteccion diferencial de barras 220 kV por Conexion de la nueva UB-87B hacia la UC existente,Configuracion y Pruebas. | H12: 0 | I12: P | J12: E/S | K12: N | L12: P.ENERG | M12: 13869 | N12: T
B13: ATLANTICA TRANSMISION SUR S.A. | C13: MONTALVO | D13: BARRA A_500KV | E13: 15/05/2025 00:00 | F13: 16/05/2025 00:00 | G13: Proyecto Refuerzos: Indisponibilidad de la proteccion diferencial de barras 500kV por conexion de nueva UB-87B hacia la UC existente, Configuracion y Pruebas. | H13: 0 | I13: P | J13: E/S | K13: N | L13: P.ENERG | M13: 13870 | N13: T
B14: ATLANTICA TRANSMISION SUR S.A. | C14: MONTALVO | D14: BARRA B_220kV | E14: 15/05/2025 00:00 | F14: 16/05/2025 00:00 | G14: Proyecto Refuerzos: Indisponibilidad de la proteccion diferencial de barras 220 kV por Conexion de la nueva UB-87B hacia la UC existente,Configuracion y Pruebas. | H14: 0 | I14: P | J14: E/S | K14: N | L14: P.ENERG | M14: 14765 | N14: T
B15: ATLANTICA TRANSMISION SUR S.A. | C15: MONTALVO | D15: BARRA B_500KV | E15: 15/05/2025 00:00 | F15: 16/05/2025 00:00 | G15: Proyecto Refuerzos: Indisponibilidad de la proteccion diferencial de barras 500kV por conexion de nueva UB-87B hacia la UC existente, Configuracion y Pruebas. | H15: 0 | I15: P | J15: E/S | K15: N | L15: P.ENERG | M15: 13871 | N15: T
B16: ATLANTICA TRANSMISION SUR S.A. | C16: MONTALVO | D16: CL-2057 | E16: 15/05/2025 00:00 | F16: 16/05/2025 00:00 | G16: Proyecto Refuerzos: Reemplazo del HMI existente, Pruebas y Configuracion. No se contara con nivel 1 de operacion. | H16: 0 | I16: P | J16: E/S | K16: N | L16: P.ENERG | M16: 13812 | N16: T
B17: ATLANTICA TRANSMISION SUR S.A. | C17: MONTALVO | D17: CL-AUT-5671_500 | E17: 15/05/2025 00:00 | F17: 16/05/2025 00:00 | G17: Proyecto Refuerzos: Reemplazo del HMI existente, Pruebas y Configuracion. No se contara con nivel 1 de operacion en INT-5671, INT-5652 y SAT-5671. | H17: 0 | I17: P | J17: E/S | K17: N | L17: P.ENERG | M17: 13809 | N17: T
B18: ATLANTICA TRANSMISION SUR S.A. | C18: MONTALVO | D18: INT-5652 | E18: 15/05/2025 00:00 | F18: 16/05/2025 00:00 | G18: Proyecto Refuerzos:Indisponible por Implementacion de conexion de corrientes, disparos, posiciones, enclavamientos hacia los equipos del nuevos Autotransformador. AUT-5671 en servicio solo por Barra A 500kV. | H18: 0 | I18: P | J18: F/S | K18: N | L18: P.ENERG | M18: 13765 | N18: T
... B170: TRANSMISORA ELECTRICA DEL SUR S.A.C | C170: TINTAYA NUEVA | D170: TINTA220B | E170: 15/05/2025 13:05 | F170: 15/05/2025 16:47 | G170: INDISPONIBLE A SOLICITUD DE ATN1, DEBIDO A MANTENIMIENTO EN CL-2024. | H170: 0 | I170: P | J170: F/S | K170: N | L170: OTROS | M170: 13851 | N170: T

Sheet INGRESO OC
A3: jueves, 15 de Mayo del 2025
A5: INGRESO A OPERACIÓN COMERCIAL
A6: EMPRESA | B6: TIPO DE EQUIPO | C6: UBICACIÓN | D6: EQUIPO | E6: Fecha y hora de Ingreso a Operación Comercial

Sheet DESPACHO_EJECUTADO
B3: jueves, 15 de Mayo del 2025
A5: POTENCIA ACTIVA EJECUTADA DE LAS UNIDADES DE GENERACIÓN DEL SEIN (MW) | FL5: CENTRALES NO INTEGRANTES COES
A6: FECHA | B6: HORA | C6: 65333 | D6: 101 | E6: 102 | F6: 42667 | G6: 42668 | H6: 126 | I6: 127 | J6: 138 | K6: 139 | L6: 197 | M6: 203 | N6: 204 | O6: 230 | P6: 209 | Q6: 56677 | R6: 796 | S6: 2146 | T6: 142 | U6: 143 | V6: 125 | W6: 187 | X6: 163 | Y6: 298 | Z6: 299 | AA6: 219 | AB6: 151 | AC6: 152 | AD6: 153 | AE6: 154 | AF6: 756 | AG6: 156 | AH6: 155 | AI6: 182 | AJ6: 212 | AK6: 758 | AL6: 263 | AM6: 265 | AN6: 775 | AO6: 777 | AP6: 2154 | AQ6: 150 | AR6: 149 | AS6: 188 | AT6: 2131 | AU6: 755 | AV6: 252 | AW6: 249 | AX6: 250 | AY6: 117 | AZ6: 267 | BA6: 268 | BB6: 119 | BC6: 120 | BD6: 189 | BE6: 122 | BF6: 266 | BG6: 337 | BH6: 338 | BI6: 251 | BJ6: 115 | BK6: 239 | BL6: 288 | BM6: 240 | BN6: 241 | BO6: 242 | BP6: 191 | BQ6: 194 | BR6: 196 | BS6: 207 | BT6: 236 | BU6: 795 | BV6: 285 | BW6: 995 | BX6: 996 | BY6: 997 | BZ6: 766 | CA6: 926 | CB6: 924 | CC6: 121 | CD6: 103 | CE6: 104 | CF6: 106 | CG6: 105 | CH6: 107 | CI6: 110 | CJ6: 109 | CK6: 144 | CL6: 113 | CM6: 114 | CN6: 193 | CO6: 208 | CP6: 786 | CQ6: 787 | CR6: 788 | CS6: 789 | CT6: 248 | CU6: 2159 | CV6: 303 | CW6: 59715 | CX6: 62255 | CY6: 1263 | CZ6: 61800 | DA6: 2194 | DB6: 216 | DC6: 198 | DD6: 49607 | DE6: 214 | DF6: 260 | DG6: 2152 | DH6: 2128 | DI6: 247 | DJ6: 228 | DK6: 2135 | DL6: 261 | DM6: 237 | DN6: 253 | DO6: 770 | DP6: 225 | DQ6: 2201 | DR6: 2171 | DS6: 760 | DT6: 235 | DU6: 238 | DV6: 2184 | DW6: 61855 | DX6: 223 | DY6: 226 | DZ6: 201 | EA6: 258 | EB6: 259 | EC6: 920 | ED6: 257 | EE6: 256 | EF6: 2148 | EG6: 58288 | EH6: 58289 | EI6: 58839 | EJ6: 58840 | EK6: 296 | EL6: 297 | EM6: 211 | EN6: 2175 | EO6: 2178 | EP6: 2181 | EQ6: 1262 | ER6: 63425 | ES6: 233 | ET6: 2150 | EU6: 2165 | EV6: 2161 | EW6: 61197 | EX6: 58851 | EY6: 234 | EZ6: 215 | FA6: 917 | FB6: 289 | FC6: 58333 | FD6: 58336 | FE6: 202 | FF6: 58487 | FG6: 213 | FH6: 232 | FI6: 2190 | FJ6: TOTAL COES | FL6: 221 | FM6: 222 | FN6: 224 | FO6: 2187 | FP6: 227 | FQ6: 49400 | FR6: 199 | FS6: 200 | FT6: TOTAL NO COES
C7: SUR | D7: CENTRO | E7: CENTRO | F7: NORTE | G7: NORTE | H7: NORTE | I7: NORTE | J7: CENTRO | K7: CENTRO | L7: CENTRO | M7: CENTRO | N7: CENTRO | O7: CENTRO | P7: CENTRO | Q7: CENTRO | R7: CENTRO | S7: CENTRO | T7: CENTRO | U7: CENTRO | V7: CENTRO | W7: CENTRO | X7: SUR | Y7: SUR | Z7: SUR | AA7: CENTRO | AB7: SUR | AC7: SUR | AD7: SUR | AE7: SUR | AF7: SUR | AG7: SUR | AH7: SUR | AI7: SUR | AJ7: CENTRO | AK7: NORTE | AL7: NORTE | AM7: NORTE | AN7: CENTRO | AO7: CENTRO | AP7: CENTRO | AQ7: CENTRO | AR7: CENTRO | AS7: CENTRO | AT7: CENTRO | AU7: SUR | AV7: CENTRO | AW7: CENTRO | AX7: CENTRO | AY7: CENTRO | AZ7: CENTRO | BA7: CENTRO | BB7: CENTRO | BC7: CENTRO | BD7: SUR | BE7: NORTE | BF7: CENTRO | BG7: CENTRO | BH7: CENTRO | BI7: CENTRO | BJ7: NORTE | BK7: NORTE | BL7: NORTE | BM7: SUR | BN7: SUR | BO7: SUR | BP7: CENTRO | BQ7: CENTRO | BR7: CENTRO | BS7: CENTRO | BT7: CENTRO | BU7: CENTRO | BV7: CENTRO | BW7: SUR | BX7: SUR | BY7: SUR | BZ7: NORTE | CA7: SUR | CB7: CENTRO | CC7: NORTE | CD7: CENTRO | CE7: CENTRO | CF7: CENTRO | CG7: CENTRO | CH7: CENTRO | CI7: CENTRO | CJ7: CENTRO | CK7: CENTRO | CL7: CENTRO | CM7: CENTRO | CN7: CENTRO | CO7: CENTRO | CP7: SUR | CQ7: SUR | CR7: SUR | CS7: SUR | CT7: CENTRO | CU7: CENTRO | CV7: CENTRO | CW7: CENTRO | CX7: SUR | CY7: NORTE | CZ7: NORTE | DA7: NORTE | DB7: NORTE | DC7: NORTE | DD7: SUR | DE7: CENTRO | DF7: CENTRO | DG7: CENTRO | DH7: NORTE | DI7: NORTE | DJ7: CENTRO | DK7: CENTRO | DL7: SUR | DM7: SUR | DN7: CENTRO | DO7: CENTRO | DP7: CENTRO | DQ7: CENTRO | DR7: CENTRO | DS7: CENTRO | DT7: SUR | DU7: CENTRO | DV7: CENTRO | DW7: NORTE | DX7: CENTRO | DY7: CENTRO | DZ7: NORTE | EA7: CENTRO | EB7: CENTRO | EC7: CENTRO | ED7: NORTE | EE7: NORTE | EF7: SUR | EG7: CENTRO | EH7: CENTRO | EI7: CENTRO | EJ7: CENTRO | EK7: CENTRO | EL7: CENTRO | EM7: SUR | EN7: SUR | EO7: SUR | EP7: SUR | EQ7: NORTE | ER7: SUR | ES7: SUR | ET7: SUR | EU7: CENTRO | EV7: CENTRO | EW7: CENTRO | EX7: SUR | EY7: SUR | EZ7: NORTE | FA7: CENTRO | FB7: NORTE | FC7: NORTE | FD7: NORTE | FE7: CENTRO | FF7: CENTRO | FG7: CENTRO | FH7: NORTE | FI7: NORTE | FL7: NORTE | FM7: CENTRO | FN7: NORTE | FO7: NORTE | FP7: NORTE | FQ7: NORTE | FR7: NORTE | FS7: NORTE
C8: HIDROELÉCTRICA | D8: HIDROELÉCTRICA | E8: HIDROELÉCTRICA | F8: TERMOELÉCTRICA | G8: TERMOELÉCTRICA | H8: HIDROELÉCTRICA | I8: HIDROELÉCTRICA | J8: TERMOELÉCTRICA | K8: TERMOELÉCTRICA | L8: TERMOELÉCTRICA | M8: TERMOELÉCTRICA | N8: TERMOELÉCTRICA | O8: TERMOELÉCTRICA | P8: TERMOELÉCTRICA | Q8: TERMOELÉCTRICA | R8: HIDROELÉCTRICA | S8: HIDROELÉCTRICA | T8: TERMOELÉCTRICA | U8: TERMOELÉCTRICA | V8: TERMOELÉCTRICA | W8: TERMOELÉCTRICA | X8: HIDROELÉCTRICA | Y8: HIDROELÉCTRICA | Z8: HIDROELÉCTRICA | AA8: TERMOELÉCTRICA | AB8: HIDROELÉCTRICA | AC8: HIDROELÉCTRICA | AD8: HIDROELÉCTRICA | AE8: HIDROELÉCTRICA | AF8: TERMOELÉCTRICA | AG8: TERMOELÉCTRICA | AH8: TERMOELÉCTRICA | AI8: HIDROELÉCTRICA | AJ8: HIDROELÉCTRICA | AK8: TERMOELÉCTRICA | AL8: TERMOELÉCTRICA | AM8: TERMOELÉCTRICA | AN8: HIDROELÉCTRICA | AO8: HIDROELÉCTRICA | AP8: HIDROELÉCTRICA | AQ8: HIDROELÉCTRICA | AR8: HIDROELÉCTRICA | AS8: HIDROELÉCTRICA | AT8: HIDROELÉCTRICA | AU8: HIDROELÉCTRICA | AV8: TERMOELÉCTRICA | AW8: TERMOELÉCTRICA | AX8: TERMOELÉCTRICA | AY8: HIDROELÉCTRICA | AZ8: HIDROELÉCTRICA | BA8: HIDROELÉCTRICA | BB8: HIDROELÉCTRICA | BC8: HIDROELÉCTRICA | BD8: HIDROELÉCTRICA | BE8: HIDROELÉCTRICA | BF8: HIDROELÉCTRICA | BG8: HIDROELÉCTRICA | BH8: HIDROELÉCTRICA | BI8: HIDROELÉCTRICA | BJ8: TERMOELÉCTRICA | BK8: TERMOELÉCTRICA | BL8: TERMOELÉCTRICA | BM8: TERMOELÉCTRICA | BN8: TERMOELÉCTRICA | BO8: TERMOELÉCTRICA | BP8: HIDROELÉCTRICA | BQ8: TERMOELÉCTRICA | BR8: TERMOELÉCTRICA | BS8: TERMOELÉCTRICA | BT8: TERMOELÉCTRICA | BU8: TERMOELÉCTRICA | BV8: TERMOELÉCTRICA | BW8: TERMOELÉCTRICA | BX8: TERMOELÉCTRICA | BY8: TERMOELÉCTRICA | BZ8: HIDROELÉCTRICA | CA8: TERMOELÉCTRICA | CB8: TERMOELÉCTRICA | CC8: HIDROELÉCTRICA | CD8: HIDROELÉCTRICA | CE8: HIDROELÉCTRICA | CF8: HIDROELÉCTRICA | CG8: HIDROELÉCTRICA | CH8: HIDROELÉCTRICA | CI8: TERMOELÉCTRICA | CJ8: TERMOELÉCTRICA | CK8: TERMOELÉCTRICA | CL8: TERMOELÉCTRICA | CM8: TERMOELÉCTRICA | CN8: TERMOELÉCTRICA | CO8: TERMOELÉCTRICA | CP8: TERMOELÉCTRICA | CQ8: TERMOELÉCTRICA | CR8: TERMOELÉCTRICA | CS8: TERMOELÉCTRICA | CT8: TERMOELÉCTRICA | CU8: TERMOELÉCTRICA | CV8: SOLAR | CW8: EÓLICA | CX8: SOLAR | CY8: EÓLICA | CZ8: SOLAR | DA8: HIDROELÉCTRICA | DB8: HIDROELÉCTRICA | DC8: HIDROELÉCTRICA | DD8: HIDROELÉCTRICA | DE8: HIDROELÉCTRICA | DF8: HIDROELÉCTRICA | DG8: HIDROELÉCTRICA | DH8: HIDROELÉCTRICA | DI8: HIDROELÉCTRICA | DJ8: HIDROELÉCTRICA | DK8: HIDROELÉCTRICA | DL8: SOLAR | DM8: SOLAR | DN8: EÓLICA | DO8: EÓLICA | DP8: TERMOELÉCTRICA | DQ8: TERMOELÉCTRICA | DR8: TERMOELÉCTRICA | DS8: TERMOELÉCTRICA | DT8: SOLAR | DU8: HIDROELÉCTRICA | DV8: HIDROELÉCTRICA | DW8: HIDROELÉCTRICA | DX8: HIDROELÉCTRICA | DY8: HIDROELÉCTRICA | DZ8: HIDROELÉCTRICA | EA8: HIDROELÉCTRICA | EB8: HIDROELÉCTRICA | EC8: HIDROELÉCTRICA | ED8: EÓLICA | EE8: EÓLICA | EF8: SOLAR | EG8: EÓLICA | EH8: EÓLICA | EI8: EÓLICA | EJ8: EÓLICA | EK8: HIDROELÉCTRICA | EL8: HIDROELÉCTRICA | EM8: HIDROELÉCTRICA | EN8: HIDROELÉCTRICA | EO8: HIDROELÉCTRICA | EP8: HIDROELÉCTRICA | EQ8: EÓLICA | ER8: SOLAR | ES8: SOLAR | ET8: SOLAR | EU8: HIDROELÉCTRICA | EV8: EÓLICA | EW8: EÓLICA | EX8: SOLAR | EY8: SOLAR | EZ8: HIDROELÉCTRICA | FA8: HIDROELÉCTRICA | FB8: TERMOELÉCTRICA | FC8: TERMOELÉCTRICA | FD8: TERMOELÉCTRICA | FE8: TERMOELÉCTRICA | FF8: TERMOELÉCTRICA | FG8: TERMOELÉCTRICA | FH8: TERMOELÉCTRICA | FI8: TERMOELÉCTRICA | FL8: HIDROELÉCTRICA | FM8: HIDROELÉCTRICA | FN8: HIDROELÉCTRICA | FO8: HIDROELÉCTRICA | FP8: TERMOELÉCTRICA | FQ8: TERMOELÉCTRICA | FR8: HIDROELÉCTRICA | FS8: HIDROELÉCTRICA
C9: HYDRO GLOBAL PERÚ S.A.C. | D9: ELECTROPERU | E9: ELECTROPERU | F9: ELECTROPERU | G9: ELECTROPERU | H9: ORAZUL ENERGY PERÚ | I9: ORAZUL ENERGY PERÚ | J9: TERMOSELVA | K9: TERMOSELVA | L9: KALLPA GENERACION S.A. | M9: KALLPA GENERACION S.A. | N9: KALLPA GENERACION S.A. | O9: KALLPA GENERACION S.A. | P9: KALLPA GENERACION S.A. | Q9: KALLPA GENERACION S.A. | R9: KALLPA GENERACION S.A. | S9: KALLPA GENERACION S.A. | T9: SHOUGESA | U9: SHOUGESA | V9: SHOUGESA | W9: SHOUGESA | X9: EGEMSA | Y9: EGESUR | Z9: EGESUR | AA9: EGESUR | AB9: EGASA | AC9: EGASA | AD9: EGASA | AE9: EGASA | AF9: EGASA | AG9: EGASA | AH9: EGASA | AI9: SAN GABAN | AJ9: CELEPSA | AK9: MINERA CERRO VERDE | AL9: PLANTA DE RESERVA FRIA DE GENERACION DE ETEN S.A. | AM9: PLANTA DE RESERVA FRIA DE GENERACION DE ETEN S.A. | AN9: EMPRESA DE GENERACION HUALLAGA | AO9: EMPRESA DE GENERACION HUALLAGA | AP9: LA VIRGEN | AQ9: CHINANGO S.A.C. | AR9: CHINANGO S.A.C. | AS9: HIDROELECTRICA HUANCHOR S.A.C. | AT9: CELEPSA RENOVABLES S.R.L. | AU9: INLAND ENERGY SAC | AV9: FENIX POWER PERÚ | AW9: FENIX POWER PERÚ | AX9: FENIX POWER PERÚ | AY9: STATKRAFT S.A | AZ9: STATKRAFT S.A | BA9: STATKRAFT S.A | BB9: STATKRAFT S.A | BC9: STATKRAFT S.A | BD9: STATKRAFT S.A | BE9: STATKRAFT S.A | BF9: STATKRAFT S.A | BG9: CENTRALES SANTA ROSA S.A.C. | BH9: CENTRALES SANTA ROSA S.A.C. | BI9: EMPRESA DE GENERACION HUANZA | BJ9: ENEL GENERACION PIURA S.A. | BK9: ENEL GENERACION PIURA S.A. | BL9: ENEL GENERACION PIURA S.A. | BM9: ENGIE | BN9: ENGIE | BO9: ENGIE | BP9: ENGIE | BQ9: ENGIE | BR9: ENGIE | BS9: ENGIE | BT9: ENGIE | BU9: ENGIE | BV9: ENGIE | BW9: ENGIE | BX9: ENGIE | BY9: ENGIE | BZ9: ENGIE | CA9: INFRAESTRUCTURAS Y ENERGIAS DEL PERU S.A.C. | CB9: INFRAESTRUCTURAS Y ENERGIAS DEL PERU S.A.C. | CC9: INVERSIONES SHAQSHA S.A.C. | CD9: ORYGEN PERU S.A.A. | CE9: ORYGEN PERU S.A.A. | CF9: ORYGEN PERU S.A.A. | CG9: ORYGEN PERU S.A.A. | CH9: ORYGEN PERU S.A.A. | CI9: ORYGEN PERU S.A.A. | CJ9: ORYGEN PERU S.A.A. | CK9: ORYGEN PERU S.A.A. | CL9: ORYGEN PERU S.A.A. | CM9: ORYGEN PERU S.A.A. | CN9: ORYGEN PERU S.A.A. | CO9: ORYGEN PERU S.A.A. | CP9: SAMAY I S.A.C | CQ9: SAMAY I S.A.C | CR9: SAMAY I S.A.C | CS9: SAMAY I S.A.C | CT9: TERMOCHILCA S.A.C. | CU9: TERMOCHILCA S.A.C. | CV9: COLCA SOLAR S.A.C. | CW9: ENERGIA RENOVABLE DEL SUR S.A. | CX9: GR CORTARRAMA SOCIEDAD ANONIMA CERRADA | CY9: GR TARUCA SOCIEDAD ANONIMA CERRADA | CZ9: KONDU SAC | DA9: PERUANA DE INVERSIONES EN ENERGIAS RENOVABLES S.A. | DB9: ORAZUL ENERGY PERÚ | DC9: ORAZUL ENERGY PERÚ | DD9: SAN GABAN | DE9: MAJA ENERGIA S.A.C. | DF9: EMPRESA DE GENERACION ELECTRICA CANCHAYLLO SAC | DG9: EMPRESA DE GENERACION ELECTRICA SANTA ANA S.A.C. | DH9: EMPRESA ELECTRICA AGUA AZUL | DI9: EMPRESA ELECTRICA RIO DOBLE | DJ9: HIDROCAÑETE S.A. | DK9: HUAURA POWER GROUP S.A. | DL9: MOQUEGUA FV S.A.C. | DM9: PANAMERICANA SOLAR SAC. | DN9: PARQUE EOLICO MARCONA S.A.C. | DO9: PARQUE EOLICO TRES HERMANAS S.A.C. | DP9: PETRAMAS | DQ9: PETRAMAS | DR9: PETRAMAS | DS9: PETRAMAS | DT9: TACNA SOLAR SAC. | DU9: ELECTRICA YANAPAMPA SAC | DV9: ANDEAN POWER S.A.C. | DW9: ASOCIACIÓN SANTA LUCIA DE CHACAS | DX9: ATRIA ENERGIA S.A.C. | DY9: EGEJUNIN | DZ9: EGEJUNIN | EA9: EGEJUNIN | EB9: EGEJUNIN | EC9: EMPRESA DE GENERACION ELECTRICA RIO BAÑOS S.A.C. | ED9: ENERGÍA EÓLICA S.A. | EE9: ENERGÍA EÓLICA S.A. | EF9: ENGIE | EG9: ENGIE | EH9: ENGIE | EI9: ENGIE | EJ9: ENGIE | EK9: GENERACIÓN ANDINA S.A.C. | EL9: GENERACIÓN ANDINA S.A.C. | EM9: GENERADORA DE ENERGÍA DEL PERÚ | EN9: GENERADORA DE ENERGÍA DEL PERÚ | EO9: GENERADORA DE ENERGÍA DEL PERÚ | EP9: GENERADORA DE ENERGÍA DEL PERÚ | EQ9: GR PAINO SOCIEDAD ANONIMA CERRADA | ER9: JOYA SOLAR S.A.C. | ES9: MAJES ARCUS S.A.C. | ET9: ORYGEN PERU S.A.A. | EU9: ORYGEN PERU S.A.A. | EV9: ORYGEN PERU S.A.A. | EW9: ORYGEN PERU S.A.A. | EX9: ORYGEN PERU S.A.A. | EY9: REPARTICIÓN ARCUS S.A.C. | EZ9: SINERSA | FA9: SINERSA | FB9: BIOENERGIA DEL CHIRA S.A. | FC9: GM OPERACIONES S.A.C. | FD9: GM OPERACIONES S.A.C. | FE9: SDF ENERGIA SAC | FF9: SDF ENERGIA SAC | FG9: AGRO INDUSTRIAL PARAMONGA S.A. | FH9: AGROAURORA S.A.C. | FI9: AGROINDUSTRIAS SAN JACINTO S.A.A. | FL9: UNACEM PERU S.A. | FM9: ELECTRO ORIENTE | FN9: AGUAS Y ENERGIA PERU | FO9: ELECTRO ZAÑA S.A.C. | FP9: ELECTRONOROESTE S.A. | FQ9: SDE PIURA | FR9: SINERSA | FS9: SINERSA
C10: SAN GABAN III | D10: MANTARO | E10: RESTITUCION | F10: TUMBES MAK 1 | G10: TUMBES MAK 2 | H10: CARHUAQUERO | I10: CAÑON DEL PATO | J10: AGUAYTIA TG1 | K10: AGUAYTIA TG2 | L10: KALLPA TG1 | M10: KALLPA TG2 | N10: KALLPA TG3 | O10: KALLPA TV | P10: LFLORES TG1 | Q10: LFLORES TV | R10: CERRO DEL AGUILA | S10: CERRODELAGUILAG4 | T10: SHOUGESA TV1 | U10: SHOUGESA TV2 | V10: SHOUGESA TV3 | W10: SHOUGESA CUMMINS | X10: MACHUPICCHU | Y10: ARICOTA 1 | Z10: ARICOTA 2 | AA10: INDEPENDENCIA | AB10: CHARCANI I,II,III | AC10: CHARCANI IV | AD10: CHARCANI V | AE10: CHARCANI VI | AF10: CHILINA TG | AG10: MOLLENDO 1, 2, 3 | AH10: CHILINA (SULZ 1,2) | AI10: SAN GABAN II | AJ10: PLATANAL | AK10: RECKA | AL10: RF ETEN TG1 | AM10: RF ETEN TG2 | AN10: CHAGLLA GP1 | AO10: CHAGLLA | AP10: LA VIRGEN | AQ10: CHIMAY | AR10: YANANGO | AS10: HUANCHOR | AT10: MARAÑON | AU10: STA TERESA | AV10: FENIX GT11 | AW10: FENIX GT12 | AX10: FENIX TV10 | AY10: YAUPI | AZ10: OROYA | BA10: PACHACHACA | BB10: MALPASO | BC10: CAHUA | BD10: ARCATA | BE10: GALLITO CIEGO | BF10: CHEVES | BG10: SANTA ROSA 1 | BH10: SANTA ROSA 2 | BI10: HUANZA | BJ10: MALACAS2 TG4 | BK10: MALACAS3 TG 5 | BL10: MALACAS1 TG6 | BM10: RF ILO2 TG1 | BN10: RF ILO2 TG2 | BO10: RF ILO2 TG3 | BP10: YUNCAN | BQ10: CHILCA1 TG1 | BR10: CHILCA1 TG2 | BS10: CHILCA1 TG3 | BT10: CHILCA-TV | BU10: CHILCA2 TG41 | BV10: CHILCA2-TV | BW10: CTNEPI_TG41 | BX10: CTNEPI_TG42 | BY10: CTNEPI_TG43 | BZ10: QUITARACSA | CA10: RF PTO MALDONADO | CB10: RF PUCALLPA | CC10: PARIAC | CD10: HUINCO | CE10: MATUCANA | CF10: MOYOPAMPA | CG10: CALLAHUANCA | CH10: HUAMPANI | CI10: STA ROSA WEST TG7 | CJ10: UTI_5 | CK10: UTI_6 | CL10: VENTANILLA 3 | CM10: VENTANILLA 4 | CN10: VENTANILLA TV | CO10: STAROSA TG8 | CP10: PTO_BRVO TG1 | CQ10: PTO_BRVO TG2 | CR10: PTO_BRVO TG3 | CS10: PTO_BRVO TG4 | CT10: OLLEROS TG1 | CU10: OLLEROS TV | CV10: CS YARUCAYA | CW10: SAN JUAN | CX10: MATARANI | CY10: DUNA | CZ10: CARHUAQUERO (CS) | DA10: MANTA I | DB10: CARHUAQUERO4 | DC10: CAÑA BRAVA | DD10: TUPURI | DE10: RONCADOR | DF10: CANCHAYLLO | DG10: RENOVANDESH1 | DH10: POTRERO | DI10: PIZARRAS | DJ10: NIMPERIAL | DK10: YARUCAYA | DL10: MOQUEGUA-SOLAR | DM10: PANAMERICANA-SOLAR | DN10: PQE-EOLICO-MARCONA | DO10: PQE-EOLICO-3-HERMANAS | DP10: HUAYCOLORO | DQ10: CALLAO | DR10: DONA_CATALINA | DS10: LAGRINGAV | DT10: TACNA-SOLAR | DU10: YANAPAMPA | DV10: CARHUAC | DW10: HUALLIN | DX10: PURMACANA | DY10: HUASAHUASI | DZ10: STACRUZ_1_2 | EA10: RUNATULLO_II | EB10: RUNATULLO_III | EC10: RUCUY | ED10: PQE-EOLICO-TALARA | EE10: PQE-EOLICO-CUPISNIQUE | EF10: INTIPAMPA | EG10: PUNTA LOMITAS-BL1 | EH10: PUNTA LOMITAS-BL2 | EI10: PUN LOMITAS_EXP-BL1 | EJ10: PUN LOMITAS_EXP-BL2 | EK10: 8AGOSTO | EL10: EL CARMEN | EM10: LA JOYA | EN10: ANGEL_I | EO10: ANGEL_II | EP10: ANGEL_III | EQ10: HUAMBOS | ER10: SAN MARTIN SOLAR | ES10: MAJES | ET10: RUBI | EU10: CH_HER1 | EV10: WAYRA-I | EW10: WAYRA EXTENSION | EX10: CLEMESI | EY10: REPARTICION | EZ10: POECHOS2 | FA10: CHANCAY | FB10: CANA BRAVA | FC10: REFINERIA TALARA TV1 | FD10: REFINERÍA TALARA TV2 | FE10: OQUENDO TG1 | FF10: OQUENDO TV1 | FG10: PARAMONGA | FH10: MAPLE | FI10: SAN_JACINTO | FJ10: MW | FL10: CARPAPATA | FM10: CENTRALES ELOR | FN10: PIAS1 | FO10: ZANA | FP10: TABLAZO | FQ10: TALLANCA | FR10: CURUMUY | FS10: POECHOS1 | FT10: MW
A11: 15/05/2025 | B11: 00:30 | C11: 99.5 | D11: 647.7 | E11: 215.2 | F11: 0 | G11: 0 | H11: 89.7 | I11: 211.2 | L11: 106.4 | M11: 106.5 | N11: 106.6 | O11: 207 | P11: 213.2 | Q11: 110.8 | R11: 553.5 | S11: 10.4 | X11: 166 | Y11: 7.2 | Z11: 4.7 | AB11: 6.7 | AC11: 13.9 | AD11: 84.8 | AG11: 0 | AI11: 111 | AJ11: 196.3 | AN11: 6.5 | AO11: 229.8 | AP11: 73 | AQ11: 136.5 | AR11: 39.2 | AS11: 9.4 | AT11: 19.7 | AU11: 91.4 | AV11: 123.9 | AX11: 75 | AY11: 110.5 | AZ11: 8.2 | BA11: 4.3 | BB11: 46.4 | BD11: 4 | BE11: 37.6 | BF11: 133.1 | BI11: 48 | BJ11: 0 | BK11: 102.1 | BL11: 45.6 | BP11: 86.2 | BR11: 175.7 | BS11: 200 | BT11: 181.9 | CC11: 4.6 | CD11: 100.9 | CE11: 119.8 | CF11: 65.3 | CG11: 78.9 | CH11: 30.3 | CL11: 103.3 | CM11: 104.1 | CN11: 122.8 | CV11: 0 | CW11: 41.2 | CX11: 0 | CY11: 9.7 | CZ11: 0 | DA11: 20 | DB11: 9.9 | DC11: 5.4 | DD11: 1 | DF11: 4.834 | DG11: 20.5 | DH11: 20 | DI11: 18.8 | DJ11: 3.7 | DK11: 18.5 | DL11: 0 | DM11: 0 | DN11: 3.7 | DO11: 10.7 | DP11: 4.5 | DQ11: 1 | DR11: 2.2 | DS11: 0 | DT11: 0 | DU11: 3.3 | DV11: 14.4 | DW11: 2.6 | DX11: 0 | DY11: 17.1 | DZ11: 8 | EA11: 11.3 | EB11: 14.5 | EC11: 19.9 | ED11: 6.1 | EE11: 44.9 | EF11: 0 | EG11: 19 | EH11: 36.6 | EI11: 0.6 | EJ11: 0 | EK11: 17.7 | EL11: 4.8 | EM11: 8 | EN11: 15.2 | EO11: 16 | EP11: 15.8 | EQ11: 4.6 | ER11: 0 | ES11: 0 | ET11: 0 | EU11: 0.6 | EV11: 0 | EW11: 0 | EX11: 0 | EY11: 0 | EZ11: 9.6 | FA11: 20 | FB11: 9.5 | FC11: 0 | FG11: 18.3 | FJ11: 6520.334 | FL11: 24.72332 | FM11: 7.919 | FO11: 13.2 | FP11: 26.53976 | FQ11: 18.91146 | FR11: 12 | FS11: 15.8 | FT11: 119.09354
A12: 15/05/2025 | B12: 01:00 | C12: 99.8 | D12: 647.2 | E12: 214.6 | F12: 3.5 | G12: 3.6 | H12: 90.3 | I12: 211.2 | L12: 105.4 | M12: 105.4 | N12: 104.9 | O12: 206.9 | P12: 211.1 | Q12: 110 | R12: 566.7 | S12: 10.4 | X12: 168 | Y12: 7.7 | Z12: 4.7 | AB12: 6.7 | AC12: 13.6 | AD12: 86 | AG12: 0 | AI12: 111 | AJ12: 147.7 | AN12: 6.5 | AO12: 231.7 | AP12: 72.8 | AQ12: 135.1 | AR12: 39.6 | AS12: 9.3 | AT12: 19.7 | AU12: 88 | AV12: 122.7 | AX12: 75.6 | AY12: 110.1 | AZ12: 8.2 | BA12: 4.3 | BB12: 46.8 | BD12: 4 | BE12: 37.6 | BF12: 128.1 | BI12: 47.9 | BJ12: 0 | BK12: 30.2 | BL12: 46.8 | BP12: 86.5 | BR12: 175.6 | BS12: 200 | BT12: 183 | CC12: 4.6 | CD12: 88.4 | CE12: 118.1 | CF12: 62.8 | CG12: 79.1 | CH12: 30.5 | CL12: 103.8 | CM12: 100.6 | CN12: 123.8 | CV12: 0 | CW12: 38.2 | CX12: 0 | CY12: 9.3 | CZ12: 0 | DA12: 20 | DB12: 9.9 | DC12: 5.4 | DD12: 1 | DF12: 4.799 | DG12: 20.6 | DH12: 20 | DI12: 19.1 | DJ12: 3.7 | DK12: 18.5 | DL12: 0 | DM12: 0 | DN12: 6.2 | DO12: 7.8 | DP12: 4.5 | DQ12: 1 | DR12: 2.2 | DS12: 0 | DT12: 0 | DU12: 3.3 | DV12: 14.4 | DW12: 2.6 | DX12: 0 | DY12: 17.1 | DZ12: 8 | EA12: 11.3 | EB12: 14.8 | EC12: 19.8 | ED12: 5.2 | EE12: 41.2 | EF12: 0 | EG12: 13.4 | EH12: 29.3 | EI12: 0.4 | EJ12: 0 | EK12: 17.6 | EL12: 4.8 | EM12: 8 | EN12: 15.2 | EO12: 16 | EP12: 15.8 | EQ12: 4.6 | ER12: 0 | ES12: 0 | ET12: 0 | EU12: 0.6 | EV12: 0 | EW12: 0 | EX12: 0 | EY12: 0 | EZ12: 9.5 | FA12: 19.8 | FB12: 9.5 | FC12: 0 | FG12: 17.8 | FJ12: 6370.399 | FL12: 24.72039 | FM12: 7.16 | FO12: 13.1 | FP12: 26.61729 | FQ12: 18.91095 | FR12: 12 | FS12: 15.9 | FT12: 118.40863
A13: 15/05/2025 | B13: 01:30 | C13: 99 | D13: 646.3 | E13: 215.1 | F13: 3.7 | G13: 3.6 | H13: 89.6 | I13: 207.9 | L13: 106.5 | M13: 106.8 | N13: 106.6 | O13: 206.7 | P13: 211.2 | Q13: 110.3 | R13: 557.1 | S13: 10.4 | X13: 163.7 | Y13: 7.4 | Z13: 4.7 | AB13: 6.7 | AC13: 13.8 | AD13: 69.9 | AG13: 0 | AI13: 111 | AJ13: 180.9 | AN13: 6.5 | AO13: 231.9 | AP13: 73.5 | AQ13: 126 | AR13: 39.1 | AS13: 9.4 | AT13: 19.7 | AU13: 92.8 | AV13: 123.1 | AX13: 74.4 | AY13: 109.7 | AZ13: 8.2 | BA13: 4.3 | BB13: 46.7 | BD13: 4 | BE13: 37.5 | BF13: 115.4 | BI13: 48 | BJ13: 0 | BK13: 0 | BL13: 46.5 | BP13: 86.1 | BR13: 175.6 | BS13: 200 | BT13: 182.6 | CC13: 4.6 | CD13: 72.6 | CE13: 113.9 | CF13: 62.1 | CG13: 78.8 | CH13: 30.2 | CL13: 103 | CM13: 102.5 | CN13: 123.1 | CV13: 0 | CW13: 32 | CX13: 0 | CY13: 6.5 | CZ13: 0 | DA13: 20 | DB13: 9.9 | DC13: 5.4 | DD13: 1 | DF13: 5.034 | DG13: 20.3 | DH13: 20 | DI13: 18.9 | DJ13: 3.7 | DK13: 18.5 | DL13: 0 | DM13: 0 | DN13: 3.9 | DO13: 6.1 | DP13: 4.5 | DQ13: 1 | DR13: 2.2 | DS13: 0 | DT13: 0 | DU13: 2.5 | DV13: 14.4 | DW13: 2.6 | DX13: 0 | DY13: 17.2 | DZ13: 8 | EA13: 11.1 | EB13: 14.8 | EC13: 20 | ED13: 5.4 | EE13: 29 | EF13: 0 | EG13: 9.9 | EH13: 20.8 | EI13: 0.3 | EJ13: 0 | EK13: 17.3 | EL13: 4.8 | EM13: 8 | EN13: 15.4 | EO13: 16.3 | EP13: 15.8 | EQ13: 2.6 | ER13: 0 | ES13: 0 | ET13: 0 | EU13: 0.6 | EV13: 0 | EW13: 0 | EX13: 0 | EY13: 0 | EZ13: 9.4 | FA13: 20 | FB13: 9 | FC13: 0 | FG13: 17.5 | FJ13: 6262.334 | FL13: 24.72239 | FM13: 6.599 | FO13: 13.2 | FP13: 26.64498 | FQ13: 18.91006 | FR13: 11.9 | FS13: 15.9 | FT13: 117.87643
A14: 15/05/2025 | B14: 02:00 | C14: 100.6 | D14: 646.6 | E14: 214.6 | F14: 3.9 | G14: 3.7 | H14: 90.3 | I14: 210.2 | L14: 105.7 | M14: 106.2 | N14: 105.6 | O14: 206.6 | P14: 211.2 | Q14: 110.3 | R14: 561.1 | S14: 10.5 | X14: 165.1 | Y14: 7.6 | Z14: 5.2 | AB14: 6.7 | AC14: 12 | AD14: 69.9 | AG14: 0 | AI14: 110.9 | AJ14: 172.1 | AN14: 6.5 | AO14: 231.2 | AP14: 74 | AQ14: 135.4 | AR14: 38.9 | AS14: 9.4 | AT14: 19.7 | AU14: 89.4 | AV14: 124.8 | AX14: 74.8 | AY14: 110.1 | AZ14: 8.2 | BA14: 4.3 | BB14: 47.1 | BD14: 4 | BE14: 38.2 | BF14: 144.8 | BI14: 48 | BJ14: 0 | BK14: 0 | BL14: 46.7 | BP14: 86.2 | BR14: 134.2 | BS14: 164.1 | BT14: 157.6 | CC14: 4.6 | CD14: 85.2 | CE14: 124 | CF14: 62 | CG14: 79.6 | CH14: 30.1 | CL14: 102.8 | CM14: 102.3 | CN14: 122.4 | CV14: 0 | CW14: 33 | CX14: 0 | CY14: 7.5 | CZ14: 0 | DA14: 20 | DB14: 9.9 | DC14: 5.4 | DD14: 1 | DF14: 5.026 | DG14: 20.3 | DH14: 20 | DI14: 18.9 | DJ14: 3.7 | DK14: 18.5 | DL14: 0 | DM14: 0 | DN14: 2.9 | DO14: 5 | DP14: 4.5 | DQ14: 1 | DR14: 2.2 | DS14: 0 | DT14: 0 | DU14: 3.3 | DV14: 14.4 | DW14: 2.6 | DX14: 0 | DY14: 17.1 | DZ14: 8 | EA14: 11.1 | EB14: 15.1 | EC14: 20 | ED14: 5.7 | EE14: 34.1 | EF14: 0 | EG14: 8.6 | EH14: 20.2 | EI14: 0 | EJ14: 0 | EK14: 17.3 | EL14: 4.8 | EM14: 8 | EN14: 15.4 | EO14: 16.3 | EP14: 15.8 | EQ14: 3.4 | ER14: 0 | ES14: 0 | ET14: 0 | EU14: 0.6 | EV14: 0 | EW14: 0 | EX14: 0 | EY14: 0 | EZ14: 9.3 | FA14: 20 | FB14: 9.2 | FC14: 0 | FG14: 17.5 | FJ14: 6223.826 | FL14: 24.71785 | FM14: 5.417 | FO14: 13.2 | FP14: 26.66759 | FQ14: 18.91 | FR14: 12 | FS14: 15.9 | FT14: 116.81244
A15: 15/05/2025 | B15: 02:30 | C15: 99.9 | D15: 648.3 | E15: 214.9 | F15: 3.5 | G15: 3.6 | H15: 91.4 | I15: 214.2 | L15: 109.8 | M15: 110.2 | N15: 110.4 | O15: 209.8 | P15: 210 | Q15: 109.8 | R15: 561.1 | S15: 10.4 | X15: 166.6 | Y15: 7.9 | Z15: 5.2 | AB15: 6.7 | AC15: 12 | AD15: 69.9 | AG15: 0 | AI15: 111.4 | AJ15: 223.6 | AN15: 6.5 | AO15: 229.8 | AP15: 75 | AQ15: 148.6 | AR15: 39.3 | AS15: 9.4 | AT15: 19.7 | AU15: 90.4 | AV15: 124.2 | AX15: 74.7 | AY15: 110.3 | AZ15: 8.2 | BA15: 4.3 | BB15: 47.1 | BD15: 4 | BE15: 37.9 | BF15: 171.7 | BI15: 48 | BJ15: 0 | BK15: 0 | BL15: 45.6 | BP15: 86.5 | BR15: 84.1 | BS15: 84.4 | BT15: 108 | CC15: 4.6 | CD15: 141.5 | CE15: 130.9 | CF15: 62.5 | CG15: 79.8 | CH15: 30.4 | CL15: 101.8 | CM15: 102.5 | CN15: 122 | CV15: 0 | CW15: 31.8 | CX15: 0 | CY15: 6.8 | CZ15: 0 | DA15: 20 | DB15: 9.8 | DC15: 5.5 | DD15: 1 | DF15: 5.049 | DG15: 20.4 | DH15: 20 | DI15: 18.9 | DJ15: 3.7 | DK15: 18.5 | DL15: 0 | DM15: 0 | DN15: 3.7 | DO15: 4.7 | DP15: 4.5 | DQ15: 1 | DR15: 2.2 | DS15: 0 | DT15: 0 | DU15: 3.4 | DV15: 14.4 | DW15: 2.6 | DX15: 0 | DY15: 17.1 | DZ15: 7.9 | EA15: 11.4 | EB15: 15.3 | EC15: 20 | ED15: 7.7 | EE15: 29.2 | EF15: 0 | EG15: 6.9 | EH15: 16.8 | EI15: 0 | EJ15: 0 | EK15: 17.5 | EL15: 4.8 | EM15: 8.2 | EN15: 15.4 | EO15: 16.3 | EP15: 15.8 | EQ15: 2.7 | ER15: 0 | ES15: 0 | ET15: 0 | EU15: 0.6 | EV15: 0 | EW15: 0 | EX15: 0 | EY15: 0 | EZ15: 9.4 | FA15: 20 | FB15: 9.5 | FC15: 0 | FG15: 17.5 | FJ15: 6212.249 | FL15: 24.71614 | FM15: 5.098 | FO15: 13.2 | FP15: 26.71292 | FQ15: 18.91047 | FR15: 12 | FS15: 15.9 | FT15: 116.53753
A16: 15/05/2025 | B16: 03:00 | C16: 101 | D16: 650.7 | E16: 215.3 | F16: 3.8 | G16: 3.9 | H16: 90.1 | I16: 211.4 | L16: 128.2 | M16: 128.2 | N16: 128.3 | O16: 224 | P16: 209.9 | Q16: 110.1 | R16: 563.9 | S16: 10.5 | X16: 160.1 | Y16: 7.8 | Z16: 5.4 | AB16: 6.7 | AC16: 11.3 | AD16: 70.9 | AG16: 0 | AI16: 111.2 | AJ16: 223.6 | AN16: 6.5 | AO16: 231.9 | AP16: 75.4 | AQ16: 114 | AR16: 40.4 | AS16: 9.4 | AT16: 19.7 | AU16: 89.2 | AV16: 123.9 | AX16: 75.2 | AY16: 110.4 | AZ16: 8.3 | BA16: 4.3 | BB16: 47.2 | BD16: 4 | BE16: 37.9 | BF16: 167.7 | BI16: 48.1 | BJ16: 0 | BK16: 0 | BL16: 46.2 | BP16: 86.3 | BR16: 85.1 | BS16: 84.9 | BT16: 105.7 | CC16: 4.6 | CD16: 116.9 | CE16: 131.4 | CF16: 62.3 | CG16: 79.8 | CH16: 30.3 | CL16: 102.4 | CM16: 102.3 | CN16: 122.8 | CV16: 0 | CW16: 27.2 | CX16: 0 | CY16: 9.4 | CZ16: 0 | DA16: 20 | DB16: 9.9 | DC16: 5.5 | DD16: 1 | DF16: 4.97 | DG16: 20.4 | DH16: 20 | DI16: 18.9 | DJ16: 3.7 | DK16: 18.5 | DL16: 0 | DM16: 0 | DN16: 3 | DO16: 4.6 | DP16: 4.5 | DQ16: 1 | DR16: 2.2 | DS16: 0 | DT16: 0 | DU16: 3.2 | DV16: 14.4 | DW16: 2.6 | DX16: 0 | DY16: 17.1 | DZ16: 7.9 | EA16: 11.3 | EB16: 15.2 | EC16: 20 | ED16: 6.5 | EE16: 18.8 | EF16: 0 | EG16: 3.4 | EH16: 11.5 | EI16: 0 | EJ16: 0 | EK16: 17.5 | EL16: 4.8 | EM16: 8.4 | EN16: 15.4 | EO16: 16.3 | EP16: 16 | EQ16: 3.8 | ER16: 0 | ES16: 0 | ET16: 0 | EU16: 0.6 | EV16: 0 | EW16: 0 | EX16: 0 | EY16: 0 | EZ16: 9.5 | FA16: 20 | FB16: 9.1 | FC16: 0 | FG16: 17.5 | FJ16: 6196.37 | FL16: 24.71684 | FM16: 5.093 | FO16: 13.2 | FP16: 26.72958 | FQ16: 18.91048 | FR16: 12 | FS16: 16 | FT16: 116.6499
A17: 15/05/2025 | B17: 03:30 | C17: 100.7 | D17: 649.3 | E17: 214.8 | F17: 3.7 | G17: 3.6 | H17: 89.9 | I17: 212.4 | L17: 118.5 | M17: 117.7 | N17: 116.5 | O17: 209.4 | P17: 209.5 | Q17: 110.1 | R17: 567.3 | S17: 10.4 | X17: 167.4 | Y17: 7.6 | Z17: 5.4 | AB17: 6.7 | AC17: 11.3 | AD17: 70.9 | AG17: 0 | AI17: 110.8 | AJ17: 220.5 | AN17: 6.5 | AO17: 228.8 | AP17: 76.2 | AQ17: 132.9 | AR17: 39.9 | AS17: 9.4 | AT17: 19.7 | AU17: 91.2 | AV17: 124.5 | AX17: 74.8 | AY17: 109.9 | AZ17: 8.2 | BA17: 4.3 | BB17: 47 | BD17: 4 | BE17: 37.9 | BF17: 170.3 | BI17: 47.9 | BJ17: 0 | BK17: 0 | BL17: 46.2 | BP17: 86.1 | BR17: 84 | BS17: 84 | BT17: 106.3 | CC17: 4.6 | CD17: 97.4 | CE17: 131.8 | CF17: 62 | CG17: 79.7 | CH17: 30.1 | CL17: 102.5 | CM17: 102.1 | CN17: 121.9 | CV17: 0 | CW17: 37.3 | CX17: 0 | CY17: 8.4 | CZ17: 0 | DA17: 20 | DB17: 9.9 | DC17: 5.5 | DD17: 1 | DF17: 4.841 | DG17: 20.2 | DH17: 20 | DI17: 18.8 | DJ17: 3.7 | DK17: 18.5 | DL17: 0 | DM17: 0 | DN17: 3.3 | DO17: 5.1 | DP17: 4.5 | DQ17: 1 | DR17: 2.2 | DS17: 0 | DT17: 0 | DU17: 3.4 | DV17: 14.4 | DW17: 2.6 | DX17: 0 | DY17: 17 | DZ17: 7.9 | EA17: 11 | EB17: 15.7 | EC17: 20 | ED17: 6.3 | EE17: 14.4 | EF17: 0 | EG17: 1.4 | EH17: 7.4 | EI17: 0 | EJ17: 0 | EK17: 17.5 | EL17: 4.8 | EM17: 8.3 | EN17: 15.5 | EO17: 16.5 | EP17: 16 | EQ17: 4.5 | ER17: 0 | ES17: 0 | ET17: 0 | EU17: 0.6 | EV17: 0 | EW17: 0 | EX17: 0 | EY17: 0 | EZ17: 9.4 | FA17: 20 | FB17: 9 | FC17: 0 | FG17: 17.6 | FJ17: 6151.941 | FL17: 24.71456 | FM17: 5.086 | FO17: 13.2 | FP17: 26.78858 | FQ17: 18.91028 | FR17: 11.9 | FS17: 15.6 | FT17: 116.19942
A18: 15/05/2025 | B18: 04:00 | C18: 98.1 | D18: 643.3 | E18: 214.4 | F18: 3.6 | G18: 3.6 | H18: 89.8 | I18: 210.1 | L18: 117.7 | M18: 116.5 | N18: 116.6 | O18: 221.5 | P18: 210 | Q18: 110.2 | R18: 555.2 | S18: 10.3 | X18: 162.3 | Y18: 6.8 | Z18: 5.2 | AB18: 6.7 | AC18: 11.3 | AD18: 69.7 | AG18: 0 | AI18: 110 | AJ18: 222.6 | AN18: 6.5 | AO18: 227.6 | AP18: 75.3 | AQ18: 139.8 | AR18: 39.4 | AS18: 9.4 | AT18: 19.7 | AU18: 90.8 | AV18: 120.9 | AX18: 75.3 | AY18: 108.9 | AZ18: 8.3 | BA18: 4.4 | BB18: 46.6 | BD18: 4 | BE18: 37.2 | BF18: 162 | BI18: 47.6 | BJ18: 0 | BK18: 0 | BL18: 45.3 | BP18: 85.8 | BR18: 85.1 | BS18: 84.6 | BT18: 106.4 | CC18: 4.6 | CD18: 91.2 | CE18: 129.9 | CF18: 61.3 | CG18: 78.3 | CH18: 29.7 | CL18: 102.3 | CM18: 101.6 | CN18: 122.5 | CV18: 0 | CW18: 43.4 | CX18: 0 | CY18: 8.2 | CZ18: 0 | DA18: 20 | DB18: 9.9 | DC18: 5.4 | DD18: 1 | DF18: 4.835 | DG18: 20 | DH18: 20 | DI18: 18.9 | DJ18: 3.7 | DK18: 18.5 | DL18: 0 | DM18: 0 | DN18: 5.4 | DO18: 4.6 | DP18: 4.5 | DQ18: 1 | DR18: 2.2 | DS18: 0 | DT18: 0 | DU18: 3.3 | DV18: 14.4 | DW18: 2.6 | DX18: 0 | DY18: 17 | DZ18: 7.9 | EA18: 10.5 | EB18: 15.4 | EC18: 20 | ED18: 4.9 | EE18: 14.1 | EF18: 0 | EG18: 2.9 | EH18: 10.8 | EI18: 0 | EJ18: 0 | EK18: 17.5 | EL18: 4.8 | EM18: 8.3 | EN18: 15.5 | EO18: 16.5 | EP18: 16.3 | EQ18: 4.9 | ER18: 0 | ES18: 0 | ET18: 0 | EU18: 0.6 | EV18: 0 | EW18: 0 | EX18: 0 | EY18: 0 | EZ18: 9.5 | FA18: 20 | FB18: 8.9 | FC18: 0 | FG18: 17.5 | FJ18: 6123.435 | FL18: 24.71772 | FM18: 5.067 | FO18: 13.2 | FP18: 26.85731 | FQ18: 18.90996 | FR18: 11.9 | FS18: 15.8 | FT18: 116.45199
A19: 15/05/2025 | B19: 04:30 | C19: 98.6 | D19: 642.3 | E19: 213.5 | F19: 3.8 | G19: 3.7 | H19: 90.2 | I19: 210 | L19: 111.8 | M19: 112.4 | N19: 113.1 | O19: 216.8 | P19: 208.2 | Q19: 109.4 | R19: 553.9 | S19: 10.4 | X19: 163.3 | Y19: 7 | Z19: 5.3 | AB19: 6.7 | AC19: 11.3 | AD19: 69.8 | AG19: 0 | AI19: 110.5 | AJ19: 221.1 | AN19: 6.5 | AO19: 230.7 | AP19: 75 | AQ19: 134.1 | AR19: 39.9 | AS19: 9.4 | AT19: 19.7 | AU19: 89.6 | AV19: 124.2 | AX19: 73.9 | AY19: 109.9 | AZ19: 8.4 | BA19: 4.3 | BB19: 47 | BD19: 4 | BE19: 38.2 | BF19: 166.8 | BI19: 47.7 | BJ19: 0 | BK19: 0 | BL19: 45.5 | BP19: 85.8 | BR19: 84.3 | BS19: 84.5 | BT19: 107.8 | CC19: 4.6 | CD19: 133.7 | CE19: 131.4 | CF19: 61.7 | CG19: 78.8 | CH19: 30.1 | CL19: 102.8 | CM19: 101.7 | CN19: 121.7 | CV19: 0 | CW19: 53.9 | CX19: 0 | CY19: 7.8 | CZ19: 0 | DA19: 20 | DB19: 10 | DC19: 5.4 | DD19: 1 | DF19: 4.852 | DG19: 20.2 | DH19: 20 | DI19: 18.9 | DJ19: 3.7 | DK19: 18.5 | DL19: 0 | DM19: 0 | DN19: 7 | DO19: 6.7 | DP19: 4.5 | DQ19: 1 | DR19: 2.2 | DS19: 0 | DT19: 0 | DU19: 3.3 | DV19: 14.4 | DW19: 2.6 | DX19: 0 | DY19: 17.1 | DZ19: 7.9 | EA19: 10.5 | EB19: 15.3 | EC19: 20 | ED19: 7 | EE19: 7.3 | EF19: 0 | EG19: 1.5 | EH19: 8.1 | EI19: 0 | EJ19: 0 | EK19: 17.5 | EL19: 4.8 | EM19: 8.3 | EN19: 15.5 | EO19: 16.5 | EP19: 16.3 | EQ19: 4.5 | ER19: 0 | ES19: 0 | ET19: 0 | EU19: 0.6 | EV19: 0 | EW19: 0 | EX19: 0 | EY19: 0 | EZ19: 9.5 | FA19: 20 | FB19: 9 | FC19: 0 | FG19: 17.7 | FJ19: 6157.652 | FL19: 24.71228 | FM19: 5.042 | FO19: 13.2 | FP19: 26.98783 | FQ19: 18.90959 | FR19: 12 | FS19: 15.9 | FT19: 116.7517
A20: 15/05/2025 | B20: 05:00 | C20: 99.7 | D20: 647.8 | E20: 214.9 | F20: 3.6 | G20: 3.7 | H20: 89.7 | I20: 211.8 | L20: 113 | M20: 112.5 | N20: 113.2 | O20: 209.8 | P20: 210.2 | Q20: 110.3 | R20: 560 | S20: 10.4 | X20: 163.7 | Y20: 7.3 | Z20: 5.4 | AB20: 6.7 | AC20: 11.2 | AD20: 70.1 | AG20: 0 | AI20: 110.9 | AJ20: 222.5 | AN20: 6.5 | AO20: 228.3 | AP20: 75 | AQ20: 132.5 | AR20: 40.2 | AS20: 9.4 | AT20: 19.7 | AU20: 86.2 | AV20: 124.2 | AX20: 74.7 | AY20: 109.8 | AZ20: 8.3 | BA20: 4.3 | BB20: 47 | BD20: 4 | BE20: 37.8 | BF20: 169.7 | BI20: 47.9 | BJ20: 0 | BK20: 0 | BL20: 45.7 | BP20: 85.9 | BR20: 84.6 | BS20: 84.9 | BT20: 106 | CC20: 4.6 | CD20: 101.5 | CE20: 131.8 | CF20: 62 | CG20: 78.9 | CH20: 30.3 | CL20: 102.7 | CM20: 102.9 | CN20: 121.7 | CV20: 0 | CW20: 51.3 | CX20: 0 | CY20: 8.7 | CZ20: 0 | DA20: 20 | DB20: 10 | DC20: 5.4 | DD20: 1 | DF20: 4.85 | DG20: 20.4 | DH20: 20 | DI20: 18.9 | DJ20: 3.7 | DK20: 18.5 | DL20: 0 | DM20: 0 | DN20: 4.7 | DO20: 8.7 | DP20: 4.5 | DQ20: 1 | DR20: 2.2 | DS20: 0 | DT20: 0 | DU20: 3.3 | DV20: 14.4 | DW20: 2.6 | DX20: 0 | DY20: 17 | DZ20: 7.9 | EA20: 10.8 | EB20: 15.6 | EC20: 20 | ED20: 9.2 | EE20: 9.5 | EF20: 0 | EG20: 0.4 | EH20: 5.4 | EI20: 0 | EJ20: 0 | EK20: 17.5 | EL20: 4.8 | EM20: 8.3 | EN20: 15.4 | EO20: 16.5 | EP20: 16.3 | EQ20: 3.5 | ER20: 0 | ES20: 0 | ET20: 0 | EU20: 0.6 | EV20: 0 | EW20: 0 | EX20: 0 | EY20: 0 | EZ20: 9.5 | FA20: 20 | FB20: 9.2 | FC20: 0 | FG20: 17.6 | FJ20: 6136.55 | FL20: 24.71282 | FM20: 5.049 | FO20: 13.2 | FP20: 27.06484 | FQ20: 18.90952 | FR20: 12 | FS20: 15.9 | FT20: 116.83618
A21: 15/05/2025 | B21: 05:30 | C21: 100.2 | D21: 649.8 | E21: 215.1 | F21: 3.6 | G21: 3.8 | H21: 92.3 | I21: 214.4 | L21: 120.4 | M21: 121.1 | N21: 120.2 | O21: 215.9 | P21: 209.2 | Q21: 109.7 | R21: 562.1 | S21: 10.6 | X21: 165.5 | Y21: 7.5 | Z21: 5 | AB21: 6.7 | AC21: 11.3 | AD21: 70.2 | AG21: 0 | AI21: 110.9 | AJ21: 222.7 | AN21: 6.5 | AO21: 228.6 | AP21: 75 | AQ21: 140.7 | AR21: 40.4 | AS21: 9.4 | AT21: 19.7 | AU21: 91.7 | AV21: 123.9 | AX21: 74.2 | AY21: 110.4 | AZ21: 8.3 | BA21: 4.3 | BB21: 47.5 | BD21: 4 | BE21: 38.6 | BF21: 170.3 | BI21: 48.3 | BJ21: 0 | BK21: 0 | BL21: 46 | BP21: 86.8 | BR21: 154 | BS21: 153.7 | BT21: 153.5 | CC21: 4.5 | CD21: 123.1 | CE21: 133.4 | CF21: 62.8 | CG21: 79 | CH21: 30.4 | CL21: 102.1 | CM21: 101.3 | CN21: 122.1 | CV21: 0 | CW21: 56.3 | CX21: 0 | CY21: 9.4 | CZ21: 0 | DA21: 20 | DB21: 10 | DC21: 5.5 | DD21: 1 | DF21: 4.869 | DG21: 20.3 | DH21: 20 | DI21: 18.9 | DJ21: 3.7 | DK21: 18.5 | DL21: 0 | DM21: 0 | DN21: 7.6 | DO21: 10 | DP21: 4.5 | DQ21: 1 | DR21: 2.2 | DS21: 0 | DT21: 0 | DU21: 3.3 | DV21: 14.4 | DW21: 2.5 | DX21: 0 | DY21: 17 | DZ21: 7.9 | EA21: 10.9 | EB21: 15.6 | EC21: 20 | ED21: 13.4 | EE21: 11.1 | EF21: 0 | EG21: 0.4 | EH21: 3.3 | EI21: 0 | EJ21: 0 | EK21: 17.5 | EL21: 4.8 | EM21: 8.3 | EN21: 15.4 | EO21: 16.5 | EP21: 16.3 | EQ21: 6.6 | ER21: 0 | ES21: 0 | ET21: 0 | EU21: 0.6 | EV21: 0 | EW21: 0 | EX21: 0 | EY21: 0 | EZ21: 9.4 | FA21: 20 | FB21: 9.1 | FC21: 0 | FG21: 18 | FJ21: 6418.769 | FL21: 24.70265 | FM21: 6.389 | FO21: 13.2 | FP21: 27.09486 | FQ21: 18.90837 | FR21: 11.9 | FS21: 15.8 | FT21: 117.99488
A22: 15/05/2025 | B22: 06:00 | C22: 99.4 | D22: 647.4 | E22: 214.8 | F22: 3.7 | G22: 3.7 | H22: 90.2 | I22: 213.9 | L22: 103.7 | M22: 103.2 | N22: 103.9 | O22: 215.5 | P22: 211.8 | Q22: 109.8 | R22: 556.2 | S22: 10.5 | X22: 169.3 | Y22: 6.7 | Z22: 4.9 | AB22: 6.7 | AC22: 11.4 | AD22: 70.3 | AG22: 0 | AI22: 111 | AJ22: 215.1 | AN22: 6.5 | AO22: 232.1 | AP22: 75 | AQ22: 139 | AR22: 41.3 | AS22: 9.4 | AT22: 19.7 | AU22: 92.6 | AV22: 125 | AX22: 74.5 | AY22: 110.1 | AZ22: 8.3 | BA22: 4.3 | BB22: 47 | BD22: 4 | BE22: 38.2 | BF22: 170.9 | BI22: 48 | BJ22: 0 | BK22: 35.8 | BL22: 45.6 | BP22: 86.3 | BR22: 174.3 | BS22: 200 | BT22: 174.3 | CC22: 4.6 | CD22: 99.5 | CE22: 132.1 | CF22: 62.3 | CG22: 76.9 | CH22: 30.4 | CL22: 102.7 | CM22: 101.9 | CN22: 122.7 | CV22: 0 | CW22: 67.7 | CX22: 0 | CY22: 11 | CZ22: 0 | DA22: 20 | DB22: 9.9 | DC22: 5.4 | DD22: 1 | DF22: 4.884 | DG22: 20.5 | DH22: 20 | DI22: 18.9 | DJ22: 3.8 | DK22: 18.5 | DL22: 0.4 | DM22: 0.3 | DN22: 8 | DO22: 13.1 | DP22: 4.5 | DQ22: 1 | DR22: 2.2 | DS22: 0 | DT22: 0 | DU22: 3.3 | DV22: 14.4 | DW22: 2.5 | DX22: 0 | DY22: 17 | DZ22: 7.9 | EA22: 10.8 | EB22: 15.5 | EC22: 20 | ED22: 14.9 | EE22: 8.1 | EF22: 0 | EG22: 0 | EH22: 0.6 | EI22: 0 | EJ22: 0 | EK22: 17.5 | EL22: 4.8 | EM22: 8.6 | EN22: 15.4 | EO22: 16.5 | EP22: 16.3 | EQ22: 6.1 | ER22: 0.1 | ES22: 0 | ET22: 0 | EU22: 0.6 | EV22: 0 | EW22: 0 | EX22: 0 | EY22: 0 | EZ22: 9.5 | FA22: 20 | FB22: 9.4 | FC22: 0 | FG22: 17.8 | FJ22: 6467.084 | FL22: 24.70297 | FM22: 6.857 | FO22: 13.2 | FP22: 27.1817 | FQ22: 18.90858 | FR22: 11.9 | FS22: 15.8 | FT22: 118.55025
... A58: 16/05/2025 | B58: 00:00 | C58: 100.7 | D58: 650.5 | E58: 215.1 | F58: 0 | G58: 0 | H58: 90 | I58: 208.5 | L58: 105.7 | M58: 105.9 | N58: 105.8 | O58: 207.8 | P58: 208.8 | Q58: 110.7 | R58: 559.5 | S58: 10.4 | X58: 167.9 | Y58: 7.4 | Z58: 5.4 | AB58: 6.7 | AC58: 11.8 | AD58: 76.4 | AG58: 0 | AI58: 111.2 | AJ58: 203.2 | AN58: 6.5 | AO58: 377.7 | AP58: 70.4 | AQ58: 116.4 | AR58: 38 | AS58: 9.4 | AT58: 19.7 | AU58: 90 | AV58: 184.3 | AX58: 90.7 | AY58: 110.3 | AZ58: 8.4 | BA58: 4.3 | BB58: 46.9 | BD58: 4 | BE58: 37.7 | BF58: 138.3 | BI58: 48.3 | BJ58: 0 | BK58: 0 | BL58: 46.2 | BP58: 86.5 | BR58: 174.8 | BS58: 200 | BT58: 182.4 | CC58: 4.5 | CD58: 150.5 | CE58: 127.3 | CF58: 65.8 | CG58: 79.5 | CH58: 30.5 | CL58: 116.1 | CM58: 116 | CN58: 125.8 | CV58: 0 | CW58: 76.2 | CX58: 0 | CY58: 0.6 | CZ58: 0 | DA58: 20 | DB58: 9.9 | DC58: 5.4 | DD58: 1 | DF58: 4.997 | DG58: 20.7 | DH58: 20 | DI58: 18.9 | DJ58: 3.6 | DK58: 18.5 | DL58: 0 | DM58: 0 | DN58: 4.5 | DO58: 6.9 | DP58: 2.1 | DQ58: 1.2 | DR58: 1.2 | DS58: 1.2 | DT58: 0 | DU58: 3.32 | DV58: 17.8 | DW58: 2.6 | DX58: 0 | DY58: 15.7 | DZ58: 8.1 | EA58: 10.8 | EB58: 14.4 | EC58: 20 | ED58: 1.9 | EE58: 30.7 | EF58: 0 | EG58: 6.4 | EH58: 19.1 | EI58: 0 | EJ58: 0 | EK58: 16 | EL58: 4.7 | EM58: 7.7 | EN58: 14.5 | EO58: 15.5 | EP58: 15.5 | EQ58: 0 | ER58: 0 | ES58: 0 | ET58: 0 | EU58: 0.6 | EV58: 0 | EW58: 0 | EX58: 0 | EY58: 0 | EZ58: 9.5 | FA58: 20 | FB58: 9.5 | FC58: 28.9 | FG58: 17.7 | FJ58: 6704.417 | FL58: 24.60394 | FM58: 8.054 | FO58: 13.2 | FP58: 26.54454 | FQ58: 18.9112 | FR58: 11.9 | FS58: 15.8 | FT58: 119.01368
A59: EJEC | C59: 2400.3 | D59: 15556.75 | E59: 5157.8 | F59: 20.2 | G59: 20.25 | H59: 2163.7 | I59: 5031.9 | J59: 0 | K59: 0 | L59: 2877.65 | M59: 2876.5 | N59: 2877.6 | O59: 5238.5 | P59: 4999.3 | Q59: 2633.45 | R59: 13446.7 | S59: 250.1 | T59: 0 | U59: 0 | V59: 0 | W59: 0 | X59: 3962.2 | Y59: 175.45 | Z59: 124.5 | AA59: 0 | AB59: 159.2 | AC59: 282.2 | AD59: 1920.5 | AE59: 0 | AF59: 0 | AG59: 16.8 | AH59: 0 | AI59: 2660.6 | AJ59: 4974.75 | AK59: 0 | AL59: 0 | AM59: 0 | AN59: 156 | AO59: 7196.3 | AP59: 1727.2 | AQ59: 3114.6 | AR59: 928.25 | AS59: 225.5 | AT59: 466.95 | AU59: 2159.05 | AV59: 3752.65 | AW59: 0 | AX59: 2006.5 | AY59: 2641 | AZ59: 198.95 | BA59: 103.75 | BB59: 1126.9 | BC59: 0 | BD59: 96 | BE59: 909.1 | BF59: 3663.95 | BG59: 0 | BH59: 0 | BI59: 1152.85 | BJ59: 137.15 | BK59: 1249 | BL59: 1099.35 | BM59: 0 | BN59: 0 | BO59: 0 | BP59: 2068 | BQ59: 0 | BR59: 3829.45 | BS59: 4333.75 | BT59: 4029.7 | BU59: 0 | BV59: 0 | BW59: 0 | BX59: 0 | BY59: 0 | BZ59: 0 | CA59: 0 | CB59: 0 | CC59: 110.3 | CD59: 3355.55 | CE59: 3115.25 | CF59: 1530.9 | CG59: 1895.2 | CH59: 725.55 | CI59: 0 | CJ59: 0 | CK59: 0 | CL59: 2823.85 | CM59: 2814.75 | CN59: 3161.5 | CO59: 0 | CP59: 0 | CQ59: 0 | CR59: 0 | CS59: 0 | CT59: 0 | CU59: 0 | CV59: 8.65 | CW59: 1750.15 | CX59: 632.3 | CY59: 220.75 | CZ59: 2.9 | DA59: 480.35 | DB59: 237.85 | DC59: 130.05 | DD59: 24 | DE59: 0 | DF59: 117.3805 | DG59: 488.25 | DH59: 480 | DI59: 453.2 | DJ59: 86.8 | DK59: 444 | DL59: 124.05 | DM59: 150.3 | DN59: 251.2 | DO59: 635.95 | DP59: 104.9 | DQ59: 22.05 | DR59: 51.55 | DS59: 21.9 | DT59: 151 | DU59: 78.7815 | DV59: 362.1 | DW59: 56.45 | DX59: 1.85 | DY59: 397.5 | DZ59: 185.05 | EA59: 257.05 | EB59: 364.9 | EC59: 479.3 | ED59: 195.85 | EE59: 640.2 | EF59: 269.55 | EG59: 645.1 | EH59: 1000.85 | EI59: 54.6 | EJ59: 20.3 | EK59: 405.75 | EL59: 117.05 | EM59: 189.6 | EN59: 361.9 | EO59: 386.45 | EP59: 382.8 | EQ59: 163.2 | ER59: 1966.6 | ES59: 120.6 | ET59: 1120.9 | EU59: 14.4 | EV59: 623.05 | EW59: 579.25 | EX59: 830.6 | EY59: 116 | EZ59: 227.05 | FA59: 479.45 | FB59: 232.7 | FC59: 435.4 | FD59: 0 | FE59: 0 | FF59: 0 | FG59: 422.4 | FH59: 0 | FI59: 0 | FJ59: 168985.76 | FL59: 591.24957 | FM59: 150.4285 | FN59: 0 | FO59: 316.75 | FP59: 634.55717 | FQ59: 453.90693 | FR59: 281.45 | FS59: 379 | FT59: 2807.3422

Sheet REACTIVA
B3: jueves, 15 de Mayo del 2025
A5: POTENCIA REACTIVA EJECUTADA DE LAS UNIDADES DE GENERACIÓN DEL COES (MVAR) | FK5: CENTRALES NO INTEGRANTES COES
A6: FECHA | B6: HORA | C6: 65333 | D6: 101 | E6: 102 | F6: 42667 | G6: 42668 | H6: 126 | I6: 127 | J6: 138 | K6: 139 | L6: 197 | M6: 203 | N6: 204 | O6: 230 | P6: 209 | Q6: 56677 | R6: 796 | S6: 2146 | T6: 142 | U6: 143 | V6: 125 | W6: 187 | X6: 163 | Y6: 298 | Z6: 219 | AA6: 151 | AB6: 152 | AC6: 153 | AD6: 154 | AE6: 756 | AF6: 156 | AG6: 155 | AH6: 182 | AI6: 212 | AJ6: 758 | AK6: 263 | AL6: 265 | AM6: 775 | AN6: 777 | AO6: 2154 | AP6: 150 | AQ6: 149 | AR6: 188 | AS6: 2131 | AT6: 755 | AU6: 252 | AV6: 249 | AW6: 250 | AX6: 117 | AY6: 267 | AZ6: 268 | BA6: 119 | BB6: 120 | BC6: 189 | BD6: 122 | BE6: 266 | BF6: 337 | BG6: 338 | BH6: 251 | BI6: 115 | BJ6: 239 | BK6: 288 | BL6: 240 | BM6: 241 | BN6: 242 | BO6: 191 | BP6: 194 | BQ6: 196 | BR6: 207 | BS6: 236 | BT6: 795 | BU6: 285 | BV6: 995 | BW6: 996 | BX6: 997 | BY6: 766 | BZ6: 926 | CA6: 924 | CB6: 121 | CC6: 103 | CD6: 104 | CE6: 106 | CF6: 105 | CG6: 107 | CH6: 110 | CI6: 109 | CJ6: 144 | CK6: 113 | CL6: 114 | CM6: 193 | CN6: 208 | CO6: 786 | CP6: 787 | CQ6: 788 | CR6: 789 | CS6: 248 | CT6: 2159 | CU6: 303 | CV6: 59715 | CW6: 62255 | CX6: 1263 | CY6: 61800 | CZ6: 2194 | DA6: 216 | DB6: 198 | DC6: 49607 | DD6: 214 | DE6: 260 | DF6: 2152 | DG6: 2128 | DH6: 247 | DI6: 228 | DJ6: 2135 | DK6: 261 | DL6: 237 | DM6: 253 | DN6: 770 | DO6: 225 | DP6: 2201 | DQ6: 2171 | DR6: 760 | DS6: 235 | DT6: 238 | DU6: 2184 | DV6: 61855 | DW6: 223 | DX6: 226 | DY6: 201 | DZ6: 258 | EA6: 259 | EB6: 920 | EC6: 257 | ED6: 256 | EE6: 2148 | EF6: 58288 | EG6: 58289 | EH6: 58839 | EI6: 58840 | EJ6: 296 | EK6: 297 | EL6: 211 | EM6: 2175 | EN6: 2178 | EO6: 2181 | EP6: 1262 | EQ6: 63425 | ER6: 233 | ES6: 2150 | ET6: 2165 | EU6: 2161 | EV6: 61197 | EW6: 58851 | EX6: 234 | EY6: 215 | EZ6: 917 | FA6: 289 | FB6: 58333 | FC6: 58336 | FD6: 202 | FE6: 58487 | FF6: 213 | FG6: 232 | FH6: 2190 | FI6: TOTAL COES | FK6: 221 | FL6: 222 | FM6: 224 | FN6: 2187 | FO6: 227 | FP6: 49400 | FQ6: 199 | FR6: 200 | FS6: TOTAL NO COES
C7: SUR | D7: CENTRO | E7: CENTRO | F7: NORTE | G7: NORTE | H7: NORTE | I7: NORTE | J7: CENTRO | K7: CENTRO | L7: CENTRO | M7: CENTRO | N7: CENTRO | O7: CENTRO | P7: CENTRO | Q7: CENTRO | R7: CENTRO | S7: CENTRO | T7: CENTRO | U7: CENTRO | V7: CENTRO | W7: CENTRO | X7: SUR | Y7: SUR | Z7: CENTRO | AA7: SUR | AB7: SUR | AC7: SUR | AD7: SUR | AE7: SUR | AF7: SUR | AG7: SUR | AH7: SUR | AI7: CENTRO | AJ7: NORTE | AK7: NORTE | AL7: NORTE | AM7: CENTRO | AN7: CENTRO | AO7: CENTRO | AP7: CENTRO | AQ7: CENTRO | AR7: CENTRO | AS7: CENTRO | AT7: SUR | AU7: CENTRO | AV7: CENTRO | AW7: CENTRO | AX7: CENTRO | AY7: CENTRO | AZ7: CENTRO | BA7: CENTRO | BB7: CENTRO | BC7: SUR | BD7: NORTE | BE7: CENTRO | BF7: CENTRO | BG7: CENTRO | BH7: CENTRO | BI7: NORTE | BJ7: NORTE | BK7: NORTE | BL7: SUR | BM7: SUR | BN7: SUR | BO7: CENTRO | BP7: CENTRO | BQ7: CENTRO | BR7: CENTRO | BS7: CENTRO | BT7: CENTRO | BU7: CENTRO | BV7: SUR | BW7: SUR | BX7: SUR | BY7: NORTE | BZ7: SUR | CA7: CENTRO | CB7: NORTE | CC7: CENTRO | CD7: CENTRO | CE7: CENTRO | CF7: CENTRO | CG7: CENTRO | CH7: CENTRO | CI7: CENTRO | CJ7: CENTRO | CK7: CENTRO | CL7: CENTRO | CM7: CENTRO | CN7: CENTRO | CO7: SUR | CP7: SUR | CQ7: SUR | CR7: SUR | CS7: CENTRO | CT7: CENTRO | CU7: CENTRO | CV7: CENTRO | CW7: SUR | CX7: NORTE | CY7: NORTE | CZ7: NORTE | DA7: NORTE | DB7: NORTE | DC7: SUR | DD7: CENTRO | DE7: CENTRO | DF7: CENTRO | DG7: NORTE | DH7: NORTE | DI7: CENTRO | DJ7: CENTRO | DK7: SUR | DL7: SUR | DM7: CENTRO | DN7: CENTRO | DO7: CENTRO | DP7: CENTRO | DQ7: CENTRO | DR7: CENTRO | DS7: SUR | DT7: CENTRO | DU7: CENTRO | DV7: NORTE | DW7: CENTRO | DX7: CENTRO | DY7: NORTE | DZ7: CENTRO | EA7: CENTRO | EB7: CENTRO | EC7: NORTE | ED7: NORTE | EE7: SUR | EF7: CENTRO | EG7: CENTRO | EH7: CENTRO | EI7: CENTRO | EJ7: CENTRO | EK7: CENTRO | EL7: SUR | EM7: SUR | EN7: SUR | EO7: SUR | EP7: NORTE | EQ7: SUR | ER7: SUR | ES7: SUR | ET7: CENTRO | EU7: CENTRO | EV7: CENTRO | EW7: SUR | EX7: SUR | EY7: NORTE | EZ7: CENTRO | FA7: NORTE | FB7: NORTE | FC7: NORTE | FD7: CENTRO | FE7: CENTRO | FF7: CENTRO | FG7: NORTE | FH7: NORTE | FK7: NORTE | FL7: CENTRO | FM7: NORTE | FN7: NORTE | FO7: NORTE | FP7: NORTE | FQ7: NORTE | FR7: NORTE
C8: HIDROELÉCTRICA | D8: HIDROELÉCTRICA | E8: HIDROELÉCTRICA | F8: TERMOELÉCTRICA | G8: TERMOELÉCTRICA | H8: HIDROELÉCTRICA | I8: HIDROELÉCTRICA | J8: TERMOELÉCTRICA | K8: TERMOELÉCTRICA | L8: TERMOELÉCTRICA | M8: TERMOELÉCTRICA | N8: TERMOELÉCTRICA | O8: TERMOELÉCTRICA | P8: TERMOELÉCTRICA | Q8: TERMOELÉCTRICA | R8: HIDROELÉCTRICA | S8: HIDROELÉCTRICA | T8: TERMOELÉCTRICA | U8: TERMOELÉCTRICA | V8: TERMOELÉCTRICA | W8: TERMOELÉCTRICA | X8: HIDROELÉCTRICA | Y8: HIDROELÉCTRICA | Z8: TERMOELÉCTRICA | AA8: HIDROELÉCTRICA | AB8: HIDROELÉCTRICA | AC8: HIDROELÉCTRICA | AD8: HIDROELÉCTRICA | AE8: TERMOELÉCTRICA | AF8: TERMOELÉCTRICA | AG8: TERMOELÉCTRICA | AH8: HIDROELÉCTRICA | AI8: HIDROELÉCTRICA | AJ8: TERMOELÉCTRICA | AK8: TERMOELÉCTRICA | AL8: TERMOELÉCTRICA | AM8: HIDROELÉCTRICA | AN8: HIDROELÉCTRICA | AO8: HIDROELÉCTRICA | AP8: HIDROELÉCTRICA | AQ8: HIDROELÉCTRICA | AR8: HIDROELÉCTRICA | AS8: HIDROELÉCTRICA | AT8: HIDROELÉCTRICA | AU8: TERMOELÉCTRICA | AV8: TERMOELÉCTRICA | AW8: TERMOELÉCTRICA | AX8: HIDROELÉCTRICA | AY8: HIDROELÉCTRICA | AZ8: HIDROELÉCTRICA | BA8: HIDROELÉCTRICA | BB8: HIDROELÉCTRICA | BC8: HIDROELÉCTRICA | BD8: HIDROELÉCTRICA | BE8: HIDROELÉCTRICA | BF8: HIDROELÉCTRICA | BG8: HIDROELÉCTRICA | BH8: HIDROELÉCTRICA | BI8: TERMOELÉCTRICA | BJ8: TERMOELÉCTRICA | BK8: TERMOELÉCTRICA | BL8: TERMOELÉCTRICA | BM8: TERMOELÉCTRICA | BN8: TERMOELÉCTRICA | BO8: HIDROELÉCTRICA | BP8: TERMOELÉCTRICA | BQ8: TERMOELÉCTRICA | BR8: TERMOELÉCTRICA | BS8: TERMOELÉCTRICA | BT8: TERMOELÉCTRICA | BU8: TERMOELÉCTRICA | BV8: TERMOELÉCTRICA | BW8: TERMOELÉCTRICA | BX8: TERMOELÉCTRICA | BY8: HIDROELÉCTRICA | BZ8: TERMOELÉCTRICA | CA8: TERMOELÉCTRICA | CB8: HIDROELÉCTRICA | CC8: HIDROELÉCTRICA | CD8: HIDROELÉCTRICA | CE8: HIDROELÉCTRICA | CF8: HIDROELÉCTRICA | CG8: HIDROELÉCTRICA | CH8: TERMOELÉCTRICA | CI8: TERMOELÉCTRICA | CJ8: TERMOELÉCTRICA | CK8: TERMOELÉCTRICA | CL8: TERMOELÉCTRICA | CM8: TERMOELÉCTRICA | CN8: TERMOELÉCTRICA | CO8: TERMOELÉCTRICA | CP8: TERMOELÉCTRICA | CQ8: TERMOELÉCTRICA | CR8: TERMOELÉCTRICA | CS8: TERMOELÉCTRICA | CT8: TERMOELÉCTRICA | CU8: SOLAR | CV8: EÓLICA | CW8: SOLAR | CX8: EÓLICA | CY8: SOLAR | CZ8: HIDROELÉCTRICA | DA8: HIDROELÉCTRICA | DB8: HIDROELÉCTRICA | DC8: HIDROELÉCTRICA | DD8: HIDROELÉCTRICA | DE8: HIDROELÉCTRICA | DF8: HIDROELÉCTRICA | DG8: HIDROELÉCTRICA | DH8: HIDROELÉCTRICA | DI8: HIDROELÉCTRICA | DJ8: HIDROELÉCTRICA | DK8: SOLAR | DL8: SOLAR | DM8: EÓLICA | DN8: EÓLICA | DO8: TERMOELÉCTRICA | DP8: TERMOELÉCTRICA | DQ8: TERMOELÉCTRICA | DR8: TERMOELÉCTRICA | DS8: SOLAR | DT8: HIDROELÉCTRICA | DU8: HIDROELÉCTRICA | DV8: HIDROELÉCTRICA | DW8: HIDROELÉCTRICA | DX8: HIDROELÉCTRICA | DY8: HIDROELÉCTRICA | DZ8: HIDROELÉCTRICA | EA8: HIDROELÉCTRICA | EB8: HIDROELÉCTRICA | EC8: EÓLICA | ED8: EÓLICA | EE8: SOLAR | EF8: EÓLICA | EG8: EÓLICA | EH8: EÓLICA | EI8: EÓLICA | EJ8: HIDROELÉCTRICA | EK8: HIDROELÉCTRICA | EL8: HIDROELÉCTRICA | EM8: HIDROELÉCTRICA | EN8: HIDROELÉCTRICA | EO8: HIDROELÉCTRICA | EP8: EÓLICA | EQ8: SOLAR | ER8: SOLAR | ES8: SOLAR | ET8: HIDROELÉCTRICA | EU8: EÓLICA | EV8: EÓLICA | EW8: SOLAR | EX8: SOLAR | EY8: HIDROELÉCTRICA | EZ8: HIDROELÉCTRICA | FA8: TERMOELÉCTRICA | FB8: TERMOELÉCTRICA | FC8: TERMOELÉCTRICA | FD8: TERMOELÉCTRICA | FE8: TERMOELÉCTRICA | FF8: TERMOELÉCTRICA | FG8: TERMOELÉCTRICA | FH8: TERMOELÉCTRICA | FK8: HIDROELÉCTRICA | FL8: HIDROELÉCTRICA | FM8: HIDROELÉCTRICA | FN8: HIDROELÉCTRICA | FO8: TERMOELÉCTRICA | FP8: TERMOELÉCTRICA | FQ8: HIDROELÉCTRICA | FR8: HIDROELÉCTRICA
C9: HYDRO GLOBAL PERÚ S.A.C. | D9: ELECTROPERU | E9: ELECTROPERU | F9: ELECTROPERU | G9: ELECTROPERU | H9: ORAZUL ENERGY PERÚ | I9: ORAZUL ENERGY PERÚ | J9: TERMOSELVA | K9: TERMOSELVA | L9: KALLPA GENERACION S.A. | M9: KALLPA GENERACION S.A. | N9: KALLPA GENERACION S.A. | O9: KALLPA GENERACION S.A. | P9: KALLPA GENERACION S.A. | Q9: KALLPA GENERACION S.A. | R9: KALLPA GENERACION S.A. | S9: KALLPA GENERACION S.A. | T9: SHOUGESA | U9: SHOUGESA | V9: SHOUGESA | W9: SHOUGESA | X9: EGEMSA | Y9: EGESUR | Z9: EGESUR | AA9: EGASA | AB9: EGASA | AC9: EGASA | AD9: EGASA | AE9: EGASA | AF9: EGASA | AG9: EGASA | AH9: SAN GABAN | AI9: CELEPSA | AJ9: MINERA CERRO VERDE | AK9: PLANTA DE RESERVA FRIA DE GENERACION DE ETEN S.A. | AL9: PLANTA DE RESERVA FRIA DE GENERACION DE ETEN S.A. | AM9: EMPRESA DE GENERACION HUALLAGA | AN9: EMPRESA DE GENERACION HUALLAGA | AO9: LA VIRGEN | AP9: CHINANGO S.A.C. | AQ9: CHINANGO S.A.C. | AR9: HIDROELECTRICA HUANCHOR S.A.C. | AS9: CELEPSA RENOVABLES S.R.L. | AT9: INLAND ENERGY SAC | AU9: FENIX POWER PERÚ | AV9: FENIX POWER PERÚ | AW9: FENIX POWER PERÚ | AX9: STATKRAFT S.A | AY9: STATKRAFT S.A | AZ9: STATKRAFT S.A | BA9: STATKRAFT S.A | BB9: STATKRAFT S.A | BC9: STATKRAFT S.A | BD9: STATKRAFT S.A | BE9: STATKRAFT S.A | BF9: CENTRALES SANTA ROSA S.A.C. | BG9: CENTRALES SANTA ROSA S.A.C. | BH9: EMPRESA DE GENERACION HUANZA | BI9: ENEL GENERACION PIURA S.A. | BJ9: ENEL GENERACION PIURA S.A. | BK9: ENEL GENERACION PIURA S.A. | BL9: ENGIE | BM9: ENGIE | BN9: ENGIE | BO9: ENGIE | BP9: ENGIE | BQ9: ENGIE | BR9: ENGIE | BS9: ENGIE | BT9: ENGIE | BU9: ENGIE | BV9: ENGIE | BW9: ENGIE | BX9: ENGIE | BY9: ENGIE | BZ9: INFRAESTRUCTURAS Y ENERGIAS DEL PERU S.A.C. | CA9: INFRAESTRUCTURAS Y ENERGIAS DEL PERU S.A.C. | CB9: INVERSIONES SHAQSHA S.A.C. | CC9: ORYGEN PERU S.A.A. | CD9: ORYGEN PERU S.A.A. | CE9: ORYGEN PERU S.A.A. | CF9: ORYGEN PERU S.A.A. | CG9: ORYGEN PERU S.A.A. | CH9: ORYGEN PERU S.A.A. | CI9: ORYGEN PERU S.A.A. | CJ9: ORYGEN PERU S.A.A. | CK9: ORYGEN PERU S.A.A. | CL9: ORYGEN PERU S.A.A. | CM9: ORYGEN PERU S.A.A. | CN9: ORYGEN PERU S.A.A. | CO9: SAMAY I S.A.C | CP9: SAMAY I S.A.C | CQ9: SAMAY I S.A.C | CR9: SAMAY I S.A.C | CS9: TERMOCHILCA S.A.C. | CT9: TERMOCHILCA S.A.C. | CU9: COLCA SOLAR S.A.C. | CV9: ENERGIA RENOVABLE DEL SUR S.A. | CW9: GR CORTARRAMA SOCIEDAD ANONIMA CERRADA | CX9: GR TARUCA SOCIEDAD ANONIMA CERRADA | CY9: KONDU SAC | CZ9: PERUANA DE INVERSIONES EN ENERGIAS RENOVABLES S.A. | DA9: ORAZUL ENERGY PERÚ | DB9: ORAZUL ENERGY PERÚ | DC9: SAN GABAN | DD9: MAJA ENERGIA S.A.C. | DE9: EMPRESA DE GENERACION ELECTRICA CANCHAYLLO SAC | DF9: EMPRESA DE GENERACION ELECTRICA SANTA ANA S.A.C. | DG9: EMPRESA ELECTRICA AGUA AZUL | DH9: EMPRESA ELECTRICA RIO DOBLE | DI9: HIDROCAÑETE S.A. | DJ9: HUAURA POWER GROUP S.A. | DK9: MOQUEGUA FV S.A.C. | DL9: PANAMERICANA SOLAR SAC. | DM9: PARQUE EOLICO MARCONA S.A.C. | DN9: PARQUE EOLICO TRES HERMANAS S.A.C. | DO9: PETRAMAS | DP9: PETRAMAS | DQ9: PETRAMAS | DR9: PETRAMAS | DS9: TACNA SOLAR SAC. | DT9: ELECTRICA YANAPAMPA SAC | DU9: ANDEAN POWER S.A.C. | DV9: ASOCIACIÓN SANTA LUCIA DE CHACAS | DW9: ATRIA ENERGIA S.A.C. | DX9: EGEJUNIN | DY9: EGEJUNIN | DZ9: EGEJUNIN | EA9: EGEJUNIN | EB9: EMPRESA DE GENERACION ELECTRICA RIO BAÑOS S.A.C. | EC9: ENERGÍA EÓLICA S.A. | ED9: ENERGÍA EÓLICA S.A. | EE9: ENGIE | EF9: ENGIE | EG9: ENGIE | EH9: ENGIE | EI9: ENGIE | EJ9: GENERACIÓN ANDINA S.A.C. | EK9: GENERACIÓN ANDINA S.A.C. | EL9: GENERADORA DE ENERGÍA DEL PERÚ | EM9: GENERADORA DE ENERGÍA DEL PERÚ | EN9: GENERADORA DE ENERGÍA DEL PERÚ | EO9: GENERADORA DE ENERGÍA DEL PERÚ | EP9: GR PAINO SOCIEDAD ANONIMA CERRADA | EQ9: JOYA SOLAR S.A.C. | ER9: MAJES ARCUS S.A.C. | ES9: ORYGEN PERU S.A.A. | ET9: ORYGEN PERU S.A.A. | EU9: ORYGEN PERU S.A.A. | EV9: ORYGEN PERU S.A.A. | EW9: ORYGEN PERU S.A.A. | EX9: REPARTICIÓN ARCUS S.A.C. | EY9: SINERSA | EZ9: SINERSA | FA9: BIOENERGIA DEL CHIRA S.A. | FB9: GM OPERACIONES S.A.C. | FC9: GM OPERACIONES S.A.C. | FD9: SDF ENERGIA SAC | FE9: SDF ENERGIA SAC | FF9: AGRO INDUSTRIAL PARAMONGA S.A. | FG9: AGROAURORA S.A.C. | FH9: AGROINDUSTRIAS SAN JACINTO S.A.A. | FK9: UNACEM PERU S.A. | FL9: ELECTRO ORIENTE | FM9: AGUAS Y ENERGIA PERU | FN9: ELECTRO ZAÑA S.A.C. | FO9: ELECTRONOROESTE S.A. | FP9: SDE PIURA | FQ9: SINERSA | FR9: SINERSA
