Workbook

Sheet EVENTOS
B3: martes, 21 de Enero del 2025
B5: INFORMACIÓN DE EVENTOS PRINCIPALES EN SUS INSTALACIONES
B6: TIPO DE EVENTO | C6: EMPRESA | D6: UBICACIÓN | E6: TIPO DE EQUIPO | F6: EQUIPO | G6: INICIO | H6: FINAL | I6: DESCRIPCIÓN | J6: MW INDISP. | K6: INTERRUPCIÓN (SI/NO) | L6: TENSIÓN DE FALLA (kV)
B7: FALLA | C7: ARUNTANI S.A.C. | D7: PUNO - TUCARI | E7: LINEA DE TRANSMISION | F7: L-6007 | G7: 21/01/2025 01:43:44 | H7: 21/01/2025 03:26:00 | I7: DESCONEXIÓN DE LA LÍNEA L-6007 (PUNO - TUCARI) DE 60 KV | J7: 0.51 | K7: SI | L7: 60
B8: FALLA | C8: ARUNTANI S.A.C. | D8: PUNO - TUCARI | E8: LINEA DE TRANSMISION | F8: L-6007 | G8: 21/01/2025 06:25:39 | H8: 21/01/2025 07:38:00 | I8: DESCONEXIÓN DE LA LÍNEA L-6007 (PUNO - TUCARI) DE 60 kV | J8: 0.12 | K8: SI | L8: 60
B9: EVENTO | C9: CONELSUR LT SAC | D9: PORTILLO | E9: SUBESTACION | F9: SS.EE. | G9: 21/01/2025 00:00:00 | H9: 22/01/2025 00:00:00 | I9: DECLARACIÓN DE SITUACIÓN EXCEPCIONAL EN LA S.E. PORTILLO DE 60 kV | K9: NO
B10: FALLA | C10: GENERADORA DE ENERGÍA DEL PERÚ | D10: ÁNGEL III | E10: CENTRAL HIDROELÉCTRICA | F10: CENTRAL | G10: 21/01/2025 08:16:00 | H10: 21/01/2025 08:45:00 | I10: DESCONEXIÓN DE LAS CC.HH. ÁNGEL I, II y II. | K10: NO | L10: 6.6
B11: FALLA | C11: HIDRANDINA | D11: KIMAN AYLLU - SIHUAS | E11: LINEA DE TRANSMISION | F11: L-1132 | G11: 21/01/2025 11:13:16 | H11: 21/01/2025 11:32:00 | I11: DESCONEXIÓN DE LA LÍNEA L-1132 (KIMAN AYLLU - SIHUAS) DE 138 KV | K11: SI | L11: 138
B12: FALLA | C12: MINERA BUENAVENTURA | D12: ARES - HUANCARAMA | E12: LINEA DE TRANSMISION | F12: L-6017 | G12: 21/01/2025 13:16:00 | H12: 21/01/2025 13:21:00 | I12: DESCONEXIÓN DE LA LÍNEA L-6017 (ARES - HUANCARAMA) 66 KV | K12: SI | L12: 66
B13: EVENTO | C13: RED DE ENERGIA DEL PERU S.A. | D13: TINGO MARÍA - AUCAYACU | E13: LINEA DE TRANSMISION | F13: L-1122 | G13: 21/01/2025 18:51:00 | H13: 21/01/2025 20:30:00 | I13: DECLARACIÓN DE SITUACIÓN EXCEPCIONAL EN LA LÍNEA L-1122 (TINGO MARÍA - AUCAYACU) DE 138 KV | K13: NO
B14: FALLA | C14: SAN GABAN | D14: SAN GABÁN II | E14: GENERADOR HIDROELÉCTRICO | F14: G2 | G14: 21/01/2025 09:23:00 | H14: 21/01/2025 09:29:00 | I14: DESCONEXIÓN DEL GRUPO G2 DE LA C.H. SAN GABAN II | K14: NO | L14: 13.8

Sheet RESTRIC_OPE
B3: martes, 21 de Enero del 2025
B5: RESTRICCIONES OPERATIVAS
B6: FECHA | C6: HORA INICIO | D6: HORA FINAL | E6: EMPRESA | F6: UBICACIÓN | G6: T.Eq. | H6: EQUIPO | I6: DESCRIPCIÓN
B7: 21/01/2025 | C7: 00:00 | D7: 24:00 | E7: CELEPSA | F7: C.H. EL PLATANAL | G7: CH | H7: CENTRAL | I7: Debido al incremento del caudal del rio cañete y establecimiento de la temporada de avenida, se declara la C.H. El Platanal como CENTRAL HIDRÁULICA DE PASADA (correo 03/01/2025).
B8: 21/01/2025 | C8: 00:00 | D8: 24:00 | E8: EGASA | F8: S.E. CONVERTIDOR | G8: BARRA | H8: BARRA138KV | I8: EGASA limitó la capacidad del transformador 138 kV/33 kV a 50 MVA por deterioro del aislamiento.
B9: 21/01/2025 | C9: 00:00 | D9: 24:00 | E9: ENEL GENERACION PIURA S.A. | F9: C.T. MALACAS | G9: CT | H9: CENTRAL | I9: De acuerdo con la comunicación vía correo del día 24.10.2024. ENEL GENERACIÓN PIURA informa una restricción de potencia para alcanzar 105 MW en simultaneo (TG6+TGN4).
B10: 21/01/2025 | C10: 00:00 | D10: 24:00 | E10: ENGIE | F10: C.E. PUNTA LOMITAS | G10: CE | H10: CENTRAL | I10: De acuerdo a la carta ENG/737-2024 (Exp:202400007555). Limitación de cables de media tensión a 100 MW de los transformadores PLT1 y PLT2 de la CE Punta Lomitas. Quedan limitados a 200 MW la generación de CE Punta Lomitas y Punta Lomitas Extensión.
B11: 21/01/2025 | C11: 00:00 | D11: 24:00 | E11: ENGIE | F11: C.H. QUITARACSA | G11: CH | H11: CENTRAL | I11: De acuerdo con el correo del 23.04 se considera la operación continua de la CH Quitaracsa debido a que el sistema de refrigeración de la CH Cañón del Pato se alimenta desde la descarga del caudal turbinado por la CH Quitaracsa.
B12: 21/01/2025 | C12: 00:00 | D12: 24:00 | E12: ENGIE | F12: C.H. YUNCÁN | G12: GH | H12: G3 | I12: Según la carta N° ENG/ 198-2024 enviada por su representada, se opera de forma continua el G3 de la CH Yuncán, debido a la ejecución de mantenimientos necesarios para evitar daños en los sellos de seguridad de la válvula esférica del grupo.
B13: 21/01/2025 | C13: 00:00 | D13: 24:00 | E13: ENGIE | F13: C.T. CHILCA 1 | G13: CT | H13: CENTRAL | I13: Con carta ENG/971-2023, indica que no puede cumplir con las IO considerada en el PDO_17122023 dado que vulneran la seguridad de sus activos. Indican que se debe tomar TMO=168h.
B14: 21/01/2025 | C14: 00:00 | D14: 24:00 | E14: ENGIE | F14: C.T. CHILCA 1 | G14: CT | H14: CENTRAL | I14: Restricción de temperatura de la C.T Chilca, ver valor en el modelo de despacho.
B15: 21/01/2025 | C15: 00:00 | D15: 24:00 | E15: ENGIE | F15: C.T. CHILCA 2 | G15: CT | H15: CENTRAL | I15: Restricción de temperatura de la C.T Chilca2, ver valor en el modelo de despacho.
B16: 21/01/2025 | C16: 00:00 | D16: 24:00 | E16: ENGIE | F16: C.T. CHILCA 2 | G16: CT | H16: CENTRAL | I16: Con carta ENG/971-2023, indica que no puede cumplir con las IO considerada en el PDO_17122023 dado que vulneran la seguridad de sus activos. Indican que se debe tomar TMO=168h.
B17: 21/01/2025 | C17: 00:00 | D17: 24:00 | E17: FENIX POWER PERÚ | F17: C.T. FENIX | G17: CT | H17: CENTRAL | I17: De acuerdo con el correo del 20/01/2025 a las 10:54 h: La unidad TG11 y TG12 cuentan no cuentan con arranques, en cualquiera de sus modos de operación para el día de mañana 21 de enero de 00:00h a 24:00h.
... B38: 21/01/2025 | C38: 00:00 | D38: 24:00 | E38: TRANSMANTARO | F38: S.E. SOCABAYA | G38: SSEE | H38: S.E. | I38: Opera en simple barra en 220 kV por indisponibilidad de la protección diferencial de barras por alarma.

Sheet MANTENIMIENTO EJECUTADOS
B3: martes, 21 de Enero del 2025
B5: Mantenimiento Ejecutado
B6: Empresa | C6: Ubicación | D6: Equipo | E6: Inicio | F6: Final | G6: Descripción | H6: MW Indisp. | I6: Prog. | J6: Dispon | K6: Interrupc. | L6: Tipo | M6: CodEq | N6: TipoEq_Osinerg
B7: ATLANTICA TRANSMISION SUR S.A. | C7: CHILCA-CTM | D7: INT-5261 | E7: 21/01/2025 00:00 | F7: 22/01/2025 00:00 | G7: Seccionador SBB-5261 fase S indisponible para maniobras de apertura y cierre por anomalia en tapa de tanque de compresion, el seccionador permanece cerrado y bloqueado. | H7: 0 | I7: P | J7: E/S | K7: N | L7: OTROS | M7: 13854 | N7: T
B8: ATLANTICA TRANSMISION SUR S.A. | C8: OCONA | D8: INT-5450 | E8: 21/01/2025 00:00 | F8: 22/01/2025 00:00 | G8: RESTRICCION OPERATIVA EN INTERRUPTOR INT-5450, POSICION CERRADA, REB-5450 EN SERVICIO SUMINISTRANDO LOS SS.AA. DE S.E. OCO?A | H8: 0 | I8: P | J8: E/S | K8: N | L8: OTROS | M8: 13761 | N8: T
B9: ATLANTICA TRANSMISION SUR S.A. | C9: OCONA | D9: INT-5462 | E9: 21/01/2025 00:00 | F9: 22/01/2025 00:00 | G9: Seccionador SBA-5462 fase T indisponible por problemas mecanicos, el seccionador permanece cerrado y bloqueado | H9: 0 | I9: P | J9: E/S | K9: N | L9: OTROS | M9: 13758 | N9: T
B10: ATLANTICA TRANSMISION SUR S.A. | C10: POROMA | D10: INT-5361 | E10: 21/01/2025 00:00 | F10: 22/01/2025 00:00 | G10: Seccionador SBA-5361 fase R indisponible por problemas mecanicos, el seccionador permanece cerrado y bloqueado | H10: 0 | I10: P | J10: E/S | K10: N | L10: OTROS | M10: 13746 | N10: T
B11: ATLANTICA TRANSMISION SUR S.A. | C11: POROMA | D11: REB-5350 | E11: 21/01/2025 00:00 | F11: 22/01/2025 00:00 | G11: FUERA DE SERVICIO POR FALLA EN EL EQUIPO. | H11: 0 | I11: P | J11: F/S | K11: N | L11: OTROS | M11: 13771 | N11: T
B12: ATN S.A. | C12: ISHCAYUCRO | D12: CL-2365 | E12: 21/01/2025 09:23 | F12: 21/01/2025 14:52 | G12: A solicitud de Conelsur: Tendido de Conductor ACSR y OPGW de T01 a Portico S.E. Ishcayucro. | H12: 0 | I12: P | J12: F/S | K12: N | L12: OTROS | M12: 23900 | N12: T
B13: ATRIA ENERGIA S.A.C. | C13: PURMACANA | D13: G1 | E13: 21/01/2025 00:00 | F13: 22/01/2025 00:00 | G13: OVERHAUL DE TURBINA | H13: 0.7 | I13: P | J13: F/S | K13: N | L13: PREV. | M13: 13133 | N13: G
B14: CHINANGO S.A.C. | C14: CHIMAY | D14: CENTRAL | E14: 21/01/2025 00:00 | F14: 21/01/2025 07:54 | G14: FUERA DE SERVICIO POR ACUMULACION DE SOLIDOS | H14: 0 | I14: F | J14: F/S | K14: N | L14: OTROS | M14: 1191 | N14: G
B15: CHINANGO S.A.C. | C15: CHIMAY | D15: G1 | E15: 21/01/2025 08:00 | F15: 22/01/2025 00:00 | G15: Reparacion de valvula bypass manual de VVMM | H15: 75 | I15: F | J15: F/S | K15: N | L15: CORR. | M15: 109 | N15: G
B16: CONELSUR LT SAC | C16: CAJAMARQUILLA | D16: BARRA A 220kV | E16: 21/01/2025 00:00 | F16: 21/01/2025 12:27 | G16: POR SEGURIDAD POR MANTENIMIENTO DE PORTICOS. La indisponibilidad de la Barra A culmino el dia 19.01, por motivo de apoyo de maniobras de NEXA no se pudo retornar a la configuracion normal de la subestacion. Por lo que se programo el 21.01.25 11:00hrs normalizar la configuracion. | H16: 0 | I16: P | J16: F/S | K16: N | L16: SEG.PER | M16: 1103 | N16: T
B17: CONELSUR LT SAC | C17: LOMERA | D17: BARRA A 220 kV | E17: 21/01/2025 00:00 | F17: 22/01/2025 00:00 | G17: POR REEMPLAZO DE COMPONENTES Y GAS SF6 EN CL2117. LOMERA OPERA EN BARRA SIMPLE | H17: 0 | I17: P | J17: F/S | K17: N | L17: OTROS | M17: 16951 | N17: T
B18: CONELSUR LT SAC | C18: LOMERA | D18: CL-2117 | E18: 21/01/2025 00:00 | F18: 22/01/2025 00:00 | G18: REEMPLAZO DE COMPONENTES Y GAS SF6 | H18: 0 | I18: P | J18: F/S | K18: N | L18: OTROS | M18: 14198 | N18: T
... B90: TRANSMANTARO | C90: YARABAMBA | D90: AT-104 523 | E90: 21/01/2025 00:00 | F90: 22/01/2025 00:00 | G90: NO SE TIENE MANDO REMOTO PARA CONTROLAR LOS TAPS DEL AUTOTRANSFORMADOR POR PROBLEMAS EN EL TRANSDUCTOR. LA MANIOBRA ES LOCAL Y REQUIERE AL ASISTENTE EN LA SUBESTACION PARA LAS MANIOBRAS. | H90: 0 | I90: P | J90: E/S | K90: N | L90: OTROS | M90: 17433 | N90: T

Sheet INGRESO OC
A3: martes, 21 de Enero del 2025
A5: INGRESO A OPERACIÓN COMERCIAL
A6: EMPRESA | B6: TIPO DE EQUIPO | C6: UBICACIÓN | D6: EQUIPO | E6: Fecha y hora de Ingreso a Operación Comercial

Sheet DESPACHO_EJECUTADO
B3: martes, 21 de Enero del 2025
A5: POTENCIA ACTIVA EJECUTADA DE LAS UNIDADES DE GENERACIÓN DEL SEIN (MW) | FH5: CENTRALES NO INTEGRANTES COES
A6: FECHA | B6: HORA | C6: 337 | D6: 338 | E6: 121 | F6: 101 | G6: 102 | H6: 42667 | I6: 42668 | J6: 126 | K6: 127 | L6: 138 | M6: 139 | N6: 197 | O6: 203 | P6: 204 | Q6: 230 | R6: 209 | S6: 56677 | T6: 796 | U6: 2146 | V6: 142 | W6: 143 | X6: 125 | Y6: 187 | Z6: 163 | AA6: 298 | AB6: 219 | AC6: 151 | AD6: 152 | AE6: 153 | AF6: 154 | AG6: 756 | AH6: 156 | AI6: 155 | AJ6: 182 | AK6: 212 | AL6: 758 | AM6: 263 | AN6: 265 | AO6: 775 | AP6: 777 | AQ6: 2154 | AR6: 150 | AS6: 149 | AT6: 188 | AU6: 2131 | AV6: 755 | AW6: 252 | AX6: 249 | AY6: 250 | AZ6: 117 | BA6: 267 | BB6: 268 | BC6: 119 | BD6: 120 | BE6: 189 | BF6: 122 | BG6: 266 | BH6: 251 | BI6: 115 | BJ6: 239 | BK6: 288 | BL6: 240 | BM6: 241 | BN6: 242 | BO6: 191 | BP6: 194 | BQ6: 196 | BR6: 207 | BS6: 236 | BT6: 795 | BU6: 285 | BV6: 995 | BW6: 996 | BX6: 997 | BY6: 766 | BZ6: 926 | CA6: 924 | CB6: 103 | CC6: 104 | CD6: 106 | CE6: 105 | CF6: 107 | CG6: 110 | CH6: 109 | CI6: 144 | CJ6: 113 | CK6: 114 | CL6: 193 | CM6: 208 | CN6: 786 | CO6: 787 | CP6: 788 | CQ6: 789 | CR6: 248 | CS6: 2159 | CT6: 303 | CU6: 59715 | CV6: 62255 | CW6: 1263 | CX6: 61800 | CY6: 2194 | CZ6: 216 | DA6: 198 | DB6: 214 | DC6: 260 | DD6: 2152 | DE6: 2128 | DF6: 247 | DG6: 228 | DH6: 2135 | DI6: 261 | DJ6: 237 | DK6: 253 | DL6: 770 | DM6: 225 | DN6: 2201 | DO6: 2171 | DP6: 760 | DQ6: 235 | DR6: 238 | DS6: 2184 | DT6: 61855 | DU6: 223 | DV6: 226 | DW6: 201 | DX6: 258 | DY6: 259 | DZ6: 920 | EA6: 257 | EB6: 256 | EC6: 2148 | ED6: 58288 | EE6: 58289 | EF6: 58839 | EG6: 58840 | EH6: 296 | EI6: 297 | EJ6: 211 | EK6: 2175 | EL6: 2178 | EM6: 2181 | EN6: 1262 | EO6: 233 | EP6: 2150 | EQ6: 2165 | ER6: 2161 | ES6: 61197 | ET6: 58851 | EU6: 234 | EV6: 215 | EW6: 917 | EX6: 289 | EY6: 58333 | EZ6: 58336 | FA6: 202 | FB6: 58487 | FC6: 213 | FD6: 232 | FE6: 2190 | FF6: TOTAL COES | FH6: 221 | FI6: 49607 | FJ6: 222 | FK6: 224 | FL6: 2187 | FM6: 227 | FN6: 49400 | FO6: 199 | FP6: 200 | FQ6: TOTAL NO COES
C7: CENTRO | D7: CENTRO | E7: NORTE | F7: CENTRO | G7: CENTRO | H7: NORTE | I7: NORTE | J7: NORTE | K7: NORTE | L7: CENTRO | M7: CENTRO | N7: CENTRO | O7: CENTRO | P7: CENTRO | Q7: CENTRO | R7: CENTRO | S7: CENTRO | T7: CENTRO | U7: CENTRO | V7: CENTRO | W7: CENTRO | X7: CENTRO | Y7: CENTRO | Z7: SUR | AA7: SUR | AB7: CENTRO | AC7: SUR | AD7: SUR | AE7: SUR | AF7: SUR | AG7: SUR | AH7: SUR | AI7: SUR | AJ7: SUR | AK7: CENTRO | AL7: NORTE | AM7: NORTE | AN7: NORTE | AO7: CENTRO | AP7: CENTRO | AQ7: CENTRO | AR7: CENTRO | AS7: CENTRO | AT7: CENTRO | AU7: CENTRO | AV7: SUR | AW7: CENTRO | AX7: CENTRO | AY7: CENTRO | AZ7: CENTRO | BA7: CENTRO | BB7: CENTRO | BC7: CENTRO | BD7: CENTRO | BE7: SUR | BF7: NORTE | BG7: CENTRO | BH7: CENTRO | BI7: NORTE | BJ7: NORTE | BK7: NORTE | BL7: SUR | BM7: SUR | BN7: SUR | BO7: CENTRO | BP7: CENTRO | BQ7: CENTRO | BR7: CENTRO | BS7: CENTRO | BT7: CENTRO | BU7: CENTRO | BV7: SUR | BW7: SUR | BX7: SUR | BY7: NORTE | BZ7: SUR | CA7: CENTRO | CB7: CENTRO | CC7: CENTRO | CD7: CENTRO | CE7: CENTRO | CF7: CENTRO | CG7: CENTRO | CH7: CENTRO | CI7: CENTRO | CJ7: CENTRO | CK7: CENTRO | CL7: CENTRO | CM7: CENTRO | CN7: SUR | CO7: SUR | CP7: SUR | CQ7: SUR | CR7: CENTRO | CS7: CENTRO | CT7: CENTRO | CU7: CENTRO | CV7: SUR | CW7: NORTE | CX7: NORTE | CY7: NORTE | CZ7: NORTE | DA7: NORTE | DB7: CENTRO | DC7: CENTRO | DD7: CENTRO | DE7: NORTE | DF7: NORTE | DG7: CENTRO | DH7: CENTRO | DI7: SUR | DJ7: SUR | DK7: CENTRO | DL7: CENTRO | DM7: CENTRO | DN7: CENTRO | DO7: CENTRO | DP7: CENTRO | DQ7: SUR | DR7: CENTRO | DS7: CENTRO | DT7: NORTE | DU7: CENTRO | DV7: CENTRO | DW7: NORTE | DX7: CENTRO | DY7: CENTRO | DZ7: CENTRO | EA7: NORTE | EB7: NORTE | EC7: SUR | ED7: CENTRO | EE7: CENTRO | EF7: CENTRO | EG7: CENTRO | EH7: CENTRO | EI7: CENTRO | EJ7: SUR | EK7: SUR | EL7: SUR | EM7: SUR | EN7: NORTE | EO7: SUR | EP7: SUR | EQ7: CENTRO | ER7: CENTRO | ES7: CENTRO | ET7: SUR | EU7: SUR | EV7: NORTE | EW7: CENTRO | EX7: NORTE | EY7: NORTE | EZ7: NORTE | FA7: CENTRO | FB7: CENTRO | FC7: CENTRO | FD7: NORTE | FE7: NORTE | FH7: NORTE | FI7: SUR | FJ7: CENTRO | FK7: NORTE | FL7: NORTE | FM7: NORTE | FN7: NORTE | FO7: NORTE | FP7: NORTE
C8: HIDROELÉCTRICA | D8: HIDROELÉCTRICA | E8: HIDROELÉCTRICA | F8: HIDROELÉCTRICA | G8: HIDROELÉCTRICA | H8: TERMOELÉCTRICA | I8: TERMOELÉCTRICA | J8: HIDROELÉCTRICA | K8: HIDROELÉCTRICA | L8: TERMOELÉCTRICA | M8: TERMOELÉCTRICA | N8: TERMOELÉCTRICA | O8: TERMOELÉCTRICA | P8: TERMOELÉCTRICA | Q8: TERMOELÉCTRICA | R8: TERMOELÉCTRICA | S8: TERMOELÉCTRICA | T8: HIDROELÉCTRICA | U8: HIDROELÉCTRICA | V8: TERMOELÉCTRICA | W8: TERMOELÉCTRICA | X8: TERMOELÉCTRICA | Y8: TERMOELÉCTRICA | Z8: HIDROELÉCTRICA | AA8: HIDROELÉCTRICA | AB8: TERMOELÉCTRICA | AC8: HIDROELÉCTRICA | AD8: HIDROELÉCTRICA | AE8: HIDROELÉCTRICA | AF8: HIDROELÉCTRICA | AG8: TERMOELÉCTRICA | AH8: TERMOELÉCTRICA | AI8: TERMOELÉCTRICA | AJ8: HIDROELÉCTRICA | AK8: HIDROELÉCTRICA | AL8: TERMOELÉCTRICA | AM8: TERMOELÉCTRICA | AN8: TERMOELÉCTRICA | AO8: HIDROELÉCTRICA | AP8: HIDROELÉCTRICA | AQ8: HIDROELÉCTRICA | AR8: HIDROELÉCTRICA | AS8: HIDROELÉCTRICA | AT8: HIDROELÉCTRICA | AU8: HIDROELÉCTRICA | AV8: HIDROELÉCTRICA | AW8: TERMOELÉCTRICA | AX8: TERMOELÉCTRICA | AY8: TERMOELÉCTRICA | AZ8: HIDROELÉCTRICA | BA8: HIDROELÉCTRICA | BB8: HIDROELÉCTRICA | BC8: HIDROELÉCTRICA | BD8: HIDROELÉCTRICA | BE8: HIDROELÉCTRICA | BF8: HIDROELÉCTRICA | BG8: HIDROELÉCTRICA | BH8: HIDROELÉCTRICA | BI8: TERMOELÉCTRICA | BJ8: TERMOELÉCTRICA | BK8: TERMOELÉCTRICA | BL8: TERMOELÉCTRICA | BM8: TERMOELÉCTRICA | BN8: TERMOELÉCTRICA | BO8: HIDROELÉCTRICA | BP8: TERMOELÉCTRICA | BQ8: TERMOELÉCTRICA | BR8: TERMOELÉCTRICA | BS8: TERMOELÉCTRICA | BT8: TERMOELÉCTRICA | BU8: TERMOELÉCTRICA | BV8: TERMOELÉCTRICA | BW8: TERMOELÉCTRICA | BX8: TERMOELÉCTRICA | BY8: HIDROELÉCTRICA | BZ8: TERMOELÉCTRICA | CA8: TERMOELÉCTRICA | CB8: HIDROELÉCTRICA | CC8: HIDROELÉCTRICA | CD8: HIDROELÉCTRICA | CE8: HIDROELÉCTRICA | CF8: HIDROELÉCTRICA | CG8: TERMOELÉCTRICA | CH8: TERMOELÉCTRICA | CI8: TERMOELÉCTRICA | CJ8: TERMOELÉCTRICA | CK8: TERMOELÉCTRICA | CL8: TERMOELÉCTRICA | CM8: TERMOELÉCTRICA | CN8: TERMOELÉCTRICA | CO8: TERMOELÉCTRICA | CP8: TERMOELÉCTRICA | CQ8: TERMOELÉCTRICA | CR8: TERMOELÉCTRICA | CS8: TERMOELÉCTRICA | CT8: SOLAR | CU8: EÓLICA | CV8: SOLAR | CW8: EÓLICA | CX8: SOLAR | CY8: HIDROELÉCTRICA | CZ8: HIDROELÉCTRICA | DA8: HIDROELÉCTRICA | DB8: HIDROELÉCTRICA | DC8: HIDROELÉCTRICA | DD8: HIDROELÉCTRICA | DE8: HIDROELÉCTRICA | DF8: HIDROELÉCTRICA | DG8: HIDROELÉCTRICA | DH8: HIDROELÉCTRICA | DI8: SOLAR | DJ8: SOLAR | DK8: EÓLICA | DL8: EÓLICA | DM8: TERMOELÉCTRICA | DN8: TERMOELÉCTRICA | DO8: TERMOELÉCTRICA | DP8: TERMOELÉCTRICA | DQ8: SOLAR | DR8: HIDROELÉCTRICA | DS8: HIDROELÉCTRICA | DT8: HIDROELÉCTRICA | DU8: HIDROELÉCTRICA | DV8: HIDROELÉCTRICA | DW8: HIDROELÉCTRICA | DX8: HIDROELÉCTRICA | DY8: HIDROELÉCTRICA | DZ8: HIDROELÉCTRICA | EA8: EÓLICA | EB8: EÓLICA | EC8: SOLAR | ED8: EÓLICA | EE8: EÓLICA | EF8: EÓLICA | EG8: EÓLICA | EH8: HIDROELÉCTRICA | EI8: HIDROELÉCTRICA | EJ8: HIDROELÉCTRICA | EK8: HIDROELÉCTRICA | EL8: HIDROELÉCTRICA | EM8: HIDROELÉCTRICA | EN8: EÓLICA | EO8: SOLAR | EP8: SOLAR | EQ8: HIDROELÉCTRICA | ER8: EÓLICA | ES8: EÓLICA | ET8: SOLAR | EU8: SOLAR | EV8: HIDROELÉCTRICA | EW8: HIDROELÉCTRICA | EX8: TERMOELÉCTRICA | EY8: TERMOELÉCTRICA | EZ8: TERMOELÉCTRICA | FA8: TERMOELÉCTRICA | FB8: TERMOELÉCTRICA | FC8: TERMOELÉCTRICA | FD8: TERMOELÉCTRICA | FE8: TERMOELÉCTRICA | FH8: HIDROELÉCTRICA | FI8: HIDROELÉCTRICA | FJ8: HIDROELÉCTRICA | FK8: HIDROELÉCTRICA | FL8: HIDROELÉCTRICA | FM8: TERMOELÉCTRICA | FN8: TERMOELÉCTRICA | FO8: HIDROELÉCTRICA | FP8: HIDROELÉCTRICA
C9: CENTRALES SANTA ROSA S.A.C. | D9: CENTRALES SANTA ROSA S.A.C. | E9: INVERSIONES SHAQSHA S.A.C. | F9: ELECTROPERU | G9: ELECTROPERU | H9: ELECTROPERU | I9: ELECTROPERU | J9: ORAZUL ENERGY PERÚ | K9: ORAZUL ENERGY PERÚ | L9: TERMOSELVA | M9: TERMOSELVA | N9: KALLPA GENERACION S.A. | O9: KALLPA GENERACION S.A. | P9: KALLPA GENERACION S.A. | Q9: KALLPA GENERACION S.A. | R9: KALLPA GENERACION S.A. | S9: KALLPA GENERACION S.A. | T9: KALLPA GENERACION S.A. | U9: KALLPA GENERACION S.A. | V9: SHOUGESA | W9: SHOUGESA | X9: SHOUGESA | Y9: SHOUGESA | Z9: EGEMSA | AA9: EGESUR | AB9: EGESUR | AC9: EGASA | AD9: EGASA | AE9: EGASA | AF9: EGASA | AG9: EGASA | AH9: EGASA | AI9: EGASA | AJ9: SAN GABAN | AK9: CELEPSA | AL9: MINERA CERRO VERDE | AM9: PLANTA DE RESERVA FRIA DE GENERACION DE ETEN S.A. | AN9: PLANTA DE RESERVA FRIA DE GENERACION DE ETEN S.A. | AO9: EMPRESA DE GENERACION HUALLAGA | AP9: EMPRESA DE GENERACION HUALLAGA | AQ9: LA VIRGEN | AR9: CHINANGO S.A.C. | AS9: CHINANGO S.A.C. | AT9: HIDROELECTRICA HUANCHOR S.A.C. | AU9: CELEPSA RENOVABLES S.R.L. | AV9: INLAND ENERGY SAC | AW9: FENIX POWER PERÚ | AX9: FENIX POWER PERÚ | AY9: FENIX POWER PERÚ | AZ9: STATKRAFT S.A | BA9: STATKRAFT S.A | BB9: STATKRAFT S.A | BC9: STATKRAFT S.A | BD9: STATKRAFT S.A | BE9: STATKRAFT S.A | BF9: STATKRAFT S.A | BG9: STATKRAFT S.A | BH9: EMPRESA DE GENERACION HUANZA | BI9: ENEL GENERACION PIURA S.A. | BJ9: ENEL GENERACION PIURA S.A. | BK9: ENEL GENERACION PIURA S.A. | BL9: ENGIE | BM9: ENGIE | BN9: ENGIE | BO9: ENGIE | BP9: ENGIE | BQ9: ENGIE | BR9: ENGIE | BS9: ENGIE | BT9: ENGIE | BU9: ENGIE | BV9: ENGIE | BW9: ENGIE | BX9: ENGIE | BY9: ENGIE | BZ9: INFRAESTRUCTURAS Y ENERGIAS DEL PERU S.A.C. | CA9: INFRAESTRUCTURAS Y ENERGIAS DEL PERU S.A.C. | CB9: ORYGEN PERU S.A.A. | CC9: ORYGEN PERU S.A.A. | CD9: ORYGEN PERU S.A.A. | CE9: ORYGEN PERU S.A.A. | CF9: ORYGEN PERU S.A.A. | CG9: ORYGEN PERU S.A.A. | CH9: ORYGEN PERU S.A.A. | CI9: ORYGEN PERU S.A.A. | CJ9: ORYGEN PERU S.A.A. | CK9: ORYGEN PERU S.A.A. | CL9: ORYGEN PERU S.A.A. | CM9: ORYGEN PERU S.A.A. | CN9: SAMAY I S.A.C | CO9: SAMAY I S.A.C | CP9: SAMAY I S.A.C | CQ9: SAMAY I S.A.C | CR9: TERMOCHILCA S.A.C. | CS9: TERMOCHILCA S.A.C. | CT9: COLCA SOLAR S.A.C. | CU9: ENERGIA RENOVABLE DEL SUR S.A. | CV9: GR CORTARRAMA SOCIEDAD ANONIMA CERRADA | CW9: GR TARUCA SOCIEDAD ANONIMA CERRADA | CX9: KONDU SAC | CY9: PERUANA DE INVERSIONES EN ENERGIAS RENOVABLES S.A. | CZ9: ORAZUL ENERGY PERÚ | DA9: ORAZUL ENERGY PERÚ | DB9: MAJA ENERGIA S.A.C. | DC9: EMPRESA DE GENERACION ELECTRICA CANCHAYLLO SAC | DD9: EMPRESA DE GENERACION ELECTRICA SANTA ANA S.A.C. | DE9: EMPRESA ELECTRICA AGUA AZUL | DF9: EMPRESA ELECTRICA RIO DOBLE | DG9: HIDROCAÑETE S.A. | DH9: HUAURA POWER GROUP S.A. | DI9: MOQUEGUA FV S.A.C. | DJ9: PANAMERICANA SOLAR SAC. | DK9: PARQUE EOLICO MARCONA S.A.C. | DL9: PARQUE EOLICO TRES HERMANAS S.A.C. | DM9: PETRAMAS | DN9: PETRAMAS | DO9: PETRAMAS | DP9: PETRAMAS | DQ9: TACNA SOLAR SAC. | DR9: ELECTRICA YANAPAMPA SAC | DS9: ANDEAN POWER S.A.C. | DT9: ASOCIACIÓN SANTA LUCIA DE CHACAS | DU9: ATRIA ENERGIA S.A.C. | DV9: EGEJUNIN | DW9: EGEJUNIN | DX9: EGEJUNIN | DY9: EGEJUNIN | DZ9: EMPRESA DE GENERACION ELECTRICA RIO BAÑOS S.A.C. | EA9: ENERGÍA EÓLICA S.A. | EB9: ENERGÍA EÓLICA S.A. | EC9: ENGIE | ED9: ENGIE | EE9: ENGIE | EF9: ENGIE | EG9: ENGIE | EH9: GENERACIÓN ANDINA S.A.C. | EI9: GENERACIÓN ANDINA S.A.C. | EJ9: GENERADORA DE ENERGÍA DEL PERÚ | EK9: GENERADORA DE ENERGÍA DEL PERÚ | EL9: GENERADORA DE ENERGÍA DEL PERÚ | EM9: GENERADORA DE ENERGÍA DEL PERÚ | EN9: GR PAINO SOCIEDAD ANONIMA CERRADA | EO9: MAJES ARCUS S.A.C. | EP9: ORYGEN PERU S.A.A. | EQ9: ORYGEN PERU S.A.A. | ER9: ORYGEN PERU S.A.A. | ES9: ORYGEN PERU S.A.A. | ET9: ORYGEN PERU S.A.A. | EU9: REPARTICIÓN ARCUS S.A.C. | EV9: SINERSA | EW9: SINERSA | EX9: BIOENERGIA DEL CHIRA S.A. | EY9: GM OPERACIONES S.A.C. | EZ9: GM OPERACIONES S.A.C. | FA9: SDF ENERGIA SAC | FB9: SDF ENERGIA SAC | FC9: AGRO INDUSTRIAL PARAMONGA S.A. | FD9: AGROAURORA S.A.C. | FE9: AGROINDUSTRIAS SAN JACINTO S.A.A. | FH9: UNACEM PERU S.A. | FI9: SAN GABAN | FJ9: ELECTRO ORIENTE | FK9: AGUAS Y ENERGIA PERU | FL9: ELECTRO ZAÑA S.A.C. | FM9: ELECTRONOROESTE S.A. | FN9: SDE PIURA | FO9: SINERSA | FP9: SINERSA
C10: SANTA ROSA 1 | D10: SANTA ROSA 2 | E10: PARIAC | F10: MANTARO | G10: RESTITUCION | H10: TUMBES MAK 1 | I10: TUMBES MAK 2 | J10: CARHUAQUERO | K10: CAÑON DEL PATO | L10: AGUAYTIA TG1 | M10: AGUAYTIA TG2 | N10: KALLPA TG1 | O10: KALLPA TG2 | P10: KALLPA TG3 | Q10: KALLPA TV | R10: LFLORES TG1 | S10: LFLORES TV | T10: CERRO DEL AGUILA | U10: CERRODELAGUILAG4 | V10: SHOUGESA TV1 | W10: SHOUGESA TV2 | X10: SHOUGESA TV3 | Y10: SHOUGESA CUMMINS | Z10: MACHUPICCHU | AA10: ARICOTA 1 | AB10: INDEPENDENCIA | AC10: CHARCANI I,II,III | AD10: CHARCANI IV | AE10: CHARCANI V | AF10: CHARCANI VI | AG10: CHILINA TG | AH10: MOLLENDO 1, 2, 3 | AI10: CHILINA (SULZ 1,2) | AJ10: SAN GABAN II | AK10: PLATANAL | AL10: RECKA | AM10: RF ETEN TG1 | AN10: RF ETEN TG2 | AO10: CHAGLLA GP1 | AP10: CHAGLLA | AQ10: LA VIRGEN | AR10: CHIMAY | AS10: YANANGO | AT10: HUANCHOR | AU10: MARAÑON | AV10: STA TERESA | AW10: FENIX GT11 | AX10: FENIX GT12 | AY10: FENIX TV10 | AZ10: YAUPI | BA10: OROYA | BB10: PACHACHACA | BC10: MALPASO | BD10: CAHUA | BE10: ARCATA | BF10: GALLITO CIEGO | BG10: CHEVES | BH10: HUANZA | BI10: MALACAS2 TG4 | BJ10: MALACAS3 TG 5 | BK10: MALACAS1 TG6 | BL10: RF ILO2 TG1 | BM10: RF ILO2 TG2 | BN10: RF ILO2 TG3 | BO10: YUNCAN | BP10: CHILCA1 TG1 | BQ10: CHILCA1 TG2 | BR10: CHILCA1 TG3 | BS10: CHILCA-TV | BT10: CHILCA2 TG41 | BU10: CHILCA2-TV | BV10: CTNEPI_TG41 | BW10: CTNEPI_TG42 | BX10: CTNEPI_TG43 | BY10: QUITARACSA | BZ10: RF PTO MALDONADO | CA10: RF PUCALLPA | CB10: HUINCO | CC10: MATUCANA | CD10: MOYOPAMPA | CE10: CALLAHUANCA | CF10: HUAMPANI | CG10: STA ROSA WEST TG7 | CH10: UTI_5 | CI10: UTI_6 | CJ10: VENTANILLA 3 | CK10: VENTANILLA 4 | CL10: VENTANILLA TV | CM10: STAROSA TG8 | CN10: PTO_BRVO TG1 | CO10: PTO_BRVO TG2 | CP10: PTO_BRVO TG3 | CQ10: PTO_BRVO TG4 | CR10: OLLEROS TG1 | CS10: OLLEROS TV | CT10: CS YARUCAYA | CU10: SAN JUAN | CV10: MATARANI | CW10: DUNA | CX10: CARHUAQUERO (CS) | CY10: MANTA I | CZ10: CARHUAQUERO4 | DA10: CAÑA BRAVA | DB10: RONCADOR | DC10: CANCHAYLLO | DD10: RENOVANDESH1 | DE10: POTRERO | DF10: PIZARRAS | DG10: NIMPERIAL | DH10: YARUCAYA | DI10: MOQUEGUA-SOLAR | DJ10: PANAMERICANA-SOLAR | DK10: PQE-EOLICO-MARCONA | DL10: PQE-EOLICO-3-HERMANAS | DM10: HUAYCOLORO | DN10: CALLAO | DO10: DONA_CATALINA | DP10: LAGRINGAV | DQ10: TACNA-SOLAR | DR10: YANAPAMPA | DS10: CARHUAC | DT10: HUALLIN | DU10: PURMACANA | DV10: HUASAHUASI | DW10: STACRUZ_1_2 | DX10: RUNATULLO_II | DY10: RUNATULLO_III | DZ10: RUCUY | EA10: PQE-EOLICO-TALARA | EB10: PQE-EOLICO-CUPISNIQUE | EC10: INTIPAMPA | ED10: PUNTA LOMITAS-BL1 | EE10: PUNTA LOMITAS-BL2 | EF10: PUN LOMITAS_EXP-BL1 | EG10: PUN LOMITAS_EXP-BL2 | EH10: 8AGOSTO | EI10: EL CARMEN | EJ10: LA JOYA | EK10: ANGEL_I | EL10: ANGEL_II | EM10: ANGEL_III | EN10: HUAMBOS | EO10: MAJES | EP10: RUBI | EQ10: CH_HER1 | ER10: WAYRA-I | ES10: WAYRA EXTENSION | ET10: CLEMESI | EU10: REPARTICION | EV10: POECHOS2 | EW10: CHANCAY | EX10: CANA BRAVA | EY10: REFINERIA TALARA TV1 | EZ10: REFINERÍA TALARA TV2 | FA10: OQUENDO TG1 | FB10: OQUENDO TV1 | FC10: PARAMONGA | FD10: MAPLE | FE10: SAN_JACINTO | FF10: MW | FH10: CARPAPATA | FI10: TUPURI | FJ10: CENTRALES ELOR | FK10: PIAS1 | FL10: ZANA | FM10: TABLAZO | FN10: TALLANCA | FO10: CURUMUY | FP10: POECHOS1 | FQ10: MW
A11: 21/01/2025 | B11: 00:30 | C11: 1.1 | D11: 1.6 | E11: 4.3 | F11: 585.6 | G11: 196.6 | J11: 88.2 | K11: 237.3 | N11: 116.8 | O11: 116.6 | P11: 117.3 | Q11: 224 | R11: 205.7 | S11: 108.7 | T11: 545.9 | U11: 10.3 | Z11: 160.2 | AA11: 7 | AB11: 0 | AC11: 6.8 | AD11: 5 | AE11: 75.9 | AF11: 8.6 | AJ11: 109.2 | AK11: 222.9 | AO11: 6.5 | AP11: 409.4 | AQ11: 70.9 | AR11: 0 | AS11: 41 | AT11: 18.4 | AU11: 19.8 | AV11: 89.7 | AW11: 177 | AX11: 177.2 | AY11: 182.8 | AZ11: 108.1 | BA11: 7.7 | BB11: 9 | BC11: 34.7 | BD11: 46.1 | BE11: 3.8 | BF11: 31.3 | BG11: 152.1 | BH11: 20.4 | BK11: 47.6 | BO11: 116 | BQ11: 0 | BT11: 0 | BY11: 56.2 | CB11: 48.8 | CC11: 122.8 | CD11: 61.9 | CE11: 81.1 | CF11: 30 | CJ11: 145.2 | CK11: 144.3 | CL11: 147.8 | CT11: 0 | CU11: 67.4 | CV11: 0 | CW11: 0 | CX11: 0 | CY11: 20 | CZ11: 9.9 | DA11: 5.3 | DB11: 3.6 | DC11: 5 | DD11: 19.8 | DE11: 20 | DF11: 18.75 | DG11: 3.5 | DH11: 18.7 | DI11: 0 | DJ11: 0 | DK11: 17.2 | DL11: 43.1 | DM11: 4.7 | DN11: 2.4 | DO11: 2.4 | DP11: 2.9 | DQ11: 0 | DR11: 3.5 | DS11: 12.3 | DT11: 2 | DV11: 14.5 | DW11: 9.1 | DX11: 19.9 | DY11: 20.3 | DZ11: 20 | EA11: 24.8 | EB11: 38.6 | EC11: 0 | ED11: 45.7 | EE11: 66.4 | EF11: 3.8 | EG11: 1.9 | EH11: 21 | EI11: 7.2 | EJ11: 7.6 | EK11: 20 | EL11: 20 | EM11: 10 | EN11: 0 | EO11: 0 | EP11: 0 | EQ11: 0.6 | ER11: 30 | ES11: 35.3 | ET11: 0 | EU11: 0 | EV11: 5.5 | EW11: 20 | EX11: 10.5 | EY11: 14.9 | EZ11: 35.4 | FA11: 29.1 | FB11: 3.3 | FC11: 14 | FD11: 17.6 | FE11: 8.4 | FF11: 6621.05 | FH11: 24.02809 | FI11: 1.3 | FJ11: 5.86 | FK11: 6.13025 | FL11: 7.8 | FN11: 18.91607 | FO11: 4.6 | FP11: 4.2 | FQ11: 72.83441
A12: 21/01/2025 | B12: 01:00 | C12: 1.1 | D12: 1.6 | E12: 4.3 | F12: 599.4 | G12: 199.1 | J12: 90.3 | K12: 239.3 | N12: 107.8 | O12: 107.8 | P12: 108.3 | Q12: 209.4 | R12: 205.8 | S12: 109.4 | T12: 560.5 | U12: 10.6 | Z12: 167 | AA12: 7.8 | AB12: 0 | AC12: 6.8 | AD12: 5 | AE12: 77.7 | AF12: 8.8 | AJ12: 111.2 | AK12: 221.5 | AO12: 6.5 | AP12: 373.1 | AQ12: 80.8 | AR12: 0 | AS12: 42.1 | AT12: 18.3 | AU12: 19.8 | AV12: 93.2 | AW12: 179.8 | AX12: 180.6 | AY12: 183.3 | AZ12: 108.8 | BA12: 7.6 | BB12: 9 | BC12: 35.9 | BD12: 47.2 | BE12: 3.8 | BF12: 31.5 | BG12: 154.1 | BH12: 21.7 | BK12: 47.3 | BO12: 118 | BQ12: 0 | BT12: 0 | BY12: 57.1 | CB12: 68.6 | CC12: 122.9 | CD12: 63.6 | CE12: 81.6 | CF12: 30.5 | CJ12: 144.8 | CK12: 143.8 | CL12: 148.1 | CT12: 0 | CU12: 66.6 | CV12: 0 | CW12: 0 | CX12: 0 | CY12: 20 | CZ12: 9.9 | DA12: 5.4 | DB12: 3.6 | DC12: 5.2 | DD12: 20.3 | DE12: 20 | DF12: 18.7 | DG12: 3.5 | DH12: 18.7 | DI12: 0 | DJ12: 0 | DK12: 15.8 | DL12: 41.1 | DM12: 4.7 | DN12: 2.4 | DO12: 2.4 | DP12: 2.9 | DQ12: 0 | DR12: 3.5 | DS12: 7.2 | DT12: 2 | DV12: 14.6 | DW12: 9.1 | DX12: 20.1 | DY12: 20.3 | DZ12: 19.8 | EA12: 25 | EB12: 30.4 | EC12: 0 | ED12: 44.5 | EE12: 56.8 | EF12: 6.4 | EG12: 2.5 | EH12: 21 | EI12: 7.2 | EJ12: 7.6 | EK12: 20 | EL12: 20 | EM12: 10 | EN12: 0 | EO12: 0 | EP12: 0 | EQ12: 0.6 | ER12: 33.8 | ES12: 30.3 | ET12: 0 | EU12: 0 | EV12: 5.5 | EW12: 19.8 | EX12: 9.9 | EY12: 14.9 | EZ12: 35.8 | FA12: 29.2 | FB12: 3.3 | FC12: 14.1 | FD12: 17.2 | FE12: 8.1 | FF12: 6615.6 | FH12: 23.96628 | FI12: 1.3 | FJ12: 5.216 | FK12: 6.12975 | FL12: 7.8 | FN12: 18.91522 | FO12: 4.6 | FP12: 4.1 | FQ12: 72.02725
A13: 21/01/2025 | B13: 01:30 | C13: 1.1 | D13: 1.6 | E13: 4.3 | F13: 589.5 | G13: 197.9 | J13: 87.6 | K13: 239.1 | N13: 107.5 | O13: 107.8 | P13: 107.6 | Q13: 207.7 | R13: 207.1 | S13: 108.8 | T13: 540 | U13: 10.2 | Z13: 163.2 | AA13: 7 | AB13: 0 | AC13: 6.8 | AD13: 5 | AE13: 75.3 | AF13: 8.1 | AJ13: 109 | AK13: 221.4 | AO13: 6.5 | AP13: 363.5 | AQ13: 80.8 | AR13: 0 | AS13: 40.8 | AT13: 18.3 | AU13: 19.8 | AV13: 88.1 | AW13: 146.8 | AX13: 147 | AY13: 167.8 | AZ13: 107.6 | BA13: 7.7 | BB13: 9 | BC13: 34.5 | BD13: 45.9 | BE13: 3.8 | BF13: 31.3 | BG13: 151 | BH13: 20.1 | BK13: 47.4 | BO13: 115.7 | BQ13: 0 | BT13: 0 | BY13: 55.9 | CB13: 46.8 | CC13: 114.2 | CD13: 61.6 | CE13: 80.4 | CF13: 29.9 | CJ13: 144.5 | CK13: 143.8 | CL13: 148.1 | CT13: 0 | CU13: 73 | CV13: 0 | CW13: 0.1 | CX13: 0 | CY13: 20 | CZ13: 9.9 | DA13: 5.3 | DB13: 3.7 | DC13: 5.2 | DD13: 19.7 | DE13: 20 | DF13: 18.64 | DG13: 3.4 | DH13: 18.7 | DI13: 0 | DJ13: 0 | DK13: 17.4 | DL13: 48.2 | DM13: 4.7 | DN13: 2.4 | DO13: 2.4 | DP13: 2.9 | DQ13: 0 | DR13: 3.5 | DS13: 7.1 | DT13: 2 | DV13: 14.5 | DW13: 9.2 | DX13: 19.5 | DY13: 20.1 | DZ13: 19.8 | EA13: 25.2 | EB13: 29.8 | EC13: 0 | ED13: 32.3 | EE13: 51.7 | EF13: 2 | EG13: 1.2 | EH13: 20.9 | EI13: 7.1 | EJ13: 7.6 | EK13: 20 | EL13: 20 | EM13: 10 | EN13: 0 | EO13: 0 | EP13: 0 | EQ13: 0.6 | ER13: 27.6 | ES13: 26.5 | ET13: 0 | EU13: 0 | EV13: 5.5 | EW13: 19.8 | EX13: 10 | EY13: 14.9 | EZ13: 36.2 | FA13: 29.2 | FB13: 3.3 | FC13: 14.3 | FD13: 17.2 | FE13: 8.4 | FF13: 6404.84 | FH13: 24.00742 | FI13: 1.3 | FJ13: 5.202 | FK13: 6.13 | FL13: 7.8 | FN13: 18.9142 | FO13: 4.7 | FP13: 4.1 | FQ13: 72.15362
A14: 21/01/2025 | B14: 02:00 | C14: 1.1 | D14: 1.6 | E14: 4.3 | F14: 598.4 | G14: 200.2 | J14: 90.1 | K14: 239.4 | N14: 107.7 | O14: 107.8 | P14: 107.5 | Q14: 207.5 | R14: 205.7 | S14: 109.1 | T14: 556.6 | U14: 10.5 | Z14: 166 | AA14: 7.9 | AB14: 0 | AC14: 6.8 | AD14: 5 | AE14: 40.2 | AF14: 8.1 | AJ14: 110.9 | AK14: 223 | AO14: 6.5 | AP14: 416.9 | AQ14: 25.3 | AR14: 0 | AS14: 42 | AT14: 18.4 | AU14: 19.8 | AV14: 87.7 | AW14: 130.4 | AX14: 130.7 | AY14: 155.8 | AZ14: 108.7 | BA14: 7.6 | BB14: 9 | BC14: 35.9 | BD14: 46.8 | BE14: 3.8 | BF14: 31.3 | BG14: 153.8 | BH14: 21.5 | BK14: 47.2 | BO14: 118 | BQ14: 0 | BT14: 0 | BY14: 57 | CB14: 65.5 | CC14: 126.7 | CD14: 63.3 | CE14: 81.4 | CF14: 30.4 | CJ14: 144.7 | CK14: 144 | CL14: 147.9 | CT14: 0 | CU14: 70.6 | CV14: 0 | CW14: 0 | CX14: 0 | CY14: 20 | CZ14: 9.9 | DA14: 5.4 | DB14: 3.7 | DC14: 5.2 | DD14: 20.2 | DE14: 20 | DF14: 18.29 | DG14: 3.5 | DH14: 18.7 | DI14: 0 | DJ14: 0 | DK14: 17.1 | DL14: 41.2 | DM14: 4.7 | DN14: 2.4 | DO14: 2.4 | DP14: 2.9 | DQ14: 0 | DR14: 3.5 | DS14: 7.1 | DT14: 2 | DV14: 14.6 | DW14: 9.3 | DX14: 19.4 | DY14: 20.3 | DZ14: 19.8 | EA14: 23.3 | EB14: 31 | EC14: 0 | ED14: 37.7 | EE14: 54 | EF14: 3 | EG14: 1.3 | EH14: 20.9 | EI14: 7 | EJ14: 7.9 | EK14: 20 | EL14: 20 | EM14: 10 | EN14: 0 | EO14: 0 | EP14: 0 | EQ14: 0.6 | ER14: 39.6 | ES14: 36 | ET14: 0 | EU14: 0 | EV14: 5.6 | EW14: 19.8 | EX14: 10.3 | EY14: 15 | EZ14: 35.6 | FA14: 29.2 | FB14: 3.4 | FC14: 14.6 | FD14: 17.4 | FE14: 7.7 | FF14: 6426.49 | FH14: 24.14923 | FI14: 1.3 | FJ14: 5.193 | FK14: 6.12975 | FL14: 7.8 | FN14: 18.91412 | FO14: 4.8 | FP14: 4.1 | FQ14: 72.3861
A15: 21/01/2025 | B15: 02:30 | C15: 1.1 | D15: 1.6 | E15: 4.3 | F15: 599.1 | G15: 199.8 | J15: 90.1 | K15: 239.2 | N15: 108.2 | O15: 108.2 | P15: 109 | Q15: 208.5 | R15: 205.4 | S15: 108.6 | T15: 559.8 | U15: 10.5 | Z15: 163.9 | AA15: 7.9 | AB15: 0 | AC15: 6.8 | AD15: 5 | AE15: 40.4 | AF15: 7.9 | AJ15: 110.9 | AK15: 159.3 | AO15: 6.5 | AP15: 465.9 | AQ15: 69 | AR15: 0 | AS15: 42 | AT15: 18.4 | AU15: 19.8 | AV15: 89.8 | AW15: 143.7 | AX15: 144.1 | AY15: 161.3 | AZ15: 108.7 | BA15: 7.2 | BB15: 8.9 | BC15: 43.9 | BD15: 47 | BE15: 3.8 | BF15: 31.5 | BG15: 95.2 | BH15: 7.9 | BK15: 47.6 | BO15: 118 | BQ15: 0 | BT15: 0 | BY15: 16.2 | CB15: 40.9 | CC15: 131.1 | CD15: 63.6 | CE15: 81.5 | CF15: 30.4 | CJ15: 145.7 | CK15: 144.9 | CL15: 148.3 | CT15: 0 | CU15: 77.7 | CV15: 0 | CW15: 0 | CX15: 0 | CY15: 20 | CZ15: 9.9 | DA15: 5.2 | DB15: 3.6 | DC15: 5.2 | DD15: 20.3 | DE15: 20 | DF15: 18.35 | DG15: 3.5 | DH15: 18.7 | DI15: 0 | DJ15: 0 | DK15: 19.6 | DL15: 42.9 | DM15: 4.7 | DN15: 2.4 | DO15: 2.4 | DP15: 2.9 | DQ15: 0 | DR15: 3.5 | DS15: 7.1 | DT15: 2 | DV15: 14.5 | DW15: 9.2 | DX15: 19.3 | DY15: 20.3 | DZ15: 19.8 | EA15: 23.4 | EB15: 23.3 | EC15: 0 | ED15: 52.1 | EE15: 55.9 | EF15: 2 | EG15: 1 | EH15: 21 | EI15: 7 | EJ15: 7.9 | EK15: 20 | EL15: 20 | EM15: 10 | EN15: 0 | EO15: 0 | EP15: 0 | EQ15: 0.6 | ER15: 43.5 | ES15: 40.2 | ET15: 0 | EU15: 0 | EV15: 5.5 | EW15: 19.8 | EX15: 10.1 | EY15: 15 | EZ15: 35.9 | FA15: 29.1 | FB15: 3.3 | FC15: 13.8 | FD15: 17.6 | FE15: 8 | FF15: 6397.35 | FH15: 24.13155 | FI15: 1.3 | FJ15: 5.083 | FK15: 6.1305 | FL15: 7.8 | FN15: 18.91392 | FO15: 4.8 | FP15: 4.1 | FQ15: 72.25897
A16: 21/01/2025 | B16: 03:00 | C16: 1.1 | D16: 1.6 | E16: 4.3 | F16: 602.9 | G16: 200.2 | J16: 89.9 | K16: 240.9 | N16: 108 | O16: 105.8 | P16: 110 | Q16: 208 | R16: 205.9 | S16: 109.2 | T16: 564.6 | U16: 10.5 | Z16: 168.1 | AA16: 8.5 | AB16: 0 | AC16: 6.8 | AD16: 5 | AE16: 40.7 | AF16: 4.7 | AJ16: 111.2 | AK16: 164.2 | AO16: 6.5 | AP16: 468.9 | AQ16: 81.6 | AR16: 0 | AS16: 42.2 | AT16: 18.4 | AU16: 19.8 | AV16: 93.1 | AW16: 60.8 | AX16: 120.3 | AY16: 148.4 | AZ16: 109.5 | BA16: 7.2 | BB16: 9 | BC16: 43.6 | BD16: 47.8 | BE16: 3.8 | BF16: 31.4 | BG16: 96.4 | BH16: 8.6 | BK16: 47.2 | BO16: 118.6 | BQ16: 0 | BT16: 0 | BY16: 16.4 | CB16: 44.3 | CC16: 131.5 | CD16: 65.9 | CE16: 81.8 | CF16: 30.7 | CJ16: 145.6 | CK16: 144.7 | CL16: 148 | CT16: 0 | CU16: 83.1 | CV16: 0 | CW16: 0 | CX16: 0 | CY16: 20 | CZ16: 9.9 | DA16: 5.3 | DB16: 3.7 | DC16: 5.2 | DD16: 20.6 | DE16: 20 | DF16: 18.34 | DG16: 3.5 | DH16: 18.7 | DI16: 0 | DJ16: 0 | DK16: 18.9 | DL16: 49.7 | DM16: 4.7 | DN16: 2.4 | DO16: 2.4 | DP16: 2.9 | DQ16: 0 | DR16: 3.5 | DS16: 4 | DT16: 2 | DV16: 14.6 | DW16: 9.2 | DX16: 19.3 | DY16: 20.3 | DZ16: 19.8 | EA16: 26 | EB16: 19.9 | EC16: 0 | ED16: 38.1 | EE16: 54.2 | EF16: 4.7 | EG16: 1.1 | EH16: 21 | EI16: 6.9 | EJ16: 7.9 | EK16: 20 | EL16: 20 | EM16: 10 | EN16: 0 | EO16: 0 | EP16: 0 | EQ16: 0.6 | ER16: 47 | ES16: 32 | ET16: 0 | EU16: 0 | EV16: 5.5 | EW16: 19.8 | EX16: 10.1 | EY16: 15.1 | EZ16: 35.7 | FA16: 29.1 | FB16: 3.3 | FC16: 14.5 | FD16: 17.6 | FE16: 7.1 | FF16: 6313.34 | FH16: 24.13608 | FI16: 1.3 | FJ16: 5.094 | FK16: 6.13025 | FL16: 7.8 | FN16: 18.91372 | FO16: 4.9 | FP16: 4.2 | FQ16: 72.47405
A17: 21/01/2025 | B17: 03:30 | C17: 1.1 | D17: 1.6 | E17: 4.3 | F17: 598.3 | G17: 197.4 | J17: 87.2 | K17: 238.3 | N17: 128.8 | O17: 129.1 | P17: 128.2 | Q17: 236.4 | R17: 206.9 | S17: 109.1 | T17: 563.1 | U17: 10.3 | Z17: 166.5 | AA17: 7.4 | AB17: 0 | AC17: 6.8 | AD17: 5 | AE17: 40.8 | AF17: 6.1 | AJ17: 110.2 | AK17: 220 | AO17: 6.5 | AP17: 388.6 | AQ17: 81.6 | AR17: 0 | AS17: 42.1 | AT17: 18.2 | AU17: 19.8 | AV17: 92.2 | AW17: 121 | AX17: 116 | AY17: 68.2 | AZ17: 108.9 | BA17: 7.2 | BB17: 8.9 | BC17: 41.8 | BD17: 46.6 | BE17: 3.8 | BF17: 31.7 | BG17: 93.7 | BH17: 6.4 | BK17: 47.6 | BO17: 116.7 | BQ17: 0 | BT17: 0 | BY17: 15.4 | CB17: 46 | CC17: 121.7 | CD17: 64.3 | CE17: 80.9 | CF17: 30 | CJ17: 145.6 | CK17: 144.8 | CL17: 147.9 | CT17: 0 | CU17: 85.7 | CV17: 0 | CW17: 0 | CX17: 0 | CY17: 20 | CZ17: 9.8 | DA17: 5.4 | DB17: 3.7 | DC17: 5.2 | DD17: 20 | DE17: 20 | DF17: 18.34 | DG17: 3.5 | DH17: 18.7 | DI17: 0 | DJ17: 0 | DK17: 22.6 | DL17: 54.8 | DM17: 4.7 | DN17: 2.4 | DO17: 2.4 | DP17: 2.9 | DQ17: 0 | DR17: 3.6 | DS17: 6 | DT17: 2 | DV17: 14.6 | DW17: 9.2 | DX17: 19.4 | DY17: 20.2 | DZ17: 19.8 | EA17: 24 | EB17: 19.8 | EC17: 0 | ED17: 57.5 | EE17: 71 | EF17: 2.9 | EG17: 2.8 | EH17: 21 | EI17: 6.8 | EJ17: 7.6 | EK17: 20 | EL17: 20 | EM17: 10 | EN17: 0 | EO17: 0 | EP17: 0 | EQ17: 0.6 | ER17: 42 | ES17: 27.6 | ET17: 0 | EU17: 0 | EV17: 5.6 | EW17: 19.9 | EX17: 10 | EY17: 15 | EZ17: 35.8 | FA17: 29.2 | FB17: 3.3 | FC17: 14.3 | FD17: 16.3 | FE17: 6.7 | FF17: 6351.64 | FH17: 24.12149 | FI17: 1.3 | FJ17: 5.105 | FK17: 6.1305 | FL17: 7.8 | FN17: 18.90809 | FO17: 4.8 | FP17: 4.2 | FQ17: 72.36508
A18: 21/01/2025 | B18: 04:00 | C18: 1.1 | D18: 1.6 | E18: 4.3 | F18: 604.9 | G18: 199.2 | J18: 90.7 | K18: 241.4 | N18: 131.7 | O18: 130.8 | P18: 131.9 | Q18: 230 | R18: 208.8 | S18: 108.7 | T18: 570.6 | U18: 10.5 | Z18: 173.1 | AA18: 8.3 | AB18: 0 | AC18: 6.8 | AD18: 5 | AE18: 41.6 | AF18: 6.1 | AJ18: 111.3 | AK18: 222.2 | AO18: 6.5 | AP18: 362.7 | AQ18: 81.8 | AR18: 0 | AS18: 42.2 | AT18: 18.3 | AU18: 19.8 | AV18: 93.8 | AW18: 127.7 | AX18: 128.5 | AY18: 0 | AZ18: 110.3 | BA18: 7.2 | BB18: 9 | BC18: 44.5 | BD18: 47.9 | BE18: 3.8 | BF18: 31.1 | BG18: 97.7 | BH18: 7.5 | BK18: 47.6 | BO18: 118.8 | BQ18: 0 | BT18: 0 | BY18: 17 | CB18: 49.7 | CC18: 123.1 | CD18: 66.2 | CE18: 82 | CF18: 30.8 | CJ18: 146.3 | CK18: 145.5 | CL18: 148.9 | CT18: 0 | CU18: 85.4 | CV18: 0 | CW18: 0 | CX18: 0 | CY18: 20 | CZ18: 9.9 | DA18: 5.4 | DB18: 3.7 | DC18: 5.2 | DD18: 20.7 | DE18: 20 | DF18: 18.32 | DG18: 3.5 | DH18: 18.7 | DI18: 0 | DJ18: 0 | DK18: 23.9 | DL18: 58.7 | DM18: 4.7 | DN18: 2.4 | DO18: 2.4 | DP18: 2.9 | DQ18: 0 | DR18: 3.5 | DS18: 3.7 | DT18: 2 | DV18: 14.6 | DW18: 9.2 | DX18: 19.2 | DY18: 20.3 | DZ18: 20 | EA18: 21.2 | EB18: 26.4 | EC18: 0 | ED18: 65.1 | EE18: 76.5 | EF18: 4.6 | EG18: 3.5 | EH18: 21 | EI18: 6.7 | EJ18: 7.8 | EK18: 20 | EL18: 20 | EM18: 10 | EN18: 0 | EO18: 0 | EP18: 0 | EQ18: 0.6 | ER18: 36 | ES18: 26.3 | ET18: 0 | EU18: 0 | EV18: 5.5 | EW18: 20 | EX18: 9.6 | EY18: 14.9 | EZ18: 35.5 | FA18: 29.3 | FB18: 3.2 | FC18: 14.3 | FD18: 16.1 | FE18: 7.7 | FF18: 6356.92 | FH18: 24.07265 | FI18: 1.3 | FJ18: 5.104 | FK18: 6.1325 | FL18: 7.8 | FN18: 18.91289 | FO18: 4.9 | FP18: 4.1 | FQ18: 72.32204
A19: 21/01/2025 | B19: 04:30 | C19: 1.1 | D19: 1.6 | E19: 4.3 | F19: 596.2 | G19: 200.9 | J19: 88.3 | K19: 238.6 | N19: 131 | O19: 130.2 | P19: 131.1 | Q19: 230.7 | R19: 208 | S19: 109.6 | T19: 557.7 | U19: 10.3 | Z19: 163.6 | AA19: 6.9 | AB19: 0 | AC19: 6.8 | AD19: 5 | AE19: 40.5 | AF19: 6.3 | AJ19: 109.7 | AK19: 223.4 | AO19: 6.5 | AP19: 443.8 | AQ19: 81.9 | AR19: 0 | AS19: 41.4 | AT19: 18.4 | AU19: 19.9 | AV19: 89.2 | AW19: 122.9 | AX19: 123.4 | AY19: 0 | AZ19: 105.7 | BA19: 7.2 | BB19: 9 | BC19: 41.6 | BD19: 46.5 | BE19: 3.8 | BF19: 31.6 | BG19: 93.4 | BH19: 5.7 | BK19: 47.7 | BO19: 117.1 | BQ19: 0 | BT19: 0 | BY19: 15.5 | CB19: 74.1 | CC19: 128.4 | CD19: 64 | CE19: 80 | CF19: 29.9 | CJ19: 146.6 | CK19: 145.5 | CL19: 148.8 | CT19: 0 | CU19: 83.8 | CV19: 0 | CW19: 1.4 | CX19: 0 | CY19: 20 | CZ19: 9.8 | DA19: 5.5 | DB19: 3.6 | DC19: 5.2 | DD19: 19.8 | DE19: 20 | DF19: 18.37 | DG19: 3.5 | DH19: 18.7 | DI19: 0 | DJ19: 0 | DK19: 23.7 | DL19: 57.5 | DM19: 4.7 | DN19: 2.4 | DO19: 2.4 | DP19: 2.9 | DQ19: 0 | DR19: 3.5 | DS19: 3.2 | DT19: 2 | DV19: 14.6 | DW19: 9.2 | DX19: 19 | DY19: 20.2 | DZ19: 20 | EA19: 23.8 | EB19: 32.1 | EC19: 0 | ED19: 72.9 | EE19: 83.9 | EF19: 3.8 | EG19: 3.3 | EH19: 21 | EI19: 6.6 | EJ19: 7.9 | EK19: 20 | EL19: 20 | EM19: 10 | EN19: 0.1 | EO19: 0 | EP19: 0 | EQ19: 0.6 | ER19: 61.2 | ES19: 44.3 | ET19: 0 | EU19: 0 | EV19: 5.6 | EW19: 20 | EX19: 9.8 | EY19: 15.3 | EZ19: 36 | FA19: 29.3 | FB19: 3.3 | FC19: 14.3 | FD19: 15.5 | FE19: 8.2 | FF19: 6455.07 | FH19: 24.12588 | FI19: 1.3 | FJ19: 3.317 | FK19: 6.13175 | FL19: 7.8 | FN19: 18.91284 | FO19: 4.8 | FP19: 4.1 | FQ19: 70.48747
A20: 21/01/2025 | B20: 05:00 | C20: 1.1 | D20: 1.6 | E20: 4.3 | F20: 599.2 | G20: 201.2 | J20: 90.9 | K20: 239.8 | N20: 129.8 | O20: 129.2 | P20: 129 | Q20: 230.2 | R20: 208.2 | S20: 109.2 | T20: 558.7 | U20: 10.5 | Z20: 166.7 | AA20: 7.7 | AB20: 0 | AC20: 6.8 | AD20: 5 | AE20: 40.9 | AF20: 6.2 | AJ20: 111.2 | AK20: 223.3 | AO20: 6.5 | AP20: 450.7 | AQ20: 81.6 | AR20: 0 | AS20: 42 | AT20: 18.4 | AU20: 19.8 | AV20: 87.2 | AW20: 126.8 | AX20: 126.8 | AY20: 0 | AZ20: 108.2 | BA20: 7.2 | BB20: 9 | BC20: 43.9 | BD20: 47 | BE20: 3.8 | BF20: 30.5 | BG20: 95.6 | BH20: 6.7 | BK20: 47.6 | BO20: 118.5 | BQ20: 0 | BT20: 0 | BY20: 16.4 | CB20: 86.4 | CC20: 131.1 | CD20: 65.1 | CE20: 80.3 | CF20: 30.5 | CJ20: 144.9 | CK20: 144.3 | CL20: 147.4 | CT20: 0 | CU20: 83.4 | CV20: 0 | CW20: 1.3 | CX20: 0 | CY20: 20 | CZ20: 9.9 | DA20: 5.5 | DB20: 3.7 | DC20: 5.2 | DD20: 20.3 | DE20: 20 | DF20: 18.38 | DG20: 3.5 | DH20: 18.7 | DI20: 0 | DJ20: 0 | DK20: 22.8 | DL20: 54.7 | DM20: 4.7 | DN20: 2.4 | DO20: 2.4 | DP20: 3 | DQ20: 0 | DR20: 3.5 | DS20: 3.4 | DT20: 2 | DV20: 15 | DW20: 9.1 | DX20: 19 | DY20: 20.2 | DZ20: 20 | EA20: 25.1 | EB20: 22.9 | EC20: 0 | ED20: 66.9 | EE20: 88.1 | EF20: 4.7 | EG20: 3.7 | EH20: 21 | EI20: 6.6 | EJ20: 8 | EK20: 20 | EL20: 20 | EM20: 10 | EN20: 0 | EO20: 0 | EP20: 0 | EQ20: 0.6 | ER20: 62.4 | ES20: 41.2 | ET20: 0 | EU20: 0 | EV20: 5.4 | EW20: 20 | EX20: 9.6 | EY20: 14.9 | EZ20: 35.5 | FA20: 29.3 | FB20: 3.3 | FC20: 14.3 | FD20: 16.5 | FE20: 7.9 | FF20: 6484.88 | FH20: 24.10548 | FI20: 1.3 | FJ20: 3.43 | FK20: 6.13125 | FL20: 7.8 | FN20: 18.91221 | FO20: 4.7 | FP20: 4.1 | FQ20: 70.47894
A21: 21/01/2025 | B21: 05:30 | C21: 1.1 | D21: 1.6 | E21: 4.3 | F21: 602.1 | G21: 203.7 | J21: 91.8 | K21: 241.2 | N21: 175.4 | O21: 185.1 | P21: 184.6 | Q21: 273.1 | R21: 207.3 | S21: 108.8 | T21: 561.4 | U21: 10.7 | Z21: 168.3 | AA21: 8 | AB21: 0 | AC21: 6.8 | AD21: 5 | AE21: 40.7 | AF21: 5.9 | AJ21: 111.1 | AK21: 224 | AO21: 6.5 | AP21: 302.8 | AQ21: 81.8 | AR21: 0 | AS21: 42.2 | AT21: 18.4 | AU21: 19.8 | AV21: 88.7 | AW21: 148.5 | AX21: 86.1 | AY21: 0 | AZ21: 111 | BA21: 7.4 | BB21: 9 | BC21: 45.7 | BD21: 47.4 | BE21: 3.8 | BF21: 31 | BG21: 96.6 | BH21: 7.1 | BK21: 47.1 | BO21: 118.8 | BQ21: 0 | BT21: 0 | BY21: 16.8 | CB21: 46.4 | CC21: 133.6 | CD21: 65.2 | CE21: 80.6 | CF21: 30.7 | CJ21: 145.1 | CK21: 144.4 | CL21: 147.9 | CT21: 0 | CU21: 81.7 | CV21: 0 | CW21: 2.1 | CX21: 0 | CY21: 20 | CZ21: 10 | DA21: 5.5 | DB21: 3.6 | DC21: 5.2 | DD21: 20.5 | DE21: 20 | DF21: 18.35 | DG21: 3.4 | DH21: 18.7 | DI21: 0.3 | DJ21: 0.1 | DK21: 21.7 | DL21: 60.7 | DM21: 4.7 | DN21: 2.4 | DO21: 2.4 | DP21: 3 | DQ21: 0.7 | DR21: 3.6 | DS21: 3.4 | DT21: 2 | DV21: 15.6 | DW21: 9 | DX21: 19.1 | DY21: 20.2 | DZ21: 20 | EA21: 26.9 | EB21: 18.9 | EC21: 0 | ED21: 63.2 | EE21: 89.2 | EF21: 3.4 | EG21: 2.8 | EH21: 21 | EI21: 6.3 | EJ21: 8.1 | EK21: 20 | EL21: 20 | EM21: 10 | EN21: 0.3 | EO21: 0 | EP21: 0 | EQ21: 0.6 | ER21: 76.1 | ES21: 60.3 | ET21: 0.1 | EU21: 0 | EV21: 5.4 | EW21: 20 | EX21: 8 | EY21: 15.1 | EZ21: 35.7 | FA21: 29.4 | FB21: 3.3 | FC21: 14.5 | FD21: 17.5 | FE21: 8.6 | FF21: 6535.05 | FH21: 24.1065 | FI21: 1.3 | FJ21: 2.964 | FK21: 6.13325 | FL21: 7.8 | FN21: 18.91132 | FO21: 4.8 | FP21: 4.1 | FQ21: 70.11507
A22: 21/01/2025 | B22: 06:00 | C22: 1 | D22: 1.6 | E22: 4.3 | F22: 603.4 | G22: 200.2 | J22: 90.1 | K22: 240 | N22: 175.8 | O22: 201 | P22: 200.8 | Q22: 273.6 | R22: 208.7 | S22: 108.7 | T22: 566.2 | U22: 10.6 | Z22: 162.7 | AA22: 8.3 | AB22: 0 | AC22: 6.8 | AD22: 5 | AE22: 40.7 | AF22: 6 | AJ22: 111 | AK22: 223.6 | AO22: 6.5 | AP22: 307.7 | AQ22: 78.9 | AR22: 0 | AS22: 42.1 | AT22: 18.4 | AU22: 19.8 | AV22: 93.7 | AW22: 180 | AX22: 45.9 | AY22: 0 | AZ22: 110.7 | BA22: 7.7 | BB22: 9 | BC22: 44.6 | BD22: 47.2 | BE22: 3.8 | BF22: 31.2 | BG22: 96.5 | BH22: 6.8 | BK22: 47.5 | BO22: 118.2 | BQ22: 0 | BT22: 0 | BY22: 16.4 | CB22: 52 | CC22: 133.5 | CD22: 64.5 | CE22: 81.6 | CF22: 30.6 | CJ22: 145.6 | CK22: 145.1 | CL22: 148.8 | CT22: 0 | CU22: 69 | CV22: 1.6 | CW22: 0.9 | CX22: 0 | CY22: 20 | CZ22: 9.9 | DA22: 5.3 | DB22: 3.6 | DC22: 5.2 | DD22: 20.5 | DE22: 20 | DF22: 18.37 | DG22: 3.4 | DH22: 18.7 | DI22: 1.2 | DJ22: 0.9 | DK22: 20.3 | DL22: 56.1 | DM22: 4.7 | DN22: 2.4 | DO22: 2.4 | DP22: 3 | DQ22: 2.5 | DR22: 3.6 | DS22: 3.3 | DT22: 2 | DV22: 15.5 | DW22: 9.1 | DX22: 19.4 | DY22: 20.2 | DZ22: 20 | EA22: 28 | EB22: 13.4 | EC22: 2.5 | ED22: 64.5 | EE22: 85.2 | EF22: 3.7 | EG22: 3.4 | EH22: 21 | EI22: 6.2 | EJ22: 8 | EK22: 20 | EL22: 20 | EM22: 10 | EN22: 0 | EO22: 0 | EP22: 2.5 | EQ22: 0.6 | ER22: 66.1 | ES22: 50.7 | ET22: 2.4 | EU22: 0 | EV22: 5.5 | EW22: 20 | EX22: 10 | EY22: 15.1 | EZ22: 35.4 | FA22: 29.4 | FB22: 3.2 | FC22: 14.5 | FD22: 17.2 | FE22: 8.6 | FF22: 6534.57 | FH22: 24.1531 | FI22: 1.3 | FJ22: 2.949 | FK22: 6.13175 | FL22: 7.8 | FN22: 18.91062 | FO22: 4.8 | FP22: 4.1 | FQ22: 70.14447
... A58: 22/01/2025 | B58: 00:00 | C58: 1 | D58: 1.6 | E58: 4.3 | F58: 650.2 | G58: 220.5 | J58: 90.7 | K58: 239.3 | N58: 141.4 | O58: 142.1 | P58: 141.2 | Q58: 235.7 | R58: 204.3 | S58: 108.4 | T58: 563.7 | U58: 10.5 | Z58: 164.9 | AA58: 8.2 | AB58: 0 | AC58: 6.9 | AD58: 5.1 | AE58: 80.8 | AF58: 8.4 | AJ58: 111.4 | AK58: 222.4 | AO58: 6.5 | AP58: 461.2 | AQ58: 78.8 | AR58: 67.9 | AS58: 42 | AT58: 18.4 | AU58: 19.8 | AV58: 96.7 | AW58: 168.5 | AX58: 169.3 | AY58: 182.1 | AZ58: 109 | BA58: 7.9 | BB58: 2.1 | BC58: 44.4 | BD58: 47.3 | BE58: 3.8 | BF58: 31.6 | BG58: 95.1 | BH58: 46.3 | BK58: 47.3 | BO58: 131.5 | BQ58: 0 | BT58: 0 | BY58: 73 | CB58: 42 | CC58: 132.9 | CD58: 63.7 | CE58: 81.2 | CF58: 30.7 | CJ58: 144.6 | CK58: 144 | CL58: 147.7 | CT58: 0 | CU58: 64.9 | CV58: 0 | CW58: 4.8 | CX58: 0 | CY58: 20 | CZ58: 9.9 | DA58: 5.4 | DB58: 3.6 | DC58: 5.2 | DD58: 20.5 | DE58: 20 | DF58: 17.77 | DG58: 3.4 | DH58: 18.7 | DI58: 0 | DJ58: 0 | DK58: 19.3 | DL58: 51.3 | DM58: 4.7 | DN58: 2.4 | DO58: 2.4 | DP58: 2.9 | DQ58: 0 | DR58: 3.6 | DS58: 12.8 | DT58: 2 | DV58: 15.4 | DW58: 8.4 | DX58: 19.9 | DY58: 20.3 | DZ58: 19.9 | EA58: 11.6 | EB58: 42.8 | EC58: 0 | ED58: 43.8 | EE58: 68.9 | EF58: 2.2 | EG58: 1.2 | EH58: 21 | EI58: 6 | EJ58: 7.8 | EK58: 20 | EL58: 20 | EM58: 10 | EN58: 2.1 | EO58: 0 | EP58: 0 | EQ58: 0.6 | ER58: 0.8 | ES58: 1.6 | ET58: 0 | EU58: 0 | EV58: 6 | EW58: 19.9 | EX58: 9.9 | EY58: 14.9 | EZ58: 36 | FA58: 29 | FB58: 3.4 | FC58: 13.6 | FD58: 17.2 | FE58: 7.9 | FF58: 6897.97 | FH58: 24.04072 | FI58: 1.3 | FJ58: 8.005 | FK58: 6.12425 | FL58: 7.8 | FN58: 18.91156 | FO58: 5.7 | FP58: 16 | FQ58: 87.88153
A59: EJEC | C59: 24.55 | D59: 38.1 | E59: 103.2 | F59: 15205.1 | G59: 5134.35 | H59: 0 | I59: 0 | J59: 2158.4 | K59: 5732.3 | L59: 0 | M59: 0 | N59: 3614.3 | O59: 3653.5 | P59: 3657.35 | Q59: 5958.9 | R59: 4897.25 | S59: 2597 | T59: 13401.7 | U59: 252.05 | V59: 0 | W59: 0 | X59: 0 | Y59: 0 | Z59: 3984.45 | AA59: 183.15 | AB59: 240.85 | AC59: 163.9 | AD59: 121.15 | AE59: 1801.45 | AF59: 170.8 | AG59: 0 | AH59: 0 | AI59: 0 | AJ59: 1997.45 | AK59: 5275.15 | AL59: 0 | AM59: 0 | AN59: 0 | AO59: 156 | AP59: 10536.25 | AQ59: 1846.6 | AR59: 1126.4 | AS59: 1000.85 | AT59: 440.75 | AU59: 475.45 | AV59: 2176.85 | AW59: 4003.8 | AX59: 3690.9 | AY59: 3372 | AZ59: 2609.25 | BA59: 188.95 | BB59: 151.45 | BC59: 1031.2 | BD59: 1126.05 | BE59: 89.3 | BF59: 751.25 | BG59: 3138.85 | BH59: 1069.2 | BI59: 0 | BJ59: 0 | BK59: 1126.05 | BL59: 0 | BM59: 0 | BN59: 0 | BO59: 3070.9 | BP59: 0 | BQ59: 1818.95 | BR59: 0 | BS59: 0 | BT59: 164.9 | BU59: 0 | BV59: 0 | BW59: 0 | BX59: 0 | BY59: 1733.2 | BZ59: 0 | CA59: 0 | CB59: 2761.7 | CC59: 3090.35 | CD59: 1524.95 | CE59: 1943.4 | CF59: 731.45 | CG59: 0 | CH59: 0 | CI59: 0 | CJ59: 3458.35 | CK59: 3436.6 | CL59: 3538 | CM59: 0 | CN59: 0 | CO59: 0 | CP59: 0 | CQ59: 0 | CR59: 0 | CS59: 0 | CT59: 5.05 | CU59: 2080.4 | CV59: 503.9 | CW59: 59.75 | CX59: 1.95 | CY59: 479.85 | CZ59: 237.75 | DA59: 128.55 | DB59: 86.15 | DC59: 124.05 | DD59: 484.55 | DE59: 479.95 | DF59: 437.035 | DG59: 82.6 | DH59: 448.8 | DI59: 100.9 | DJ59: 122.1 | DK59: 521.2 | DL59: 1462.8 | DM59: 110.9 | DN59: 56.1 | DO59: 57.4 | DP59: 67.6 | DQ59: 145.5 | DR59: 85.15 | DS59: 285.4 | DT59: 46.25 | DU59: 0 | DV59: 360.7 | DW59: 206.35 | DX59: 476.9 | DY59: 485.45 | DZ59: 478.85 | EA59: 443.55 | EB59: 1002.6 | EC59: 240 | ED59: 1457.65 | EE59: 1766.25 | EF59: 147.15 | EG59: 129.35 | EH59: 503.9 | EI59: 160.6 | EJ59: 192.4 | EK59: 450 | EL59: 437.5 | EM59: 222.25 | EN59: 42.55 | EO59: 102.7 | EP59: 1109.4 | EQ59: 14.4 | ER59: 1362.25 | ES59: 1269.7 | ET59: 922.55 | EU59: 117.9 | EV59: 140.1 | EW59: 479 | EX59: 240.15 | EY59: 359.15 | EZ59: 857.2 | FA59: 694.1 | FB59: 82.3 | FC59: 331.15 | FD59: 408.2 | FE59: 159.85 | FF59: 174302.29 | FH59: 578.7329 | FI59: 31.2 | FJ59: 129.6705 | FK59: 139.174 | FL59: 185.7 | FM59: 0 | FN59: 451.25068 | FO59: 118.8 | FP59: 187.9 | FQ59: 1822.4281

Sheet REACTIVA
B3: martes, 21 de Enero del 2025
A5: POTENCIA REACTIVA EJECUTADA DE LAS UNIDADES DE GENERACIÓN DEL COES (MVAR) | FH5: CENTRALES NO INTEGRANTES COES
A6: FECHA | B6: HORA | C6: 337 | D6: 338 | E6: 121 | F6: 101 | G6: 102 | H6: 42667 | I6: 42668 | J6: 126 | K6: 127 | L6: 138 | M6: 139 | N6: 197 | O6: 203 | P6: 204 | Q6: 230 | R6: 209 | S6: 56677 | T6: 796 | U6: 2146 | V6: 142 | W6: 143 | X6: 125 | Y6: 187 | Z6: 163 | AA6: 298 | AB6: 219 | AC6: 151 | AD6: 152 | AE6: 153 | AF6: 154 | AG6: 756 | AH6: 156 | AI6: 155 | AJ6: 182 | AK6: 212 | AL6: 758 | AM6: 263 | AN6: 265 | AO6: 775 | AP6: 777 | AQ6: 2154 | AR6: 150 | AS6: 149 | AT6: 188 | AU6: 2131 | AV6: 755 | AW6: 252 | AX6: 249 | AY6: 250 | AZ6: 117 | BA6: 267 | BB6: 268 | BC6: 119 | BD6: 120 | BE6: 189 | BF6: 122 | BG6: 266 | BH6: 251 | BI6: 115 | BJ6: 239 | BK6: 288 | BL6: 240 | BM6: 241 | BN6: 242 | BO6: 191 | BP6: 194 | BQ6: 196 | BR6: 207 | BS6: 236 | BT6: 795 | BU6: 285 | BV6: 995 | BW6: 996 | BX6: 997 | BY6: 766 | BZ6: 926 | CA6: 924 | CB6: 103 | CC6: 104 | CD6: 106 | CE6: 105 | CF6: 107 | CG6: 110 | CH6: 109 | CI6: 144 | CJ6: 113 | CK6: 114 | CL6: 193 | CM6: 208 | CN6: 786 | CO6: 787 | CP6: 788 | CQ6: 789 | CR6: 248 | CS6: 2159 | CT6: 303 | CU6: 59715 | CV6: 62255 | CW6: 1263 | CX6: 61800 | CY6: 2194 | CZ6: 216 | DA6: 198 | DB6: 214 | DC6: 260 | DD6: 2152 | DE6: 2128 | DF6: 247 | DG6: 228 | DH6: 2135 | DI6: 261 | DJ6: 237 | DK6: 253 | DL6: 770 | DM6: 225 | DN6: 2201 | DO6: 2171 | DP6: 760 | DQ6: 235 | DR6: 238 | DS6: 2184 | DT6: 61855 | DU6: 223 | DV6: 226 | DW6: 201 | DX6: 258 | DY6: 259 | DZ6: 920 | EA6: 257 | EB6: 256 | EC6: 2148 | ED6: 58288 | EE6: 58289 | EF6: 58839 | EG6: 58840 | EH6: 296 | EI6: 297 | EJ6: 211 | EK6: 2175 | EL6: 2178 | EM6: 2181 | EN6: 1262 | EO6: 233 | EP6: 2150 | EQ6: 2165 | ER6: 2161 | ES6: 61197 | ET6: 58851 | EU6: 234 | EV6: 215 | EW6: 917 | EX6: 289 | EY6: 58333 | EZ6: 58336 | FA6: 202 | FB6: 58487 | FC6: 213 | FD6: 232 | FE6: 2190 | FF6: TOTAL COES | FH6: 221 | FI6: 49607 | FJ6: 222 | FK6: 224 | FL6: 2187 | FM6: 227 | FN6: 49400 | FO6: 199 | FP6: 200 | FQ6: TOTAL NO COES
C7: CENTRO | D7: CENTRO | E7: NORTE | F7: CENTRO | G7: CENTRO | H7: NORTE | I7: NORTE | J7: NORTE | K7: NORTE | L7: CENTRO | M7: CENTRO | N7: CENTRO | O7: CENTRO | P7: CENTRO | Q7: CENTRO | R7: CENTRO | S7: CENTRO | T7: CENTRO | U7: CENTRO | V7: CENTRO | W7: CENTRO | X7: CENTRO | Y7: CENTRO | Z7: SUR | AA7: SUR | AB7: CENTRO | AC7: SUR | AD7: SUR | AE7: SUR | AF7: SUR | AG7: SUR | AH7: SUR | AI7: SUR | AJ7: SUR | AK7: CENTRO | AL7: NORTE | AM7: NORTE | AN7: NORTE | AO7: CENTRO | AP7: CENTRO | AQ7: CENTRO | AR7: CENTRO | AS7: CENTRO | AT7: CENTRO | AU7: CENTRO | AV7: SUR | AW7: CENTRO | AX7: CENTRO | AY7: CENTRO | AZ7: CENTRO | BA7: CENTRO | BB7: CENTRO | BC7: CENTRO | BD7: CENTRO | BE7: SUR | BF7: NORTE | BG7: CENTRO | BH7: CENTRO | BI7: NORTE | BJ7: NORTE | BK7: NORTE | BL7: SUR | BM7: SUR | BN7: SUR | BO7: CENTRO | BP7: CENTRO | BQ7: CENTRO | BR7: CENTRO | BS7: CENTRO | BT7: CENTRO | BU7: CENTRO | BV7: SUR | BW7: SUR | BX7: SUR | BY7: NORTE | BZ7: SUR | CA7: CENTRO | CB7: CENTRO | CC7: CENTRO | CD7: CENTRO | CE7: CENTRO | CF7: CENTRO | CG7: CENTRO | CH7: CENTRO | CI7: CENTRO | CJ7: CENTRO | CK7: CENTRO | CL7: CENTRO | CM7: CENTRO | CN7: SUR | CO7: SUR | CP7: SUR | CQ7: SUR | CR7: CENTRO | CS7: CENTRO | CT7: CENTRO | CU7: CENTRO | CV7: SUR | CW7: NORTE | CX7: NORTE | CY7: NORTE | CZ7: NORTE | DA7: NORTE | DB7: CENTRO | DC7: CENTRO | DD7: CENTRO | DE7: NORTE | DF7: NORTE | DG7: CENTRO | DH7: CENTRO | DI7: SUR | DJ7: SUR | DK7: CENTRO | DL7: CENTRO | DM7: CENTRO | DN7: CENTRO | DO7: CENTRO | DP7: CENTRO | DQ7: SUR | DR7: CENTRO | DS7: CENTRO | DT7: NORTE | DU7: CENTRO | DV7: CENTRO | DW7: NORTE | DX7: CENTRO | DY7: CENTRO | DZ7: CENTRO | EA7: NORTE | EB7: NORTE | EC7: SUR | ED7: CENTRO | EE7: CENTRO | EF7: CENTRO | EG7: CENTRO | EH7: CENTRO | EI7: CENTRO | EJ7: SUR | EK7: SUR | EL7: SUR | EM7: SUR | EN7: NORTE | EO7: SUR | EP7: SUR | EQ7: CENTRO | ER7: CENTRO | ES7: CENTRO | ET7: SUR | EU7: SUR | EV7: NORTE | EW7: CENTRO | EX7: NORTE | EY7: NORTE | EZ7: NORTE | FA7: CENTRO | FB7: CENTRO | FC7: CENTRO | FD7: NORTE | FE7: NORTE | FH7: NORTE | FI7: SUR | FJ7: CENTRO | FK7: NORTE | FL7: NORTE | FM7: NORTE | FN7: NORTE | FO7: NORTE | FP7: NORTE
C8: HIDROELÉCTRICA | D8: HIDROELÉCTRICA | E8: HIDROELÉCTRICA | F8: HIDROELÉCTRICA | G8: HIDROELÉCTRICA | H8: TERMOELÉCTRICA | I8: TERMOELÉCTRICA | J8: HIDROELÉCTRICA | K8: HIDROELÉCTRICA | L8: TERMOELÉCTRICA | M8: TERMOELÉCTRICA | N8: TERMOELÉCTRICA | O8: TERMOELÉCTRICA | P8: TERMOELÉCTRICA | Q8: TERMOELÉCTRICA | R8: TERMOELÉCTRICA | S8: TERMOELÉCTRICA | T8: HIDROELÉCTRICA | U8: HIDROELÉCTRICA | V8: TERMOELÉCTRICA | W8: TERMOELÉCTRICA | X8: TERMOELÉCTRICA | Y8: TERMOELÉCTRICA | Z8: HIDROELÉCTRICA | AA8: HIDROELÉCTRICA | AB8: TERMOELÉCTRICA | AC8: HIDROELÉCTRICA | AD8: HIDROELÉCTRICA | AE8: HIDROELÉCTRICA | AF8: HIDROELÉCTRICA | AG8: TERMOELÉCTRICA | AH8: TERMOELÉCTRICA | AI8: TERMOELÉCTRICA | AJ8: HIDROELÉCTRICA | AK8: HIDROELÉCTRICA | AL8: TERMOELÉCTRICA | AM8: TERMOELÉCTRICA | AN8: TERMOELÉCTRICA | AO8: HIDROELÉCTRICA | AP8: HIDROELÉCTRICA | AQ8: HIDROELÉCTRICA | AR8: HIDROELÉCTRICA | AS8: HIDROELÉCTRICA | AT8: HIDROELÉCTRICA | AU8: HIDROELÉCTRICA | AV8: HIDROELÉCTRICA | AW8: TERMOELÉCTRICA | AX8: TERMOELÉCTRICA | AY8: TERMOELÉCTRICA | AZ8: HIDROELÉCTRICA | BA8: HIDROELÉCTRICA | BB8: HIDROELÉCTRICA | BC8: HIDROELÉCTRICA | BD8: HIDROELÉCTRICA | BE8: HIDROELÉCTRICA | BF8: HIDROELÉCTRICA | BG8: HIDROELÉCTRICA | BH8: HIDROELÉCTRICA | BI8: TERMOELÉCTRICA | BJ8: TERMOELÉCTRICA | BK8: TERMOELÉCTRICA | BL8: TERMOELÉCTRICA | BM8: TERMOELÉCTRICA | BN8: TERMOELÉCTRICA | BO8: HIDROELÉCTRICA | BP8: TERMOELÉCTRICA | BQ8: TERMOELÉCTRICA | BR8: TERMOELÉCTRICA | BS8: TERMOELÉCTRICA | BT8: TERMOELÉCTRICA | BU8: TERMOELÉCTRICA | BV8: TERMOELÉCTRICA | BW8: TERMOELÉCTRICA | BX8: TERMOELÉCTRICA | BY8: HIDROELÉCTRICA | BZ8: TERMOELÉCTRICA | CA8: TERMOELÉCTRICA | CB8: HIDROELÉCTRICA | CC8: HIDROELÉCTRICA | CD8: HIDROELÉCTRICA | CE8: HIDROELÉCTRICA | CF8: HIDROELÉCTRICA | CG8: TERMOELÉCTRICA | CH8: TERMOELÉCTRICA | CI8: TERMOELÉCTRICA | CJ8: TERMOELÉCTRICA | CK8: TERMOELÉCTRICA | CL8: TERMOELÉCTRICA | CM8: TERMOELÉCTRICA | CN8: TERMOELÉCTRICA | CO8: TERMOELÉCTRICA | CP8: TERMOELÉCTRICA | CQ8: TERMOELÉCTRICA | CR8: TERMOELÉCTRICA | CS8: TERMOELÉCTRICA | CT8: SOLAR | CU8: EÓLICA | CV8: SOLAR | CW8: EÓLICA | CX8: SOLAR | CY8: HIDROELÉCTRICA | CZ8: HIDROELÉCTRICA | DA8: HIDROELÉCTRICA | DB8: HIDROELÉCTRICA | DC8: HIDROELÉCTRICA | DD8: HIDROELÉCTRICA | DE8: HIDROELÉCTRICA | DF8: HIDROELÉCTRICA | DG8: HIDROELÉCTRICA | DH8: HIDROELÉCTRICA | DI8: SOLAR | DJ8: SOLAR | DK8: EÓLICA | DL8: EÓLICA | DM8: TERMOELÉCTRICA | DN8: TERMOELÉCTRICA | DO8: TERMOELÉCTRICA | DP8: TERMOELÉCTRICA | DQ8: SOLAR | DR8: HIDROELÉCTRICA | DS8: HIDROELÉCTRICA | DT8: HIDROELÉCTRICA | DU8: HIDROELÉCTRICA | DV8: HIDROELÉCTRICA | DW8: HIDROELÉCTRICA | DX8: HIDROELÉCTRICA | DY8: HIDROELÉCTRICA | DZ8: HIDROELÉCTRICA | EA8: EÓLICA | EB8: EÓLICA | EC8: SOLAR | ED8: EÓLICA | EE8: EÓLICA | EF8: EÓLICA | EG8: EÓLICA | EH8: HIDROELÉCTRICA | EI8: HIDROELÉCTRICA | EJ8: HIDROELÉCTRICA | EK8: HIDROELÉCTRICA | EL8: HIDROELÉCTRICA | EM8: HIDROELÉCTRICA | EN8: EÓLICA | EO8: SOLAR | EP8: SOLAR | EQ8: HIDROELÉCTRICA | ER8: EÓLICA | ES8: EÓLICA | ET8: SOLAR | EU8: SOLAR | EV8: HIDROELÉCTRICA | EW8: HIDROELÉCTRICA | EX8: TERMOELÉCTRICA | EY8: TERMOELÉCTRICA | EZ8: TERMOELÉCTRICA | FA8: TERMOELÉCTRICA | FB8: TERMOELÉCTRICA | FC8: TERMOELÉCTRICA | FD8: TERMOELÉCTRICA | FE8: TERMOELÉCTRICA | FH8: HIDROELÉCTRICA | FI8: HIDROELÉCTRICA | FJ8: HIDROELÉCTRICA | FK8: HIDROELÉCTRICA | FL8: HIDROELÉCTRICA | FM8: TERMOELÉCTRICA | FN8: TERMOELÉCTRICA | FO8: HIDROELÉCTRICA | FP8: HIDROELÉCTRICA
