Workbook

Sheet EVENTOS
B3: miércoles, 9 de Abril del 2025
B5: INFORMACIÓN DE EVENTOS PRINCIPALES EN SUS INSTALACIONES
B6: TIPO DE EVENTO | C6: EMPRESA | D6: UBICACIÓN | E6: TIPO DE EQUIPO | F6: EQUIPO | G6: INICIO | H6: FINAL | I6: DESCRIPCIÓN | J6: MW INDISP. | K6: INTERRUPCIÓN (SI/NO) | L6: TENSIÓN DE FALLA (kV)
B7: EVENTO | C7: CONCESIONARIA LINEA DE TRANSMISION CCNCM S.A.C. | D7: CACLIC - BELAUNDE TERRY | E7: LINEA DE TRANSMISION | F7: L-2194 | G7: 09/04/2025 10:16:00 | H7: 09/04/2025 10:16:00 | I7: RECIERRE EXITOSO EN LA LÍNEA L-2194 (CACLIC - BELAUNDE TERRY) DE 220 KV | K7: NO
B8: EVENTO | C8: CONELSUR LT SAC | D8: PORTILLO | E8: SUBESTACION | F8: SS.EE. | G8: 09/04/2025 00:00:00 | H8: 10/04/2025 00:00:00 | I8: DECLARACIÓN DE SITUACIÓN EXCEPCIONAL EN LA S.E. PORTILLO DE 60 kV | K8: NO
B9: FALLA | C9: ELECTRO DUNAS | D9: ICA - SANTA MARGARITA | E9: LINEA DE TRANSMISION | F9: L-6624 | G9: 09/04/2025 11:50:41 | H9: 09/04/2025 12:03:56 | I9: DESCONEXIÓN DE LA LÍNEA L-6624 (ICA-SANTA MARGARITA) DE 60 KV | J9: 16.7 | K9: SI | L9: 60
B10: FALLA | C10: EMPRESA ELECTRICA AGUA AZUL | D10: POTRERO | E10: GENERADOR HIDROELÉCTRICO | F10: G2 | G10: 09/04/2025 23:51:10 | H10: 10/04/2025 01:15:23 | I10: DESCONEXIÓN DEL GRUPO G2 DE LA C.H. POTRERO | K10: NO | L10: 10
B11: EVENTO | C11: RED DE ENERGIA DEL PERU S.A. | D11: TINGO MARÍA - AUCAYACU | E11: LINEA DE TRANSMISION | F11: L-1122 | G11: 09/04/2025 10:54:00 | H11: 09/04/2025 16:57:00 | I11: DECLARACIÓN DE SITUACIÓN EXCEPCIONAL EN LA LÍNEA L-1122 (TINGO MARÍA - AUCAYACU) DE 138 kV | K11: NO
B12: EVENTO | C12: RED DE ENERGIA DEL PERU S.A. | D12: TINGO MARÍA - AUCAYACU | E12: LINEA DE TRANSMISION | F12: L-1122 | G12: 09/04/2025 18:30:00 | H12: 09/04/2025 20:54:00 | I12: DECLARACIÓN DE SITUACIÓN EXCEPCIONAL EN LA LÍNEA L-1122 (TINGO MARÍA - AUCAYACU) DE 138 kV | K12: NO
B13: EVENTO | C13: RED DE ENERGIA DEL PERU S.A. | D13: ZORRITOS - MACHALA | E13: LINEA DE TRANSMISION | F13: L-2280_old | G13: 09/04/2025 08:56:00 | H13: 09/04/2025 16:02:00 | I13: IMPORTACIÓN DE ENERGÍA DE ECUADOR | K13: NO
B14: EVENTO | C14: ATLANTICA TRANSMISION SUR S.A. | D14: POROMA - OCONA | E14: LINEA DE TRANSMISION | F14: L-5034 | G14: 09/04/2025 00:00:00 | H14: 09/04/2025 07:00:00 | I14: DECLARACIÓN DE SITUACION EXCEPCIONAL EN EL ENLACE CENTRO - SUR | K14: NO
B15: EVENTO | C15: ATLANTICA TRANSMISION SUR S.A. | D15: POROMA - OCONA | E15: LINEA DE TRANSMISION | F15: L-5034 | G15: 09/04/2025 16:45:00 | H15: 10/04/2025 00:00:00 | I15: DECLARACIÓN DE SITUACION EXCEPCIONAL EN EL ENLACE CENTRO - SUR | K15: NO

Sheet RESTRIC_OPE
B3: miércoles, 9 de Abril del 2025
B5: RESTRICCIONES OPERATIVAS
B6: FECHA | C6: HORA INICIO | D6: HORA FINAL | E6: EMPRESA | F6: UBICACIÓN | G6: T.Eq. | H6: EQUIPO | I6: DESCRIPCIÓN
B7: 09/04/2025 | C7: 00:00 | D7: 24:00 | E7: CELEPSA | F7: C.H. EL PLATANAL | G7: CH | H7: CENTRAL | I7: Debido al incremento del caudal del rio cañete y establecimiento de la temporada de avenida, se declara la C.H. El Platanal como CENTRAL HIDRÁULICA DE PASADA (correo 03/01/2025).
B8: 09/04/2025 | C8: 00:00 | D8: 24:00 | E8: EGASA | F8: C.H. CHARCANI II | G8: GH | H8: G2 | I8: El Grupo N°02 esta operando con una potencia no mayor a 0.07MW en referencia a 0.18MW de su potencia efectiva, con el fin de no generar daños mayores hasta la reparación de su cojinete.
B9: 09/04/2025 | C9: 00:00 | D9: 24:00 | E9: EGASA | F9: S.E. CONVERTIDOR | G9: BARRA | H9: BARRA138KV | I9: EGASA limitó la capacidad del transformador 138 kV/33 kV a 50 MVA por deterioro del aislamiento.
B10: 09/04/2025 | C10: 00:00 | D10: 24:00 | E10: ENEL GENERACION PIURA S.A. | F10: C.T. MALACAS | G10: CT | H10: CENTRAL | I10: De acuerdo con la comunicación vía correo del día 24.10.2024. ENEL GENERACIÓN PIURA informa una restricción de potencia para alcanzar 105 MW en simultaneo (TG6+TGN4).
B11: 09/04/2025 | C11: 00:00 | D11: 24:00 | E11: ENGIE | F11: C.E. PUNTA LOMITAS | G11: CE | H11: CENTRAL | I11: De acuerdo a la carta ENG/737-2024 (Exp:202400007555). Limitación de cables de media tensión a 100 MW de los transformadores PLT1 y PLT2 de la CE Punta Lomitas. Quedan limitados a 200 MW la generación de CE Punta Lomitas y Punta Lomitas Extensión.
B12: 09/04/2025 | C12: 00:00 | D12: 24:00 | E12: ENGIE | F12: C.H. QUITARACSA | G12: CH | H12: CENTRAL | I12: De acuerdo con el correo del 23.04 se considera la operación continua de la CH Quitaracsa debido a que el sistema de refrigeración de la CH Cañón del Pato se alimenta desde la descarga del caudal turbinado por la CH Quitaracsa.
B13: 09/04/2025 | C13: 00:00 | D13: 24:00 | E13: ENGIE | F13: C.H. YUNCÁN | G13: GH | H13: G3 | I13: Según la carta N° ENG/ 198-2024 enviada por su representada, se opera de forma continua el G3 de la CH Yuncán, debido a la ejecución de mantenimientos necesarios para evitar daños en los sellos de seguridad de la válvula esférica del grupo.
B14: 09/04/2025 | C14: 00:00 | D14: 24:00 | E14: ENGIE | F14: C.T. CHILCA 1 | G14: CT | H14: CENTRAL | I14: Con carta ENG/971-2023, indica que no puede cumplir con las IO considerada en el PDO_17122023 dado que vulneran la seguridad de sus activos. Indican que se debe tomar TMO=168h.
B15: 09/04/2025 | C15: 00:00 | D15: 24:00 | E15: ENGIE | F15: C.T. CHILCA 1 | G15: CT | H15: CENTRAL | I15: Restricción de temperatura de la C.T Chilca, ver valor en el modelo de despacho.
B16: 09/04/2025 | C16: 00:00 | D16: 24:00 | E16: ENGIE | F16: C.T. CHILCA 2 | G16: CT | H16: CENTRAL | I16: Con carta ENG/971-2023, indica que no puede cumplir con las IO considerada en el PDO_17122023 dado que vulneran la seguridad de sus activos. Indican que se debe tomar TMO=168h.
B17: 09/04/2025 | C17: 00:00 | D17: 24:00 | E17: ENGIE | F17: C.T. CHILCA 2 | G17: CT | H17: CENTRAL | I17: Restricción de temperatura de la C.T Chilca2, ver valor en el modelo de despacho.
... B50: 09/04/2025 | C50: 00:00 | D50: 24:00 | E50: TRANSMANTARO | F50: S.E. SOCABAYA | G50: SSEE | H50: S.E. | I50: Opera en simple barra en 220 kV por indisponibilidad de la protección diferencial de barras por alarma.

Sheet MANTENIMIENTO EJECUTADOS
B3: miércoles, 9 de Abril del 2025
B5: Mantenimiento Ejecutado
B6: Empresa | C6: Ubicación | D6: Equipo | E6: Inicio | F6: Final | G6: Descripción | H6: MW Indisp. | I6: Prog. | J6: Dispon | K6: Interrupc. | L6: Tipo | M6: CodEq | N6: TipoEq_Osinerg
B7: AGROAURORA S.A.C. | C7: MAPLE ETANOL | D7: CENTRAL | E7: 09/04/2025 00:00 | F7: 10/04/2025 00:00 | G7: CENTRAL TERMOELECTRICA FUERA DE SERVICIO POR FALTA DE MATERIA PRIMA PARA LOS REQUERIMIENTOS DE CALOR UTIL EN FABRICA. | H7: 14 | I7: P | J7: F/S | K7: N | L7: OTROS | M7: 13417 | N7: G
B8: AGROAURORA S.A.C. | C8: MAPLE ETANOL | D8: CENTRAL | E8: 09/04/2025 00:00 | F8: 10/04/2025 00:00 | G8: MANTENIMIENTO PREVENTIVO PROGRAMADO DE LA CENTRAL TERMOELECTRICA Y EQUIPOS AUXILIARES. | H8: 14 | I8: P | J8: F/S | K8: N | L8: PREV. | M8: 13417 | N8: G
B9: AGROINDUSTRIAS SAN JACINTO S.A.A. | C9: SAN JACINTO | D9: CENTRAL | E9: 09/04/2025 00:00 | F9: 10/04/2025 00:00 | G9: Mantenimiento Anual. | H9: 8.15 | I9: P | J9: F/S | K9: N | L9: PREV. | M9: 19865 | N9: G
B10: ATLANTICA TRANSMISION SUR S.A. | C10: CHILCA-CTM | D10: INT-5261 | E10: 09/04/2025 00:00 | F10: 10/04/2025 00:00 | G10: Seccionador SBB-5261 fase S indisponible para maniobras de apertura y cierre por anomalia en tapa de tanque de compresion, el seccionador permanece cerrado y bloqueado. | H10: 0 | I10: P | J10: E/S | K10: N | L10: OTROS | M10: 13854 | N10: T
B11: ATLANTICA TRANSMISION SUR S.A. | C11: MONTALVO | D11: ACOPLE 220 | E11: 09/04/2025 00:00 | F11: 10/04/2025 00:00 | G11: Proyecto Refuerzos: Reemplazo del HMI existente, Pruebas y Configuracion. No se contara con nivel 1 de operacion. | H11: 0 | I11: P | J11: E/S | K11: N | L11: P.ENERG | M11: 14767 | N11: T
B12: ATLANTICA TRANSMISION SUR S.A. | C12: MONTALVO | D12: CL-2057 | E12: 09/04/2025 00:00 | F12: 10/04/2025 00:00 | G12: Proyecto Refuerzos: Reemplazo del HMI existente, Pruebas y Configuracion. No se contara con nivel 1 de operacion. | H12: 0 | I12: P | J12: E/S | K12: N | L12: P.ENERG | M12: 13812 | N12: T
B13: ATLANTICA TRANSMISION SUR S.A. | C13: MONTALVO | D13: CL-AUT-5671_500 | E13: 09/04/2025 00:00 | F13: 10/04/2025 00:00 | G13: Proyecto Refuerzos: Reemplazo del HMI existente, Pruebas y Configuracion. No se contara con nivel 1 de operacion en INT-5671, INT-5652 y SAT-5671. | H13: 0 | I13: P | J13: E/S | K13: N | L13: P.ENERG | M13: 13809 | N13: T
B14: ATLANTICA TRANSMISION SUR S.A. | C14: MONTALVO | D14: INT-5652 | E14: 09/04/2025 00:00 | F14: 10/04/2025 00:00 | G14: Proyecto Refuerzos:Indisponible por Implementacion de conexion de corrientes, disparos, posiciones, enclavamientos hacia los equipos del nuevos Autotransformador. AUT-5671 en servicio solo por Barra A 500kV. | H14: 0 | I14: P | J14: F/S | K14: N | L14: P.ENERG | M14: 13765 | N14: T
B15: ATLANTICA TRANSMISION SUR S.A. | C15: OCONA | D15: INT-5450 | E15: 09/04/2025 00:00 | F15: 10/04/2025 00:00 | G15: Interruptor INT-5450 cerrado con restriccion operativa, REB-5450 en servicio y suministrando los SS.AA. de la S.E. Oco?a. | H15: 0 | I15: P | J15: E/S | K15: N | L15: OTROS | M15: 13761 | N15: T
B16: ATLANTICA TRANSMISION SUR S.A. | C16: OCONA | D16: INT-5462 | E16: 09/04/2025 00:00 | F16: 10/04/2025 00:00 | G16: Seccionador SBA-5462 fase T indisponible por problemas mecanicos, el seccionador permanece cerrado y bloqueado | H16: 0 | I16: P | J16: E/S | K16: N | L16: OTROS | M16: 13758 | N16: T
B17: ATLANTICA TRANSMISION SUR S.A. | C17: POROMA | D17: ACOPLE 220 | E17: 09/04/2025 00:00 | F17: 10/04/2025 00:00 | G17: Proyecto Refuerzos: Reemplazo del HMI existente, Pruebas y Configuracion. No se contara con nivel 1 de operacion. | H17: 0 | I17: P | J17: E/S | K17: N | L17: P.ENERG | M17: 13797 | N17: T
B18: ATLANTICA TRANSMISION SUR S.A. | C18: POROMA | D18: CL-2292 | E18: 09/04/2025 00:00 | F18: 10/04/2025 00:00 | G18: Proyecto Refuerzos: Reemplazo del HMI existente, Pruebas y Configuracion. No se contara con nivel 1 de operacion. | H18: 0 | I18: P | J18: E/S | K18: N | L18: P.ENERG | M18: 13798 | N18: T
... B168: TRANSMISORA ELECTRICA DEL SUR 4 S.A.C. - TESUR 4 | C168: PUMIRI | D168: BARRA A -220kV | E168: 09/04/2025 08:30 | F168: 09/04/2025 17:30 | G168: Solicitado por la empresa HYDRO GLOBAL para realizar revisiones y pruebas finales de envio de se?ales 87B Respaldo. Deshabilitacion de la proteccion diferencial. | H168: 0 | I168: R | J168: E/S | K168: N | L168: OTROS | M168: 22359 | N168: T

Sheet INGRESO OC
A3: miércoles, 9 de Abril del 2025
A5: INGRESO A OPERACIÓN COMERCIAL
A6: EMPRESA | B6: TIPO DE EQUIPO | C6: UBICACIÓN | D6: EQUIPO | E6: Fecha y hora de Ingreso a Operación Comercial

Sheet DESPACHO_EJECUTADO
B3: miércoles, 9 de Abril del 2025
A5: POTENCIA ACTIVA EJECUTADA DE LAS UNIDADES DE GENERACIÓN DEL SEIN (MW) | FK5: CENTRALES NO INTEGRANTES COES
A6: FECHA | B6: HORA | C6: 337 | D6: 338 | E6: 101 | F6: 102 | G6: 42667 | H6: 42668 | I6: 126 | J6: 127 | K6: 138 | L6: 139 | M6: 197 | N6: 203 | O6: 204 | P6: 230 | Q6: 209 | R6: 56677 | S6: 796 | T6: 2146 | U6: 142 | V6: 143 | W6: 125 | X6: 187 | Y6: 163 | Z6: 298 | AA6: 299 | AB6: 219 | AC6: 151 | AD6: 152 | AE6: 153 | AF6: 154 | AG6: 756 | AH6: 156 | AI6: 155 | AJ6: 182 | AK6: 212 | AL6: 758 | AM6: 263 | AN6: 265 | AO6: 775 | AP6: 777 | AQ6: 2154 | AR6: 150 | AS6: 149 | AT6: 188 | AU6: 2131 | AV6: 755 | AW6: 252 | AX6: 249 | AY6: 250 | AZ6: 117 | BA6: 267 | BB6: 268 | BC6: 119 | BD6: 120 | BE6: 189 | BF6: 122 | BG6: 266 | BH6: 251 | BI6: 115 | BJ6: 239 | BK6: 288 | BL6: 240 | BM6: 241 | BN6: 242 | BO6: 191 | BP6: 194 | BQ6: 196 | BR6: 207 | BS6: 236 | BT6: 795 | BU6: 285 | BV6: 995 | BW6: 996 | BX6: 997 | BY6: 766 | BZ6: 926 | CA6: 924 | CB6: 121 | CC6: 103 | CD6: 104 | CE6: 106 | CF6: 105 | CG6: 107 | CH6: 110 | CI6: 109 | CJ6: 144 | CK6: 113 | CL6: 114 | CM6: 193 | CN6: 208 | CO6: 786 | CP6: 787 | CQ6: 788 | CR6: 789 | CS6: 248 | CT6: 2159 | CU6: 303 | CV6: 59715 | CW6: 62255 | CX6: 1263 | CY6: 63425 | CZ6: 61800 | DA6: 2194 | DB6: 216 | DC6: 198 | DD6: 49607 | DE6: 214 | DF6: 260 | DG6: 2152 | DH6: 2128 | DI6: 247 | DJ6: 228 | DK6: 2135 | DL6: 261 | DM6: 237 | DN6: 253 | DO6: 770 | DP6: 225 | DQ6: 2201 | DR6: 2171 | DS6: 760 | DT6: 235 | DU6: 238 | DV6: 2184 | DW6: 61855 | DX6: 223 | DY6: 226 | DZ6: 201 | EA6: 258 | EB6: 259 | EC6: 920 | ED6: 257 | EE6: 256 | EF6: 2148 | EG6: 58288 | EH6: 58289 | EI6: 58839 | EJ6: 58840 | EK6: 296 | EL6: 297 | EM6: 211 | EN6: 2175 | EO6: 2178 | EP6: 2181 | EQ6: 1262 | ER6: 233 | ES6: 2150 | ET6: 2165 | EU6: 2161 | EV6: 61197 | EW6: 58851 | EX6: 234 | EY6: 215 | EZ6: 917 | FA6: 289 | FB6: 58333 | FC6: 58336 | FD6: 202 | FE6: 58487 | FF6: 213 | FG6: 232 | FH6: 2190 | FI6: TOTAL COES | FK6: 221 | FL6: 222 | FM6: 224 | FN6: 2187 | FO6: 227 | FP6: 49400 | FQ6: 199 | FR6: 200 | FS6: TOTAL NO COES
C7: CENTRO | D7: CENTRO | E7: CENTRO | F7: CENTRO | G7: NORTE | H7: NORTE | I7: NORTE | J7: NORTE | K7: CENTRO | L7: CENTRO | M7: CENTRO | N7: CENTRO | O7: CENTRO | P7: CENTRO | Q7: CENTRO | R7: CENTRO | S7: CENTRO | T7: CENTRO | U7: CENTRO | V7: CENTRO | W7: CENTRO | X7: CENTRO | Y7: SUR | Z7: SUR | AA7: SUR | AB7: CENTRO | AC7: SUR | AD7: SUR | AE7: SUR | AF7: SUR | AG7: SUR | AH7: SUR | AI7: SUR | AJ7: SUR | AK7: CENTRO | AL7: NORTE | AM7: NORTE | AN7: NORTE | AO7: CENTRO | AP7: CENTRO | AQ7: CENTRO | AR7: CENTRO | AS7: CENTRO | AT7: CENTRO | AU7: CENTRO | AV7: SUR | AW7: CENTRO | AX7: CENTRO | AY7: CENTRO | AZ7: CENTRO | BA7: CENTRO | BB7: CENTRO | BC7: CENTRO | BD7: CENTRO | BE7: SUR | BF7: NORTE | BG7: CENTRO | BH7: CENTRO | BI7: NORTE | BJ7: NORTE | BK7: NORTE | BL7: SUR | BM7: SUR | BN7: SUR | BO7: CENTRO | BP7: CENTRO | BQ7: CENTRO | BR7: CENTRO | BS7: CENTRO | BT7: CENTRO | BU7: CENTRO | BV7: SUR | BW7: SUR | BX7: SUR | BY7: NORTE | BZ7: SUR | CA7: CENTRO | CB7: NORTE | CC7: CENTRO | CD7: CENTRO | CE7: CENTRO | CF7: CENTRO | CG7: CENTRO | CH7: CENTRO | CI7: CENTRO | CJ7: CENTRO | CK7: CENTRO | CL7: CENTRO | CM7: CENTRO | CN7: CENTRO | CO7: SUR | CP7: SUR | CQ7: SUR | CR7: SUR | CS7: CENTRO | CT7: CENTRO | CU7: CENTRO | CV7: CENTRO | CW7: SUR | CX7: NORTE | CY7: SUR | CZ7: NORTE | DA7: NORTE | DB7: NORTE | DC7: NORTE | DD7: SUR | DE7: CENTRO | DF7: CENTRO | DG7: CENTRO | DH7: NORTE | DI7: NORTE | DJ7: CENTRO | DK7: CENTRO | DL7: SUR | DM7: SUR | DN7: CENTRO | DO7: CENTRO | DP7: CENTRO | DQ7: CENTRO | DR7: CENTRO | DS7: CENTRO | DT7: SUR | DU7: CENTRO | DV7: CENTRO | DW7: NORTE | DX7: CENTRO | DY7: CENTRO | DZ7: NORTE | EA7: CENTRO | EB7: CENTRO | EC7: CENTRO | ED7: NORTE | EE7: NORTE | EF7: SUR | EG7: CENTRO | EH7: CENTRO | EI7: CENTRO | EJ7: CENTRO | EK7: CENTRO | EL7: CENTRO | EM7: SUR | EN7: SUR | EO7: SUR | EP7: SUR | EQ7: NORTE | ER7: SUR | ES7: SUR | ET7: CENTRO | EU7: CENTRO | EV7: CENTRO | EW7: SUR | EX7: SUR | EY7: NORTE | EZ7: CENTRO | FA7: NORTE | FB7: NORTE | FC7: NORTE | FD7: CENTRO | FE7: CENTRO | FF7: CENTRO | FG7: NORTE | FH7: NORTE | FK7: NORTE | FL7: CENTRO | FM7: NORTE | FN7: NORTE | FO7: NORTE | FP7: NORTE | FQ7: NORTE | FR7: NORTE
C8: HIDROELÉCTRICA | D8: HIDROELÉCTRICA | E8: HIDROELÉCTRICA | F8: HIDROELÉCTRICA | G8: TERMOELÉCTRICA | H8: TERMOELÉCTRICA | I8: HIDROELÉCTRICA | J8: HIDROELÉCTRICA | K8: TERMOELÉCTRICA | L8: TERMOELÉCTRICA | M8: TERMOELÉCTRICA | N8: TERMOELÉCTRICA | O8: TERMOELÉCTRICA | P8: TERMOELÉCTRICA | Q8: TERMOELÉCTRICA | R8: TERMOELÉCTRICA | S8: HIDROELÉCTRICA | T8: HIDROELÉCTRICA | U8: TERMOELÉCTRICA | V8: TERMOELÉCTRICA | W8: TERMOELÉCTRICA | X8: TERMOELÉCTRICA | Y8: HIDROELÉCTRICA | Z8: HIDROELÉCTRICA | AA8: HIDROELÉCTRICA | AB8: TERMOELÉCTRICA | AC8: HIDROELÉCTRICA | AD8: HIDROELÉCTRICA | AE8: HIDROELÉCTRICA | AF8: HIDROELÉCTRICA | AG8: TERMOELÉCTRICA | AH8: TERMOELÉCTRICA | AI8: TERMOELÉCTRICA | AJ8: HIDROELÉCTRICA | AK8: HIDROELÉCTRICA | AL8: TERMOELÉCTRICA | AM8: TERMOELÉCTRICA | AN8: TERMOELÉCTRICA | AO8: HIDROELÉCTRICA | AP8: HIDROELÉCTRICA | AQ8: HIDROELÉCTRICA | AR8: HIDROELÉCTRICA | AS8: HIDROELÉCTRICA | AT8: HIDROELÉCTRICA | AU8: HIDROELÉCTRICA | AV8: HIDROELÉCTRICA | AW8: TERMOELÉCTRICA | AX8: TERMOELÉCTRICA | AY8: TERMOELÉCTRICA | AZ8: HIDROELÉCTRICA | BA8: HIDROELÉCTRICA | BB8: HIDROELÉCTRICA | BC8: HIDROELÉCTRICA | BD8: HIDROELÉCTRICA | BE8: HIDROELÉCTRICA | BF8: HIDROELÉCTRICA | BG8: HIDROELÉCTRICA | BH8: HIDROELÉCTRICA | BI8: TERMOELÉCTRICA | BJ8: TERMOELÉCTRICA | BK8: TERMOELÉCTRICA | BL8: TERMOELÉCTRICA | BM8: TERMOELÉCTRICA | BN8: TERMOELÉCTRICA | BO8: HIDROELÉCTRICA | BP8: TERMOELÉCTRICA | BQ8: TERMOELÉCTRICA | BR8: TERMOELÉCTRICA | BS8: TERMOELÉCTRICA | BT8: TERMOELÉCTRICA | BU8: TERMOELÉCTRICA | BV8: TERMOELÉCTRICA | BW8: TERMOELÉCTRICA | BX8: TERMOELÉCTRICA | BY8: HIDROELÉCTRICA | BZ8: TERMOELÉCTRICA | CA8: TERMOELÉCTRICA | CB8: HIDROELÉCTRICA | CC8: HIDROELÉCTRICA | CD8: HIDROELÉCTRICA | CE8: HIDROELÉCTRICA | CF8: HIDROELÉCTRICA | CG8: HIDROELÉCTRICA | CH8: TERMOELÉCTRICA | CI8: TERMOELÉCTRICA | CJ8: TERMOELÉCTRICA | CK8: TERMOELÉCTRICA | CL8: TERMOELÉCTRICA | CM8: TERMOELÉCTRICA | CN8: TERMOELÉCTRICA | CO8: TERMOELÉCTRICA | CP8: TERMOELÉCTRICA | CQ8: TERMOELÉCTRICA | CR8: TERMOELÉCTRICA | CS8: TERMOELÉCTRICA | CT8: TERMOELÉCTRICA | CU8: SOLAR | CV8: EÓLICA | CW8: SOLAR | CX8: EÓLICA | CY8: SOLAR | CZ8: SOLAR | DA8: HIDROELÉCTRICA | DB8: HIDROELÉCTRICA | DC8: HIDROELÉCTRICA | DD8: HIDROELÉCTRICA | DE8: HIDROELÉCTRICA | DF8: HIDROELÉCTRICA | DG8: HIDROELÉCTRICA | DH8: HIDROELÉCTRICA | DI8: HIDROELÉCTRICA | DJ8: HIDROELÉCTRICA | DK8: HIDROELÉCTRICA | DL8: SOLAR | DM8: SOLAR | DN8: EÓLICA | DO8: EÓLICA | DP8: TERMOELÉCTRICA | DQ8: TERMOELÉCTRICA | DR8: TERMOELÉCTRICA | DS8: TERMOELÉCTRICA | DT8: SOLAR | DU8: HIDROELÉCTRICA | DV8: HIDROELÉCTRICA | DW8: HIDROELÉCTRICA | DX8: HIDROELÉCTRICA | DY8: HIDROELÉCTRICA | DZ8: HIDROELÉCTRICA | EA8: HIDROELÉCTRICA | EB8: HIDROELÉCTRICA | EC8: HIDROELÉCTRICA | ED8: EÓLICA | EE8: EÓLICA | EF8: SOLAR | EG8: EÓLICA | EH8: EÓLICA | EI8: EÓLICA | EJ8: EÓLICA | EK8: HIDROELÉCTRICA | EL8: HIDROELÉCTRICA | EM8: HIDROELÉCTRICA | EN8: HIDROELÉCTRICA | EO8: HIDROELÉCTRICA | EP8: HIDROELÉCTRICA | EQ8: EÓLICA | ER8: SOLAR | ES8: SOLAR | ET8: HIDROELÉCTRICA | EU8: EÓLICA | EV8: EÓLICA | EW8: SOLAR | EX8: SOLAR | EY8: HIDROELÉCTRICA | EZ8: HIDROELÉCTRICA | FA8: TERMOELÉCTRICA | FB8: TERMOELÉCTRICA | FC8: TERMOELÉCTRICA | FD8: TERMOELÉCTRICA | FE8: TERMOELÉCTRICA | FF8: TERMOELÉCTRICA | FG8: TERMOELÉCTRICA | FH8: TERMOELÉCTRICA | FK8: HIDROELÉCTRICA | FL8: HIDROELÉCTRICA | FM8: HIDROELÉCTRICA | FN8: HIDROELÉCTRICA | FO8: TERMOELÉCTRICA | FP8: TERMOELÉCTRICA | FQ8: HIDROELÉCTRICA | FR8: HIDROELÉCTRICA
C9: CENTRALES SANTA ROSA S.A.C. | D9: CENTRALES SANTA ROSA S.A.C. | E9: ELECTROPERU | F9: ELECTROPERU | G9: ELECTROPERU | H9: ELECTROPERU | I9: ORAZUL ENERGY PERÚ | J9: ORAZUL ENERGY PERÚ | K9: TERMOSELVA | L9: TERMOSELVA | M9: KALLPA GENERACION S.A. | N9: KALLPA GENERACION S.A. | O9: KALLPA GENERACION S.A. | P9: KALLPA GENERACION S.A. | Q9: KALLPA GENERACION S.A. | R9: KALLPA GENERACION S.A. | S9: KALLPA GENERACION S.A. | T9: KALLPA GENERACION S.A. | U9: SHOUGESA | V9: SHOUGESA | W9: SHOUGESA | X9: SHOUGESA | Y9: EGEMSA | Z9: EGESUR | AA9: EGESUR | AB9: EGESUR | AC9: EGASA | AD9: EGASA | AE9: EGASA | AF9: EGASA | AG9: EGASA | AH9: EGASA | AI9: EGASA | AJ9: SAN GABAN | AK9: CELEPSA | AL9: MINERA CERRO VERDE | AM9: PLANTA DE RESERVA FRIA DE GENERACION DE ETEN S.A. | AN9: PLANTA DE RESERVA FRIA DE GENERACION DE ETEN S.A. | AO9: EMPRESA DE GENERACION HUALLAGA | AP9: EMPRESA DE GENERACION HUALLAGA | AQ9: LA VIRGEN | AR9: CHINANGO S.A.C. | AS9: CHINANGO S.A.C. | AT9: HIDROELECTRICA HUANCHOR S.A.C. | AU9: CELEPSA RENOVABLES S.R.L. | AV9: INLAND ENERGY SAC | AW9: FENIX POWER PERÚ | AX9: FENIX POWER PERÚ | AY9: FENIX POWER PERÚ | AZ9: STATKRAFT S.A | BA9: STATKRAFT S.A | BB9: STATKRAFT S.A | BC9: STATKRAFT S.A | BD9: STATKRAFT S.A | BE9: STATKRAFT S.A | BF9: STATKRAFT S.A | BG9: STATKRAFT S.A | BH9: EMPRESA DE GENERACION HUANZA | BI9: ENEL GENERACION PIURA S.A. | BJ9: ENEL GENERACION PIURA S.A. | BK9: ENEL GENERACION PIURA S.A. | BL9: ENGIE | BM9: ENGIE | BN9: ENGIE | BO9: ENGIE | BP9: ENGIE | BQ9: ENGIE | BR9: ENGIE | BS9: ENGIE | BT9: ENGIE | BU9: ENGIE | BV9: ENGIE | BW9: ENGIE | BX9: ENGIE | BY9: ENGIE | BZ9: INFRAESTRUCTURAS Y ENERGIAS DEL PERU S.A.C. | CA9: INFRAESTRUCTURAS Y ENERGIAS DEL PERU S.A.C. | CB9: INVERSIONES SHAQSHA S.A.C. | CC9: ORYGEN PERU S.A.A. | CD9: ORYGEN PERU S.A.A. | CE9: ORYGEN PERU S.A.A. | CF9: ORYGEN PERU S.A.A. | CG9: ORYGEN PERU S.A.A. | CH9: ORYGEN PERU S.A.A. | CI9: ORYGEN PERU S.A.A. | CJ9: ORYGEN PERU S.A.A. | CK9: ORYGEN PERU S.A.A. | CL9: ORYGEN PERU S.A.A. | CM9: ORYGEN PERU S.A.A. | CN9: ORYGEN PERU S.A.A. | CO9: SAMAY I S.A.C | CP9: SAMAY I S.A.C | CQ9: SAMAY I S.A.C | CR9: SAMAY I S.A.C | CS9: TERMOCHILCA S.A.C. | CT9: TERMOCHILCA S.A.C. | CU9: COLCA SOLAR S.A.C. | CV9: ENERGIA RENOVABLE DEL SUR S.A. | CW9: GR CORTARRAMA SOCIEDAD ANONIMA CERRADA | CX9: GR TARUCA SOCIEDAD ANONIMA CERRADA | CY9: JOYA SOLAR S.A.C. | CZ9: KONDU SAC | DA9: PERUANA DE INVERSIONES EN ENERGIAS RENOVABLES S.A. | DB9: ORAZUL ENERGY PERÚ | DC9: ORAZUL ENERGY PERÚ | DD9: SAN GABAN | DE9: MAJA ENERGIA S.A.C. | DF9: EMPRESA DE GENERACION ELECTRICA CANCHAYLLO SAC | DG9: EMPRESA DE GENERACION ELECTRICA SANTA ANA S.A.C. | DH9: EMPRESA ELECTRICA AGUA AZUL | DI9: EMPRESA ELECTRICA RIO DOBLE | DJ9: HIDROCAÑETE S.A. | DK9: HUAURA POWER GROUP S.A. | DL9: MOQUEGUA FV S.A.C. | DM9: PANAMERICANA SOLAR SAC. | DN9: PARQUE EOLICO MARCONA S.A.C. | DO9: PARQUE EOLICO TRES HERMANAS S.A.C. | DP9: PETRAMAS | DQ9: PETRAMAS | DR9: PETRAMAS | DS9: PETRAMAS | DT9: TACNA SOLAR SAC. | DU9: ELECTRICA YANAPAMPA SAC | DV9: ANDEAN POWER S.A.C. | DW9: ASOCIACIÓN SANTA LUCIA DE CHACAS | DX9: ATRIA ENERGIA S.A.C. | DY9: EGEJUNIN | DZ9: EGEJUNIN | EA9: EGEJUNIN | EB9: EGEJUNIN | EC9: EMPRESA DE GENERACION ELECTRICA RIO BAÑOS S.A.C. | ED9: ENERGÍA EÓLICA S.A. | EE9: ENERGÍA EÓLICA S.A. | EF9: ENGIE | EG9: ENGIE | EH9: ENGIE | EI9: ENGIE | EJ9: ENGIE | EK9: GENERACIÓN ANDINA S.A.C. | EL9: GENERACIÓN ANDINA S.A.C. | EM9: GENERADORA DE ENERGÍA DEL PERÚ | EN9: GENERADORA DE ENERGÍA DEL PERÚ | EO9: GENERADORA DE ENERGÍA DEL PERÚ | EP9: GENERADORA DE ENERGÍA DEL PERÚ | EQ9: GR PAINO SOCIEDAD ANONIMA CERRADA | ER9: MAJES ARCUS S.A.C. | ES9: ORYGEN PERU S.A.A. | ET9: ORYGEN PERU S.A.A. | EU9: ORYGEN PERU S.A.A. | EV9: ORYGEN PERU S.A.A. | EW9: ORYGEN PERU S.A.A. | EX9: REPARTICIÓN ARCUS S.A.C. | EY9: SINERSA | EZ9: SINERSA | FA9: BIOENERGIA DEL CHIRA S.A. | FB9: GM OPERACIONES S.A.C. | FC9: GM OPERACIONES S.A.C. | FD9: SDF ENERGIA SAC | FE9: SDF ENERGIA SAC | FF9: AGRO INDUSTRIAL PARAMONGA S.A. | FG9: AGROAURORA S.A.C. | FH9: AGROINDUSTRIAS SAN JACINTO S.A.A. | FK9: UNACEM PERU S.A. | FL9: ELECTRO ORIENTE | FM9: AGUAS Y ENERGIA PERU | FN9: ELECTRO ZAÑA S.A.C. | FO9: ELECTRONOROESTE S.A. | FP9: SDE PIURA | FQ9: SINERSA | FR9: SINERSA
C10: SANTA ROSA 1 | D10: SANTA ROSA 2 | E10: MANTARO | F10: RESTITUCION | G10: TUMBES MAK 1 | H10: TUMBES MAK 2 | I10: CARHUAQUERO | J10: CAÑON DEL PATO | K10: AGUAYTIA TG1 | L10: AGUAYTIA TG2 | M10: KALLPA TG1 | N10: KALLPA TG2 | O10: KALLPA TG3 | P10: KALLPA TV | Q10: LFLORES TG1 | R10: LFLORES TV | S10: CERRO DEL AGUILA | T10: CERRODELAGUILAG4 | U10: SHOUGESA TV1 | V10: SHOUGESA TV2 | W10: SHOUGESA TV3 | X10: SHOUGESA CUMMINS | Y10: MACHUPICCHU | Z10: ARICOTA 1 | AA10: ARICOTA 2 | AB10: INDEPENDENCIA | AC10: CHARCANI I,II,III | AD10: CHARCANI IV | AE10: CHARCANI V | AF10: CHARCANI VI | AG10: CHILINA TG | AH10: MOLLENDO 1, 2, 3 | AI10: CHILINA (SULZ 1,2) | AJ10: SAN GABAN II | AK10: PLATANAL | AL10: RECKA | AM10: RF ETEN TG1 | AN10: RF ETEN TG2 | AO10: CHAGLLA GP1 | AP10: CHAGLLA | AQ10: LA VIRGEN | AR10: CHIMAY | AS10: YANANGO | AT10: HUANCHOR | AU10: MARAÑON | AV10: STA TERESA | AW10: FENIX GT11 | AX10: FENIX GT12 | AY10: FENIX TV10 | AZ10: YAUPI | BA10: OROYA | BB10: PACHACHACA | BC10: MALPASO | BD10: CAHUA | BE10: ARCATA | BF10: GALLITO CIEGO | BG10: CHEVES | BH10: HUANZA | BI10: MALACAS2 TG4 | BJ10: MALACAS3 TG 5 | BK10: MALACAS1 TG6 | BL10: RF ILO2 TG1 | BM10: RF ILO2 TG2 | BN10: RF ILO2 TG3 | BO10: YUNCAN | BP10: CHILCA1 TG1 | BQ10: CHILCA1 TG2 | BR10: CHILCA1 TG3 | BS10: CHILCA-TV | BT10: CHILCA2 TG41 | BU10: CHILCA2-TV | BV10: CTNEPI_TG41 | BW10: CTNEPI_TG42 | BX10: CTNEPI_TG43 | BY10: QUITARACSA | BZ10: RF PTO MALDONADO | CA10: RF PUCALLPA | CB10: PARIAC | CC10: HUINCO | CD10: MATUCANA | CE10: MOYOPAMPA | CF10: CALLAHUANCA | CG10: HUAMPANI | CH10: STA ROSA WEST TG7 | CI10: UTI_5 | CJ10: UTI_6 | CK10: VENTANILLA 3 | CL10: VENTANILLA 4 | CM10: VENTANILLA TV | CN10: STAROSA TG8 | CO10: PTO_BRVO TG1 | CP10: PTO_BRVO TG2 | CQ10: PTO_BRVO TG3 | CR10: PTO_BRVO TG4 | CS10: OLLEROS TG1 | CT10: OLLEROS TV | CU10: CS YARUCAYA | CV10: SAN JUAN | CW10: MATARANI | CX10: DUNA | CY10: SAN MARTIN SOLAR | CZ10: CARHUAQUERO (CS) | DA10: MANTA I | DB10: CARHUAQUERO4 | DC10: CAÑA BRAVA | DD10: TUPURI | DE10: RONCADOR | DF10: CANCHAYLLO | DG10: RENOVANDESH1 | DH10: POTRERO | DI10: PIZARRAS | DJ10: NIMPERIAL | DK10: YARUCAYA | DL10: MOQUEGUA-SOLAR | DM10: PANAMERICANA-SOLAR | DN10: PQE-EOLICO-MARCONA | DO10: PQE-EOLICO-3-HERMANAS | DP10: HUAYCOLORO | DQ10: CALLAO | DR10: DONA_CATALINA | DS10: LAGRINGAV | DT10: TACNA-SOLAR | DU10: YANAPAMPA | DV10: CARHUAC | DW10: HUALLIN | DX10: PURMACANA | DY10: HUASAHUASI | DZ10: STACRUZ_1_2 | EA10: RUNATULLO_II | EB10: RUNATULLO_III | EC10: RUCUY | ED10: PQE-EOLICO-TALARA | EE10: PQE-EOLICO-CUPISNIQUE | EF10: INTIPAMPA | EG10: PUNTA LOMITAS-BL1 | EH10: PUNTA LOMITAS-BL2 | EI10: PUN LOMITAS_EXP-BL1 | EJ10: PUN LOMITAS_EXP-BL2 | EK10: 8AGOSTO | EL10: EL CARMEN | EM10: LA JOYA | EN10: ANGEL_I | EO10: ANGEL_II | EP10: ANGEL_III | EQ10: HUAMBOS | ER10: MAJES | ES10: RUBI | ET10: CH_HER1 | EU10: WAYRA-I | EV10: WAYRA EXTENSION | EW10: CLEMESI | EX10: REPARTICION | EY10: POECHOS2 | EZ10: CHANCAY | FA10: CANA BRAVA | FB10: REFINERIA TALARA TV1 | FC10: REFINERÍA TALARA TV2 | FD10: OQUENDO TG1 | FE10: OQUENDO TV1 | FF10: PARAMONGA | FG10: MAPLE | FH10: SAN_JACINTO | FI10: MW | FK10: CARPAPATA | FL10: CENTRALES ELOR | FM10: PIAS1 | FN10: ZANA | FO10: TABLAZO | FP10: TALLANCA | FQ10: CURUMUY | FR10: POECHOS1 | FS10: MW
A11: 09/04/2025 | B11: 00:30 | E11: 550.2 | F11: 178.7 | I11: 90.9 | J11: 239.3 | M11: 105.4 | N11: 105.5 | O11: 105.4 | P11: 208.2 | Q11: 108.7 | R11: 66.9 | S11: 562.7 | T11: 10.6 | Y11: 166.5 | Z11: 8.3 | AA11: 3.7 | AB11: 0 | AC11: 6.5 | AD11: 10.1 | AE11: 143.3 | AF11: 8.9 | AJ11: 111 | AK11: 214 | AO11: 6.5 | AP11: 335.8 | AQ11: 5 | AR11: 149.6 | AS11: 42.4 | AT11: 18.5 | AU11: 19.7 | AV11: 89.6 | AZ11: 65.6 | BA11: 0 | BB11: 9.2 | BC11: 46.3 | BD11: 42.5 | BE11: 3.8 | BF11: 36.6 | BG11: 169.2 | BH11: 94.9 | BK11: 0 | BO11: 86.7 | BP11: 0 | BR11: 139.1 | BS11: 67.8 | BT11: 0 | CB11: 4.6 | CC11: 267.6 | CD11: 133.3 | CE11: 63.3 | CF11: 79.4 | CG11: 30.2 | CK11: 102.7 | CL11: 102.5 | CM11: 118.2 | CS11: 191.8 | CT11: 102.9 | CU11: 0 | CV11: 81.5 | CW11: 0 | CX11: 10.2 | CZ11: 0 | DA11: 20 | DB11: 10.5 | DC11: 5.4 | DD11: 1.2 | DE11: 1.7 | DF11: 4.9 | DG11: 20.2 | DH11: 20 | DI11: 18.8 | DJ11: 3.5 | DK11: 9.3 | DL11: 0 | DM11: 0 | DN11: 26.2 | DO11: 51.6 | DP11: 4.4 | DQ11: 2.4 | DR11: 2.4 | DT11: 0 | DU11: 2.9 | DV11: 20.2 | DW11: 3 | DY11: 17.4 | DZ11: 9.8 | EA11: 20.3 | EB11: 20.3 | EC11: 20 | ED11: 13.6 | EE11: 35.1 | EF11: 0 | EG11: 30.7 | EH11: 74.6 | EI11: 2.1 | EJ11: 1.6 | EK11: 21 | EL11: 6.9 | EM11: 7.4 | EN11: 20.4 | EO11: 20.4 | EP11: 20.2 | EQ11: 7.3 | ER11: 0 | ES11: 0 | ET11: 0.6 | EU11: 74 | EV11: 58.3 | EW11: 0 | EX11: 0 | EY11: 7.9 | EZ11: 20 | FB11: 43.7 | FC11: 0 | FD11: 29 | FE11: 3.3 | FF11: 16.4 | FI11: 6552.7 | FK11: 24.4391 | FL11: 7.895 | FN11: 13.2 | FP11: 9.44018 | FQ11: 10.5 | FR11: 15.1 | FS11: 80.57428
A12: 09/04/2025 | B12: 01:00 | E12: 546.4 | F12: 179.7 | I12: 90 | J12: 236.9 | M12: 105.9 | N12: 104.3 | O12: 106 | P12: 206.7 | Q12: 108.2 | R12: 66.9 | S12: 552.3 | T12: 10.5 | Y12: 164.2 | Z12: 8.1 | AA12: 3.5 | AB12: 0 | AC12: 6.5 | AD12: 10.1 | AE12: 142.7 | AF12: 8.9 | AJ12: 111 | AK12: 185.4 | AO12: 6.5 | AP12: 296.5 | AQ12: 5 | AR12: 133.3 | AS12: 42.4 | AT12: 18.5 | AU12: 19.7 | AV12: 90.7 | AZ12: 64.6 | BA12: 0 | BB12: 9.2 | BC12: 45.2 | BD12: 42.1 | BE12: 3.8 | BF12: 35.8 | BG12: 168.4 | BH12: 94.4 | BK12: 0 | BO12: 86.6 | BP12: 0 | BR12: 139.4 | BS12: 67.8 | BT12: 0 | CB12: 4.6 | CC12: 227.9 | CD12: 120.5 | CE12: 63.1 | CF12: 77.3 | CG12: 30.2 | CK12: 102.4 | CL12: 102.1 | CM12: 118.6 | CS12: 191.8 | CT12: 103 | CU12: 0 | CV12: 87.9 | CW12: 0 | CX12: 9.1 | CZ12: 0 | DA12: 20 | DB12: 10.4 | DC12: 5.4 | DD12: 1.2 | DE12: 1.7 | DF12: 4.8 | DG12: 20.2 | DH12: 20 | DI12: 18.8 | DJ12: 3.6 | DK12: 9.3 | DL12: 0 | DM12: 0 | DN12: 26.2 | DO12: 57.9 | DP12: 4.4 | DQ12: 2.4 | DR12: 2.4 | DT12: 0 | DU12: 2.9 | DV12: 20.3 | DW12: 3 | DY12: 17.5 | DZ12: 9.8 | EA12: 20.1 | EB12: 20.3 | EC12: 20 | ED12: 18.6 | EE12: 34.7 | EF12: 0 | EG12: 33.6 | EH12: 66.5 | EI12: 2.9 | EJ12: 2.4 | EK12: 21 | EL12: 6.9 | EM12: 7.4 | EN12: 20.4 | EO12: 20.4 | EP12: 20.2 | EQ12: 6.2 | ER12: 0 | ES12: 0 | ET12: 0.6 | EU12: 37.7 | EV12: 26.1 | EW12: 0 | EX12: 0 | EY12: 7.8 | EZ12: 20 | FB12: 43.9 | FC12: 0 | FD12: 29 | FE12: 3.2 | FF12: 16.5 | FI12: 6331.2 | FK12: 24.43857 | FL12: 7.884 | FN12: 13.2 | FP12: 9.43985 | FQ12: 10.4 | FR12: 15.1 | FS12: 80.46242
A13: 09/04/2025 | B13: 01:30 | E13: 548.5 | F13: 178.4 | I13: 91.7 | J13: 237.4 | M13: 107.2 | N13: 107.1 | O13: 105.6 | P13: 209 | Q13: 109.7 | R13: 66.6 | S13: 561.4 | T13: 10.5 | Y13: 167 | Z13: 7.5 | AA13: 3.4 | AB13: 0 | AC13: 6.5 | AD13: 10.1 | AE13: 143.1 | AF13: 8.9 | AJ13: 110.5 | AK13: 154.3 | AO13: 6.5 | AP13: 296.1 | AQ13: 5 | AR13: 137.2 | AS13: 42.4 | AT13: 18.5 | AU13: 19.7 | AV13: 92.2 | AZ13: 66.3 | BA13: 0 | BB13: 9.2 | BC13: 46.5 | BD13: 41.9 | BE13: 3.8 | BF13: 36.9 | BG13: 167.2 | BH13: 95.4 | BK13: 0 | BO13: 86.2 | BP13: 0 | BR13: 140.3 | BS13: 67.2 | BT13: 0 | CB13: 4.6 | CC13: 216.4 | CD13: 121.2 | CE13: 62.8 | CF13: 77.7 | CG13: 30.2 | CK13: 103.9 | CL13: 103.6 | CM13: 118.8 | CS13: 191.8 | CT13: 103 | CU13: 0 | CV13: 90.5 | CW13: 0 | CX13: 13.7 | CZ13: 0 | DA13: 19.9 | DB13: 10.6 | DC13: 5.4 | DD13: 1.2 | DE13: 1.7 | DF13: 4.8 | DG13: 20.1 | DH13: 20 | DI13: 18.8 | DJ13: 3.5 | DK13: 9.3 | DL13: 0 | DM13: 0 | DN13: 25.1 | DO13: 61.5 | DP13: 4.4 | DQ13: 2.4 | DR13: 2.4 | DT13: 0 | DU13: 3 | DV13: 20.3 | DW13: 3 | DY13: 17.4 | DZ13: 9.7 | EA13: 20.1 | EB13: 20.3 | EC13: 19.9 | ED13: 18.8 | EE13: 33.4 | EF13: 0 | EG13: 32.4 | EH13: 65 | EI13: 3.1 | EJ13: 3 | EK13: 21 | EL13: 6.9 | EM13: 7.4 | EN13: 20.4 | EO13: 20.4 | EP13: 20.2 | EQ13: 11.3 | ER13: 0 | ES13: 0 | ET13: 0.6 | EU13: 15.4 | EV13: 10.2 | EW13: 0 | EX13: 0 | EY13: 7.8 | EZ13: 20 | FB13: 44.1 | FC13: 0 | FD13: 29 | FE13: 3.2 | FF13: 16.6 | FI13: 6296.1 | FK13: 24.43701 | FL13: 1.689 | FN13: 13.2 | FP13: 9.43948 | FQ13: 10.5 | FR13: 15 | FS13: 74.26549
A14: 09/04/2025 | B14: 02:00 | E14: 535.2 | F14: 177.9 | I14: 88.8 | J14: 234 | M14: 105.9 | N14: 105.3 | O14: 105.6 | P14: 208 | Q14: 109.1 | R14: 67.1 | S14: 540.3 | T14: 10.3 | Y14: 161.8 | Z14: 6.7 | AA14: 3 | AB14: 0 | AC14: 6.5 | AD14: 10.1 | AE14: 141.3 | AF14: 9 | AJ14: 108.9 | AK14: 166.3 | AO14: 6.5 | AP14: 288.6 | AQ14: 5 | AR14: 120.3 | AS14: 42.2 | AT14: 18.5 | AU14: 19.7 | AV14: 86.1 | AZ14: 63.1 | BA14: 0 | BB14: 9.2 | BC14: 44.4 | BD14: 41.6 | BE14: 3.8 | BF14: 34.5 | BG14: 164 | BH14: 93 | BK14: 0 | BO14: 85.1 | BP14: 0 | BR14: 139.5 | BS14: 67.2 | BT14: 0 | CB14: 4.6 | CC14: 162.5 | CD14: 106.4 | CE14: 61.2 | CF14: 76.6 | CG14: 29.4 | CK14: 102.7 | CL14: 101.9 | CM14: 118.8 | CS14: 191.8 | CT14: 102.9 | CU14: 0 | CV14: 90.7 | CW14: 0 | CX14: 15.4 | CZ14: 0 | DA14: 20 | DB14: 10.4 | DC14: 5.3 | DD14: 1.2 | DE14: 1.7 | DF14: 4.8 | DG14: 19.8 | DH14: 20 | DI14: 18.8 | DJ14: 3.6 | DK14: 9.3 | DL14: 0 | DM14: 0 | DN14: 23.5 | DO14: 64.3 | DP14: 4.4 | DQ14: 2.4 | DR14: 2.4 | DT14: 0 | DU14: 2.8 | DV14: 20.3 | DW14: 3 | DY14: 17.4 | DZ14: 9.8 | EA14: 20.1 | EB14: 20.2 | EC14: 19.9 | ED14: 20.7 | EE14: 27.9 | EF14: 0 | EG14: 47.4 | EH14: 87.7 | EI14: 5.9 | EJ14: 1.7 | EK14: 21 | EL14: 6.8 | EM14: 7.4 | EN14: 20.4 | EO14: 20.4 | EP14: 20.2 | EQ14: 13.2 | ER14: 0 | ES14: 0 | ET14: 0.6 | EU14: 5.1 | EV14: 4.9 | EW14: 0 | EX14: 0 | EY14: 7.9 | EZ14: 20 | FB14: 44.8 | FC14: 0 | FD14: 29 | FE14: 3.1 | FF14: 16.7 | FI14: 6156.5 | FK14: 24.43744 | FL14: 0 | FN14: 13.2 | FP14: 9.43905 | FQ14: 10.4 | FR14: 15.1 | FS14: 72.57649
A15: 09/04/2025 | B15: 02:30 | E15: 445.1 | F15: 146.1 | I15: 89.6 | J15: 236.1 | M15: 105.8 | N15: 105.1 | O15: 105.5 | P15: 207.3 | Q15: 109 | R15: 67.2 | S15: 557 | T15: 10.5 | Y15: 164.8 | Z15: 7.2 | AA15: 3.2 | AB15: 0 | AC15: 6.4 | AD15: 10.1 | AE15: 142.8 | AF15: 8.9 | AJ15: 110.3 | AK15: 199.5 | AO15: 6.5 | AP15: 308.7 | AQ15: 5 | AR15: 137.5 | AS15: 42.4 | AT15: 18.5 | AU15: 19.7 | AV15: 88.2 | AZ15: 31.9 | BA15: 0 | BB15: 9.2 | BC15: 45.2 | BD15: 41.9 | BE15: 3.8 | BF15: 35.3 | BG15: 166.5 | BH15: 94 | BK15: 0 | BO15: 86 | BP15: 0 | BR15: 139 | BS15: 68.1 | BT15: 0 | CB15: 4.6 | CC15: 193.4 | CD15: 122 | CE15: 63.5 | CF15: 77.3 | CG15: 29.9 | CK15: 102.2 | CL15: 103 | CM15: 118.3 | CS15: 191.7 | CT15: 102.8 | CU15: 0 | CV15: 84.5 | CW15: 0 | CX15: 13.5 | CZ15: 0 | DA15: 20 | DB15: 10.4 | DC15: 5.4 | DD15: 1.2 | DE15: 1.7 | DF15: 4.9 | DG15: 20 | DH15: 20 | DI15: 18.8 | DJ15: 3.6 | DK15: 9.3 | DL15: 0 | DM15: 0 | DN15: 23.2 | DO15: 63.6 | DP15: 4.4 | DQ15: 2.4 | DR15: 2.4 | DT15: 0 | DU15: 2.7 | DV15: 20.3 | DW15: 3 | DY15: 17.4 | DZ15: 9.8 | EA15: 19.9 | EB15: 20.2 | EC15: 20 | ED15: 19.6 | EE15: 24.5 | EF15: 0 | EG15: 64.2 | EH15: 90.4 | EI15: 7.8 | EJ15: 3.6 | EK15: 21 | EL15: 6.8 | EM15: 7.3 | EN15: 20.4 | EO15: 20.4 | EP15: 20.2 | EQ15: 12.6 | ER15: 0 | ES15: 0 | ET15: 0.6 | EU15: 2.7 | EV15: 2.8 | EW15: 0 | EX15: 0 | EY15: 8 | EZ15: 20 | FB15: 44.2 | FC15: 0 | FD15: 29 | FE15: 3.3 | FF15: 16.6 | FI15: 6162.2 | FK15: 24.4373 | FL15: 0 | FN15: 13.2 | FP15: 9.4385 | FQ15: 10.5 | FR15: 15.1 | FS15: 72.6758
A16: 09/04/2025 | B16: 03:00 | E16: 450.4 | F16: 144.2 | I16: 90.5 | J16: 237.2 | M16: 105.9 | N16: 105.6 | O16: 105.4 | P16: 209 | Q16: 108.7 | R16: 67.1 | S16: 564.5 | T16: 10.6 | Y16: 167.2 | Z16: 7.6 | AA16: 3.3 | AB16: 0 | AC16: 6.5 | AD16: 10.1 | AE16: 143.6 | AF16: 9 | AJ16: 111.1 | AK16: 181.5 | AO16: 6.5 | AP16: 317.2 | AQ16: 5 | AR16: 137.8 | AS16: 42.3 | AT16: 18.5 | AU16: 19.7 | AV16: 90.6 | AZ16: 32.7 | BA16: 0 | BB16: 9.2 | BC16: 45.5 | BD16: 42.5 | BE16: 3.8 | BF16: 35.6 | BG16: 168.1 | BH16: 94.6 | BK16: 0 | BO16: 86.9 | BP16: 0 | BR16: 139.8 | BS16: 66.6 | BT16: 0 | CB16: 4.6 | CC16: 190.9 | CD16: 123.5 | CE16: 64 | CF16: 77.3 | CG16: 30.2 | CK16: 101.9 | CL16: 103.5 | CM16: 118.8 | CS16: 191.6 | CT16: 102.8 | CU16: 0 | CV16: 75.5 | CW16: 0 | CX16: 13.3 | CZ16: 0 | DA16: 20 | DB16: 10.4 | DC16: 5.5 | DD16: 1.2 | DE16: 1.7 | DF16: 4.8 | DG16: 20.1 | DH16: 20 | DI16: 18.8 | DJ16: 3.6 | DK16: 9.3 | DL16: 0 | DM16: 0 | DN16: 19.9 | DO16: 55.1 | DP16: 4.4 | DQ16: 2.4 | DR16: 2.4 | DT16: 0 | DU16: 2.7 | DV16: 20.3 | DW16: 3 | DY16: 17.4 | DZ16: 9.8 | EA16: 19.9 | EB16: 20.3 | EC16: 19.9 | ED16: 24.7 | EE16: 26 | EF16: 0 | EG16: 55.6 | EH16: 71.9 | EI16: 7.3 | EJ16: 2.3 | EK16: 21 | EL16: 6.8 | EM16: 7.2 | EN16: 20.4 | EO16: 20.4 | EP16: 20.2 | EQ16: 11 | ER16: 0 | ES16: 0 | ET16: 0.6 | EU16: 18.2 | EV16: 20.5 | EW16: 0 | EX16: 0 | EY16: 7.9 | EZ16: 20 | FB16: 43.7 | FC16: 0 | FD16: 29 | FE16: 3.3 | FF16: 16.5 | FI16: 6167.2 | FK16: 24.43606 | FL16: 0 | FN16: 13.2 | FP16: 9.43817 | FQ16: 10.3 | FR16: 15.2 | FS16: 72.57423
A17: 09/04/2025 | B17: 03:30 | E17: 450.5 | F17: 144 | I17: 89.5 | J17: 238.9 | M17: 106 | N17: 105.7 | O17: 105.1 | P17: 207.7 | Q17: 110.2 | R17: 67 | S17: 560.5 | T17: 10.6 | Y17: 167.3 | Z17: 7.8 | AA17: 3.3 | AB17: 0 | AC17: 6.4 | AD17: 10.1 | AE17: 142.9 | AF17: 8.9 | AJ17: 111.1 | AK17: 184.8 | AO17: 6.5 | AP17: 297.1 | AQ17: 5 | AR17: 137 | AS17: 42.4 | AT17: 18.5 | AU17: 19.7 | AV17: 90.1 | AZ17: 32.8 | BA17: 0 | BB17: 9.2 | BC17: 45.7 | BD17: 42 | BE17: 3.8 | BF17: 35.5 | BG17: 169.3 | BH17: 94.8 | BK17: 0 | BO17: 86.7 | BP17: 0 | BR17: 139.1 | BS17: 67.2 | BT17: 0 | CB17: 4.6 | CC17: 201.9 | CD17: 122.6 | CE17: 63.5 | CF17: 77.6 | CG17: 30.3 | CK17: 103 | CL17: 102.3 | CM17: 118.3 | CS17: 191.5 | CT17: 102.8 | CU17: 0 | CV17: 71.2 | CW17: 0 | CX17: 12 | CZ17: 0 | DA17: 20 | DB17: 10.4 | DC17: 5.5 | DD17: 1.2 | DE17: 1.7 | DF17: 4.8 | DG17: 20.5 | DH17: 20 | DI17: 18.8 | DJ17: 3.5 | DK17: 9.3 | DL17: 0 | DM17: 0 | DN17: 17 | DO17: 46.4 | DP17: 4.4 | DQ17: 2.4 | DR17: 2.4 | DT17: 0 | DU17: 2.6 | DV17: 20.3 | DW17: 3 | DY17: 17.2 | DZ17: 9.8 | EA17: 19.8 | EB17: 20.3 | EC17: 19.9 | ED17: 29 | EE17: 25.7 | EF17: 0 | EG17: 49.9 | EH17: 72.3 | EI17: 5 | EJ17: 1.8 | EK17: 21 | EL17: 6.8 | EM17: 7.2 | EN17: 20.4 | EO17: 20.4 | EP17: 20.2 | EQ17: 10.3 | ER17: 0 | ES17: 0 | ET17: 0.6 | EU17: 20.6 | EV17: 16.8 | EW17: 0 | EX17: 0 | EY17: 7.8 | EZ17: 20 | FB17: 44 | FC17: 0 | FD17: 29 | FE17: 3.3 | FF17: 16.6 | FI17: 6132.2 | FK17: 24.43323 | FL17: 0 | FN17: 13.2 | FP17: 9.43783 | FQ17: 10.5 | FR17: 15.1 | FS17: 72.67106
A18: 09/04/2025 | B18: 04:00 | E18: 441.2 | F18: 144.2 | I18: 89.2 | J18: 235.2 | M18: 105.8 | N18: 105.6 | O18: 105.7 | P18: 208.7 | Q18: 108.8 | R18: 67.2 | S18: 552 | T18: 10.3 | Y18: 157.3 | Z18: 7 | AA18: 3.1 | AB18: 0 | AC18: 6.4 | AD18: 10.1 | AE18: 142.8 | AF18: 9 | AJ18: 109.4 | AK18: 185.3 | AO18: 6.5 | AP18: 293.5 | AQ18: 5 | AR18: 138.3 | AS18: 42.3 | AT18: 18.5 | AU18: 19.7 | AV18: 90.6 | AZ18: 31.3 | BA18: 0 | BB18: 9.2 | BC18: 44.6 | BD18: 43.6 | BE18: 3.8 | BF18: 35 | BG18: 164.2 | BH18: 93.4 | BK18: 0 | BO18: 85.8 | BP18: 0 | BR18: 139.9 | BS18: 68.2 | BT18: 0 | CB18: 4.6 | CC18: 173.6 | CD18: 112.9 | CE18: 62 | CF18: 76.9 | CG18: 29.3 | CK18: 102.1 | CL18: 103.5 | CM18: 119.1 | CS18: 191.5 | CT18: 102.7 | CU18: 0 | CV18: 70.6 | CW18: 0 | CX18: 13.1 | CZ18: 0 | DA18: 20 | DB18: 10.4 | DC18: 5.4 | DD18: 1.2 | DE18: 1.7 | DF18: 4.8 | DG18: 19.8 | DH18: 20 | DI18: 18.8 | DJ18: 3.6 | DK18: 9.3 | DL18: 0 | DM18: 0 | DN18: 13.1 | DO18: 37.3 | DP18: 4.4 | DQ18: 2.4 | DR18: 2.4 | DT18: 0 | DU18: 2.9 | DV18: 20.3 | DW18: 3 | DY18: 17.3 | DZ18: 9.8 | EA18: 19.7 | EB18: 20.2 | EC18: 20 | ED18: 29 | EE18: 23.4 | EF18: 0 | EG18: 44.7 | EH18: 65.8 | EI18: 6.9 | EJ18: 2.9 | EK18: 21 | EL18: 6.8 | EM18: 7.2 | EN18: 20.4 | EO18: 20.4 | EP18: 20.2 | EQ18: 11.4 | ER18: 0 | ES18: 0 | ET18: 0.6 | EU18: 23.3 | EV18: 17.7 | EW18: 0 | EX18: 0 | EY18: 7.9 | EZ18: 20 | FB18: 43.9 | FC18: 0 | FD18: 29.1 | FE18: 3.1 | FF18: 16.5 | FI18: 6029.6 | FK18: 24.43398 | FL18: 0 | FN18: 13.2 | FP18: 9.43743 | FQ18: 10.5 | FR18: 15.1 | FS18: 72.67141
A19: 09/04/2025 | B19: 04:30 | E19: 449.3 | F19: 145.9 | I19: 90.2 | J19: 236.6 | M19: 106.1 | N19: 106.2 | O19: 106.5 | P19: 207.3 | Q19: 107.8 | R19: 67.1 | S19: 560.6 | T19: 0 | Y19: 164.4 | Z19: 7.6 | AA19: 3.4 | AB19: 0 | AC19: 6.4 | AD19: 10.1 | AE19: 143.5 | AF19: 9 | AJ19: 111 | AK19: 222.2 | AO19: 6.5 | AP19: 336.5 | AQ19: 5 | AR19: 149.2 | AS19: 42.4 | AT19: 18.5 | AU19: 19.7 | AV19: 91 | AZ19: 32.4 | BA19: 0 | BB19: 9 | BC19: 45.7 | BD19: 44.1 | BE19: 3.8 | BF19: 35.4 | BG19: 168.7 | BH19: 94.6 | BK19: 0 | BO19: 86.5 | BP19: 0 | BR19: 139.5 | BS19: 67.3 | BT19: 0 | CB19: 4.6 | CC19: 235.8 | CD19: 132.8 | CE19: 63.3 | CF19: 77.4 | CG19: 30.1 | CK19: 102.8 | CL19: 103 | CM19: 118.8 | CS19: 191.6 | CT19: 102.8 | CU19: 0 | CV19: 71.9 | CW19: 0 | CX19: 10.8 | CZ19: 0 | DA19: 20 | DB19: 10.5 | DC19: 5.5 | DD19: 1.2 | DE19: 1.7 | DF19: 4.7 | DG19: 20.3 | DH19: 20 | DI19: 18.8 | DJ19: 3.6 | DK19: 9.3 | DL19: 0 | DM19: 0 | DN19: 13.1 | DO19: 35.5 | DP19: 4.4 | DQ19: 2.4 | DR19: 2.4 | DT19: 0 | DU19: 2.9 | DV19: 20.3 | DW19: 3 | DY19: 17.3 | DZ19: 9.8 | EA19: 19.8 | EB19: 20.3 | EC19: 20 | ED19: 24.5 | EE19: 29.8 | EF19: 0 | EG19: 22.6 | EH19: 45.3 | EI19: 2.5 | EJ19: 1.6 | EK19: 21 | EL19: 6.8 | EM19: 7.2 | EN19: 20.4 | EO19: 20.4 | EP19: 20.2 | EQ19: 9.4 | ER19: 0 | ES19: 0 | ET19: 0.6 | EU19: 21.9 | EV19: 19 | EW19: 0 | EX19: 0 | EY19: 7.9 | EZ19: 20 | FB19: 44.5 | FC19: 0 | FD19: 29.1 | FE19: 3.2 | FF19: 16.5 | FI19: 6183.9 | FK19: 24.43453 | FL19: 0 | FN19: 13.2 | FP19: 9.43724 | FQ19: 10.5 | FR19: 15.1 | FS19: 72.67177
A20: 09/04/2025 | B20: 05:00 | E20: 515.2 | F20: 166.5 | I20: 89.1 | J20: 236.9 | M20: 106 | N20: 106.1 | O20: 106.3 | P20: 207.1 | Q20: 109.4 | R20: 67 | S20: 556.5 | T20: 0 | Y20: 166 | Z20: 7.3 | AA20: 3.3 | AB20: 0 | AC20: 6.4 | AD20: 10.1 | AE20: 142.6 | AF20: 9 | AJ20: 110.5 | AK20: 217.7 | AO20: 6.5 | AP20: 300.5 | AQ20: 5 | AR20: 142.4 | AS20: 42.3 | AT20: 18.5 | AU20: 19.7 | AV20: 87.8 | AZ20: 32.1 | BA20: 0 | BB20: 9.2 | BC20: 45.7 | BD20: 44 | BE20: 3.8 | BF20: 34.9 | BG20: 167.1 | BH20: 94.2 | BK20: 0 | BO20: 86 | BP20: 0 | BR20: 139.7 | BS20: 68 | BT20: 0 | CB20: 4.6 | CC20: 222.1 | CD20: 126.4 | CE20: 62.8 | CF20: 77.4 | CG20: 30 | CK20: 103.1 | CL20: 102.2 | CM20: 118.6 | CS20: 191.4 | CT20: 102.6 | CU20: 0 | CV20: 71.1 | CW20: 0 | CX20: 12.4 | CZ20: 0 | DA20: 20.1 | DB20: 10.5 | DC20: 5.4 | DD20: 1.2 | DE20: 1.7 | DF20: 4.7 | DG20: 20.2 | DH20: 20 | DI20: 18.8 | DJ20: 3.6 | DK20: 9.3 | DL20: 0 | DM20: 0 | DN20: 18 | DO20: 35.4 | DP20: 4.4 | DQ20: 2.4 | DR20: 2.4 | DT20: 0 | DU20: 3.1 | DV20: 20.3 | DW20: 3 | DY20: 17.3 | DZ20: 9.7 | EA20: 19.7 | EB20: 20.3 | EC20: 20 | ED20: 23.2 | EE20: 31.9 | EF20: 0 | EG20: 16.7 | EH20: 42.2 | EI20: 0.8 | EJ20: 0.3 | EK20: 21 | EL20: 6.8 | EM20: 7.2 | EN20: 20.4 | EO20: 20.4 | EP20: 20.2 | EQ20: 11 | ER20: 0 | ES20: 0 | ET20: 0.6 | EU20: 19 | EV20: 13.4 | EW20: 0 | EX20: 0 | EY20: 8 | EZ20: 20 | FB20: 44.4 | FC20: 0 | FD20: 29 | FE20: 3.2 | FF20: 16.6 | FI20: 6178.9 | FK20: 24.43507 | FL20: 0 | FN20: 13.2 | FP20: 9.43703 | FQ20: 10.5 | FR20: 15.1 | FS20: 72.6721
A21: 09/04/2025 | B21: 05:30 | E21: 519.9 | F21: 168.9 | I21: 90.3 | J21: 237.7 | M21: 106.8 | N21: 106.3 | O21: 106 | P21: 207 | Q21: 109.6 | R21: 67 | S21: 565.7 | T21: 0 | Y21: 165.2 | Z21: 7.6 | AA21: 3.4 | AB21: 0 | AC21: 6.4 | AD21: 10.1 | AE21: 143.7 | AF21: 8.9 | AJ21: 110.9 | AK21: 219.5 | AO21: 6.5 | AP21: 387 | AQ21: 5.3 | AR21: 149.5 | AS21: 42.3 | AT21: 18.5 | AU21: 19.7 | AV21: 89.5 | AZ21: 64.6 | BA21: 0 | BB21: 9.2 | BC21: 45.6 | BD21: 44.4 | BE21: 3.8 | BF21: 35.7 | BG21: 167.8 | BH21: 94.6 | BK21: 0 | BO21: 86.2 | BP21: 0 | BR21: 139.9 | BS21: 66.1 | BT21: 0 | CB21: 4.6 | CC21: 269.2 | CD21: 132.6 | CE21: 63.3 | CF21: 79.4 | CG21: 30.2 | CK21: 103.1 | CL21: 102 | CM21: 118.8 | CS21: 191.4 | CT21: 102.6 | CU21: 0 | CV21: 63.7 | CW21: 0 | CX21: 12.2 | CZ21: 0 | DA21: 20 | DB21: 10.5 | DC21: 5.4 | DD21: 1.2 | DE21: 1.6 | DF21: 4.6 | DG21: 20.3 | DH21: 20 | DI21: 18.9 | DJ21: 3.6 | DK21: 9.3 | DL21: 0 | DM21: 0 | DN21: 21.2 | DO21: 36.6 | DP21: 4.4 | DQ21: 2.4 | DR21: 2.4 | DT21: 0 | DU21: 2.9 | DV21: 20.4 | DW21: 3 | DY21: 17.3 | DZ21: 9.8 | EA21: 20.2 | EB21: 20.3 | EC21: 20 | ED21: 18.5 | EE21: 18.8 | EF21: 0 | EG21: 16.8 | EH21: 35.9 | EI21: 0.6 | EJ21: 0 | EK21: 21 | EL21: 7.1 | EM21: 7.2 | EN21: 20.4 | EO21: 20.4 | EP21: 20.2 | EQ21: 8.3 | ER21: 0 | ES21: 0 | ET21: 0.6 | EU21: 17.6 | EV21: 11.4 | EW21: 0 | EX21: 0 | EY21: 8.1 | EZ21: 20 | FB21: 44.5 | FC21: 0 | FD21: 29.1 | FE21: 3.3 | FF21: 16.5 | FI21: 6352.8 | FK21: 24.42287 | FL21: 0 | FN21: 13.2 | FP21: 9.4366 | FQ21: 10.5 | FR21: 15.2 | FS21: 72.75947
A22: 09/04/2025 | B22: 06:00 | E22: 642.6 | F22: 205.9 | I22: 90 | J22: 237.5 | M22: 106 | N22: 105.8 | O22: 105.5 | P22: 207.2 | Q22: 108.3 | R22: 67.3 | S22: 557.4 | T22: 0 | Y22: 165 | Z22: 7.3 | AA22: 3.3 | AB22: 0 | AC22: 4.6 | AD22: 10.1 | AE22: 143.1 | AF22: 9 | AJ22: 110.3 | AK22: 220.9 | AO22: 6.4 | AP22: 352.9 | AQ22: 10.3 | AR22: 148.5 | AS22: 42.3 | AT22: 18.5 | AU22: 19.7 | AV22: 92.1 | AZ22: 81.5 | BA22: 0 | BB22: 9.2 | BC22: 45.8 | BD22: 44.1 | BE22: 3.8 | BF22: 36.2 | BG22: 166.2 | BH22: 94 | BK22: 0 | BO22: 86.2 | BP22: 0 | BR22: 139.5 | BS22: 67.4 | BT22: 0 | CB22: 4.6 | CC22: 255.1 | CD22: 131.1 | CE22: 62.7 | CF22: 79.3 | CG22: 29.9 | CK22: 102.6 | CL22: 101.3 | CM22: 118.3 | CS22: 191.6 | CT22: 102.7 | CU22: 0 | CV22: 77.2 | CW22: 0 | CX22: 14.5 | CZ22: 0 | DA22: 20 | DB22: 10.4 | DC22: 5.5 | DD22: 1.2 | DE22: 1.7 | DF22: 4.6 | DG22: 20 | DH22: 20 | DI22: 18.8 | DJ22: 3.6 | DK22: 9.3 | DL22: 1.4 | DM22: 1.4 | DN22: 19.4 | DO22: 42 | DP22: 4.4 | DQ22: 2.4 | DR22: 2.4 | DT22: 0 | DU22: 3 | DV22: 20.2 | DW22: 3 | DY22: 17.3 | DZ22: 9.8 | EA22: 20 | EB22: 20.2 | EC22: 20 | ED22: 21.7 | EE22: 13.1 | EF22: 0 | EG22: 20.1 | EH22: 48.6 | EI22: 1.6 | EJ22: 0 | EK22: 21 | EL22: 7 | EM22: 7.2 | EN22: 20.4 | EO22: 20.4 | EP22: 20.2 | EQ22: 11.5 | ER22: 0 | ES22: 0.8 | ET22: 0.6 | EU22: 7 | EV22: 2.7 | EW22: 0.7 | EX22: 0 | EY22: 8 | EZ22: 20 | FB22: 44 | FC22: 0 | FD22: 29.1 | FE22: 3.3 | FF22: 16.7 | FI22: 6490.3 | FK22: 24.4199 | FL22: 3.105 | FN22: 13.2 | FP22: 9.43637 | FQ22: 10.5 | FR22: 15.2 | FS22: 75.86127
... A58: 10/04/2025 | B58: 00:00 | E58: 642 | F58: 213.7 | I58: 87.2 | J58: 236.8 | M58: 118.7 | N58: 119.1 | O58: 119.2 | P58: 225.9 | Q58: 108.7 | R58: 67.8 | S58: 556.2 | T58: 0 | Y58: 164.2 | Z58: 6.9 | AA58: 3.1 | AB58: 0 | AC58: 6.6 | AD58: 10.1 | AE58: 142.8 | AF58: 9 | AJ58: 109.7 | AK58: 221.1 | AO58: 6.5 | AP58: 459.3 | AQ58: 82 | AR58: 147.4 | AS58: 42.3 | AT58: 18.5 | AU58: 19.7 | AV58: 89.3 | AZ58: 107.4 | BA58: 4.5 | BB58: 9.3 | BC58: 44.6 | BD58: 23.4 | BE58: 3.8 | BF58: 38.2 | BG58: 171.5 | BH58: 94.2 | BK58: 0 | BO58: 85.8 | BP58: 0 | BR58: 139.9 | BS58: 67.3 | BT58: 0 | CB58: 4.6 | CC58: 255.6 | CD58: 128 | CE58: 63 | CF58: 80 | CG58: 29.7 | CK58: 104.4 | CL58: 103 | CM58: 120 | CS58: 0 | CT58: 0 | CU58: 0 | CV58: 59.8 | CW58: 0 | CX58: 0 | CZ58: 0 | DA58: 20 | DB58: 10.4 | DC58: 5.4 | DD58: 1.2 | DE58: 1.5 | DF58: 5 | DG58: 19.9 | DH58: 14.3 | DI58: 18.6 | DJ58: 3.7 | DK58: 9.3 | DL58: 0 | DM58: 0 | DN58: 11.5 | DO58: 32.8 | DP58: 4.4 | DQ58: 2.4 | DR58: 2.4 | DT58: 0 | DU58: 2.8 | DV58: 20.4 | DW58: 2 | DY58: 16.3 | DZ58: 9.9 | EA58: 20.2 | EB58: 20.2 | EC58: 20 | ED58: 2.5 | EE58: 35.1 | EF58: 0 | EG58: 61.4 | EH58: 80.8 | EI58: 4.7 | EJ58: 3.4 | EK58: 21 | EL58: 7.3 | EM58: 8.6 | EN58: 20.4 | EO58: 20.4 | EP58: 20.2 | EQ58: 0 | ER58: 0 | ES58: 0 | ET58: 0.6 | EU58: 46.5 | EV58: 44 | EW58: 0 | EX58: 0 | EY58: 7.9 | EZ58: 20 | FB58: 43.5 | FC58: 16 | FD58: 29 | FE58: 3.2 | FF58: 16.5 | FI58: 6559.4 | FK58: 24.45668 | FL58: 8.069 | FN58: 0 | FP58: 9.44031 | FQ58: 10.5 | FR58: 15.1 | FS58: 67.56599
A59: EJEC | C59: 0 | D59: 0 | E59: 14716.15 | F59: 4891.8 | G59: 0 | H59: 0 | I59: 2129.8 | J59: 5700.85 | K59: 0 | L59: 0 | M59: 3021.95 | N59: 3023.4 | O59: 3023.5 | P59: 5411.45 | Q59: 3776.4 | R59: 2097.7 | S59: 13430.55 | T59: 41.95 | U59: 0 | V59: 0 | W59: 0 | X59: 0 | Y59: 3928.15 | Z59: 181.05 | AA59: 78.7 | AB59: 131.95 | AC59: 154.5 | AD59: 242.45 | AE59: 3197.05 | AF59: 215.15 | AG59: 0 | AH59: 0 | AI59: 0 | AJ59: 2657.35 | AK59: 4963.3 | AL59: 0 | AM59: 0 | AN59: 0 | AO59: 154.7 | AP59: 9951.85 | AQ59: 1495.9 | AR59: 3419.15 | AS59: 1016.6 | AT59: 444.6 | AU59: 472.8 | AV59: 2137.5 | AW59: 0 | AX59: 0 | AY59: 0 | AZ59: 2183 | BA59: 29.7 | BB59: 222.15 | BC59: 1097.35 | BD59: 724.5 | BE59: 91.2 | BF59: 849.65 | BG59: 4125.9 | BH59: 2165.15 | BI59: 0 | BJ59: 0 | BK59: 694.8 | BL59: 0 | BM59: 0 | BN59: 0 | BO59: 2074.6 | BP59: 230 | BQ59: 0 | BR59: 4027.9 | BS59: 1841.3 | BT59: 168.7 | BU59: 0 | BV59: 0 | BW59: 0 | BX59: 0 | BY59: 0 | BZ59: 0 | CA59: 0 | CB59: 110.4 | CC59: 5901.1 | CD59: 3064.65 | CE59: 1524.95 | CF59: 1902.5 | CG59: 725.65 | CH59: 0 | CI59: 0 | CJ59: 0 | CK59: 2946.95 | CL59: 2964.2 | CM59: 3218.45 | CN59: 0 | CO59: 0 | CP59: 0 | CQ59: 0 | CR59: 0 | CS59: 4198.5 | CT59: 2254 | CU59: 7.3 | CV59: 1750.95 | CW59: 692.7 | CX59: 201.25 | CY59: 0 | CZ59: 1.7 | DA59: 480.1 | DB59: 250.1 | DC59: 130.3 | DD59: 29.05 | DE59: 25.4 | DF59: 114.2 | DG59: 485.4 | DH59: 476.75 | DI59: 423.35 | DJ59: 75.9 | DK59: 223.2 | DL59: 134.8 | DM59: 166.55 | DN59: 356.4 | DO59: 1103.4 | DP59: 103.7 | DQ59: 57.6 | DR59: 57.6 | DS59: 0 | DT59: 166.45 | DU59: 65.8 | DV59: 486.95 | DW59: 71.35 | DX59: 0 | DY59: 407.15 | DZ59: 234.05 | EA59: 484.4 | EB59: 486.6 | EC59: 478.95 | ED59: 317.55 | EE59: 796.15 | EF59: 328.5 | EG59: 1026.85 | EH59: 1441.65 | EI59: 138.35 | EJ59: 92.7 | EK59: 504 | EL59: 166.9 | EM59: 185.35 | EN59: 489.6 | EO59: 489.6 | EP59: 484.8 | EQ59: 192.65 | ER59: 131.2 | ES59: 1274.95 | ET59: 14.4 | EU59: 1152 | EV59: 1129.65 | EW59: 946.4 | EX59: 130.65 | EY59: 191.25 | EZ59: 479.8 | FA59: 0 | FB59: 1042.8 | FC59: 115.2 | FD59: 690.45 | FE59: 77.05 | FF59: 397 | FG59: 0 | FH59: 0 | FI59: 170102.35 | FK59: 582.44458 | FL59: 135.6365 | FM59: 0 | FN59: 204.6 | FO59: 0 | FP59: 226.57273 | FQ59: 246.2 | FR59: 362.3 | FS59: 1757.7538

Sheet REACTIVA
B3: miércoles, 9 de Abril del 2025
A5: POTENCIA REACTIVA EJECUTADA DE LAS UNIDADES DE GENERACIÓN DEL COES (MVAR) | FJ5: CENTRALES NO INTEGRANTES COES
A6: FECHA | B6: HORA | C6: 337 | D6: 338 | E6: 101 | F6: 102 | G6: 42667 | H6: 42668 | I6: 126 | J6: 127 | K6: 138 | L6: 139 | M6: 197 | N6: 203 | O6: 204 | P6: 230 | Q6: 209 | R6: 56677 | S6: 796 | T6: 2146 | U6: 142 | V6: 143 | W6: 125 | X6: 187 | Y6: 163 | Z6: 298 | AA6: 219 | AB6: 151 | AC6: 152 | AD6: 153 | AE6: 154 | AF6: 756 | AG6: 156 | AH6: 155 | AI6: 182 | AJ6: 212 | AK6: 758 | AL6: 263 | AM6: 265 | AN6: 775 | AO6: 777 | AP6: 2154 | AQ6: 150 | AR6: 149 | AS6: 188 | AT6: 2131 | AU6: 755 | AV6: 252 | AW6: 249 | AX6: 250 | AY6: 117 | AZ6: 267 | BA6: 268 | BB6: 119 | BC6: 120 | BD6: 189 | BE6: 122 | BF6: 266 | BG6: 251 | BH6: 115 | BI6: 239 | BJ6: 288 | BK6: 240 | BL6: 241 | BM6: 242 | BN6: 191 | BO6: 194 | BP6: 196 | BQ6: 207 | BR6: 236 | BS6: 795 | BT6: 285 | BU6: 995 | BV6: 996 | BW6: 997 | BX6: 766 | BY6: 926 | BZ6: 924 | CA6: 121 | CB6: 103 | CC6: 104 | CD6: 106 | CE6: 105 | CF6: 107 | CG6: 110 | CH6: 109 | CI6: 144 | CJ6: 113 | CK6: 114 | CL6: 193 | CM6: 208 | CN6: 786 | CO6: 787 | CP6: 788 | CQ6: 789 | CR6: 248 | CS6: 2159 | CT6: 303 | CU6: 59715 | CV6: 62255 | CW6: 1263 | CX6: 63425 | CY6: 61800 | CZ6: 2194 | DA6: 216 | DB6: 198 | DC6: 49607 | DD6: 214 | DE6: 260 | DF6: 2152 | DG6: 2128 | DH6: 247 | DI6: 228 | DJ6: 2135 | DK6: 261 | DL6: 237 | DM6: 253 | DN6: 770 | DO6: 225 | DP6: 2201 | DQ6: 2171 | DR6: 760 | DS6: 235 | DT6: 238 | DU6: 2184 | DV6: 61855 | DW6: 223 | DX6: 226 | DY6: 201 | DZ6: 258 | EA6: 259 | EB6: 920 | EC6: 257 | ED6: 256 | EE6: 2148 | EF6: 58288 | EG6: 58289 | EH6: 58839 | EI6: 58840 | EJ6: 296 | EK6: 297 | EL6: 211 | EM6: 2175 | EN6: 2178 | EO6: 2181 | EP6: 1262 | EQ6: 233 | ER6: 2150 | ES6: 2165 | ET6: 2161 | EU6: 61197 | EV6: 58851 | EW6: 234 | EX6: 215 | EY6: 917 | EZ6: 289 | FA6: 58333 | FB6: 58336 | FC6: 202 | FD6: 58487 | FE6: 213 | FF6: 232 | FG6: 2190 | FH6: TOTAL COES | FJ6: 221 | FK6: 222 | FL6: 224 | FM6: 2187 | FN6: 227 | FO6: 49400 | FP6: 199 | FQ6: 200 | FR6: TOTAL NO COES
C7: CENTRO | D7: CENTRO | E7: CENTRO | F7: CENTRO | G7: NORTE | H7: NORTE | I7: NORTE | J7: NORTE | K7: CENTRO | L7: CENTRO | M7: CENTRO | N7: CENTRO | O7: CENTRO | P7: CENTRO | Q7: CENTRO | R7: CENTRO | S7: CENTRO | T7: CENTRO | U7: CENTRO | V7: CENTRO | W7: CENTRO | X7: CENTRO | Y7: SUR | Z7: SUR | AA7: CENTRO | AB7: SUR | AC7: SUR | AD7: SUR | AE7: SUR | AF7: SUR | AG7: SUR | AH7: SUR | AI7: SUR | AJ7: CENTRO | AK7: NORTE | AL7: NORTE | AM7: NORTE | AN7: CENTRO | AO7: CENTRO | AP7: CENTRO | AQ7: CENTRO | AR7: CENTRO | AS7: CENTRO | AT7: CENTRO | AU7: SUR | AV7: CENTRO | AW7: CENTRO | AX7: CENTRO | AY7: CENTRO | AZ7: CENTRO | BA7: CENTRO | BB7: CENTRO | BC7: CENTRO | BD7: SUR | BE7: NORTE | BF7: CENTRO | BG7: CENTRO | BH7: NORTE | BI7: NORTE | BJ7: NORTE | BK7: SUR | BL7: SUR | BM7: SUR | BN7: CENTRO | BO7: CENTRO | BP7: CENTRO | BQ7: CENTRO | BR7: CENTRO | BS7: CENTRO | BT7: CENTRO | BU7: SUR | BV7: SUR | BW7: SUR | BX7: NORTE | BY7: SUR | BZ7: CENTRO | CA7: NORTE | CB7: CENTRO | CC7: CENTRO | CD7: CENTRO | CE7: CENTRO | CF7: CENTRO | CG7: CENTRO | CH7: CENTRO | CI7: CENTRO | CJ7: CENTRO | CK7: CENTRO | CL7: CENTRO | CM7: CENTRO | CN7: SUR | CO7: SUR | CP7: SUR | CQ7: SUR | CR7: CENTRO | CS7: CENTRO | CT7: CENTRO | CU7: CENTRO | CV7: SUR | CW7: NORTE | CX7: SUR | CY7: NORTE | CZ7: NORTE | DA7: NORTE | DB7: NORTE | DC7: SUR | DD7: CENTRO | DE7: CENTRO | DF7: CENTRO | DG7: NORTE | DH7: NORTE | DI7: CENTRO | DJ7: CENTRO | DK7: SUR | DL7: SUR | DM7: CENTRO | DN7: CENTRO | DO7: CENTRO | DP7: CENTRO | DQ7: CENTRO | DR7: CENTRO | DS7: SUR | DT7: CENTRO | DU7: CENTRO | DV7: NORTE | DW7: CENTRO | DX7: CENTRO | DY7: NORTE | DZ7: CENTRO | EA7: CENTRO | EB7: CENTRO | EC7: NORTE | ED7: NORTE | EE7: SUR | EF7: CENTRO | EG7: CENTRO | EH7: CENTRO | EI7: CENTRO | EJ7: CENTRO | EK7: CENTRO | EL7: SUR | EM7: SUR | EN7: SUR | EO7: SUR | EP7: NORTE | EQ7: SUR | ER7: SUR | ES7: CENTRO | ET7: CENTRO | EU7: CENTRO | EV7: SUR | EW7: SUR | EX7: NORTE | EY7: CENTRO | EZ7: NORTE | FA7: NORTE | FB7: NORTE | FC7: CENTRO | FD7: CENTRO | FE7: CENTRO | FF7: NORTE | FG7: NORTE | FJ7: NORTE | FK7: CENTRO | FL7: NORTE | FM7: NORTE | FN7: NORTE | FO7: NORTE | FP7: NORTE | FQ7: NORTE
C8: HIDROELÉCTRICA | D8: HIDROELÉCTRICA | E8: HIDROELÉCTRICA | F8: HIDROELÉCTRICA | G8: TERMOELÉCTRICA | H8: TERMOELÉCTRICA | I8: HIDROELÉCTRICA | J8: HIDROELÉCTRICA | K8: TERMOELÉCTRICA | L8: TERMOELÉCTRICA | M8: TERMOELÉCTRICA | N8: TERMOELÉCTRICA | O8: TERMOELÉCTRICA | P8: TERMOELÉCTRICA | Q8: TERMOELÉCTRICA | R8: TERMOELÉCTRICA | S8: HIDROELÉCTRICA | T8: HIDROELÉCTRICA | U8: TERMOELÉCTRICA | V8: TERMOELÉCTRICA | W8: TERMOELÉCTRICA | X8: TERMOELÉCTRICA | Y8: HIDROELÉCTRICA | Z8: HIDROELÉCTRICA | AA8: TERMOELÉCTRICA | AB8: HIDROELÉCTRICA | AC8: HIDROELÉCTRICA | AD8: HIDROELÉCTRICA | AE8: HIDROELÉCTRICA | AF8: TERMOELÉCTRICA | AG8: TERMOELÉCTRICA | AH8: TERMOELÉCTRICA | AI8: HIDROELÉCTRICA | AJ8: HIDROELÉCTRICA | AK8: TERMOELÉCTRICA | AL8: TERMOELÉCTRICA | AM8: TERMOELÉCTRICA | AN8: HIDROELÉCTRICA | AO8: HIDROELÉCTRICA | AP8: HIDROELÉCTRICA | AQ8: HIDROELÉCTRICA | AR8: HIDROELÉCTRICA | AS8: HIDROELÉCTRICA | AT8: HIDROELÉCTRICA | AU8: HIDROELÉCTRICA | AV8: TERMOELÉCTRICA | AW8: TERMOELÉCTRICA | AX8: TERMOELÉCTRICA | AY8: HIDROELÉCTRICA | AZ8: HIDROELÉCTRICA | BA8: HIDROELÉCTRICA | BB8: HIDROELÉCTRICA | BC8: HIDROELÉCTRICA | BD8: HIDROELÉCTRICA | BE8: HIDROELÉCTRICA | BF8: HIDROELÉCTRICA | BG8: HIDROELÉCTRICA | BH8: TERMOELÉCTRICA | BI8: TERMOELÉCTRICA | BJ8: TERMOELÉCTRICA | BK8: TERMOELÉCTRICA | BL8: TERMOELÉCTRICA | BM8: TERMOELÉCTRICA | BN8: HIDROELÉCTRICA | BO8: TERMOELÉCTRICA | BP8: TERMOELÉCTRICA | BQ8: TERMOELÉCTRICA | BR8: TERMOELÉCTRICA | BS8: TERMOELÉCTRICA | BT8: TERMOELÉCTRICA | BU8: TERMOELÉCTRICA | BV8: TERMOELÉCTRICA | BW8: TERMOELÉCTRICA | BX8: HIDROELÉCTRICA | BY8: TERMOELÉCTRICA | BZ8: TERMOELÉCTRICA | CA8: HIDROELÉCTRICA | CB8: HIDROELÉCTRICA | CC8: HIDROELÉCTRICA | CD8: HIDROELÉCTRICA | CE8: HIDROELÉCTRICA | CF8: HIDROELÉCTRICA | CG8: TERMOELÉCTRICA | CH8: TERMOELÉCTRICA | CI8: TERMOELÉCTRICA | CJ8: TERMOELÉCTRICA | CK8: TERMOELÉCTRICA | CL8: TERMOELÉCTRICA | CM8: TERMOELÉCTRICA | CN8: TERMOELÉCTRICA | CO8: TERMOELÉCTRICA | CP8: TERMOELÉCTRICA | CQ8: TERMOELÉCTRICA | CR8: TERMOELÉCTRICA | CS8: TERMOELÉCTRICA | CT8: SOLAR | CU8: EÓLICA | CV8: SOLAR | CW8: EÓLICA | CX8: SOLAR | CY8: SOLAR | CZ8: HIDROELÉCTRICA | DA8: HIDROELÉCTRICA | DB8: HIDROELÉCTRICA | DC8: HIDROELÉCTRICA | DD8: HIDROELÉCTRICA | DE8: HIDROELÉCTRICA | DF8: HIDROELÉCTRICA | DG8: HIDROELÉCTRICA | DH8: HIDROELÉCTRICA | DI8: HIDROELÉCTRICA | DJ8: HIDROELÉCTRICA | DK8: SOLAR | DL8: SOLAR | DM8: EÓLICA | DN8: EÓLICA | DO8: TERMOELÉCTRICA | DP8: TERMOELÉCTRICA | DQ8: TERMOELÉCTRICA | DR8: TERMOELÉCTRICA | DS8: SOLAR | DT8: HIDROELÉCTRICA | DU8: HIDROELÉCTRICA | DV8: HIDROELÉCTRICA | DW8: HIDROELÉCTRICA | DX8: HIDROELÉCTRICA | DY8: HIDROELÉCTRICA | DZ8: HIDROELÉCTRICA | EA8: HIDROELÉCTRICA | EB8: HIDROELÉCTRICA | EC8: EÓLICA | ED8: EÓLICA | EE8: SOLAR | EF8: EÓLICA | EG8: EÓLICA | EH8: EÓLICA | EI8: EÓLICA | EJ8: HIDROELÉCTRICA | EK8: HIDROELÉCTRICA | EL8: HIDROELÉCTRICA | EM8: HIDROELÉCTRICA | EN8: HIDROELÉCTRICA | EO8: HIDROELÉCTRICA | EP8: EÓLICA | EQ8: SOLAR | ER8: SOLAR | ES8: HIDROELÉCTRICA | ET8: EÓLICA | EU8: EÓLICA | EV8: SOLAR | EW8: SOLAR | EX8: HIDROELÉCTRICA | EY8: HIDROELÉCTRICA | EZ8: TERMOELÉCTRICA | FA8: TERMOELÉCTRICA | FB8: TERMOELÉCTRICA | FC8: TERMOELÉCTRICA | FD8: TERMOELÉCTRICA | FE8: TERMOELÉCTRICA | FF8: TERMOELÉCTRICA | FG8: TERMOELÉCTRICA | FJ8: HIDROELÉCTRICA | FK8: HIDROELÉCTRICA | FL8: HIDROELÉCTRICA | FM8: HIDROELÉCTRICA | FN8: TERMOELÉCTRICA | FO8: TERMOELÉCTRICA | FP8: HIDROELÉCTRICA | FQ8: HIDROELÉCTRICA
