Workbook

Sheet EVENTOS
B3: domingo, 19 de Octubre del 2025
B5: INFORMACIÓN DE EVENTOS PRINCIPALES EN SUS INSTALACIONES
B6: TIPO DE EVENTO | C6: EMPRESA | D6: UBICACIÓN | E6: TIPO DE EQUIPO | F6: EQUIPO | G6: INICIO | H6: FINAL | I6: DESCRIPCIÓN | J6: MW INDISP. | K6: INTERRUPCIÓN (SI/NO) | L6: TENSIÓN DE FALLA (kV)
B7: EVENTO | C7: CONELSUR LT SAC | D7: PORTILLO | E7: SUBESTACION | F7: SS.EE. | G7: 19/10/2025 00:00:00 | H7: 19/10/2025 03:39:00 | I7: DECLARACIÓN DE SITUACIÓN EXCEPCIONAL EN LA S.E. PORTILLO DE 60 kV | K7: NO
B8: FALLA | C8: ELECTRO ORIENTE | D8: BELAUNDE TERRY - TARAPOTO | E8: LINEA DE TRANSMISION | F8: L-1018 | G8: 19/10/2025 13:03:23 | H8: 19/10/2025 13:18:45 | I8: DESCONEXIÓN DE LA LÍNEA L-1018 (BELAUNDE TERRY - TARAPOTO) DE 138 KV POR FALLA | J8: 31.97 | K8: SI | L8: 138
B9: FALLA | C9: INFRAESTRUCTURAS Y ENERGIAS DEL PERU S.A.C. | D9: PUCALLPA | E9: TRANSFORMADOR 2D | F9: TR35-163 | G9: 19/10/2025 19:09:27 | H9: 19/10/2025 19:11:55 | I9: DESCONEXIÓN DEL TRANSFORMADOR TR35 DE LA CTRF PUCALLPA POR FALLA EXTERNA | K9: NO | L9: 60
B10: FALLA | C10: RED DE ENERGIA DEL PERU S.A. | D10: PARAMONGA N. - CHIMBOTE 1 | E10: LINEA DE TRANSMISION | F10: L-2215 | G10: 19/10/2025 15:23:47 | H10: 19/10/2025 16:44:15 | I10: DESCONEXIÓN DE LA LÍNEA L-2215 (PARAMONGA NUEVA - CHIMBOTE 1) POR FALLA | K10: NO | L10: 220
B11: FALLA | C11: RED DE ENERGIA DEL PERU S.A. | D11: TRUJILLO NORTE | E11: SVC | F11: SVC-1 | G11: 19/10/2025 20:58:17 | H11: 19/10/2025 21:46:19 | I11: DESCONEXIÓN DEL SVC-1 DE LA SE TRUJILLO NORTE POR FALLA | K11: NO | L11: 0

Sheet RESTRIC_OPE
B3: domingo, 19 de Octubre del 2025
B5: RESTRICCIONES OPERATIVAS
B6: FECHA | C6: HORA INICIO | D6: HORA FINAL | E6: EMPRESA | F6: UBICACIÓN | G6: T.Eq. | H6: EQUIPO | I6: DESCRIPCIÓN
B7: 19/10/2025 | C7: 00:00 | D7: 24:00 | E7: EGASA | F7: S.E. CONVERTIDOR | G7: BARRA | H7: BARRA138KV | I7: EGASA limitó la capacidad del transformador 138 kV/33 kV a 50 MVA por deterioro del aislamiento.
B8: 19/10/2025 | C8: 00:00 | D8: 24:00 | E8: ELECTROPERU | F8: C.H. MANTARO | G8: CH | H8: CENTRAL | I8: De acuerdo con el correo del día 25.08.2025, la central tiene una limitación de potencia máxima de 650 MW por seguridad de la central.
B9: 19/10/2025 | C9: 00:00 | D9: 24:00 | E9: ENEL GENERACION PIURA S.A. | F9: C.T. MALACAS | G9: CT | H9: CENTRAL | I9: De acuerdo con la comunicación vía correo del día 24.10.2024. ENEL GENERACIÓN PIURA informa una restricción de potencia para alcanzar 105 MW en simultaneo (TG6+TGN4).
B10: 19/10/2025 | C10: 00:00 | D10: 24:00 | E10: ENEL GENERACION PIURA S.A. | F10: C.T. MALACAS | G10: GT | H10: TG4 | I10: De acuerdo a lo informado mediante correo electronico el día 04.07, la uniadTG4 puede operar a potencia efectiva durante 3 horas o con 80MW durante 4 horas, y el resto de los periodos a mínima generación.
B11: 19/10/2025 | C11: 00:00 | D11: 24:00 | E11: ENGIE ENERGIA PERU S.A.A. | F11: C.H. YUNCÁN | G11: GH | H11: G3 | I11: Según la carta N° ENG/ 198-2024 enviada por su representada, se opera de forma continua el G3 de la CH Yuncán, debido a la ejecución de mantenimientos necesarios para evitar daños en los sellos de seguridad de la válvula esférica del grupo.
B12: 19/10/2025 | C12: 00:00 | D12: 24:00 | E12: ENGIE ENERGIA PERU S.A.A. | F12: C.T. CHILCA 1 | G12: CT | H12: CENTRAL | I12: Con carta ENG/971-2023, indica que no puede cumplir con las IO considerada en el PDO_17122023 dado que vulneran la seguridad de sus activos. Indican que se debe tomar TMO=168h.
B13: 19/10/2025 | C13: 00:00 | D13: 24:00 | E13: ENGIE ENERGIA PERU S.A.A. | F13: C.T. CHILCA 1 | G13: CT | H13: CENTRAL | I13: Restricción de temperatura de la C.T Chilca, ver valor en el modelo de despacho.
B14: 19/10/2025 | C14: 00:00 | D14: 24:00 | E14: ENGIE ENERGIA PERU S.A.A. | F14: C.T. CHILCA 2 | G14: CT | H14: CENTRAL | I14: Con carta ENG/971-2023, indica que no puede cumplir con las IO considerada en el PDO_17122023 dado que vulneran la seguridad de sus activos. Indican que se debe tomar TMO=168h.
B15: 19/10/2025 | C15: 00:00 | D15: 24:00 | E15: FENIX POWER PERÚ | F15: C.T. FENIX | G15: CT | H15: CENTRAL | I15: De acuerdo con lo comunicado en el correo del día 06.05.2024, la CT Fenix cuenta con TMO de 168 hrs en todos su modos de operación.
B16: 19/10/2025 | C16: 00:00 | D16: 24:00 | E16: KALLPA GENERACION S.A. | F16: C.H. MINI CENTRAL CERRO DEL AGUILA | G16: CH | H16: CENTRAL | I16: Caudal ecológico de la Mini CH Cerro del Águila es de 6.1 m3/s correspondiente al mes de setiembre.
B17: 19/10/2025 | C17: 00:00 | D17: 24:00 | E17: KALLPA GENERACION S.A. | F17: C.H. MINI CENTRAL CERRO DEL AGUILA | G17: CH | H17: CENTRAL | I17: De acuerdo con lo informado por Kallpa el día 20.08.2025, la MCH Cerro del Águila tiene TA=0.07h, TMO=0.08h, TMA=0.16h.
... B47: 19/10/2025 | C47: 00:00 | D47: 24:00 | E47: UNACEM PERU S.A. | F47: S.E. CONDORCOCHA | G47: TRAFO3D | H47: T-3 138/44 kV | I47: De acuerdo con lo comunicado UNACEM mediante el informe INF_00142-2025, la transformador T3 de la SE Condorcocha esta limitado al 50% de su capacidad.

Sheet MANTENIMIENTO EJECUTADOS
B3: domingo, 19 de Octubre del 2025
B5: Mantenimiento Ejecutado
B6: Empresa | C6: Ubicación | D6: Equipo | E6: Inicio | F6: Final | G6: Descripción | H6: MW Indisp. | I6: Prog. | J6: Dispon | K6: Interrupc. | L6: Tipo | M6: CodEq | N6: TipoEq_Osinerg
B7: AGRO INDUSTRIAL PARAMONGA S.A. | C7: PARAMONGA | D7: CENTRAL | E7: 19/10/2025 07:00 | F7: 19/10/2025 17:00 | G7: Operara en sistema aislado debido al mantenimiento en la linea L-1101 y SE PARAMONGA EXISTENTE. | H7: 0 | I7: P | J7: E/S | K7: N | L7: OTROS | M7: 12815 | N7: G
B8: ATLANTICA TRANSMISION SUR S.A. | C8: MONTALVO | D8: BARRA A_220KV | E8: 19/10/2025 07:51 | F8: 19/10/2025 13:21 | G8: INDISPONIBLE DEBIDO A MANTENIMIENTO EN EQUIPOS DE CELDA 2057 | H8: 0 | I8: P | J8: F/S | K8: N | L8: OTROS | M8: 13869 | N8: T
B9: ATLANTICA TRANSMISION SUR S.A. | C9: MONTALVO | D9: CL-2057 | E9: 19/10/2025 08:24 | F9: 19/10/2025 16:34 | G9: MANTENIMIENTO PREVENTIVO EN EQUIPOS DE CELDA | H9: 0 | I9: P | J9: F/S | K9: N | L9: PREV. | M9: 13812 | N9: T
B10: ATLANTICA TRANSMISION SUR S.A. | C10: MONTALVO | D10: BARRA B_220kV | E10: 19/10/2025 13:30 | F10: 19/10/2025 16:41 | G10: INDISPONIBLE DEBIDO A MANTENIMIENTO EN EQUIPOS DE CELDA 2057 | H10: 0 | I10: P | J10: F/S | K10: N | L10: OTROS | M10: 14765 | N10: T
B11: ATLANTICA TRANSMISION SUR S.A. | C11: MONTALVO - MOQUEGUA | D11: L-2057 | E11: 19/10/2025 08:24 | F11: 19/10/2025 16:30 | G11: INDISPONIBLE DEBIDO A MANTENIMIENTO EN EQUIPOS DE CELDA | H11: 0 | I11: P | J11: F/S | K11: N | L11: OTROS | M11: 13815 | N11: T
B12: ATLANTICA TRANSMISION SUR S.A. | C12: MOQUEGUA | D12: CL-2057 | E12: 19/10/2025 08:24 | F12: 19/10/2025 16:33 | G12: MANTENIMIENTO PREVENTIVO EN EQUIPOS DE CELDA | H12: 0 | I12: P | J12: F/S | K12: N | L12: PREV. | M12: 13819 | N12: T
B13: ATLANTICA TRANSMISION SUR S.A. | C13: OCONA | D13: INT-5450 | E13: 19/10/2025 00:00 | F13: 20/10/2025 00:00 | G13: Interruptor INT-5450 cerrado con restriccion operativa, REB-5450 en servicio y suministrando los SS.AA. de la S.E. Oco?a. | H13: 0 | I13: P | J13: E/S | K13: N | L13: OTROS | M13: 13761 | N13: T
B14: ATLANTICA TRANSMISION SUR S.A. | C14: POROMA | D14: INT-5371 | E14: 19/10/2025 00:00 | F14: 20/10/2025 00:00 | G14: Seccionador SBB-5371 fase T indisponible por problemas mecanicos, el seccionador permanece cerrado y bloqueado | H14: 0 | I14: P | J14: E/S | K14: N | L14: OTROS | M14: 13751 | N14: T
B15: ATLANTICA TRANSMISION SUR S.A. | C15: POROMA | D15: REB-5350 | E15: 19/10/2025 00:00 | F15: 20/10/2025 00:00 | G15: Fuera de servicio po falla en el equipo. | H15: 0 | I15: P | J15: F/S | K15: N | L15: OTROS | M15: 13771 | N15: T
B16: ATN S.A. | C16: CARHUAMAYO | D16: CL-1707 | E16: 19/10/2025 08:33 | F16: 19/10/2025 15:37 | G16: Mantenimiento preventivo de equipos en celda | H16: 0 | I16: P | J16: F/S | K16: N | L16: PREV. | M16: 13722 | N16: T
B17: ATN S.A. | C17: CARHUAMAYO NUEVA | D17: CL-1707 | E17: 19/10/2025 08:33 | F17: 19/10/2025 15:43 | G17: Mantenimiento preventivo de equipos en celda | H17: 0 | I17: P | J17: F/S | K17: N | L17: PREV. | M17: 13721 | N17: T
B18: ATN S.A. | C18: CARHUAMAYO NUEVA | D18: AUT-201 | E18: 19/10/2025 08:34 | F18: 19/10/2025 15:33 | G18: Mantenimiento preventivo de equipos en celda | H18: 0 | I18: P | J18: F/S | K18: N | L18: PREV. | M18: 12850 | N18: T
... B158: TRANSMISORA ELECTRICA DEL SUR 2 S.A.C. | C158: SAN ROMAN | D158: BARRA B_138 kV | E158: 19/10/2025 07:44 | F158: 19/10/2025 14:36 | G158: LIMPIEZA DE AISLADORES Y MANTENIMIENTO ELECTROMECANICO DE EQUIPOS DE PATIO 138KV DE LAS CL-1012 Y CL-1046. | H158: 0 | I158: P | J158: F/S | K158: N | L158: OTROS | M158: 18574 | N158: T

Sheet INGRESO OC
A3: domingo, 19 de Octubre del 2025
A5: INGRESO A OPERACIÓN COMERCIAL
A6: EMPRESA | B6: TIPO DE EQUIPO | C6: UBICACIÓN | D6: EQUIPO | E6: Fecha y hora de Ingreso a Operación Comercial

Sheet DESPACHO_EJECUTADO
B3: domingo, 19 de Octubre del 2025
A5: POTENCIA ACTIVA EJECUTADA DE LAS UNIDADES DE GENERACIÓN DEL SEIN (MW) | FM5: CENTRALES NO INTEGRANTES COES
A6: FECHA | B6: HORA | C6: 65333 | D6: 101 | E6: 102 | F6: 42667 | G6: 42668 | H6: 126 | I6: 127 | J6: 138 | K6: 139 | L6: 197 | M6: 203 | N6: 204 | O6: 230 | P6: 209 | Q6: 56677 | R6: 796 | S6: 2146 | T6: 142 | U6: 143 | V6: 125 | W6: 187 | X6: 163 | Y6: 298 | Z6: 299 | AA6: 219 | AB6: 151 | AC6: 152 | AD6: 153 | AE6: 154 | AF6: 756 | AG6: 156 | AH6: 155 | AI6: 182 | AJ6: 212 | AK6: 758 | AL6: 263 | AM6: 265 | AN6: 775 | AO6: 777 | AP6: 2154 | AQ6: 150 | AR6: 149 | AS6: 188 | AT6: 2131 | AU6: 755 | AV6: 252 | AW6: 249 | AX6: 250 | AY6: 117 | AZ6: 267 | BA6: 268 | BB6: 119 | BC6: 120 | BD6: 189 | BE6: 122 | BF6: 266 | BG6: 337 | BH6: 338 | BI6: 251 | BJ6: 115 | BK6: 239 | BL6: 288 | BM6: 240 | BN6: 241 | BO6: 242 | BP6: 191 | BQ6: 194 | BR6: 196 | BS6: 207 | BT6: 236 | BU6: 795 | BV6: 285 | BW6: 995 | BX6: 996 | BY6: 997 | BZ6: 766 | CA6: 926 | CB6: 924 | CC6: 121 | CD6: 103 | CE6: 104 | CF6: 106 | CG6: 105 | CH6: 107 | CI6: 110 | CJ6: 109 | CK6: 144 | CL6: 113 | CM6: 114 | CN6: 193 | CO6: 208 | CP6: 786 | CQ6: 787 | CR6: 788 | CS6: 789 | CT6: 248 | CU6: 2159 | CV6: 303 | CW6: 59715 | CX6: 62255 | CY6: 1263 | CZ6: 61800 | DA6: 2194 | DB6: 69125 | DC6: 216 | DD6: 198 | DE6: 70400 | DF6: 49607 | DG6: 214 | DH6: 260 | DI6: 2152 | DJ6: 2128 | DK6: 247 | DL6: 228 | DM6: 2135 | DN6: 261 | DO6: 237 | DP6: 253 | DQ6: 770 | DR6: 235 | DS6: 238 | DT6: 2184 | DU6: 61855 | DV6: 223 | DW6: 226 | DX6: 201 | DY6: 258 | DZ6: 259 | EA6: 920 | EB6: 257 | EC6: 256 | ED6: 2148 | EE6: 58288 | EF6: 58289 | EG6: 58839 | EH6: 58840 | EI6: 296 | EJ6: 297 | EK6: 211 | EL6: 2175 | EM6: 2178 | EN6: 2181 | EO6: 1262 | EP6: 63425 | EQ6: 233 | ER6: 2150 | ES6: 2165 | ET6: 2161 | EU6: 61197 | EV6: 58851 | EW6: 225 | EX6: 2201 | EY6: 2171 | EZ6: 760 | FA6: 234 | FB6: 215 | FC6: 917 | FD6: 289 | FE6: 58333 | FF6: 58336 | FG6: 213 | FH6: 232 | FI6: 2190 | FJ6: 69867 | FK6: TOTAL COES | FM6: 221 | FN6: 222 | FO6: 224 | FP6: 2187 | FQ6: 227 | FR6: 49400 | FS6: 199 | FT6: 200 | FU6: TOTAL NO COES
C7: SUR | D7: CENTRO | E7: CENTRO | F7: NORTE | G7: NORTE | H7: NORTE | I7: NORTE | J7: CENTRO | K7: CENTRO | L7: CENTRO | M7: CENTRO | N7: CENTRO | O7: CENTRO | P7: CENTRO | Q7: CENTRO | R7: CENTRO | S7: CENTRO | T7: CENTRO | U7: CENTRO | V7: CENTRO | W7: CENTRO | X7: SUR | Y7: SUR | Z7: SUR | AA7: CENTRO | AB7: SUR | AC7: SUR | AD7: SUR | AE7: SUR | AF7: SUR | AG7: SUR | AH7: SUR | AI7: SUR | AJ7: CENTRO | AK7: NORTE | AL7: NORTE | AM7: NORTE | AN7: CENTRO | AO7: CENTRO | AP7: CENTRO | AQ7: CENTRO | AR7: CENTRO | AS7: CENTRO | AT7: CENTRO | AU7: SUR | AV7: CENTRO | AW7: CENTRO | AX7: CENTRO | AY7: CENTRO | AZ7: CENTRO | BA7: CENTRO | BB7: CENTRO | BC7: CENTRO | BD7: SUR | BE7: NORTE | BF7: CENTRO | BG7: CENTRO | BH7: CENTRO | BI7: CENTRO | BJ7: NORTE | BK7: NORTE | BL7: NORTE | BM7: SUR | BN7: SUR | BO7: SUR | BP7: CENTRO | BQ7: CENTRO | BR7: CENTRO | BS7: CENTRO | BT7: CENTRO | BU7: CENTRO | BV7: CENTRO | BW7: SUR | BX7: SUR | BY7: SUR | BZ7: NORTE | CA7: SUR | CB7: CENTRO | CC7: NORTE | CD7: CENTRO | CE7: CENTRO | CF7: CENTRO | CG7: CENTRO | CH7: CENTRO | CI7: CENTRO | CJ7: CENTRO | CK7: CENTRO | CL7: CENTRO | CM7: CENTRO | CN7: CENTRO | CO7: CENTRO | CP7: SUR | CQ7: SUR | CR7: SUR | CS7: SUR | CT7: CENTRO | CU7: CENTRO | CV7: CENTRO | CW7: CENTRO | CX7: SUR | CY7: NORTE | CZ7: NORTE | DA7: NORTE | DB7: CENTRO | DC7: NORTE | DD7: NORTE | DE7: SUR | DF7: SUR | DG7: CENTRO | DH7: CENTRO | DI7: CENTRO | DJ7: NORTE | DK7: NORTE | DL7: CENTRO | DM7: CENTRO | DN7: SUR | DO7: SUR | DP7: CENTRO | DQ7: CENTRO | DR7: SUR | DS7: CENTRO | DT7: CENTRO | DU7: NORTE | DV7: CENTRO | DW7: CENTRO | DX7: NORTE | DY7: CENTRO | DZ7: CENTRO | EA7: CENTRO | EB7: NORTE | EC7: NORTE | ED7: SUR | EE7: CENTRO | EF7: CENTRO | EG7: CENTRO | EH7: CENTRO | EI7: CENTRO | EJ7: CENTRO | EK7: SUR | EL7: SUR | EM7: SUR | EN7: SUR | EO7: NORTE | EP7: SUR | EQ7: SUR | ER7: SUR | ES7: CENTRO | ET7: CENTRO | EU7: CENTRO | EV7: SUR | EW7: CENTRO | EX7: CENTRO | EY7: CENTRO | EZ7: CENTRO | FA7: SUR | FB7: NORTE | FC7: CENTRO | FD7: NORTE | FE7: NORTE | FF7: NORTE | FG7: CENTRO | FH7: NORTE | FI7: NORTE | FJ7: NORTE | FM7: NORTE | FN7: CENTRO | FO7: NORTE | FP7: NORTE | FQ7: NORTE | FR7: NORTE | FS7: NORTE | FT7: NORTE
C8: HIDROELÉCTRICA | D8: HIDROELÉCTRICA | E8: HIDROELÉCTRICA | F8: TERMOELÉCTRICA | G8: TERMOELÉCTRICA | H8: HIDROELÉCTRICA | I8: HIDROELÉCTRICA | J8: TERMOELÉCTRICA | K8: TERMOELÉCTRICA | L8: TERMOELÉCTRICA | M8: TERMOELÉCTRICA | N8: TERMOELÉCTRICA | O8: TERMOELÉCTRICA | P8: TERMOELÉCTRICA | Q8: TERMOELÉCTRICA | R8: HIDROELÉCTRICA | S8: HIDROELÉCTRICA | T8: TERMOELÉCTRICA | U8: TERMOELÉCTRICA | V8: TERMOELÉCTRICA | W8: TERMOELÉCTRICA | X8: HIDROELÉCTRICA | Y8: HIDROELÉCTRICA | Z8: HIDROELÉCTRICA | AA8: TERMOELÉCTRICA | AB8: HIDROELÉCTRICA | AC8: HIDROELÉCTRICA | AD8: HIDROELÉCTRICA | AE8: HIDROELÉCTRICA | AF8: TERMOELÉCTRICA | AG8: TERMOELÉCTRICA | AH8: TERMOELÉCTRICA | AI8: HIDROELÉCTRICA | AJ8: HIDROELÉCTRICA | AK8: TERMOELÉCTRICA | AL8: TERMOELÉCTRICA | AM8: TERMOELÉCTRICA | AN8: HIDROELÉCTRICA | AO8: HIDROELÉCTRICA | AP8: HIDROELÉCTRICA | AQ8: HIDROELÉCTRICA | AR8: HIDROELÉCTRICA | AS8: HIDROELÉCTRICA | AT8: HIDROELÉCTRICA | AU8: HIDROELÉCTRICA | AV8: TERMOELÉCTRICA | AW8: TERMOELÉCTRICA | AX8: TERMOELÉCTRICA | AY8: HIDROELÉCTRICA | AZ8: HIDROELÉCTRICA | BA8: HIDROELÉCTRICA | BB8: HIDROELÉCTRICA | BC8: HIDROELÉCTRICA | BD8: HIDROELÉCTRICA | BE8: HIDROELÉCTRICA | BF8: HIDROELÉCTRICA | BG8: HIDROELÉCTRICA | BH8: HIDROELÉCTRICA | BI8: HIDROELÉCTRICA | BJ8: TERMOELÉCTRICA | BK8: TERMOELÉCTRICA | BL8: TERMOELÉCTRICA | BM8: TERMOELÉCTRICA | BN8: TERMOELÉCTRICA | BO8: TERMOELÉCTRICA | BP8: HIDROELÉCTRICA | BQ8: TERMOELÉCTRICA | BR8: TERMOELÉCTRICA | BS8: TERMOELÉCTRICA | BT8: TERMOELÉCTRICA | BU8: TERMOELÉCTRICA | BV8: TERMOELÉCTRICA | BW8: TERMOELÉCTRICA | BX8: TERMOELÉCTRICA | BY8: TERMOELÉCTRICA | BZ8: HIDROELÉCTRICA | CA8: TERMOELÉCTRICA | CB8: TERMOELÉCTRICA | CC8: HIDROELÉCTRICA | CD8: HIDROELÉCTRICA | CE8: HIDROELÉCTRICA | CF8: HIDROELÉCTRICA | CG8: HIDROELÉCTRICA | CH8: HIDROELÉCTRICA | CI8: TERMOELÉCTRICA | CJ8: TERMOELÉCTRICA | CK8: TERMOELÉCTRICA | CL8: TERMOELÉCTRICA | CM8: TERMOELÉCTRICA | CN8: TERMOELÉCTRICA | CO8: TERMOELÉCTRICA | CP8: TERMOELÉCTRICA | CQ8: TERMOELÉCTRICA | CR8: TERMOELÉCTRICA | CS8: TERMOELÉCTRICA | CT8: TERMOELÉCTRICA | CU8: TERMOELÉCTRICA | CV8: SOLAR | CW8: EÓLICA | CX8: SOLAR | CY8: EÓLICA | CZ8: SOLAR | DA8: HIDROELÉCTRICA | DB8: HIDROELÉCTRICA | DC8: HIDROELÉCTRICA | DD8: HIDROELÉCTRICA | DE8: SOLAR | DF8: HIDROELÉCTRICA | DG8: HIDROELÉCTRICA | DH8: HIDROELÉCTRICA | DI8: HIDROELÉCTRICA | DJ8: HIDROELÉCTRICA | DK8: HIDROELÉCTRICA | DL8: HIDROELÉCTRICA | DM8: HIDROELÉCTRICA | DN8: SOLAR | DO8: SOLAR | DP8: EÓLICA | DQ8: EÓLICA | DR8: SOLAR | DS8: HIDROELÉCTRICA | DT8: HIDROELÉCTRICA | DU8: HIDROELÉCTRICA | DV8: HIDROELÉCTRICA | DW8: HIDROELÉCTRICA | DX8: HIDROELÉCTRICA | DY8: HIDROELÉCTRICA | DZ8: HIDROELÉCTRICA | EA8: HIDROELÉCTRICA | EB8: EÓLICA | EC8: EÓLICA | ED8: SOLAR | EE8: EÓLICA | EF8: EÓLICA | EG8: EÓLICA | EH8: EÓLICA | EI8: HIDROELÉCTRICA | EJ8: HIDROELÉCTRICA | EK8: HIDROELÉCTRICA | EL8: HIDROELÉCTRICA | EM8: HIDROELÉCTRICA | EN8: HIDROELÉCTRICA | EO8: EÓLICA | EP8: SOLAR | EQ8: SOLAR | ER8: SOLAR | ES8: HIDROELÉCTRICA | ET8: EÓLICA | EU8: EÓLICA | EV8: SOLAR | EW8: TERMOELÉCTRICA | EX8: TERMOELÉCTRICA | EY8: TERMOELÉCTRICA | EZ8: TERMOELÉCTRICA | FA8: SOLAR | FB8: HIDROELÉCTRICA | FC8: HIDROELÉCTRICA | FD8: TERMOELÉCTRICA | FE8: TERMOELÉCTRICA | FF8: TERMOELÉCTRICA | FG8: TERMOELÉCTRICA | FH8: TERMOELÉCTRICA | FI8: TERMOELÉCTRICA | FJ8: TERMOELÉCTRICA | FM8: HIDROELÉCTRICA | FN8: HIDROELÉCTRICA | FO8: HIDROELÉCTRICA | FP8: HIDROELÉCTRICA | FQ8: TERMOELÉCTRICA | FR8: TERMOELÉCTRICA | FS8: HIDROELÉCTRICA | FT8: HIDROELÉCTRICA
C9: HYDRO GLOBAL PERÚ S.A.C. | D9: ELECTROPERU | E9: ELECTROPERU | F9: ELECTROPERU | G9: ELECTROPERU | H9: ORAZUL ENERGY PERÚ | I9: ORAZUL ENERGY PERÚ | J9: TERMOSELVA | K9: TERMOSELVA | L9: KALLPA GENERACION S.A. | M9: KALLPA GENERACION S.A. | N9: KALLPA GENERACION S.A. | O9: KALLPA GENERACION S.A. | P9: KALLPA GENERACION S.A. | Q9: KALLPA GENERACION S.A. | R9: KALLPA GENERACION S.A. | S9: KALLPA GENERACION S.A. | T9: SHOUGESA | U9: SHOUGESA | V9: SHOUGESA | W9: SHOUGESA | X9: EGEMSA | Y9: EGESUR | Z9: EGESUR | AA9: EGESUR | AB9: EGASA | AC9: EGASA | AD9: EGASA | AE9: EGASA | AF9: EGASA | AG9: EGASA | AH9: EGASA | AI9: SAN GABAN | AJ9: CELEPSA | AK9: MINERA CERRO VERDE | AL9: PLANTA DE RESERVA FRIA DE GENERACION DE ETEN S.A. | AM9: PLANTA DE RESERVA FRIA DE GENERACION DE ETEN S.A. | AN9: EMPRESA DE GENERACION HUALLAGA | AO9: EMPRESA DE GENERACION HUALLAGA | AP9: LA VIRGEN | AQ9: CHINANGO S.A.C. | AR9: CHINANGO S.A.C. | AS9: HIDROELECTRICA HUANCHOR S.A.C. | AT9: CELEPSA RENOVABLES S.R.L. | AU9: INLAND ENERGY SAC | AV9: FENIX POWER PERÚ | AW9: FENIX POWER PERÚ | AX9: FENIX POWER PERÚ | AY9: STATKRAFT S.A | AZ9: STATKRAFT S.A | BA9: STATKRAFT S.A | BB9: STATKRAFT S.A | BC9: STATKRAFT S.A | BD9: STATKRAFT S.A | BE9: STATKRAFT S.A | BF9: STATKRAFT S.A | BG9: CENTRALES SANTA ROSA S.A.C. | BH9: CENTRALES SANTA ROSA S.A.C. | BI9: EMPRESA DE GENERACION HUANZA | BJ9: ENEL GENERACION PIURA S.A. | BK9: ENEL GENERACION PIURA S.A. | BL9: ENEL GENERACION PIURA S.A. | BM9: ENGIE ENERGIA PERU S.A.A. | BN9: ENGIE ENERGIA PERU S.A.A. | BO9: ENGIE ENERGIA PERU S.A.A. | BP9: ENGIE ENERGIA PERU S.A.A. | BQ9: ENGIE ENERGIA PERU S.A.A. | BR9: ENGIE ENERGIA PERU S.A.A. | BS9: ENGIE ENERGIA PERU S.A.A. | BT9: ENGIE ENERGIA PERU S.A.A. | BU9: ENGIE ENERGIA PERU S.A.A. | BV9: ENGIE ENERGIA PERU S.A.A. | BW9: ENGIE ENERGIA PERU S.A.A. | BX9: ENGIE ENERGIA PERU S.A.A. | BY9: ENGIE ENERGIA PERU S.A.A. | BZ9: ENGIE ENERGIA PERU S.A.A. | CA9: INFRAESTRUCTURAS Y ENERGIAS DEL PERU S.A.C. | CB9: INFRAESTRUCTURAS Y ENERGIAS DEL PERU S.A.C. | CC9: INVERSIONES SHAQSHA S.A.C. | CD9: ORYGEN PERU S.A.A. | CE9: ORYGEN PERU S.A.A. | CF9: ORYGEN PERU S.A.A. | CG9: ORYGEN PERU S.A.A. | CH9: ORYGEN PERU S.A.A. | CI9: ORYGEN PERU S.A.A. | CJ9: ORYGEN PERU S.A.A. | CK9: ORYGEN PERU S.A.A. | CL9: ORYGEN PERU S.A.A. | CM9: ORYGEN PERU S.A.A. | CN9: ORYGEN PERU S.A.A. | CO9: ORYGEN PERU S.A.A. | CP9: SAMAY I S.A.C | CQ9: SAMAY I S.A.C | CR9: SAMAY I S.A.C | CS9: SAMAY I S.A.C | CT9: TERMOCHILCA S.A.C. | CU9: TERMOCHILCA S.A.C. | CV9: COLCA SOLAR S.A.C. | CW9: ENERGIA RENOVABLE DEL SUR S.A. | CX9: GR CORTARRAMA SOCIEDAD ANONIMA CERRADA | CY9: GR TARUCA SOCIEDAD ANONIMA CERRADA | CZ9: KONDU SAC | DA9: PERUANA DE INVERSIONES EN ENERGIAS RENOVABLES S.A. | DB9: VARI ENERGIA S.A.C. | DC9: ORAZUL ENERGY PERÚ | DD9: ORAZUL ENERGY PERÚ | DE9: KALLPA GENERACION S.A. | DF9: SAN GABAN | DG9: MAJA ENERGIA S.A.C. | DH9: EMPRESA DE GENERACION ELECTRICA CANCHAYLLO SAC | DI9: EMPRESA DE GENERACION ELECTRICA SANTA ANA S.A.C. | DJ9: EMPRESA ELECTRICA AGUA AZUL | DK9: EMPRESA ELECTRICA RIO DOBLE | DL9: HIDROCAÑETE S.A. | DM9: HUAURA POWER GROUP S.A. | DN9: MOQUEGUA FV S.A.C. | DO9: PANAMERICANA SOLAR SAC. | DP9: PARQUE EOLICO MARCONA S.A.C. | DQ9: PARQUE EOLICO TRES HERMANAS S.A.C. | DR9: TACNA SOLAR SAC. | DS9: ELECTRICA YANAPAMPA SAC | DT9: ANDEAN POWER S.A.C. | DU9: ASOCIACIÓN SANTA LUCIA DE CHACAS | DV9: ATRIA ENERGIA S.A.C. | DW9: EGEJUNIN | DX9: EGEJUNIN | DY9: EGEJUNIN | DZ9: EGEJUNIN | EA9: EMPRESA DE GENERACION ELECTRICA RIO BAÑOS S.A.C. | EB9: ENERGÍA EÓLICA S.A. | EC9: ENERGÍA EÓLICA S.A. | ED9: ENGIE ENERGIA PERU S.A.A. | EE9: ENGIE ENERGIA PERU S.A.A. | EF9: ENGIE ENERGIA PERU S.A.A. | EG9: ENGIE ENERGIA PERU S.A.A. | EH9: ENGIE ENERGIA PERU S.A.A. | EI9: GENERACIÓN ANDINA S.A.C. | EJ9: GENERACIÓN ANDINA S.A.C. | EK9: GENERADORA DE ENERGÍA DEL PERÚ | EL9: GENERADORA DE ENERGÍA DEL PERÚ | EM9: GENERADORA DE ENERGÍA DEL PERÚ | EN9: GENERADORA DE ENERGÍA DEL PERÚ | EO9: GR PAINO SOCIEDAD ANONIMA CERRADA | EP9: JOYA SOLAR S.A.C. | EQ9: MAJES ARCUS S.A.C. | ER9: ORYGEN PERU S.A.A. | ES9: ORYGEN PERU S.A.A. | ET9: ORYGEN PERU S.A.A. | EU9: ORYGEN PERU S.A.A. | EV9: ORYGEN PERU S.A.A. | EW9: PETRAMAS | EX9: PETRAMAS | EY9: PETRAMAS | EZ9: PETRAMAS | FA9: REPARTICIÓN ARCUS S.A.C. | FB9: SINERSA | FC9: SINERSA | FD9: BIOENERGIA DEL CHIRA S.A. | FE9: GM OPERACIONES S.A.C. | FF9: GM OPERACIONES S.A.C. | FG9: AGRO INDUSTRIAL PARAMONGA S.A. | FH9: AGROAURORA S.A.C. | FI9: AGROINDUSTRIAS SAN JACINTO S.A.A. | FJ9: AGROLMOS SOCIEDAD ANONIMA - AGROLMOS S.A. | FM9: UNACEM PERU S.A. | FN9: ELECTRO ORIENTE | FO9: AGUAS Y ENERGIA PERU | FP9: ELECTRO ZAÑA S.A.C. | FQ9: ELECTRONOROESTE S.A. | FR9: SDE PIURA | FS9: SINERSA | FT9: SINERSA
C10: SAN GABAN III | D10: MANTARO | E10: RESTITUCION | F10: TUMBES MAK 1 | G10: TUMBES MAK 2 | H10: CARHUAQUERO | I10: CAÑON DEL PATO | J10: AGUAYTIA TG1 | K10: AGUAYTIA TG2 | L10: KALLPA TG1 | M10: KALLPA TG2 | N10: KALLPA TG3 | O10: KALLPA TV | P10: LFLORES TG1 | Q10: LFLORES TV | R10: CERRO DEL AGUILA | S10: CERRODELAGUILAG4 | T10: SHOUGESA TV1 | U10: SHOUGESA TV2 | V10: SHOUGESA TV3 | W10: SHOUGESA CUMMINS | X10: MACHUPICCHU | Y10: ARICOTA 1 | Z10: ARICOTA 2 | AA10: INDEPENDENCIA | AB10: CHARCANI I,II,III | AC10: CHARCANI IV | AD10: CHARCANI V | AE10: CHARCANI VI | AF10: CHILINA TG | AG10: MOLLENDO 1, 2, 3 | AH10: CHILINA (SULZ 1,2) | AI10: SAN GABAN II | AJ10: PLATANAL | AK10: RECKA | AL10: RF ETEN TG1 | AM10: RF ETEN TG2 | AN10: CHAGLLA GP1 | AO10: CHAGLLA | AP10: LA VIRGEN | AQ10: CHIMAY | AR10: YANANGO | AS10: HUANCHOR | AT10: MARAÑON | AU10: STA TERESA | AV10: FENIX GT11 | AW10: FENIX GT12 | AX10: FENIX TV10 | AY10: YAUPI | AZ10: OROYA | BA10: PACHACHACA | BB10: MALPASO | BC10: CAHUA | BD10: ARCATA | BE10: GALLITO CIEGO | BF10: CHEVES | BG10: SANTA ROSA 1 | BH10: SANTA ROSA 2 | BI10: HUANZA | BJ10: MALACAS2 TG4 | BK10: MALACAS3 TG 5 | BL10: MALACAS1 TG6 | BM10: RF ILO2 TG1 | BN10: RF ILO2 TG2 | BO10: RF ILO2 TG3 | BP10: YUNCAN | BQ10: CHILCA1 TG1 | BR10: CHILCA1 TG2 | BS10: CHILCA1 TG3 | BT10: CHILCA-TV | BU10: CHILCA2 TG41 | BV10: CHILCA2-TV | BW10: CTNEPI_TG41 | BX10: CTNEPI_TG42 | BY10: CTNEPI_TG43 | BZ10: QUITARACSA | CA10: RF PTO MALDONADO | CB10: RF PUCALLPA | CC10: PARIAC | CD10: HUINCO | CE10: MATUCANA | CF10: MOYOPAMPA | CG10: CALLAHUANCA | CH10: HUAMPANI | CI10: STA ROSA WEST TG7 | CJ10: UTI_5 | CK10: UTI_6 | CL10: VENTANILLA 3 | CM10: VENTANILLA 4 | CN10: VENTANILLA TV | CO10: STAROSA TG8 | CP10: PTO_BRVO TG1 | CQ10: PTO_BRVO TG2 | CR10: PTO_BRVO TG3 | CS10: PTO_BRVO TG4 | CT10: OLLEROS TG1 | CU10: OLLEROS TV | CV10: CS YARUCAYA | CW10: SAN JUAN | CX10: MATARANI | CY10: DUNA | CZ10: CARHUAQUERO (CS) | DA10: MANTA I | DB10: ANASHIRONI | DC10: CARHUAQUERO4 | DD10: CAÑA BRAVA | DE10: SUNNY | DF10: TUPURI | DG10: RONCADOR | DH10: CANCHAYLLO | DI10: RENOVANDESH1 | DJ10: POTRERO | DK10: PIZARRAS | DL10: NIMPERIAL | DM10: YARUCAYA | DN10: MOQUEGUA-SOLAR | DO10: PANAMERICANA-SOLAR | DP10: PQE-EOLICO-MARCONA | DQ10: PQE-EOLICO-3-HERMANAS | DR10: TACNA-SOLAR | DS10: YANAPAMPA | DT10: CARHUAC | DU10: HUALLIN | DV10: PURMACANA | DW10: HUASAHUASI | DX10: STACRUZ_1_2 | DY10: RUNATULLO_II | DZ10: RUNATULLO_III | EA10: RUCUY | EB10: PQE-EOLICO-TALARA | EC10: PQE-EOLICO-CUPISNIQUE | ED10: INTIPAMPA | EE10: PUNTA LOMITAS-BL1 | EF10: PUNTA LOMITAS-BL2 | EG10: PUN LOMITAS_EXP-BL1 | EH10: PUN LOMITAS_EXP-BL2 | EI10: 8AGOSTO | EJ10: EL CARMEN | EK10: LA JOYA | EL10: ANGEL_I | EM10: ANGEL_II | EN10: ANGEL_III | EO10: HUAMBOS | EP10: SAN MARTIN SOLAR | EQ10: MAJES | ER10: RUBI | ES10: CH_HER1 | ET10: WAYRA-I | EU10: WAYRA EXTENSION | EV10: CLEMESI | EW10: HUAYCOLORO | EX10: CALLAO | EY10: DONA_CATALINA | EZ10: LAGRINGAV | FA10: REPARTICION | FB10: POECHOS2 | FC10: CHANCAY | FD10: CANA BRAVA | FE10: REFINERIA TALARA TV1 | FF10: REFINERÍA TALARA TV2 | FG10: PARAMONGA | FH10: MAPLE | FI10: SAN_JACINTO | FJ10: AGROLMOS | FK10: MW | FM10: CARPAPATA | FN10: CENTRALES ELOR | FO10: PIAS1 | FP10: ZANA | FQ10: TABLAZO | FR10: TALLANCA | FS10: CURUMUY | FT10: POECHOS1 | FU10: MW
A11: 19/10/2025 | B11: 00:30 | C11: 200.2 | D11: 601 | E11: 204.3 | H11: 21.6 | I11: 144.1 | L11: 127.7 | M11: 127.6 | N11: 128.7 | O11: 225.1 | P11: 213.5 | Q11: 110.7 | R11: 559.7 | S11: 3.3 | X11: 168.1 | Y11: 7.4 | Z11: 6.2 | AB11: 6.8 | AC11: 13.3 | AD11: 72.1 | AI11: 109.8 | AJ11: 150 | AK11: 0 | AN11: 6.5 | AO11: 355.2 | AP11: 45 | AQ11: 151.3 | AR11: 25.4 | AS11: 17 | AT11: 12.1 | AU11: 89.2 | AV11: 181.4 | AW11: 181.9 | AX11: 184.4 | AY11: 109.7 | AZ11: 7.3 | BA11: 8.8 | BB11: 32.8 | BC11: 21.1 | BD11: 2.2 | BE11: 13.2 | BF11: 55.3 | BI11: 86.1 | BJ11: 0 | BP11: 110.7 | BS11: 209.2 | BT11: 90.4 | CC11: 2.5 | CD11: 243.6 | CF11: 59.7 | CG11: 63 | CH11: 29.8 | CL11: 146.6 | CM11: 147.7 | CN11: 149.8 | CV11: 0 | CW11: 37.3 | CX11: 0 | CY11: 2 | CZ11: 0 | DA11: 20 | DB11: 18.3 | DC11: 9.9 | DD11: 4 | DE11: 0 | DF11: 0.7 | DG11: 3.4 | DH11: 5 | DI11: 19.9 | DJ11: 13.6 | DK11: 7.8 | DL11: 3.6 | DM11: 18.6 | DN11: 0 | DO11: 0 | DP11: 9.7 | DQ11: 28 | DR11: 0 | DS11: 3.4 | DT11: 20.1 | DU11: 2.8 | DW11: 9.6 | DX11: 6.6 | DY11: 19.8 | DZ11: 20.2 | EA11: 20 | EB11: 15.4 | EC11: 19.3 | ED11: 0 | EE11: 48.8 | EF11: 65.2 | EG11: 5 | EH11: 3.3 | EI11: 10.4 | EJ11: 7.5 | EK11: 7.2 | EL11: 20.4 | EM11: 20.4 | EN11: 19.6 | EO11: 1.1 | EP11: 0 | EQ11: 0 | ER11: 0 | ES11: 0.6 | ET11: 11.3 | EU11: 8.7 | EV11: 0 | EW11: 2.1 | EX11: 2.3 | EY11: 2 | EZ11: 1 | FA11: 0 | FB11: 6.9 | FC11: 20 | FD11: 9.3 | FE11: 26.8 | FF11: 34.3 | FG11: 15.1 | FH11: 0 | FI11: 7.6 | FJ11: 11.1 | FK11: 6747.1 | FM11: 21.4 | FN11: 5.602 | FO11: 6.133 | FP11: 6.57 | FQ11: 27.43412 | FR11: 18.92717 | FS11: 4.9 | FT11: 5.2 | FU11: 96.16629
A12: 19/10/2025 | B12: 01:00 | C12: 203.4 | D12: 600.5 | E12: 205.3 | H12: 22.5 | I12: 144.4 | L12: 133.3 | M12: 131.7 | N12: 132.7 | O12: 240.6 | P12: 214.7 | Q12: 110.5 | R12: 550.4 | S12: 3.4 | X12: 166.5 | Y12: 7.6 | Z12: 6.2 | AB12: 6.8 | AC12: 11.9 | AD12: 72.2 | AI12: 109.8 | AJ12: 150.2 | AK12: 0 | AN12: 6.5 | AO12: 295.9 | AP12: 44.8 | AQ12: 150.6 | AR12: 28.8 | AS12: 17 | AT12: 12.1 | AU12: 92.5 | AV12: 184.9 | AW12: 184.9 | AX12: 184.5 | AY12: 109.2 | AZ12: 7.5 | BA12: 8.9 | BB12: 33.6 | BC12: 21.1 | BD12: 2.2 | BE12: 12.1 | BF12: 55.2 | BI12: 86.5 | BJ12: 0 | BP12: 111.5 | BS12: 163.1 | BT12: 90.1 | CC12: 2.5 | CD12: 189.5 | CF12: 63.2 | CG12: 63 | CH12: 29.9 | CL12: 147.1 | CM12: 147.7 | CN12: 151.2 | CV12: 0 | CW12: 32.2 | CX12: 0 | CY12: 2 | CZ12: 0 | DA12: 20 | DB12: 19.1 | DC12: 9.8 | DD12: 1.5 | DE12: 0 | DF12: 0.7 | DG12: 3.4 | DH12: 5 | DI12: 19.8 | DJ12: 13.6 | DK12: 7.8 | DL12: 3.6 | DM12: 18.6 | DN12: 0 | DO12: 0 | DP12: 9.9 | DQ12: 29 | DR12: 0 | DS12: 3.5 | DT12: 20.1 | DU12: 2.7 | DW12: 9.6 | DX12: 6.6 | DY12: 19.7 | DZ12: 20.2 | EA12: 19.8 | EB12: 13.5 | EC12: 15.2 | ED12: 0 | EE12: 41.3 | EF12: 65.8 | EG12: 4.8 | EH12: 2.7 | EI12: 10.4 | EJ12: 7.4 | EK12: 7.2 | EL12: 20.4 | EM12: 20.4 | EN12: 19.6 | EO12: 1.2 | EP12: 0 | EQ12: 0 | ER12: 0 | ES12: 0.6 | ET12: 16.5 | EU12: 11.2 | EV12: 0 | EW12: 2.1 | EX12: 2.3 | EY12: 2 | EZ12: 1 | FA12: 0 | FB12: 7 | FC12: 19.9 | FD12: 9.4 | FE12: 27.1 | FF12: 34.5 | FG12: 14.1 | FH12: 0 | FI12: 8.2 | FJ12: 11.1 | FK12: 6617.3 | FM12: 21.9 | FN12: 5.346 | FO12: 6.132 | FP12: 6.63 | FQ12: 27.48612 | FR12: 18.9271 | FS12: 5 | FT12: 5.3 | FU12: 96.72122
A13: 19/10/2025 | B13: 01:30 | C13: 201.5 | D13: 602 | E13: 204.5 | H13: 21.8 | I13: 146.5 | L13: 171.1 | M13: 170.8 | N13: 169.9 | O13: 254.6 | P13: 214.4 | Q13: 110.5 | R13: 559.8 | S13: 3.3 | X13: 166.6 | Y13: 7.9 | Z13: 6.3 | AB13: 6.8 | AC13: 10.9 | AD13: 72.4 | AI13: 109.8 | AJ13: 150.6 | AK13: 0 | AN13: 6.5 | AO13: 294.7 | AP13: 45 | AQ13: 151.5 | AR13: 28 | AS13: 17.2 | AT13: 12.1 | AU13: 89.9 | AV13: 181.6 | AW13: 182.3 | AX13: 185.1 | AY13: 110.2 | AZ13: 7.6 | BA13: 8.8 | BB13: 33 | BC13: 22.1 | BD13: 2.2 | BE13: 12.3 | BF13: 56 | BI13: 86.5 | BJ13: 0 | BP13: 111.4 | BS13: 4.2 | BT13: 0 | CC13: 2.5 | CD13: 223.5 | CF13: 63.9 | CG13: 62.9 | CH13: 29.9 | CL13: 146.4 | CM13: 148.6 | CN13: 149.5 | CV13: 0 | CW13: 30.9 | CX13: 0 | CY13: 5.7 | CZ13: 0 | DA13: 20 | DB13: 17.7 | DC13: 9.9 | DD13: 2 | DE13: 0 | DF13: 0.6 | DG13: 3.4 | DH13: 5.1 | DI13: 20 | DJ13: 13.6 | DK13: 7.8 | DL13: 3.6 | DM13: 18.6 | DN13: 0 | DO13: 0 | DP13: 7.1 | DQ13: 24.3 | DR13: 0 | DS13: 3.5 | DT13: 20.2 | DU13: 2.7 | DW13: 9.6 | DX13: 6.6 | DY13: 19.2 | DZ13: 20.2 | EA13: 20 | EB13: 16.1 | EC13: 18.5 | ED13: 0 | EE13: 42.4 | EF13: 62.4 | EG13: 5 | EH13: 2.7 | EI13: 10.4 | EJ13: 7.3 | EK13: 7.2 | EL13: 20.4 | EM13: 20.4 | EN13: 19.6 | EO13: 3.2 | EP13: 0 | EQ13: 0 | ER13: 0 | ES13: 0.6 | ET13: 14.9 | EU13: 9.3 | EV13: 0 | EW13: 2.1 | EX13: 2.3 | EY13: 2 | EZ13: 1 | FA13: 0 | FB13: 6.8 | FC13: 20 | FD13: 9.1 | FE13: 27 | FF13: 34.4 | FG13: 14.5 | FH13: 0 | FI13: 7.1 | FJ13: 11.1 | FK13: 6527.5 | FM13: 22.3 | FN13: 5.435 | FO13: 6.131 | FP13: 7.47 | FQ13: 27.51566 | FR13: 18.92716 | FS13: 5 | FT13: 5.2 | FU13: 97.97882
A14: 19/10/2025 | B14: 02:00 | C14: 205.4 | D14: 601.5 | E14: 203.8 | H14: 22.7 | I14: 151.3 | L14: 130.5 | M14: 131 | N14: 131.2 | O14: 239 | P14: 214.9 | Q14: 110.6 | R14: 554.2 | S14: 3.2 | X14: 170.1 | Y14: 8 | Z14: 6.2 | AB14: 6.8 | AC14: 11.3 | AD14: 72.4 | AI14: 110.3 | AJ14: 148.8 | AK14: 0 | AN14: 6.5 | AO14: 295.5 | AP14: 47 | AQ14: 152.1 | AR14: 29.1 | AS14: 17 | AT14: 12.1 | AU14: 91.7 | AV14: 183.9 | AW14: 184.9 | AX14: 183.8 | AY14: 110.5 | AZ14: 7.6 | BA14: 8.8 | BB14: 33.9 | BC14: 22 | BD14: 2.2 | BE14: 13.6 | BF14: 56.7 | BI14: 87 | BJ14: 0 | BP14: 112.1 | BS14: 0 | BT14: 0 | CC14: 2.5 | CD14: 152.1 | CF14: 64.3 | CG14: 64.9 | CH14: 30.1 | CL14: 146.4 | CM14: 147.5 | CN14: 149.7 | CV14: 0 | CW14: 31.2 | CX14: 0 | CY14: 4.6 | CZ14: 0 | DA14: 20 | DB14: 13 | DC14: 9.9 | DD14: 1.9 | DE14: 0 | DF14: 0.6 | DG14: 3.4 | DH14: 5 | DI14: 20.3 | DJ14: 13.6 | DK14: 7.8 | DL14: 3.6 | DM14: 18.6 | DN14: 0 | DO14: 0 | DP14: 8.2 | DQ14: 26.9 | DR14: 0 | DS14: 3.5 | DT14: 20.1 | DU14: 2.6 | DW14: 9.6 | DX14: 6.6 | DY14: 19.3 | DZ14: 20.2 | EA14: 20 | EB14: 17.3 | EC14: 16 | ED14: 0 | EE14: 48.8 | EF14: 68.1 | EG14: 4.5 | EH14: 3.2 | EI14: 10.4 | EJ14: 7.2 | EK14: 7.2 | EL14: 20.4 | EM14: 20.4 | EN14: 19.6 | EO14: 2.8 | EP14: 0 | EQ14: 0 | ER14: 0 | ES14: 0.6 | ET14: 11 | EU14: 6.9 | EV14: 0 | EW14: 2.1 | EX14: 2.3 | EY14: 2 | EZ14: 1 | FA14: 0 | FB14: 6.9 | FC14: 20 | FD14: 9.3 | FE14: 27 | FF14: 33.8 | FG14: 14.5 | FH14: 0 | FI14: 7.6 | FJ14: 11.1 | FK14: 6341.2 | FM14: 22.5 | FN14: 5.331 | FO14: 6.129 | FP14: 7.49 | FQ14: 27.4806 | FR14: 18.92695 | FS14: 4.9 | FT14: 5.2 | FU14: 97.95755
A15: 19/10/2025 | B15: 02:30 | C15: 201.4 | D15: 603.8 | E15: 205.6 | H15: 21.8 | I15: 151.4 | L15: 143 | M15: 142.4 | N15: 142.5 | O15: 239.2 | P15: 215.8 | Q15: 111 | R15: 560.6 | S15: 3.2 | X15: 169.3 | Y15: 7.6 | Z15: 6.2 | AB15: 6.8 | AC15: 11.3 | AD15: 72.3 | AI15: 110.3 | AJ15: 149.3 | AK15: 0 | AN15: 6.5 | AO15: 296.7 | AP15: 48 | AQ15: 151.6 | AR15: 28.5 | AS15: 17 | AT15: 12.1 | AU15: 92.6 | AV15: 181.6 | AW15: 182.5 | AX15: 185.2 | AY15: 110.6 | AZ15: 7.6 | BA15: 8.8 | BB15: 32.6 | BC15: 22 | BD15: 2.2 | BE15: 12 | BF15: 56.5 | BI15: 86.5 | BJ15: 0 | BP15: 111.4 | BS15: 0 | BT15: 0 | CC15: 2.5 | CD15: 163.9 | CF15: 64.1 | CG15: 64.8 | CH15: 30 | CL15: 147.4 | CM15: 149.1 | CN15: 150 | CV15: 0 | CW15: 31.8 | CX15: 0 | CY15: 8.2 | CZ15: 0 | DA15: 19.9 | DB15: 6.8 | DC15: 9.9 | DD15: 2 | DE15: 0 | DF15: 0.6 | DG15: 3.4 | DH15: 5 | DI15: 9.4 | DJ15: 13.8 | DK15: 7.8 | DL15: 3.6 | DM15: 18.6 | DN15: 0 | DO15: 0 | DP15: 8.9 | DQ15: 27.3 | DR15: 0 | DS15: 3.5 | DT15: 20.1 | DU15: 2.6 | DW15: 9.6 | DX15: 6.6 | DY15: 19.2 | DZ15: 20.2 | EA15: 20 | EB15: 17.9 | EC15: 16.7 | ED15: 0 | EE15: 54.6 | EF15: 72.5 | EG15: 5.8 | EH15: 3 | EI15: 10.4 | EJ15: 7 | EK15: 7.2 | EL15: 20.4 | EM15: 20.4 | EN15: 19.6 | EO15: 5.2 | EP15: 0 | EQ15: 0 | ER15: 0 | ES15: 0.6 | ET15: 12.3 | EU15: 9 | EV15: 0 | EW15: 2.1 | EX15: 2.3 | EY15: 2 | EZ15: 1 | FA15: 0 | FB15: 7 | FC15: 20 | FD15: 9.5 | FE15: 27 | FF15: 34.5 | FG15: 14.5 | FH15: 0 | FI15: 7.5 | FJ15: 11.1 | FK15: 6399 | FM15: 22.6 | FN15: 5.304 | FO15: 6.129 | FP15: 7.49 | FQ15: 27.48795 | FR15: 18.92705 | FS15: 5 | FT15: 5.3 | FU15: 98.238
A16: 19/10/2025 | B16: 03:00 | C16: 202.4 | D16: 604 | E16: 206.3 | H16: 22.3 | I16: 155 | L16: 129.1 | M16: 130.7 | N16: 130.2 | O16: 230.6 | P16: 213.8 | Q16: 110.6 | R16: 560 | S16: 3.3 | X16: 168.3 | Y16: 8.1 | Z16: 6.2 | AB16: 6.8 | AC16: 11.3 | AD16: 72.4 | AI16: 110.5 | AJ16: 149.6 | AK16: 0 | AN16: 6.5 | AO16: 297.4 | AP16: 48 | AQ16: 153 | AR16: 31 | AS16: 17.2 | AT16: 12.1 | AU16: 88.7 | AV16: 160.8 | AW16: 161.1 | AX16: 172.5 | AY16: 111.1 | AZ16: 7.6 | BA16: 8.8 | BB16: 33.1 | BC16: 22.3 | BD16: 2.2 | BE16: 0 | BF16: 57.5 | BI16: 86.9 | BJ16: 0 | BP16: 112.5 | BS16: 0 | BT16: 0 | CC16: 2.5 | CD16: 176.7 | CF16: 64.9 | CG16: 65 | CH16: 30.3 | CL16: 147 | CM16: 149.1 | CN16: 149.7 | CV16: 0 | CW16: 31.4 | CX16: 0 | CY16: 8.2 | CZ16: 0 | DA16: 20 | DB16: 6.6 | DC16: 9.9 | DD16: 1.9 | DE16: 0 | DF16: 0.6 | DG16: 3.4 | DH16: 5.2 | DI16: 7.3 | DJ16: 14.2 | DK16: 7.7 | DL16: 3.6 | DM16: 18.6 | DN16: 0 | DO16: 0 | DP16: 8 | DQ16: 25.5 | DR16: 0 | DS16: 3.5 | DT16: 20.2 | DU16: 2.5 | DW16: 9.6 | DX16: 6.6 | DY16: 19.1 | DZ16: 20.3 | EA16: 19.9 | EB16: 16.2 | EC16: 14.1 | ED16: 0 | EE16: 57.2 | EF16: 77.4 | EG16: 5.3 | EH16: 4.1 | EI16: 10.4 | EJ16: 7 | EK16: 6.7 | EL16: 20.4 | EM16: 20.4 | EN16: 19.6 | EO16: 5.8 | EP16: 0 | EQ16: 0 | ER16: 0 | ES16: 0.6 | ET16: 19.6 | EU16: 15.9 | EV16: 0 | EW16: 2.1 | EX16: 2.3 | EY16: 2 | EZ16: 1 | FA16: 0 | FB16: 7 | FC16: 20 | FD16: 9.5 | FE16: 27 | FF16: 34 | FG16: 14.7 | FH16: 0 | FI16: 7.5 | FJ16: 11.1 | FK16: 6319.7 | FM16: 22.8 | FN16: 5.31 | FO16: 6.1285 | FP16: 7.48 | FQ16: 27.48058 | FR16: 18.92736 | FS16: 4.9 | FT16: 5.4 | FU16: 98.42644
A17: 19/10/2025 | B17: 03:30 | C17: 202.5 | D17: 602 | E17: 203.9 | H17: 54 | I17: 154.9 | L17: 116.9 | M17: 115.8 | N17: 116.4 | O17: 217.1 | P17: 213.8 | Q17: 110.5 | R17: 556.2 | S17: 3.3 | X17: 167.3 | Y17: 7.5 | Z17: 6.3 | AB17: 6.8 | AC17: 11.3 | AD17: 72.4 | AI17: 110 | AJ17: 149.5 | AK17: 0 | AN17: 6.5 | AO17: 295.6 | AP17: 48.8 | AQ17: 151.2 | AR17: 30.4 | AS17: 17.2 | AT17: 12.1 | AU17: 93.2 | AV17: 163.5 | AW17: 163.9 | AX17: 173.8 | AY17: 108.8 | AZ17: 7.6 | BA17: 8.8 | BB17: 33.5 | BC17: 21.5 | BD17: 2.2 | BE17: 0 | BF17: 55.9 | BI17: 86.6 | BJ17: 0 | BP17: 111.5 | BS17: 0 | BT17: 0 | CC17: 2.5 | CD17: 155.2 | CF17: 64 | CG17: 65 | CH17: 29.9 | CL17: 147.7 | CM17: 148.6 | CN17: 150.2 | CV17: 0 | CW17: 32.2 | CX17: 0 | CY17: 7.6 | CZ17: 0 | DA17: 20 | DB17: 6.4 | DC17: 9.9 | DD17: 3 | DE17: 0 | DF17: 0.6 | DG17: 3.4 | DH17: 5 | DI17: 6.9 | DJ17: 14.5 | DK17: 8.5 | DL17: 3.6 | DM17: 18.6 | DN17: 0 | DO17: 0 | DP17: 7.1 | DQ17: 23.6 | DR17: 0 | DS17: 3.3 | DT17: 20.2 | DU17: 2.4 | DW17: 9.6 | DX17: 6.6 | DY17: 18.9 | DZ17: 20.2 | EA17: 20 | EB17: 23.1 | EC17: 11.4 | ED17: 0 | EE17: 52 | EF17: 73.4 | EG17: 5.3 | EH17: 1.8 | EI17: 10.4 | EJ17: 6.8 | EK17: 6.7 | EL17: 20.4 | EM17: 20.4 | EN17: 19.6 | EO17: 6.1 | EP17: 0 | EQ17: 0 | ER17: 0 | ES17: 0.6 | ET17: 21.6 | EU17: 13.9 | EV17: 0 | EW17: 2.1 | EX17: 2.3 | EY17: 2 | EZ17: 1 | FA17: 0 | FB17: 6.9 | FC17: 20 | FD17: 9.5 | FE17: 27 | FF17: 34.7 | FG17: 14.5 | FH17: 0 | FI17: 9 | FJ17: 11.1 | FK17: 6259.8 | FM17: 23 | FN17: 5.389 | FO17: 6.129 | FP17: 7.48 | FQ17: 27.45785 | FR17: 18.92754 | FS17: 5 | FT17: 5.3 | FU17: 98.68339
A18: 19/10/2025 | B18: 04:00 | C18: 205.7 | D18: 604.9 | E18: 203.4 | H18: 54.9 | I18: 154.8 | L18: 114.4 | M18: 113.4 | N18: 113.6 | O18: 208.2 | P18: 214.7 | Q18: 110.2 | R18: 566.7 | S18: 3.3 | X18: 170.6 | Y18: 8.1 | Z18: 6.5 | AB18: 6.8 | AC18: 11.5 | AD18: 73.3 | AI18: 110.5 | AJ18: 149.4 | AK18: 0 | AN18: 6.5 | AO18: 296 | AP18: 49.7 | AQ18: 152.1 | AR18: 30.3 | AS18: 17.2 | AT18: 12.1 | AU18: 93 | AV18: 164.8 | AW18: 165.4 | AX18: 173.3 | AY18: 110.8 | AZ18: 7.6 | BA18: 8.8 | BB18: 34.3 | BC18: 22.3 | BD18: 2.2 | BE18: 0 | BF18: 57.2 | BI18: 87.1 | BJ18: 0 | BP18: 112.3 | BS18: 0 | BT18: 0 | CC18: 2.5 | CD18: 129.8 | CF18: 64.6 | CG18: 65 | CH18: 30.3 | CL18: 146.8 | CM18: 148 | CN18: 149.5 | CV18: 0 | CW18: 26.3 | CX18: 0 | CY18: 5.6 | CZ18: 0 | DA18: 20 | DB18: 6.5 | DC18: 9.9 | DD18: 4.2 | DE18: 0 | DF18: 0.6 | DG18: 3.4 | DH18: 5 | DI18: 7.1 | DJ18: 14.5 | DK18: 8.5 | DL18: 3.6 | DM18: 18.6 | DN18: 0 | DO18: 0 | DP18: 6.4 | DQ18: 20.4 | DR18: 0 | DS18: 3.4 | DT18: 20.2 | DU18: 2.4 | DW18: 9.6 | DX18: 6.6 | DY18: 18.4 | DZ18: 20.3 | EA18: 19.9 | EB18: 26.4 | EC18: 12.7 | ED18: 0 | EE18: 66.1 | EF18: 80.4 | EG18: 7.6 | EH18: 3.7 | EI18: 10.4 | EJ18: 6.7 | EK18: 6.7 | EL18: 20.4 | EM18: 20.4 | EN18: 19.6 | EO18: 4.5 | EP18: 0 | EQ18: 0 | ER18: 0 | ES18: 0.6 | ET18: 32.1 | EU18: 19.3 | EV18: 0 | EW18: 2.1 | EX18: 2.3 | EY18: 2 | EZ18: 1 | FA18: 0 | FB18: 6.9 | FC18: 20 | FD18: 9.6 | FE18: 26.9 | FF18: 34.3 | FG18: 14.9 | FH18: 0 | FI18: 7.3 | FJ18: 11.1 | FK18: 6281.8 | FM18: 23.1 | FN18: 5.396 | FO18: 6.1275 | FP18: 7.5 | FQ18: 27.45989 | FR18: 18.92749 | FS18: 5 | FT18: 5.3 | FU18: 98.81088
A19: 19/10/2025 | B19: 04:30 | C19: 200.7 | D19: 597.2 | E19: 203.3 | H19: 54.1 | I19: 153.8 | L19: 108.6 | M19: 109.6 | N19: 109.2 | O19: 222.8 | P19: 214.8 | Q19: 110.4 | R19: 545.7 | S19: 3.2 | X19: 161.9 | Y19: 7.4 | Z19: 6.2 | AB19: 6.8 | AC19: 11.6 | AD19: 71.6 | AI19: 109.3 | AJ19: 150 | AK19: 0 | AN19: 6.5 | AO19: 293.9 | AP19: 48.1 | AQ19: 150.4 | AR19: 31.4 | AS19: 17.2 | AT19: 12.1 | AU19: 92.5 | AV19: 122.7 | AW19: 123.2 | AX19: 155.1 | AY19: 108.9 | AZ19: 7.6 | BA19: 8.9 | BB19: 33.1 | BC19: 21.1 | BD19: 2.2 | BE19: 0 | BF19: 54.9 | BI19: 85.6 | BJ19: 0 | BP19: 127.2 | BS19: 0 | BT19: 0 | CC19: 2.5 | CD19: 153.9 | CF19: 63.6 | CG19: 64.8 | CH19: 29.7 | CL19: 146.9 | CM19: 147.7 | CN19: 150 | CV19: 0 | CW19: 29 | CX19: 0 | CY19: 7.3 | CZ19: 0 | DA19: 20 | DB19: 10.1 | DC19: 9.9 | DD19: 4.4 | DE19: 0 | DF19: 0.6 | DG19: 3.4 | DH19: 5 | DI19: 14.2 | DJ19: 14.3 | DK19: 8.5 | DL19: 3.6 | DM19: 18.6 | DN19: 0 | DO19: 0 | DP19: 6.2 | DQ19: 23 | DR19: 0 | DS19: 3.4 | DT19: 20.2 | DU19: 2.4 | DW19: 9.6 | DX19: 6.6 | DY19: 18.4 | DZ19: 20.1 | EA19: 20 | EB19: 26.5 | EC19: 11.1 | ED19: 0 | EE19: 52 | EF19: 77.4 | EG19: 4.6 | EH19: 2 | EI19: 10.4 | EJ19: 6.5 | EK19: 6.9 | EL19: 20.4 | EM19: 20.4 | EN19: 19.6 | EO19: 4.8 | EP19: 0 | EQ19: 0 | ER19: 0 | ES19: 0.6 | ET19: 40.1 | EU19: 28.9 | EV19: 0 | EW19: 2.1 | EX19: 2.3 | EY19: 2 | EZ19: 1 | FA19: 0 | FB19: 7 | FC19: 20 | FD19: 9.5 | FE19: 26.9 | FF19: 33.8 | FG19: 15.2 | FH19: 0 | FI19: 8.8 | FJ19: 11.1 | FK19: 6170.6 | FM19: 23 | FN19: 5.391 | FO19: 6.128 | FP19: 7.5 | FQ19: 27.47876 | FR19: 18.92765 | FS19: 5 | FT19: 5.3 | FU19: 98.72541
A20: 19/10/2025 | B20: 05:00 | C20: 198.5 | D20: 603.3 | E20: 205 | H20: 53.9 | I20: 155 | L20: 156 | M20: 156 | N20: 156.3 | O20: 239.6 | P20: 215.3 | Q20: 110.6 | R20: 562.4 | S20: 3.3 | X20: 115.8 | Y20: 8 | Z20: 6.1 | AB20: 6.8 | AC20: 11.6 | AD20: 73.1 | AI20: 109.9 | AJ20: 150.6 | AK20: 0 | AN20: 6.5 | AO20: 294.6 | AP20: 49.9 | AQ20: 149.7 | AR20: 33.2 | AS20: 17.2 | AT20: 12.1 | AU20: 89.7 | AV20: 122 | AW20: 122.3 | AX20: 154 | AY20: 109.3 | AZ20: 7.6 | BA20: 8.9 | BB20: 33.4 | BC20: 22 | BD20: 2.2 | BE20: 0 | BF20: 56.2 | BI20: 60.3 | BJ20: 0 | BP20: 127.1 | BS20: 0 | BT20: 0 | CC20: 2.5 | CD20: 173.2 | CF20: 63.9 | CG20: 64.8 | CH20: 29.8 | CL20: 147.2 | CM20: 148.3 | CN20: 150 | CV20: 0 | CW20: 27.3 | CX20: 0 | CY20: 8.8 | CZ20: 0 | DA20: 20 | DB20: 8.5 | DC20: 9.9 | DD20: 4.3 | DE20: 0 | DF20: 0.6 | DG20: 3.4 | DH20: 5 | DI20: 19.1 | DJ20: 14.3 | DK20: 8.5 | DL20: 3.6 | DM20: 18.6 | DN20: 0.1 | DO20: 0 | DP20: 6.3 | DQ20: 22.7 | DR20: 0 | DS20: 3.4 | DT20: 19.6 | DU20: 2.3 | DW20: 9.6 | DX20: 6.6 | DY20: 18.5 | DZ20: 20.2 | EA20: 20 | EB20: 25.9 | EC20: 14 | ED20: 0 | EE20: 47.8 | EF20: 77.1 | EG20: 5.1 | EH20: 3.1 | EI20: 10.4 | EJ20: 6.4 | EK20: 6.9 | EL20: 20.4 | EM20: 20.4 | EN20: 19.6 | EO20: 6.3 | EP20: 0 | EQ20: 0 | ER20: 0 | ES20: 0.6 | ET20: 45.4 | EU20: 35 | EV20: 0 | EW20: 2.1 | EX20: 2.3 | EY20: 2 | EZ20: 1 | FA20: 0 | FB20: 7 | FC20: 20 | FD20: 9.3 | FE20: 26.7 | FF20: 33.1 | FG20: 14.6 | FH20: 0 | FI20: 7.9 | FJ20: 11.1 | FK20: 6317.7 | FM20: 23 | FN20: 5.36 | FO20: 6.13 | FP20: 7.49 | FQ20: 27.56414 | FR20: 18.92808 | FS20: 4.9 | FT20: 5.3 | FU20: 98.67222
A21: 19/10/2025 | B21: 05:30 | C21: 202.3 | D21: 604.1 | E21: 206.5 | H21: 54.2 | I21: 158.5 | L21: 119.9 | M21: 119.6 | N21: 120 | O21: 224.1 | P21: 215.5 | Q21: 110.7 | R21: 561.9 | S21: 3.4 | X21: 82.9 | Y21: 7.9 | Z21: 6.1 | AB21: 6.8 | AC21: 11.6 | AD21: 72.6 | AI21: 110.2 | AJ21: 149.8 | AK21: 0 | AN21: 6.5 | AO21: 295.8 | AP21: 51 | AQ21: 151.3 | AR21: 32.7 | AS21: 17 | AT21: 12.1 | AU21: 68.8 | AV21: 138.1 | AW21: 138.2 | AX21: 161.3 | AY21: 109.7 | AZ21: 7.6 | BA21: 8.9 | BB21: 33.4 | BC21: 21.6 | BD21: 2.2 | BE21: 0 | BF21: 56.4 | BI21: 60.9 | BJ21: 0 | BP21: 127.8 | BS21: 0 | BT21: 0 | CC21: 2.5 | CD21: 230.9 | CF21: 64 | CG21: 65 | CH21: 29.9 | CL21: 147.9 | CM21: 148.6 | CN21: 151 | CV21: 0 | CW21: 34.5 | CX21: 0.5 | CY21: 11.3 | CZ21: 0 | DA21: 19.9 | DB21: 20 | DC21: 9.9 | DD21: 4.4 | DE21: 2.9 | DF21: 0.6 | DG21: 3.4 | DH21: 4.9 | DI21: 20 | DJ21: 14.9 | DK21: 8.5 | DL21: 3.6 | DM21: 18.6 | DN21: 3.2 | DO21: 3.3 | DP21: 10.7 | DQ21: 25.2 | DR21: 0.4 | DS21: 3.5 | DT21: 15.3 | DU21: 2.3 | DW21: 9.5 | DX21: 6.6 | DY21: 19.1 | DZ21: 20.2 | EA21: 20 | EB21: 23.1 | EC21: 17.3 | ED21: 0.5 | EE21: 48.8 | EF21: 70.6 | EG21: 4.7 | EH21: 1.5 | EI21: 10.4 | EJ21: 6.3 | EK21: 6.9 | EL21: 20.4 | EM21: 20.4 | EN21: 19.6 | EO21: 10.7 | EP21: 3.5 | EQ21: 0 | ER21: 3.2 | ES21: 0.6 | ET21: 43.2 | EU21: 32.4 | EV21: 2.5 | EW21: 2.1 | EX21: 2.3 | EY21: 2 | EZ21: 1 | FA21: 0 | FB21: 6.9 | FC21: 20 | FD21: 9.5 | FE21: 27 | FF21: 33.6 | FG21: 15.7 | FH21: 0 | FI21: 8.3 | FJ21: 11.1 | FK21: 6293 | FM21: 23 | FN21: 5.303 | FO21: 6.1315 | FP21: 7.51 | FQ21: 27.54742 | FR21: 18.92788 | FS21: 4.9 | FT21: 5.3 | FU21: 98.6198
A22: 19/10/2025 | B22: 06:00 | C22: 204 | D22: 603.4 | E22: 205.1 | H22: 54.6 | I22: 160.8 | L22: 122.2 | M22: 122 | N22: 121.1 | O22: 215.8 | P22: 213.7 | Q22: 110.9 | R22: 559.3 | S22: 3.3 | X22: 84 | Y22: 8.1 | Z22: 6.2 | AB22: 6.8 | AC22: 11.5 | AD22: 72.5 | AI22: 110.4 | AJ22: 89 | AK22: 0 | AN22: 6.5 | AO22: 147.3 | AP22: 51.9 | AQ22: 152.2 | AR22: 33.2 | AS22: 17 | AT22: 12.1 | AU22: 49.3 | AV22: 125.2 | AW22: 125.4 | AX22: 153.5 | AY22: 111.1 | AZ22: 7.6 | BA22: 9.1 | BB22: 33.1 | BC22: 22 | BD22: 2.2 | BE22: 0 | BF22: 57.6 | BI22: 60.8 | BJ22: 0 | BP22: 128.2 | BS22: 0 | BT22: 0 | CC22: 2.5 | CD22: 98.7 | CF22: 64.4 | CG22: 65.1 | CH22: 30.3 | CL22: 147.3 | CM22: 148.4 | CN22: 149.9 | CV22: 0 | CW22: 38.9 | CX22: 19.8 | CY22: 9.6 | CZ22: 0 | DA22: 19.9 | DB22: 20.3 | DC22: 9.9 | DD22: 4.4 | DE22: 38.5 | DF22: 0.6 | DG22: 3.4 | DH22: 4.9 | DI22: 20.5 | DJ22: 14.9 | DK22: 8.5 | DL22: 3.6 | DM22: 18.6 | DN22: 10.3 | DO22: 11.3 | DP22: 8.5 | DQ22: 22.9 | DR22: 1 | DS22: 3.3 | DT22: 15.1 | DU22: 2.3 | DW22: 9.4 | DX22: 6.6 | DY22: 19.3 | DZ22: 20.2 | EA22: 20 | EB22: 21 | EC22: 19.2 | ED22: 7.5 | EE22: 47.8 | EF22: 70.5 | EG22: 5.5 | EH22: 2.4 | EI22: 10.4 | EJ22: 6.2 | EK22: 7.1 | EL22: 20.4 | EM22: 20.4 | EN22: 19.6 | EO22: 6.6 | EP22: 62 | EQ22: 0.7 | ER22: 36.9 | ES22: 0.6 | ET22: 34.1 | EU22: 23.7 | EV22: 30.9 | EW22: 2.1 | EX22: 2.3 | EY22: 2 | EZ22: 1 | FA22: 0.7 | FB22: 6.6 | FC22: 20 | FD22: 9.5 | FE22: 27 | FF22: 33.6 | FG22: 15.7 | FH22: 3.1 | FI22: 7 | FJ22: 11.1 | FK22: 6078.3 | FM22: 23 | FN22: 5.307 | FO22: 6.1305 | FP22: 7.49 | FQ22: 27.55404 | FR22: 18.92788 | FS22: 4.9 | FT22: 5.2 | FU22: 98.50942
... A58: 20/10/2025 | B58: 00:00 | C58: 200.4 | D58: 627.9 | E58: 215.1 | H58: 79.2 | I58: 166 | L58: 103.6 | M58: 103.9 | N58: 103.7 | O58: 213.4 | P58: 216 | Q58: 110.2 | R58: 548 | S58: 3.1 | X58: 168.3 | Y58: 7.4 | Z58: 6.1 | AB58: 6.9 | AC58: 13.1 | AD58: 71.9 | AI58: 109.1 | AJ58: 87.6 | AK58: 0 | AN58: 6.4 | AO58: 295.6 | AP58: 49.9 | AQ58: 151.3 | AR58: 32.2 | AS58: 17.8 | AT58: 18.6 | AU58: 94.4 | AV58: 180 | AW58: 180.5 | AX58: 183.6 | AY58: 108.8 | AZ58: 7.5 | BA58: 8.9 | BB58: 33.1 | BC58: 0 | BD58: 2 | BE58: 12.2 | BF58: 50.7 | BI58: 94.5 | BJ58: 25.8 | BP58: 127 | BS58: 0 | BT58: 0 | CC58: 2.5 | CD58: 198.4 | CF58: 62.2 | CG58: 63.6 | CH58: 29.6 | CL58: 147.4 | CM58: 148.1 | CN58: 149.3 | CV58: 0 | CW58: 38.7 | CX58: 0 | CY58: 10.1 | CZ58: 0 | DA58: 17.5 | DB58: 12.1 | DC58: 10 | DD58: 5.2 | DE58: 0 | DF58: 1.2 | DG58: 3.4 | DH58: 5.1 | DI58: 20.3 | DJ58: 11.6 | DK58: 8.7 | DL58: 3.5 | DM58: 18.6 | DN58: 0 | DO58: 0 | DP58: 9.2 | DQ58: 27.6 | DR58: 0 | DS58: 3.1 | DT58: 20.2 | DU58: 2.9 | DW58: 10 | DX58: 6.6 | DY58: 20.1 | DZ58: 20.1 | EA58: 19.9 | EB58: 15.4 | EC58: 12.8 | ED58: 0 | EE58: 73.2 | EF58: 92.9 | EG58: 8.3 | EH58: 2.6 | EI58: 10.4 | EJ58: 8.3 | EK58: 7.3 | EL58: 20.4 | EM58: 20.4 | EN58: 19.6 | EO58: 9.4 | EP58: 0 | EQ58: 0 | ER58: 0 | ES58: 0.6 | ET58: 29.3 | EU58: 17.7 | EV58: 0 | EW58: 2.1 | EX58: 2.3 | EY58: 2 | EZ58: 1 | FA58: 0 | FB58: 7 | FC58: 20 | FD58: 8.5 | FE58: 27.9 | FF58: 33.9 | FG58: 14.5 | FH58: 19.1 | FI58: 7.7 | FJ58: 11 | FK58: 6454.1 | FM58: 22.1 | FN58: 7.911 | FO58: 6.1105 | FP58: 0 | FQ58: 27.31556 | FR58: 18.9291 | FS58: 4.9 | FT58: 7.1 | FU58: 94.36616
A59: EJEC | C59: 4855.05 | D59: 14832.6 | E59: 5051.45 | F59: 0 | G59: 0 | H59: 1545.7 | I59: 3682.6 | J59: 0 | K59: 0 | L59: 3140.85 | M59: 3142.55 | N59: 3141.4 | O59: 5516.9 | P59: 4053.95 | Q59: 2205.15 | R59: 11190.3 | S59: 78.15 | T59: 0 | U59: 0 | V59: 0 | W59: 0 | X59: 2989.35 | Y59: 184.85 | Z59: 146.75 | AA59: 0 | AB59: 163.15 | AC59: 290.6 | AD59: 1890.15 | AE59: 0 | AF59: 0 | AG59: 0 | AH59: 0 | AI59: 2633.25 | AJ59: 3544.5 | AK59: 133.75 | AL59: 0 | AM59: 0 | AN59: 155.8 | AO59: 5561 | AP59: 1184.45 | AQ59: 3407.25 | AR59: 742.5 | AS59: 404.65 | AT59: 344.95 | AU59: 1677.95 | AV59: 3647.2 | AW59: 3655.1 | AX59: 4036.25 | AY59: 2622.3 | AZ59: 180.65 | BA59: 214.45 | BB59: 799.85 | BC59: 141.6 | BD59: 51 | BE59: 432.5 | BF59: 1312.85 | BG59: 0 | BH59: 0 | BI59: 1778.25 | BJ59: 719.1 | BK59: 0 | BL59: 0 | BM59: 0 | BN59: 0 | BO59: 0 | BP59: 2928.2 | BQ59: 0 | BR59: 0 | BS59: 660.85 | BT59: 90.25 | BU59: 0 | BV59: 0 | BW59: 0 | BX59: 0 | BY59: 0 | BZ59: 0 | CA59: 0 | CB59: 0 | CC59: 60 | CD59: 3927.55 | CE59: 0 | CF59: 1542.65 | CG59: 1547.7 | CH59: 717.35 | CI59: 0 | CJ59: 0 | CK59: 0 | CL59: 3035.9 | CM59: 3032.55 | CN59: 3292.65 | CO59: 0 | CP59: 0 | CQ59: 0 | CR59: 0 | CS59: 0 | CT59: 0 | CU59: 0 | CV59: 9.2 | CW59: 1587.5 | CX59: 824.05 | CY59: 169.4 | CZ59: 3.3 | DA59: 449.95 | DB59: 350.95 | DC59: 237.9 | DD59: 105.2 | DE59: 2189.65 | DF59: 22.7 | DG59: 81.6 | DH59: 117.95 | DI59: 458.3 | DJ59: 322 | DK59: 196 | DL59: 84.55 | DM59: 446.4 | DN59: 164.7 | DO59: 200.5 | DP59: 384.7 | DQ59: 1162.95 | DR59: 177.45 | DS59: 79.3 | DT59: 408.85 | DU59: 55.05 | DV59: 0 | DW59: 237.3 | DX59: 150.05 | DY59: 458.45 | DZ59: 484.45 | EA59: 479.05 | EB59: 358.2 | EC59: 859.35 | ED59: 386.9 | EE59: 1726.95 | EF59: 1994.7 | EG59: 242.05 | EH59: 145.85 | EI59: 250.05 | EJ59: 177.5 | EK59: 167.25 | EL59: 489 | EM59: 489.6 | EN59: 470.4 | EO59: 172.45 | EP59: 2582 | EQ59: 139.85 | ER59: 1539.55 | ES59: 14.4 | ET59: 1349 | EU59: 1265.5 | EV59: 1137 | EW59: 50.4 | EX59: 55.2 | EY59: 48 | EZ59: 24 | FA59: 137.8 | FB59: 164.05 | FC59: 480.15 | FD59: 222.5 | FE59: 657.9 | FF59: 810.95 | FG59: 256.3 | FH59: 313.15 | FI59: 190.1 | FJ59: 260.4 | FK59: 160046.15 | FM59: 530.95 | FN59: 146.3205 | FO59: 146.952 | FP59: 73.755 | FQ59: 650.35741 | FR59: 454.22719 | FS59: 113.5 | FT59: 198.5 | FU59: 2314.5621

Sheet REACTIVA
B3: domingo, 19 de Octubre del 2025
A5: POTENCIA REACTIVA EJECUTADA DE LAS UNIDADES DE GENERACIÓN DEL COES (MVAR) | FM5: CENTRALES NO INTEGRANTES COES
A6: FECHA | B6: HORA | C6: 65333 | D6: 101 | E6: 102 | F6: 42667 | G6: 42668 | H6: 126 | I6: 127 | J6: 138 | K6: 139 | L6: 197 | M6: 203 | N6: 204 | O6: 230 | P6: 209 | Q6: 56677 | R6: 796 | S6: 2146 | T6: 142 | U6: 143 | V6: 125 | W6: 187 | X6: 163 | Y6: 298 | Z6: 299 | AA6: 219 | AB6: 151 | AC6: 152 | AD6: 153 | AE6: 154 | AF6: 756 | AG6: 156 | AH6: 155 | AI6: 182 | AJ6: 212 | AK6: 758 | AL6: 263 | AM6: 265 | AN6: 775 | AO6: 777 | AP6: 2154 | AQ6: 150 | AR6: 149 | AS6: 188 | AT6: 2131 | AU6: 755 | AV6: 252 | AW6: 249 | AX6: 250 | AY6: 117 | AZ6: 267 | BA6: 268 | BB6: 119 | BC6: 120 | BD6: 189 | BE6: 122 | BF6: 266 | BG6: 337 | BH6: 338 | BI6: 251 | BJ6: 115 | BK6: 239 | BL6: 288 | BM6: 240 | BN6: 241 | BO6: 242 | BP6: 191 | BQ6: 194 | BR6: 196 | BS6: 207 | BT6: 236 | BU6: 795 | BV6: 285 | BW6: 995 | BX6: 996 | BY6: 997 | BZ6: 766 | CA6: 926 | CB6: 924 | CC6: 121 | CD6: 103 | CE6: 104 | CF6: 106 | CG6: 105 | CH6: 107 | CI6: 110 | CJ6: 109 | CK6: 144 | CL6: 113 | CM6: 114 | CN6: 193 | CO6: 208 | CP6: 786 | CQ6: 787 | CR6: 788 | CS6: 789 | CT6: 248 | CU6: 2159 | CV6: 303 | CW6: 59715 | CX6: 62255 | CY6: 1263 | CZ6: 61800 | DA6: 2194 | DB6: 69125 | DC6: 216 | DD6: 198 | DE6: 70400 | DF6: 49607 | DG6: 214 | DH6: 260 | DI6: 2152 | DJ6: 2128 | DK6: 247 | DL6: 228 | DM6: 2135 | DN6: 261 | DO6: 237 | DP6: 253 | DQ6: 770 | DR6: 235 | DS6: 238 | DT6: 2184 | DU6: 61855 | DV6: 223 | DW6: 226 | DX6: 201 | DY6: 258 | DZ6: 259 | EA6: 920 | EB6: 257 | EC6: 256 | ED6: 2148 | EE6: 58288 | EF6: 58289 | EG6: 58839 | EH6: 58840 | EI6: 296 | EJ6: 297 | EK6: 211 | EL6: 2175 | EM6: 2178 | EN6: 2181 | EO6: 1262 | EP6: 63425 | EQ6: 233 | ER6: 2150 | ES6: 2165 | ET6: 2161 | EU6: 61197 | EV6: 58851 | EW6: 225 | EX6: 2201 | EY6: 2171 | EZ6: 760 | FA6: 234 | FB6: 215 | FC6: 917 | FD6: 289 | FE6: 58333 | FF6: 58336 | FG6: 213 | FH6: 232 | FI6: 2190 | FJ6: 69867 | FK6: TOTAL COES | FM6: 221 | FN6: 222 | FO6: 224 | FP6: 2187 | FQ6: 227 | FR6: 49400 | FS6: 199 | FT6: 200 | FU6: TOTAL NO COES
C7: SUR | D7: CENTRO | E7: CENTRO | F7: NORTE | G7: NORTE | H7: NORTE | I7: NORTE | J7: CENTRO | K7: CENTRO | L7: CENTRO | M7: CENTRO | N7: CENTRO | O7: CENTRO | P7: CENTRO | Q7: CENTRO | R7: CENTRO | S7: CENTRO | T7: CENTRO | U7: CENTRO | V7: CENTRO | W7: CENTRO | X7: SUR | Y7: SUR | Z7: SUR | AA7: CENTRO | AB7: SUR | AC7: SUR | AD7: SUR | AE7: SUR | AF7: SUR | AG7: SUR | AH7: SUR | AI7: SUR | AJ7: CENTRO | AK7: NORTE | AL7: NORTE | AM7: NORTE | AN7: CENTRO | AO7: CENTRO | AP7: CENTRO | AQ7: CENTRO | AR7: CENTRO | AS7: CENTRO | AT7: CENTRO | AU7: SUR | AV7: CENTRO | AW7: CENTRO | AX7: CENTRO | AY7: CENTRO | AZ7: CENTRO | BA7: CENTRO | BB7: CENTRO | BC7: CENTRO | BD7: SUR | BE7: NORTE | BF7: CENTRO | BG7: CENTRO | BH7: CENTRO | BI7: CENTRO | BJ7: NORTE | BK7: NORTE | BL7: NORTE | BM7: SUR | BN7: SUR | BO7: SUR | BP7: CENTRO | BQ7: CENTRO | BR7: CENTRO | BS7: CENTRO | BT7: CENTRO | BU7: CENTRO | BV7: CENTRO | BW7: SUR | BX7: SUR | BY7: SUR | BZ7: NORTE | CA7: SUR | CB7: CENTRO | CC7: NORTE | CD7: CENTRO | CE7: CENTRO | CF7: CENTRO | CG7: CENTRO | CH7: CENTRO | CI7: CENTRO | CJ7: CENTRO | CK7: CENTRO | CL7: CENTRO | CM7: CENTRO | CN7: CENTRO | CO7: CENTRO | CP7: SUR | CQ7: SUR | CR7: SUR | CS7: SUR | CT7: CENTRO | CU7: CENTRO | CV7: CENTRO | CW7: CENTRO | CX7: SUR | CY7: NORTE | CZ7: NORTE | DA7: NORTE | DB7: CENTRO | DC7: NORTE | DD7: NORTE | DE7: SUR | DF7: SUR | DG7: CENTRO | DH7: CENTRO | DI7: CENTRO | DJ7: NORTE | DK7: NORTE | DL7: CENTRO | DM7: CENTRO | DN7: SUR | DO7: SUR | DP7: CENTRO | DQ7: CENTRO | DR7: SUR | DS7: CENTRO | DT7: CENTRO | DU7: NORTE | DV7: CENTRO | DW7: CENTRO | DX7: NORTE | DY7: CENTRO | DZ7: CENTRO | EA7: CENTRO | EB7: NORTE | EC7: NORTE | ED7: SUR | EE7: CENTRO | EF7: CENTRO | EG7: CENTRO | EH7: CENTRO | EI7: CENTRO | EJ7: CENTRO | EK7: SUR | EL7: SUR | EM7: SUR | EN7: SUR | EO7: NORTE | EP7: SUR | EQ7: SUR | ER7: SUR | ES7: CENTRO | ET7: CENTRO | EU7: CENTRO | EV7: SUR | EW7: CENTRO | EX7: CENTRO | EY7: CENTRO | EZ7: CENTRO | FA7: SUR | FB7: NORTE | FC7: CENTRO | FD7: NORTE | FE7: NORTE | FF7: NORTE | FG7: CENTRO | FH7: NORTE | FI7: NORTE | FJ7: NORTE | FM7: NORTE | FN7: CENTRO | FO7: NORTE | FP7: NORTE | FQ7: NORTE | FR7: NORTE | FS7: NORTE | FT7: NORTE
C8: HIDROELÉCTRICA | D8: HIDROELÉCTRICA | E8: HIDROELÉCTRICA | F8: TERMOELÉCTRICA | G8: TERMOELÉCTRICA | H8: HIDROELÉCTRICA | I8: HIDROELÉCTRICA | J8: TERMOELÉCTRICA | K8: TERMOELÉCTRICA | L8: TERMOELÉCTRICA | M8: TERMOELÉCTRICA | N8: TERMOELÉCTRICA | O8: TERMOELÉCTRICA | P8: TERMOELÉCTRICA | Q8: TERMOELÉCTRICA | R8: HIDROELÉCTRICA | S8: HIDROELÉCTRICA | T8: TERMOELÉCTRICA | U8: TERMOELÉCTRICA | V8: TERMOELÉCTRICA | W8: TERMOELÉCTRICA | X8: HIDROELÉCTRICA | Y8: HIDROELÉCTRICA | Z8: HIDROELÉCTRICA | AA8: TERMOELÉCTRICA | AB8: HIDROELÉCTRICA | AC8: HIDROELÉCTRICA | AD8: HIDROELÉCTRICA | AE8: HIDROELÉCTRICA | AF8: TERMOELÉCTRICA | AG8: TERMOELÉCTRICA | AH8: TERMOELÉCTRICA | AI8: HIDROELÉCTRICA | AJ8: HIDROELÉCTRICA | AK8: TERMOELÉCTRICA | AL8: TERMOELÉCTRICA | AM8: TERMOELÉCTRICA | AN8: HIDROELÉCTRICA | AO8: HIDROELÉCTRICA | AP8: HIDROELÉCTRICA | AQ8: HIDROELÉCTRICA | AR8: HIDROELÉCTRICA | AS8: HIDROELÉCTRICA | AT8: HIDROELÉCTRICA | AU8: HIDROELÉCTRICA | AV8: TERMOELÉCTRICA | AW8: TERMOELÉCTRICA | AX8: TERMOELÉCTRICA | AY8: HIDROELÉCTRICA | AZ8: HIDROELÉCTRICA | BA8: HIDROELÉCTRICA | BB8: HIDROELÉCTRICA | BC8: HIDROELÉCTRICA | BD8: HIDROELÉCTRICA | BE8: HIDROELÉCTRICA | BF8: HIDROELÉCTRICA | BG8: HIDROELÉCTRICA | BH8: HIDROELÉCTRICA | BI8: HIDROELÉCTRICA | BJ8: TERMOELÉCTRICA | BK8: TERMOELÉCTRICA | BL8: TERMOELÉCTRICA | BM8: TERMOELÉCTRICA | BN8: TERMOELÉCTRICA | BO8: TERMOELÉCTRICA | BP8: HIDROELÉCTRICA | BQ8: TERMOELÉCTRICA | BR8: TERMOELÉCTRICA | BS8: TERMOELÉCTRICA | BT8: TERMOELÉCTRICA | BU8: TERMOELÉCTRICA | BV8: TERMOELÉCTRICA | BW8: TERMOELÉCTRICA | BX8: TERMOELÉCTRICA | BY8: TERMOELÉCTRICA | BZ8: HIDROELÉCTRICA | CA8: TERMOELÉCTRICA | CB8: TERMOELÉCTRICA | CC8: HIDROELÉCTRICA | CD8: HIDROELÉCTRICA | CE8: HIDROELÉCTRICA | CF8: HIDROELÉCTRICA | CG8: HIDROELÉCTRICA | CH8: HIDROELÉCTRICA | CI8: TERMOELÉCTRICA | CJ8: TERMOELÉCTRICA | CK8: TERMOELÉCTRICA | CL8: TERMOELÉCTRICA | CM8: TERMOELÉCTRICA | CN8: TERMOELÉCTRICA | CO8: TERMOELÉCTRICA | CP8: TERMOELÉCTRICA | CQ8: TERMOELÉCTRICA | CR8: TERMOELÉCTRICA | CS8: TERMOELÉCTRICA | CT8: TERMOELÉCTRICA | CU8: TERMOELÉCTRICA | CV8: SOLAR | CW8: EÓLICA | CX8: SOLAR | CY8: EÓLICA | CZ8: SOLAR | DA8: HIDROELÉCTRICA | DB8: HIDROELÉCTRICA | DC8: HIDROELÉCTRICA | DD8: HIDROELÉCTRICA | DE8: SOLAR | DF8: HIDROELÉCTRICA | DG8: HIDROELÉCTRICA | DH8: HIDROELÉCTRICA | DI8: HIDROELÉCTRICA | DJ8: HIDROELÉCTRICA | DK8: HIDROELÉCTRICA | DL8: HIDROELÉCTRICA | DM8: HIDROELÉCTRICA | DN8: SOLAR | DO8: SOLAR | DP8: EÓLICA | DQ8: EÓLICA | DR8: SOLAR | DS8: HIDROELÉCTRICA | DT8: HIDROELÉCTRICA | DU8: HIDROELÉCTRICA | DV8: HIDROELÉCTRICA | DW8: HIDROELÉCTRICA | DX8: HIDROELÉCTRICA | DY8: HIDROELÉCTRICA | DZ8: HIDROELÉCTRICA | EA8: HIDROELÉCTRICA | EB8: EÓLICA | EC8: EÓLICA | ED8: SOLAR | EE8: EÓLICA | EF8: EÓLICA | EG8: EÓLICA | EH8: EÓLICA | EI8: HIDROELÉCTRICA | EJ8: HIDROELÉCTRICA | EK8: HIDROELÉCTRICA | EL8: HIDROELÉCTRICA | EM8: HIDROELÉCTRICA | EN8: HIDROELÉCTRICA | EO8: EÓLICA | EP8: SOLAR | EQ8: SOLAR | ER8: SOLAR | ES8: HIDROELÉCTRICA | ET8: EÓLICA | EU8: EÓLICA | EV8: SOLAR | EW8: TERMOELÉCTRICA | EX8: TERMOELÉCTRICA | EY8: TERMOELÉCTRICA | EZ8: TERMOELÉCTRICA | FA8: SOLAR | FB8: HIDROELÉCTRICA | FC8: HIDROELÉCTRICA | FD8: TERMOELÉCTRICA | FE8: TERMOELÉCTRICA | FF8: TERMOELÉCTRICA | FG8: TERMOELÉCTRICA | FH8: TERMOELÉCTRICA | FI8: TERMOELÉCTRICA | FJ8: TERMOELÉCTRICA | FM8: HIDROELÉCTRICA | FN8: HIDROELÉCTRICA | FO8: HIDROELÉCTRICA | FP8: HIDROELÉCTRICA | FQ8: TERMOELÉCTRICA | FR8: TERMOELÉCTRICA | FS8: HIDROELÉCTRICA | FT8: HIDROELÉCTRICA
