Workbook

Sheet EVENTOS
B3: sábado, 15 de Marzo del 2025
B5: INFORMACIÓN DE EVENTOS PRINCIPALES EN SUS INSTALACIONES
B6: TIPO DE EVENTO | C6: EMPRESA | D6: UBICACIÓN | E6: TIPO DE EQUIPO | F6: EQUIPO | G6: INICIO | H6: FINAL | I6: DESCRIPCIÓN | J6: MW INDISP. | K6: INTERRUPCIÓN (SI/NO) | L6: TENSIÓN DE FALLA (kV)
B7: EVENTO | C7: CONELSUR LT SAC | D7: PORTILLO | E7: SUBESTACION | F7: SS.EE. | G7: 15/03/2025 00:00:00 | H7: 16/03/2025 00:00:00 | I7: DECLARACIÓN DE SITUACIÓN EXCEPCIONAL EN LA S.E. PORTILLO DE 60 kV | K7: NO
B8: EVENTO | C8: RED DE ENERGIA DEL PERU S.A. | D8: TINGO MARÍA - AUCAYACU | E8: LINEA DE TRANSMISION | F8: L-1122 | G8: 15/03/2025 18:31:00 | H8: 16/03/2025 00:00:00 | I8: DECLARACIÓN DE SITUACIÓN EXCEPCIONAL EN LA LÍNEA L-1122 (TINGO MARÍA - AUCAYACU) DE 138 kV | K8: NO
B9: FALLA | C9: TRANSMISORA ELECTRICA DEL SUR S.A.C | D9: TINTAYA NUEVA - SOCABAYA | E9: LINEA DE TRANSMISION | F9: L-2023 | G9: 15/03/2025 15:44:00 | H9: 15/03/2025 15:57:00 | I9: DESCONEXIÓN DE LA LÍNEA L-2023 (SOCABAYA - TINTAYA NUEVA) DE 220 KV | J9: 0.8 | K9: SI | L9: 220

Sheet RESTRIC_OPE
B3: sábado, 15 de Marzo del 2025
B5: RESTRICCIONES OPERATIVAS
B6: FECHA | C6: HORA INICIO | D6: HORA FINAL | E6: EMPRESA | F6: UBICACIÓN | G6: T.Eq. | H6: EQUIPO | I6: DESCRIPCIÓN
B7: 15/03/2025 | C7: 00:00 | D7: 24:00 | E7: CELEPSA | F7: C.H. EL PLATANAL | G7: CH | H7: CENTRAL | I7: Debido al incremento del caudal del rio cañete y establecimiento de la temporada de avenida, se declara la C.H. El Platanal como CENTRAL HIDRÁULICA DE PASADA (correo 03/01/2025).
B8: 15/03/2025 | C8: 00:00 | D8: 24:00 | E8: EGASA | F8: C.H. CHARCANI II | G8: GH | H8: G2 | I8: El Grupo N°02 esta operando con una potencia no mayor a 0.07MW en referencia a 0.18MW de su potencia efectiva, con el fin de no generar daños mayores hasta la reparación de su cojinete.
B9: 15/03/2025 | C9: 00:00 | D9: 24:00 | E9: EGASA | F9: S.E. CONVERTIDOR | G9: BARRA | H9: BARRA138KV | I9: EGASA limitó la capacidad del transformador 138 kV/33 kV a 50 MVA por deterioro del aislamiento.
B10: 15/03/2025 | C10: 00:00 | D10: 24:00 | E10: ENEL GENERACION PIURA S.A. | F10: C.T. MALACAS | G10: CT | H10: CENTRAL | I10: De acuerdo con la comunicación vía correo del día 24.10.2024. ENEL GENERACIÓN PIURA informa una restricción de potencia para alcanzar 105 MW en simultaneo (TG6+TGN4).
B11: 15/03/2025 | C11: 00:00 | D11: 24:00 | E11: ENGIE | F11: C.E. PUNTA LOMITAS | G11: CE | H11: CENTRAL | I11: De acuerdo a la carta ENG/737-2024 (Exp:202400007555). Limitación de cables de media tensión a 100 MW de los transformadores PLT1 y PLT2 de la CE Punta Lomitas. Quedan limitados a 200 MW la generación de CE Punta Lomitas y Punta Lomitas Extensión.
B12: 15/03/2025 | C12: 00:00 | D12: 24:00 | E12: ENGIE | F12: C.H. QUITARACSA | G12: CH | H12: CENTRAL | I12: De acuerdo con el correo del 23.04 se considera la operación continua de la CH Quitaracsa debido a que el sistema de refrigeración de la CH Cañón del Pato se alimenta desde la descarga del caudal turbinado por la CH Quitaracsa.
B13: 15/03/2025 | C13: 00:00 | D13: 24:00 | E13: ENGIE | F13: C.H. YUNCÁN | G13: GH | H13: G3 | I13: Según la carta N° ENG/ 198-2024 enviada por su representada, se opera de forma continua el G3 de la CH Yuncán, debido a la ejecución de mantenimientos necesarios para evitar daños en los sellos de seguridad de la válvula esférica del grupo.
B14: 15/03/2025 | C14: 00:00 | D14: 24:00 | E14: ENGIE | F14: C.T. CHILCA 1 | G14: CT | H14: CENTRAL | I14: Restricción de temperatura de la C.T Chilca, ver valor en el modelo de despacho.
B15: 15/03/2025 | C15: 00:00 | D15: 24:00 | E15: ENGIE | F15: C.T. CHILCA 1 | G15: CT | H15: CENTRAL | I15: Con carta ENG/971-2023, indica que no puede cumplir con las IO considerada en el PDO_17122023 dado que vulneran la seguridad de sus activos. Indican que se debe tomar TMO=168h.
B16: 15/03/2025 | C16: 00:00 | D16: 24:00 | E16: ENGIE | F16: C.T. CHILCA 2 | G16: CT | H16: CENTRAL | I16: Con carta ENG/971-2023, indica que no puede cumplir con las IO considerada en el PDO_17122023 dado que vulneran la seguridad de sus activos. Indican que se debe tomar TMO=168h.
B17: 15/03/2025 | C17: 00:00 | D17: 24:00 | E17: ENGIE | F17: C.T. CHILCA 2 | G17: CT | H17: CENTRAL | I17: Restricción de temperatura de la C.T Chilca2, ver valor en el modelo de despacho.
... B50: 15/03/2025 | C50: 00:00 | D50: 24:00 | E50: TRANSMANTARO | F50: S.E. SOCABAYA | G50: SSEE | H50: S.E. | I50: Opera en simple barra en 220 kV por indisponibilidad de la protección diferencial de barras por alarma.

Sheet MANTENIMIENTO EJECUTADOS
B3: sábado, 15 de Marzo del 2025
B5: Mantenimiento Ejecutado
B6: Empresa | C6: Ubicación | D6: Equipo | E6: Inicio | F6: Final | G6: Descripción | H6: MW Indisp. | I6: Prog. | J6: Dispon | K6: Interrupc. | L6: Tipo | M6: CodEq | N6: TipoEq_Osinerg
B7: AGRO INDUSTRIAL PARAMONGA S.A. | C7: PARAMONGA | D7: TV-01 | E7: 15/03/2025 00:00 | F7: 15/03/2025 18:44 | G7: LIMPIEZA E INSPECCION DE LA CALDERA CBS Y MANTENIMIENTO A SUS PERIFERICOS (CONDUCTORES, VENTILADORES, BOMBAS, MOTORES, ETC) | H7: 14 | I7: P | J7: F/S | K7: N | L7: PREV. | M7: 12664 | N7: G
B8: ATLANTICA TRANSMISION SUR S.A. | C8: CHILCA-CTM | D8: INT-5261 | E8: 15/03/2025 00:00 | F8: 16/03/2025 00:00 | G8: Seccionador SBB-5261 fase S indisponible para maniobras de apertura y cierre por anomalia en tapa de tanque de compresion, el seccionador permanece cerrado y bloqueado. | H8: 0 | I8: P | J8: E/S | K8: N | L8: OTROS | M8: 13854 | N8: T
B9: ATLANTICA TRANSMISION SUR S.A. | C9: MONTALVO | D9: ACOPLE 220 | E9: 15/03/2025 00:00 | F9: 16/03/2025 00:00 | G9: Proyecto Refuerzos: Reemplazo del HMI existente, Pruebas y Configuracion. No se contara con nivel 1 de operacion. | H9: 0 | I9: P | J9: E/S | K9: N | L9: P.ENERG | M9: 14767 | N9: T
B10: ATLANTICA TRANSMISION SUR S.A. | C10: MONTALVO | D10: CL-2057 | E10: 15/03/2025 00:00 | F10: 16/03/2025 00:00 | G10: Proyecto Refuerzos: Reemplazo del HMI existente, Pruebas y Configuracion. No se contara con nivel 1 de operacion. | H10: 0 | I10: P | J10: E/S | K10: N | L10: P.ENERG | M10: 13812 | N10: T
B11: ATLANTICA TRANSMISION SUR S.A. | C11: MONTALVO | D11: CL-AUT-5671_500 | E11: 15/03/2025 00:00 | F11: 16/03/2025 00:00 | G11: Proyecto Refuerzos: Reemplazo del HMI existente, Pruebas y Configuracion. No se contara con nivel 1 de operacion en INT-5671, INT-5652 y SAT-5671. | H11: 0 | I11: P | J11: E/S | K11: N | L11: P.ENERG | M11: 13809 | N11: T
B12: ATLANTICA TRANSMISION SUR S.A. | C12: MONTALVO | D12: INT-5652 | E12: 15/03/2025 00:00 | F12: 16/03/2025 00:00 | G12: Proyecto Refuerzos:Indisponible por Implementacion de conexion de corrientes, disparos, posiciones, enclavamientos hacia los nuevos equipos del transformador. Pruebas y Puesta en servicio. AUT-5671 en servicio solo por Barra A 500kV. | H12: 0 | I12: P | J12: F/S | K12: N | L12: P.ENERG | M12: 13765 | N12: T
B13: ATLANTICA TRANSMISION SUR S.A. | C13: OCONA | D13: INT-5450 | E13: 15/03/2025 00:00 | F13: 16/03/2025 00:00 | G13: RESTRICCION OPERATIVA EN INTERRUPTOR INT-5450, POSICION CERRADA, REB-5450 EN SERVICIO SUMINISTRANDO LOS SS.AA. DE S.E. OCO?A | H13: 0 | I13: P | J13: E/S | K13: N | L13: OTROS | M13: 13761 | N13: T
B14: ATLANTICA TRANSMISION SUR S.A. | C14: OCONA | D14: INT-5462 | E14: 15/03/2025 00:00 | F14: 16/03/2025 00:00 | G14: Seccionador SBA-5462 fase T indisponible por problemas mecanicos, el seccionador permanece cerrado y bloqueado | H14: 0 | I14: P | J14: E/S | K14: N | L14: OTROS | M14: 13758 | N14: T
B15: ATLANTICA TRANSMISION SUR S.A. | C15: POROMA | D15: ACOPLE 220 | E15: 15/03/2025 00:00 | F15: 16/03/2025 00:00 | G15: Proyecto Refuerzos: Reemplazo del HMI existente, Pruebas y Configuracion. No se contara con nivel 1 de operacion. | H15: 0 | I15: P | J15: E/S | K15: N | L15: P.ENERG | M15: 13797 | N15: T
B16: ATLANTICA TRANSMISION SUR S.A. | C16: POROMA | D16: CL-2292 | E16: 15/03/2025 00:00 | F16: 16/03/2025 00:00 | G16: Proyecto Refuerzos: Reemplazo del HMI existente, Pruebas y Configuracion. No se contara con nivel 1 de operacion. | H16: 0 | I16: P | J16: E/S | K16: N | L16: P.ENERG | M16: 13798 | N16: T
B17: ATLANTICA TRANSMISION SUR S.A. | C17: POROMA | D17: CL-2293 | E17: 15/03/2025 00:00 | F17: 16/03/2025 00:00 | G17: Proyecto Refuerzos: Reemplazo del HMI existente, Pruebas y Configuracion. No se contara con nivel 1 de operacion. | H17: 0 | I17: P | J17: E/S | K17: N | L17: P.ENERG | M17: 13799 | N17: T
B18: ATLANTICA TRANSMISION SUR S.A. | C18: POROMA | D18: CL-AUT5371_220 | E18: 15/03/2025 00:00 | F18: 16/03/2025 00:00 | G18: Proyecto Refuerzos: Reemplazo del HMI existente, Pruebas y Configuracion. No se contara con nivel 1 de operacion. | H18: 0 | I18: P | J18: E/S | K18: N | L18: P.ENERG | M18: 13796 | N18: T
... B113: TRANSMANTARO | C113: YARABAMBA | D113: IN-5120 | E113: 15/03/2025 00:00 | F113: 16/03/2025 00:00 | G113: INTERRUPTOR INDISPONIBLE POR FALLA EN LOS MANDOS DE CONTROL DE N1, N2 Y N3. | H113: 0 | I113: P | J113: F/S | K113: N | L113: OTROS | M113: 17437 | N113: T

Sheet INGRESO OC
A3: sábado, 15 de Marzo del 2025
A5: INGRESO A OPERACIÓN COMERCIAL
A6: EMPRESA | B6: TIPO DE EQUIPO | C6: UBICACIÓN | D6: EQUIPO | E6: Fecha y hora de Ingreso a Operación Comercial

Sheet DESPACHO_EJECUTADO
B3: sábado, 15 de Marzo del 2025
A5: POTENCIA ACTIVA EJECUTADA DE LAS UNIDADES DE GENERACIÓN DEL SEIN (MW) | FJ5: CENTRALES NO INTEGRANTES COES
A6: FECHA | B6: HORA | C6: 337 | D6: 338 | E6: 101 | F6: 102 | G6: 42667 | H6: 42668 | I6: 126 | J6: 127 | K6: 138 | L6: 139 | M6: 197 | N6: 203 | O6: 204 | P6: 230 | Q6: 209 | R6: 56677 | S6: 796 | T6: 2146 | U6: 142 | V6: 143 | W6: 125 | X6: 187 | Y6: 163 | Z6: 298 | AA6: 299 | AB6: 219 | AC6: 151 | AD6: 152 | AE6: 153 | AF6: 154 | AG6: 756 | AH6: 156 | AI6: 155 | AJ6: 182 | AK6: 212 | AL6: 758 | AM6: 263 | AN6: 265 | AO6: 775 | AP6: 777 | AQ6: 2154 | AR6: 150 | AS6: 149 | AT6: 188 | AU6: 2131 | AV6: 755 | AW6: 252 | AX6: 249 | AY6: 250 | AZ6: 117 | BA6: 267 | BB6: 268 | BC6: 119 | BD6: 120 | BE6: 189 | BF6: 122 | BG6: 266 | BH6: 251 | BI6: 115 | BJ6: 239 | BK6: 288 | BL6: 240 | BM6: 241 | BN6: 242 | BO6: 191 | BP6: 194 | BQ6: 196 | BR6: 207 | BS6: 236 | BT6: 795 | BU6: 285 | BV6: 995 | BW6: 996 | BX6: 997 | BY6: 766 | BZ6: 926 | CA6: 924 | CB6: 121 | CC6: 103 | CD6: 104 | CE6: 106 | CF6: 105 | CG6: 107 | CH6: 110 | CI6: 109 | CJ6: 144 | CK6: 113 | CL6: 114 | CM6: 193 | CN6: 208 | CO6: 786 | CP6: 787 | CQ6: 788 | CR6: 789 | CS6: 248 | CT6: 2159 | CU6: 303 | CV6: 59715 | CW6: 62255 | CX6: 1263 | CY6: 61800 | CZ6: 2194 | DA6: 216 | DB6: 198 | DC6: 49607 | DD6: 214 | DE6: 260 | DF6: 2152 | DG6: 2128 | DH6: 247 | DI6: 228 | DJ6: 2135 | DK6: 261 | DL6: 237 | DM6: 253 | DN6: 770 | DO6: 225 | DP6: 2201 | DQ6: 2171 | DR6: 760 | DS6: 235 | DT6: 238 | DU6: 2184 | DV6: 61855 | DW6: 223 | DX6: 226 | DY6: 201 | DZ6: 258 | EA6: 259 | EB6: 920 | EC6: 257 | ED6: 256 | EE6: 2148 | EF6: 58288 | EG6: 58289 | EH6: 58839 | EI6: 58840 | EJ6: 296 | EK6: 297 | EL6: 211 | EM6: 2175 | EN6: 2178 | EO6: 2181 | EP6: 1262 | EQ6: 233 | ER6: 2150 | ES6: 2165 | ET6: 2161 | EU6: 61197 | EV6: 58851 | EW6: 234 | EX6: 215 | EY6: 917 | EZ6: 289 | FA6: 58333 | FB6: 58336 | FC6: 202 | FD6: 58487 | FE6: 213 | FF6: 232 | FG6: 2190 | FH6: TOTAL COES | FJ6: 221 | FK6: 222 | FL6: 224 | FM6: 2187 | FN6: 227 | FO6: 49400 | FP6: 199 | FQ6: 200 | FR6: TOTAL NO COES
C7: CENTRO | D7: CENTRO | E7: CENTRO | F7: CENTRO | G7: NORTE | H7: NORTE | I7: NORTE | J7: NORTE | K7: CENTRO | L7: CENTRO | M7: CENTRO | N7: CENTRO | O7: CENTRO | P7: CENTRO | Q7: CENTRO | R7: CENTRO | S7: CENTRO | T7: CENTRO | U7: CENTRO | V7: CENTRO | W7: CENTRO | X7: CENTRO | Y7: SUR | Z7: SUR | AA7: SUR | AB7: CENTRO | AC7: SUR | AD7: SUR | AE7: SUR | AF7: SUR | AG7: SUR | AH7: SUR | AI7: SUR | AJ7: SUR | AK7: CENTRO | AL7: NORTE | AM7: NORTE | AN7: NORTE | AO7: CENTRO | AP7: CENTRO | AQ7: CENTRO | AR7: CENTRO | AS7: CENTRO | AT7: CENTRO | AU7: CENTRO | AV7: SUR | AW7: CENTRO | AX7: CENTRO | AY7: CENTRO | AZ7: CENTRO | BA7: CENTRO | BB7: CENTRO | BC7: CENTRO | BD7: CENTRO | BE7: SUR | BF7: NORTE | BG7: CENTRO | BH7: CENTRO | BI7: NORTE | BJ7: NORTE | BK7: NORTE | BL7: SUR | BM7: SUR | BN7: SUR | BO7: CENTRO | BP7: CENTRO | BQ7: CENTRO | BR7: CENTRO | BS7: CENTRO | BT7: CENTRO | BU7: CENTRO | BV7: SUR | BW7: SUR | BX7: SUR | BY7: NORTE | BZ7: SUR | CA7: CENTRO | CB7: NORTE | CC7: CENTRO | CD7: CENTRO | CE7: CENTRO | CF7: CENTRO | CG7: CENTRO | CH7: CENTRO | CI7: CENTRO | CJ7: CENTRO | CK7: CENTRO | CL7: CENTRO | CM7: CENTRO | CN7: CENTRO | CO7: SUR | CP7: SUR | CQ7: SUR | CR7: SUR | CS7: CENTRO | CT7: CENTRO | CU7: CENTRO | CV7: CENTRO | CW7: SUR | CX7: NORTE | CY7: NORTE | CZ7: NORTE | DA7: NORTE | DB7: NORTE | DC7: SUR | DD7: CENTRO | DE7: CENTRO | DF7: CENTRO | DG7: NORTE | DH7: NORTE | DI7: CENTRO | DJ7: CENTRO | DK7: SUR | DL7: SUR | DM7: CENTRO | DN7: CENTRO | DO7: CENTRO | DP7: CENTRO | DQ7: CENTRO | DR7: CENTRO | DS7: SUR | DT7: CENTRO | DU7: CENTRO | DV7: NORTE | DW7: CENTRO | DX7: CENTRO | DY7: NORTE | DZ7: CENTRO | EA7: CENTRO | EB7: CENTRO | EC7: NORTE | ED7: NORTE | EE7: SUR | EF7: CENTRO | EG7: CENTRO | EH7: CENTRO | EI7: CENTRO | EJ7: CENTRO | EK7: CENTRO | EL7: SUR | EM7: SUR | EN7: SUR | EO7: SUR | EP7: NORTE | EQ7: SUR | ER7: SUR | ES7: CENTRO | ET7: CENTRO | EU7: CENTRO | EV7: SUR | EW7: SUR | EX7: NORTE | EY7: CENTRO | EZ7: NORTE | FA7: NORTE | FB7: NORTE | FC7: CENTRO | FD7: CENTRO | FE7: CENTRO | FF7: NORTE | FG7: NORTE | FJ7: NORTE | FK7: CENTRO | FL7: NORTE | FM7: NORTE | FN7: NORTE | FO7: NORTE | FP7: NORTE | FQ7: NORTE
C8: HIDROELÉCTRICA | D8: HIDROELÉCTRICA | E8: HIDROELÉCTRICA | F8: HIDROELÉCTRICA | G8: TERMOELÉCTRICA | H8: TERMOELÉCTRICA | I8: HIDROELÉCTRICA | J8: HIDROELÉCTRICA | K8: TERMOELÉCTRICA | L8: TERMOELÉCTRICA | M8: TERMOELÉCTRICA | N8: TERMOELÉCTRICA | O8: TERMOELÉCTRICA | P8: TERMOELÉCTRICA | Q8: TERMOELÉCTRICA | R8: TERMOELÉCTRICA | S8: HIDROELÉCTRICA | T8: HIDROELÉCTRICA | U8: TERMOELÉCTRICA | V8: TERMOELÉCTRICA | W8: TERMOELÉCTRICA | X8: TERMOELÉCTRICA | Y8: HIDROELÉCTRICA | Z8: HIDROELÉCTRICA | AA8: HIDROELÉCTRICA | AB8: TERMOELÉCTRICA | AC8: HIDROELÉCTRICA | AD8: HIDROELÉCTRICA | AE8: HIDROELÉCTRICA | AF8: HIDROELÉCTRICA | AG8: TERMOELÉCTRICA | AH8: TERMOELÉCTRICA | AI8: TERMOELÉCTRICA | AJ8: HIDROELÉCTRICA | AK8: HIDROELÉCTRICA | AL8: TERMOELÉCTRICA | AM8: TERMOELÉCTRICA | AN8: TERMOELÉCTRICA | AO8: HIDROELÉCTRICA | AP8: HIDROELÉCTRICA | AQ8: HIDROELÉCTRICA | AR8: HIDROELÉCTRICA | AS8: HIDROELÉCTRICA | AT8: HIDROELÉCTRICA | AU8: HIDROELÉCTRICA | AV8: HIDROELÉCTRICA | AW8: TERMOELÉCTRICA | AX8: TERMOELÉCTRICA | AY8: TERMOELÉCTRICA | AZ8: HIDROELÉCTRICA | BA8: HIDROELÉCTRICA | BB8: HIDROELÉCTRICA | BC8: HIDROELÉCTRICA | BD8: HIDROELÉCTRICA | BE8: HIDROELÉCTRICA | BF8: HIDROELÉCTRICA | BG8: HIDROELÉCTRICA | BH8: HIDROELÉCTRICA | BI8: TERMOELÉCTRICA | BJ8: TERMOELÉCTRICA | BK8: TERMOELÉCTRICA | BL8: TERMOELÉCTRICA | BM8: TERMOELÉCTRICA | BN8: TERMOELÉCTRICA | BO8: HIDROELÉCTRICA | BP8: TERMOELÉCTRICA | BQ8: TERMOELÉCTRICA | BR8: TERMOELÉCTRICA | BS8: TERMOELÉCTRICA | BT8: TERMOELÉCTRICA | BU8: TERMOELÉCTRICA | BV8: TERMOELÉCTRICA | BW8: TERMOELÉCTRICA | BX8: TERMOELÉCTRICA | BY8: HIDROELÉCTRICA | BZ8: TERMOELÉCTRICA | CA8: TERMOELÉCTRICA | CB8: HIDROELÉCTRICA | CC8: HIDROELÉCTRICA | CD8: HIDROELÉCTRICA | CE8: HIDROELÉCTRICA | CF8: HIDROELÉCTRICA | CG8: HIDROELÉCTRICA | CH8: TERMOELÉCTRICA | CI8: TERMOELÉCTRICA | CJ8: TERMOELÉCTRICA | CK8: TERMOELÉCTRICA | CL8: TERMOELÉCTRICA | CM8: TERMOELÉCTRICA | CN8: TERMOELÉCTRICA | CO8: TERMOELÉCTRICA | CP8: TERMOELÉCTRICA | CQ8: TERMOELÉCTRICA | CR8: TERMOELÉCTRICA | CS8: TERMOELÉCTRICA | CT8: TERMOELÉCTRICA | CU8: SOLAR | CV8: EÓLICA | CW8: SOLAR | CX8: EÓLICA | CY8: SOLAR | CZ8: HIDROELÉCTRICA | DA8: HIDROELÉCTRICA | DB8: HIDROELÉCTRICA | DC8: HIDROELÉCTRICA | DD8: HIDROELÉCTRICA | DE8: HIDROELÉCTRICA | DF8: HIDROELÉCTRICA | DG8: HIDROELÉCTRICA | DH8: HIDROELÉCTRICA | DI8: HIDROELÉCTRICA | DJ8: HIDROELÉCTRICA | DK8: SOLAR | DL8: SOLAR | DM8: EÓLICA | DN8: EÓLICA | DO8: TERMOELÉCTRICA | DP8: TERMOELÉCTRICA | DQ8: TERMOELÉCTRICA | DR8: TERMOELÉCTRICA | DS8: SOLAR | DT8: HIDROELÉCTRICA | DU8: HIDROELÉCTRICA | DV8: HIDROELÉCTRICA | DW8: HIDROELÉCTRICA | DX8: HIDROELÉCTRICA | DY8: HIDROELÉCTRICA | DZ8: HIDROELÉCTRICA | EA8: HIDROELÉCTRICA | EB8: HIDROELÉCTRICA | EC8: EÓLICA | ED8: EÓLICA | EE8: SOLAR | EF8: EÓLICA | EG8: EÓLICA | EH8: EÓLICA | EI8: EÓLICA | EJ8: HIDROELÉCTRICA | EK8: HIDROELÉCTRICA | EL8: HIDROELÉCTRICA | EM8: HIDROELÉCTRICA | EN8: HIDROELÉCTRICA | EO8: HIDROELÉCTRICA | EP8: EÓLICA | EQ8: SOLAR | ER8: SOLAR | ES8: HIDROELÉCTRICA | ET8: EÓLICA | EU8: EÓLICA | EV8: SOLAR | EW8: SOLAR | EX8: HIDROELÉCTRICA | EY8: HIDROELÉCTRICA | EZ8: TERMOELÉCTRICA | FA8: TERMOELÉCTRICA | FB8: TERMOELÉCTRICA | FC8: TERMOELÉCTRICA | FD8: TERMOELÉCTRICA | FE8: TERMOELÉCTRICA | FF8: TERMOELÉCTRICA | FG8: TERMOELÉCTRICA | FJ8: HIDROELÉCTRICA | FK8: HIDROELÉCTRICA | FL8: HIDROELÉCTRICA | FM8: HIDROELÉCTRICA | FN8: TERMOELÉCTRICA | FO8: TERMOELÉCTRICA | FP8: HIDROELÉCTRICA | FQ8: HIDROELÉCTRICA
C9: CENTRALES SANTA ROSA S.A.C. | D9: CENTRALES SANTA ROSA S.A.C. | E9: ELECTROPERU | F9: ELECTROPERU | G9: ELECTROPERU | H9: ELECTROPERU | I9: ORAZUL ENERGY PERÚ | J9: ORAZUL ENERGY PERÚ | K9: TERMOSELVA | L9: TERMOSELVA | M9: KALLPA GENERACION S.A. | N9: KALLPA GENERACION S.A. | O9: KALLPA GENERACION S.A. | P9: KALLPA GENERACION S.A. | Q9: KALLPA GENERACION S.A. | R9: KALLPA GENERACION S.A. | S9: KALLPA GENERACION S.A. | T9: KALLPA GENERACION S.A. | U9: SHOUGESA | V9: SHOUGESA | W9: SHOUGESA | X9: SHOUGESA | Y9: EGEMSA | Z9: EGESUR | AA9: EGESUR | AB9: EGESUR | AC9: EGASA | AD9: EGASA | AE9: EGASA | AF9: EGASA | AG9: EGASA | AH9: EGASA | AI9: EGASA | AJ9: SAN GABAN | AK9: CELEPSA | AL9: MINERA CERRO VERDE | AM9: PLANTA DE RESERVA FRIA DE GENERACION DE ETEN S.A. | AN9: PLANTA DE RESERVA FRIA DE GENERACION DE ETEN S.A. | AO9: EMPRESA DE GENERACION HUALLAGA | AP9: EMPRESA DE GENERACION HUALLAGA | AQ9: LA VIRGEN | AR9: CHINANGO S.A.C. | AS9: CHINANGO S.A.C. | AT9: HIDROELECTRICA HUANCHOR S.A.C. | AU9: CELEPSA RENOVABLES S.R.L. | AV9: INLAND ENERGY SAC | AW9: FENIX POWER PERÚ | AX9: FENIX POWER PERÚ | AY9: FENIX POWER PERÚ | AZ9: STATKRAFT S.A | BA9: STATKRAFT S.A | BB9: STATKRAFT S.A | BC9: STATKRAFT S.A | BD9: STATKRAFT S.A | BE9: STATKRAFT S.A | BF9: STATKRAFT S.A | BG9: STATKRAFT S.A | BH9: EMPRESA DE GENERACION HUANZA | BI9: ENEL GENERACION PIURA S.A. | BJ9: ENEL GENERACION PIURA S.A. | BK9: ENEL GENERACION PIURA S.A. | BL9: ENGIE | BM9: ENGIE | BN9: ENGIE | BO9: ENGIE | BP9: ENGIE | BQ9: ENGIE | BR9: ENGIE | BS9: ENGIE | BT9: ENGIE | BU9: ENGIE | BV9: ENGIE | BW9: ENGIE | BX9: ENGIE | BY9: ENGIE | BZ9: INFRAESTRUCTURAS Y ENERGIAS DEL PERU S.A.C. | CA9: INFRAESTRUCTURAS Y ENERGIAS DEL PERU S.A.C. | CB9: INVERSIONES SHAQSHA S.A.C. | CC9: ORYGEN PERU S.A.A. | CD9: ORYGEN PERU S.A.A. | CE9: ORYGEN PERU S.A.A. | CF9: ORYGEN PERU S.A.A. | CG9: ORYGEN PERU S.A.A. | CH9: ORYGEN PERU S.A.A. | CI9: ORYGEN PERU S.A.A. | CJ9: ORYGEN PERU S.A.A. | CK9: ORYGEN PERU S.A.A. | CL9: ORYGEN PERU S.A.A. | CM9: ORYGEN PERU S.A.A. | CN9: ORYGEN PERU S.A.A. | CO9: SAMAY I S.A.C | CP9: SAMAY I S.A.C | CQ9: SAMAY I S.A.C | CR9: SAMAY I S.A.C | CS9: TERMOCHILCA S.A.C. | CT9: TERMOCHILCA S.A.C. | CU9: COLCA SOLAR S.A.C. | CV9: ENERGIA RENOVABLE DEL SUR S.A. | CW9: GR CORTARRAMA SOCIEDAD ANONIMA CERRADA | CX9: GR TARUCA SOCIEDAD ANONIMA CERRADA | CY9: KONDU SAC | CZ9: PERUANA DE INVERSIONES EN ENERGIAS RENOVABLES S.A. | DA9: ORAZUL ENERGY PERÚ | DB9: ORAZUL ENERGY PERÚ | DC9: SAN GABAN | DD9: MAJA ENERGIA S.A.C. | DE9: EMPRESA DE GENERACION ELECTRICA CANCHAYLLO SAC | DF9: EMPRESA DE GENERACION ELECTRICA SANTA ANA S.A.C. | DG9: EMPRESA ELECTRICA AGUA AZUL | DH9: EMPRESA ELECTRICA RIO DOBLE | DI9: HIDROCAÑETE S.A. | DJ9: HUAURA POWER GROUP S.A. | DK9: MOQUEGUA FV S.A.C. | DL9: PANAMERICANA SOLAR SAC. | DM9: PARQUE EOLICO MARCONA S.A.C. | DN9: PARQUE EOLICO TRES HERMANAS S.A.C. | DO9: PETRAMAS | DP9: PETRAMAS | DQ9: PETRAMAS | DR9: PETRAMAS | DS9: TACNA SOLAR SAC. | DT9: ELECTRICA YANAPAMPA SAC | DU9: ANDEAN POWER S.A.C. | DV9: ASOCIACIÓN SANTA LUCIA DE CHACAS | DW9: ATRIA ENERGIA S.A.C. | DX9: EGEJUNIN | DY9: EGEJUNIN | DZ9: EGEJUNIN | EA9: EGEJUNIN | EB9: EMPRESA DE GENERACION ELECTRICA RIO BAÑOS S.A.C. | EC9: ENERGÍA EÓLICA S.A. | ED9: ENERGÍA EÓLICA S.A. | EE9: ENGIE | EF9: ENGIE | EG9: ENGIE | EH9: ENGIE | EI9: ENGIE | EJ9: GENERACIÓN ANDINA S.A.C. | EK9: GENERACIÓN ANDINA S.A.C. | EL9: GENERADORA DE ENERGÍA DEL PERÚ | EM9: GENERADORA DE ENERGÍA DEL PERÚ | EN9: GENERADORA DE ENERGÍA DEL PERÚ | EO9: GENERADORA DE ENERGÍA DEL PERÚ | EP9: GR PAINO SOCIEDAD ANONIMA CERRADA | EQ9: MAJES ARCUS S.A.C. | ER9: ORYGEN PERU S.A.A. | ES9: ORYGEN PERU S.A.A. | ET9: ORYGEN PERU S.A.A. | EU9: ORYGEN PERU S.A.A. | EV9: ORYGEN PERU S.A.A. | EW9: REPARTICIÓN ARCUS S.A.C. | EX9: SINERSA | EY9: SINERSA | EZ9: BIOENERGIA DEL CHIRA S.A. | FA9: GM OPERACIONES S.A.C. | FB9: GM OPERACIONES S.A.C. | FC9: SDF ENERGIA SAC | FD9: SDF ENERGIA SAC | FE9: AGRO INDUSTRIAL PARAMONGA S.A. | FF9: AGROAURORA S.A.C. | FG9: AGROINDUSTRIAS SAN JACINTO S.A.A. | FJ9: UNACEM PERU S.A. | FK9: ELECTRO ORIENTE | FL9: AGUAS Y ENERGIA PERU | FM9: ELECTRO ZAÑA S.A.C. | FN9: ELECTRONOROESTE S.A. | FO9: SDE PIURA | FP9: SINERSA | FQ9: SINERSA
C10: SANTA ROSA 1 | D10: SANTA ROSA 2 | E10: MANTARO | F10: RESTITUCION | G10: TUMBES MAK 1 | H10: TUMBES MAK 2 | I10: CARHUAQUERO | J10: CAÑON DEL PATO | K10: AGUAYTIA TG1 | L10: AGUAYTIA TG2 | M10: KALLPA TG1 | N10: KALLPA TG2 | O10: KALLPA TG3 | P10: KALLPA TV | Q10: LFLORES TG1 | R10: LFLORES TV | S10: CERRO DEL AGUILA | T10: CERRODELAGUILAG4 | U10: SHOUGESA TV1 | V10: SHOUGESA TV2 | W10: SHOUGESA TV3 | X10: SHOUGESA CUMMINS | Y10: MACHUPICCHU | Z10: ARICOTA 1 | AA10: ARICOTA 2 | AB10: INDEPENDENCIA | AC10: CHARCANI I,II,III | AD10: CHARCANI IV | AE10: CHARCANI V | AF10: CHARCANI VI | AG10: CHILINA TG | AH10: MOLLENDO 1, 2, 3 | AI10: CHILINA (SULZ 1,2) | AJ10: SAN GABAN II | AK10: PLATANAL | AL10: RECKA | AM10: RF ETEN TG1 | AN10: RF ETEN TG2 | AO10: CHAGLLA GP1 | AP10: CHAGLLA | AQ10: LA VIRGEN | AR10: CHIMAY | AS10: YANANGO | AT10: HUANCHOR | AU10: MARAÑON | AV10: STA TERESA | AW10: FENIX GT11 | AX10: FENIX GT12 | AY10: FENIX TV10 | AZ10: YAUPI | BA10: OROYA | BB10: PACHACHACA | BC10: MALPASO | BD10: CAHUA | BE10: ARCATA | BF10: GALLITO CIEGO | BG10: CHEVES | BH10: HUANZA | BI10: MALACAS2 TG4 | BJ10: MALACAS3 TG 5 | BK10: MALACAS1 TG6 | BL10: RF ILO2 TG1 | BM10: RF ILO2 TG2 | BN10: RF ILO2 TG3 | BO10: YUNCAN | BP10: CHILCA1 TG1 | BQ10: CHILCA1 TG2 | BR10: CHILCA1 TG3 | BS10: CHILCA-TV | BT10: CHILCA2 TG41 | BU10: CHILCA2-TV | BV10: CTNEPI_TG41 | BW10: CTNEPI_TG42 | BX10: CTNEPI_TG43 | BY10: QUITARACSA | BZ10: RF PTO MALDONADO | CA10: RF PUCALLPA | CB10: PARIAC | CC10: HUINCO | CD10: MATUCANA | CE10: MOYOPAMPA | CF10: CALLAHUANCA | CG10: HUAMPANI | CH10: STA ROSA WEST TG7 | CI10: UTI_5 | CJ10: UTI_6 | CK10: VENTANILLA 3 | CL10: VENTANILLA 4 | CM10: VENTANILLA TV | CN10: STAROSA TG8 | CO10: PTO_BRVO TG1 | CP10: PTO_BRVO TG2 | CQ10: PTO_BRVO TG3 | CR10: PTO_BRVO TG4 | CS10: OLLEROS TG1 | CT10: OLLEROS TV | CU10: CS YARUCAYA | CV10: SAN JUAN | CW10: MATARANI | CX10: DUNA | CY10: CARHUAQUERO (CS) | CZ10: MANTA I | DA10: CARHUAQUERO4 | DB10: CAÑA BRAVA | DC10: TUPURI | DD10: RONCADOR | DE10: CANCHAYLLO | DF10: RENOVANDESH1 | DG10: POTRERO | DH10: PIZARRAS | DI10: NIMPERIAL | DJ10: YARUCAYA | DK10: MOQUEGUA-SOLAR | DL10: PANAMERICANA-SOLAR | DM10: PQE-EOLICO-MARCONA | DN10: PQE-EOLICO-3-HERMANAS | DO10: HUAYCOLORO | DP10: CALLAO | DQ10: DONA_CATALINA | DR10: LAGRINGAV | DS10: TACNA-SOLAR | DT10: YANAPAMPA | DU10: CARHUAC | DV10: HUALLIN | DW10: PURMACANA | DX10: HUASAHUASI | DY10: STACRUZ_1_2 | DZ10: RUNATULLO_II | EA10: RUNATULLO_III | EB10: RUCUY | EC10: PQE-EOLICO-TALARA | ED10: PQE-EOLICO-CUPISNIQUE | EE10: INTIPAMPA | EF10: PUNTA LOMITAS-BL1 | EG10: PUNTA LOMITAS-BL2 | EH10: PUN LOMITAS_EXP-BL1 | EI10: PUN LOMITAS_EXP-BL2 | EJ10: 8AGOSTO | EK10: EL CARMEN | EL10: LA JOYA | EM10: ANGEL_I | EN10: ANGEL_II | EO10: ANGEL_III | EP10: HUAMBOS | EQ10: MAJES | ER10: RUBI | ES10: CH_HER1 | ET10: WAYRA-I | EU10: WAYRA EXTENSION | EV10: CLEMESI | EW10: REPARTICION | EX10: POECHOS2 | EY10: CHANCAY | EZ10: CANA BRAVA | FA10: REFINERIA TALARA TV1 | FB10: REFINERÍA TALARA TV2 | FC10: OQUENDO TG1 | FD10: OQUENDO TV1 | FE10: PARAMONGA | FF10: MAPLE | FG10: SAN_JACINTO | FH10: MW | FJ10: CARPAPATA | FK10: CENTRALES ELOR | FL10: PIAS1 | FM10: ZANA | FN10: TABLAZO | FO10: TALLANCA | FP10: CURUMUY | FQ10: POECHOS1 | FR10: MW
A11: 15/03/2025 | B11: 00:30 | C11: 0.9 | D11: 1.5 | E11: 649.7 | F11: 218.5 | I11: 89.4 | J11: 143.8 | M11: 107.4 | N11: 0 | O11: 107.7 | P11: 137.3 | Q11: 108.1 | R11: 68 | S11: 379 | T11: 10.5 | Y11: 161.1 | Z11: 8.4 | AA11: 3 | AC11: 6.2 | AD11: 8.1 | AE11: 142.3 | AF11: 3.6 | AJ11: 110.4 | AK11: 222.6 | AO11: 6.6 | AP11: 459.5 | AQ11: 81.7 | AR11: 148.4 | AS11: 42.4 | AT11: 18.5 | AU11: 17.8 | AV11: 91 | AW11: 50.7 | AX11: 122.3 | AY11: 137.9 | AZ11: 108.2 | BC11: 45.2 | BD11: 39.6 | BE11: 4 | BF11: 38.4 | BG11: 173.3 | BH11: 94.4 | BI11: 25.2 | BO11: 86.6 | BP11: 137.3 | BQ11: 137.3 | BR11: 138.3 | BS11: 219.3 | CB11: 2.1 | CC11: 267.4 | CD11: 127.7 | CE11: 62.8 | CF11: 79.8 | CG11: 29.9 | CL11: 142 | CM11: 65 | CU11: 0 | CV11: 80.6 | CW11: 0 | CX11: 2.6 | CY11: 0 | DA11: 9.8 | DB11: 0 | DC11: 1.1 | DD11: 1.8 | DE11: 4.8 | DF11: 20.1 | DG11: 20 | DH11: 18.3 | DI11: 0 | DJ11: 18.5 | DK11: 0 | DL11: 0 | DM11: 23.3 | DN11: 53.8 | DO11: 4.8 | DP11: 2.4 | DQ11: 2.4 | DR11: 1 | DS11: 0 | DT11: 3.2 | DU11: 20.3 | DV11: 3 | DW11: 0.3 | DX11: 19.9 | DY11: 12.7 | DZ11: 20.2 | EA11: 20.2 | EB11: 19.9 | EC11: 7.8 | ED11: 25.3 | EE11: 0 | EF11: 21 | EG11: 52.9 | EH11: 1.1 | EI11: 0.4 | EJ11: 21 | EK11: 8.4 | EL11: 4 | EM11: 20.4 | EN11: 20.4 | EO11: 20 | EP11: 2.3 | EQ11: 0 | ER11: 0 | ES11: 0.6 | ET11: 60 | EU11: 51.9 | EV11: 0 | EW11: 0 | EX11: 9.4 | EY11: 20 | FA11: 31.3 | FB11: 34.6 | FC11: 28.9 | FD11: 3.5 | FE11: 0 | FF11: 0 | FG11: 7 | FH11: 6725.3 | FJ11: 24.45946 | FK11: 7.974 | FM11: 13.2 | FO11: 18.92064 | FP11: 10.9 | FQ11: 16 | FR11: 91.4541
A12: 15/03/2025 | B12: 01:00 | C12: 0.9 | D12: 0.7 | E12: 646.3 | F12: 216.9 | I12: 89.6 | J12: 144.3 | M12: 106.4 | N12: 0 | O12: 105.9 | P12: 135.7 | Q12: 108.1 | R12: 68.1 | S12: 374 | T12: 10.4 | Y12: 163.1 | Z12: 7.2 | AA12: 2.5 | AC12: 6.2 | AD12: 8.1 | AE12: 143.2 | AF12: 3.6 | AJ12: 109.8 | AK12: 221.4 | AO12: 6.6 | AP12: 452.1 | AQ12: 81.9 | AR12: 146.4 | AS12: 42.4 | AT12: 18.5 | AU12: 17.8 | AV12: 90.9 | AW12: 0 | AX12: 124 | AY12: 72.4 | AZ12: 105.6 | BC12: 43.8 | BD12: 39.8 | BE12: 4 | BF12: 37.5 | BG12: 174.1 | BH12: 93.7 | BI12: 25.1 | BO12: 86.8 | BP12: 132 | BQ12: 132 | BR12: 134.6 | BS12: 220.1 | CB12: 2.1 | CC12: 266.2 | CD12: 126.8 | CE12: 62.3 | CF12: 79.6 | CG12: 29.9 | CL12: 141.9 | CM12: 65.3 | CU12: 0 | CV12: 78.8 | CW12: 0 | CX12: 1.7 | CY12: 0 | DA12: 9.9 | DB12: 0 | DC12: 1.1 | DD12: 1.8 | DE12: 4.8 | DF12: 19.9 | DG12: 19.6 | DH12: 18.3 | DI12: 0 | DJ12: 18.5 | DK12: 0 | DL12: 0 | DM12: 22.4 | DN12: 57.2 | DO12: 4.8 | DP12: 2.4 | DQ12: 2.4 | DR12: 1 | DS12: 0 | DT12: 3.3 | DU12: 20.3 | DV12: 3 | DW12: 0.3 | DX12: 19.9 | DY12: 12.8 | DZ12: 19.7 | EA12: 20.2 | EB12: 20 | EC12: 9.6 | ED12: 23.7 | EE12: 0 | EF12: 22.7 | EG12: 52.8 | EH12: 1.4 | EI12: 1 | EJ12: 21 | EK12: 8.4 | EL12: 3.8 | EM12: 20.4 | EN12: 20.4 | EO12: 20 | EP12: 1.8 | EQ12: 0 | ER12: 0 | ES12: 0.6 | ET12: 55.3 | EU12: 48.7 | EV12: 0 | EW12: 0 | EX12: 9.2 | EY12: 20 | FA12: 31.3 | FB12: 34.7 | FC12: 28.8 | FD12: 3.4 | FE12: 0 | FF12: 0 | FG12: 7.7 | FH12: 6559.4 | FJ12: 24.47376 | FK12: 7.973 | FM12: 13.2 | FO12: 18.92033 | FP12: 10.9 | FQ12: 16 | FR12: 91.46709
A13: 15/03/2025 | B13: 01:30 | C13: 1.1 | D13: 1.6 | E13: 650.9 | F13: 217.7 | I13: 90.8 | J13: 145.7 | M13: 105.2 | N13: 0 | O13: 104.7 | P13: 135.5 | Q13: 108.8 | R13: 67.6 | S13: 376 | T13: 10.5 | Y13: 166.6 | Z13: 7.2 | AA13: 3.3 | AC13: 6.2 | AD13: 8 | AE13: 143.1 | AF13: 4.2 | AJ13: 111.1 | AK13: 222.3 | AO13: 6.6 | AP13: 463.2 | AQ13: 82 | AR13: 146.9 | AS13: 42.5 | AT13: 18.5 | AU13: 17.7 | AV13: 92.1 | AW13: 0 | AX13: 125.9 | AY13: 73.9 | AZ13: 108.9 | BC13: 46.2 | BD13: 40.5 | BE13: 4 | BF13: 39.2 | BG13: 175.6 | BH13: 95.6 | BI13: 24.2 | BO13: 87.4 | BP13: 119.1 | BQ13: 118.9 | BR13: 118 | BS13: 212.1 | CB13: 2.1 | CC13: 261.4 | CD13: 126.5 | CE13: 63.8 | CF13: 80.2 | CG13: 30.5 | CL13: 142.4 | CM13: 65.1 | CU13: 0 | CV13: 81.7 | CW13: 0 | CX13: 1 | CY13: 0 | DA13: 9.9 | DB13: 0 | DC13: 1.1 | DD13: 1.8 | DE13: 5.1 | DF13: 20.5 | DG13: 19.4 | DH13: 18.4 | DI13: 0 | DJ13: 18.5 | DK13: 0 | DL13: 0 | DM13: 19.5 | DN13: 55.6 | DO13: 4.8 | DP13: 2.4 | DQ13: 2.4 | DR13: 1 | DS13: 0 | DT13: 3.3 | DU13: 20.3 | DV13: 3 | DW13: 0.3 | DX13: 19.9 | DY13: 12.9 | DZ13: 19.8 | EA13: 20.3 | EB13: 20 | EC13: 10.5 | ED13: 27.2 | EE13: 0 | EF13: 16.7 | EG13: 44.1 | EH13: 1.7 | EI13: 1.1 | EJ13: 21 | EK13: 8.4 | EL13: 3.7 | EM13: 20.4 | EN13: 20.4 | EO13: 20 | EP13: 0.8 | EQ13: 0 | ER13: 0 | ES13: 0.6 | ET13: 44.2 | EU13: 41 | EV13: 0 | EW13: 0 | EX13: 9.2 | EY13: 20 | FA13: 31.5 | FB13: 35.4 | FC13: 28.7 | FD13: 3.4 | FE13: 0 | FF13: 0 | FG13: 7.5 | FH13: 6519.5 | FJ13: 24.48969 | FK13: 7.974 | FM13: 13.2 | FO13: 18.92022 | FP13: 10.9 | FQ13: 16 | FR13: 91.48391
A14: 15/03/2025 | B14: 02:00 | C14: 1 | D14: 1.7 | E14: 651.1 | F14: 218.8 | I14: 89.8 | J14: 144.5 | M14: 106.2 | N14: 42 | O14: 105.8 | P14: 133.4 | Q14: 110.2 | R14: 68.3 | S14: 378.9 | T14: 10.5 | Y14: 162 | Z14: 7 | AA14: 2.9 | AC14: 6.2 | AD14: 8.1 | AE14: 142.9 | AF14: 3.7 | AJ14: 110.9 | AK14: 220.5 | AO14: 6.6 | AP14: 460.9 | AQ14: 81.8 | AR14: 148.7 | AS14: 42.5 | AT14: 18.5 | AU14: 17.7 | AV14: 90.8 | AW14: 0 | AX14: 123.2 | AY14: 74.3 | AZ14: 107.9 | BC14: 45.2 | BD14: 40.2 | BE14: 4 | BF14: 38.6 | BG14: 173.5 | BH14: 94.7 | BI14: 24.9 | BO14: 87.1 | BP14: 105.4 | BQ14: 105.3 | BR14: 105.3 | BS14: 189.2 | CB14: 2.1 | CC14: 268.4 | CD14: 128.5 | CE14: 63 | CF14: 80 | CG14: 30.1 | CL14: 143.4 | CM14: 65.3 | CU14: 0 | CV14: 81.2 | CW14: 0 | CX14: 0.6 | CY14: 0 | DA14: 9.9 | DB14: 0 | DC14: 1.1 | DD14: 1.8 | DE14: 5.1 | DF14: 20.3 | DG14: 20 | DH14: 18.2 | DI14: 0 | DJ14: 18.5 | DK14: 0 | DL14: 0 | DM14: 21.2 | DN14: 55.9 | DO14: 4.8 | DP14: 2.4 | DQ14: 2.4 | DR14: 1.1 | DS14: 0 | DT14: 3.3 | DU14: 20.3 | DV14: 3 | DW14: 0.3 | DX14: 19.9 | DY14: 12.9 | DZ14: 19.5 | EA14: 20.3 | EB14: 20 | EC14: 9 | ED14: 26.5 | EE14: 0 | EF14: 16.7 | EG14: 45.8 | EH14: 1.8 | EI14: 1.6 | EJ14: 21 | EK14: 8.4 | EL14: 4.1 | EM14: 20.4 | EN14: 20.4 | EO14: 20 | EP14: 0.9 | EQ14: 0 | ER14: 0 | ES14: 0.6 | ET14: 41.3 | EU14: 28.9 | EV14: 0 | EW14: 0 | EX14: 9.2 | EY14: 20 | FA14: 31.6 | FB14: 34.4 | FC14: 28.9 | FD14: 3.4 | FE14: 0 | FF14: 0 | FG14: 6.5 | FH14: 6478.9 | FJ14: 24.44552 | FK14: 7.975 | FM14: 13.2 | FO14: 18.92014 | FP14: 10.9 | FQ14: 16.1 | FR14: 91.54066
A15: 15/03/2025 | B15: 02:30 | C15: 1 | D15: 1.7 | E15: 659.1 | F15: 219.1 | I15: 90.2 | J15: 146.5 | M15: 103.5 | N15: 56.8 | O15: 101.6 | P15: 126 | Q15: 108.5 | R15: 67.5 | S15: 388.2 | T15: 10.6 | Y15: 171.5 | Z15: 8.5 | AA15: 3.2 | AC15: 6.2 | AD15: 8 | AE15: 143.3 | AF15: 3.3 | AJ15: 111.1 | AK15: 220.9 | AO15: 6.6 | AP15: 447.8 | AQ15: 81.8 | AR15: 150.9 | AS15: 42.4 | AT15: 18.5 | AU15: 17.8 | AV15: 92.5 | AW15: 0 | AX15: 125.5 | AY15: 73 | AZ15: 108.8 | BC15: 45.6 | BD15: 40.7 | BE15: 4 | BF15: 39.5 | BG15: 177.4 | BH15: 95.8 | BI15: 0 | BO15: 88.2 | BP15: 69.5 | BQ15: 69.2 | BR15: 68.6 | BS15: 173.7 | CB15: 2.1 | CC15: 276.2 | CD15: 132.2 | CE15: 64.9 | CF15: 80.4 | CG15: 30.8 | CL15: 141.2 | CM15: 63.8 | CU15: 0 | CV15: 76.3 | CW15: 0 | CX15: 0.5 | CY15: 0 | DA15: 9.9 | DB15: 0 | DC15: 1.1 | DD15: 1.8 | DE15: 5.1 | DF15: 20.8 | DG15: 19.2 | DH15: 18.4 | DI15: 0 | DJ15: 18.5 | DK15: 0 | DL15: 0 | DM15: 18 | DN15: 49.3 | DO15: 4.8 | DP15: 2.4 | DQ15: 2.4 | DR15: 1 | DS15: 0 | DT15: 3.3 | DU15: 20.3 | DV15: 3 | DW15: 0.3 | DX15: 19.9 | DY15: 12.9 | DZ15: 19.3 | EA15: 20.3 | EB15: 19.9 | EC15: 8.4 | ED15: 25.8 | EE15: 0 | EF15: 21.9 | EG15: 58.5 | EH15: 1.9 | EI15: 1.5 | EJ15: 21 | EK15: 8.4 | EL15: 4.1 | EM15: 20.4 | EN15: 20.4 | EO15: 20 | EP15: 0.3 | EQ15: 0 | ER15: 0 | ES15: 0.6 | ET15: 29.4 | EU15: 23.6 | EV15: 0 | EW15: 0 | EX15: 9.2 | EY15: 19.9 | FA15: 31.4 | FB15: 34.4 | FC15: 28.6 | FD15: 3.5 | FE15: 0 | FF15: 0 | FG15: 6.9 | FH15: 6354.5 | FJ15: 24.48968 | FK15: 7.973 | FM15: 13.2 | FO15: 18.92002 | FP15: 10.8 | FQ15: 16 | FR15: 91.3827
A16: 15/03/2025 | B16: 03:00 | C16: 1 | D16: 1.7 | E16: 642.4 | F16: 215.7 | I16: 86.4 | J16: 144 | M16: 105 | N16: 105 | O16: 105 | P16: 196.9 | Q16: 108.5 | R16: 68.5 | S16: 367.1 | T16: 10.4 | Y16: 161.5 | Z16: 7.2 | AA16: 2.9 | AC16: 6 | AD16: 8 | AE16: 143.7 | AF16: 3.6 | AJ16: 109.5 | AK16: 220.3 | AO16: 6.6 | AP16: 446.5 | AQ16: 81.9 | AR16: 133.9 | AS16: 42.2 | AT16: 18.4 | AU16: 17.7 | AV16: 90.7 | AW16: 0 | AX16: 122.3 | AY16: 73.1 | AZ16: 107.2 | BC16: 44.8 | BD16: 31.4 | BE16: 4 | BF16: 38.6 | BG16: 171.7 | BH16: 94 | BI16: 0 | BO16: 86.5 | BP16: 64 | BQ16: 63.7 | BR16: 63.9 | BS16: 154.8 | CB16: 2.1 | CC16: 240.5 | CD16: 117.9 | CE16: 62 | CF16: 79.3 | CG16: 29.7 | CL16: 141.6 | CM16: 65.4 | CU16: 0 | CV16: 67.9 | CW16: 0 | CX16: 0.2 | CY16: 0 | DA16: 9.9 | DB16: 0 | DC16: 1.1 | DD16: 1.8 | DE16: 5 | DF16: 19.9 | DG16: 19.3 | DH16: 18.4 | DI16: 0 | DJ16: 18.5 | DK16: 0 | DL16: 0 | DM16: 19.5 | DN16: 45.9 | DO16: 4.8 | DP16: 2.3 | DQ16: 2.4 | DR16: 1 | DS16: 0 | DT16: 3.3 | DU16: 20.3 | DV16: 3 | DW16: 0.3 | DX16: 19.8 | DY16: 12.8 | DZ16: 19 | EA16: 20.2 | EB16: 19.9 | EC16: 12.5 | ED16: 25.7 | EE16: 0 | EF16: 28.9 | EG16: 63 | EH16: 2.3 | EI16: 1.5 | EJ16: 21 | EK16: 8.4 | EL16: 3.9 | EM16: 20.4 | EN16: 20.4 | EO16: 20 | EP16: 0.3 | EQ16: 0 | ER16: 0 | ES16: 0.6 | ET16: 21.1 | EU16: 20.6 | EV16: 0 | EW16: 0 | EX16: 9.3 | EY16: 20 | FA16: 31.5 | FB16: 35 | FC16: 28.8 | FD16: 3.5 | FE16: 0 | FF16: 0 | FG16: 7.5 | FH16: 6279.4 | FJ16: 24.44556 | FK16: 7.974 | FM16: 13.2 | FO16: 18.91997 | FP16: 10.7 | FQ16: 16.1 | FR16: 91.33953
A17: 15/03/2025 | B17: 03:30 | C17: 1 | D17: 1.7 | E17: 650.1 | F17: 217.2 | I17: 83.9 | J17: 145.3 | M17: 150.6 | N17: 150.3 | O17: 150.3 | P17: 244.7 | Q17: 108.7 | R17: 67.5 | S17: 370.5 | T17: 10.4 | Y17: 165.5 | Z17: 7.6 | AA17: 3.1 | AC17: 6 | AD17: 8 | AE17: 142.2 | AF17: 3.7 | AJ17: 111 | AK17: 183.1 | AO17: 6.6 | AP17: 434.7 | AQ17: 81.7 | AR17: 125.8 | AS17: 42.5 | AT17: 18.3 | AU17: 17.7 | AV17: 89.4 | AW17: 0 | AX17: 123.8 | AY17: 74.1 | AZ17: 107.9 | BC17: 45.4 | BD17: 21 | BE17: 4 | BF17: 39.5 | BG17: 173.2 | BH17: 94.9 | BI17: 0 | BO17: 87.2 | BP17: 68.8 | BQ17: 68.5 | BR17: 68.4 | BS17: 145.2 | CB17: 2.1 | CC17: 224.1 | CD17: 112.7 | CE17: 63.2 | CF17: 80.1 | CG17: 30.1 | CL17: 122.3 | CM17: 58 | CU17: 0 | CV17: 82.4 | CW17: 0 | CX17: 0.1 | CY17: 0 | DA17: 9.9 | DB17: 0 | DC17: 1.2 | DD17: 1.8 | DE17: 5 | DF17: 20.3 | DG17: 20 | DH17: 18.5 | DI17: 0 | DJ17: 18.5 | DK17: 0 | DL17: 0 | DM17: 23.3 | DN17: 46 | DO17: 4.8 | DP17: 2.3 | DQ17: 2.4 | DR17: 1 | DS17: 0 | DT17: 3.2 | DU17: 20.3 | DV17: 3 | DW17: 0.3 | DX17: 19.8 | DY17: 12.9 | DZ17: 19 | EA17: 20.3 | EB17: 19.8 | EC17: 10 | ED17: 17.5 | EE17: 0 | EF17: 36.5 | EG17: 76.1 | EH17: 2.9 | EI17: 2.5 | EJ17: 21 | EK17: 8.4 | EL17: 3.8 | EM17: 20.4 | EN17: 20.4 | EO17: 20 | EP17: 0 | EQ17: 0 | ER17: 0 | ES17: 0.6 | ET17: 21.3 | EU17: 21.7 | EV17: 0 | EW17: 0 | EX17: 9.1 | EY17: 19.9 | FA17: 30.9 | FB17: 34.9 | FC17: 28.8 | FD17: 3.4 | FE17: 0 | FF17: 0 | FG17: 7.1 | FH17: 6406.9 | FJ17: 24.4691 | FK17: 7.974 | FM17: 13.2 | FO17: 18.91891 | FP17: 10.9 | FQ17: 15.7 | FR17: 91.16201
A18: 15/03/2025 | B18: 04:00 | C18: 1 | D18: 1.7 | E18: 650.6 | F18: 218.5 | I18: 83.7 | J18: 145.3 | M18: 149.5 | N18: 150 | O18: 148.7 | P18: 246.8 | Q18: 109.5 | R18: 68.7 | S18: 375 | T18: 10.5 | Y18: 162.6 | Z18: 7.8 | AA18: 3.2 | AC18: 6 | AD18: 8.1 | AE18: 142.7 | AF18: 3.7 | AJ18: 110.5 | AK18: 140.5 | AO18: 6.6 | AP18: 373.5 | AQ18: 81.7 | AR18: 124.4 | AS18: 42.5 | AT18: 18.5 | AU18: 17.7 | AV18: 91.8 | AW18: 0 | AX18: 126 | AY18: 74.3 | AZ18: 107.9 | BC18: 45.4 | BD18: 10 | BE18: 4 | BF18: 38.8 | BG18: 173.4 | BH18: 94.9 | BI18: 0 | BO18: 87.4 | BP18: 68.2 | BQ18: 68.2 | BR18: 68.1 | BS18: 145.8 | CB18: 2.1 | CC18: 224.1 | CD18: 112.4 | CE18: 63.2 | CF18: 79.9 | CG18: 30.1 | CL18: 121.6 | CM18: 57.9 | CU18: 0 | CV18: 98.2 | CW18: 0 | CX18: 0.6 | CY18: 0 | DA18: 9.9 | DB18: 0 | DC18: 1.2 | DD18: 1.8 | DE18: 5.1 | DF18: 20.1 | DG18: 19.6 | DH18: 18.5 | DI18: 0 | DJ18: 18.5 | DK18: 0 | DL18: 0 | DM18: 26.9 | DN18: 55.2 | DO18: 4.8 | DP18: 2.4 | DQ18: 2.4 | DR18: 1 | DS18: 0 | DT18: 2.9 | DU18: 20.3 | DV18: 3 | DW18: 0.3 | DX18: 19.8 | DY18: 12.7 | DZ18: 19 | EA18: 20.2 | EB18: 19.8 | EC18: 8.7 | ED18: 14.1 | EE18: 0 | EF18: 36.8 | EG18: 79 | EH18: 3.7 | EI18: 2.6 | EJ18: 21 | EK18: 8.4 | EL18: 4.2 | EM18: 20.4 | EN18: 20.4 | EO18: 20 | EP18: 0.4 | EQ18: 0 | ER18: 0 | ES18: 0.6 | ET18: 18 | EU18: 21.8 | EV18: 0 | EW18: 0 | EX18: 9.2 | EY18: 19.8 | FA18: 30.8 | FB18: 34.4 | FC18: 28.7 | FD18: 3.4 | FE18: 0 | FF18: 0 | FG18: 7.4 | FH18: 6323 | FJ18: 24.40248 | FK18: 7.976 | FM18: 13.2 | FO18: 18.91861 | FP18: 10.8 | FQ18: 15.7 | FR18: 90.99709
A19: 15/03/2025 | B19: 04:30 | C19: 1 | D19: 1.7 | E19: 645.2 | F19: 217.3 | I19: 88 | J19: 144.5 | M19: 108.8 | N19: 108 | O19: 107.6 | P19: 209.3 | Q19: 107.7 | R19: 67.7 | S19: 376.3 | T19: 10.4 | Y19: 162.1 | Z19: 7.8 | AA19: 3 | AC19: 6 | AD19: 8.1 | AE19: 143.3 | AF19: 3.7 | AJ19: 110.2 | AK19: 171.5 | AO19: 6.6 | AP19: 419 | AQ19: 81.9 | AR19: 143.8 | AS19: 42.3 | AT19: 18.5 | AU19: 17.6 | AV19: 88.5 | AW19: 0 | AX19: 121.5 | AY19: 73.5 | AZ19: 108 | BC19: 45.3 | BD19: 0 | BE19: 4 | BF19: 39 | BG19: 172.3 | BH19: 94.5 | BI19: 0 | BO19: 86.7 | BP19: 68.4 | BQ19: 68.3 | BR19: 69.1 | BS19: 146.6 | CB19: 2.1 | CC19: 257.5 | CD19: 128 | CE19: 62.8 | CF19: 79.9 | CG19: 30.1 | CL19: 119.6 | CM19: 56.7 | CU19: 0 | CV19: 97.4 | CW19: 0 | CX19: 0.8 | CY19: 0 | DA19: 9.9 | DB19: 0 | DC19: 1.2 | DD19: 1.8 | DE19: 5.1 | DF19: 20.2 | DG19: 20 | DH19: 18.5 | DI19: 1.5 | DJ19: 18.5 | DK19: 0 | DL19: 0 | DM19: 27.3 | DN19: 53.8 | DO19: 4.8 | DP19: 2.4 | DQ19: 2.4 | DR19: 1.1 | DS19: 0 | DT19: 2.9 | DU19: 20.3 | DV19: 3 | DW19: 0.3 | DX19: 19.9 | DY19: 12.7 | DZ19: 19.1 | EA19: 20.2 | EB19: 20 | EC19: 10.1 | ED19: 14 | EE19: 0 | EF19: 37.3 | EG19: 83.8 | EH19: 2.7 | EI19: 3.3 | EJ19: 21 | EK19: 8.4 | EL19: 4.6 | EM19: 20.4 | EN19: 20.4 | EO19: 20 | EP19: 0.4 | EQ19: 0 | ER19: 0 | ES19: 0.6 | ET19: 20.1 | EU19: 22.4 | EV19: 0 | EW19: 0 | EX19: 9.2 | EY19: 20 | FA19: 30.6 | FB19: 33.9 | FC19: 28.7 | FD19: 3.4 | FE19: 0 | FF19: 0 | FG19: 7.4 | FH19: 6289.1 | FJ19: 24.42988 | FK19: 7.974 | FM19: 13.2 | FO19: 18.91818 | FP19: 10.7 | FQ19: 15.6 | FR19: 90.82206
A20: 15/03/2025 | B20: 05:00 | C20: 1 | D20: 1.7 | E20: 655.8 | F20: 219 | I20: 87.2 | J20: 145.3 | M20: 106.5 | N20: 106.2 | O20: 107.5 | P20: 206.8 | Q20: 109.9 | R20: 67.6 | S20: 380.5 | T20: 10.5 | Y20: 167.5 | Z20: 8.6 | AA20: 3.1 | AC20: 5.8 | AD20: 8 | AE20: 143.4 | AF20: 3.6 | AJ20: 111.3 | AK20: 182.7 | AO20: 6.6 | AP20: 453.1 | AQ20: 81.9 | AR20: 143 | AS20: 42.5 | AT20: 18.5 | AU20: 17.6 | AV20: 90 | AW20: 0 | AX20: 125.1 | AY20: 74.2 | AZ20: 109.1 | BC20: 45.5 | BD20: 0 | BE20: 4 | BF20: 39 | BG20: 176.1 | BH20: 95.1 | BI20: 0 | BO20: 87.2 | BP20: 70.8 | BQ20: 70.6 | BR20: 70.1 | BS20: 145 | CB20: 2.1 | CC20: 257.5 | CD20: 126.1 | CE20: 63.5 | CF20: 80 | CG20: 30.4 | CL20: 120.4 | CM20: 57.4 | CU20: 0 | CV20: 106.4 | CW20: 0 | CX20: 1.3 | CY20: 0 | DA20: 9.9 | DB20: 0 | DC20: 1.2 | DD20: 1.8 | DE20: 5 | DF20: 20.6 | DG20: 20 | DH20: 18.5 | DI20: 3.9 | DJ20: 18.5 | DK20: 0 | DL20: 0 | DM20: 27 | DN20: 56.4 | DO20: 4.8 | DP20: 2.4 | DQ20: 2.4 | DR20: 1 | DS20: 0 | DT20: 3 | DU20: 20.3 | DV20: 3 | DW20: 0.3 | DX20: 19.9 | DY20: 12.7 | DZ20: 19.6 | EA20: 20.3 | EB20: 20 | EC20: 13.5 | ED20: 13.5 | EE20: 0 | EF20: 42.6 | EG20: 89.4 | EH20: 2.1 | EI20: 0.8 | EJ20: 21 | EK20: 8.4 | EL20: 4.8 | EM20: 20.4 | EN20: 20.4 | EO20: 20 | EP20: 1.2 | EQ20: 0 | ER20: 0 | ES20: 0.6 | ET20: 21.2 | EU20: 21 | EV20: 0 | EW20: 0 | EX20: 9.2 | EY20: 20 | FA20: 31 | FB20: 34.2 | FC20: 28.5 | FD20: 3.4 | FE20: 0 | FF20: 0 | FG20: 7.3 | FH20: 6396.6 | FJ20: 24.38957 | FK20: 7.974 | FM20: 13.2 | FO20: 18.91792 | FP20: 10.7 | FQ20: 15.7 | FR20: 90.88149
A21: 15/03/2025 | B21: 05:30 | C21: 1 | D21: 1.6 | E21: 647.4 | F21: 218.2 | I21: 87.1 | J21: 144.9 | M21: 106.7 | N21: 106.7 | O21: 106.7 | P21: 206.6 | Q21: 109.3 | R21: 68.1 | S21: 372.9 | T21: 10.3 | Y21: 165.1 | Z21: 6.9 | AA21: 3.2 | AC21: 5.9 | AD21: 8 | AE21: 143.7 | AF21: 2.9 | AJ21: 110.6 | AK21: 220.7 | AO21: 6.6 | AP21: 457.8 | AQ21: 81.9 | AR21: 142.5 | AS21: 42.5 | AT21: 17.9 | AU21: 17.6 | AV21: 89.2 | AW21: 0 | AX21: 123 | AY21: 73.9 | AZ21: 108.1 | BC21: 44.9 | BD21: 0 | BE21: 4 | BF21: 38.7 | BG21: 172.9 | BH21: 94.6 | BI21: 0 | BO21: 86.9 | BP21: 66.5 | BQ21: 66.6 | BR21: 70.5 | BS21: 156.1 | CB21: 2.1 | CC21: 253.1 | CD21: 127.2 | CE21: 62.8 | CF21: 78 | CG21: 30.1 | CL21: 121.5 | CM21: 58.3 | CU21: 0 | CV21: 95.8 | CW21: 0 | CX21: 0.8 | CY21: 0 | DA21: 9.9 | DB21: 0 | DC21: 1.2 | DD21: 1.8 | DE21: 5 | DF21: 20.2 | DG21: 20 | DH21: 18.5 | DI21: 3.9 | DJ21: 18.5 | DK21: 0 | DL21: 0 | DM21: 27.3 | DN21: 53.1 | DO21: 4.8 | DP21: 2.4 | DQ21: 2.4 | DR21: 1 | DS21: 0 | DT21: 3.2 | DU21: 20.3 | DV21: 2.9 | DW21: 0.3 | DX21: 19.8 | DY21: 12.8 | DZ21: 19.5 | EA21: 20.2 | EB21: 20 | EC21: 14.8 | ED21: 15.3 | EE21: 0 | EF21: 29.8 | EG21: 71.1 | EH21: 1.3 | EI21: 0.9 | EJ21: 21 | EK21: 8.4 | EL21: 4.8 | EM21: 0.3 | EN21: 0 | EO21: 7.4 | EP21: 0.7 | EQ21: 0 | ER21: 0 | ES21: 0.6 | ET21: 19.9 | EU21: 20.4 | EV21: 0 | EW21: 0 | EX21: 9.2 | EY21: 20 | FA21: 30.9 | FB21: 34.5 | FC21: 28.3 | FD21: 3.4 | FE21: 0 | FF21: 0 | FG21: 6.6 | FH21: 6305.5 | FJ21: 24.39852 | FK21: 7.971 | FM21: 13.2 | FO21: 18.91777 | FP21: 10.7 | FQ21: 15.8 | FR21: 90.98729
A22: 15/03/2025 | B22: 06:00 | C22: 1 | D22: 1.6 | E22: 651.8 | F22: 219.1 | I22: 88.9 | J22: 145.2 | M22: 106.5 | N22: 107.2 | O22: 106.8 | P22: 206.6 | Q22: 109.4 | R22: 68 | S22: 380.4 | T22: 10.5 | Y22: 165.3 | Z22: 7.1 | AA22: 2.9 | AC22: 5.5 | AD22: 8.1 | AE22: 142.4 | AF22: 2.9 | AJ22: 43.4 | AK22: 221.8 | AO22: 6.6 | AP22: 461.7 | AQ22: 81.9 | AR22: 149.6 | AS22: 42.5 | AT22: 18.5 | AU22: 17.7 | AV22: 90.7 | AW22: 0 | AX22: 123.5 | AY22: 74.3 | AZ22: 108.7 | BC22: 45.1 | BD22: 0 | BE22: 4 | BF22: 38.7 | BG22: 174.8 | BH22: 94.9 | BI22: 0 | BO22: 87.4 | BP22: 110 | BQ22: 109.9 | BR22: 109.9 | BS22: 192.3 | CB22: 2.1 | CC22: 269 | CD22: 133 | CE22: 63.5 | CF22: 78.2 | CG22: 30.3 | CL22: 121.6 | CM22: 58.2 | CU22: 0 | CV22: 84.8 | CW22: 0.1 | CX22: 0.7 | CY22: 0 | DA22: 9.9 | DB22: 0 | DC22: 0.4 | DD22: 1.8 | DE22: 5 | DF22: 20.5 | DG22: 19.4 | DH22: 18.5 | DI22: 3.9 | DJ22: 18.5 | DK22: 1.9 | DL22: 2 | DM22: 26.3 | DN22: 53.6 | DO22: 4.8 | DP22: 2.4 | DQ22: 2.4 | DR22: 1 | DS22: 2.3 | DT22: 3.2 | DU22: 20.3 | DV22: 3 | DW22: 0.3 | DX22: 19.8 | DY22: 12.9 | DZ22: 20 | EA22: 20.3 | EB22: 20 | EC22: 13.6 | ED22: 15.1 | EE22: 0.3 | EF22: 33.5 | EG22: 65.2 | EH22: 2.2 | EI22: 1.4 | EJ22: 21 | EK22: 8.4 | EL22: 4.7 | EM22: 0 | EN22: 0 | EO22: 0 | EP22: 1.2 | EQ22: 0 | ER22: 1.6 | ES22: 0.6 | ET22: 19 | EU22: 21 | EV22: 1.4 | EW22: 0 | EX22: 9.3 | EY22: 20 | FA22: 30.9 | FB22: 34.4 | FC22: 28.3 | FD22: 3.4 | FE22: 0 | FF22: 0 | FG22: 7.7 | FH22: 6445.2 | FJ22: 24.46983 | FK22: 7.95 | FM22: 13.2 | FO22: 18.9175 | FP22: 10.7 | FQ22: 15.6 | FR22: 90.83733
... A58: 16/03/2025 | B58: 00:00 | C58: 0.9 | D58: 1.6 | E58: 642.8 | F58: 216 | I58: 59.3 | J58: 145.6 | M58: 152.9 | N58: 105.9 | O58: 153.9 | P58: 234.1 | Q58: 202.4 | R58: 107.2 | S58: 371.6 | T58: 10.4 | Y58: 167.3 | Z58: 7.5 | AA58: 2.7 | AC58: 6.6 | AD58: 8.6 | AE58: 143.1 | AF58: 8.3 | AJ58: 110 | AK58: 148.8 | AO58: 6.5 | AP58: 455.9 | AQ58: 81.7 | AR58: 122.4 | AS58: 42.2 | AT58: 18.3 | AU58: 17.1 | AV58: 88.8 | AW58: 0 | AX58: 0 | AY58: 0 | AZ58: 107.4 | BC58: 45.7 | BD58: 45.6 | BE58: 4 | BF58: 37.9 | BG58: 109.5 | BH58: 94.4 | BI58: 0 | BO58: 86.1 | BP58: 170.5 | BQ58: 162.7 | BR58: 200 | BS58: 261.7 | CB58: 2.1 | CC58: 210.4 | CD58: 107.9 | CE58: 64.2 | CF58: 78.4 | CG58: 30 | CL58: 141.1 | CM58: 64.7 | CU58: 0 | CV58: 76.2 | CW58: 0 | CX58: 0.7 | CY58: 0 | DA58: 9.9 | DB58: 2.9 | DC58: 1.1 | DD58: 1.8 | DE58: 5.1 | DF58: 20.1 | DG58: 20 | DH58: 18.9 | DI58: 3.6 | DJ58: 18.5 | DK58: 0 | DL58: 0 | DM58: 26.1 | DN58: 75.9 | DO58: 4.8 | DP58: 2.4 | DQ58: 2.4 | DR58: 1 | DS58: 0 | DT58: 2.6 | DU58: 20.3 | DV58: 3 | DW58: 0 | DX58: 19.8 | DY58: 12.9 | DZ58: 20.2 | EA58: 20.2 | EB58: 19.8 | EC58: 9.1 | ED58: 50.2 | EE58: 0 | EF58: 80.5 | EG58: 94.5 | EH58: 7.4 | EI58: 7.2 | EJ58: 12.6 | EK58: 8.4 | EL58: 6.4 | EM58: 20.4 | EN58: 20.4 | EO58: 20 | EP58: 0.6 | EQ58: 0 | ER58: 0 | ES58: 0.6 | ET58: 37.2 | EU58: 42.6 | EV58: 0 | EW58: 0 | EX58: 9.3 | EY58: 19.8 | FA58: 30.9 | FB58: 35.3 | FC58: 28.7 | FD58: 3.4 | FE58: 15 | FF58: 9.6 | FG58: 5.7 | FH58: 6850.7 | FJ58: 24.37069 | FK58: 7.897 | FM58: 13.2 | FO58: 18.91712 | FP58: 10.2 | FQ58: 16.1 | FR58: 90.68481
A59: EJEC | C59: 23.65 | D59: 37.25 | E59: 15592.6 | F59: 5227.6 | G59: 0 | H59: 0 | I59: 2085.6 | J59: 3482.5 | K59: 0 | L59: 0 | M59: 2961.1 | N59: 2849.35 | O59: 2972.8 | P59: 5140 | Q59: 3633.05 | R59: 2047.15 | S59: 9053.65 | T59: 250.9 | U59: 0 | V59: 0 | W59: 0 | X59: 0 | Y59: 3952.4 | Z59: 182.6 | AA59: 70.7 | AB59: 0 | AC59: 148.95 | AD59: 166.45 | AE59: 3434.05 | AF59: 97.55 | AG59: 0 | AH59: 0 | AI59: 0 | AJ59: 1978.7 | AK59: 4829.15 | AL59: 0 | AM59: 0 | AN59: 0 | AO59: 98.3 | AP59: 10924.9 | AQ59: 1965.1 | AR59: 3415.65 | AS59: 1017.35 | AT59: 442.65 | AU59: 373.4 | AV59: 2158.9 | AW59: 25.35 | AX59: 3224.7 | AY59: 1834.5 | AZ59: 2596.45 | BA59: 0 | BB59: 0 | BC59: 1089.15 | BD59: 397.6 | BE59: 96 | BF59: 935.1 | BG59: 4106.95 | BH59: 2275.7 | BI59: 49.7 | BJ59: 0 | BK59: 0 | BL59: 0 | BM59: 0 | BN59: 0 | BO59: 2087.7 | BP59: 3263 | BQ59: 3172.85 | BR59: 3611.95 | BS59: 5308.6 | BT59: 0 | BU59: 0 | BV59: 0 | BW59: 0 | BX59: 0 | BY59: 0 | BZ59: 0 | CA59: 0 | CB59: 50.3 | CC59: 6063.85 | CD59: 3078.5 | CE59: 1530.65 | CF59: 1898 | CG59: 722.95 | CH59: 0 | CI59: 0 | CJ59: 0 | CK59: 0 | CL59: 3273.95 | CM59: 1523.2 | CN59: 0 | CO59: 0 | CP59: 0 | CQ59: 0 | CR59: 0 | CS59: 0 | CT59: 0 | CU59: 5 | CV59: 2307.8 | CW59: 730.8 | CX59: 14.1 | CY59: 1.95 | CZ59: 0 | DA59: 237.65 | DB59: 49.75 | DC59: 13.4 | DD59: 43.55 | DE59: 122.25 | DF59: 485.7 | DG59: 476.05 | DH59: 447.7 | DI59: 71.8 | DJ59: 444 | DK59: 150.8 | DL59: 180.05 | DM59: 608.3 | DN59: 1732.6 | DO59: 112.2 | DP59: 57.5 | DQ59: 57.6 | DR59: 24.15 | DS59: 184.7 | DT59: 66.85 | DU59: 487.5 | DV59: 71.7 | DW59: 4.35 | DX59: 475.6 | DY59: 308.4 | DZ59: 480.25 | EA59: 486.5 | EB59: 479.35 | EC59: 260.15 | ED59: 990.85 | EE59: 328.95 | EF59: 1607.2 | EG59: 1943.3 | EH59: 142.45 | EI59: 171.5 | EJ59: 374.25 | EK59: 201.6 | EL59: 141.65 | EM59: 234.75 | EN59: 214.7 | EO59: 158.7 | EP59: 10.5 | EQ59: 135.25 | ER59: 1403.55 | ES59: 14.4 | ET59: 1789.3 | EU59: 1784.05 | EV59: 1044.5 | EW59: 137.1 | EX59: 223.05 | EY59: 479.5 | EZ59: 0 | FA59: 737.85 | FB59: 844.65 | FC59: 678.55 | FD59: 78.05 | FE59: 82.25 | FF59: 123.75 | FG59: 167.85 | FH59: 170754.8 | FJ59: 585.40248 | FK59: 190.765 | FL59: 0 | FM59: 316.6 | FN59: 0 | FO59: 454.08565 | FP59: 244.8 | FQ59: 383.1 | FR59: 2174.7531

Sheet REACTIVA
B3: sábado, 15 de Marzo del 2025
A5: POTENCIA REACTIVA EJECUTADA DE LAS UNIDADES DE GENERACIÓN DEL COES (MVAR) | FI5: CENTRALES NO INTEGRANTES COES
A6: FECHA | B6: HORA | C6: 337 | D6: 338 | E6: 101 | F6: 102 | G6: 42667 | H6: 42668 | I6: 126 | J6: 127 | K6: 138 | L6: 139 | M6: 197 | N6: 203 | O6: 204 | P6: 230 | Q6: 209 | R6: 56677 | S6: 796 | T6: 2146 | U6: 142 | V6: 143 | W6: 125 | X6: 187 | Y6: 163 | Z6: 298 | AA6: 219 | AB6: 151 | AC6: 152 | AD6: 153 | AE6: 154 | AF6: 756 | AG6: 156 | AH6: 155 | AI6: 182 | AJ6: 212 | AK6: 758 | AL6: 263 | AM6: 265 | AN6: 775 | AO6: 777 | AP6: 2154 | AQ6: 150 | AR6: 149 | AS6: 188 | AT6: 2131 | AU6: 755 | AV6: 252 | AW6: 249 | AX6: 250 | AY6: 117 | AZ6: 267 | BA6: 268 | BB6: 119 | BC6: 120 | BD6: 189 | BE6: 122 | BF6: 266 | BG6: 251 | BH6: 115 | BI6: 239 | BJ6: 288 | BK6: 240 | BL6: 241 | BM6: 242 | BN6: 191 | BO6: 194 | BP6: 196 | BQ6: 207 | BR6: 236 | BS6: 795 | BT6: 285 | BU6: 995 | BV6: 996 | BW6: 997 | BX6: 766 | BY6: 926 | BZ6: 924 | CA6: 121 | CB6: 103 | CC6: 104 | CD6: 106 | CE6: 105 | CF6: 107 | CG6: 110 | CH6: 109 | CI6: 144 | CJ6: 113 | CK6: 114 | CL6: 193 | CM6: 208 | CN6: 786 | CO6: 787 | CP6: 788 | CQ6: 789 | CR6: 248 | CS6: 2159 | CT6: 303 | CU6: 59715 | CV6: 62255 | CW6: 1263 | CX6: 61800 | CY6: 2194 | CZ6: 216 | DA6: 198 | DB6: 49607 | DC6: 214 | DD6: 260 | DE6: 2152 | DF6: 2128 | DG6: 247 | DH6: 228 | DI6: 2135 | DJ6: 261 | DK6: 237 | DL6: 253 | DM6: 770 | DN6: 225 | DO6: 2201 | DP6: 2171 | DQ6: 760 | DR6: 235 | DS6: 238 | DT6: 2184 | DU6: 61855 | DV6: 223 | DW6: 226 | DX6: 201 | DY6: 258 | DZ6: 259 | EA6: 920 | EB6: 257 | EC6: 256 | ED6: 2148 | EE6: 58288 | EF6: 58289 | EG6: 58839 | EH6: 58840 | EI6: 296 | EJ6: 297 | EK6: 211 | EL6: 2175 | EM6: 2178 | EN6: 2181 | EO6: 1262 | EP6: 233 | EQ6: 2150 | ER6: 2165 | ES6: 2161 | ET6: 61197 | EU6: 58851 | EV6: 234 | EW6: 215 | EX6: 917 | EY6: 289 | EZ6: 58333 | FA6: 58336 | FB6: 202 | FC6: 58487 | FD6: 213 | FE6: 232 | FF6: 2190 | FG6: TOTAL COES | FI6: 221 | FJ6: 222 | FK6: 224 | FL6: 2187 | FM6: 227 | FN6: 49400 | FO6: 199 | FP6: 200 | FQ6: TOTAL NO COES
C7: CENTRO | D7: CENTRO | E7: CENTRO | F7: CENTRO | G7: NORTE | H7: NORTE | I7: NORTE | J7: NORTE | K7: CENTRO | L7: CENTRO | M7: CENTRO | N7: CENTRO | O7: CENTRO | P7: CENTRO | Q7: CENTRO | R7: CENTRO | S7: CENTRO | T7: CENTRO | U7: CENTRO | V7: CENTRO | W7: CENTRO | X7: CENTRO | Y7: SUR | Z7: SUR | AA7: CENTRO | AB7: SUR | AC7: SUR | AD7: SUR | AE7: SUR | AF7: SUR | AG7: SUR | AH7: SUR | AI7: SUR | AJ7: CENTRO | AK7: NORTE | AL7: NORTE | AM7: NORTE | AN7: CENTRO | AO7: CENTRO | AP7: CENTRO | AQ7: CENTRO | AR7: CENTRO | AS7: CENTRO | AT7: CENTRO | AU7: SUR | AV7: CENTRO | AW7: CENTRO | AX7: CENTRO | AY7: CENTRO | AZ7: CENTRO | BA7: CENTRO | BB7: CENTRO | BC7: CENTRO | BD7: SUR | BE7: NORTE | BF7: CENTRO | BG7: CENTRO | BH7: NORTE | BI7: NORTE | BJ7: NORTE | BK7: SUR | BL7: SUR | BM7: SUR | BN7: CENTRO | BO7: CENTRO | BP7: CENTRO | BQ7: CENTRO | BR7: CENTRO | BS7: CENTRO | BT7: CENTRO | BU7: SUR | BV7: SUR | BW7: SUR | BX7: NORTE | BY7: SUR | BZ7: CENTRO | CA7: NORTE | CB7: CENTRO | CC7: CENTRO | CD7: CENTRO | CE7: CENTRO | CF7: CENTRO | CG7: CENTRO | CH7: CENTRO | CI7: CENTRO | CJ7: CENTRO | CK7: CENTRO | CL7: CENTRO | CM7: CENTRO | CN7: SUR | CO7: SUR | CP7: SUR | CQ7: SUR | CR7: CENTRO | CS7: CENTRO | CT7: CENTRO | CU7: CENTRO | CV7: SUR | CW7: NORTE | CX7: NORTE | CY7: NORTE | CZ7: NORTE | DA7: NORTE | DB7: SUR | DC7: CENTRO | DD7: CENTRO | DE7: CENTRO | DF7: NORTE | DG7: NORTE | DH7: CENTRO | DI7: CENTRO | DJ7: SUR | DK7: SUR | DL7: CENTRO | DM7: CENTRO | DN7: CENTRO | DO7: CENTRO | DP7: CENTRO | DQ7: CENTRO | DR7: SUR | DS7: CENTRO | DT7: CENTRO | DU7: NORTE | DV7: CENTRO | DW7: CENTRO | DX7: NORTE | DY7: CENTRO | DZ7: CENTRO | EA7: CENTRO | EB7: NORTE | EC7: NORTE | ED7: SUR | EE7: CENTRO | EF7: CENTRO | EG7: CENTRO | EH7: CENTRO | EI7: CENTRO | EJ7: CENTRO | EK7: SUR | EL7: SUR | EM7: SUR | EN7: SUR | EO7: NORTE | EP7: SUR | EQ7: SUR | ER7: CENTRO | ES7: CENTRO | ET7: CENTRO | EU7: SUR | EV7: SUR | EW7: NORTE | EX7: CENTRO | EY7: NORTE | EZ7: NORTE | FA7: NORTE | FB7: CENTRO | FC7: CENTRO | FD7: CENTRO | FE7: NORTE | FF7: NORTE | FI7: NORTE | FJ7: CENTRO | FK7: NORTE | FL7: NORTE | FM7: NORTE | FN7: NORTE | FO7: NORTE | FP7: NORTE
C8: HIDROELÉCTRICA | D8: HIDROELÉCTRICA | E8: HIDROELÉCTRICA | F8: HIDROELÉCTRICA | G8: TERMOELÉCTRICA | H8: TERMOELÉCTRICA | I8: HIDROELÉCTRICA | J8: HIDROELÉCTRICA | K8: TERMOELÉCTRICA | L8: TERMOELÉCTRICA | M8: TERMOELÉCTRICA | N8: TERMOELÉCTRICA | O8: TERMOELÉCTRICA | P8: TERMOELÉCTRICA | Q8: TERMOELÉCTRICA | R8: TERMOELÉCTRICA | S8: HIDROELÉCTRICA | T8: HIDROELÉCTRICA | U8: TERMOELÉCTRICA | V8: TERMOELÉCTRICA | W8: TERMOELÉCTRICA | X8: TERMOELÉCTRICA | Y8: HIDROELÉCTRICA | Z8: HIDROELÉCTRICA | AA8: TERMOELÉCTRICA | AB8: HIDROELÉCTRICA | AC8: HIDROELÉCTRICA | AD8: HIDROELÉCTRICA | AE8: HIDROELÉCTRICA | AF8: TERMOELÉCTRICA | AG8: TERMOELÉCTRICA | AH8: TERMOELÉCTRICA | AI8: HIDROELÉCTRICA | AJ8: HIDROELÉCTRICA | AK8: TERMOELÉCTRICA | AL8: TERMOELÉCTRICA | AM8: TERMOELÉCTRICA | AN8: HIDROELÉCTRICA | AO8: HIDROELÉCTRICA | AP8: HIDROELÉCTRICA | AQ8: HIDROELÉCTRICA | AR8: HIDROELÉCTRICA | AS8: HIDROELÉCTRICA | AT8: HIDROELÉCTRICA | AU8: HIDROELÉCTRICA | AV8: TERMOELÉCTRICA | AW8: TERMOELÉCTRICA | AX8: TERMOELÉCTRICA | AY8: HIDROELÉCTRICA | AZ8: HIDROELÉCTRICA | BA8: HIDROELÉCTRICA | BB8: HIDROELÉCTRICA | BC8: HIDROELÉCTRICA | BD8: HIDROELÉCTRICA | BE8: HIDROELÉCTRICA | BF8: HIDROELÉCTRICA | BG8: HIDROELÉCTRICA | BH8: TERMOELÉCTRICA | BI8: TERMOELÉCTRICA | BJ8: TERMOELÉCTRICA | BK8: TERMOELÉCTRICA | BL8: TERMOELÉCTRICA | BM8: TERMOELÉCTRICA | BN8: HIDROELÉCTRICA | BO8: TERMOELÉCTRICA | BP8: TERMOELÉCTRICA | BQ8: TERMOELÉCTRICA | BR8: TERMOELÉCTRICA | BS8: TERMOELÉCTRICA | BT8: TERMOELÉCTRICA | BU8: TERMOELÉCTRICA | BV8: TERMOELÉCTRICA | BW8: TERMOELÉCTRICA | BX8: HIDROELÉCTRICA | BY8: TERMOELÉCTRICA | BZ8: TERMOELÉCTRICA | CA8: HIDROELÉCTRICA | CB8: HIDROELÉCTRICA | CC8: HIDROELÉCTRICA | CD8: HIDROELÉCTRICA | CE8: HIDROELÉCTRICA | CF8: HIDROELÉCTRICA | CG8: TERMOELÉCTRICA | CH8: TERMOELÉCTRICA | CI8: TERMOELÉCTRICA | CJ8: TERMOELÉCTRICA | CK8: TERMOELÉCTRICA | CL8: TERMOELÉCTRICA | CM8: TERMOELÉCTRICA | CN8: TERMOELÉCTRICA | CO8: TERMOELÉCTRICA | CP8: TERMOELÉCTRICA | CQ8: TERMOELÉCTRICA | CR8: TERMOELÉCTRICA | CS8: TERMOELÉCTRICA | CT8: SOLAR | CU8: EÓLICA | CV8: SOLAR | CW8: EÓLICA | CX8: SOLAR | CY8: HIDROELÉCTRICA | CZ8: HIDROELÉCTRICA | DA8: HIDROELÉCTRICA | DB8: HIDROELÉCTRICA | DC8: HIDROELÉCTRICA | DD8: HIDROELÉCTRICA | DE8: HIDROELÉCTRICA | DF8: HIDROELÉCTRICA | DG8: HIDROELÉCTRICA | DH8: HIDROELÉCTRICA | DI8: HIDROELÉCTRICA | DJ8: SOLAR | DK8: SOLAR | DL8: EÓLICA | DM8: EÓLICA | DN8: TERMOELÉCTRICA | DO8: TERMOELÉCTRICA | DP8: TERMOELÉCTRICA | DQ8: TERMOELÉCTRICA | DR8: SOLAR | DS8: HIDROELÉCTRICA | DT8: HIDROELÉCTRICA | DU8: HIDROELÉCTRICA | DV8: HIDROELÉCTRICA | DW8: HIDROELÉCTRICA | DX8: HIDROELÉCTRICA | DY8: HIDROELÉCTRICA | DZ8: HIDROELÉCTRICA | EA8: HIDROELÉCTRICA | EB8: EÓLICA | EC8: EÓLICA | ED8: SOLAR | EE8: EÓLICA | EF8: EÓLICA | EG8: EÓLICA | EH8: EÓLICA | EI8: HIDROELÉCTRICA | EJ8: HIDROELÉCTRICA | EK8: HIDROELÉCTRICA | EL8: HIDROELÉCTRICA | EM8: HIDROELÉCTRICA | EN8: HIDROELÉCTRICA | EO8: EÓLICA | EP8: SOLAR | EQ8: SOLAR | ER8: HIDROELÉCTRICA | ES8: EÓLICA | ET8: EÓLICA | EU8: SOLAR | EV8: SOLAR | EW8: HIDROELÉCTRICA | EX8: HIDROELÉCTRICA | EY8: TERMOELÉCTRICA | EZ8: TERMOELÉCTRICA | FA8: TERMOELÉCTRICA | FB8: TERMOELÉCTRICA | FC8: TERMOELÉCTRICA | FD8: TERMOELÉCTRICA | FE8: TERMOELÉCTRICA | FF8: TERMOELÉCTRICA | FI8: HIDROELÉCTRICA | FJ8: HIDROELÉCTRICA | FK8: HIDROELÉCTRICA | FL8: HIDROELÉCTRICA | FM8: TERMOELÉCTRICA | FN8: TERMOELÉCTRICA | FO8: HIDROELÉCTRICA | FP8: HIDROELÉCTRICA
C9: CENTRALES SANTA ROSA S.A.C. | D9: CENTRALES SANTA ROSA S.A.C. | E9: ELECTROPERU | F9: ELECTROPERU | G9: ELECTROPERU | H9: ELECTROPERU | I9: ORAZUL ENERGY PERÚ | J9: ORAZUL ENERGY PERÚ | K9: TERMOSELVA | L9: TERMOSELVA | M9: KALLPA GENERACION S.A. | N9: KALLPA GENERACION S.A. | O9: KALLPA GENERACION S.A. | P9: KALLPA GENERACION S.A. | Q9: KALLPA GENERACION S.A. | R9: KALLPA GENERACION S.A. | S9: KALLPA GENERACION S.A. | T9: KALLPA GENERACION S.A. | U9: SHOUGESA | V9: SHOUGESA | W9: SHOUGESA | X9: SHOUGESA | Y9: EGEMSA | Z9: EGESUR | AA9: EGESUR | AB9: EGASA | AC9: EGASA | AD9: EGASA | AE9: EGASA | AF9: EGASA | AG9: EGASA | AH9: EGASA | AI9: SAN GABAN | AJ9: CELEPSA | AK9: MINERA CERRO VERDE | AL9: PLANTA DE RESERVA FRIA DE GENERACION DE ETEN S.A. | AM9: PLANTA DE RESERVA FRIA DE GENERACION DE ETEN S.A. | AN9: EMPRESA DE GENERACION HUALLAGA | AO9: EMPRESA DE GENERACION HUALLAGA | AP9: LA VIRGEN | AQ9: CHINANGO S.A.C. | AR9: CHINANGO S.A.C. | AS9: HIDROELECTRICA HUANCHOR S.A.C. | AT9: CELEPSA RENOVABLES S.R.L. | AU9: INLAND ENERGY SAC | AV9: FENIX POWER PERÚ | AW9: FENIX POWER PERÚ | AX9: FENIX POWER PERÚ | AY9: STATKRAFT S.A | AZ9: STATKRAFT S.A | BA9: STATKRAFT S.A | BB9: STATKRAFT S.A | BC9: STATKRAFT S.A | BD9: STATKRAFT S.A | BE9: STATKRAFT S.A | BF9: STATKRAFT S.A | BG9: EMPRESA DE GENERACION HUANZA | BH9: ENEL GENERACION PIURA S.A. | BI9: ENEL GENERACION PIURA S.A. | BJ9: ENEL GENERACION PIURA S.A. | BK9: ENGIE | BL9: ENGIE | BM9: ENGIE | BN9: ENGIE | BO9: ENGIE | BP9: ENGIE | BQ9: ENGIE | BR9: ENGIE | BS9: ENGIE | BT9: ENGIE | BU9: ENGIE | BV9: ENGIE | BW9: ENGIE | BX9: ENGIE | BY9: INFRAESTRUCTURAS Y ENERGIAS DEL PERU S.A.C. | BZ9: INFRAESTRUCTURAS Y ENERGIAS DEL PERU S.A.C. | CA9: INVERSIONES SHAQSHA S.A.C. | CB9: ORYGEN PERU S.A.A. | CC9: ORYGEN PERU S.A.A. | CD9: ORYGEN PERU S.A.A. | CE9: ORYGEN PERU S.A.A. | CF9: ORYGEN PERU S.A.A. | CG9: ORYGEN PERU S.A.A. | CH9: ORYGEN PERU S.A.A. | CI9: ORYGEN PERU S.A.A. | CJ9: ORYGEN PERU S.A.A. | CK9: ORYGEN PERU S.A.A. | CL9: ORYGEN PERU S.A.A. | CM9: ORYGEN PERU S.A.A. | CN9: SAMAY I S.A.C | CO9: SAMAY I S.A.C | CP9: SAMAY I S.A.C | CQ9: SAMAY I S.A.C | CR9: TERMOCHILCA S.A.C. | CS9: TERMOCHILCA S.A.C. | CT9: COLCA SOLAR S.A.C. | CU9: ENERGIA RENOVABLE DEL SUR S.A. | CV9: GR CORTARRAMA SOCIEDAD ANONIMA CERRADA | CW9: GR TARUCA SOCIEDAD ANONIMA CERRADA | CX9: KONDU SAC | CY9: PERUANA DE INVERSIONES EN ENERGIAS RENOVABLES S.A. | CZ9: ORAZUL ENERGY PERÚ | DA9: ORAZUL ENERGY PERÚ | DB9: SAN GABAN | DC9: MAJA ENERGIA S.A.C. | DD9: EMPRESA DE GENERACION ELECTRICA CANCHAYLLO SAC | DE9: EMPRESA DE GENERACION ELECTRICA SANTA ANA S.A.C. | DF9: EMPRESA ELECTRICA AGUA AZUL | DG9: EMPRESA ELECTRICA RIO DOBLE | DH9: HIDROCAÑETE S.A. | DI9: HUAURA POWER GROUP S.A. | DJ9: MOQUEGUA FV S.A.C. | DK9: PANAMERICANA SOLAR SAC. | DL9: PARQUE EOLICO MARCONA S.A.C. | DM9: PARQUE EOLICO TRES HERMANAS S.A.C. | DN9: PETRAMAS | DO9: PETRAMAS | DP9: PETRAMAS | DQ9: PETRAMAS | DR9: TACNA SOLAR SAC. | DS9: ELECTRICA YANAPAMPA SAC | DT9: ANDEAN POWER S.A.C. | DU9: ASOCIACIÓN SANTA LUCIA DE CHACAS | DV9: ATRIA ENERGIA S.A.C. | DW9: EGEJUNIN | DX9: EGEJUNIN | DY9: EGEJUNIN | DZ9: EGEJUNIN | EA9: EMPRESA DE GENERACION ELECTRICA RIO BAÑOS S.A.C. | EB9: ENERGÍA EÓLICA S.A. | EC9: ENERGÍA EÓLICA S.A. | ED9: ENGIE | EE9: ENGIE | EF9: ENGIE | EG9: ENGIE | EH9: ENGIE | EI9: GENERACIÓN ANDINA S.A.C. | EJ9: GENERACIÓN ANDINA S.A.C. | EK9: GENERADORA DE ENERGÍA DEL PERÚ | EL9: GENERADORA DE ENERGÍA DEL PERÚ | EM9: GENERADORA DE ENERGÍA DEL PERÚ | EN9: GENERADORA DE ENERGÍA DEL PERÚ | EO9: GR PAINO SOCIEDAD ANONIMA CERRADA | EP9: MAJES ARCUS S.A.C. | EQ9: ORYGEN PERU S.A.A. | ER9: ORYGEN PERU S.A.A. | ES9: ORYGEN PERU S.A.A. | ET9: ORYGEN PERU S.A.A. | EU9: ORYGEN PERU S.A.A. | EV9: REPARTICIÓN ARCUS S.A.C. | EW9: SINERSA | EX9: SINERSA | EY9: BIOENERGIA DEL CHIRA S.A. | EZ9: GM OPERACIONES S.A.C. | FA9: GM OPERACIONES S.A.C. | FB9: SDF ENERGIA SAC | FC9: SDF ENERGIA SAC | FD9: AGRO INDUSTRIAL PARAMONGA S.A. | FE9: AGROAURORA S.A.C. | FF9: AGROINDUSTRIAS SAN JACINTO S.A.A. | FI9: UNACEM PERU S.A. | FJ9: ELECTRO ORIENTE | FK9: AGUAS Y ENERGIA PERU | FL9: ELECTRO ZAÑA S.A.C. | FM9: ELECTRONOROESTE S.A. | FN9: SDE PIURA | FO9: SINERSA | FP9: SINERSA
