Workbook

Sheet EVENTOS
B3: sábado, 25 de Enero del 2025
B5: INFORMACIÓN DE EVENTOS PRINCIPALES EN SUS INSTALACIONES
B6: TIPO DE EVENTO | C6: EMPRESA | D6: UBICACIÓN | E6: TIPO DE EQUIPO | F6: EQUIPO | G6: INICIO | H6: FINAL | I6: DESCRIPCIÓN | J6: MW INDISP. | K6: INTERRUPCIÓN (SI/NO) | L6: TENSIÓN DE FALLA (kV)
B7: EVENTO | C7: CONELSUR LT SAC | D7: PORTILLO | E7: SUBESTACION | F7: SS.EE. | G7: 25/01/2025 00:00:00 | H7: 26/01/2025 00:00:00 | I7: DECLARACIÓN DE SITUACIÓN EXCEPCIONAL EN LA S.E. PORTILLO DE 60 kV | K7: NO
B8: FALLA | C8: EMPRESA ELECTRICA AGUA AZUL | D8: POTRERO | E8: CENTRAL HIDROELÉCTRICA | F8: CENTRAL | G8: 25/01/2025 21:05:00 | H8: 25/01/2025 21:22:00 | I8: DESCONEXIÓN DEL GENERADOR G1 DE LA C.H. POTRERO POR FALLA | K8: NO | L8: 10
B9: FALLA | C9: HUAURA POWER GROUP S.A. | D9: YARUCAYA | E9: CENTRAL HIDROELÉCTRICA | F9: CENTRAL | G9: 25/01/2025 10:10:00 | H9: 25/01/2025 11:18:00 | I9: DESCONEXIÓN DEL GENERADOR G1 DE LA C.H. YARUCAYA POR FALLA | K9: NO | L9: 13.8
B10: EVENTO | C10: RED DE ENERGIA DEL PERU S.A. | D10: TINGO MARÍA - AUCAYACU | E10: LINEA DE TRANSMISION | F10: L-1122 | G10: 25/01/2025 19:05:00 | H10: 25/01/2025 20:30:00 | I10: DECLARACIÓN DE SITUACIÓN EXCEPCIONAL EN LA LÍNEA L-1122 (TINGO MARÍA - AUCAYACU) DE 138 KV | K10: NO
B11: FALLA | C11: RED DE ENERGIA DEL PERU S.A. | D11: TRUJILLO NORTE - CHIMBOTE 1 | E11: LINEA DE TRANSMISION | F11: L-2233 | G11: 25/01/2025 10:48:00 | H11: 26/01/2025 00:00:00 | I11: DESCONEXIÓN DE LA LÍNEA L-2233 (CHIMBOTE 1 - TRUJILLO NORTE) DE 220 kV POR FALLA | K11: NO | L11: 220
B12: FALLA | C12: RED DE ENERGIA DEL PERU S.A. | D12: TRUJILLO NORTE | E12: SVC | F12: SVC-1 | G12: 25/01/2025 21:08:00 | H12: 25/01/2025 22:51:00 | I12: DESCONEXIÓN DEL SVC-1 DE LA S.E. TRUJILLO NORTE POR FALLA | K12: NO | L12: 0
B13: FALLA | C13: TRANSMANTARO | D13: COTARUSE | E13: BANCO DE CONDENSADORES SERIE | F13: CAPAC XC1 | G13: 25/01/2025 15:15:00 | H13: 25/01/2025 17:33:00 | I13: DESCONEXIÓN DEL BANCO SERIE XC1 DE LA S.E. COTARUSE POR FALLA | K13: NO | L13: 0

Sheet RESTRIC_OPE
B3: sábado, 25 de Enero del 2025
B5: RESTRICCIONES OPERATIVAS
B6: FECHA | C6: HORA INICIO | D6: HORA FINAL | E6: EMPRESA | F6: UBICACIÓN | G6: T.Eq. | H6: EQUIPO | I6: DESCRIPCIÓN
B7: 25/01/2025 | C7: 00:00 | D7: 24:00 | E7: CELEPSA | F7: C.H. EL PLATANAL | G7: CH | H7: CENTRAL | I7: Debido al incremento del caudal del rio cañete y establecimiento de la temporada de avenida, se declara la C.H. El Platanal como CENTRAL HIDRÁULICA DE PASADA (correo 03/01/2025).
B8: 25/01/2025 | C8: 00:00 | D8: 24:00 | E8: EGASA | F8: S.E. CONVERTIDOR | G8: BARRA | H8: BARRA138KV | I8: EGASA limitó la capacidad del transformador 138 kV/33 kV a 50 MVA por deterioro del aislamiento.
B9: 25/01/2025 | C9: 00:00 | D9: 24:00 | E9: ENEL GENERACION PIURA S.A. | F9: C.T. MALACAS | G9: CT | H9: CENTRAL | I9: De acuerdo con la comunicación vía correo del día 24.10.2024. ENEL GENERACIÓN PIURA informa una restricción de potencia para alcanzar 105 MW en simultaneo (TG6+TGN4).
B10: 25/01/2025 | C10: 00:00 | D10: 24:00 | E10: ENGIE | F10: C.E. PUNTA LOMITAS | G10: CE | H10: CENTRAL | I10: De acuerdo a la carta ENG/737-2024 (Exp:202400007555). Limitación de cables de media tensión a 100 MW de los transformadores PLT1 y PLT2 de la CE Punta Lomitas. Quedan limitados a 200 MW la generación de CE Punta Lomitas y Punta Lomitas Extensión.
B11: 25/01/2025 | C11: 00:00 | D11: 24:00 | E11: ENGIE | F11: C.H. QUITARACSA | G11: CH | H11: CENTRAL | I11: De acuerdo con el correo del 23.04 se considera la operación continua de la CH Quitaracsa debido a que el sistema de refrigeración de la CH Cañón del Pato se alimenta desde la descarga del caudal turbinado por la CH Quitaracsa.
B12: 25/01/2025 | C12: 00:00 | D12: 24:00 | E12: ENGIE | F12: C.H. YUNCÁN | G12: GH | H12: G3 | I12: Según la carta N° ENG/ 198-2024 enviada por su representada, se opera de forma continua el G3 de la CH Yuncán, debido a la ejecución de mantenimientos necesarios para evitar daños en los sellos de seguridad de la válvula esférica del grupo.
B13: 25/01/2025 | C13: 00:00 | D13: 24:00 | E13: ENGIE | F13: C.T. CHILCA 1 | G13: CT | H13: CENTRAL | I13: Restricción de temperatura de la C.T Chilca, ver valor en el modelo de despacho.
B14: 25/01/2025 | C14: 00:00 | D14: 24:00 | E14: ENGIE | F14: C.T. CHILCA 1 | G14: CT | H14: CENTRAL | I14: Con carta ENG/971-2023, indica que no puede cumplir con las IO considerada en el PDO_17122023 dado que vulneran la seguridad de sus activos. Indican que se debe tomar TMO=168h.
B15: 25/01/2025 | C15: 00:00 | D15: 24:00 | E15: ENGIE | F15: C.T. CHILCA 2 | G15: CT | H15: CENTRAL | I15: Restricción de temperatura de la C.T Chilca2, ver valor en el modelo de despacho.
B16: 25/01/2025 | C16: 00:00 | D16: 24:00 | E16: ENGIE | F16: C.T. CHILCA 2 | G16: CT | H16: CENTRAL | I16: Con carta ENG/971-2023, indica que no puede cumplir con las IO considerada en el PDO_17122023 dado que vulneran la seguridad de sus activos. Indican que se debe tomar TMO=168h.
B17: 25/01/2025 | C17: 00:00 | D17: 24:00 | E17: FENIX POWER PERÚ | F17: C.T. FENIX | G17: CT | H17: CENTRAL | I17: Restricción de temperatura de la CT FENIX, ver valor en el modelo de despacho
... B41: 25/01/2025 | C41: 00:00 | D41: 24:00 | E41: TRANSMANTARO | F41: S.E. SOCABAYA | G41: SSEE | H41: S.E. | I41: Opera en simple barra en 220 kV por indisponibilidad de la protección diferencial de barras por alarma.

Sheet MANTENIMIENTO EJECUTADOS
B3: sábado, 25 de Enero del 2025
B5: Mantenimiento Ejecutado
B6: Empresa | C6: Ubicación | D6: Equipo | E6: Inicio | F6: Final | G6: Descripción | H6: MW Indisp. | I6: Prog. | J6: Dispon | K6: Interrupc. | L6: Tipo | M6: CodEq | N6: TipoEq_Osinerg
B7: ATLANTICA TRANSMISION SUR S.A. | C7: CHILCA-CTM | D7: INT-5261 | E7: 25/01/2025 00:00 | F7: 26/01/2025 00:00 | G7: Seccionador SBB-5261 fase S indisponible para maniobras de apertura y cierre por anomalia en tapa de tanque de compresion, el seccionador permanece cerrado y bloqueado. | H7: 0 | I7: P | J7: E/S | K7: N | L7: OTROS | M7: 13854 | N7: T
B8: ATLANTICA TRANSMISION SUR S.A. | C8: OCONA | D8: INT-5450 | E8: 25/01/2025 00:00 | F8: 26/01/2025 00:00 | G8: RESTRICCION OPERATIVA EN INTERRUPTOR INT-5450, POSICION CERRADA, REB-5450 EN SERVICIO SUMINISTRANDO LOS SS.AA. DE S.E. OCO?A | H8: 0 | I8: P | J8: E/S | K8: N | L8: OTROS | M8: 13761 | N8: T
B9: ATLANTICA TRANSMISION SUR S.A. | C9: OCONA | D9: INT-5462 | E9: 25/01/2025 00:00 | F9: 26/01/2025 00:00 | G9: Seccionador SBA-5462 fase T indisponible por problemas mecanicos, el seccionador permanece cerrado y bloqueado | H9: 0 | I9: P | J9: E/S | K9: N | L9: OTROS | M9: 13758 | N9: T
B10: ATLANTICA TRANSMISION SUR S.A. | C10: OCONA | D10: CL- 5034 | E10: 25/01/2025 08:00 | F10: 25/01/2025 16:00 | G10: Pruebas de mando de los equipos del BCS-5482, REL-5481 y otros por cambio de RTU. | H10: 0 | I10: P | J10: F/S | K10: N | L10: PREV. | M10: 13800 | N10: T
B11: ATLANTICA TRANSMISION SUR S.A. | C11: OCONA | D11: CL-REB-5450 | E11: 25/01/2025 08:00 | F11: 25/01/2025 16:00 | G11: Pruebas de mando de los equipos SBA-5450 e INT-5450 por cambio de RTU. | H11: 0 | I11: P | J11: F/S | K11: N | L11: PREV. | M11: 13803 | N11: T
B12: ATLANTICA TRANSMISION SUR S.A. | C12: OCONA | D12: CL- 5034 | E12: 25/01/2025 08:22 | F12: 25/01/2025 17:25 | G12: MANTENIMIENTO PREVENTIVO EN EQUIPOS DE CELDA | H12: 0 | I12: P | J12: F/S | K12: N | L12: PREV. | M12: 13800 | N12: T
B13: ATLANTICA TRANSMISION SUR S.A. | C13: OCONA | D13: CL-5036 | E13: 25/01/2025 10:00 | F13: 25/01/2025 13:00 | G13: Pruebas de mando de los equipos del BCS-5484, REL-5483 y otros por cambio de RTU. | H13: 0 | I13: P | J13: F/S | K13: N | L13: PREV. | M13: 13802 | N13: T
B14: ATLANTICA TRANSMISION SUR S.A. | C14: OCONA - SAN JOSE | D14: L-5036 | E14: 25/01/2025 08:22 | F14: 25/01/2025 17:25 | G14: INDISPONIBLE POR MANTENIMIENTO EN LA LINEA L-5034 | H14: 0 | I14: P | J14: F/S | K14: N | L14: OTROS | M14: 14961 | N14: T
B15: ATLANTICA TRANSMISION SUR S.A. | C15: POROMA | D15: INT-5361 | E15: 25/01/2025 00:00 | F15: 26/01/2025 00:00 | G15: Seccionador SBA-5361 fase R indisponible por problemas mecanicos, el seccionador permanece cerrado y bloqueado | H15: 0 | I15: P | J15: E/S | K15: N | L15: OTROS | M15: 13746 | N15: T
B16: ATLANTICA TRANSMISION SUR S.A. | C16: POROMA | D16: REB-5350 | E16: 25/01/2025 00:00 | F16: 26/01/2025 00:00 | G16: FUERA DE SERVICIO POR FALLA EN EL EQUIPO. | H16: 0 | I16: P | J16: F/S | K16: N | L16: OTROS | M16: 13771 | N16: T
B17: ATLANTICA TRANSMISION SUR S.A. | C17: POROMA | D17: CL-5034 | E17: 25/01/2025 08:22 | F17: 25/01/2025 17:25 | G17: MANTENIMIENTO PREVENTIVO EN EQUIPOS DE CELDA | H17: 0 | I17: P | J17: F/S | K17: N | L17: PREV. | M17: 13790 | N17: T
B18: ATLANTICA TRANSMISION SUR S.A. | C18: POROMA - OCONA | D18: L-5034 | E18: 25/01/2025 08:22 | F18: 25/01/2025 17:25 | G18: LIMPIEZA DE AISLAMIENTO | H18: 0 | I18: P | J18: F/S | K18: N | L18: PREV. | M18: 13743 | N18: T
... B109: TRANSMANTARO | C109: YARABAMBA | D109: AT-104 523 | E109: 25/01/2025 00:00 | F109: 26/01/2025 00:00 | G109: NO SE TIENE MANDO REMOTO PARA CONTROLAR LOS TAPS DEL AUTOTRANSFORMADOR POR PROBLEMAS EN EL TRANSDUCTOR. LA MANIOBRA ES LOCAL Y REQUIERE AL ASISTENTE EN LA SUBESTACION PARA LAS MANIOBRAS. | H109: 0 | I109: P | J109: E/S | K109: N | L109: OTROS | M109: 17433 | N109: T

Sheet INGRESO OC
A3: sábado, 25 de Enero del 2025
A5: INGRESO A OPERACIÓN COMERCIAL
A6: EMPRESA | B6: TIPO DE EQUIPO | C6: UBICACIÓN | D6: EQUIPO | E6: Fecha y hora de Ingreso a Operación Comercial

Sheet DESPACHO_EJECUTADO
B3: sábado, 25 de Enero del 2025
A5: POTENCIA ACTIVA EJECUTADA DE LAS UNIDADES DE GENERACIÓN DEL SEIN (MW) | FI5: CENTRALES NO INTEGRANTES COES
A6: FECHA | B6: HORA | C6: 337 | D6: 338 | E6: 121 | F6: 101 | G6: 102 | H6: 42667 | I6: 42668 | J6: 126 | K6: 127 | L6: 138 | M6: 139 | N6: 197 | O6: 203 | P6: 204 | Q6: 230 | R6: 209 | S6: 56677 | T6: 796 | U6: 2146 | V6: 142 | W6: 143 | X6: 125 | Y6: 187 | Z6: 163 | AA6: 298 | AB6: 299 | AC6: 219 | AD6: 151 | AE6: 152 | AF6: 153 | AG6: 154 | AH6: 756 | AI6: 156 | AJ6: 155 | AK6: 182 | AL6: 212 | AM6: 758 | AN6: 263 | AO6: 265 | AP6: 775 | AQ6: 777 | AR6: 2154 | AS6: 150 | AT6: 149 | AU6: 188 | AV6: 2131 | AW6: 755 | AX6: 252 | AY6: 249 | AZ6: 250 | BA6: 117 | BB6: 267 | BC6: 268 | BD6: 119 | BE6: 120 | BF6: 189 | BG6: 122 | BH6: 266 | BI6: 251 | BJ6: 115 | BK6: 239 | BL6: 288 | BM6: 240 | BN6: 241 | BO6: 242 | BP6: 191 | BQ6: 194 | BR6: 196 | BS6: 207 | BT6: 236 | BU6: 795 | BV6: 285 | BW6: 995 | BX6: 996 | BY6: 997 | BZ6: 766 | CA6: 926 | CB6: 924 | CC6: 103 | CD6: 104 | CE6: 106 | CF6: 105 | CG6: 107 | CH6: 110 | CI6: 109 | CJ6: 144 | CK6: 113 | CL6: 114 | CM6: 193 | CN6: 208 | CO6: 786 | CP6: 787 | CQ6: 788 | CR6: 789 | CS6: 248 | CT6: 2159 | CU6: 303 | CV6: 59715 | CW6: 62255 | CX6: 1263 | CY6: 61800 | CZ6: 2194 | DA6: 216 | DB6: 198 | DC6: 214 | DD6: 260 | DE6: 2152 | DF6: 2128 | DG6: 247 | DH6: 228 | DI6: 2135 | DJ6: 261 | DK6: 237 | DL6: 253 | DM6: 770 | DN6: 225 | DO6: 2201 | DP6: 2171 | DQ6: 760 | DR6: 235 | DS6: 238 | DT6: 2184 | DU6: 61855 | DV6: 223 | DW6: 226 | DX6: 201 | DY6: 258 | DZ6: 259 | EA6: 920 | EB6: 257 | EC6: 256 | ED6: 2148 | EE6: 58288 | EF6: 58289 | EG6: 58839 | EH6: 58840 | EI6: 296 | EJ6: 297 | EK6: 211 | EL6: 2175 | EM6: 2178 | EN6: 2181 | EO6: 1262 | EP6: 233 | EQ6: 2150 | ER6: 2165 | ES6: 2161 | ET6: 61197 | EU6: 58851 | EV6: 234 | EW6: 215 | EX6: 917 | EY6: 289 | EZ6: 58333 | FA6: 58336 | FB6: 202 | FC6: 58487 | FD6: 213 | FE6: 232 | FF6: 2190 | FG6: TOTAL COES | FI6: 221 | FJ6: 49607 | FK6: 222 | FL6: 224 | FM6: 2187 | FN6: 227 | FO6: 49400 | FP6: 199 | FQ6: 200 | FR6: TOTAL NO COES
C7: CENTRO | D7: CENTRO | E7: NORTE | F7: CENTRO | G7: CENTRO | H7: NORTE | I7: NORTE | J7: NORTE | K7: NORTE | L7: CENTRO | M7: CENTRO | N7: CENTRO | O7: CENTRO | P7: CENTRO | Q7: CENTRO | R7: CENTRO | S7: CENTRO | T7: CENTRO | U7: CENTRO | V7: CENTRO | W7: CENTRO | X7: CENTRO | Y7: CENTRO | Z7: SUR | AA7: SUR | AB7: SUR | AC7: CENTRO | AD7: SUR | AE7: SUR | AF7: SUR | AG7: SUR | AH7: SUR | AI7: SUR | AJ7: SUR | AK7: SUR | AL7: CENTRO | AM7: NORTE | AN7: NORTE | AO7: NORTE | AP7: CENTRO | AQ7: CENTRO | AR7: CENTRO | AS7: CENTRO | AT7: CENTRO | AU7: CENTRO | AV7: CENTRO | AW7: SUR | AX7: CENTRO | AY7: CENTRO | AZ7: CENTRO | BA7: CENTRO | BB7: CENTRO | BC7: CENTRO | BD7: CENTRO | BE7: CENTRO | BF7: SUR | BG7: NORTE | BH7: CENTRO | BI7: CENTRO | BJ7: NORTE | BK7: NORTE | BL7: NORTE | BM7: SUR | BN7: SUR | BO7: SUR | BP7: CENTRO | BQ7: CENTRO | BR7: CENTRO | BS7: CENTRO | BT7: CENTRO | BU7: CENTRO | BV7: CENTRO | BW7: SUR | BX7: SUR | BY7: SUR | BZ7: NORTE | CA7: SUR | CB7: CENTRO | CC7: CENTRO | CD7: CENTRO | CE7: CENTRO | CF7: CENTRO | CG7: CENTRO | CH7: CENTRO | CI7: CENTRO | CJ7: CENTRO | CK7: CENTRO | CL7: CENTRO | CM7: CENTRO | CN7: CENTRO | CO7: SUR | CP7: SUR | CQ7: SUR | CR7: SUR | CS7: CENTRO | CT7: CENTRO | CU7: CENTRO | CV7: CENTRO | CW7: SUR | CX7: NORTE | CY7: NORTE | CZ7: NORTE | DA7: NORTE | DB7: NORTE | DC7: CENTRO | DD7: CENTRO | DE7: CENTRO | DF7: NORTE | DG7: NORTE | DH7: CENTRO | DI7: CENTRO | DJ7: SUR | DK7: SUR | DL7: CENTRO | DM7: CENTRO | DN7: CENTRO | DO7: CENTRO | DP7: CENTRO | DQ7: CENTRO | DR7: SUR | DS7: CENTRO | DT7: CENTRO | DU7: NORTE | DV7: CENTRO | DW7: CENTRO | DX7: NORTE | DY7: CENTRO | DZ7: CENTRO | EA7: CENTRO | EB7: NORTE | EC7: NORTE | ED7: SUR | EE7: CENTRO | EF7: CENTRO | EG7: CENTRO | EH7: CENTRO | EI7: CENTRO | EJ7: CENTRO | EK7: SUR | EL7: SUR | EM7: SUR | EN7: SUR | EO7: NORTE | EP7: SUR | EQ7: SUR | ER7: CENTRO | ES7: CENTRO | ET7: CENTRO | EU7: SUR | EV7: SUR | EW7: NORTE | EX7: CENTRO | EY7: NORTE | EZ7: NORTE | FA7: NORTE | FB7: CENTRO | FC7: CENTRO | FD7: CENTRO | FE7: NORTE | FF7: NORTE | FI7: NORTE | FJ7: SUR | FK7: CENTRO | FL7: NORTE | FM7: NORTE | FN7: NORTE | FO7: NORTE | FP7: NORTE | FQ7: NORTE
C8: HIDROELÉCTRICA | D8: HIDROELÉCTRICA | E8: HIDROELÉCTRICA | F8: HIDROELÉCTRICA | G8: HIDROELÉCTRICA | H8: TERMOELÉCTRICA | I8: TERMOELÉCTRICA | J8: HIDROELÉCTRICA | K8: HIDROELÉCTRICA | L8: TERMOELÉCTRICA | M8: TERMOELÉCTRICA | N8: TERMOELÉCTRICA | O8: TERMOELÉCTRICA | P8: TERMOELÉCTRICA | Q8: TERMOELÉCTRICA | R8: TERMOELÉCTRICA | S8: TERMOELÉCTRICA | T8: HIDROELÉCTRICA | U8: HIDROELÉCTRICA | V8: TERMOELÉCTRICA | W8: TERMOELÉCTRICA | X8: TERMOELÉCTRICA | Y8: TERMOELÉCTRICA | Z8: HIDROELÉCTRICA | AA8: HIDROELÉCTRICA | AB8: HIDROELÉCTRICA | AC8: TERMOELÉCTRICA | AD8: HIDROELÉCTRICA | AE8: HIDROELÉCTRICA | AF8: HIDROELÉCTRICA | AG8: HIDROELÉCTRICA | AH8: TERMOELÉCTRICA | AI8: TERMOELÉCTRICA | AJ8: TERMOELÉCTRICA | AK8: HIDROELÉCTRICA | AL8: HIDROELÉCTRICA | AM8: TERMOELÉCTRICA | AN8: TERMOELÉCTRICA | AO8: TERMOELÉCTRICA | AP8: HIDROELÉCTRICA | AQ8: HIDROELÉCTRICA | AR8: HIDROELÉCTRICA | AS8: HIDROELÉCTRICA | AT8: HIDROELÉCTRICA | AU8: HIDROELÉCTRICA | AV8: HIDROELÉCTRICA | AW8: HIDROELÉCTRICA | AX8: TERMOELÉCTRICA | AY8: TERMOELÉCTRICA | AZ8: TERMOELÉCTRICA | BA8: HIDROELÉCTRICA | BB8: HIDROELÉCTRICA | BC8: HIDROELÉCTRICA | BD8: HIDROELÉCTRICA | BE8: HIDROELÉCTRICA | BF8: HIDROELÉCTRICA | BG8: HIDROELÉCTRICA | BH8: HIDROELÉCTRICA | BI8: HIDROELÉCTRICA | BJ8: TERMOELÉCTRICA | BK8: TERMOELÉCTRICA | BL8: TERMOELÉCTRICA | BM8: TERMOELÉCTRICA | BN8: TERMOELÉCTRICA | BO8: TERMOELÉCTRICA | BP8: HIDROELÉCTRICA | BQ8: TERMOELÉCTRICA | BR8: TERMOELÉCTRICA | BS8: TERMOELÉCTRICA | BT8: TERMOELÉCTRICA | BU8: TERMOELÉCTRICA | BV8: TERMOELÉCTRICA | BW8: TERMOELÉCTRICA | BX8: TERMOELÉCTRICA | BY8: TERMOELÉCTRICA | BZ8: HIDROELÉCTRICA | CA8: TERMOELÉCTRICA | CB8: TERMOELÉCTRICA | CC8: HIDROELÉCTRICA | CD8: HIDROELÉCTRICA | CE8: HIDROELÉCTRICA | CF8: HIDROELÉCTRICA | CG8: HIDROELÉCTRICA | CH8: TERMOELÉCTRICA | CI8: TERMOELÉCTRICA | CJ8: TERMOELÉCTRICA | CK8: TERMOELÉCTRICA | CL8: TERMOELÉCTRICA | CM8: TERMOELÉCTRICA | CN8: TERMOELÉCTRICA | CO8: TERMOELÉCTRICA | CP8: TERMOELÉCTRICA | CQ8: TERMOELÉCTRICA | CR8: TERMOELÉCTRICA | CS8: TERMOELÉCTRICA | CT8: TERMOELÉCTRICA | CU8: SOLAR | CV8: EÓLICA | CW8: SOLAR | CX8: EÓLICA | CY8: SOLAR | CZ8: HIDROELÉCTRICA | DA8: HIDROELÉCTRICA | DB8: HIDROELÉCTRICA | DC8: HIDROELÉCTRICA | DD8: HIDROELÉCTRICA | DE8: HIDROELÉCTRICA | DF8: HIDROELÉCTRICA | DG8: HIDROELÉCTRICA | DH8: HIDROELÉCTRICA | DI8: HIDROELÉCTRICA | DJ8: SOLAR | DK8: SOLAR | DL8: EÓLICA | DM8: EÓLICA | DN8: TERMOELÉCTRICA | DO8: TERMOELÉCTRICA | DP8: TERMOELÉCTRICA | DQ8: TERMOELÉCTRICA | DR8: SOLAR | DS8: HIDROELÉCTRICA | DT8: HIDROELÉCTRICA | DU8: HIDROELÉCTRICA | DV8: HIDROELÉCTRICA | DW8: HIDROELÉCTRICA | DX8: HIDROELÉCTRICA | DY8: HIDROELÉCTRICA | DZ8: HIDROELÉCTRICA | EA8: HIDROELÉCTRICA | EB8: EÓLICA | EC8: EÓLICA | ED8: SOLAR | EE8: EÓLICA | EF8: EÓLICA | EG8: EÓLICA | EH8: EÓLICA | EI8: HIDROELÉCTRICA | EJ8: HIDROELÉCTRICA | EK8: HIDROELÉCTRICA | EL8: HIDROELÉCTRICA | EM8: HIDROELÉCTRICA | EN8: HIDROELÉCTRICA | EO8: EÓLICA | EP8: SOLAR | EQ8: SOLAR | ER8: HIDROELÉCTRICA | ES8: EÓLICA | ET8: EÓLICA | EU8: SOLAR | EV8: SOLAR | EW8: HIDROELÉCTRICA | EX8: HIDROELÉCTRICA | EY8: TERMOELÉCTRICA | EZ8: TERMOELÉCTRICA | FA8: TERMOELÉCTRICA | FB8: TERMOELÉCTRICA | FC8: TERMOELÉCTRICA | FD8: TERMOELÉCTRICA | FE8: TERMOELÉCTRICA | FF8: TERMOELÉCTRICA | FI8: HIDROELÉCTRICA | FJ8: HIDROELÉCTRICA | FK8: HIDROELÉCTRICA | FL8: HIDROELÉCTRICA | FM8: HIDROELÉCTRICA | FN8: TERMOELÉCTRICA | FO8: TERMOELÉCTRICA | FP8: HIDROELÉCTRICA | FQ8: HIDROELÉCTRICA
C9: CENTRALES SANTA ROSA S.A.C. | D9: CENTRALES SANTA ROSA S.A.C. | E9: INVERSIONES SHAQSHA S.A.C. | F9: ELECTROPERU | G9: ELECTROPERU | H9: ELECTROPERU | I9: ELECTROPERU | J9: ORAZUL ENERGY PERÚ | K9: ORAZUL ENERGY PERÚ | L9: TERMOSELVA | M9: TERMOSELVA | N9: KALLPA GENERACION S.A. | O9: KALLPA GENERACION S.A. | P9: KALLPA GENERACION S.A. | Q9: KALLPA GENERACION S.A. | R9: KALLPA GENERACION S.A. | S9: KALLPA GENERACION S.A. | T9: KALLPA GENERACION S.A. | U9: KALLPA GENERACION S.A. | V9: SHOUGESA | W9: SHOUGESA | X9: SHOUGESA | Y9: SHOUGESA | Z9: EGEMSA | AA9: EGESUR | AB9: EGESUR | AC9: EGESUR | AD9: EGASA | AE9: EGASA | AF9: EGASA | AG9: EGASA | AH9: EGASA | AI9: EGASA | AJ9: EGASA | AK9: SAN GABAN | AL9: CELEPSA | AM9: MINERA CERRO VERDE | AN9: PLANTA DE RESERVA FRIA DE GENERACION DE ETEN S.A. | AO9: PLANTA DE RESERVA FRIA DE GENERACION DE ETEN S.A. | AP9: EMPRESA DE GENERACION HUALLAGA | AQ9: EMPRESA DE GENERACION HUALLAGA | AR9: LA VIRGEN | AS9: CHINANGO S.A.C. | AT9: CHINANGO S.A.C. | AU9: HIDROELECTRICA HUANCHOR S.A.C. | AV9: CELEPSA RENOVABLES S.R.L. | AW9: INLAND ENERGY SAC | AX9: FENIX POWER PERÚ | AY9: FENIX POWER PERÚ | AZ9: FENIX POWER PERÚ | BA9: STATKRAFT S.A | BB9: STATKRAFT S.A | BC9: STATKRAFT S.A | BD9: STATKRAFT S.A | BE9: STATKRAFT S.A | BF9: STATKRAFT S.A | BG9: STATKRAFT S.A | BH9: STATKRAFT S.A | BI9: EMPRESA DE GENERACION HUANZA | BJ9: ENEL GENERACION PIURA S.A. | BK9: ENEL GENERACION PIURA S.A. | BL9: ENEL GENERACION PIURA S.A. | BM9: ENGIE | BN9: ENGIE | BO9: ENGIE | BP9: ENGIE | BQ9: ENGIE | BR9: ENGIE | BS9: ENGIE | BT9: ENGIE | BU9: ENGIE | BV9: ENGIE | BW9: ENGIE | BX9: ENGIE | BY9: ENGIE | BZ9: ENGIE | CA9: INFRAESTRUCTURAS Y ENERGIAS DEL PERU S.A.C. | CB9: INFRAESTRUCTURAS Y ENERGIAS DEL PERU S.A.C. | CC9: ORYGEN PERU S.A.A. | CD9: ORYGEN PERU S.A.A. | CE9: ORYGEN PERU S.A.A. | CF9: ORYGEN PERU S.A.A. | CG9: ORYGEN PERU S.A.A. | CH9: ORYGEN PERU S.A.A. | CI9: ORYGEN PERU S.A.A. | CJ9: ORYGEN PERU S.A.A. | CK9: ORYGEN PERU S.A.A. | CL9: ORYGEN PERU S.A.A. | CM9: ORYGEN PERU S.A.A. | CN9: ORYGEN PERU S.A.A. | CO9: SAMAY I S.A.C | CP9: SAMAY I S.A.C | CQ9: SAMAY I S.A.C | CR9: SAMAY I S.A.C | CS9: TERMOCHILCA S.A.C. | CT9: TERMOCHILCA S.A.C. | CU9: COLCA SOLAR S.A.C. | CV9: ENERGIA RENOVABLE DEL SUR S.A. | CW9: GR CORTARRAMA SOCIEDAD ANONIMA CERRADA | CX9: GR TARUCA SOCIEDAD ANONIMA CERRADA | CY9: KONDU SAC | CZ9: PERUANA DE INVERSIONES EN ENERGIAS RENOVABLES S.A. | DA9: ORAZUL ENERGY PERÚ | DB9: ORAZUL ENERGY PERÚ | DC9: MAJA ENERGIA S.A.C. | DD9: EMPRESA DE GENERACION ELECTRICA CANCHAYLLO SAC | DE9: EMPRESA DE GENERACION ELECTRICA SANTA ANA S.A.C. | DF9: EMPRESA ELECTRICA AGUA AZUL | DG9: EMPRESA ELECTRICA RIO DOBLE | DH9: HIDROCAÑETE S.A. | DI9: HUAURA POWER GROUP S.A. | DJ9: MOQUEGUA FV S.A.C. | DK9: PANAMERICANA SOLAR SAC. | DL9: PARQUE EOLICO MARCONA S.A.C. | DM9: PARQUE EOLICO TRES HERMANAS S.A.C. | DN9: PETRAMAS | DO9: PETRAMAS | DP9: PETRAMAS | DQ9: PETRAMAS | DR9: TACNA SOLAR SAC. | DS9: ELECTRICA YANAPAMPA SAC | DT9: ANDEAN POWER S.A.C. | DU9: ASOCIACIÓN SANTA LUCIA DE CHACAS | DV9: ATRIA ENERGIA S.A.C. | DW9: EGEJUNIN | DX9: EGEJUNIN | DY9: EGEJUNIN | DZ9: EGEJUNIN | EA9: EMPRESA DE GENERACION ELECTRICA RIO BAÑOS S.A.C. | EB9: ENERGÍA EÓLICA S.A. | EC9: ENERGÍA EÓLICA S.A. | ED9: ENGIE | EE9: ENGIE | EF9: ENGIE | EG9: ENGIE | EH9: ENGIE | EI9: GENERACIÓN ANDINA S.A.C. | EJ9: GENERACIÓN ANDINA S.A.C. | EK9: GENERADORA DE ENERGÍA DEL PERÚ | EL9: GENERADORA DE ENERGÍA DEL PERÚ | EM9: GENERADORA DE ENERGÍA DEL PERÚ | EN9: GENERADORA DE ENERGÍA DEL PERÚ | EO9: GR PAINO SOCIEDAD ANONIMA CERRADA | EP9: MAJES ARCUS S.A.C. | EQ9: ORYGEN PERU S.A.A. | ER9: ORYGEN PERU S.A.A. | ES9: ORYGEN PERU S.A.A. | ET9: ORYGEN PERU S.A.A. | EU9: ORYGEN PERU S.A.A. | EV9: REPARTICIÓN ARCUS S.A.C. | EW9: SINERSA | EX9: SINERSA | EY9: BIOENERGIA DEL CHIRA S.A. | EZ9: GM OPERACIONES S.A.C. | FA9: GM OPERACIONES S.A.C. | FB9: SDF ENERGIA SAC | FC9: SDF ENERGIA SAC | FD9: AGRO INDUSTRIAL PARAMONGA S.A. | FE9: AGROAURORA S.A.C. | FF9: AGROINDUSTRIAS SAN JACINTO S.A.A. | FI9: UNACEM PERU S.A. | FJ9: SAN GABAN | FK9: ELECTRO ORIENTE | FL9: AGUAS Y ENERGIA PERU | FM9: ELECTRO ZAÑA S.A.C. | FN9: ELECTRONOROESTE S.A. | FO9: SDE PIURA | FP9: SINERSA | FQ9: SINERSA
C10: SANTA ROSA 1 | D10: SANTA ROSA 2 | E10: PARIAC | F10: MANTARO | G10: RESTITUCION | H10: TUMBES MAK 1 | I10: TUMBES MAK 2 | J10: CARHUAQUERO | K10: CAÑON DEL PATO | L10: AGUAYTIA TG1 | M10: AGUAYTIA TG2 | N10: KALLPA TG1 | O10: KALLPA TG2 | P10: KALLPA TG3 | Q10: KALLPA TV | R10: LFLORES TG1 | S10: LFLORES TV | T10: CERRO DEL AGUILA | U10: CERRODELAGUILAG4 | V10: SHOUGESA TV1 | W10: SHOUGESA TV2 | X10: SHOUGESA TV3 | Y10: SHOUGESA CUMMINS | Z10: MACHUPICCHU | AA10: ARICOTA 1 | AB10: ARICOTA 2 | AC10: INDEPENDENCIA | AD10: CHARCANI I,II,III | AE10: CHARCANI IV | AF10: CHARCANI V | AG10: CHARCANI VI | AH10: CHILINA TG | AI10: MOLLENDO 1, 2, 3 | AJ10: CHILINA (SULZ 1,2) | AK10: SAN GABAN II | AL10: PLATANAL | AM10: RECKA | AN10: RF ETEN TG1 | AO10: RF ETEN TG2 | AP10: CHAGLLA GP1 | AQ10: CHAGLLA | AR10: LA VIRGEN | AS10: CHIMAY | AT10: YANANGO | AU10: HUANCHOR | AV10: MARAÑON | AW10: STA TERESA | AX10: FENIX GT11 | AY10: FENIX GT12 | AZ10: FENIX TV10 | BA10: YAUPI | BB10: OROYA | BC10: PACHACHACA | BD10: MALPASO | BE10: CAHUA | BF10: ARCATA | BG10: GALLITO CIEGO | BH10: CHEVES | BI10: HUANZA | BJ10: MALACAS2 TG4 | BK10: MALACAS3 TG 5 | BL10: MALACAS1 TG6 | BM10: RF ILO2 TG1 | BN10: RF ILO2 TG2 | BO10: RF ILO2 TG3 | BP10: YUNCAN | BQ10: CHILCA1 TG1 | BR10: CHILCA1 TG2 | BS10: CHILCA1 TG3 | BT10: CHILCA-TV | BU10: CHILCA2 TG41 | BV10: CHILCA2-TV | BW10: CTNEPI_TG41 | BX10: CTNEPI_TG42 | BY10: CTNEPI_TG43 | BZ10: QUITARACSA | CA10: RF PTO MALDONADO | CB10: RF PUCALLPA | CC10: HUINCO | CD10: MATUCANA | CE10: MOYOPAMPA | CF10: CALLAHUANCA | CG10: HUAMPANI | CH10: STA ROSA WEST TG7 | CI10: UTI_5 | CJ10: UTI_6 | CK10: VENTANILLA 3 | CL10: VENTANILLA 4 | CM10: VENTANILLA TV | CN10: STAROSA TG8 | CO10: PTO_BRVO TG1 | CP10: PTO_BRVO TG2 | CQ10: PTO_BRVO TG3 | CR10: PTO_BRVO TG4 | CS10: OLLEROS TG1 | CT10: OLLEROS TV | CU10: CS YARUCAYA | CV10: SAN JUAN | CW10: MATARANI | CX10: DUNA | CY10: CARHUAQUERO (CS) | CZ10: MANTA I | DA10: CARHUAQUERO4 | DB10: CAÑA BRAVA | DC10: RONCADOR | DD10: CANCHAYLLO | DE10: RENOVANDESH1 | DF10: POTRERO | DG10: PIZARRAS | DH10: NIMPERIAL | DI10: YARUCAYA | DJ10: MOQUEGUA-SOLAR | DK10: PANAMERICANA-SOLAR | DL10: PQE-EOLICO-MARCONA | DM10: PQE-EOLICO-3-HERMANAS | DN10: HUAYCOLORO | DO10: CALLAO | DP10: DONA_CATALINA | DQ10: LAGRINGAV | DR10: TACNA-SOLAR | DS10: YANAPAMPA | DT10: CARHUAC | DU10: HUALLIN | DV10: PURMACANA | DW10: HUASAHUASI | DX10: STACRUZ_1_2 | DY10: RUNATULLO_II | DZ10: RUNATULLO_III | EA10: RUCUY | EB10: PQE-EOLICO-TALARA | EC10: PQE-EOLICO-CUPISNIQUE | ED10: INTIPAMPA | EE10: PUNTA LOMITAS-BL1 | EF10: PUNTA LOMITAS-BL2 | EG10: PUN LOMITAS_EXP-BL1 | EH10: PUN LOMITAS_EXP-BL2 | EI10: 8AGOSTO | EJ10: EL CARMEN | EK10: LA JOYA | EL10: ANGEL_I | EM10: ANGEL_II | EN10: ANGEL_III | EO10: HUAMBOS | EP10: MAJES | EQ10: RUBI | ER10: CH_HER1 | ES10: WAYRA-I | ET10: WAYRA EXTENSION | EU10: CLEMESI | EV10: REPARTICION | EW10: POECHOS2 | EX10: CHANCAY | EY10: CANA BRAVA | EZ10: REFINERIA TALARA TV1 | FA10: REFINERÍA TALARA TV2 | FB10: OQUENDO TG1 | FC10: OQUENDO TV1 | FD10: PARAMONGA | FE10: MAPLE | FF10: SAN_JACINTO | FG10: MW | FI10: CARPAPATA | FJ10: TUPURI | FK10: CENTRALES ELOR | FL10: PIAS1 | FM10: ZANA | FN10: TABLAZO | FO10: TALLANCA | FP10: CURUMUY | FQ10: POECHOS1 | FR10: MW
A11: 25/01/2025 | B11: 00:30 | C11: 1.1 | D11: 1.6 | E11: 4.3 | F11: 648.3 | G11: 218 | J11: 60 | K11: 237 | N11: 121 | O11: 120.9 | P11: 120.6 | Q11: 217.3 | R11: 205.5 | S11: 108 | T11: 564.2 | U11: 10.6 | Z11: 168 | AA11: 7.629 | AB11: 2.563 | AC11: 0 | AD11: 6.5 | AF11: 32.5 | AG11: 6.2 | AH11: 0 | AK11: 110.9 | AL11: 221.8 | AP11: 6.5 | AQ11: 460.1 | AR11: 70.2 | AS11: 142.8 | AT11: 42.1 | AU11: 18.3 | AV11: 19.5 | AW11: 90.1 | AY11: 0 | AZ11: 0 | BA11: 108.9 | BB11: 8 | BC11: 2.2 | BD11: 45.8 | BE11: 47.5 | BF11: 3.5 | BG11: 31.1 | BH11: 174 | BI11: 45.3 | BL11: 47.1 | BP11: 130.8 | BR11: 0 | BZ11: 114.2 | CC11: 222.9 | CD11: 128.5 | CE11: 63.9 | CF11: 81 | CG11: 30.2 | CK11: 142.9 | CL11: 142.4 | CM11: 146.4 | CS11: 188.3 | CT11: 101 | CU11: 0 | CV11: 42.7 | CW11: 0 | CX11: 14.4 | CY11: 0 | CZ11: 20 | DA11: 9.9 | DB11: 4.9 | DC11: 3.6 | DD11: 5.1 | DE11: 20.1 | DF11: 20 | DG11: 15.6 | DH11: 3.5 | DI11: 18.7 | DJ11: 0 | DK11: 0 | DL11: 8.5 | DM11: 23.5 | DN11: 4.7 | DO11: 2.3 | DP11: 2.4 | DQ11: 1.4 | DR11: 0 | DS11: 3.5 | DT11: 17.5 | DU11: 2 | DW11: 19.4 | DX11: 9.6 | DY11: 19.6 | DZ11: 20.3 | EA11: 20 | EB11: 18.3 | EC11: 55.3 | ED11: 0 | EE11: 23.8 | EF11: 50.5 | EG11: 1.1 | EH11: 0.7 | EI11: 21 | EJ11: 7.8 | EK11: 9.5 | EL11: 20 | EM11: 20 | EN11: 19 | EO11: 8.3 | EP11: 0 | EQ11: 0 | ER11: 0.6 | ES11: 13.4 | ET11: 15.7 | EU11: 0 | EV11: 0 | EW11: 6 | EX11: 20 | EY11: 10.9 | EZ11: 17.2 | FA11: 37.4 | FB11: 28.8 | FC11: 3.2 | FD11: 14.2 | FE11: 11.3 | FF11: 8.2 | FG11: 6825.392 | FI11: 23.93035 | FJ11: 1.3 | FK11: 0 | FL11: 6.0435 | FM11: 7.1 | FO11: 18.92246 | FP11: 4.9 | FQ11: 15.9 | FR11: 78.09631
A12: 25/01/2025 | B12: 01:00 | C12: 1.1 | D12: 1.6 | E12: 4.3 | F12: 645.5 | G12: 217.9 | J12: 59.4 | K12: 236.3 | N12: 108 | O12: 108.1 | P12: 108 | Q12: 208 | R12: 204.4 | S12: 108.3 | T12: 558.1 | U12: 10.4 | Z12: 167.2 | AA12: 7.638 | AB12: 2.657 | AC12: 0 | AD12: 6.5 | AF12: 31.4 | AG12: 3.7 | AH12: 0 | AK12: 110.5 | AL12: 179.8 | AP12: 6.5 | AQ12: 457.3 | AR12: 69.5 | AS12: 138.6 | AT12: 41.7 | AU12: 18.3 | AV12: 19.5 | AW12: 87.4 | AY12: 0 | AZ12: 0 | BA12: 109.1 | BB12: 7.9 | BC12: 2.3 | BD12: 45.8 | BE12: 46.8 | BF12: 3.5 | BG12: 31.4 | BH12: 173.7 | BI12: 45.2 | BL12: 47.1 | BP12: 130.2 | BR12: 0 | BZ12: 114.3 | CC12: 185.6 | CD12: 124.2 | CE12: 63.3 | CF12: 80.9 | CG12: 30 | CK12: 142.9 | CL12: 143.2 | CM12: 147.3 | CS12: 187.7 | CT12: 101 | CU12: 0 | CV12: 33.9 | CW12: 0 | CX12: 15.1 | CY12: 0 | CZ12: 20 | DA12: 9.9 | DB12: 4.7 | DC12: 3.6 | DD12: 5.1 | DE12: 20.2 | DF12: 20 | DG12: 15 | DH12: 3.5 | DI12: 18.7 | DJ12: 0 | DK12: 0 | DL12: 9.6 | DM12: 26.8 | DN12: 4.7 | DO12: 2.3 | DP12: 2.4 | DQ12: 1.4 | DR12: 0 | DS12: 3.7 | DT12: 16.4 | DU12: 2 | DW12: 18.4 | DX12: 9.5 | DY12: 19.3 | DZ12: 20.3 | EA12: 19.8 | EB12: 19.3 | EC12: 57.1 | ED12: 0 | EE12: 28.3 | EF12: 58.4 | EG12: 1.8 | EH12: 1.2 | EI12: 21 | EJ12: 7.7 | EK12: 2 | EL12: 20 | EM12: 20 | EN12: 19 | EO12: 9.7 | EP12: 0 | EQ12: 0 | ER12: 0.6 | ES12: 26.9 | ET12: 24.8 | EU12: 0 | EV12: 0 | EW12: 6 | EX12: 19.8 | EY12: 9.8 | EZ12: 16.8 | FA12: 36.7 | FB12: 28.9 | FC12: 3.2 | FD12: 14 | FE12: 13.3 | FF12: 8.1 | FG12: 6691.695 | FI12: 23.93041 | FJ12: 1.3 | FK12: 0 | FL12: 6.0455 | FM12: 7.1 | FO12: 18.92274 | FP12: 4.9 | FQ12: 15.9 | FR12: 78.09865
A13: 25/01/2025 | B13: 01:30 | C13: 1.1 | D13: 1.6 | E13: 4.3 | F13: 648.1 | G13: 217.7 | J13: 60.1 | K13: 238.7 | N13: 108.1 | O13: 107.5 | P13: 108.6 | Q13: 206.1 | R13: 205.5 | S13: 107.5 | T13: 554.6 | U13: 10.6 | Z13: 171.7 | AA13: 7.78 | AB13: 2.7 | AC13: 0 | AD13: 6.5 | AF13: 31.3 | AG13: 5.7 | AH13: 0 | AK13: 111 | AL13: 147.4 | AP13: 6.5 | AQ13: 460.5 | AR13: 69.7 | AS13: 126.2 | AT13: 42 | AU13: 18.3 | AV13: 19.5 | AW13: 90.3 | AY13: 0 | AZ13: 0 | BA13: 110.6 | BB13: 8 | BC13: 2.3 | BD13: 46.9 | BE13: 47.8 | BF13: 3.5 | BG13: 31.5 | BH13: 174.5 | BI13: 46.2 | BL13: 47 | BP13: 131.3 | BR13: 0 | BZ13: 115.2 | CC13: 170.5 | CD13: 115.6 | CE13: 64.2 | CF13: 81.4 | CG13: 30.4 | CK13: 107.5 | CL13: 107.2 | CM13: 123.7 | CS13: 186.4 | CT13: 101.2 | CU13: 0 | CV13: 33.2 | CW13: 0 | CX13: 14.2 | CY13: 0 | CZ13: 20 | DA13: 9.8 | DB13: 4.7 | DC13: 3.6 | DD13: 5.2 | DE13: 20.3 | DF13: 20 | DG13: 15 | DH13: 3.5 | DI13: 18.7 | DJ13: 0 | DK13: 0 | DL13: 8.2 | DM13: 24.5 | DN13: 4.7 | DO13: 2.3 | DP13: 2.4 | DQ13: 1.4 | DR13: 0 | DS13: 3.7 | DT13: 16.4 | DU13: 2 | DW13: 18.3 | DX13: 9.5 | DY13: 19.1 | DZ13: 20.3 | EA13: 19.8 | EB13: 21.1 | EC13: 61.4 | ED13: 0 | EE13: 28.9 | EF13: 51.2 | EG13: 1.4 | EH13: 2.3 | EI13: 21 | EJ13: 7.6 | EK13: 1.4 | EL13: 20 | EM13: 20 | EN13: 19.5 | EO13: 9.5 | EP13: 0 | EQ13: 0 | ER13: 0.6 | ES13: 34.2 | ET13: 29.5 | EU13: 0 | EV13: 0 | EW13: 6 | EX13: 19.8 | EY13: 9.8 | EZ13: 16.5 | FA13: 36.7 | FB13: 28.9 | FC13: 3.2 | FD13: 14.4 | FE13: 15 | FF13: 7.5 | FG13: 6558.28 | FI13: 23.92699 | FJ13: 1.3 | FK13: 0 | FL13: 6.045 | FM13: 7.1 | FO13: 18.92284 | FP13: 4.8 | FQ13: 15.9 | FR13: 77.99483
A14: 25/01/2025 | B14: 02:00 | C14: 1.1 | D14: 1.6 | E14: 4.2 | F14: 650.8 | G14: 218.8 | J14: 60.5 | K14: 239.8 | N14: 116.8 | O14: 117.6 | P14: 116.5 | Q14: 217.6 | R14: 112.6 | S14: 76.1 | T14: 562.4 | U14: 10.6 | Z14: 170.5 | AA14: 8.113 | AB14: 2.718 | AC14: 0 | AD14: 6.5 | AF14: 32.3 | AG14: 5.6 | AH14: 0 | AK14: 111.3 | AL14: 222.1 | AP14: 6.5 | AQ14: 460.4 | AR14: 70 | AS14: 149.4 | AT14: 42.2 | AU14: 18.4 | AV14: 19.5 | AW14: 91.3 | AY14: 0 | AZ14: 0 | BA14: 108.9 | BB14: 8 | BC14: 2.3 | BD14: 46.4 | BE14: 47.5 | BF14: 3.5 | BG14: 31.8 | BH14: 174.9 | BI14: 46.2 | BL14: 47.5 | BP14: 131.5 | BR14: 0 | BZ14: 115.5 | CC14: 214.1 | CD14: 133.8 | CE14: 64.5 | CF14: 81.2 | CG14: 30.5 | CK14: 107.7 | CL14: 108.7 | CM14: 122.5 | CS14: 136.5 | CT14: 79.8 | CU14: 0 | CV14: 31.7 | CW14: 0 | CX14: 12.5 | CY14: 0 | CZ14: 20 | DA14: 9.9 | DB14: 4.8 | DC14: 3.7 | DD14: 5.2 | DE14: 20.6 | DF14: 20 | DG14: 15 | DH14: 3.5 | DI14: 18.7 | DJ14: 0 | DK14: 0 | DL14: 7.3 | DM14: 23.7 | DN14: 4.7 | DO14: 2.3 | DP14: 2.4 | DQ14: 1.4 | DR14: 0 | DS14: 3.5 | DT14: 16.1 | DU14: 2 | DW14: 18.3 | DX14: 9.5 | DY14: 19.2 | DZ14: 20.4 | EA14: 20 | EB14: 22.5 | EC14: 46 | ED14: 0 | EE14: 23.4 | EF14: 44.9 | EG14: 1.4 | EH14: 3.2 | EI14: 21 | EJ14: 7.6 | EK14: 0 | EL14: 20 | EM14: 20 | EN14: 19.8 | EO14: 10.3 | EP14: 0 | EQ14: 0 | ER14: 0.6 | ES14: 29.9 | ET14: 29.2 | EU14: 0 | EV14: 0 | EW14: 6 | EX14: 20 | EY14: 11.3 | EZ14: 16.8 | FA14: 36.4 | FB14: 28.9 | FC14: 3.2 | FD14: 14 | FE14: 14.1 | FF14: 8 | FG14: 6542.031 | FI14: 23.92521 | FJ14: 1.3 | FK14: 0 | FL14: 6.045 | FM14: 7.1 | FO14: 18.92349 | FP14: 4.8 | FQ14: 15.9 | FR14: 77.9937
A15: 25/01/2025 | B15: 02:30 | C15: 1.1 | D15: 1.7 | E15: 4.2 | F15: 632 | G15: 213.6 | J15: 59.6 | K15: 232.3 | N15: 155.3 | O15: 154.1 | P15: 154 | Q15: 259.6 | R15: 108.8 | S15: 67.4 | T15: 531.4 | U15: 10.4 | Z15: 160.2 | AA15: 6.473 | AB15: 2.328 | AC15: 0 | AD15: 6.5 | AF15: 30.2 | AG15: 5.6 | AH15: 0 | AK15: 108.5 | AL15: 222.3 | AP15: 6.5 | AQ15: 451.1 | AR15: 70.6 | AS15: 141.2 | AT15: 40.4 | AU15: 18.3 | AV15: 19.5 | AW15: 89.5 | AY15: 0 | AZ15: 0 | BA15: 105.3 | BB15: 8 | BC15: 2.2 | BD15: 43 | BE15: 46 | BF15: 3.5 | BG15: 30.2 | BH15: 170.2 | BI15: 0 | BL15: 47.3 | BP15: 129.1 | BR15: 0 | BZ15: 111.2 | CC15: 164.4 | CD15: 126.1 | CE15: 61.9 | CF15: 80 | CG15: 29.3 | CK15: 102.9 | CL15: 103.1 | CM15: 119.3 | CS15: 136.8 | CT15: 78.8 | CU15: 0 | CV15: 28.7 | CW15: 0 | CX15: 13.4 | CY15: 0 | CZ15: 20 | DA15: 10 | DB15: 4.7 | DC15: 3.6 | DD15: 5.2 | DE15: 19.7 | DF15: 20 | DG15: 15 | DH15: 3.5 | DI15: 18.7 | DJ15: 0 | DK15: 0 | DL15: 5.4 | DM15: 17.2 | DN15: 4.7 | DO15: 2.3 | DP15: 2.4 | DQ15: 1.4 | DR15: 0 | DS15: 3.6 | DT15: 14.9 | DU15: 2 | DW15: 17.7 | DX15: 9.5 | DY15: 18.7 | DZ15: 20.2 | EA15: 20 | EB15: 17 | EC15: 37.2 | ED15: 0 | EE15: 24.7 | EF15: 50.5 | EG15: 2 | EH15: 1.2 | EI15: 21 | EJ15: 7.5 | EK15: 0 | EL15: 20 | EM15: 20 | EN15: 19.8 | EO15: 9.9 | EP15: 0 | EQ15: 0 | ER15: 0.6 | ES15: 22.2 | ET15: 19.7 | EU15: 0 | EV15: 0 | EW15: 6 | EX15: 20 | EY15: 10.7 | EZ15: 16.5 | FA15: 36.4 | FB15: 28.9 | FC15: 3.2 | FD15: 14 | FE15: 15.1 | FF15: 7.7 | FG15: 6397.601 | FI15: 23.92496 | FJ15: 1.3 | FK15: 0 | FL15: 6.0455 | FM15: 7.1 | FO15: 18.92297 | FP15: 4.8 | FQ15: 15.9 | FR15: 77.99343
A16: 25/01/2025 | B16: 03:00 | C16: 1.1 | D16: 1.7 | E16: 4.3 | F16: 653.8 | G16: 219.5 | J16: 61 | K16: 240.6 | N16: 123.7 | O16: 122.3 | P16: 123.8 | Q16: 235.6 | R16: 109 | S16: 67.5 | T16: 562.1 | U16: 10.5 | Z16: 173.8 | AA16: 8.017 | AB16: 2.66 | AC16: 0 | AD16: 6.6 | AF16: 32.3 | AG16: 6 | AH16: 0 | AK16: 111.5 | AL16: 221.6 | AP16: 6.5 | AQ16: 464.7 | AR16: 70.4 | AS16: 141.9 | AT16: 42.4 | AU16: 18.3 | AV16: 19.5 | AW16: 91.4 | AY16: 0 | AZ16: 0 | BA16: 109.7 | BB16: 8.1 | BC16: 2.3 | BD16: 46 | BE16: 47.8 | BF16: 3.5 | BG16: 31.7 | BH16: 176.6 | BI16: 0 | BL16: 47.3 | BP16: 132.1 | BR16: 0 | BZ16: 115.7 | CC16: 146.5 | CD16: 128.1 | CE16: 65.6 | CF16: 81.7 | CG16: 30.7 | CK16: 104.3 | CL16: 104.3 | CM16: 120.7 | CS16: 137.2 | CT16: 79.8 | CU16: 0 | CV16: 34.7 | CW16: 0 | CX16: 15.1 | CY16: 0 | CZ16: 20 | DA16: 9.9 | DB16: 4.7 | DC16: 3.6 | DD16: 5.2 | DE16: 20.8 | DF16: 20 | DG16: 15.1 | DH16: 3.5 | DI16: 18.7 | DJ16: 0 | DK16: 0 | DL16: 6.9 | DM16: 18.3 | DN16: 4.7 | DO16: 2.3 | DP16: 2.4 | DQ16: 1.4 | DR16: 0 | DS16: 3.6 | DT16: 4.9 | DU16: 2 | DW16: 17.1 | DX16: 9.5 | DY16: 19 | DZ16: 20.4 | EA16: 19.8 | EB16: 15.6 | EC16: 34.8 | ED16: 0 | EE16: 31.4 | EF16: 63.4 | EG16: 1.8 | EH16: 1.6 | EI16: 21 | EJ16: 7.4 | EK16: 0 | EL16: 20 | EM16: 20 | EN16: 19.8 | EO16: 7.9 | EP16: 0 | EQ16: 0 | ER16: 0.6 | ES16: 27.4 | ET16: 25.6 | EU16: 0 | EV16: 0 | EW16: 6 | EX16: 19.8 | EY16: 10.1 | EZ16: 16.6 | FA16: 35.9 | FB16: 28.9 | FC16: 3.3 | FD16: 14.4 | FE16: 16.2 | FF16: 7.9 | FG16: 6434.777 | FI16: 23.92046 | FJ16: 1.3 | FK16: 0 | FL16: 6.044 | FM16: 7.1 | FO16: 18.92306 | FP16: 4.9 | FQ16: 15.9 | FR16: 78.08752
A17: 25/01/2025 | B17: 03:30 | C17: 1.1 | D17: 1.7 | E17: 4.2 | F17: 646.5 | G17: 218.3 | J17: 60.2 | K17: 238.1 | N17: 121.5 | O17: 122 | P17: 121.9 | Q17: 215 | R17: 109.3 | S17: 66.9 | T17: 560.8 | U17: 10.6 | Z17: 158.8 | AA17: 7.577 | AB17: 2.665 | AC17: 0 | AD17: 6.6 | AF17: 32.4 | AG17: 6 | AH17: 0 | AK17: 111 | AL17: 221.4 | AP17: 6.5 | AQ17: 461.5 | AR17: 69.1 | AS17: 148.1 | AT17: 42 | AU17: 18.4 | AV17: 19.5 | AW17: 91.2 | AY17: 0 | AZ17: 0 | BA17: 108.8 | BB17: 8 | BC17: 2.3 | BD17: 45.9 | BE17: 46.9 | BF17: 3.5 | BG17: 31.3 | BH17: 173.9 | BI17: 0 | BL17: 47.4 | BP17: 130.8 | BR17: 0 | BZ17: 114.2 | CC17: 208 | CD17: 132.2 | CE17: 63.9 | CF17: 81 | CG17: 30.2 | CK17: 102.9 | CL17: 102.7 | CM17: 120.1 | CS17: 136.2 | CT17: 78.7 | CU17: 0 | CV17: 39.3 | CW17: 0 | CX17: 14.5 | CY17: 0 | CZ17: 20 | DA17: 9.9 | DB17: 4.8 | DC17: 3.6 | DD17: 5.2 | DE17: 20.3 | DF17: 20 | DG17: 15 | DH17: 3.5 | DI17: 18.7 | DJ17: 0 | DK17: 0 | DL17: 7 | DM17: 20 | DN17: 4.7 | DO17: 2.3 | DP17: 2.4 | DQ17: 1.4 | DR17: 0 | DS17: 3.5 | DT17: 5.4 | DU17: 2 | DW17: 17.1 | DX17: 9.5 | DY17: 18.8 | DZ17: 20.3 | EA17: 20 | EB17: 15.6 | EC17: 28.8 | ED17: 0 | EE17: 25 | EF17: 53.9 | EG17: 1.1 | EH17: 1.8 | EI17: 21 | EJ17: 7.3 | EK17: 0 | EL17: 20 | EM17: 20 | EN17: 20 | EO17: 10.5 | EP17: 0 | EQ17: 0 | ER17: 0.6 | ES17: 29.2 | ET17: 24.5 | EU17: 0 | EV17: 0 | EW17: 6 | EX17: 20 | EY17: 9.8 | EZ17: 16.4 | FA17: 35.9 | FB17: 29 | FC17: 3.2 | FD17: 14.5 | FE17: 16.3 | FF17: 7.8 | FG17: 6417.142 | FI17: 24.07807 | FJ17: 1.3 | FK17: 0 | FL17: 6.0445 | FM17: 7.1 | FO17: 18.92316 | FP17: 4.8 | FQ17: 15.9 | FR17: 78.14573
A18: 25/01/2025 | B18: 04:00 | C18: 1.1 | D18: 1.7 | E18: 4.3 | F18: 637.8 | G18: 215.1 | J18: 59.9 | K18: 234.7 | N18: 107.3 | O18: 108 | P18: 107.6 | Q18: 207.5 | R18: 198.7 | S18: 94.3 | T18: 546.8 | U18: 10.5 | Z18: 165.2 | AA18: 6.93 | AB18: 2.455 | AC18: 0 | AD18: 6.7 | AF18: 31.4 | AG18: 6 | AH18: 0 | AK18: 109.8 | AL18: 222.6 | AP18: 6.5 | AQ18: 351.1 | AR18: 68.9 | AS18: 129.4 | AT18: 41.1 | AU18: 18.3 | AV18: 19.5 | AW18: 89.3 | AY18: 0 | AZ18: 0 | BA18: 108.1 | BB18: 8 | BC18: 2.3 | BD18: 45.2 | BE18: 46.3 | BF18: 3.5 | BG18: 31 | BH18: 168.4 | BI18: 0 | BL18: 47.4 | BP18: 130 | BR18: 0 | BZ18: 112.7 | CC18: 221.9 | CD18: 118.7 | CE18: 62.8 | CF18: 80.6 | CG18: 29.7 | CK18: 103.2 | CL18: 103.7 | CM18: 120 | CS18: 136.3 | CT18: 79.5 | CU18: 0 | CV18: 48.4 | CW18: 0 | CX18: 15.4 | CY18: 0 | CZ18: 20 | DA18: 9.9 | DB18: 4.7 | DC18: 3.6 | DD18: 5.2 | DE18: 19.9 | DF18: 20 | DG18: 15 | DH18: 3.6 | DI18: 18.7 | DJ18: 0 | DK18: 0 | DL18: 8.2 | DM18: 23.1 | DN18: 4.7 | DO18: 2.3 | DP18: 2.4 | DQ18: 1.4 | DR18: 0 | DS18: 3.6 | DT18: 5.5 | DU18: 2 | DW18: 17.2 | DX18: 9.5 | DY18: 18.6 | DZ18: 20.3 | EA18: 19.8 | EB18: 20.2 | EC18: 22.8 | ED18: 0 | EE18: 15.9 | EF18: 38.6 | EG18: 1.9 | EH18: 1.7 | EI18: 21 | EJ18: 7.2 | EK18: 0 | EL18: 20 | EM18: 20 | EN18: 20 | EO18: 10.8 | EP18: 0 | EQ18: 0 | ER18: 0.6 | ES18: 35.8 | ET18: 39.9 | EU18: 0 | EV18: 0 | EW18: 6 | EX18: 19.9 | EY18: 9.3 | EZ18: 16.3 | FA18: 35.4 | FB18: 29 | FC18: 3.2 | FD18: 14.4 | FE18: 14.6 | FF18: 8 | FG18: 6325.285 | FI18: 24.07355 | FJ18: 1.3 | FK18: 0 | FL18: 6.0435 | FM18: 6.9 | FO18: 18.92289 | FP18: 4.9 | FQ18: 15.9 | FR18: 78.03994
A19: 25/01/2025 | B19: 04:30 | C19: 1.1 | D19: 1.7 | E19: 4.3 | F19: 655.5 | G19: 220.6 | J19: 60.4 | K19: 240.8 | N19: 109.8 | O19: 109.6 | P19: 109.9 | Q19: 209.4 | R19: 206.8 | S19: 107.6 | T19: 567.9 | U19: 10.5 | Z19: 170.8 | AA19: 8.006 | AB19: 2.758 | AC19: 0 | AD19: 6.5 | AF19: 32.9 | AG19: 5.9 | AH19: 0 | AK19: 111.7 | AL19: 223 | AP19: 6.5 | AQ19: 470.7 | AR19: 69.6 | AS19: 148.9 | AT19: 42.3 | AU19: 18.4 | AV19: 19.5 | AW19: 94.9 | AY19: 0 | AZ19: 0 | BA19: 110.4 | BB19: 8.1 | BC19: 2.3 | BD19: 45.9 | BE19: 47.6 | BF19: 3.5 | BG19: 31.5 | BH19: 171.8 | BI19: 0 | BL19: 47.1 | BP19: 131.8 | BR19: 0 | BZ19: 115.5 | CC19: 72.1 | CD19: 134.4 | CE19: 64.8 | CF19: 81.5 | CG19: 30.6 | CK19: 104.3 | CL19: 103.7 | CM19: 121.1 | CS19: 137.4 | CT19: 79.7 | CU19: 0 | CV19: 56.4 | CW19: 0 | CX19: 13 | CY19: 0 | CZ19: 20 | DA19: 9.9 | DB19: 4.6 | DC19: 3.6 | DD19: 5.1 | DE19: 20.7 | DF19: 20 | DG19: 15 | DH19: 3.5 | DI19: 18.7 | DJ19: 0 | DK19: 0 | DL19: 10.4 | DM19: 27.3 | DN19: 4.7 | DO19: 2.3 | DP19: 2.4 | DQ19: 1.4 | DR19: 0 | DS19: 3.5 | DT19: 5.3 | DU19: 2 | DW19: 17.4 | DX19: 9.5 | DY19: 18.9 | DZ19: 20.5 | EA19: 19.9 | EB19: 21.1 | EC19: 15.2 | ED19: 0 | EE19: 14.5 | EF19: 34.1 | EG19: 0.9 | EH19: 1.2 | EI19: 21 | EJ19: 7.1 | EK19: 0 | EL19: 20 | EM19: 20 | EN19: 20 | EO19: 9.8 | EP19: 0 | EQ19: 0 | ER19: 0.6 | ES19: 44 | ET19: 38.9 | EU19: 0 | EV19: 0 | EW19: 6.1 | EX19: 20 | EY19: 10.2 | EZ19: 16.9 | FA19: 35.9 | FB19: 29 | FC19: 3.3 | FD19: 14.3 | FE19: 16.3 | FF19: 8 | FG19: 6457.764 | FI19: 24.07229 | FJ19: 1.3 | FK19: 0 | FL19: 6.0425 | FM19: 6.9 | FO19: 18.92223 | FP19: 5 | FQ19: 15.9 | FR19: 78.13702
A20: 25/01/2025 | B20: 05:00 | C20: 1.1 | D20: 1.7 | E20: 4.3 | F20: 641.3 | G20: 216 | J20: 59.2 | K20: 235.1 | N20: 108.1 | O20: 109 | P20: 108.4 | Q20: 223 | R20: 204.8 | S20: 108.2 | T20: 551.8 | U20: 10.3 | Z20: 162.9 | AA20: 7.015 | AB20: 2.46 | AC20: 0 | AD20: 6.7 | AF20: 30.6 | AG20: 5.9 | AH20: 0 | AK20: 110 | AL20: 221.7 | AP20: 6.5 | AQ20: 464.1 | AR20: 68.9 | AS20: 137 | AT20: 41.2 | AU20: 18.4 | AV20: 19.5 | AW20: 89.8 | AY20: 0 | AZ20: 0 | BA20: 108.6 | BB20: 8 | BC20: 2.3 | BD20: 44.7 | BE20: 46.5 | BF20: 3.5 | BG20: 31 | BH20: 168.5 | BI20: 0 | BL20: 47 | BP20: 129.7 | BR20: 0 | BZ20: 113.4 | CC20: 72.2 | CD20: 125.1 | CE20: 63.1 | CF20: 78.8 | CG20: 29.9 | CK20: 104.1 | CL20: 104.4 | CM20: 120.7 | CS20: 136.3 | CT20: 79.7 | CU20: 0 | CV20: 59.3 | CW20: 0 | CX20: 14.2 | CY20: 0 | CZ20: 20 | DA20: 9.9 | DB20: 4.7 | DC20: 3.6 | DD20: 5.1 | DE20: 20 | DF20: 20 | DG20: 15.1 | DH20: 3.5 | DI20: 18.7 | DJ20: 0 | DK20: 0 | DL20: 12.6 | DM20: 28.4 | DN20: 4.6 | DO20: 2.3 | DP20: 2.4 | DQ20: 1.3 | DR20: 0 | DS20: 3.5 | DT20: 5.1 | DU20: 2 | DW20: 17.6 | DX20: 9.4 | DY20: 18.7 | DZ20: 20.3 | EA20: 20 | EB20: 22.6 | EC20: 11.6 | ED20: 0 | EE20: 9.1 | EF20: 25.1 | EG20: 1 | EH20: 0.7 | EI20: 21 | EJ20: 7 | EK20: 0 | EL20: 20 | EM20: 20 | EN20: 20 | EO20: 12.3 | EP20: 0 | EQ20: 0 | ER20: 0.6 | ES20: 41.9 | ET20: 31 | EU20: 0 | EV20: 0 | EW20: 6 | EX20: 20 | EY20: 9.5 | EZ20: 16.3 | FA20: 35.4 | FB20: 28.9 | FC20: 3.3 | FD20: 14.5 | FE20: 14.6 | FF20: 7.4 | FG20: 6334.575 | FI20: 24.07335 | FJ20: 1.3 | FK20: 0 | FL20: 6.0435 | FM20: 6.9 | FO20: 18.92209 | FP20: 5 | FQ20: 15.7 | FR20: 77.93894
A21: 25/01/2025 | B21: 05:30 | C21: 1.1 | D21: 1.7 | E21: 4.3 | F21: 647.1 | G21: 218.3 | J21: 60 | K21: 206.5 | N21: 145.9 | O21: 145.3 | P21: 145.5 | Q21: 240.7 | R21: 206 | S21: 108.3 | T21: 559.8 | U21: 10.5 | Z21: 164.9 | AA21: 7.302 | AB21: 2.57 | AC21: 0 | AD21: 6.7 | AF21: 32.1 | AG21: 5.6 | AH21: 0 | AK21: 110.7 | AL21: 223.1 | AP21: 6.5 | AQ21: 463.7 | AR21: 69 | AS21: 146.6 | AT21: 41.9 | AU21: 18.4 | AV21: 19.5 | AW21: 91.4 | AY21: 0 | AZ21: 0 | BA21: 107.3 | BB21: 8 | BC21: 2.3 | BD21: 44.5 | BE21: 46.5 | BF21: 3.5 | BG21: 31 | BH21: 170 | BI21: 0 | BL21: 47.2 | BP21: 130.5 | BR21: 0 | BZ21: 113.8 | CC21: 92.7 | CD21: 131.2 | CE21: 63.6 | CF21: 79 | CG21: 30 | CK21: 103.9 | CL21: 103.6 | CM21: 120.1 | CS21: 137.3 | CT21: 79.7 | CU21: 0 | CV21: 58.5 | CW21: 0 | CX21: 16.9 | CY21: 0 | CZ21: 20 | DA21: 9.9 | DB21: 4.7 | DC21: 3.6 | DD21: 5.1 | DE21: 20.2 | DF21: 20 | DG21: 15 | DH21: 3.5 | DI21: 18.8 | DJ21: 0.1 | DK21: 0 | DL21: 15.2 | DM21: 27.4 | DN21: 3.8 | DO21: 2.3 | DP21: 2.4 | DQ21: 2.3 | DR21: 0.7 | DS21: 3.6 | DT21: 5.2 | DU21: 2 | DW21: 17.6 | DX21: 9.4 | DY21: 18.9 | DZ21: 20.4 | EA21: 20 | EB21: 18.3 | EC21: 18 | ED21: 0 | EE21: 5.4 | EF21: 12.2 | EG21: 0.8 | EH21: 0 | EI21: 21 | EJ21: 6.9 | EK21: 0 | EL21: 20 | EM21: 20 | EN21: 20 | EO21: 12.6 | EP21: 0 | EQ21: 0 | ER21: 0.6 | ES21: 29.7 | ET21: 26.4 | EU21: 0.2 | EV21: 0 | EW21: 6.1 | EX21: 20 | EY21: 10 | EZ21: 16.6 | FA21: 36 | FB21: 28.9 | FC21: 3.2 | FD21: 14 | FE21: 12.6 | FF21: 7.5 | FG21: 6471.172 | FI21: 24.07693 | FJ21: 1.3 | FK21: 0 | FL21: 6.0455 | FM21: 6.9 | FO21: 18.92197 | FP21: 5 | FQ21: 15.9 | FR21: 78.1444
A22: 25/01/2025 | B22: 06:00 | C22: 1.1 | D22: 1.7 | E22: 4.3 | F22: 643.6 | G22: 216.8 | J22: 58.3 | K22: 204.4 | N22: 140.8 | O22: 140.3 | P22: 140.1 | Q22: 239 | R22: 207.9 | S22: 108.1 | T22: 551.2 | U22: 10.3 | Z22: 164.6 | AA22: 7.062 | AB22: 2.562 | AC22: 0 | AD22: 6.7 | AF22: 30.8 | AG22: 4.9 | AH22: 0 | AK22: 110 | AL22: 222.6 | AP22: 6.5 | AQ22: 464.7 | AR22: 65.9 | AS22: 146.2 | AT22: 41.5 | AU22: 18.4 | AV22: 19.5 | AW22: 90.1 | AY22: 0 | AZ22: 0 | BA22: 109 | BB22: 8 | BC22: 2.3 | BD22: 45.5 | BE22: 46.3 | BF22: 3.5 | BG22: 31.1 | BH22: 168.9 | BI22: 0 | BL22: 47 | BP22: 129.1 | BR22: 0 | BZ22: 113.2 | CC22: 88.9 | CD22: 129.2 | CE22: 62.6 | CF22: 78.3 | CG22: 29.7 | CK22: 104.2 | CL22: 104.5 | CM22: 120.5 | CS22: 135.9 | CT22: 79.2 | CU22: 0 | CV22: 46.3 | CW22: 6.7 | CX22: 14.2 | CY22: 0 | CZ22: 20 | DA22: 9.9 | DB22: 4.7 | DC22: 3.6 | DD22: 5.1 | DE22: 19.9 | DF22: 20 | DG22: 15 | DH22: 3.5 | DI22: 18.8 | DJ22: 0.6 | DK22: 0.6 | DL22: 9.8 | DM22: 18.5 | DN22: 3.7 | DO22: 2.3 | DP22: 2.4 | DQ22: 2.4 | DR22: 3.1 | DS22: 3.5 | DT22: 5.2 | DU22: 2 | DW22: 17.1 | DX22: 9.5 | DY22: 19 | DZ22: 20.3 | EA22: 19.9 | EB22: 19.2 | EC22: 25.6 | ED22: 2.9 | EE22: 3 | EF22: 6.1 | EG22: 0 | EH22: 0.1 | EI22: 21 | EJ22: 6.8 | EK22: 0 | EL22: 20 | EM22: 20 | EN22: 20 | EO22: 7.8 | EP22: 0.5 | EQ22: 9.6 | ER22: 0.6 | ES22: 20.9 | ET22: 20.7 | EU22: 8.1 | EV22: 0.5 | EW22: 6 | EX22: 19.8 | EY22: 9.8 | EZ22: 16.7 | FA22: 35.8 | FB22: 28.8 | FC22: 3.2 | FD22: 12.8 | FE22: 14.9 | FF22: 7.6 | FG22: 6403.224 | FI22: 24.07498 | FJ22: 1.3 | FK22: 0 | FL22: 6.0455 | FM22: 6.9 | FO22: 18.92278 | FP22: 5 | FQ22: 15.9 | FR22: 78.14326
... A58: 26/01/2025 | B58: 00:00 | C58: 1.1 | D58: 1.6 | E58: 4.3 | F58: 648.6 | G58: 218.7 | J58: 89.6 | K58: 238.2 | N58: 145.2 | O58: 147.1 | P58: 146.9 | Q58: 240.9 | R58: 210.1 | S58: 108.7 | T58: 563.7 | U58: 10.3 | Z58: 163.3 | AA58: 7.446 | AB58: 2.727 | AC58: 0 | AD58: 6.6 | AF58: 85.3 | AG58: 6 | AH58: 0 | AK58: 110.6 | AL58: 211.3 | AP58: 6.5 | AQ58: 459.3 | AR58: 59 | AS58: 146.7 | AT58: 41.9 | AU58: 18.4 | AV58: 19.6 | AW58: 90.8 | AY58: 0 | AZ58: 0 | BA58: 106.7 | BB58: 8.1 | BC58: 2.5 | BD58: 46.8 | BE58: 47 | BF58: 3.6 | BG58: 31.6 | BH58: 166.7 | BI58: 19.6 | BL58: 47.4 | BP58: 129.7 | BR58: 0 | BZ58: 115.4 | CC58: 228.8 | CD58: 131.6 | CE58: 62.9 | CF58: 81 | CG58: 29.9 | CK58: 145.4 | CL58: 145.6 | CM58: 149.2 | CS58: 136.8 | CT58: 84.3 | CU58: 0 | CV58: 24.8 | CW58: 0 | CX58: 5.3 | CY58: 0 | CZ58: 20 | DA58: 10 | DB58: 5.3 | DC58: 3.6 | DD58: 5.2 | DE58: 20.3 | DF58: 20 | DG58: 13.5 | DH58: 3.4 | DI58: 18.8 | DJ58: 0 | DK58: 0 | DL58: 4.5 | DM58: 11.6 | DN58: 4.6 | DO58: 2.3 | DP58: 2.4 | DQ58: 3.1 | DR58: 0 | DS58: 3.6 | DT58: 11 | DU58: 2 | DW58: 15 | DX58: 9 | DY58: 20 | DZ58: 20.4 | EA58: 19.9 | EB58: 19.8 | EC58: 64.2 | ED58: 0 | EE58: 10.8 | EF58: 19.2 | EG58: 0.2 | EH58: 0.1 | EI58: 21 | EJ58: 5.3 | EK58: 6.6 | EL58: 20 | EM58: 20 | EN58: 20 | EO58: 3.7 | EP58: 0 | EQ58: 0 | ER58: 0.6 | ES58: 21.6 | ET58: 19.4 | EU58: 0 | EV58: 0 | EW58: 6 | EX58: 20 | EY58: 10.3 | EZ58: 16.6 | FA58: 36.2 | FB58: 29.2 | FC58: 3.4 | FD58: 13 | FE58: 12 | FF58: 8.6 | FG58: 6818.473 | FI58: 23.96457 | FJ58: 1.2 | FK58: 0.536 | FL58: 6.122 | FM58: 13.2 | FO58: 18.92216 | FP58: 4.7 | FQ58: 15.8 | FR58: 84.44473
A59: EJEC | C59: 26.4 | D59: 40.15 | E59: 103.05 | F59: 15521 | G59: 5222.6 | H59: 0 | I59: 0 | J59: 1905.95 | K59: 5583.95 | L59: 0 | M59: 0 | N59: 3075.8 | O59: 3075.55 | P59: 3073.5 | Q59: 5461.45 | R59: 4715.05 | S59: 2507.3 | T59: 13388.7 | U59: 252.35 | V59: 0 | W59: 0 | X59: 0 | Y59: 0 | Z59: 3979.55 | AA59: 181.154 | AB59: 62.7405 | AC59: 97.056 | AD59: 158.7 | AE59: 0 | AF59: 1548.95 | AG59: 138.15 | AH59: 4.25 | AI59: 0 | AJ59: 0 | AK59: 2655.9 | AL59: 5063.2 | AM59: 0 | AN59: 0 | AO59: 0 | AP59: 156 | AQ59: 10957.85 | AR59: 1557.6 | AS59: 3397.55 | AT59: 1002.7 | AU59: 440.85 | AV59: 466.95 | AW59: 2166.25 | AX59: 0 | AY59: 2285.3 | AZ59: 1127.95 | BA59: 2610.25 | BB59: 192.7 | BC59: 57.25 | BD59: 1094.7 | BE59: 1126 | BF59: 84.45 | BG59: 750.2 | BH59: 3502.05 | BI59: 1035.05 | BJ59: 0 | BK59: 0 | BL59: 1118.85 | BM59: 0 | BN59: 0 | BO59: 0 | BP59: 3136.85 | BQ59: 0 | BR59: 233.85 | BS59: 0 | BT59: 0 | BU59: 0 | BV59: 0 | BW59: 0 | BX59: 0 | BY59: 0 | BZ59: 2067.8 | CA59: 0 | CB59: 0 | CC59: 3472.15 | CD59: 3058 | CE59: 1529.5 | CF59: 1941.6 | CG59: 722.2 | CH59: 0 | CI59: 0 | CJ59: 0 | CK59: 3158.35 | CL59: 3147.8 | CM59: 3341.85 | CN59: 0 | CO59: 0 | CP59: 0 | CQ59: 0 | CR59: 0 | CS59: 4221.55 | CT59: 2295.05 | CU59: 8.1 | CV59: 1151.9 | CW59: 645.3 | CX59: 290.3 | CY59: 2.1 | CZ59: 479.6 | DA59: 238.1 | DB59: 122.5 | DC59: 86.45 | DD59: 124.1 | DE59: 484.25 | DF59: 476.95 | DG59: 355.35 | DH59: 82.15 | DI59: 431.75 | DJ59: 115.25 | DK59: 140.45 | DL59: 253.05 | DM59: 731.7 | DN59: 98 | DO59: 54.9 | DP59: 57.6 | DQ59: 54.9 | DR59: 158.3 | DS59: 84.75 | DT59: 331.05 | DU59: 48 | DV59: 0 | DW59: 383.65 | DX59: 212.7 | DY59: 475.25 | DZ59: 487.8 | EA59: 478.4 | EB59: 384.9 | EC59: 1193.4 | ED59: 266.5 | EE59: 599.35 | EF59: 907.35 | EG59: 53.8 | EH59: 53.15 | EI59: 504 | EJ59: 148 | EK59: 114.45 | EL59: 480 | EM59: 480 | EN59: 478.45 | EO59: 230.9 | EP59: 121.45 | EQ59: 1112.45 | ER59: 14.4 | ES59: 1093.05 | ET59: 1084.2 | EU59: 904.85 | EV59: 120.15 | EW59: 144.25 | EX59: 478.65 | EY59: 210.35 | EZ59: 395.35 | FA59: 852.7 | FB59: 683.65 | FC59: 77.25 | FD59: 328.6 | FE59: 334.4 | FF59: 185 | FG59: 168479.15 | FI59: 572.31946 | FJ59: 31.15 | FK59: 78.0955 | FL59: 145.75775 | FM59: 193.55 | FN59: 0 | FO59: 454.12627 | FP59: 105.95 | FQ59: 380.55 | FR59: 1961.499

Sheet REACTIVA
B3: sábado, 25 de Enero del 2025
A5: POTENCIA REACTIVA EJECUTADA DE LAS UNIDADES DE GENERACIÓN DEL COES (MVAR) | FH5: CENTRALES NO INTEGRANTES COES
A6: FECHA | B6: HORA | C6: 337 | D6: 338 | E6: 121 | F6: 101 | G6: 102 | H6: 42667 | I6: 42668 | J6: 126 | K6: 127 | L6: 138 | M6: 139 | N6: 197 | O6: 203 | P6: 204 | Q6: 230 | R6: 209 | S6: 56677 | T6: 796 | U6: 2146 | V6: 142 | W6: 143 | X6: 125 | Y6: 187 | Z6: 163 | AA6: 298 | AB6: 219 | AC6: 151 | AD6: 152 | AE6: 153 | AF6: 154 | AG6: 756 | AH6: 156 | AI6: 155 | AJ6: 182 | AK6: 212 | AL6: 758 | AM6: 263 | AN6: 265 | AO6: 775 | AP6: 777 | AQ6: 2154 | AR6: 150 | AS6: 149 | AT6: 188 | AU6: 2131 | AV6: 755 | AW6: 252 | AX6: 249 | AY6: 250 | AZ6: 117 | BA6: 267 | BB6: 268 | BC6: 119 | BD6: 120 | BE6: 189 | BF6: 122 | BG6: 266 | BH6: 251 | BI6: 115 | BJ6: 239 | BK6: 288 | BL6: 240 | BM6: 241 | BN6: 242 | BO6: 191 | BP6: 194 | BQ6: 196 | BR6: 207 | BS6: 236 | BT6: 795 | BU6: 285 | BV6: 995 | BW6: 996 | BX6: 997 | BY6: 766 | BZ6: 926 | CA6: 924 | CB6: 103 | CC6: 104 | CD6: 106 | CE6: 105 | CF6: 107 | CG6: 110 | CH6: 109 | CI6: 144 | CJ6: 113 | CK6: 114 | CL6: 193 | CM6: 208 | CN6: 786 | CO6: 787 | CP6: 788 | CQ6: 789 | CR6: 248 | CS6: 2159 | CT6: 303 | CU6: 59715 | CV6: 62255 | CW6: 1263 | CX6: 61800 | CY6: 2194 | CZ6: 216 | DA6: 198 | DB6: 214 | DC6: 260 | DD6: 2152 | DE6: 2128 | DF6: 247 | DG6: 228 | DH6: 2135 | DI6: 261 | DJ6: 237 | DK6: 253 | DL6: 770 | DM6: 225 | DN6: 2201 | DO6: 2171 | DP6: 760 | DQ6: 235 | DR6: 238 | DS6: 2184 | DT6: 61855 | DU6: 223 | DV6: 226 | DW6: 201 | DX6: 258 | DY6: 259 | DZ6: 920 | EA6: 257 | EB6: 256 | EC6: 2148 | ED6: 58288 | EE6: 58289 | EF6: 58839 | EG6: 58840 | EH6: 296 | EI6: 297 | EJ6: 211 | EK6: 2175 | EL6: 2178 | EM6: 2181 | EN6: 1262 | EO6: 233 | EP6: 2150 | EQ6: 2165 | ER6: 2161 | ES6: 61197 | ET6: 58851 | EU6: 234 | EV6: 215 | EW6: 917 | EX6: 289 | EY6: 58333 | EZ6: 58336 | FA6: 202 | FB6: 58487 | FC6: 213 | FD6: 232 | FE6: 2190 | FF6: TOTAL COES | FH6: 221 | FI6: 49607 | FJ6: 222 | FK6: 224 | FL6: 2187 | FM6: 227 | FN6: 49400 | FO6: 199 | FP6: 200 | FQ6: TOTAL NO COES
C7: CENTRO | D7: CENTRO | E7: NORTE | F7: CENTRO | G7: CENTRO | H7: NORTE | I7: NORTE | J7: NORTE | K7: NORTE | L7: CENTRO | M7: CENTRO | N7: CENTRO | O7: CENTRO | P7: CENTRO | Q7: CENTRO | R7: CENTRO | S7: CENTRO | T7: CENTRO | U7: CENTRO | V7: CENTRO | W7: CENTRO | X7: CENTRO | Y7: CENTRO | Z7: SUR | AA7: SUR | AB7: CENTRO | AC7: SUR | AD7: SUR | AE7: SUR | AF7: SUR | AG7: SUR | AH7: SUR | AI7: SUR | AJ7: SUR | AK7: CENTRO | AL7: NORTE | AM7: NORTE | AN7: NORTE | AO7: CENTRO | AP7: CENTRO | AQ7: CENTRO | AR7: CENTRO | AS7: CENTRO | AT7: CENTRO | AU7: CENTRO | AV7: SUR | AW7: CENTRO | AX7: CENTRO | AY7: CENTRO | AZ7: CENTRO | BA7: CENTRO | BB7: CENTRO | BC7: CENTRO | BD7: CENTRO | BE7: SUR | BF7: NORTE | BG7: CENTRO | BH7: CENTRO | BI7: NORTE | BJ7: NORTE | BK7: NORTE | BL7: SUR | BM7: SUR | BN7: SUR | BO7: CENTRO | BP7: CENTRO | BQ7: CENTRO | BR7: CENTRO | BS7: CENTRO | BT7: CENTRO | BU7: CENTRO | BV7: SUR | BW7: SUR | BX7: SUR | BY7: NORTE | BZ7: SUR | CA7: CENTRO | CB7: CENTRO | CC7: CENTRO | CD7: CENTRO | CE7: CENTRO | CF7: CENTRO | CG7: CENTRO | CH7: CENTRO | CI7: CENTRO | CJ7: CENTRO | CK7: CENTRO | CL7: CENTRO | CM7: CENTRO | CN7: SUR | CO7: SUR | CP7: SUR | CQ7: SUR | CR7: CENTRO | CS7: CENTRO | CT7: CENTRO | CU7: CENTRO | CV7: SUR | CW7: NORTE | CX7: NORTE | CY7: NORTE | CZ7: NORTE | DA7: NORTE | DB7: CENTRO | DC7: CENTRO | DD7: CENTRO | DE7: NORTE | DF7: NORTE | DG7: CENTRO | DH7: CENTRO | DI7: SUR | DJ7: SUR | DK7: CENTRO | DL7: CENTRO | DM7: CENTRO | DN7: CENTRO | DO7: CENTRO | DP7: CENTRO | DQ7: SUR | DR7: CENTRO | DS7: CENTRO | DT7: NORTE | DU7: CENTRO | DV7: CENTRO | DW7: NORTE | DX7: CENTRO | DY7: CENTRO | DZ7: CENTRO | EA7: NORTE | EB7: NORTE | EC7: SUR | ED7: CENTRO | EE7: CENTRO | EF7: CENTRO | EG7: CENTRO | EH7: CENTRO | EI7: CENTRO | EJ7: SUR | EK7: SUR | EL7: SUR | EM7: SUR | EN7: NORTE | EO7: SUR | EP7: SUR | EQ7: CENTRO | ER7: CENTRO | ES7: CENTRO | ET7: SUR | EU7: SUR | EV7: NORTE | EW7: CENTRO | EX7: NORTE | EY7: NORTE | EZ7: NORTE | FA7: CENTRO | FB7: CENTRO | FC7: CENTRO | FD7: NORTE | FE7: NORTE | FH7: NORTE | FI7: SUR | FJ7: CENTRO | FK7: NORTE | FL7: NORTE | FM7: NORTE | FN7: NORTE | FO7: NORTE | FP7: NORTE
C8: HIDROELÉCTRICA | D8: HIDROELÉCTRICA | E8: HIDROELÉCTRICA | F8: HIDROELÉCTRICA | G8: HIDROELÉCTRICA | H8: TERMOELÉCTRICA | I8: TERMOELÉCTRICA | J8: HIDROELÉCTRICA | K8: HIDROELÉCTRICA | L8: TERMOELÉCTRICA | M8: TERMOELÉCTRICA | N8: TERMOELÉCTRICA | O8: TERMOELÉCTRICA | P8: TERMOELÉCTRICA | Q8: TERMOELÉCTRICA | R8: TERMOELÉCTRICA | S8: TERMOELÉCTRICA | T8: HIDROELÉCTRICA | U8: HIDROELÉCTRICA | V8: TERMOELÉCTRICA | W8: TERMOELÉCTRICA | X8: TERMOELÉCTRICA | Y8: TERMOELÉCTRICA | Z8: HIDROELÉCTRICA | AA8: HIDROELÉCTRICA | AB8: TERMOELÉCTRICA | AC8: HIDROELÉCTRICA | AD8: HIDROELÉCTRICA | AE8: HIDROELÉCTRICA | AF8: HIDROELÉCTRICA | AG8: TERMOELÉCTRICA | AH8: TERMOELÉCTRICA | AI8: TERMOELÉCTRICA | AJ8: HIDROELÉCTRICA | AK8: HIDROELÉCTRICA | AL8: TERMOELÉCTRICA | AM8: TERMOELÉCTRICA | AN8: TERMOELÉCTRICA | AO8: HIDROELÉCTRICA | AP8: HIDROELÉCTRICA | AQ8: HIDROELÉCTRICA | AR8: HIDROELÉCTRICA | AS8: HIDROELÉCTRICA | AT8: HIDROELÉCTRICA | AU8: HIDROELÉCTRICA | AV8: HIDROELÉCTRICA | AW8: TERMOELÉCTRICA | AX8: TERMOELÉCTRICA | AY8: TERMOELÉCTRICA | AZ8: HIDROELÉCTRICA | BA8: HIDROELÉCTRICA | BB8: HIDROELÉCTRICA | BC8: HIDROELÉCTRICA | BD8: HIDROELÉCTRICA | BE8: HIDROELÉCTRICA | BF8: HIDROELÉCTRICA | BG8: HIDROELÉCTRICA | BH8: HIDROELÉCTRICA | BI8: TERMOELÉCTRICA | BJ8: TERMOELÉCTRICA | BK8: TERMOELÉCTRICA | BL8: TERMOELÉCTRICA | BM8: TERMOELÉCTRICA | BN8: TERMOELÉCTRICA | BO8: HIDROELÉCTRICA | BP8: TERMOELÉCTRICA | BQ8: TERMOELÉCTRICA | BR8: TERMOELÉCTRICA | BS8: TERMOELÉCTRICA | BT8: TERMOELÉCTRICA | BU8: TERMOELÉCTRICA | BV8: TERMOELÉCTRICA | BW8: TERMOELÉCTRICA | BX8: TERMOELÉCTRICA | BY8: HIDROELÉCTRICA | BZ8: TERMOELÉCTRICA | CA8: TERMOELÉCTRICA | CB8: HIDROELÉCTRICA | CC8: HIDROELÉCTRICA | CD8: HIDROELÉCTRICA | CE8: HIDROELÉCTRICA | CF8: HIDROELÉCTRICA | CG8: TERMOELÉCTRICA | CH8: TERMOELÉCTRICA | CI8: TERMOELÉCTRICA | CJ8: TERMOELÉCTRICA | CK8: TERMOELÉCTRICA | CL8: TERMOELÉCTRICA | CM8: TERMOELÉCTRICA | CN8: TERMOELÉCTRICA | CO8: TERMOELÉCTRICA | CP8: TERMOELÉCTRICA | CQ8: TERMOELÉCTRICA | CR8: TERMOELÉCTRICA | CS8: TERMOELÉCTRICA | CT8: SOLAR | CU8: EÓLICA | CV8: SOLAR | CW8: EÓLICA | CX8: SOLAR | CY8: HIDROELÉCTRICA | CZ8: HIDROELÉCTRICA | DA8: HIDROELÉCTRICA | DB8: HIDROELÉCTRICA | DC8: HIDROELÉCTRICA | DD8: HIDROELÉCTRICA | DE8: HIDROELÉCTRICA | DF8: HIDROELÉCTRICA | DG8: HIDROELÉCTRICA | DH8: HIDROELÉCTRICA | DI8: SOLAR | DJ8: SOLAR | DK8: EÓLICA | DL8: EÓLICA | DM8: TERMOELÉCTRICA | DN8: TERMOELÉCTRICA | DO8: TERMOELÉCTRICA | DP8: TERMOELÉCTRICA | DQ8: SOLAR | DR8: HIDROELÉCTRICA | DS8: HIDROELÉCTRICA | DT8: HIDROELÉCTRICA | DU8: HIDROELÉCTRICA | DV8: HIDROELÉCTRICA | DW8: HIDROELÉCTRICA | DX8: HIDROELÉCTRICA | DY8: HIDROELÉCTRICA | DZ8: HIDROELÉCTRICA | EA8: EÓLICA | EB8: EÓLICA | EC8: SOLAR | ED8: EÓLICA | EE8: EÓLICA | EF8: EÓLICA | EG8: EÓLICA | EH8: HIDROELÉCTRICA | EI8: HIDROELÉCTRICA | EJ8: HIDROELÉCTRICA | EK8: HIDROELÉCTRICA | EL8: HIDROELÉCTRICA | EM8: HIDROELÉCTRICA | EN8: EÓLICA | EO8: SOLAR | EP8: SOLAR | EQ8: HIDROELÉCTRICA | ER8: EÓLICA | ES8: EÓLICA | ET8: SOLAR | EU8: SOLAR | EV8: HIDROELÉCTRICA | EW8: HIDROELÉCTRICA | EX8: TERMOELÉCTRICA | EY8: TERMOELÉCTRICA | EZ8: TERMOELÉCTRICA | FA8: TERMOELÉCTRICA | FB8: TERMOELÉCTRICA | FC8: TERMOELÉCTRICA | FD8: TERMOELÉCTRICA | FE8: TERMOELÉCTRICA | FH8: HIDROELÉCTRICA | FI8: HIDROELÉCTRICA | FJ8: HIDROELÉCTRICA | FK8: HIDROELÉCTRICA | FL8: HIDROELÉCTRICA | FM8: TERMOELÉCTRICA | FN8: TERMOELÉCTRICA | FO8: HIDROELÉCTRICA | FP8: HIDROELÉCTRICA
