Workbook

Sheet EVENTOS
B3: jueves, 19 de Junio del 2025
B5: INFORMACIÓN DE EVENTOS PRINCIPALES EN SUS INSTALACIONES
B6: TIPO DE EVENTO | C6: EMPRESA | D6: UBICACIÓN | E6: TIPO DE EQUIPO | F6: EQUIPO | G6: INICIO | H6: FINAL | I6: DESCRIPCIÓN | J6: MW INDISP. | K6: INTERRUPCIÓN (SI/NO) | L6: TENSIÓN DE FALLA (kV)
B7: EVENTO | C7: CONELSUR LT SAC | D7: PORTILLO | E7: SUBESTACION | F7: SS.EE. | G7: 19/06/2025 00:00:00 | H7: 20/06/2025 00:00:00 | I7: DECLARACIÓN DE SITUACIÓN EXCEPCIONAL EN LA S.E. PORTILLO DE 60 kV | K7: NO
B8: EVENTO | C8: RED DE ENERGIA DEL PERU S.A. | D8: TINGO MARÍA - AUCAYACU | E8: LINEA DE TRANSMISION | F8: L-1122 | G8: 19/06/2025 18:42:00 | H8: 19/06/2025 20:11:00 | I8: DECLARACIÓN DE SITUACIÓN EXCEPCIONAL EN LA LINEA L-1122 (TINGO MARIA - AUCAYACU) DE 138 KV | K8: NO

Sheet RESTRIC_OPE
B3: jueves, 19 de Junio del 2025
B5: RESTRICCIONES OPERATIVAS
B6: FECHA | C6: HORA INICIO | D6: HORA FINAL | E6: EMPRESA | F6: UBICACIÓN | G6: T.Eq. | H6: EQUIPO | I6: DESCRIPCIÓN
B7: 19/06/2025 | C7: 00:00 | D7: 24:00 | E7: EGASA | F7: C.H. CHARCANI II | G7: GH | H7: G2 | I7: El Grupo N°02 esta operando con una potencia no mayor a 0.07MW en referencia a 0.18MW de su potencia efectiva, con el fin de no generar daños mayores hasta la reparación de su cojinete.
B8: 19/06/2025 | C8: 00:00 | D8: 24:00 | E8: EGASA | F8: S.E. CONVERTIDOR | G8: BARRA | H8: BARRA138KV | I8: EGASA limitó la capacidad del transformador 138 kV/33 kV a 50 MVA por deterioro del aislamiento.
B9: 19/06/2025 | C9: 00:00 | D9: 24:00 | E9: ENEL GENERACION PIURA S.A. | F9: C.T. MALACAS | G9: CT | H9: CENTRAL | I9: De acuerdo con la comunicación vía correo del día 24.10.2024. ENEL GENERACIÓN PIURA informa una restricción de potencia para alcanzar 105 MW en simultaneo (TG6+TGN4).
B10: 19/06/2025 | C10: 00:00 | D10: 24:00 | E10: ENEL GENERACION PIURA S.A. | F10: C.T. MALACAS | G10: GT | H10: TG4 | I10: De acuerdo a lo informado mediante correo electronico el día 19.05, la TG4 solo puede operar a máxima generación dos horas y el resto a carga a mínima carga.
B11: 19/06/2025 | C11: 00:00 | D11: 24:00 | E11: ENGIE | F11: C.E. PUNTA LOMITAS | G11: CE | H11: CENTRAL | I11: De acuerdo a la carta ENG/737-2024 (Exp:202400007555). Limitación de cables de media tensión a 100 MW de los transformadores PLT1 y PLT2 de la CE Punta Lomitas. Quedan limitados a 200 MW la generación de CE Punta Lomitas y Punta Lomitas Extensión.
B12: 19/06/2025 | C12: 00:00 | D12: 24:00 | E12: ENGIE | F12: C.H. YUNCÁN | G12: GH | H12: G3 | I12: Según la carta N° ENG/ 198-2024 enviada por su representada, se opera de forma continua el G3 de la CH Yuncán, debido a la ejecución de mantenimientos necesarios para evitar daños en los sellos de seguridad de la válvula esférica del grupo.
B13: 19/06/2025 | C13: 00:00 | D13: 24:00 | E13: ENGIE | F13: C.T. CHILCA 1 | G13: CT | H13: CENTRAL | I13: Restricción de temperatura de la C.T Chilca, ver valor en el modelo de despacho.
B14: 19/06/2025 | C14: 00:00 | D14: 24:00 | E14: ENGIE | F14: C.T. CHILCA 1 | G14: CT | H14: CENTRAL | I14: Con carta ENG/971-2023, indica que no puede cumplir con las IO considerada en el PDO_17122023 dado que vulneran la seguridad de sus activos. Indican que se debe tomar TMO=168h.
B15: 19/06/2025 | C15: 00:00 | D15: 24:00 | E15: ENGIE | F15: C.T. CHILCA 2 | G15: CT | H15: CENTRAL | I15: Restricción de temperatura de la C.T Chilca2, ver valor en el modelo de despacho.
B16: 19/06/2025 | C16: 00:00 | D16: 24:00 | E16: ENGIE | F16: C.T. CHILCA 2 | G16: CT | H16: CENTRAL | I16: Con carta ENG/971-2023, indica que no puede cumplir con las IO considerada en el PDO_17122023 dado que vulneran la seguridad de sus activos. Indican que se debe tomar TMO=168h.
B17: 19/06/2025 | C17: 00:00 | D17: 24:00 | E17: FENIX POWER PERÚ | F17: C.T. FENIX | G17: CT | H17: CENTRAL | I17: De acuerdo con lo comunicado en el correo del día 06.05.2024, la CT Fenix cuenta con TMO de 168 hrs en todos su modos de operación.
... B42: 19/06/2025 | C42: 00:00 | D42: 24:00 | E42: TERMOSELVA | F42: C.T. AGUAYTÍA | G42: CT | H42: CENTRAL | I42: Disponibilidad de 12 MMSCF para la CT Aguaytía.

Sheet MANTENIMIENTO EJECUTADOS
B3: jueves, 19 de Junio del 2025
B5: Mantenimiento Ejecutado
B6: Empresa | C6: Ubicación | D6: Equipo | E6: Inicio | F6: Final | G6: Descripción | H6: MW Indisp. | I6: Prog. | J6: Dispon | K6: Interrupc. | L6: Tipo | M6: CodEq | N6: TipoEq_Osinerg
B7: AGROAURORA S.A.C. | C7: MAPLE ETANOL | D7: CENTRAL | E7: 19/06/2025 00:00 | F7: 20/06/2025 00:00 | G7: CENTRAL TERMOELECTRICA FUERA DE SERVICIO POR FALTA DE MATERIA PRIMA PARA LOS REQUERIMIENTOS DE CALOR UTIL EN FABRICA. | H7: 17 | I7: P | J7: F/S | K7: N | L7: OTROS | M7: 13417 | N7: G
B8: ATLANTICA TRANSMISION SUR S.A. | C8: MONTALVO | D8: ACOPLE 220 | E8: 19/06/2025 00:00 | F8: 20/06/2025 00:00 | G8: Proyecto Refuerzos: Reemplazo del HMI existente, Pruebas y Configuracion. No se contara con nivel 1 de operacion. | H8: 0 | I8: P | J8: E/S | K8: N | L8: P.ENERG | M8: 14767 | N8: T
B9: ATLANTICA TRANSMISION SUR S.A. | C9: MONTALVO | D9: BARRA A_220KV | E9: 19/06/2025 00:00 | F9: 20/06/2025 00:00 | G9: Proyecto Refuerzos: Indisponibilidad de la proteccion diferencial de barras 220 kV por Conexion de la nueva UB-87B hacia la UC existente,Configuracion y Pruebas. | H9: 0 | I9: P | J9: E/S | K9: N | L9: P.ENERG | M9: 13869 | N9: T
B10: ATLANTICA TRANSMISION SUR S.A. | C10: MONTALVO | D10: BARRA A_500KV | E10: 19/06/2025 00:00 | F10: 20/06/2025 00:00 | G10: Proyecto Refuerzos: Indisponibilidad de la proteccion diferencial de barras 500kV por conexion de nueva UB-87B hacia la UC existente, Configuracion y Pruebas. | H10: 0 | I10: P | J10: E/S | K10: N | L10: P.ENERG | M10: 13870 | N10: T
B11: ATLANTICA TRANSMISION SUR S.A. | C11: MONTALVO | D11: BARRA B_220kV | E11: 19/06/2025 00:00 | F11: 20/06/2025 00:00 | G11: Proyecto Refuerzos: Indisponibilidad de la proteccion diferencial de barras 220 kV por Conexion de la nueva UB-87B hacia la UC existente,Configuracion y Pruebas. | H11: 0 | I11: P | J11: E/S | K11: N | L11: P.ENERG | M11: 14765 | N11: T
B12: ATLANTICA TRANSMISION SUR S.A. | C12: MONTALVO | D12: BARRA B_500KV | E12: 19/06/2025 00:00 | F12: 20/06/2025 00:00 | G12: Proyecto Refuerzos: Indisponibilidad de la proteccion diferencial de barras 500kV por conexion de nueva UB-87B hacia la UC existente, Configuracion y Pruebas. | H12: 0 | I12: P | J12: E/S | K12: N | L12: P.ENERG | M12: 13871 | N12: T
B13: ATLANTICA TRANSMISION SUR S.A. | C13: MONTALVO | D13: CL-2057 | E13: 19/06/2025 00:00 | F13: 20/06/2025 00:00 | G13: Proyecto Refuerzos: Reemplazo del HMI existente, Pruebas y Configuracion. No se contara con nivel 1 de operacion. | H13: 0 | I13: P | J13: E/S | K13: N | L13: P.ENERG | M13: 13812 | N13: T
B14: ATLANTICA TRANSMISION SUR S.A. | C14: MONTALVO | D14: CL-AUT-5671_500 | E14: 19/06/2025 00:00 | F14: 20/06/2025 00:00 | G14: Proyecto Refuerzos: Reemplazo del HMI existente, Pruebas y Configuracion. No se contara con nivel 1 de operacion en INT-5671, INT-5652 y SAT-5671. | H14: 0 | I14: P | J14: E/S | K14: N | L14: P.ENERG | M14: 13809 | N14: T
B15: ATLANTICA TRANSMISION SUR S.A. | C15: MONTALVO | D15: INT-5652 | E15: 19/06/2025 00:00 | F15: 20/06/2025 00:00 | G15: Proyecto Refuerzos: Indisponible por Implementacion de Conexion de corrientes, disparos, posiciones, enclavamientos hacia los equipos del nuevo Autotransformador. AUT-5671 en servicio solo por Barra A 500kV. | H15: 0 | I15: P | J15: F/S | K15: N | L15: P.ENERG | M15: 13765 | N15: T
B16: ATLANTICA TRANSMISION SUR S.A. | C16: OCONA | D16: INT-5450 | E16: 19/06/2025 00:00 | F16: 20/06/2025 00:00 | G16: Interruptor INT-5450 cerrado con restriccion operativa, REB-5450 en servicio y suministrando los SS.AA. de la S.E. Oco?a. | H16: 0 | I16: P | J16: E/S | K16: N | L16: OTROS | M16: 13761 | N16: T
B17: ATLANTICA TRANSMISION SUR S.A. | C17: OCONA | D17: INT-5462 | E17: 19/06/2025 00:00 | F17: 20/06/2025 00:00 | G17: Seccionador SBA-5462 fase T indisponible por problemas mecanicos, el seccionador permanece cerrado y bloqueado | H17: 0 | I17: P | J17: E/S | K17: N | L17: OTROS | M17: 13758 | N17: T
B18: ATLANTICA TRANSMISION SUR S.A. | C18: OCONA | D18: CL-BCS-5484 | E18: 19/06/2025 08:11 | F18: 19/06/2025 14:50 | G18: LIMPIEZA DE AISLAMIENTO | H18: 0 | I18: P | J18: F/S | K18: N | L18: PREV. | M18: 13868 | N18: T
... B168: TRANSMANTARO | C168: YARABAMBA | D168: BARRA A_220 kV | E168: 19/06/2025 14:37 | F168: 19/06/2025 16:25 | G168: FUERA DE SERVICIO DEBIDO A TRABAJOS DE CL-2066. (R0114238) | H168: 0 | I168: P | J168: F/S | K168: N | L168: OTROS | M168: 17444 | N168: T

Sheet INGRESO OC
A3: jueves, 19 de Junio del 2025
A5: INGRESO A OPERACIÓN COMERCIAL
A6: EMPRESA | B6: TIPO DE EQUIPO | C6: UBICACIÓN | D6: EQUIPO | E6: Fecha y hora de Ingreso a Operación Comercial

Sheet DESPACHO_EJECUTADO
B3: jueves, 19 de Junio del 2025
A5: POTENCIA ACTIVA EJECUTADA DE LAS UNIDADES DE GENERACIÓN DEL SEIN (MW) | FL5: CENTRALES NO INTEGRANTES COES
A6: FECHA | B6: HORA | C6: 65333 | D6: 101 | E6: 102 | F6: 42667 | G6: 42668 | H6: 126 | I6: 127 | J6: 138 | K6: 139 | L6: 197 | M6: 203 | N6: 204 | O6: 230 | P6: 209 | Q6: 56677 | R6: 796 | S6: 2146 | T6: 142 | U6: 143 | V6: 125 | W6: 187 | X6: 163 | Y6: 298 | Z6: 299 | AA6: 219 | AB6: 151 | AC6: 152 | AD6: 153 | AE6: 154 | AF6: 756 | AG6: 156 | AH6: 155 | AI6: 182 | AJ6: 212 | AK6: 758 | AL6: 263 | AM6: 265 | AN6: 775 | AO6: 777 | AP6: 2154 | AQ6: 150 | AR6: 149 | AS6: 188 | AT6: 2131 | AU6: 755 | AV6: 252 | AW6: 249 | AX6: 250 | AY6: 117 | AZ6: 267 | BA6: 268 | BB6: 119 | BC6: 120 | BD6: 189 | BE6: 122 | BF6: 266 | BG6: 337 | BH6: 338 | BI6: 251 | BJ6: 115 | BK6: 239 | BL6: 288 | BM6: 240 | BN6: 241 | BO6: 242 | BP6: 191 | BQ6: 194 | BR6: 196 | BS6: 207 | BT6: 236 | BU6: 795 | BV6: 285 | BW6: 995 | BX6: 996 | BY6: 997 | BZ6: 766 | CA6: 926 | CB6: 924 | CC6: 121 | CD6: 103 | CE6: 104 | CF6: 106 | CG6: 105 | CH6: 107 | CI6: 110 | CJ6: 109 | CK6: 144 | CL6: 113 | CM6: 114 | CN6: 193 | CO6: 208 | CP6: 786 | CQ6: 787 | CR6: 788 | CS6: 789 | CT6: 248 | CU6: 2159 | CV6: 303 | CW6: 59715 | CX6: 62255 | CY6: 1263 | CZ6: 61800 | DA6: 2194 | DB6: 216 | DC6: 198 | DD6: 49607 | DE6: 214 | DF6: 260 | DG6: 2152 | DH6: 2128 | DI6: 247 | DJ6: 228 | DK6: 2135 | DL6: 261 | DM6: 237 | DN6: 253 | DO6: 770 | DP6: 225 | DQ6: 2201 | DR6: 2171 | DS6: 760 | DT6: 235 | DU6: 238 | DV6: 2184 | DW6: 61855 | DX6: 223 | DY6: 226 | DZ6: 201 | EA6: 258 | EB6: 259 | EC6: 920 | ED6: 257 | EE6: 256 | EF6: 2148 | EG6: 58288 | EH6: 58289 | EI6: 58839 | EJ6: 58840 | EK6: 296 | EL6: 297 | EM6: 211 | EN6: 2175 | EO6: 2178 | EP6: 2181 | EQ6: 1262 | ER6: 63425 | ES6: 233 | ET6: 2150 | EU6: 2165 | EV6: 2161 | EW6: 61197 | EX6: 58851 | EY6: 234 | EZ6: 215 | FA6: 917 | FB6: 289 | FC6: 58333 | FD6: 58336 | FE6: 213 | FF6: 232 | FG6: 2190 | FH6: 202 | FI6: 58487 | FJ6: TOTAL COES | FL6: 221 | FM6: 222 | FN6: 224 | FO6: 2187 | FP6: 227 | FQ6: 49400 | FR6: 199 | FS6: 200 | FT6: TOTAL NO COES
C7: SUR | D7: CENTRO | E7: CENTRO | F7: NORTE | G7: NORTE | H7: NORTE | I7: NORTE | J7: CENTRO | K7: CENTRO | L7: CENTRO | M7: CENTRO | N7: CENTRO | O7: CENTRO | P7: CENTRO | Q7: CENTRO | R7: CENTRO | S7: CENTRO | T7: CENTRO | U7: CENTRO | V7: CENTRO | W7: CENTRO | X7: SUR | Y7: SUR | Z7: SUR | AA7: CENTRO | AB7: SUR | AC7: SUR | AD7: SUR | AE7: SUR | AF7: SUR | AG7: SUR | AH7: SUR | AI7: SUR | AJ7: CENTRO | AK7: NORTE | AL7: NORTE | AM7: NORTE | AN7: CENTRO | AO7: CENTRO | AP7: CENTRO | AQ7: CENTRO | AR7: CENTRO | AS7: CENTRO | AT7: CENTRO | AU7: SUR | AV7: CENTRO | AW7: CENTRO | AX7: CENTRO | AY7: CENTRO | AZ7: CENTRO | BA7: CENTRO | BB7: CENTRO | BC7: CENTRO | BD7: SUR | BE7: NORTE | BF7: CENTRO | BG7: CENTRO | BH7: CENTRO | BI7: CENTRO | BJ7: NORTE | BK7: NORTE | BL7: NORTE | BM7: SUR | BN7: SUR | BO7: SUR | BP7: CENTRO | BQ7: CENTRO | BR7: CENTRO | BS7: CENTRO | BT7: CENTRO | BU7: CENTRO | BV7: CENTRO | BW7: SUR | BX7: SUR | BY7: SUR | BZ7: NORTE | CA7: SUR | CB7: CENTRO | CC7: NORTE | CD7: CENTRO | CE7: CENTRO | CF7: CENTRO | CG7: CENTRO | CH7: CENTRO | CI7: CENTRO | CJ7: CENTRO | CK7: CENTRO | CL7: CENTRO | CM7: CENTRO | CN7: CENTRO | CO7: CENTRO | CP7: SUR | CQ7: SUR | CR7: SUR | CS7: SUR | CT7: CENTRO | CU7: CENTRO | CV7: CENTRO | CW7: CENTRO | CX7: SUR | CY7: NORTE | CZ7: NORTE | DA7: NORTE | DB7: NORTE | DC7: NORTE | DD7: SUR | DE7: CENTRO | DF7: CENTRO | DG7: CENTRO | DH7: NORTE | DI7: NORTE | DJ7: CENTRO | DK7: CENTRO | DL7: SUR | DM7: SUR | DN7: CENTRO | DO7: CENTRO | DP7: CENTRO | DQ7: CENTRO | DR7: CENTRO | DS7: CENTRO | DT7: SUR | DU7: CENTRO | DV7: CENTRO | DW7: NORTE | DX7: CENTRO | DY7: CENTRO | DZ7: NORTE | EA7: CENTRO | EB7: CENTRO | EC7: CENTRO | ED7: NORTE | EE7: NORTE | EF7: SUR | EG7: CENTRO | EH7: CENTRO | EI7: CENTRO | EJ7: CENTRO | EK7: CENTRO | EL7: CENTRO | EM7: SUR | EN7: SUR | EO7: SUR | EP7: SUR | EQ7: NORTE | ER7: SUR | ES7: SUR | ET7: SUR | EU7: CENTRO | EV7: CENTRO | EW7: CENTRO | EX7: SUR | EY7: SUR | EZ7: NORTE | FA7: CENTRO | FB7: NORTE | FC7: NORTE | FD7: NORTE | FE7: CENTRO | FF7: NORTE | FG7: NORTE | FH7: CENTRO | FI7: CENTRO | FL7: NORTE | FM7: CENTRO | FN7: NORTE | FO7: NORTE | FP7: NORTE | FQ7: NORTE | FR7: NORTE | FS7: NORTE
C8: HIDROELÉCTRICA | D8: HIDROELÉCTRICA | E8: HIDROELÉCTRICA | F8: TERMOELÉCTRICA | G8: TERMOELÉCTRICA | H8: HIDROELÉCTRICA | I8: HIDROELÉCTRICA | J8: TERMOELÉCTRICA | K8: TERMOELÉCTRICA | L8: TERMOELÉCTRICA | M8: TERMOELÉCTRICA | N8: TERMOELÉCTRICA | O8: TERMOELÉCTRICA | P8: TERMOELÉCTRICA | Q8: TERMOELÉCTRICA | R8: HIDROELÉCTRICA | S8: HIDROELÉCTRICA | T8: TERMOELÉCTRICA | U8: TERMOELÉCTRICA | V8: TERMOELÉCTRICA | W8: TERMOELÉCTRICA | X8: HIDROELÉCTRICA | Y8: HIDROELÉCTRICA | Z8: HIDROELÉCTRICA | AA8: TERMOELÉCTRICA | AB8: HIDROELÉCTRICA | AC8: HIDROELÉCTRICA | AD8: HIDROELÉCTRICA | AE8: HIDROELÉCTRICA | AF8: TERMOELÉCTRICA | AG8: TERMOELÉCTRICA | AH8: TERMOELÉCTRICA | AI8: HIDROELÉCTRICA | AJ8: HIDROELÉCTRICA | AK8: TERMOELÉCTRICA | AL8: TERMOELÉCTRICA | AM8: TERMOELÉCTRICA | AN8: HIDROELÉCTRICA | AO8: HIDROELÉCTRICA | AP8: HIDROELÉCTRICA | AQ8: HIDROELÉCTRICA | AR8: HIDROELÉCTRICA | AS8: HIDROELÉCTRICA | AT8: HIDROELÉCTRICA | AU8: HIDROELÉCTRICA | AV8: TERMOELÉCTRICA | AW8: TERMOELÉCTRICA | AX8: TERMOELÉCTRICA | AY8: HIDROELÉCTRICA | AZ8: HIDROELÉCTRICA | BA8: HIDROELÉCTRICA | BB8: HIDROELÉCTRICA | BC8: HIDROELÉCTRICA | BD8: HIDROELÉCTRICA | BE8: HIDROELÉCTRICA | BF8: HIDROELÉCTRICA | BG8: HIDROELÉCTRICA | BH8: HIDROELÉCTRICA | BI8: HIDROELÉCTRICA | BJ8: TERMOELÉCTRICA | BK8: TERMOELÉCTRICA | BL8: TERMOELÉCTRICA | BM8: TERMOELÉCTRICA | BN8: TERMOELÉCTRICA | BO8: TERMOELÉCTRICA | BP8: HIDROELÉCTRICA | BQ8: TERMOELÉCTRICA | BR8: TERMOELÉCTRICA | BS8: TERMOELÉCTRICA | BT8: TERMOELÉCTRICA | BU8: TERMOELÉCTRICA | BV8: TERMOELÉCTRICA | BW8: TERMOELÉCTRICA | BX8: TERMOELÉCTRICA | BY8: TERMOELÉCTRICA | BZ8: HIDROELÉCTRICA | CA8: TERMOELÉCTRICA | CB8: TERMOELÉCTRICA | CC8: HIDROELÉCTRICA | CD8: HIDROELÉCTRICA | CE8: HIDROELÉCTRICA | CF8: HIDROELÉCTRICA | CG8: HIDROELÉCTRICA | CH8: HIDROELÉCTRICA | CI8: TERMOELÉCTRICA | CJ8: TERMOELÉCTRICA | CK8: TERMOELÉCTRICA | CL8: TERMOELÉCTRICA | CM8: TERMOELÉCTRICA | CN8: TERMOELÉCTRICA | CO8: TERMOELÉCTRICA | CP8: TERMOELÉCTRICA | CQ8: TERMOELÉCTRICA | CR8: TERMOELÉCTRICA | CS8: TERMOELÉCTRICA | CT8: TERMOELÉCTRICA | CU8: TERMOELÉCTRICA | CV8: SOLAR | CW8: EÓLICA | CX8: SOLAR | CY8: EÓLICA | CZ8: SOLAR | DA8: HIDROELÉCTRICA | DB8: HIDROELÉCTRICA | DC8: HIDROELÉCTRICA | DD8: HIDROELÉCTRICA | DE8: HIDROELÉCTRICA | DF8: HIDROELÉCTRICA | DG8: HIDROELÉCTRICA | DH8: HIDROELÉCTRICA | DI8: HIDROELÉCTRICA | DJ8: HIDROELÉCTRICA | DK8: HIDROELÉCTRICA | DL8: SOLAR | DM8: SOLAR | DN8: EÓLICA | DO8: EÓLICA | DP8: TERMOELÉCTRICA | DQ8: TERMOELÉCTRICA | DR8: TERMOELÉCTRICA | DS8: TERMOELÉCTRICA | DT8: SOLAR | DU8: HIDROELÉCTRICA | DV8: HIDROELÉCTRICA | DW8: HIDROELÉCTRICA | DX8: HIDROELÉCTRICA | DY8: HIDROELÉCTRICA | DZ8: HIDROELÉCTRICA | EA8: HIDROELÉCTRICA | EB8: HIDROELÉCTRICA | EC8: HIDROELÉCTRICA | ED8: EÓLICA | EE8: EÓLICA | EF8: SOLAR | EG8: EÓLICA | EH8: EÓLICA | EI8: EÓLICA | EJ8: EÓLICA | EK8: HIDROELÉCTRICA | EL8: HIDROELÉCTRICA | EM8: HIDROELÉCTRICA | EN8: HIDROELÉCTRICA | EO8: HIDROELÉCTRICA | EP8: HIDROELÉCTRICA | EQ8: EÓLICA | ER8: SOLAR | ES8: SOLAR | ET8: SOLAR | EU8: HIDROELÉCTRICA | EV8: EÓLICA | EW8: EÓLICA | EX8: SOLAR | EY8: SOLAR | EZ8: HIDROELÉCTRICA | FA8: HIDROELÉCTRICA | FB8: TERMOELÉCTRICA | FC8: TERMOELÉCTRICA | FD8: TERMOELÉCTRICA | FE8: TERMOELÉCTRICA | FF8: TERMOELÉCTRICA | FG8: TERMOELÉCTRICA | FH8: TERMOELÉCTRICA | FI8: TERMOELÉCTRICA | FL8: HIDROELÉCTRICA | FM8: HIDROELÉCTRICA | FN8: HIDROELÉCTRICA | FO8: HIDROELÉCTRICA | FP8: TERMOELÉCTRICA | FQ8: TERMOELÉCTRICA | FR8: HIDROELÉCTRICA | FS8: HIDROELÉCTRICA
C9: HYDRO GLOBAL PERÚ S.A.C. | D9: ELECTROPERU | E9: ELECTROPERU | F9: ELECTROPERU | G9: ELECTROPERU | H9: ORAZUL ENERGY PERÚ | I9: ORAZUL ENERGY PERÚ | J9: TERMOSELVA | K9: TERMOSELVA | L9: KALLPA GENERACION S.A. | M9: KALLPA GENERACION S.A. | N9: KALLPA GENERACION S.A. | O9: KALLPA GENERACION S.A. | P9: KALLPA GENERACION S.A. | Q9: KALLPA GENERACION S.A. | R9: KALLPA GENERACION S.A. | S9: KALLPA GENERACION S.A. | T9: SHOUGESA | U9: SHOUGESA | V9: SHOUGESA | W9: SHOUGESA | X9: EGEMSA | Y9: EGESUR | Z9: EGESUR | AA9: EGESUR | AB9: EGASA | AC9: EGASA | AD9: EGASA | AE9: EGASA | AF9: EGASA | AG9: EGASA | AH9: EGASA | AI9: SAN GABAN | AJ9: CELEPSA | AK9: MINERA CERRO VERDE | AL9: PLANTA DE RESERVA FRIA DE GENERACION DE ETEN S.A. | AM9: PLANTA DE RESERVA FRIA DE GENERACION DE ETEN S.A. | AN9: EMPRESA DE GENERACION HUALLAGA | AO9: EMPRESA DE GENERACION HUALLAGA | AP9: LA VIRGEN | AQ9: CHINANGO S.A.C. | AR9: CHINANGO S.A.C. | AS9: HIDROELECTRICA HUANCHOR S.A.C. | AT9: CELEPSA RENOVABLES S.R.L. | AU9: INLAND ENERGY SAC | AV9: FENIX POWER PERÚ | AW9: FENIX POWER PERÚ | AX9: FENIX POWER PERÚ | AY9: STATKRAFT S.A | AZ9: STATKRAFT S.A | BA9: STATKRAFT S.A | BB9: STATKRAFT S.A | BC9: STATKRAFT S.A | BD9: STATKRAFT S.A | BE9: STATKRAFT S.A | BF9: STATKRAFT S.A | BG9: CENTRALES SANTA ROSA S.A.C. | BH9: CENTRALES SANTA ROSA S.A.C. | BI9: EMPRESA DE GENERACION HUANZA | BJ9: ENEL GENERACION PIURA S.A. | BK9: ENEL GENERACION PIURA S.A. | BL9: ENEL GENERACION PIURA S.A. | BM9: ENGIE | BN9: ENGIE | BO9: ENGIE | BP9: ENGIE | BQ9: ENGIE | BR9: ENGIE | BS9: ENGIE | BT9: ENGIE | BU9: ENGIE | BV9: ENGIE | BW9: ENGIE | BX9: ENGIE | BY9: ENGIE | BZ9: ENGIE | CA9: INFRAESTRUCTURAS Y ENERGIAS DEL PERU S.A.C. | CB9: INFRAESTRUCTURAS Y ENERGIAS DEL PERU S.A.C. | CC9: INVERSIONES SHAQSHA S.A.C. | CD9: ORYGEN PERU S.A.A. | CE9: ORYGEN PERU S.A.A. | CF9: ORYGEN PERU S.A.A. | CG9: ORYGEN PERU S.A.A. | CH9: ORYGEN PERU S.A.A. | CI9: ORYGEN PERU S.A.A. | CJ9: ORYGEN PERU S.A.A. | CK9: ORYGEN PERU S.A.A. | CL9: ORYGEN PERU S.A.A. | CM9: ORYGEN PERU S.A.A. | CN9: ORYGEN PERU S.A.A. | CO9: ORYGEN PERU S.A.A. | CP9: SAMAY I S.A.C | CQ9: SAMAY I S.A.C | CR9: SAMAY I S.A.C | CS9: SAMAY I S.A.C | CT9: TERMOCHILCA S.A.C. | CU9: TERMOCHILCA S.A.C. | CV9: COLCA SOLAR S.A.C. | CW9: ENERGIA RENOVABLE DEL SUR S.A. | CX9: GR CORTARRAMA SOCIEDAD ANONIMA CERRADA | CY9: GR TARUCA SOCIEDAD ANONIMA CERRADA | CZ9: KONDU SAC | DA9: PERUANA DE INVERSIONES EN ENERGIAS RENOVABLES S.A. | DB9: ORAZUL ENERGY PERÚ | DC9: ORAZUL ENERGY PERÚ | DD9: SAN GABAN | DE9: MAJA ENERGIA S.A.C. | DF9: EMPRESA DE GENERACION ELECTRICA CANCHAYLLO SAC | DG9: EMPRESA DE GENERACION ELECTRICA SANTA ANA S.A.C. | DH9: EMPRESA ELECTRICA AGUA AZUL | DI9: EMPRESA ELECTRICA RIO DOBLE | DJ9: HIDROCAÑETE S.A. | DK9: HUAURA POWER GROUP S.A. | DL9: MOQUEGUA FV S.A.C. | DM9: PANAMERICANA SOLAR SAC. | DN9: PARQUE EOLICO MARCONA S.A.C. | DO9: PARQUE EOLICO TRES HERMANAS S.A.C. | DP9: PETRAMAS | DQ9: PETRAMAS | DR9: PETRAMAS | DS9: PETRAMAS | DT9: TACNA SOLAR SAC. | DU9: ELECTRICA YANAPAMPA SAC | DV9: ANDEAN POWER S.A.C. | DW9: ASOCIACIÓN SANTA LUCIA DE CHACAS | DX9: ATRIA ENERGIA S.A.C. | DY9: EGEJUNIN | DZ9: EGEJUNIN | EA9: EGEJUNIN | EB9: EGEJUNIN | EC9: EMPRESA DE GENERACION ELECTRICA RIO BAÑOS S.A.C. | ED9: ENERGÍA EÓLICA S.A. | EE9: ENERGÍA EÓLICA S.A. | EF9: ENGIE | EG9: ENGIE | EH9: ENGIE | EI9: ENGIE | EJ9: ENGIE | EK9: GENERACIÓN ANDINA S.A.C. | EL9: GENERACIÓN ANDINA S.A.C. | EM9: GENERADORA DE ENERGÍA DEL PERÚ | EN9: GENERADORA DE ENERGÍA DEL PERÚ | EO9: GENERADORA DE ENERGÍA DEL PERÚ | EP9: GENERADORA DE ENERGÍA DEL PERÚ | EQ9: GR PAINO SOCIEDAD ANONIMA CERRADA | ER9: JOYA SOLAR S.A.C. | ES9: MAJES ARCUS S.A.C. | ET9: ORYGEN PERU S.A.A. | EU9: ORYGEN PERU S.A.A. | EV9: ORYGEN PERU S.A.A. | EW9: ORYGEN PERU S.A.A. | EX9: ORYGEN PERU S.A.A. | EY9: REPARTICIÓN ARCUS S.A.C. | EZ9: SINERSA | FA9: SINERSA | FB9: BIOENERGIA DEL CHIRA S.A. | FC9: GM OPERACIONES S.A.C. | FD9: GM OPERACIONES S.A.C. | FE9: AGRO INDUSTRIAL PARAMONGA S.A. | FF9: AGROAURORA S.A.C. | FG9: AGROINDUSTRIAS SAN JACINTO S.A.A. | FH9: SDF ENERGIA SAC | FI9: SDF ENERGIA SAC | FL9: UNACEM PERU S.A. | FM9: ELECTRO ORIENTE | FN9: AGUAS Y ENERGIA PERU | FO9: ELECTRO ZAÑA S.A.C. | FP9: ELECTRONOROESTE S.A. | FQ9: SDE PIURA | FR9: SINERSA | FS9: SINERSA
C10: SAN GABAN III | D10: MANTARO | E10: RESTITUCION | F10: TUMBES MAK 1 | G10: TUMBES MAK 2 | H10: CARHUAQUERO | I10: CAÑON DEL PATO | J10: AGUAYTIA TG1 | K10: AGUAYTIA TG2 | L10: KALLPA TG1 | M10: KALLPA TG2 | N10: KALLPA TG3 | O10: KALLPA TV | P10: LFLORES TG1 | Q10: LFLORES TV | R10: CERRO DEL AGUILA | S10: CERRODELAGUILAG4 | T10: SHOUGESA TV1 | U10: SHOUGESA TV2 | V10: SHOUGESA TV3 | W10: SHOUGESA CUMMINS | X10: MACHUPICCHU | Y10: ARICOTA 1 | Z10: ARICOTA 2 | AA10: INDEPENDENCIA | AB10: CHARCANI I,II,III | AC10: CHARCANI IV | AD10: CHARCANI V | AE10: CHARCANI VI | AF10: CHILINA TG | AG10: MOLLENDO 1, 2, 3 | AH10: CHILINA (SULZ 1,2) | AI10: SAN GABAN II | AJ10: PLATANAL | AK10: RECKA | AL10: RF ETEN TG1 | AM10: RF ETEN TG2 | AN10: CHAGLLA GP1 | AO10: CHAGLLA | AP10: LA VIRGEN | AQ10: CHIMAY | AR10: YANANGO | AS10: HUANCHOR | AT10: MARAÑON | AU10: STA TERESA | AV10: FENIX GT11 | AW10: FENIX GT12 | AX10: FENIX TV10 | AY10: YAUPI | AZ10: OROYA | BA10: PACHACHACA | BB10: MALPASO | BC10: CAHUA | BD10: ARCATA | BE10: GALLITO CIEGO | BF10: CHEVES | BG10: SANTA ROSA 1 | BH10: SANTA ROSA 2 | BI10: HUANZA | BJ10: MALACAS2 TG4 | BK10: MALACAS3 TG 5 | BL10: MALACAS1 TG6 | BM10: RF ILO2 TG1 | BN10: RF ILO2 TG2 | BO10: RF ILO2 TG3 | BP10: YUNCAN | BQ10: CHILCA1 TG1 | BR10: CHILCA1 TG2 | BS10: CHILCA1 TG3 | BT10: CHILCA-TV | BU10: CHILCA2 TG41 | BV10: CHILCA2-TV | BW10: CTNEPI_TG41 | BX10: CTNEPI_TG42 | BY10: CTNEPI_TG43 | BZ10: QUITARACSA | CA10: RF PTO MALDONADO | CB10: RF PUCALLPA | CC10: PARIAC | CD10: HUINCO | CE10: MATUCANA | CF10: MOYOPAMPA | CG10: CALLAHUANCA | CH10: HUAMPANI | CI10: STA ROSA WEST TG7 | CJ10: UTI_5 | CK10: UTI_6 | CL10: VENTANILLA 3 | CM10: VENTANILLA 4 | CN10: VENTANILLA TV | CO10: STAROSA TG8 | CP10: PTO_BRVO TG1 | CQ10: PTO_BRVO TG2 | CR10: PTO_BRVO TG3 | CS10: PTO_BRVO TG4 | CT10: OLLEROS TG1 | CU10: OLLEROS TV | CV10: CS YARUCAYA | CW10: SAN JUAN | CX10: MATARANI | CY10: DUNA | CZ10: CARHUAQUERO (CS) | DA10: MANTA I | DB10: CARHUAQUERO4 | DC10: CAÑA BRAVA | DD10: TUPURI | DE10: RONCADOR | DF10: CANCHAYLLO | DG10: RENOVANDESH1 | DH10: POTRERO | DI10: PIZARRAS | DJ10: NIMPERIAL | DK10: YARUCAYA | DL10: MOQUEGUA-SOLAR | DM10: PANAMERICANA-SOLAR | DN10: PQE-EOLICO-MARCONA | DO10: PQE-EOLICO-3-HERMANAS | DP10: HUAYCOLORO | DQ10: CALLAO | DR10: DONA_CATALINA | DS10: LAGRINGAV | DT10: TACNA-SOLAR | DU10: YANAPAMPA | DV10: CARHUAC | DW10: HUALLIN | DX10: PURMACANA | DY10: HUASAHUASI | DZ10: STACRUZ_1_2 | EA10: RUNATULLO_II | EB10: RUNATULLO_III | EC10: RUCUY | ED10: PQE-EOLICO-TALARA | EE10: PQE-EOLICO-CUPISNIQUE | EF10: INTIPAMPA | EG10: PUNTA LOMITAS-BL1 | EH10: PUNTA LOMITAS-BL2 | EI10: PUN LOMITAS_EXP-BL1 | EJ10: PUN LOMITAS_EXP-BL2 | EK10: 8AGOSTO | EL10: EL CARMEN | EM10: LA JOYA | EN10: ANGEL_I | EO10: ANGEL_II | EP10: ANGEL_III | EQ10: HUAMBOS | ER10: SAN MARTIN SOLAR | ES10: MAJES | ET10: RUBI | EU10: CH_HER1 | EV10: WAYRA-I | EW10: WAYRA EXTENSION | EX10: CLEMESI | EY10: REPARTICION | EZ10: POECHOS2 | FA10: CHANCAY | FB10: CANA BRAVA | FC10: REFINERIA TALARA TV1 | FD10: REFINERÍA TALARA TV2 | FE10: PARAMONGA | FF10: MAPLE | FG10: SAN_JACINTO | FH10: OQUENDO TG1 | FI10: OQUENDO TV1 | FJ10: MW | FL10: CARPAPATA | FM10: CENTRALES ELOR | FN10: PIAS1 | FO10: ZANA | FP10: TABLAZO | FQ10: TALLANCA | FR10: CURUMUY | FS10: POECHOS1 | FT10: MW
A11: 19/06/2025 | B11: 00:30 | C11: 97.8 | D11: 600.8 | E11: 198.6 | H11: 89.8 | I11: 113.9 | J11: 25.9 | L11: 176.2 | M11: 176.4 | N11: 175.4 | O11: 265 | R11: 393.4 | S11: 4.9 | X11: 162.9 | Y11: 7 | Z11: 5.3 | AA11: 0 | AB11: 6.08 | AC11: 8.64 | AD11: 66.66 | AH11: 0 | AI11: 69.6 | AJ11: 199.6 | AN11: 6.5 | AO11: 226.5 | AP11: 74.3 | AQ11: 138.4 | AR11: 42 | AS11: 18.6 | AT11: 19.8 | AU11: 88.9 | AV11: 180.2 | AW11: 180.3 | AX11: 183.2 | AY11: 109.3 | AZ11: 8.2 | BA11: 2.4 | BB11: 33.9 | BC11: 40.3 | BD11: 4 | BE11: 0 | BF11: 37.9 | BI11: 48 | BL11: 0 | BP11: 86.6 | BQ11: 157.1 | BR11: 0 | BS11: 0 | BT11: 69.1 | BY11: 0 | CB11: 0 | CC11: 1.8 | CD11: 52.4 | CE11: 98.8 | CF11: 61.8 | CG11: 70.8 | CH11: 29.7 | CL11: 145.2 | CM11: 146.5 | CN11: 147.8 | CV11: 0 | CW11: 113.1 | CX11: 0 | CY11: 15.6 | CZ11: 0 | DA11: 17.7 | DB11: 9.9 | DC11: 5.6 | DD11: 0.8 | DE11: 1.5 | DF11: 2.6 | DG11: 20 | DH11: 20 | DI11: 15.6 | DJ11: 3.5 | DK11: 18.4 | DL11: 0 | DM11: 0 | DN11: 32 | DO11: 85.4 | DP11: 4.5 | DQ11: 2.2 | DR11: 2.1 | DS11: 1.4 | DT11: 0 | DU11: 2.9 | DV11: 13.1 | DW11: 2.3 | DY11: 19.7 | DZ11: 5.4 | EA11: 10.3 | EB11: 15.9 | EC11: 18.2 | ED11: 15.6 | EE11: 23.2 | EF11: 0 | EG11: 96.2 | EH11: 84.6 | EI11: 16.8 | EJ11: 8.2 | EK11: 16.4 | EL11: 6.6 | EN11: 9.2 | EO11: 9.8 | EP11: 10 | EQ11: 13.2 | ER11: 0 | ES11: 0 | ET11: 0 | EU11: 0.6 | EV11: 91.6 | EW11: 103.9 | EX11: 0 | EY11: 0 | EZ11: 5.5 | FA11: 19.3 | FB11: 9 | FC11: 43.1 | FD11: 13.3 | FE11: 17.1 | FG11: 7.5 | FJ11: 6434.58 | FL11: 24.2 | FM11: 7.944 | FO11: 12 | FP11: 27.24329 | FQ11: 18.91946 | FR11: 4.6 | FS11: 16 | FT11: 110.90675
A12: 19/06/2025 | B12: 01:00 | C12: 93.7 | D12: 602.1 | E12: 202.3 | H12: 89.9 | I12: 116.1 | J12: 25.7 | L12: 130.9 | M12: 129.6 | N12: 131.1 | O12: 224.6 | R12: 393.9 | S12: 4.9 | X12: 160.5 | Y12: 7.4 | Z12: 5.3 | AA12: 0 | AB12: 6.09 | AC12: 8.62 | AD12: 66.86 | AH12: 0 | AI12: 70 | AJ12: 149.4 | AN12: 6.5 | AO12: 291.2 | AP12: 74 | AQ12: 136.1 | AR12: 42.1 | AS12: 18.8 | AT12: 19.8 | AU12: 86.6 | AV12: 181.9 | AW12: 181.6 | AX12: 183.1 | AY12: 108.9 | AZ12: 8.2 | BA12: 2.4 | BB12: 31.6 | BC12: 41.5 | BD12: 4 | BE12: 0 | BF12: 64.6 | BI12: 47.7 | BL12: 0 | BP12: 86.6 | BQ12: 156.9 | BR12: 0 | BS12: 0 | BT12: 68.8 | BY12: 0 | CB12: 0 | CC12: 1.8 | CD12: 44.3 | CE12: 97.9 | CF12: 61.8 | CG12: 70.5 | CH12: 29.8 | CL12: 145.3 | CM12: 146.6 | CN12: 148.2 | CV12: 0 | CW12: 109.7 | CX12: 0 | CY12: 17.1 | CZ12: 0 | DA12: 18 | DB12: 10 | DC12: 5.6 | DD12: 0.8 | DE12: 1.5 | DF12: 2.6 | DG12: 20.3 | DH12: 20 | DI12: 15.6 | DJ12: 3.5 | DK12: 18.4 | DL12: 0 | DM12: 0 | DN12: 31.9 | DO12: 85.3 | DP12: 4.5 | DQ12: 2.2 | DR12: 2.1 | DS12: 1.4 | DT12: 0 | DU12: 3 | DV12: 13 | DW12: 2.2 | DY12: 19.7 | DZ12: 5.4 | EA12: 10.4 | EB12: 16.1 | EC12: 18 | ED12: 16.6 | EE12: 28 | EF12: 0 | EG12: 99.6 | EH12: 91 | EI12: 17.1 | EJ12: 8.6 | EK12: 16.4 | EL12: 6.5 | EN12: 9.2 | EO12: 9.8 | EP12: 10 | EQ12: 16.3 | ER12: 0 | ES12: 0 | ET12: 0 | EU12: 0.6 | EV12: 83.9 | EW12: 97.3 | EX12: 0 | EY12: 0 | EZ12: 5.6 | FA12: 19.2 | FB12: 8.9 | FC12: 43 | FD12: 14.5 | FE12: 17.6 | FG12: 7.3 | FJ12: 6293.37 | FL12: 24.2 | FM12: 7.945 | FO12: 12 | FP12: 27.11197 | FQ12: 18.91869 | FR12: 4.5 | FS12: 16.1 | FT12: 110.77566
A13: 19/06/2025 | B13: 01:30 | C13: 93.9 | D13: 599.4 | E13: 201.7 | H13: 89.1 | I13: 100 | J13: 25.9 | L13: 123.9 | M13: 123.1 | N13: 123.5 | O13: 223.4 | R13: 391.6 | S13: 4.9 | X13: 157.2 | Y13: 6.9 | Z13: 5.4 | AA13: 0 | AB13: 6.1 | AC13: 8.63 | AD13: 49.71 | AH13: 0 | AI13: 69.4 | AJ13: 79.9 | AN13: 6.5 | AO13: 294.8 | AP13: 74 | AQ13: 143.3 | AR13: 42.1 | AS13: 18.8 | AT13: 19.8 | AU13: 89.7 | AV13: 179.3 | AW13: 180 | AX13: 183.4 | AY13: 108.9 | AZ13: 8.2 | BA13: 2.5 | BB13: 29.1 | BC13: 40.5 | BD13: 4 | BE13: 0 | BF13: 67 | BI13: 47.7 | BL13: 0 | BP13: 86.3 | BQ13: 158 | BR13: 0 | BS13: 0 | BT13: 70.2 | BY13: 0 | CB13: 0 | CC13: 1.8 | CD13: 57.6 | CE13: 109.3 | CF13: 61.5 | CG13: 72.6 | CH13: 29.7 | CL13: 111.4 | CM13: 111.2 | CN13: 130.3 | CV13: 0 | CW13: 110.1 | CX13: 0 | CY13: 14 | CZ13: 0 | DA13: 18.1 | DB13: 9.9 | DC13: 5.4 | DD13: 0.7 | DE13: 1.5 | DF13: 2.6 | DG13: 20.1 | DH13: 20 | DI13: 15.6 | DJ13: 3.5 | DK13: 18.4 | DL13: 0 | DM13: 0 | DN13: 31.8 | DO13: 83.9 | DP13: 4.5 | DQ13: 2.2 | DR13: 2.1 | DS13: 1.4 | DT13: 0 | DU13: 2.9 | DV13: 13 | DW13: 2.2 | DY13: 19.7 | DZ13: 5.4 | EA13: 10.1 | EB13: 15.9 | EC13: 18 | ED13: 16.5 | EE13: 31.6 | EF13: 0 | EG13: 100.3 | EH13: 92 | EI13: 16.6 | EJ13: 7.2 | EK13: 16.4 | EL13: 6.4 | EN13: 9.2 | EO13: 9.8 | EP13: 10 | EQ13: 12.7 | ER13: 0 | ES13: 0 | ET13: 0 | EU13: 0.6 | EV13: 90 | EW13: 122.8 | EX13: 0 | EY13: 0 | EZ13: 5.6 | FA13: 19.2 | FB13: 9.3 | FC13: 42.9 | FD13: 14.5 | FE13: 17.6 | FG13: 7.7 | FJ13: 6135.04 | FL13: 24.2 | FM13: 7.94 | FO13: 12 | FP13: 27.14776 | FQ13: 18.91807 | FR13: 4.6 | FS13: 16 | FT13: 110.80583
A14: 19/06/2025 | B14: 02:00 | C14: 96 | D14: 604.7 | E14: 201.7 | H14: 90.2 | I14: 99.3 | J14: 26.2 | L14: 141.3 | M14: 139.8 | N14: 140.5 | O14: 223.5 | R14: 336 | S14: 4.9 | X14: 163 | Y14: 7.3 | Z14: 5.4 | AA14: 0 | AB14: 6.1 | AC14: 8.64 | AD14: 50.89 | AH14: 0 | AI14: 70.2 | AJ14: 95.5 | AN14: 6.5 | AO14: 355.8 | AP14: 74 | AQ14: 143.5 | AR14: 42.1 | AS14: 18.8 | AT14: 19.8 | AU14: 90.8 | AV14: 181.1 | AW14: 181.7 | AX14: 184.1 | AY14: 109.7 | AZ14: 8.2 | BA14: 2.7 | BB14: 34.1 | BC14: 41.3 | BD14: 4 | BE14: 0 | BF14: 63.4 | BI14: 47.9 | BL14: 0 | BP14: 86.7 | BQ14: 158 | BR14: 0 | BS14: 0 | BT14: 70.3 | BY14: 0 | CB14: 0 | CC14: 1.8 | CD14: 45.2 | CE14: 114.6 | CF14: 62.1 | CG14: 73.9 | CH14: 29.8 | CL14: 102.7 | CM14: 102.6 | CN14: 121.5 | CV14: 0 | CW14: 103.2 | CX14: 0 | CY14: 15 | CZ14: 0 | DA14: 18 | DB14: 10 | DC14: 5.6 | DD14: 0.7 | DE14: 1.5 | DF14: 2.6 | DG14: 20.3 | DH14: 20 | DI14: 15.5 | DJ14: 3.4 | DK14: 18.4 | DL14: 0 | DM14: 0 | DN14: 31.8 | DO14: 84.9 | DP14: 4.5 | DQ14: 2.2 | DR14: 2.1 | DS14: 1.4 | DT14: 0 | DU14: 2.9 | DV14: 13 | DW14: 2.2 | DY14: 19.7 | DZ14: 5.5 | EA14: 10.5 | EB14: 16.1 | EC14: 18 | ED14: 13.1 | EE14: 23.6 | EF14: 0 | EG14: 90 | EH14: 86.3 | EI14: 15.7 | EJ14: 6.2 | EK14: 16.4 | EL14: 6.2 | EN14: 9 | EO14: 9.8 | EP14: 10 | EQ14: 13.8 | ER14: 0 | ES14: 0 | ET14: 0 | EU14: 0.6 | EV14: 96.5 | EW14: 123.4 | EX14: 0 | EY14: 0 | EZ14: 5.6 | FA14: 19.2 | FB14: 9.6 | FC14: 42.8 | FD14: 14.5 | FE14: 16.8 | FG14: 7.8 | FJ14: 6175.73 | FL14: 24.3 | FM14: 7.941 | FO14: 12 | FP14: 27.0868 | FQ14: 18.91769 | FR14: 4.6 | FS14: 16 | FT14: 110.84549
A15: 19/06/2025 | B15: 02:30 | C15: 101.2 | D15: 602.9 | E15: 201.5 | H15: 90.4 | I15: 106.4 | J15: 25.9 | L15: 114.9 | M15: 114.5 | N15: 113.9 | O15: 224.7 | R15: 327.1 | S15: 5 | X15: 165.6 | Y15: 7.5 | Z15: 5.4 | AA15: 0 | AB15: 6.09 | AC15: 8.63 | AD15: 49.97 | AH15: 0 | AI15: 70.7 | AJ15: 4.4 | AN15: 6.5 | AO15: 408.2 | AP15: 73.8 | AQ15: 144.8 | AR15: 42.1 | AS15: 18.7 | AT15: 19.8 | AU15: 90.3 | AV15: 183.9 | AW15: 183.7 | AX15: 182.3 | AY15: 109.6 | AZ15: 8.1 | BA15: 2.6 | BB15: 23.7 | BC15: 42.2 | BD15: 4 | BE15: 0 | BF15: 54.6 | BI15: 48.3 | BL15: 0 | BP15: 86.9 | BQ15: 157.6 | BR15: 0 | BS15: 0 | BT15: 69.7 | BY15: 0 | CB15: 0 | CC15: 1.8 | CD15: 52 | CE15: 105 | CF15: 62.4 | CG15: 73.9 | CH15: 30.1 | CL15: 102.8 | CM15: 102.6 | CN15: 120.8 | CV15: 0 | CW15: 110.3 | CX15: 0 | CY15: 17.3 | CZ15: 0 | DA15: 17.9 | DB15: 9.9 | DC15: 5.4 | DD15: 0.7 | DE15: 1.5 | DF15: 2.6 | DG15: 20.5 | DH15: 20 | DI15: 15.5 | DJ15: 3.5 | DK15: 18.4 | DL15: 0 | DM15: 0 | DN15: 32 | DO15: 82.6 | DP15: 4.5 | DQ15: 2.2 | DR15: 2.1 | DS15: 1.4 | DT15: 0 | DU15: 3 | DV15: 13 | DW15: 2.2 | DY15: 19.7 | DZ15: 5.8 | EA15: 10.5 | EB15: 13.9 | EC15: 17.9 | ED15: 11.4 | EE15: 21.3 | EF15: 0 | EG15: 84.3 | EH15: 78.8 | EI15: 11.6 | EJ15: 6.4 | EK15: 16.5 | EL15: 6.2 | EN15: 8.2 | EO15: 9.5 | EP15: 9.7 | EQ15: 14.6 | ER15: 0 | ES15: 0 | ET15: 0 | EU15: 0.6 | EV15: 108.7 | EW15: 128.6 | EX15: 0 | EY15: 0 | EZ15: 5.6 | FA15: 19.2 | FB15: 9.6 | FC15: 43 | FD15: 14.6 | FE15: 16.9 | FG15: 6.9 | FJ15: 6045.99 | FL15: 24.2 | FM15: 7.94 | FO15: 12 | FP15: 27.18328 | FQ15: 18.91742 | FR15: 4.5 | FS15: 16 | FT15: 110.7407
A16: 19/06/2025 | B16: 03:00 | C16: 42.6 | D16: 595 | E16: 198.7 | H16: 89.8 | I16: 102.2 | J16: 26.2 | L16: 150.9 | M16: 150.1 | N16: 150.3 | O16: 246.7 | R16: 299.9 | S16: 4.8 | X16: 160.1 | Y16: 6.5 | Z16: 5.2 | AA16: 0 | AB16: 6.09 | AC16: 8.61 | AD16: 49.2 | AH16: 0 | AI16: 68.1 | AJ16: 0 | AN16: 6.5 | AO16: 451.3 | AP16: 74.1 | AQ16: 143.5 | AR16: 41.9 | AS16: 18.7 | AT16: 19.8 | AU16: 88.2 | AV16: 175.8 | AW16: 178.2 | AX16: 182.2 | AY16: 107.3 | AZ16: 8 | BA16: 2.7 | BB16: 30.2 | BC16: 43.7 | BD16: 4 | BE16: 0 | BF16: 60.3 | BI16: 47.5 | BL16: 0 | BP16: 85.8 | BQ16: 156.6 | BR16: 0 | BS16: 0 | BT16: 69.6 | BY16: 0 | CB16: 0 | CC16: 1.8 | CD16: 35.5 | CE16: 105.4 | CF16: 60.6 | CG16: 73.2 | CH16: 29.3 | CL16: 102 | CM16: 101.6 | CN16: 120.7 | CV16: 0 | CW16: 101.7 | CX16: 0 | CY16: 15 | CZ16: 0 | DA16: 17.8 | DB16: 10 | DC16: 5.6 | DD16: 0.7 | DE16: 1.5 | DF16: 2.6 | DG16: 19.7 | DH16: 20 | DI16: 15.5 | DJ16: 3.5 | DK16: 18.4 | DL16: 0 | DM16: 0 | DN16: 31.6 | DO16: 83.5 | DP16: 4.5 | DQ16: 2.2 | DR16: 2.1 | DS16: 1.4 | DT16: 0 | DU16: 3 | DV16: 13.2 | DW16: 2.2 | DY16: 19.7 | DZ16: 5.8 | EA16: 9.8 | EB16: 12.9 | EC16: 18 | ED16: 17.2 | EE16: 17 | EF16: 0 | EG16: 89.2 | EH16: 87.5 | EI16: 11.2 | EJ16: 8.1 | EK16: 16.5 | EL16: 6 | EN16: 8.2 | EO16: 9 | EP16: 9.5 | EQ16: 14.1 | ER16: 0 | ES16: 0 | ET16: 0 | EU16: 0.6 | EV16: 99.7 | EW16: 108.9 | EX16: 0 | EY16: 0 | EZ16: 5.4 | FA16: 19.2 | FB16: 9.5 | FC16: 42.8 | FD16: 14.7 | FE16: 17.8 | FG16: 7.7 | FJ16: 6048.7 | FL16: 24.4 | FM16: 7.939 | FO16: 12 | FP16: 27.21647 | FQ16: 18.91675 | FR16: 4.6 | FS16: 15.9 | FT16: 110.97222
A17: 19/06/2025 | B17: 03:30 | C17: 53.6 | D17: 603.6 | E17: 202.4 | H17: 91 | I17: 108.8 | J17: 26.5 | L17: 126.1 | M17: 126 | N17: 125.8 | O17: 225.8 | R17: 309.6 | S17: 5 | X17: 165.3 | Y17: 7.5 | Z17: 5.5 | AA17: 0 | AB17: 6.09 | AC17: 8.64 | AD17: 50.48 | AH17: 0 | AI17: 70.7 | AJ17: 0 | AN17: 6.5 | AO17: 457.1 | AP17: 72.4 | AQ17: 146.3 | AR17: 42.1 | AS17: 18.8 | AT17: 19.8 | AU17: 91.4 | AV17: 183.2 | AW17: 183.7 | AX17: 183 | AY17: 109.9 | AZ17: 8.1 | BA17: 2.7 | BB17: 31.8 | BC17: 44.6 | BD17: 4 | BE17: 0 | BF17: 95.9 | BI17: 48.3 | BL17: 0 | BP17: 87 | BQ17: 157.1 | BR17: 0 | BS17: 0 | BT17: 68.1 | BY17: 0 | CB17: 0 | CC17: 1.8 | CD17: 58.6 | CE17: 113.3 | CF17: 62.4 | CG17: 73.8 | CH17: 30.2 | CL17: 102.6 | CM17: 102.4 | CN17: 121.2 | CV17: 0 | CW17: 104.3 | CX17: 0 | CY17: 13.2 | CZ17: 0 | DA17: 17.8 | DB17: 9.9 | DC17: 5.5 | DD17: 0.7 | DE17: 1.6 | DF17: 2.6 | DG17: 20.4 | DH17: 20 | DI17: 15.5 | DJ17: 3.5 | DK17: 18.4 | DL17: 0 | DM17: 0 | DN17: 31.7 | DO17: 82.8 | DP17: 4.5 | DQ17: 2.2 | DR17: 2.1 | DS17: 1.4 | DT17: 0 | DU17: 3 | DV17: 13 | DW17: 2.2 | DY17: 19.7 | DZ17: 5.8 | EA17: 10 | EB17: 13.7 | EC17: 17.9 | ED17: 16.4 | EE17: 15 | EF17: 0 | EG17: 104 | EH17: 90.1 | EI17: 13.8 | EJ17: 9.8 | EK17: 16.5 | EL17: 6 | EN17: 8.2 | EO17: 9 | EP17: 9.5 | EQ17: 13.5 | ER17: 0 | ES17: 0 | ET17: 0 | EU17: 0.6 | EV17: 103.7 | EW17: 136.6 | EX17: 0 | EY17: 0 | EZ17: 5.4 | FA17: 19.2 | FB17: 9.8 | FC17: 43 | FD17: 14.7 | FE17: 17.8 | FG17: 7.2 | FJ17: 6159.71 | FL17: 24.4 | FM17: 7.937 | FO17: 12 | FP17: 27.29215 | FQ17: 18.91647 | FR17: 4.6 | FS17: 15.9 | FT17: 111.04562
A18: 19/06/2025 | B18: 04:00 | C18: 53.2 | D18: 605.3 | E18: 202.4 | H18: 90.5 | I18: 116.4 | J18: 26.6 | L18: 113.2 | M18: 113.6 | N18: 112.5 | O18: 212 | R18: 310.8 | S18: 5 | X18: 166.3 | Y18: 7.5 | Z18: 5.5 | AA18: 0 | AB18: 6.1 | AC18: 8.64 | AD18: 50.45 | AH18: 0 | AI18: 70.9 | AJ18: 0 | AN18: 6.5 | AO18: 460 | AP18: 72 | AQ18: 140.7 | AR18: 42.2 | AS18: 18.8 | AT18: 19.8 | AU18: 90.1 | AV18: 182.9 | AW18: 183.7 | AX18: 183.7 | AY18: 109.6 | AZ18: 8 | BA18: 2.7 | BB18: 27.2 | BC18: 43.5 | BD18: 4 | BE18: 0 | BF18: 65 | BI18: 48.4 | BL18: 0 | BP18: 87.1 | BQ18: 158.1 | BR18: 0 | BS18: 0 | BT18: 68.4 | BY18: 0 | CB18: 0 | CC18: 1.8 | CD18: 70.5 | CE18: 108.5 | CF18: 62.6 | CG18: 74 | CH18: 30.3 | CL18: 103.5 | CM18: 103 | CN18: 122 | CV18: 0 | CW18: 111.8 | CX18: 0 | CY18: 16.9 | CZ18: 0 | DA18: 17.8 | DB18: 9.9 | DC18: 5.6 | DD18: 0.7 | DE18: 1.6 | DF18: 2.6 | DG18: 20.3 | DH18: 20 | DI18: 13.4 | DJ18: 3.5 | DK18: 18.4 | DL18: 0 | DM18: 0 | DN18: 31.7 | DO18: 84.9 | DP18: 4.5 | DQ18: 2.2 | DR18: 2.1 | DS18: 1.4 | DT18: 0 | DU18: 3 | DV18: 13 | DW18: 2.1 | DY18: 19.7 | DZ18: 5.8 | EA18: 10.2 | EB18: 13.7 | EC18: 17.8 | ED18: 18.9 | EE18: 9.9 | EF18: 0 | EG18: 101.9 | EH18: 95.5 | EI18: 19 | EJ18: 8.9 | EK18: 16.5 | EL18: 5.9 | EN18: 8 | EO18: 8.5 | EP18: 9 | EQ18: 14.5 | ER18: 0 | ES18: 0 | ET18: 0 | EU18: 0.6 | EV18: 121.5 | EW18: 130.6 | EX18: 0 | EY18: 0 | EZ18: 5.5 | FA18: 19.2 | FB18: 9.7 | FC18: 43 | FD18: 14.6 | FE18: 17.4 | FG18: 8.1 | FJ18: 6116.79 | FL18: 24.5 | FM18: 7.94 | FO18: 12 | FP18: 27.25449 | FQ18: 18.91668 | FR18: 4.6 | FS18: 16.2 | FT18: 111.41117
A19: 19/06/2025 | B19: 04:30 | C19: 50.9 | D19: 605.3 | E19: 202.7 | H19: 91 | I19: 116.9 | J19: 24.7 | L19: 117.6 | M19: 116.1 | N19: 116.5 | O19: 209.3 | R19: 311.9 | S19: 5.1 | X19: 162.6 | Y19: 7.5 | Z19: 5.4 | AA19: 0 | AB19: 6.08 | AC19: 8.73 | AD19: 51.31 | AH19: 0 | AI19: 70.6 | AJ19: 0 | AN19: 6.5 | AO19: 458.4 | AP19: 72 | AQ19: 150 | AR19: 42 | AS19: 18.8 | AT19: 19.8 | AU19: 90.2 | AV19: 181.7 | AW19: 184 | AX19: 183.1 | AY19: 109.8 | AZ19: 8.1 | BA19: 2.7 | BB19: 34.2 | BC19: 43.4 | BD19: 4 | BE19: 0 | BF19: 83.2 | BI19: 48.2 | BL19: 0 | BP19: 87.4 | BQ19: 156.9 | BR19: 0 | BS19: 0 | BT19: 69 | BY19: 0 | CB19: 0 | CC19: 1.8 | CD19: 115.4 | CE19: 117.2 | CF19: 64.7 | CG19: 75.9 | CH19: 30.1 | CL19: 101.9 | CM19: 101.9 | CN19: 120.7 | CV19: 0 | CW19: 115.5 | CX19: 0 | CY19: 16.6 | CZ19: 0 | DA19: 17.7 | DB19: 9.9 | DC19: 5.4 | DD19: 0.7 | DE19: 1.6 | DF19: 2.6 | DG19: 20.3 | DH19: 20 | DI19: 13.5 | DJ19: 3.5 | DK19: 18.4 | DL19: 0 | DM19: 0 | DN19: 31.8 | DO19: 85.6 | DP19: 4.5 | DQ19: 2.2 | DR19: 2.1 | DS19: 1.4 | DT19: 0 | DU19: 3.2 | DV19: 13 | DW19: 2.1 | DY19: 19.7 | DZ19: 5.7 | EA19: 10.2 | EB19: 13.8 | EC19: 17.8 | ED19: 18.5 | EE19: 5.4 | EF19: 0 | EG19: 100 | EH19: 94.3 | EI19: 15.8 | EJ19: 6.8 | EK19: 16.5 | EL19: 5.8 | EN19: 8 | EO19: 8.5 | EP19: 8.7 | EQ19: 13.8 | ER19: 0 | ES19: 0 | ET19: 0 | EU19: 0.6 | EV19: 97.7 | EW19: 104.6 | EX19: 0 | EY19: 0 | EZ19: 5.6 | FA19: 19.2 | FB19: 9.7 | FC19: 43.3 | FD19: 14.7 | FE19: 17.7 | FG19: 7.9 | FJ19: 6145.12 | FL19: 24.4 | FM19: 7.939 | FO19: 12 | FP19: 27.26415 | FQ19: 18.91644 | FR19: 4.5 | FS19: 16 | FT19: 111.01959
A20: 19/06/2025 | B20: 05:00 | C20: 44.5 | D20: 603 | E20: 202.1 | H20: 89.6 | I20: 115.8 | J20: 25.9 | L20: 116.9 | M20: 117.2 | N20: 115.8 | O20: 211.3 | R20: 313.1 | S20: 5 | X20: 160.9 | Y20: 7.1 | Z20: 5.1 | AA20: 0 | AB20: 6.13 | AC20: 8.73 | AD20: 50.31 | AH20: 0 | AI20: 69.9 | AJ20: 1.3 | AN20: 6.5 | AO20: 455.2 | AP20: 72 | AQ20: 148.3 | AR20: 42 | AS20: 18.6 | AT20: 19.8 | AU20: 90 | AV20: 181.6 | AW20: 181 | AX20: 183.5 | AY20: 109.5 | AZ20: 8.1 | BA20: 2.8 | BB20: 32.9 | BC20: 43.7 | BD20: 4 | BE20: 0 | BF20: 85.4 | BI20: 47.9 | BL20: 0 | BP20: 86.5 | BQ20: 157.6 | BR20: 0 | BS20: 0 | BT20: 68.1 | BY20: 0 | CB20: 0 | CC20: 1.8 | CD20: 110.6 | CE20: 112.2 | CF20: 64 | CG20: 76.8 | CH20: 29.9 | CL20: 102.8 | CM20: 102.6 | CN20: 121.6 | CV20: 0 | CW20: 114.5 | CX20: 0 | CY20: 17.8 | CZ20: 0 | DA20: 17.3 | DB20: 9.9 | DC20: 5.5 | DD20: 0.7 | DE20: 1.6 | DF20: 2.6 | DG20: 20.1 | DH20: 20 | DI20: 13.5 | DJ20: 3.5 | DK20: 18.4 | DL20: 0 | DM20: 0 | DN20: 31.7 | DO20: 85.9 | DP20: 4.5 | DQ20: 2.2 | DR20: 2.1 | DS20: 1.4 | DT20: 0 | DU20: 3.2 | DV20: 13 | DW20: 2 | DY20: 19.7 | DZ20: 5.2 | EA20: 10 | EB20: 13.9 | EC20: 17.8 | ED20: 18.2 | EE20: 5 | EF20: 0 | EG20: 100.3 | EH20: 93.3 | EI20: 17.5 | EJ20: 7.6 | EK20: 16.5 | EL20: 5.7 | EN20: 7.5 | EO20: 8.5 | EP20: 8.7 | EQ20: 15.7 | ER20: 0 | ES20: 0 | ET20: 0 | EU20: 0.6 | EV20: 103.5 | EW20: 128.4 | EX20: 0 | EY20: 0 | EZ20: 5.5 | FA20: 19.2 | FB20: 9.7 | FC20: 42.9 | FD20: 14.8 | FE20: 17.8 | FG20: 8.3 | FJ20: 6150.17 | FL20: 24.5 | FM20: 7.937 | FO20: 12 | FP20: 27.33902 | FQ20: 18.91628 | FR20: 4.4 | FS20: 16.1 | FT20: 111.1923
A21: 19/06/2025 | B21: 05:30 | C21: 49.8 | D21: 601.4 | E21: 202.8 | H21: 90.5 | I21: 118.9 | J21: 26 | L21: 119.5 | M21: 119.4 | N21: 119.2 | O21: 224.4 | R21: 305.4 | S21: 5 | X21: 165.9 | Y21: 7.3 | Z21: 5.2 | AA21: 0 | AB21: 6.15 | AC21: 8.81 | AD21: 50.3 | AH21: 0 | AI21: 70.2 | AJ21: 62.1 | AN21: 6.5 | AO21: 455.9 | AP21: 72.7 | AQ21: 150 | AR21: 42 | AS21: 18.8 | AT21: 19.8 | AU21: 89.3 | AV21: 182.2 | AW21: 183.1 | AX21: 182.6 | AY21: 109.4 | AZ21: 8.1 | BA21: 2.7 | BB21: 34.6 | BC21: 44.3 | BD21: 4 | BE21: 0 | BF21: 83.4 | BI21: 48.1 | BL21: 0 | BP21: 86.8 | BQ21: 157.2 | BR21: 0 | BS21: 0 | BT21: 68.7 | BY21: 0 | CB21: 0 | CC21: 1.8 | CD21: 134.5 | CE21: 102.5 | CF21: 64.2 | CG21: 76.8 | CH21: 30.1 | CL21: 102.3 | CM21: 102.2 | CN21: 120.9 | CV21: 0 | CW21: 94.7 | CX21: 0 | CY21: 17.6 | CZ21: 0 | DA21: 17 | DB21: 9.9 | DC21: 5.5 | DD21: 0.7 | DE21: 1.5 | DF21: 2.6 | DG21: 20.2 | DH21: 20 | DI21: 13.5 | DJ21: 3.5 | DK21: 18.4 | DL21: 0 | DM21: 0 | DN21: 31.9 | DO21: 85.2 | DP21: 4.5 | DQ21: 2.2 | DR21: 2.1 | DS21: 1.4 | DT21: 0 | DU21: 3.2 | DV21: 13.1 | DW21: 2 | DY21: 19.7 | DZ21: 5 | EA21: 10 | EB21: 13.7 | EC21: 18 | ED21: 22.7 | EE21: 5.6 | EF21: 0 | EG21: 87.4 | EH21: 77.1 | EI21: 13.5 | EJ21: 9 | EK21: 16.5 | EL21: 5.6 | EN21: 7.5 | EO21: 8.5 | EP21: 8.7 | EQ21: 15.9 | ER21: 0 | ES21: 0 | ET21: 0 | EU21: 0.6 | EV21: 109.9 | EW21: 133.2 | EX21: 0 | EY21: 0 | EZ21: 5.5 | FA21: 19.2 | FB21: 9 | FC21: 42.8 | FD21: 14.7 | FE21: 17 | FG21: 8.4 | FJ21: 6219.16 | FL21: 24.4 | FM21: 7.939 | FO21: 12 | FP21: 27.35864 | FQ21: 18.91623 | FR21: 4.3 | FS21: 16 | FT21: 110.91387
A22: 19/06/2025 | B22: 06:00 | C22: 47.7 | D22: 602.2 | E22: 200.2 | H22: 90 | I22: 116 | J22: 25.4 | L22: 137.1 | M22: 136.8 | N22: 136.2 | O22: 241.6 | R22: 471.8 | S22: 5 | X22: 164.1 | Y22: 6.9 | Z22: 5.3 | AA22: 0 | AB22: 6.13 | AC22: 8.81 | AD22: 50.04 | AH22: 0 | AI22: 69.9 | AJ22: 82.1 | AN22: 6.5 | AO22: 458.5 | AP22: 72.3 | AQ22: 149.6 | AR22: 42.1 | AS22: 18.8 | AT22: 19.8 | AU22: 91.2 | AV22: 180.9 | AW22: 181.7 | AX22: 182.6 | AY22: 109.2 | AZ22: 8.1 | BA22: 2.7 | BB22: 34.1 | BC22: 43.9 | BD22: 4 | BE22: 0 | BF22: 57.8 | BI22: 48.1 | BL22: 0 | BP22: 86.7 | BQ22: 157.7 | BR22: 0 | BS22: 0 | BT22: 69.4 | BY22: 0 | CB22: 0 | CC22: 1.8 | CD22: 87.7 | CE22: 104.3 | CF22: 64.1 | CG22: 76.9 | CH22: 29.9 | CL22: 145 | CM22: 146.2 | CN22: 145.9 | CV22: 0 | CW22: 100.4 | CX22: 0 | CY22: 16.6 | CZ22: 0 | DA22: 16.9 | DB22: 9.9 | DC22: 5.6 | DD22: 0.7 | DE22: 1.5 | DF22: 2.6 | DG22: 20.1 | DH22: 20 | DI22: 13.6 | DJ22: 3.4 | DK22: 18.4 | DL22: 0.1 | DM22: 0 | DN22: 31.2 | DO22: 79.9 | DP22: 4.5 | DQ22: 2.2 | DR22: 2.1 | DS22: 1.4 | DT22: 0 | DU22: 3.2 | DV22: 13.2 | DW22: 2.1 | DY22: 19.7 | DZ22: 5 | EA22: 9.9 | EB22: 14 | EC22: 18 | ED22: 20 | EE22: 11 | EF22: 0 | EG22: 79.5 | EH22: 63.7 | EI22: 16.7 | EJ22: 7.8 | EK22: 16.5 | EL22: 5.5 | EN22: 7.5 | EO22: 8.5 | EP22: 8.7 | EQ22: 15.2 | ER22: 0 | ES22: 0 | ET22: 0 | EU22: 0.6 | EV22: 99.7 | EW22: 107.3 | EX22: 0 | EY22: 0 | EZ22: 5.5 | FA22: 19.3 | FB22: 9.8 | FC22: 42.9 | FD22: 15.8 | FE22: 17.1 | FG22: 8.7 | FJ22: 6454.28 | FL22: 24.4 | FM22: 7.944 | FO22: 12 | FP22: 27.33817 | FQ22: 18.91569 | FR22: 4.3 | FS22: 16.1 | FT22: 110.99786
... A58: 20/06/2025 | B58: 00:00 | C58: 51.1 | D58: 605.6 | E58: 202.5 | H58: 91.8 | I58: 114.9 | J58: 0 | L58: 186.9 | M58: 205.9 | N58: 208 | O58: 290.5 | R58: 447.4 | S58: 5.1 | X58: 166.9 | Y58: 7.5 | Z58: 5.3 | AA58: 22.1 | AB58: 6.89 | AC58: 14.27 | AD58: 93.84 | AH58: 0 | AI58: 61.4 | AJ58: 29.5 | AN58: 6.5 | AO58: 298.6 | AP58: 60 | AQ58: 125.3 | AR58: 38.8 | AS58: 18.8 | AT58: 19.8 | AU58: 91 | AV58: 182.6 | AW58: 184.4 | AX58: 183.4 | AY58: 110.6 | AZ58: 8.1 | BA58: 1.8 | BB58: 20.5 | BC58: 40 | BD58: 4 | BE58: 0 | BF58: 72 | BI58: 48.3 | BL58: 47.2 | BP58: 87.3 | BQ58: 176.8 | BR58: 174.5 | BS58: 200 | BT58: 174.9 | BY58: 0 | CB58: 0 | CC58: 1.8 | CD58: 70.4 | CE58: 83.1 | CF58: 65.3 | CG58: 73.3 | CH58: 30.4 | CL58: 145.9 | CM58: 147 | CN58: 149.4 | CV58: 0 | CW58: 52.8 | CX58: 0 | CY58: 10.9 | CZ58: 0 | DA58: 15.9 | DB58: 10 | DC58: 5.5 | DD58: 0.6 | DE58: 1.5 | DF58: 2.6 | DG58: 20.4 | DH58: 20 | DI58: 13.6 | DJ58: 3.5 | DK58: 18.4 | DL58: 0 | DM58: 0 | DN58: 18.5 | DO58: 34.1 | DP58: 4.5 | DQ58: 1.2 | DR58: 2.2 | DS58: 2.9 | DT58: 0 | DU58: 2.9 | DV58: 13.5 | DW58: 2 | DY58: 17.2 | DZ58: 4.7 | EA58: 8.5 | EB58: 11.5 | EC58: 17.3 | ED58: 29.7 | EE58: 8.5 | EF58: 0 | EG58: 3.2 | EH58: 8.8 | EI58: 0.4 | EJ58: 0 | EK58: 16.5 | EL58: 5.1 | EN58: 7.2 | EO58: 8 | EP58: 8.2 | EQ58: 7.6 | ER58: 0 | ES58: 0 | ET58: 0 | EU58: 0.6 | EV58: 17.5 | EW58: 13.7 | EX58: 0 | EY58: 0 | EZ58: 5.5 | FA58: 19 | FB58: 9.7 | FC58: 43.2 | FD58: 17.6 | FE58: 17.6 | FG58: 7.8 | FJ58: 6531.3 | FL58: 24.4 | FM58: 7.788 | FO58: 11.6 | FP58: 27.21171 | FQ58: 18.91574 | FR58: 4.5 | FS58: 16 | FT58: 110.41545
A59: EJEC | C59: 2695.5 | D59: 14475.6 | E59: 4850 | F59: 0 | G59: 0 | H59: 2162.65 | I59: 3560.75 | J59: 403.85 | K59: 0 | L59: 3820.6 | M59: 3887.25 | N59: 3897.1 | O59: 6102.5 | P59: 0 | Q59: 0 | R59: 10716.25 | S59: 119.25 | T59: 0 | U59: 0 | V59: 0 | W59: 0 | X59: 3908.05 | Y59: 173.9 | Z59: 127.7 | AA59: 297.85 | AB59: 154.29 | AC59: 255.51 | AD59: 1666.04 | AE59: 0 | AF59: 0 | AG59: 0 | AH59: 3.625 | AI59: 1893 | AJ59: 3009.85 | AK59: 0 | AL59: 0 | AM59: 0 | AN59: 156 | AO59: 8995.2 | AP59: 1619.7 | AQ59: 2969.55 | AR59: 976.7 | AS59: 450.15 | AT59: 475.2 | AU59: 2142.25 | AV59: 4368.45 | AW59: 4375.8 | AX59: 4406.3 | AY59: 2620.8 | AZ59: 194.5 | BA59: 59.9 | BB59: 738.2 | BC59: 1008.15 | BD59: 96 | BE59: 193.85 | BF59: 2271.05 | BG59: 0 | BH59: 0 | BI59: 970 | BJ59: 0 | BK59: 0 | BL59: 759.1 | BM59: 0 | BN59: 0 | BO59: 0 | BP59: 2080.8 | BQ59: 4032.75 | BR59: 2275 | BS59: 489 | BT59: 3008.6 | BU59: 0 | BV59: 0 | BW59: 0 | BX59: 0 | BY59: 455.6 | BZ59: 0 | CA59: 0 | CB59: 199.3 | CC59: 42.15 | CD59: 2670.65 | CE59: 2385.6 | CF59: 1528.25 | CG59: 1767.55 | CH59: 720.15 | CI59: 0 | CJ59: 0 | CK59: 0 | CL59: 3300.05 | CM59: 3321.45 | CN59: 3450.75 | CO59: 0 | CP59: 0 | CQ59: 0 | CR59: 0 | CS59: 0 | CT59: 0 | CU59: 0 | CV59: 7.95 | CW59: 1971.75 | CX59: 564.25 | CY59: 370.75 | CZ59: 1.45 | DA59: 400.95 | DB59: 238.35 | DC59: 132.3 | DD59: 15.2 | DE59: 36.35 | DF59: 62.4 | DG59: 485.85 | DH59: 480 | DI59: 338.3 | DJ59: 82.3 | DK59: 441.6 | DL59: 116.6 | DM59: 138.7 | DN59: 631.25 | DO59: 1691.7 | DP59: 108 | DQ59: 36.8 | DR59: 52.5 | DS59: 27.45 | DT59: 99.15 | DU59: 73.9 | DV59: 278.55 | DW59: 49.1 | DX59: 0 | DY59: 454.95 | DZ59: 113.9 | EA59: 220.9 | EB59: 316.2 | EC59: 425.9 | ED59: 520.95 | EE59: 239.25 | EF59: 240.4 | EG59: 1558.65 | EH59: 1721.45 | EI59: 238.05 | EJ59: 152.75 | EK59: 395.8 | EL59: 124.35 | EM59: 0 | EN59: 186.5 | EO59: 202 | EP59: 207.2 | EQ59: 315.15 | ER59: 1845.35 | ES59: 117.05 | ET59: 1019.85 | EU59: 14.4 | EV59: 1958.15 | EW59: 1923.7 | EX59: 757.7 | EY59: 113.15 | EZ59: 132.35 | FA59: 459.45 | FB59: 229.7 | FC59: 1034.2 | FD59: 386.95 | FE59: 413 | FF59: 0 | FG59: 180.45 | FH59: 0 | FI59: 0 | FJ59: 166908.86 | FL59: 578.45 | FM59: 183.572 | FN59: 0 | FO59: 277.1 | FP59: 648.20629 | FQ59: 410.3 | FR59: 99.6 | FS59: 385.3 | FT59: 2582.5283

Sheet REACTIVA
B3: jueves, 19 de Junio del 2025
A5: POTENCIA REACTIVA EJECUTADA DE LAS UNIDADES DE GENERACIÓN DEL COES (MVAR) | FK5: CENTRALES NO INTEGRANTES COES
A6: FECHA | B6: HORA | C6: 65333 | D6: 101 | E6: 102 | F6: 42667 | G6: 42668 | H6: 126 | I6: 127 | J6: 138 | K6: 139 | L6: 197 | M6: 203 | N6: 204 | O6: 230 | P6: 209 | Q6: 56677 | R6: 796 | S6: 2146 | T6: 142 | U6: 143 | V6: 125 | W6: 187 | X6: 163 | Y6: 298 | Z6: 219 | AA6: 151 | AB6: 152 | AC6: 153 | AD6: 154 | AE6: 756 | AF6: 156 | AG6: 155 | AH6: 182 | AI6: 212 | AJ6: 758 | AK6: 263 | AL6: 265 | AM6: 775 | AN6: 777 | AO6: 2154 | AP6: 150 | AQ6: 149 | AR6: 188 | AS6: 2131 | AT6: 755 | AU6: 252 | AV6: 249 | AW6: 250 | AX6: 117 | AY6: 267 | AZ6: 268 | BA6: 119 | BB6: 120 | BC6: 189 | BD6: 122 | BE6: 266 | BF6: 337 | BG6: 338 | BH6: 251 | BI6: 115 | BJ6: 239 | BK6: 288 | BL6: 240 | BM6: 241 | BN6: 242 | BO6: 191 | BP6: 194 | BQ6: 196 | BR6: 207 | BS6: 236 | BT6: 795 | BU6: 285 | BV6: 995 | BW6: 996 | BX6: 997 | BY6: 766 | BZ6: 926 | CA6: 924 | CB6: 121 | CC6: 103 | CD6: 104 | CE6: 106 | CF6: 105 | CG6: 107 | CH6: 110 | CI6: 109 | CJ6: 144 | CK6: 113 | CL6: 114 | CM6: 193 | CN6: 208 | CO6: 786 | CP6: 787 | CQ6: 788 | CR6: 789 | CS6: 248 | CT6: 2159 | CU6: 303 | CV6: 59715 | CW6: 62255 | CX6: 1263 | CY6: 61800 | CZ6: 2194 | DA6: 216 | DB6: 198 | DC6: 49607 | DD6: 214 | DE6: 260 | DF6: 2152 | DG6: 2128 | DH6: 247 | DI6: 228 | DJ6: 2135 | DK6: 261 | DL6: 237 | DM6: 253 | DN6: 770 | DO6: 225 | DP6: 2201 | DQ6: 2171 | DR6: 760 | DS6: 235 | DT6: 238 | DU6: 2184 | DV6: 61855 | DW6: 223 | DX6: 226 | DY6: 201 | DZ6: 258 | EA6: 259 | EB6: 920 | EC6: 257 | ED6: 256 | EE6: 2148 | EF6: 58288 | EG6: 58289 | EH6: 58839 | EI6: 58840 | EJ6: 296 | EK6: 297 | EL6: 211 | EM6: 2175 | EN6: 2178 | EO6: 2181 | EP6: 1262 | EQ6: 63425 | ER6: 233 | ES6: 2150 | ET6: 2165 | EU6: 2161 | EV6: 61197 | EW6: 58851 | EX6: 234 | EY6: 215 | EZ6: 917 | FA6: 289 | FB6: 58333 | FC6: 58336 | FD6: 213 | FE6: 232 | FF6: 2190 | FG6: 202 | FH6: 58487 | FI6: TOTAL COES | FK6: 221 | FL6: 222 | FM6: 224 | FN6: 2187 | FO6: 227 | FP6: 49400 | FQ6: 199 | FR6: 200 | FS6: TOTAL NO COES
C7: SUR | D7: CENTRO | E7: CENTRO | F7: NORTE | G7: NORTE | H7: NORTE | I7: NORTE | J7: CENTRO | K7: CENTRO | L7: CENTRO | M7: CENTRO | N7: CENTRO | O7: CENTRO | P7: CENTRO | Q7: CENTRO | R7: CENTRO | S7: CENTRO | T7: CENTRO | U7: CENTRO | V7: CENTRO | W7: CENTRO | X7: SUR | Y7: SUR | Z7: CENTRO | AA7: SUR | AB7: SUR | AC7: SUR | AD7: SUR | AE7: SUR | AF7: SUR | AG7: SUR | AH7: SUR | AI7: CENTRO | AJ7: NORTE | AK7: NORTE | AL7: NORTE | AM7: CENTRO | AN7: CENTRO | AO7: CENTRO | AP7: CENTRO | AQ7: CENTRO | AR7: CENTRO | AS7: CENTRO | AT7: SUR | AU7: CENTRO | AV7: CENTRO | AW7: CENTRO | AX7: CENTRO | AY7: CENTRO | AZ7: CENTRO | BA7: CENTRO | BB7: CENTRO | BC7: SUR | BD7: NORTE | BE7: CENTRO | BF7: CENTRO | BG7: CENTRO | BH7: CENTRO | BI7: NORTE | BJ7: NORTE | BK7: NORTE | BL7: SUR | BM7: SUR | BN7: SUR | BO7: CENTRO | BP7: CENTRO | BQ7: CENTRO | BR7: CENTRO | BS7: CENTRO | BT7: CENTRO | BU7: CENTRO | BV7: SUR | BW7: SUR | BX7: SUR | BY7: NORTE | BZ7: SUR | CA7: CENTRO | CB7: NORTE | CC7: CENTRO | CD7: CENTRO | CE7: CENTRO | CF7: CENTRO | CG7: CENTRO | CH7: CENTRO | CI7: CENTRO | CJ7: CENTRO | CK7: CENTRO | CL7: CENTRO | CM7: CENTRO | CN7: CENTRO | CO7: SUR | CP7: SUR | CQ7: SUR | CR7: SUR | CS7: CENTRO | CT7: CENTRO | CU7: CENTRO | CV7: CENTRO | CW7: SUR | CX7: NORTE | CY7: NORTE | CZ7: NORTE | DA7: NORTE | DB7: NORTE | DC7: SUR | DD7: CENTRO | DE7: CENTRO | DF7: CENTRO | DG7: NORTE | DH7: NORTE | DI7: CENTRO | DJ7: CENTRO | DK7: SUR | DL7: SUR | DM7: CENTRO | DN7: CENTRO | DO7: CENTRO | DP7: CENTRO | DQ7: CENTRO | DR7: CENTRO | DS7: SUR | DT7: CENTRO | DU7: CENTRO | DV7: NORTE | DW7: CENTRO | DX7: CENTRO | DY7: NORTE | DZ7: CENTRO | EA7: CENTRO | EB7: CENTRO | EC7: NORTE | ED7: NORTE | EE7: SUR | EF7: CENTRO | EG7: CENTRO | EH7: CENTRO | EI7: CENTRO | EJ7: CENTRO | EK7: CENTRO | EL7: SUR | EM7: SUR | EN7: SUR | EO7: SUR | EP7: NORTE | EQ7: SUR | ER7: SUR | ES7: SUR | ET7: CENTRO | EU7: CENTRO | EV7: CENTRO | EW7: SUR | EX7: SUR | EY7: NORTE | EZ7: CENTRO | FA7: NORTE | FB7: NORTE | FC7: NORTE | FD7: CENTRO | FE7: NORTE | FF7: NORTE | FG7: CENTRO | FH7: CENTRO | FK7: NORTE | FL7: CENTRO | FM7: NORTE | FN7: NORTE | FO7: NORTE | FP7: NORTE | FQ7: NORTE | FR7: NORTE
C8: HIDROELÉCTRICA | D8: HIDROELÉCTRICA | E8: HIDROELÉCTRICA | F8: TERMOELÉCTRICA | G8: TERMOELÉCTRICA | H8: HIDROELÉCTRICA | I8: HIDROELÉCTRICA | J8: TERMOELÉCTRICA | K8: TERMOELÉCTRICA | L8: TERMOELÉCTRICA | M8: TERMOELÉCTRICA | N8: TERMOELÉCTRICA | O8: TERMOELÉCTRICA | P8: TERMOELÉCTRICA | Q8: TERMOELÉCTRICA | R8: HIDROELÉCTRICA | S8: HIDROELÉCTRICA | T8: TERMOELÉCTRICA | U8: TERMOELÉCTRICA | V8: TERMOELÉCTRICA | W8: TERMOELÉCTRICA | X8: HIDROELÉCTRICA | Y8: HIDROELÉCTRICA | Z8: TERMOELÉCTRICA | AA8: HIDROELÉCTRICA | AB8: HIDROELÉCTRICA | AC8: HIDROELÉCTRICA | AD8: HIDROELÉCTRICA | AE8: TERMOELÉCTRICA | AF8: TERMOELÉCTRICA | AG8: TERMOELÉCTRICA | AH8: HIDROELÉCTRICA | AI8: HIDROELÉCTRICA | AJ8: TERMOELÉCTRICA | AK8: TERMOELÉCTRICA | AL8: TERMOELÉCTRICA | AM8: HIDROELÉCTRICA | AN8: HIDROELÉCTRICA | AO8: HIDROELÉCTRICA | AP8: HIDROELÉCTRICA | AQ8: HIDROELÉCTRICA | AR8: HIDROELÉCTRICA | AS8: HIDROELÉCTRICA | AT8: HIDROELÉCTRICA | AU8: TERMOELÉCTRICA | AV8: TERMOELÉCTRICA | AW8: TERMOELÉCTRICA | AX8: HIDROELÉCTRICA | AY8: HIDROELÉCTRICA | AZ8: HIDROELÉCTRICA | BA8: HIDROELÉCTRICA | BB8: HIDROELÉCTRICA | BC8: HIDROELÉCTRICA | BD8: HIDROELÉCTRICA | BE8: HIDROELÉCTRICA | BF8: HIDROELÉCTRICA | BG8: HIDROELÉCTRICA | BH8: HIDROELÉCTRICA | BI8: TERMOELÉCTRICA | BJ8: TERMOELÉCTRICA | BK8: TERMOELÉCTRICA | BL8: TERMOELÉCTRICA | BM8: TERMOELÉCTRICA | BN8: TERMOELÉCTRICA | BO8: HIDROELÉCTRICA | BP8: TERMOELÉCTRICA | BQ8: TERMOELÉCTRICA | BR8: TERMOELÉCTRICA | BS8: TERMOELÉCTRICA | BT8: TERMOELÉCTRICA | BU8: TERMOELÉCTRICA | BV8: TERMOELÉCTRICA | BW8: TERMOELÉCTRICA | BX8: TERMOELÉCTRICA | BY8: HIDROELÉCTRICA | BZ8: TERMOELÉCTRICA | CA8: TERMOELÉCTRICA | CB8: HIDROELÉCTRICA | CC8: HIDROELÉCTRICA | CD8: HIDROELÉCTRICA | CE8: HIDROELÉCTRICA | CF8: HIDROELÉCTRICA | CG8: HIDROELÉCTRICA | CH8: TERMOELÉCTRICA | CI8: TERMOELÉCTRICA | CJ8: TERMOELÉCTRICA | CK8: TERMOELÉCTRICA | CL8: TERMOELÉCTRICA | CM8: TERMOELÉCTRICA | CN8: TERMOELÉCTRICA | CO8: TERMOELÉCTRICA | CP8: TERMOELÉCTRICA | CQ8: TERMOELÉCTRICA | CR8: TERMOELÉCTRICA | CS8: TERMOELÉCTRICA | CT8: TERMOELÉCTRICA | CU8: SOLAR | CV8: EÓLICA | CW8: SOLAR | CX8: EÓLICA | CY8: SOLAR | CZ8: HIDROELÉCTRICA | DA8: HIDROELÉCTRICA | DB8: HIDROELÉCTRICA | DC8: HIDROELÉCTRICA | DD8: HIDROELÉCTRICA | DE8: HIDROELÉCTRICA | DF8: HIDROELÉCTRICA | DG8: HIDROELÉCTRICA | DH8: HIDROELÉCTRICA | DI8: HIDROELÉCTRICA | DJ8: HIDROELÉCTRICA | DK8: SOLAR | DL8: SOLAR | DM8: EÓLICA | DN8: EÓLICA | DO8: TERMOELÉCTRICA | DP8: TERMOELÉCTRICA | DQ8: TERMOELÉCTRICA | DR8: TERMOELÉCTRICA | DS8: SOLAR | DT8: HIDROELÉCTRICA | DU8: HIDROELÉCTRICA | DV8: HIDROELÉCTRICA | DW8: HIDROELÉCTRICA | DX8: HIDROELÉCTRICA | DY8: HIDROELÉCTRICA | DZ8: HIDROELÉCTRICA | EA8: HIDROELÉCTRICA | EB8: HIDROELÉCTRICA | EC8: EÓLICA | ED8: EÓLICA | EE8: SOLAR | EF8: EÓLICA | EG8: EÓLICA | EH8: EÓLICA | EI8: EÓLICA | EJ8: HIDROELÉCTRICA | EK8: HIDROELÉCTRICA | EL8: HIDROELÉCTRICA | EM8: HIDROELÉCTRICA | EN8: HIDROELÉCTRICA | EO8: HIDROELÉCTRICA | EP8: EÓLICA | EQ8: SOLAR | ER8: SOLAR | ES8: SOLAR | ET8: HIDROELÉCTRICA | EU8: EÓLICA | EV8: EÓLICA | EW8: SOLAR | EX8: SOLAR | EY8: HIDROELÉCTRICA | EZ8: HIDROELÉCTRICA | FA8: TERMOELÉCTRICA | FB8: TERMOELÉCTRICA | FC8: TERMOELÉCTRICA | FD8: TERMOELÉCTRICA | FE8: TERMOELÉCTRICA | FF8: TERMOELÉCTRICA | FG8: TERMOELÉCTRICA | FH8: TERMOELÉCTRICA | FK8: HIDROELÉCTRICA | FL8: HIDROELÉCTRICA | FM8: HIDROELÉCTRICA | FN8: HIDROELÉCTRICA | FO8: TERMOELÉCTRICA | FP8: TERMOELÉCTRICA | FQ8: HIDROELÉCTRICA | FR8: HIDROELÉCTRICA
C9: HYDRO GLOBAL PERÚ S.A.C. | D9: ELECTROPERU | E9: ELECTROPERU | F9: ELECTROPERU | G9: ELECTROPERU | H9: ORAZUL ENERGY PERÚ | I9: ORAZUL ENERGY PERÚ | J9: TERMOSELVA | K9: TERMOSELVA | L9: KALLPA GENERACION S.A. | M9: KALLPA GENERACION S.A. | N9: KALLPA GENERACION S.A. | O9: KALLPA GENERACION S.A. | P9: KALLPA GENERACION S.A. | Q9: KALLPA GENERACION S.A. | R9: KALLPA GENERACION S.A. | S9: KALLPA GENERACION S.A. | T9: SHOUGESA | U9: SHOUGESA | V9: SHOUGESA | W9: SHOUGESA | X9: EGEMSA | Y9: EGESUR | Z9: EGESUR | AA9: EGASA | AB9: EGASA | AC9: EGASA | AD9: EGASA | AE9: EGASA | AF9: EGASA | AG9: EGASA | AH9: SAN GABAN | AI9: CELEPSA | AJ9: MINERA CERRO VERDE | AK9: PLANTA DE RESERVA FRIA DE GENERACION DE ETEN S.A. | AL9: PLANTA DE RESERVA FRIA DE GENERACION DE ETEN S.A. | AM9: EMPRESA DE GENERACION HUALLAGA | AN9: EMPRESA DE GENERACION HUALLAGA | AO9: LA VIRGEN | AP9: CHINANGO S.A.C. | AQ9: CHINANGO S.A.C. | AR9: HIDROELECTRICA HUANCHOR S.A.C. | AS9: CELEPSA RENOVABLES S.R.L. | AT9: INLAND ENERGY SAC | AU9: FENIX POWER PERÚ | AV9: FENIX POWER PERÚ | AW9: FENIX POWER PERÚ | AX9: STATKRAFT S.A | AY9: STATKRAFT S.A | AZ9: STATKRAFT S.A | BA9: STATKRAFT S.A | BB9: STATKRAFT S.A | BC9: STATKRAFT S.A | BD9: STATKRAFT S.A | BE9: STATKRAFT S.A | BF9: CENTRALES SANTA ROSA S.A.C. | BG9: CENTRALES SANTA ROSA S.A.C. | BH9: EMPRESA DE GENERACION HUANZA | BI9: ENEL GENERACION PIURA S.A. | BJ9: ENEL GENERACION PIURA S.A. | BK9: ENEL GENERACION PIURA S.A. | BL9: ENGIE | BM9: ENGIE | BN9: ENGIE | BO9: ENGIE | BP9: ENGIE | BQ9: ENGIE | BR9: ENGIE | BS9: ENGIE | BT9: ENGIE | BU9: ENGIE | BV9: ENGIE | BW9: ENGIE | BX9: ENGIE | BY9: ENGIE | BZ9: INFRAESTRUCTURAS Y ENERGIAS DEL PERU S.A.C. | CA9: INFRAESTRUCTURAS Y ENERGIAS DEL PERU S.A.C. | CB9: INVERSIONES SHAQSHA S.A.C. | CC9: ORYGEN PERU S.A.A. | CD9: ORYGEN PERU S.A.A. | CE9: ORYGEN PERU S.A.A. | CF9: ORYGEN PERU S.A.A. | CG9: ORYGEN PERU S.A.A. | CH9: ORYGEN PERU S.A.A. | CI9: ORYGEN PERU S.A.A. | CJ9: ORYGEN PERU S.A.A. | CK9: ORYGEN PERU S.A.A. | CL9: ORYGEN PERU S.A.A. | CM9: ORYGEN PERU S.A.A. | CN9: ORYGEN PERU S.A.A. | CO9: SAMAY I S.A.C | CP9: SAMAY I S.A.C | CQ9: SAMAY I S.A.C | CR9: SAMAY I S.A.C | CS9: TERMOCHILCA S.A.C. | CT9: TERMOCHILCA S.A.C. | CU9: COLCA SOLAR S.A.C. | CV9: ENERGIA RENOVABLE DEL SUR S.A. | CW9: GR CORTARRAMA SOCIEDAD ANONIMA CERRADA | CX9: GR TARUCA SOCIEDAD ANONIMA CERRADA | CY9: KONDU SAC | CZ9: PERUANA DE INVERSIONES EN ENERGIAS RENOVABLES S.A. | DA9: ORAZUL ENERGY PERÚ | DB9: ORAZUL ENERGY PERÚ | DC9: SAN GABAN | DD9: MAJA ENERGIA S.A.C. | DE9: EMPRESA DE GENERACION ELECTRICA CANCHAYLLO SAC | DF9: EMPRESA DE GENERACION ELECTRICA SANTA ANA S.A.C. | DG9: EMPRESA ELECTRICA AGUA AZUL | DH9: EMPRESA ELECTRICA RIO DOBLE | DI9: HIDROCAÑETE S.A. | DJ9: HUAURA POWER GROUP S.A. | DK9: MOQUEGUA FV S.A.C. | DL9: PANAMERICANA SOLAR SAC. | DM9: PARQUE EOLICO MARCONA S.A.C. | DN9: PARQUE EOLICO TRES HERMANAS S.A.C. | DO9: PETRAMAS | DP9: PETRAMAS | DQ9: PETRAMAS | DR9: PETRAMAS | DS9: TACNA SOLAR SAC. | DT9: ELECTRICA YANAPAMPA SAC | DU9: ANDEAN POWER S.A.C. | DV9: ASOCIACIÓN SANTA LUCIA DE CHACAS | DW9: ATRIA ENERGIA S.A.C. | DX9: EGEJUNIN | DY9: EGEJUNIN | DZ9: EGEJUNIN | EA9: EGEJUNIN | EB9: EMPRESA DE GENERACION ELECTRICA RIO BAÑOS S.A.C. | EC9: ENERGÍA EÓLICA S.A. | ED9: ENERGÍA EÓLICA S.A. | EE9: ENGIE | EF9: ENGIE | EG9: ENGIE | EH9: ENGIE | EI9: ENGIE | EJ9: GENERACIÓN ANDINA S.A.C. | EK9: GENERACIÓN ANDINA S.A.C. | EL9: GENERADORA DE ENERGÍA DEL PERÚ | EM9: GENERADORA DE ENERGÍA DEL PERÚ | EN9: GENERADORA DE ENERGÍA DEL PERÚ | EO9: GENERADORA DE ENERGÍA DEL PERÚ | EP9: GR PAINO SOCIEDAD ANONIMA CERRADA | EQ9: JOYA SOLAR S.A.C. | ER9: MAJES ARCUS S.A.C. | ES9: ORYGEN PERU S.A.A. | ET9: ORYGEN PERU S.A.A. | EU9: ORYGEN PERU S.A.A. | EV9: ORYGEN PERU S.A.A. | EW9: ORYGEN PERU S.A.A. | EX9: REPARTICIÓN ARCUS S.A.C. | EY9: SINERSA | EZ9: SINERSA | FA9: BIOENERGIA DEL CHIRA S.A. | FB9: GM OPERACIONES S.A.C. | FC9: GM OPERACIONES S.A.C. | FD9: AGRO INDUSTRIAL PARAMONGA S.A. | FE9: AGROAURORA S.A.C. | FF9: AGROINDUSTRIAS SAN JACINTO S.A.A. | FG9: SDF ENERGIA SAC | FH9: SDF ENERGIA SAC | FK9: UNACEM PERU S.A. | FL9: ELECTRO ORIENTE | FM9: AGUAS Y ENERGIA PERU | FN9: ELECTRO ZAÑA S.A.C. | FO9: ELECTRONOROESTE S.A. | FP9: SDE PIURA | FQ9: SINERSA | FR9: SINERSA
