Workbook

Sheet EVENTOS
B3: martes, 10 de Febrero del 2026
B5: INFORMACIÓN DE EVENTOS PRINCIPALES EN SUS INSTALACIONES
B6: TIPO DE EVENTO | C6: EMPRESA | D6: UBICACIÓN | E6: TIPO DE EQUIPO | F6: EQUIPO | G6: INICIO | H6: FINAL | I6: DESCRIPCIÓN | J6: MW INDISP. | K6: INTERRUPCIÓN (SI/NO) | L6: TENSIÓN DE FALLA (kV)
B7: FALLA | C7: ARUNTANI S.A.C. | D7: PUNO - TUCARI | E7: LINEA DE TRANSMISION | F7: L-6007 | G7: 10/02/2026 16:58:20 | H7: 10/02/2026 17:22:00 | I7: DESCONECTÓ LA LÍNEA L-6007 (PUNO – TUCARI) DE 60 KV POR FALLA | J7: 0.11 | K7: SI | L7: 60
B8: FALLA | C8: CELARIS ENERGY S.A. | D8: MANTA I | E8: GENERADOR HIDROELÉCTRICO | F8: G1 | G8: 10/02/2026 19:10:10 | H8: 10/02/2026 19:44:04 | I8: DESCONEXIÓN DEL GENERADOR G1 DE LA C.H. MANTA | K8: NO | L8: 6.3
B9: EVENTO | C9: CONELSUR LT SAC | D9: PORTILLO | E9: SUBESTACION | F9: SS.EE. | G9: 10/02/2026 07:53:00 | H9: 11/02/2026 00:00:00 | I9: DECLARACIÓN DE SITUACIÓN EXCEPCIONAL EN LA S.E. PORTILLO 60 kV | K9: NO
B10: FALLA | C10: ELECTRO DUNAS | D10: NAZCA - PUQUIO | E10: LINEA DE TRANSMISION | F10: L-6630/2 | G10: 10/02/2026 19:03:39 | H10: 10/02/2026 19:03:44 | I10: DESCONEXIÓN DE LA LÍNEA L-6630/2 (NAZCA – PUQUIO) DE 60 KV | K10: NO | L10: 60
B11: EVENTO | C11: ELECTRO ORIENTE | D11: BELAUNDE TERRY - TARAPOTO | E11: LINEA DE TRANSMISION | F11: L-1018 | G11: 10/02/2026 18:25:00 | H11: 10/02/2026 20:49:00 | I11: DECLARACIÓN DE SITUACIÓN EXCEPCIONAL EN LA LÍNEA L-1018 (BELAUNDE TERRY - TARAPOTO) DE 138 kV | K11: NO
B12: FALLA | C12: ELECTRO PUNO | D12: AZÁNGARO - ANTAUTA | E12: LINEA DE TRANSMISION | F12: L-6021 | G12: 10/02/2026 15:18:00 | H12: 10/02/2026 15:19:37 | I12: DESCONEXIÓN DE LA LINEA L-6021 (AZÁNGARO - ANTAUTA) DE 60 KV | J12: 1.85 | K12: SI | L12: 60
B13: EVENTO | C13: HIDRANDINA | D13: CARAZ - HUARAZ | E13: LINEA DE TRANSMISION | F13: L-6684 | G13: 10/02/2026 03:01:23 | H13: 10/02/2026 04:34:00 | I13: DESCONEXIÓN DE LA LÍNEA L-6684 (CARAZ - HUARAZ) DE 66 kV POR FALLA | J13: 10.87 | K13: SI
B14: FALLA | C14: HIDRANDINA | D14: CARAZ - SANTA CRUZ | E14: LINEA DE TRANSMISION | F14: L-6690 | G14: 10/02/2026 16:57:51 | H14: 10/02/2026 17:13:00 | I14: DESCONEXIÓN DE LAS LÍNEAS L-6678 (HUALLANCA - SANTA CRUZ) Y L-6690 (SANTA CRUZ - CARAZ) DE 66 KV | K14: NO | L14: 66
B15: FALLA | C15: HIDRANDINA | D15: HUALLANCA - CARAZ | E15: LINEA DE TRANSMISION | F15: L-6678 | G15: 10/02/2026 17:15:34 | H15: 10/02/2026 17:23:08 | I15: DESCONEXIÓN DE LAS LÍNEAS L-6678 (HUALLANCA - SANTA CRUZ) | K15: NO | L15: 0
B16: FALLA | C16: INVERSIONES SHAQSHA S.A.C. | D16: PARIAC | E16: GENERADOR HIDROELÉCTRICO | F16: CH3 - G1 | G16: 10/02/2026 16:13:52 | H16: 11/02/2026 00:00:00 | I16: DESCONEXIÓN DEL GENERADOR G1 DE LA C.H. 3 PARIAC | K16: NO | L16: 0.44
B17: FALLA | C17: ISA PERU | D17: CHIMBOTE 1 - HUALLANCA | E17: LINEA DE TRANSMISION | F17: L-1105 | G17: 10/02/2026 17:44:16 | H17: 10/02/2026 18:14:47 | I17: DESCONEXIÓN DE LA LÍNEA L-1105 (CHIMBOTE 1 - HUALLANCA) DE 138 KV | J17: 1.5 | K17: SI | L17: 138
B18: EVENTO | C18: RED DE ENERGIA DEL PERU S.A. | D18: CALLALLI - SANTUARIO | E18: LINEA DE TRANSMISION | F18: L-1020 | G18: 10/02/2026 14:40:08 | H18: 10/02/2026 15:21:56 | I18: DESCONEXIÓN DE LA LÍNEA L-1020 (CALLALI - SANTUARIO) DE 138 kV POR FALLA | K18: NO
B19: FALLA | C19: SAN GABAN | D19: PCH TUPURI | E19: CENTRAL HIDROELÉCTRICA | F19: CENTRAL | G19: 10/02/2026 06:48:00 | H19: 10/02/2026 07:49:00 | I19: DESCONEXIÓN DE LA C.H. TUPURI POR FALLA. | K19: NO | L19: 2.4

Sheet RESTRIC_OPE
B3: martes, 10 de Febrero del 2026
B5: RESTRICCIONES OPERATIVAS
B6: FECHA | C6: HORA INICIO | D6: HORA FINAL | E6: EMPRESA | F6: UBICACIÓN | G6: T.Eq. | H6: EQUIPO | I6: DESCRIPCIÓN
B7: 10/02/2026 | C7: 00:00 | D7: 24:00 | E7: CELEPSA | F7: C.H. EL PLATANAL | G7: CH | H7: CENTRAL | I7: De acuerdo con lo informado por CELEPSA mediante correo el dia 17.01, declaran que la CH Platanal se encontrará de pasada.
B8: 10/02/2026 | C8: 00:00 | D8: 24:00 | E8: EGASA | F8: S.E. CONVERTIDOR | G8: BARRA | H8: BARRA138KV | I8: EGASA limitó la capacidad del transformador 138 kV/33 kV a 50 MVA por deterioro del aislamiento.
B9: 10/02/2026 | C9: 00:00 | D9: 24:00 | E9: ELECTROPERU | F9: C.H. MANTARO | G9: CH | H9: CENTRAL | I9: De acuerdo con el correo del día 25.08.2025, la central tiene una limitación de potencia máxima de 650 MW por seguridad de la central.
B10: 10/02/2026 | C10: 00:00 | D10: 24:00 | E10: ENEL GENERACION PIURA S.A. | F10: C.T. MALACAS | G10: CT | H10: CENTRAL | I10: De acuerdo con la comunicación vía correo del día 24.10.2024. ENEL GENERACIÓN PIURA informa una restricción de potencia para alcanzar 105 MW en simultaneo (TG6+TGN4).
B11: 10/02/2026 | C11: 00:00 | D11: 24:00 | E11: ENEL GENERACION PIURA S.A. | F11: C.T. MALACAS | G11: GT | H11: TG4 | I11: De acuerdo a lo informado por correo electrónico el día 16.01, con la disponibilidad de aproximadamente 12 MMPCD (339.8Mm³) la unidad TG4 puede con una generación de 80 MW durante 4 horas, y a potencia mínima durante el resto de los periodos
B12: 10/02/2026 | C12: 00:00 | D12: 24:00 | E12: ENGIE ENERGIA PERU S.A.A. | F12: C.H. YUNCÁN | G12: GH | H12: G3 | I12: Según la carta N° ENG/ 198-2024 enviada por su representada, se opera de forma continua el G3 de la CH Yuncán, debido a la ejecución de mantenimientos necesarios para evitar daños en los sellos de seguridad de la válvula esférica del grupo.
B13: 10/02/2026 | C13: 00:00 | D13: 24:00 | E13: ENGIE ENERGIA PERU S.A.A. | F13: C.T. CHILCA 1 | G13: CT | H13: CENTRAL | I13: Restricción de temperatura de la C.T Chilca, ver valor en el modelo de despacho.
B14: 10/02/2026 | C14: 00:00 | D14: 24:00 | E14: ENGIE ENERGIA PERU S.A.A. | F14: C.T. CHILCA 1 | G14: CT | H14: CENTRAL | I14: Con carta ENG/971-2023, indica que no puede cumplir con las IO considerada en el PDO_17122023 dado que vulneran la seguridad de sus activos. Indican que se debe tomar TMO=168h.
B15: 10/02/2026 | C15: 00:00 | D15: 24:00 | E15: ENGIE ENERGIA PERU S.A.A. | F15: C.T. CHILCA 2 | G15: CT | H15: CENTRAL | I15: Con carta ENG/971-2023, indica que no puede cumplir con las IO considerada en el PDO_17122023 dado que vulneran la seguridad de sus activos. Indican que se debe tomar TMO=168h.
B16: 10/02/2026 | C16: 00:00 | D16: 24:00 | E16: FENIX POWER PERÚ | F16: C.T. FENIX | G16: CT | H16: CENTRAL | I16: De acuerdo con lo comunicado en el correo del día 06.05.2025, la CT Fenix cuenta con TMO de 168 hrs en todos sus modos de operación.
B17: 10/02/2026 | C17: 00:00 | D17: 24:00 | E17: KALLPA GENERACION S.A. | F17: C.H. CERRO DEL AGUILA | G17: GH | H17: G1 | I17: De acuerdo a lo informado el día 17/11 por la empresa KALLPA, el G1 tiene un TA = 15min
... B59: 10/02/2026 | C59: 00:00 | D59: 24:00 | E59: TERMOSELVA | F59: C.T. AGUAYTÍA | G59: CT | H59: CENTRAL | I59: Disponibilidad de 23.5 MMSCF para la CT Aguaytía.

Sheet MANTENIMIENTO EJECUTADOS
B3: martes, 10 de Febrero del 2026
B5: Mantenimiento Ejecutado
B6: Empresa | C6: Ubicación | D6: Equipo | E6: Inicio | F6: Final | G6: Descripción | H6: MW Indisp. | I6: Prog. | J6: Dispon | K6: Interrupc. | L6: Tipo | M6: CodEq | N6: TipoEq_Osinerg
B7: ATLANTICA TRANSMISION SUR S.A. | C7: CHILCA CTM - POROMA | D7: L-5032 | E7: 10/02/2026 07:14 | F7: 10/02/2026 16:35 | G7: Inspeccion Anual en LLTT | H7: 0 | I7: P | J7: E/S | K7: N | L7: PREV. | M7: 13652 | N7: T
B8: ATLANTICA TRANSMISION SUR S.A. | C8: CHILCA-CTM | D8: INT-5261 | E8: 10/02/2026 07:58 | F8: 10/02/2026 13:52 | G8: Mantenimiento Preventivo en Seccionador SBB-5261. Requiere Barra B 500 kV. Fuera de Servicio | H8: 0 | I8: P | J8: F/S | K8: N | L8: PREV. | M8: 13854 | N8: T
B9: ATLANTICA TRANSMISION SUR S.A. | C9: OCONA | D9: INT-5450 | E9: 10/02/2026 00:00 | F9: 11/02/2026 00:00 | G9: Interruptor INT-5450 cerrado con restriccion operativa, REB-5450 en servicio y suministrando los SS.AA. de la S.E. Oco?a. | H9: 0 | I9: P | J9: E/S | K9: N | L9: OTROS | M9: 13761 | N9: T
B10: ATLANTICA TRANSMISION SUR S.A. | C10: OCONA | D10: SE OCOÑA | E10: 10/02/2026 11:37 | F10: 10/02/2026 17:30 | G10: Inspeccion Anual en Subestacion | H10: 0 | I10: P | J10: E/S | K10: N | L10: PREV. | M10: 13741 | N10: T
B11: ATLANTICA TRANSMISION SUR S.A. | C11: POROMA | D11: INT-5371 | E11: 10/02/2026 00:00 | F11: 11/02/2026 00:00 | G11: Seccionador SBB-5371 fase T indisponible por problemas mecanicos, el seccionador permanece cerrado y bloqueado | H11: 0 | I11: P | J11: E/S | K11: N | L11: OTROS | M11: 13751 | N11: T
B12: ATLANTICA TRANSMISION SUR S.A. | C12: POROMA | D12: REB-5350 | E12: 10/02/2026 00:00 | F12: 11/02/2026 00:00 | G12: Fuera de servicio por falla en el equipo. | H12: 0 | I12: P | J12: F/S | K12: N | L12: OTROS | M12: 13771 | N12: T
B13: ATLANTICA TRANSMISION SUR S.A. | C13: POROMA - OCONA | D13: L-5034 | E13: 10/02/2026 09:28 | F13: 10/02/2026 16:50 | G13: Actividad de reparacion de pedestales para la Linea L5034. | H13: 0 | I13: P | J13: F/S | K13: N | L13: PREV. | M13: 13743 | N13: T
B14: ATN S.A. | C14: KIMAN AYLLU | D14: AUT-501 | E14: 10/02/2026 00:00 | F14: 11/02/2026 00:00 | G14: Restriccion Operativa en el circuito de control de cambiador de tap s del AUT-501 | H14: 0 | I14: P | J14: E/S | K14: N | L14: OTROS | M14: 13099 | N14: T
B15: CONELSUR LT SAC | C15: CAJAMARQUILLA | D15: BARRA A 220kV | E15: 10/02/2026 00:00 | F15: 11/02/2026 00:00 | G15: NO SE PUEDE INDISPONER LA BARRA A POR RESTRICCION OPERATIVA DEL SECCIONADOR DE BARRA B DE LA CL-2708 PROPIEDAD DE NEXA. | H15: 0 | I15: P | J15: E/S | K15: N | L15: OTROS | M15: 1103 | N15: T
B16: CONELSUR LT SAC | C16: CAJAMARQUILLA | D16: BARRA A 220kV | E16: 10/02/2026 05:00 | F16: 10/02/2026 19:00 | G16: A SOLICITUD DE NEXA POR CORRECTIVO EN CL-2708 | H16: 0 | I16: P | J16: F/S | K16: N | L16: CORR. | M16: 1103 | N16: T
B17: CONELSUR LT SAC | C17: CALLAHUANCA (CNS) | D17: S.E. | E17: 10/02/2026 00:00 | F17: 11/02/2026 00:00 | G17: RELE DIFERENCIAL DE BARRAS DE CALLAHUANCA 220KV INOPERATIVO | H17: 0 | I17: P | J17: E/S | K17: N | L17: OTROS | M17: 316 | N17: T
B18: CONELSUR LT SAC | C18: HUAMPANI | D18: CL-6040 | E18: 10/02/2026 00:00 | F18: 10/02/2026 19:46 | G18: CONEXIONADO Y PRUEBA DE COLUMNA DE MANDO. (ESTA ACTIVIDAD SOLO INDISPONE UNO DE LOS TRANSFORMADORES DE LA SSEE, RESTRINGE GENERACION) | H18: 0 | I18: P | J18: F/S | K18: N | L18: PREV. | M18: 1590 | N18: T
... B112: TRANSMANTARO | C112: YARABAMBA | D112: IN-5120 | E112: 10/02/2026 00:00 | F112: 11/02/2026 00:00 | G112: SE. YARABAMBA 500KV: INTERRRUPTOR INDISPONIBLE POR PROBLEMAS DE MANDOS. REACTOR R-31 SERA OPERADO CON EL INTERRRUPTOR IN-5116. | H112: 0 | I112: P | J112: F/S | K112: N | L112: OTROS | M112: 17437 | N112: T

Sheet INGRESO OC
A3: martes, 10 de Febrero del 2026
A5: INGRESO A OPERACIÓN COMERCIAL
A6: EMPRESA | B6: TIPO DE EQUIPO | C6: UBICACIÓN | D6: EQUIPO | E6: Fecha y hora de Ingreso a Operación Comercial

Sheet DESPACHO_EJECUTADO
B3: martes, 10 de Febrero del 2026
A5: POTENCIA ACTIVA EJECUTADA DE LAS UNIDADES DE GENERACIÓN DEL SEIN (MW) | FQ5: CENTRALES NO INTEGRANTES COES
A6: FECHA | B6: HORA | C6: 65333 | D6: 101 | E6: 102 | F6: 42667 | G6: 42668 | H6: 126 | I6: 127 | J6: 138 | K6: 139 | L6: 197 | M6: 203 | N6: 204 | O6: 230 | P6: 209 | Q6: 56677 | R6: 796 | S6: 2146 | T6: 142 | U6: 143 | V6: 125 | W6: 187 | X6: 163 | Y6: 298 | Z6: 299 | AA6: 219 | AB6: 151 | AC6: 152 | AD6: 153 | AE6: 154 | AF6: 756 | AG6: 156 | AH6: 155 | AI6: 182 | AJ6: 212 | AK6: 758 | AL6: 263 | AM6: 265 | AN6: 775 | AO6: 777 | AP6: 2154 | AQ6: 150 | AR6: 149 | AS6: 188 | AT6: 2131 | AU6: 755 | AV6: 252 | AW6: 249 | AX6: 250 | AY6: 117 | AZ6: 119 | BA6: 120 | BB6: 189 | BC6: 122 | BD6: 266 | BE6: 337 | BF6: 338 | BG6: 251 | BH6: 115 | BI6: 239 | BJ6: 288 | BK6: 240 | BL6: 241 | BM6: 242 | BN6: 191 | BO6: 194 | BP6: 196 | BQ6: 207 | BR6: 236 | BS6: 795 | BT6: 285 | BU6: 995 | BV6: 996 | BW6: 997 | BX6: 766 | BY6: 926 | BZ6: 924 | CA6: 121 | CB6: 103 | CC6: 104 | CD6: 106 | CE6: 105 | CF6: 107 | CG6: 110 | CH6: 109 | CI6: 144 | CJ6: 113 | CK6: 114 | CL6: 193 | CM6: 208 | CN6: 786 | CO6: 787 | CP6: 788 | CQ6: 789 | CR6: 248 | CS6: 2159 | CT6: 267 | CU6: 268 | CV6: 2194 | CW6: 303 | CX6: 59715 | CY6: 62255 | CZ6: 1263 | DA6: 61800 | DB6: 69125 | DC6: 216 | DD6: 198 | DE6: 70400 | DF6: 76068 | DG6: 49607 | DH6: 214 | DI6: 260 | DJ6: 2152 | DK6: 2128 | DL6: 247 | DM6: 228 | DN6: 2135 | DO6: 261 | DP6: 237 | DQ6: 253 | DR6: 770 | DS6: 235 | DT6: 238 | DU6: 2184 | DV6: 61855 | DW6: 223 | DX6: 75566 | DY6: 226 | DZ6: 201 | EA6: 258 | EB6: 259 | EC6: 257 | ED6: 256 | EE6: 2148 | EF6: 58288 | EG6: 58289 | EH6: 58839 | EI6: 58840 | EJ6: 75260 | EK6: 296 | EL6: 297 | EM6: 211 | EN6: 2175 | EO6: 2178 | EP6: 2181 | EQ6: 1262 | ER6: 63425 | ES6: 233 | ET6: 2150 | EU6: 2165 | EV6: 2161 | EW6: 61197 | EX6: 58851 | EY6: 225 | EZ6: 2201 | FA6: 2171 | FB6: 760 | FC6: 234 | FD6: 215 | FE6: 917 | FF6: 920 | FG6: 289 | FH6: 58333 | FI6: 58336 | FJ6: 213 | FK6: 232 | FL6: 2190 | FM6: 69867 | FN6: 75066 | FO6: TOTAL COES | FQ6: 221 | FR6: 222 | FS6: 224 | FT6: 2187 | FU6: 227 | FV6: 49400 | FW6: 199 | FX6: 200 | FY6: TOTAL NO COES
C7: SUR | D7: CENTRO | E7: CENTRO | F7: NORTE | G7: NORTE | H7: NORTE | I7: NORTE | J7: CENTRO | K7: CENTRO | L7: CENTRO | M7: CENTRO | N7: CENTRO | O7: CENTRO | P7: CENTRO | Q7: CENTRO | R7: CENTRO | S7: CENTRO | T7: CENTRO | U7: CENTRO | V7: CENTRO | W7: CENTRO | X7: SUR | Y7: SUR | Z7: SUR | AA7: CENTRO | AB7: SUR | AC7: SUR | AD7: SUR | AE7: SUR | AF7: SUR | AG7: SUR | AH7: SUR | AI7: SUR | AJ7: CENTRO | AK7: NORTE | AL7: NORTE | AM7: NORTE | AN7: CENTRO | AO7: CENTRO | AP7: CENTRO | AQ7: CENTRO | AR7: CENTRO | AS7: CENTRO | AT7: CENTRO | AU7: SUR | AV7: CENTRO | AW7: CENTRO | AX7: CENTRO | AY7: CENTRO | AZ7: CENTRO | BA7: CENTRO | BB7: SUR | BC7: NORTE | BD7: CENTRO | BE7: CENTRO | BF7: CENTRO | BG7: CENTRO | BH7: NORTE | BI7: NORTE | BJ7: NORTE | BK7: SUR | BL7: SUR | BM7: SUR | BN7: CENTRO | BO7: CENTRO | BP7: CENTRO | BQ7: CENTRO | BR7: CENTRO | BS7: CENTRO | BT7: CENTRO | BU7: SUR | BV7: SUR | BW7: SUR | BX7: NORTE | BY7: SUR | BZ7: CENTRO | CA7: NORTE | CB7: CENTRO | CC7: CENTRO | CD7: CENTRO | CE7: CENTRO | CF7: CENTRO | CG7: CENTRO | CH7: CENTRO | CI7: CENTRO | CJ7: CENTRO | CK7: CENTRO | CL7: CENTRO | CM7: CENTRO | CN7: SUR | CO7: SUR | CP7: SUR | CQ7: SUR | CR7: CENTRO | CS7: CENTRO | CT7: CENTRO | CU7: CENTRO | CV7: NORTE | CW7: CENTRO | CX7: CENTRO | CY7: SUR | CZ7: NORTE | DA7: NORTE | DB7: CENTRO | DC7: NORTE | DD7: NORTE | DE7: SUR | DG7: SUR | DH7: CENTRO | DI7: CENTRO | DJ7: CENTRO | DK7: NORTE | DL7: NORTE | DM7: CENTRO | DN7: CENTRO | DO7: SUR | DP7: SUR | DQ7: CENTRO | DR7: CENTRO | DS7: SUR | DT7: CENTRO | DU7: CENTRO | DV7: NORTE | DW7: CENTRO | DX7: CENTRO | DY7: CENTRO | DZ7: NORTE | EA7: CENTRO | EB7: CENTRO | EC7: NORTE | ED7: NORTE | EE7: SUR | EF7: CENTRO | EG7: CENTRO | EH7: CENTRO | EI7: CENTRO | EJ7: SUR | EK7: CENTRO | EL7: CENTRO | EM7: SUR | EN7: SUR | EO7: SUR | EP7: SUR | EQ7: NORTE | ER7: SUR | ES7: SUR | ET7: SUR | EU7: CENTRO | EV7: CENTRO | EW7: CENTRO | EX7: SUR | EY7: CENTRO | EZ7: CENTRO | FA7: CENTRO | FB7: CENTRO | FC7: SUR | FD7: NORTE | FE7: CENTRO | FF7: CENTRO | FG7: NORTE | FH7: NORTE | FI7: NORTE | FJ7: CENTRO | FK7: NORTE | FL7: NORTE | FM7: NORTE | FN7: NORTE | FQ7: NORTE | FR7: CENTRO | FS7: NORTE | FT7: NORTE | FU7: NORTE | FV7: NORTE | FW7: NORTE | FX7: NORTE
C8: HIDROELÉCTRICA | D8: HIDROELÉCTRICA | E8: HIDROELÉCTRICA | F8: TERMOELÉCTRICA | G8: TERMOELÉCTRICA | H8: HIDROELÉCTRICA | I8: HIDROELÉCTRICA | J8: TERMOELÉCTRICA | K8: TERMOELÉCTRICA | L8: TERMOELÉCTRICA | M8: TERMOELÉCTRICA | N8: TERMOELÉCTRICA | O8: TERMOELÉCTRICA | P8: TERMOELÉCTRICA | Q8: TERMOELÉCTRICA | R8: HIDROELÉCTRICA | S8: HIDROELÉCTRICA | T8: TERMOELÉCTRICA | U8: TERMOELÉCTRICA | V8: TERMOELÉCTRICA | W8: TERMOELÉCTRICA | X8: HIDROELÉCTRICA | Y8: HIDROELÉCTRICA | Z8: HIDROELÉCTRICA | AA8: TERMOELÉCTRICA | AB8: HIDROELÉCTRICA | AC8: HIDROELÉCTRICA | AD8: HIDROELÉCTRICA | AE8: HIDROELÉCTRICA | AF8: TERMOELÉCTRICA | AG8: TERMOELÉCTRICA | AH8: TERMOELÉCTRICA | AI8: HIDROELÉCTRICA | AJ8: HIDROELÉCTRICA | AK8: TERMOELÉCTRICA | AL8: TERMOELÉCTRICA | AM8: TERMOELÉCTRICA | AN8: HIDROELÉCTRICA | AO8: HIDROELÉCTRICA | AP8: HIDROELÉCTRICA | AQ8: HIDROELÉCTRICA | AR8: HIDROELÉCTRICA | AS8: HIDROELÉCTRICA | AT8: HIDROELÉCTRICA | AU8: HIDROELÉCTRICA | AV8: TERMOELÉCTRICA | AW8: TERMOELÉCTRICA | AX8: TERMOELÉCTRICA | AY8: HIDROELÉCTRICA | AZ8: HIDROELÉCTRICA | BA8: HIDROELÉCTRICA | BB8: HIDROELÉCTRICA | BC8: HIDROELÉCTRICA | BD8: HIDROELÉCTRICA | BE8: HIDROELÉCTRICA | BF8: HIDROELÉCTRICA | BG8: HIDROELÉCTRICA | BH8: TERMOELÉCTRICA | BI8: TERMOELÉCTRICA | BJ8: TERMOELÉCTRICA | BK8: TERMOELÉCTRICA | BL8: TERMOELÉCTRICA | BM8: TERMOELÉCTRICA | BN8: HIDROELÉCTRICA | BO8: TERMOELÉCTRICA | BP8: TERMOELÉCTRICA | BQ8: TERMOELÉCTRICA | BR8: TERMOELÉCTRICA | BS8: TERMOELÉCTRICA | BT8: TERMOELÉCTRICA | BU8: TERMOELÉCTRICA | BV8: TERMOELÉCTRICA | BW8: TERMOELÉCTRICA | BX8: HIDROELÉCTRICA | BY8: TERMOELÉCTRICA | BZ8: TERMOELÉCTRICA | CA8: HIDROELÉCTRICA | CB8: HIDROELÉCTRICA | CC8: HIDROELÉCTRICA | CD8: HIDROELÉCTRICA | CE8: HIDROELÉCTRICA | CF8: HIDROELÉCTRICA | CG8: TERMOELÉCTRICA | CH8: TERMOELÉCTRICA | CI8: TERMOELÉCTRICA | CJ8: TERMOELÉCTRICA | CK8: TERMOELÉCTRICA | CL8: TERMOELÉCTRICA | CM8: TERMOELÉCTRICA | CN8: TERMOELÉCTRICA | CO8: TERMOELÉCTRICA | CP8: TERMOELÉCTRICA | CQ8: TERMOELÉCTRICA | CR8: TERMOELÉCTRICA | CS8: TERMOELÉCTRICA | CT8: HIDROELÉCTRICA | CU8: HIDROELÉCTRICA | CV8: HIDROELÉCTRICA | CW8: SOLAR | CX8: EÓLICA | CY8: SOLAR | CZ8: EÓLICA | DA8: SOLAR | DB8: HIDROELÉCTRICA | DC8: HIDROELÉCTRICA | DD8: HIDROELÉCTRICA | DE8: SOLAR | DF8: SOLAR | DG8: HIDROELÉCTRICA | DH8: HIDROELÉCTRICA | DI8: HIDROELÉCTRICA | DJ8: HIDROELÉCTRICA | DK8: HIDROELÉCTRICA | DL8: HIDROELÉCTRICA | DM8: HIDROELÉCTRICA | DN8: HIDROELÉCTRICA | DO8: SOLAR | DP8: SOLAR | DQ8: EÓLICA | DR8: EÓLICA | DS8: SOLAR | DT8: HIDROELÉCTRICA | DU8: HIDROELÉCTRICA | DV8: HIDROELÉCTRICA | DW8: HIDROELÉCTRICA | DX8: SOLAR | DY8: HIDROELÉCTRICA | DZ8: HIDROELÉCTRICA | EA8: HIDROELÉCTRICA | EB8: HIDROELÉCTRICA | EC8: EÓLICA | ED8: EÓLICA | EE8: SOLAR | EF8: EÓLICA | EG8: EÓLICA | EH8: EÓLICA | EI8: EÓLICA | EJ8: SOLAR | EK8: HIDROELÉCTRICA | EL8: HIDROELÉCTRICA | EM8: HIDROELÉCTRICA | EN8: HIDROELÉCTRICA | EO8: HIDROELÉCTRICA | EP8: HIDROELÉCTRICA | EQ8: EÓLICA | ER8: SOLAR | ES8: SOLAR | ET8: SOLAR | EU8: HIDROELÉCTRICA | EV8: EÓLICA | EW8: EÓLICA | EX8: SOLAR | EY8: TERMOELÉCTRICA | EZ8: TERMOELÉCTRICA | FA8: TERMOELÉCTRICA | FB8: TERMOELÉCTRICA | FC8: SOLAR | FD8: HIDROELÉCTRICA | FE8: HIDROELÉCTRICA | FF8: HIDROELÉCTRICA | FG8: TERMOELÉCTRICA | FH8: TERMOELÉCTRICA | FI8: TERMOELÉCTRICA | FJ8: TERMOELÉCTRICA | FK8: TERMOELÉCTRICA | FL8: TERMOELÉCTRICA | FM8: TERMOELÉCTRICA | FN8: TERMOELÉCTRICA | FQ8: HIDROELÉCTRICA | FR8: HIDROELÉCTRICA | FS8: HIDROELÉCTRICA | FT8: HIDROELÉCTRICA | FU8: TERMOELÉCTRICA | FV8: TERMOELÉCTRICA | FW8: HIDROELÉCTRICA | FX8: HIDROELÉCTRICA
C9: HYDRO GLOBAL PERÚ S.A.C. | D9: ELECTROPERU | E9: ELECTROPERU | F9: ELECTROPERU | G9: ELECTROPERU | H9: ORAZUL ENERGY PERÚ | I9: ORAZUL ENERGY PERÚ | J9: TERMOSELVA | K9: TERMOSELVA | L9: KALLPA GENERACION S.A. | M9: KALLPA GENERACION S.A. | N9: KALLPA GENERACION S.A. | O9: KALLPA GENERACION S.A. | P9: KALLPA GENERACION S.A. | Q9: KALLPA GENERACION S.A. | R9: KALLPA GENERACION S.A. | S9: KALLPA GENERACION S.A. | T9: SHOUGESA | U9: SHOUGESA | V9: SHOUGESA | W9: SHOUGESA | X9: EGEMSA | Y9: EGESUR | Z9: EGESUR | AA9: EGESUR | AB9: EGASA | AC9: EGASA | AD9: EGASA | AE9: EGASA | AF9: EGASA | AG9: EGASA | AH9: EGASA | AI9: SAN GABAN | AJ9: CELEPSA | AK9: MINERA CERRO VERDE | AL9: PLANTA DE RESERVA FRIA DE GENERACION DE ETEN S.A. | AM9: PLANTA DE RESERVA FRIA DE GENERACION DE ETEN S.A. | AN9: EMPRESA DE GENERACION HUALLAGA | AO9: EMPRESA DE GENERACION HUALLAGA | AP9: LA VIRGEN | AQ9: CHINANGO S.A.C. | AR9: CHINANGO S.A.C. | AS9: HIDROELECTRICA HUANCHOR S.A.C. | AT9: CELEPSA RENOVABLES S.R.L. | AU9: INLAND ENERGY SAC | AV9: FENIX POWER PERÚ | AW9: FENIX POWER PERÚ | AX9: FENIX POWER PERÚ | AY9: STATKRAFT S.A | AZ9: STATKRAFT S.A | BA9: STATKRAFT S.A | BB9: STATKRAFT S.A | BC9: STATKRAFT S.A | BD9: STATKRAFT S.A | BE9: CENTRALES SANTA ROSA S.A.C. | BF9: CENTRALES SANTA ROSA S.A.C. | BG9: EMPRESA DE GENERACION HUANZA | BH9: ENEL GENERACION PIURA S.A. | BI9: ENEL GENERACION PIURA S.A. | BJ9: ENEL GENERACION PIURA S.A. | BK9: ENGIE ENERGIA PERU S.A.A. | BL9: ENGIE ENERGIA PERU S.A.A. | BM9: ENGIE ENERGIA PERU S.A.A. | BN9: ENGIE ENERGIA PERU S.A.A. | BO9: ENGIE ENERGIA PERU S.A.A. | BP9: ENGIE ENERGIA PERU S.A.A. | BQ9: ENGIE ENERGIA PERU S.A.A. | BR9: ENGIE ENERGIA PERU S.A.A. | BS9: ENGIE ENERGIA PERU S.A.A. | BT9: ENGIE ENERGIA PERU S.A.A. | BU9: ENGIE ENERGIA PERU S.A.A. | BV9: ENGIE ENERGIA PERU S.A.A. | BW9: ENGIE ENERGIA PERU S.A.A. | BX9: ENGIE ENERGIA PERU S.A.A. | BY9: INFRAESTRUCTURAS Y ENERGIAS DEL PERU S.A.C. | BZ9: INFRAESTRUCTURAS Y ENERGIAS DEL PERU S.A.C. | CA9: INVERSIONES SHAQSHA S.A.C. | CB9: ORYGEN PERU S.A.A. | CC9: ORYGEN PERU S.A.A. | CD9: ORYGEN PERU S.A.A. | CE9: ORYGEN PERU S.A.A. | CF9: ORYGEN PERU S.A.A. | CG9: ORYGEN PERU S.A.A. | CH9: ORYGEN PERU S.A.A. | CI9: ORYGEN PERU S.A.A. | CJ9: ORYGEN PERU S.A.A. | CK9: ORYGEN PERU S.A.A. | CL9: ORYGEN PERU S.A.A. | CM9: ORYGEN PERU S.A.A. | CN9: SAMAY I S.A.C | CO9: SAMAY I S.A.C | CP9: SAMAY I S.A.C | CQ9: SAMAY I S.A.C | CR9: TERMOCHILCA S.A.C. | CS9: TERMOCHILCA S.A.C. | CT9: TRANSMISION ANDINA DE GENERACION S.A.C. | CU9: TRANSMISION ANDINA DE GENERACION S.A.C. | CV9: CELARIS ENERGY S.A. | CW9: COLCA SOLAR S.A.C. | CX9: ENERGIA RENOVABLE DEL SUR S.A. | CY9: GR CORTARRAMA SOCIEDAD ANONIMA CERRADA | CZ9: GR TARUCA SOCIEDAD ANONIMA CERRADA | DA9: KONDU SAC | DB9: VARI ENERGIA S.A.C. | DC9: ORAZUL ENERGY PERÚ | DD9: ORAZUL ENERGY PERÚ | DE9: KALLPA GENERACION S.A. | DF9: KALLPA GENERACION S.A. | DG9: SAN GABAN | DH9: MAJA ENERGIA S.A.C. | DI9: EMPRESA DE GENERACION ELECTRICA CANCHAYLLO SAC | DJ9: EMPRESA DE GENERACION ELECTRICA SANTA ANA S.A.C. | DK9: EMPRESA ELECTRICA AGUA AZUL | DL9: EMPRESA ELECTRICA RIO DOBLE | DM9: HIDROCAÑETE S.A. | DN9: HUAURA POWER GROUP S.A. | DO9: MOQUEGUA FV S.A.C. | DP9: PANAMERICANA SOLAR SAC. | DQ9: PARQUE EOLICO MARCONA S.A.C. | DR9: PARQUE EOLICO TRES HERMANAS S.A.C. | DS9: TACNA SOLAR SAC. | DT9: ELECTRICA YANAPAMPA SAC | DU9: ANDEAN POWER S.A.C. | DV9: ASOCIACIÓN SANTA LUCIA DE CHACAS | DW9: ATRIA ENERGIA S.A.C. | DX9: COENERGY S.A.C. | DY9: EGEJUNIN | DZ9: EGEJUNIN | EA9: EGEJUNIN | EB9: EGEJUNIN | EC9: ENERGÍA EÓLICA S.A. | ED9: ENERGÍA EÓLICA S.A. | EE9: ENGIE ENERGIA PERU S.A.A. | EF9: ENGIE ENERGIA PERU S.A.A. | EG9: ENGIE ENERGIA PERU S.A.A. | EH9: ENGIE ENERGIA PERU S.A.A. | EI9: ENGIE ENERGIA PERU S.A.A. | EJ9: ENGIE ENERGIA PERU S.A.A. | EK9: GENERACIÓN ANDINA S.A.C. | EL9: GENERACIÓN ANDINA S.A.C. | EM9: GENERADORA DE ENERGÍA DEL PERÚ | EN9: GENERADORA DE ENERGÍA DEL PERÚ | EO9: GENERADORA DE ENERGÍA DEL PERÚ | EP9: GENERADORA DE ENERGÍA DEL PERÚ | EQ9: GR PAINO SOCIEDAD ANONIMA CERRADA | ER9: JOYA SOLAR S.A.C. | ES9: MAJES ARCUS S.A.C. | ET9: ORYGEN PERU S.A.A. | EU9: ORYGEN PERU S.A.A. | EV9: ORYGEN PERU S.A.A. | EW9: ORYGEN PERU S.A.A. | EX9: ORYGEN PERU S.A.A. | EY9: PETRAMAS | EZ9: PETRAMAS | FA9: PETRAMAS | FB9: PETRAMAS | FC9: REPARTICIÓN ARCUS S.A.C. | FD9: SINERSA | FE9: SINERSA | FF9: SINERSA | FG9: BIOENERGIA DEL CHIRA S.A. | FH9: GM OPERACIONES S.A.C. | FI9: GM OPERACIONES S.A.C. | FJ9: AGRO INDUSTRIAL PARAMONGA S.A. | FK9: AGROAURORA S.A.C. | FL9: AGROINDUSTRIAS SAN JACINTO S.A.A. | FM9: AGROLMOS SOCIEDAD ANONIMA - AGROLMOS S.A. | FN9: CASA GRANDE S.A.A. | FQ9: UNACEM PERU S.A. | FR9: ELECTRO ORIENTE | FS9: AGUAS Y ENERGIA PERU | FT9: ELECTRO ZAÑA S.A.C. | FU9: ELECTRONOROESTE S.A. | FV9: SDE PIURA | FW9: SINERSA | FX9: SINERSA
C10: SAN GABAN III | D10: MANTARO | E10: RESTITUCION | F10: TUMBES MAK 1 | G10: TUMBES MAK 2 | H10: CARHUAQUERO | I10: CAÑON DEL PATO | J10: AGUAYTIA TG1 | K10: AGUAYTIA TG2 | L10: KALLPA TG1 | M10: KALLPA TG2 | N10: KALLPA TG3 | O10: KALLPA TV | P10: LFLORES TG1 | Q10: LFLORES TV | R10: CERRO DEL AGUILA | S10: CERRODELAGUILAG4 | T10: SHOUGESA TV1 | U10: SHOUGESA TV2 | V10: SHOUGESA TV3 | W10: SHOUGESA CUMMINS | X10: MACHUPICCHU | Y10: ARICOTA 1 | Z10: ARICOTA 2 | AA10: INDEPENDENCIA | AB10: CHARCANI I,II,III | AC10: CHARCANI IV | AD10: CHARCANI V | AE10: CHARCANI VI | AF10: CHILINA TG | AG10: MOLLENDO 1, 2, 3 | AH10: CHILINA (SULZ 1,2) | AI10: SAN GABAN II | AJ10: PLATANAL | AK10: RECKA | AL10: RF ETEN TG1 | AM10: RF ETEN TG2 | AN10: CHAGLLA GP1 | AO10: CHAGLLA | AP10: LA VIRGEN | AQ10: CHIMAY | AR10: YANANGO | AS10: HUANCHOR | AT10: MARAÑON | AU10: STA TERESA | AV10: FENIX GT11 | AW10: FENIX GT12 | AX10: FENIX TV10 | AY10: YAUPI | AZ10: MALPASO | BA10: CAHUA | BB10: ARCATA | BC10: GALLITO CIEGO | BD10: CHEVES | BE10: SANTA ROSA 1 | BF10: SANTA ROSA 2 | BG10: HUANZA | BH10: MALACAS2 TG4 | BI10: MALACAS3 TG 5 | BJ10: MALACAS1 TG6 | BK10: RF ILO2 TG1 | BL10: RF ILO2 TG2 | BM10: RF ILO2 TG3 | BN10: YUNCAN | BO10: CHILCA1 TG1 | BP10: CHILCA1 TG2 | BQ10: CHILCA1 TG3 | BR10: CHILCA-TV | BS10: CHILCA2 TG41 | BT10: CHILCA2-TV | BU10: CTNEPI_TG41 | BV10: CTNEPI_TG42 | BW10: CTNEPI_TG43 | BX10: QUITARACSA | BY10: RF PTO MALDONADO | BZ10: RF PUCALLPA | CA10: PARIAC | CB10: HUINCO | CC10: MATUCANA | CD10: MOYOPAMPA | CE10: CALLAHUANCA | CF10: HUAMPANI | CG10: STA ROSA WEST TG7 | CH10: UTI_5 | CI10: UTI_6 | CJ10: VENTANILLA 3 | CK10: VENTANILLA 4 | CL10: VENTANILLA TV | CM10: STAROSA TG8 | CN10: PTO_BRVO TG1 | CO10: PTO_BRVO TG2 | CP10: PTO_BRVO TG3 | CQ10: PTO_BRVO TG4 | CR10: OLLEROS TG1 | CS10: OLLEROS TV | CT10: OROYA | CU10: PACHACHACA | CV10: MANTA I | CW10: CS YARUCAYA | CX10: SAN JUAN | CY10: MATARANI | CZ10: DUNA | DA10: CARHUAQUERO (CS) | DB10: ANASHIRONI | DC10: CARHUAQUERO4 | DD10: CAÑA BRAVA | DE10: SUNNY | DF10: SUNNY EXPANSION | DG10: TUPURI | DH10: RONCADOR | DI10: CANCHAYLLO | DJ10: RENOVANDESH1 | DK10: POTRERO | DL10: PIZARRAS | DM10: NIMPERIAL | DN10: YARUCAYA | DO10: MOQUEGUA-SOLAR | DP10: PANAMERICANA-SOLAR | DQ10: PQE-EOLICO-MARCONA | DR10: PQE-EOLICO-3-HERMANAS | DS10: TACNA-SOLAR | DT10: YANAPAMPA | DU10: CARHUAC | DV10: HUALLIN | DW10: PURMACANA | DX10: COENERGY | DY10: HUASAHUASI | DZ10: STACRUZ_1_2 | EA10: RUNATULLO_II | EB10: RUNATULLO_III | EC10: PQE-EOLICO-TALARA | ED10: PQE-EOLICO-CUPISNIQUE | EE10: INTIPAMPA | EF10: PUNTA LOMITAS-BL1 | EG10: PUNTA LOMITAS-BL2 | EH10: PUN LOMITAS_EXP-BL1 | EI10: PUN LOMITAS_EXP-BL2 | EJ10: EXPANSIÓN INTIPAMPA | EK10: 8AGOSTO | EL10: EL CARMEN | EM10: LA JOYA | EN10: ANGEL_I | EO10: ANGEL_II | EP10: ANGEL_III | EQ10: HUAMBOS | ER10: SAN MARTIN SOLAR | ES10: MAJES | ET10: RUBI | EU10: CH_HER1 | EV10: WAYRA-I | EW10: WAYRA EXTENSION | EX10: CLEMESI | EY10: HUAYCOLORO | EZ10: CALLAO | FA10: DONA_CATALINA | FB10: LAGRINGAV | FC10: REPARTICION | FD10: POECHOS2 | FE10: CHANCAY | FF10: RUCUY | FG10: CANA BRAVA | FH10: REFINERIA TALARA TV1 | FI10: REFINERÍA TALARA TV2 | FJ10: PARAMONGA | FK10: MAPLE | FL10: SAN_JACINTO | FM10: AGROLMOS | FN10: CASA GRANDE | FO10: MW | FQ10: CARPAPATA | FR10: CENTRALES ELOR | FS10: PIAS1 | FT10: ZANA | FU10: TABLAZO | FV10: TALLANCA | FW10: CURUMUY | FX10: POECHOS1 | FY10: MW
A11: 10/02/2026 | B11: 00:30 | C11: 201.8 | D11: 637.8 | E11: 216.4 | H11: 89.2 | I11: 241.9 | L11: 141.2 | M11: 141.5 | N11: 141.3 | O11: 245.2 | P11: 205.9 | Q11: 108.7 | R11: 554.8 | S11: 10.3 | X11: 168.4 | Y11: 7.3 | Z11: 5.4 | AA11: 0 | AB11: 6.7 | AD11: 141.6 | AI11: 110.3 | AJ11: 199 | AN11: 6.5 | AO11: 459.2 | AP11: 80.4 | AQ11: 152.6 | AR11: 42.1 | AS11: 18.4 | AT11: 18.8 | AU11: 92.3 | AY11: 106.2 | AZ11: 0 | BA11: 45.7 | BB11: 4 | BC11: 32.9 | BD11: 160.4 | BG11: 0 | BJ11: 0 | BN11: 127.4 | BP11: 0 | BQ11: 0 | BS11: 38.1 | BT11: 27.6 | CA11: 2.3 | CB11: 46.8 | CC11: 101.9 | CD11: 64 | CE11: 76.6 | CF11: 26 | CJ11: 142.3 | CK11: 143.1 | CL11: 147.9 | CR11: 208.5 | CS11: 100.4 | CT11: 7 | CU11: 4.3 | CV11: 20 | CW11: 0 | CX11: 31.6 | CY11: 0 | CZ11: 0 | DA11: 0 | DB11: 20.3 | DC11: 10 | DD11: 5.5 | DE11: 0 | DG11: 2.1 | DH11: 1.8 | DI11: 5 | DJ11: 20.3 | DK11: 20 | DL11: 18.8 | DM11: 2.7 | DN11: 18.4 | DO11: 0 | DP11: 0 | DQ11: 15.2 | DR11: 29.3 | DS11: 0 | DT11: 3.5 | DU11: 6 | DV11: 2.8 | DW11: 0.4 | DX11: 0 | DY11: 19.8 | DZ11: 8 | EA11: 20.3 | EB11: 20.2 | EC11: 3.2 | ED11: 5.1 | EE11: 0 | EF11: 32.9 | EG11: 73.9 | EH11: 2.6 | EI11: 1.7 | EJ11: 0 | EK11: 21 | EL11: 6.2 | EM11: 7.2 | EN11: 20.4 | EO11: 20.4 | EP11: 20.1 | EQ11: 0.25 | ER11: 0 | ES11: 0 | ET11: 0 | EU11: 0 | EV11: 17.2 | EW11: 14.2 | EX11: 0 | EY11: 3.6 | EZ11: 1.1 | FA11: 2.4 | FB11: 0.9 | FC11: 0 | FD11: 8.4 | FE11: 20 | FF11: 20 | FG11: 9.4 | FH11: 27.6 | FI11: 34.4 | FJ11: 15 | FK11: 15.5 | FL11: 7.9 | FM11: 11.7 | FN11: 22.4 | FO11: 6807.05 | FQ11: 24.6 | FR11: 7.95 | FS11: 11.9 | FT11: 13.2 | FU11: 25.2 | FV11: 18.94327 | FW11: 12.2 | FX11: 15.7 | FY11: 129.69327
A12: 10/02/2026 | B12: 01:00 | C12: 197.4 | D12: 626.9 | E12: 213.1 | H12: 86.6 | I12: 235.9 | L12: 120.8 | M12: 120.3 | N12: 120.2 | O12: 224.2 | P12: 207 | Q12: 109.5 | R12: 549.3 | S12: 9.9 | X12: 154 | Y12: 7.1 | Z12: 5 | AA12: 0 | AB12: 6.7 | AD12: 141.4 | AI12: 108.4 | AJ12: 204.6 | AN12: 6.5 | AO12: 452.4 | AP12: 80.2 | AQ12: 149.9 | AR12: 41.7 | AS12: 18.6 | AT12: 18.8 | AU12: 88.2 | AY12: 100.3 | AZ12: 0 | BA12: 45 | BB12: 4 | BC12: 30.8 | BD12: 151.8 | BG12: 0 | BJ12: 0 | BN12: 123.1 | BP12: 0 | BQ12: 0 | BS12: 39.1 | BT12: 27.8 | CA12: 2.3 | CB12: 56.6 | CC12: 102.6 | CD12: 60.4 | CE12: 74.8 | CF12: 20.8 | CJ12: 141.3 | CK12: 142.3 | CL12: 146.4 | CR12: 208.5 | CS12: 100.5 | CT12: 6.9 | CU12: 4.4 | CV12: 20 | CW12: 0 | CX12: 32.9 | CY12: 0 | CZ12: 0 | DA12: 0 | DB12: 19.6 | DC12: 9.9 | DD12: 5.5 | DE12: 0 | DG12: 2.1 | DH12: 1.8 | DI12: 5 | DJ12: 19.9 | DK12: 20 | DL12: 18.7 | DM12: 2.7 | DN12: 18.4 | DO12: 0 | DP12: 0 | DQ12: 15.9 | DR12: 24 | DS12: 0 | DT12: 3.5 | DU12: 3.2 | DV12: 2.8 | DW12: 0.4 | DX12: 0 | DY12: 19.8 | DZ12: 8 | EA12: 19.9 | EB12: 20.1 | EC12: 2.1 | ED12: 4.2 | EE12: 0 | EF12: 19.1 | EG12: 54.2 | EH12: 1.5 | EI12: 0.8 | EJ12: 0 | EK12: 21 | EL12: 6.2 | EM12: 6.9 | EN12: 20.4 | EO12: 20.4 | EP12: 20.1 | EQ12: 0 | ER12: 0 | ES12: 0 | ET12: 0 | EU12: 0 | EV12: 14.6 | EW12: 7.4 | EX12: 0 | EY12: 3.6 | EZ12: 1.1 | FA12: 2.4 | FB12: 0.9 | FC12: 0 | FD12: 8.4 | FE12: 20 | FF12: 20 | FG12: 9.5 | FH12: 27.4 | FI12: 34.1 | FJ12: 15.1 | FK12: 17.1 | FL12: 8.3 | FM12: 11.7 | FN12: 21.7 | FO12: 6588.6 | FQ12: 24.5 | FR12: 7.96 | FS12: 12 | FT12: 13.2 | FU12: 24.8 | FV12: 18.94314 | FW12: 12 | FX12: 15.7 | FY12: 129.10314
A13: 10/02/2026 | B13: 01:30 | C13: 205.7 | D13: 639.7 | E13: 216.6 | H13: 90.6 | I13: 243.6 | L13: 131.1 | M13: 130.2 | N13: 131.3 | O13: 217.7 | P13: 205.4 | Q13: 108.7 | R13: 568.5 | S13: 10.2 | X13: 165.2 | Y13: 7.6 | Z13: 5.4 | AA13: 0 | AB13: 6.7 | AD13: 143.2 | AI13: 110.3 | AJ13: 170.7 | AN13: 6.5 | AO13: 455 | AP13: 80 | AQ13: 153.9 | AR13: 42.1 | AS13: 18.6 | AT13: 18.8 | AU13: 91.7 | AY13: 106.8 | AZ13: 0 | BA13: 46.4 | BB13: 4 | BC13: 33.9 | BD13: 84.8 | BG13: 0 | BJ13: 0 | BN13: 127.9 | BP13: 0 | BQ13: 0 | BS13: 37.6 | BT13: 27.7 | CA13: 2.3 | CB13: 67.1 | CC13: 105.5 | CD13: 62.9 | CE13: 76.4 | CF13: 30.2 | CJ13: 111 | CK13: 110.8 | CL13: 130.1 | CR13: 208.5 | CS13: 100.5 | CT13: 6.9 | CU13: 4.2 | CV13: 20 | CW13: 0 | CX13: 27.8 | CY13: 0 | CZ13: 0 | DA13: 0 | DB13: 20.4 | DC13: 9.9 | DD13: 5.3 | DE13: 0 | DG13: 2.1 | DH13: 1.8 | DI13: 5.1 | DJ13: 20.4 | DK13: 20 | DL13: 18.7 | DM13: 2.7 | DN13: 18.4 | DO13: 0 | DP13: 0 | DQ13: 14.3 | DR13: 26.3 | DS13: 0 | DT13: 3.4 | DU13: 3.4 | DV13: 2.8 | DW13: 0.4 | DX13: 0 | DY13: 19.8 | DZ13: 8.1 | EA13: 19.9 | EB13: 20.2 | EC13: 1.9 | ED13: 0.5 | EE13: 0 | EF13: 15.9 | EG13: 53.6 | EH13: 1.9 | EI13: 1 | EJ13: 0 | EK13: 21 | EL13: 6.2 | EM13: 0 | EN13: 20.4 | EO13: 20.4 | EP13: 20.1 | EQ13: 0 | ER13: 0 | ES13: 0 | ET13: 0 | EU13: 0 | EV13: 7.4 | EW13: 4.4 | EX13: 0 | EY13: 3.6 | EZ13: 1.1 | FA13: 2.4 | FB13: 0.9 | FC13: 0 | FD13: 8.3 | FE13: 20 | FF13: 20 | FG13: 9.3 | FH13: 27.7 | FI13: 34.5 | FJ13: 14.5 | FK13: 17.1 | FL13: 7.6 | FM13: 11.7 | FN13: 22.3 | FO13: 6527.4 | FQ13: 24.5 | FR13: 7.95 | FS13: 11.9 | FT13: 13.2 | FU13: 25.2 | FV13: 18.94322 | FW13: 12 | FX13: 15.6 | FY13: 129.29322
A14: 10/02/2026 | B14: 02:00 | C14: 203.9 | D14: 641.6 | E14: 217 | H14: 90.7 | I14: 242.4 | L14: 115.9 | M14: 115.7 | N14: 115.1 | O14: 219.5 | P14: 182.2 | Q14: 103.8 | R14: 561.2 | S14: 10.3 | X14: 170 | Y14: 7.7 | Z14: 5.4 | AA14: 0 | AB14: 6.7 | AD14: 142.1 | AI14: 110.5 | AJ14: 173.7 | AN14: 6.5 | AO14: 458.6 | AP14: 80.4 | AQ14: 152.8 | AR14: 42.1 | AS14: 18.6 | AT14: 18.8 | AU14: 94.2 | AY14: 107.2 | AZ14: 0 | BA14: 46.7 | BB14: 4 | BC14: 33.7 | BD14: 93.8 | BG14: 0 | BJ14: 0 | BN14: 128.7 | BP14: 0 | BQ14: 0 | BS14: 38 | BT14: 27.7 | CA14: 2.3 | CB14: 88.7 | CC14: 99.1 | CD14: 64.3 | CE14: 73.1 | CF14: 30.6 | CJ14: 103.6 | CK14: 103.5 | CL14: 121.5 | CR14: 208.6 | CS14: 100.3 | CT14: 6.9 | CU14: 4.3 | CV14: 20 | CW14: 0 | CX14: 31.1 | CY14: 0 | CZ14: 0 | DA14: 0 | DB14: 20.4 | DC14: 9.9 | DD14: 5.4 | DE14: 0 | DG14: 2.1 | DH14: 1.8 | DI14: 5.1 | DJ14: 20.7 | DK14: 20 | DL14: 18.7 | DM14: 2.8 | DN14: 18.4 | DO14: 0 | DP14: 0 | DQ14: 20.8 | DR14: 24.1 | DS14: 0 | DT14: 3.5 | DU14: 3.4 | DV14: 2.7 | DW14: 0.4 | DX14: 0 | DY14: 19.8 | DZ14: 8 | EA14: 20.1 | EB14: 20.2 | EC14: 2.9 | ED14: 0 | EE14: 0 | EF14: 11.6 | EG14: 39.6 | EH14: 0.8 | EI14: 0.3 | EJ14: 0 | EK14: 21 | EL14: 6.2 | EM14: 0 | EN14: 20.4 | EO14: 20.4 | EP14: 20.1 | EQ14: 0 | ER14: 0 | ES14: 0 | ET14: 0 | EU14: 0 | EV14: 1.5 | EW14: 1.4 | EX14: 0 | EY14: 3.6 | EZ14: 1.1 | FA14: 2.4 | FB14: 0.9 | FC14: 0 | FD14: 8.4 | FE14: 20 | FF14: 20 | FG14: 9.3 | FH14: 27.9 | FI14: 34.7 | FJ14: 14.5 | FK14: 17.1 | FL14: 8.3 | FM14: 11.7 | FN14: 22.7 | FO14: 6442.2 | FQ14: 24.6 | FR14: 7.95 | FS14: 11.8 | FT14: 13.2 | FU14: 25.3 | FV14: 18.94335 | FW14: 12 | FX14: 15.7 | FY14: 129.49335
A15: 10/02/2026 | B15: 02:30 | C15: 198.7 | D15: 631.2 | E15: 214.6 | H15: 89.3 | I15: 238.4 | L15: 140.6 | M15: 139.9 | N15: 139.2 | O15: 226.8 | P15: 108.8 | Q15: 72.4 | R15: 551.7 | S15: 9.9 | X15: 155.9 | Y15: 7.1 | Z15: 5.2 | AA15: 0 | AB15: 6.7 | AD15: 141.9 | AI15: 108.5 | AJ15: 223.5 | AN15: 6.5 | AO15: 456.6 | AP15: 79.9 | AQ15: 149.8 | AR15: 41.9 | AS15: 18.6 | AT15: 18.8 | AU15: 87.5 | AY15: 104.1 | AZ15: 0 | BA15: 44.6 | BB15: 4 | BC15: 32.2 | BD15: 85.9 | BG15: 0 | BJ15: 0 | BN15: 128.4 | BP15: 0 | BQ15: 0 | BS15: 38.2 | BT15: 27.8 | CA15: 2.3 | CB15: 101 | CC15: 93.5 | CD15: 60.8 | CE15: 71.2 | CF15: 29 | CJ15: 103.1 | CK15: 103.2 | CL15: 122 | CR15: 192.4 | CS15: 96.9 | CT15: 6.9 | CU15: 4.2 | CV15: 20 | CW15: 0 | CX15: 18.9 | CY15: 0 | CZ15: 0 | DA15: 0 | DB15: 20.1 | DC15: 10 | DD15: 5.5 | DE15: 0 | DG15: 2.1 | DH15: 1.8 | DI15: 5 | DJ15: 19.7 | DK15: 20 | DL15: 18.8 | DM15: 2.8 | DN15: 18.4 | DO15: 0 | DP15: 0 | DQ15: 17.7 | DR15: 22.5 | DS15: 0 | DT15: 3.4 | DU15: 3.4 | DV15: 2.7 | DW15: 0.4 | DX15: 0 | DY15: 19.8 | DZ15: 8.1 | EA15: 19.6 | EB15: 20.1 | EC15: 1.7 | ED15: 0 | EE15: 0 | EF15: 19.7 | EG15: 42.2 | EH15: 1.1 | EI15: 0.6 | EJ15: 0 | EK15: 21 | EL15: 6.2 | EM15: 0 | EN15: 20.4 | EO15: 20.4 | EP15: 20.1 | EQ15: 0 | ER15: 0 | ES15: 0 | ET15: 0 | EU15: 0 | EV15: 0 | EW15: 0 | EX15: 0 | EY15: 3.7 | EZ15: 1.1 | FA15: 2.4 | FB15: 0.9 | FC15: 0 | FD15: 8.4 | FE15: 20 | FF15: 20 | FG15: 9.3 | FH15: 27.7 | FI15: 34.5 | FJ15: 15 | FK15: 17.1 | FL15: 7.7 | FM15: 11.7 | FN15: 21.6 | FO15: 6356.9 | FQ15: 24.6 | FR15: 7.95 | FS15: 11.8 | FT15: 13.2 | FU15: 25.2 | FV15: 18.9434 | FW15: 12 | FX15: 15.6 | FY15: 129.2934
A16: 10/02/2026 | B16: 03:00 | C16: 204.6 | D16: 641.3 | E16: 216.3 | H16: 90.3 | I16: 244.9 | L16: 139.5 | M16: 139 | N16: 139.5 | O16: 224.3 | P16: 107.9 | Q16: 67 | R16: 565.2 | S16: 10.3 | X16: 163.9 | Y16: 7.6 | Z16: 5.4 | AA16: 0 | AB16: 6.7 | AD16: 142.7 | AI16: 110.4 | AJ16: 222.4 | AN16: 6.5 | AO16: 457 | AP16: 74 | AQ16: 153.7 | AR16: 42.1 | AS16: 18.6 | AT16: 18.8 | AU16: 93.5 | AY16: 107.9 | AZ16: 0 | BA16: 46.5 | BB16: 4 | BC16: 34.1 | BD16: 91.4 | BG16: 0 | BJ16: 0 | BN16: 128.4 | BP16: 0 | BQ16: 0 | BS16: 37.9 | BT16: 27.8 | CA16: 2.3 | CB16: 110.6 | CC16: 109.3 | CD16: 63.5 | CE16: 73 | CF16: 30.2 | CJ16: 103.1 | CK16: 103 | CL16: 121.7 | CR16: 137.2 | CS16: 78.2 | CT16: 7 | CU16: 4.3 | CV16: 10 | CW16: 0 | CX16: 15.3 | CY16: 0 | CZ16: 0 | DA16: 0 | DB16: 20.3 | DC16: 9.9 | DD16: 5.4 | DE16: 0 | DG16: 2.1 | DH16: 1.8 | DI16: 5 | DJ16: 20.4 | DK16: 20 | DL16: 18.8 | DM16: 2.8 | DN16: 18.4 | DO16: 0 | DP16: 0 | DQ16: 10.8 | DR16: 27.6 | DS16: 0 | DT16: 3.5 | DU16: 3.4 | DV16: 2.7 | DW16: 0.4 | DX16: 0 | DY16: 19.8 | DZ16: 8.1 | EA16: 19.8 | EB16: 20.2 | EC16: 1.3 | ED16: 0.2 | EE16: 0 | EF16: 19.7 | EG16: 48 | EH16: 1.2 | EI16: 0.9 | EJ16: 0 | EK16: 21 | EL16: 6.2 | EM16: 0 | EN16: 20.4 | EO16: 20.4 | EP16: 20.1 | EQ16: 0 | ER16: 0 | ES16: 0 | ET16: 0 | EU16: 0 | EV16: 2.9 | EW16: 3.1 | EX16: 0 | EY16: 3.7 | EZ16: 1.1 | FA16: 2.4 | FB16: 0.9 | FC16: 0 | FD16: 8.4 | FE16: 20 | FF16: 20 | FG16: 9.2 | FH16: 27.9 | FI16: 34.6 | FJ16: 14.5 | FK16: 17.1 | FL16: 8.6 | FM16: 11.7 | FN16: 22.4 | FO16: 6369.2 | FQ16: 24.5 | FR16: 7.95 | FS16: 11.8 | FT16: 13.2 | FU16: 25.5 | FV16: 18.94298 | FW16: 12 | FX16: 15.4 | FY16: 129.29298
A17: 10/02/2026 | B17: 03:30 | C17: 198.8 | D17: 629.9 | E17: 214.1 | H17: 88.9 | I17: 241.4 | L17: 111.9 | M17: 112.1 | N17: 112.3 | O17: 225.9 | P17: 162 | Q17: 82.8 | R17: 547.9 | S17: 10 | X17: 166.2 | Y17: 7.3 | Z17: 5.1 | AA17: 0 | AB17: 6.7 | AD17: 140.6 | AI17: 110.3 | AJ17: 175.4 | AN17: 6.5 | AO17: 457.6 | AP17: 77 | AQ17: 134.2 | AR17: 42.1 | AS17: 18.4 | AT17: 18.8 | AU17: 93 | AY17: 104.7 | AZ17: 0 | BA17: 45.1 | BB17: 4 | BC17: 32.7 | BD17: 88.2 | BG17: 0 | BJ17: 0 | BN17: 127.4 | BP17: 0 | BQ17: 0 | BS17: 38.3 | BT17: 27.8 | CA17: 0.6 | CB17: 39.6 | CC17: 87.6 | CD17: 62.9 | CE17: 72.6 | CF17: 29.9 | CJ17: 103.1 | CK17: 102.9 | CL17: 121.4 | CR17: 184.1 | CS17: 88.8 | CT17: 6.9 | CU17: 4.2 | CV17: 10 | CW17: 0 | CX17: 17.9 | CY17: 0 | CZ17: 0 | DA17: 0 | DB17: 20.3 | DC17: 9.9 | DD17: 5.4 | DE17: 0 | DG17: 2.1 | DH17: 1.8 | DI17: 5 | DJ17: 20.3 | DK17: 20 | DL17: 18.8 | DM17: 2.8 | DN17: 18.4 | DO17: 0 | DP17: 0 | DQ17: 12.4 | DR17: 25.1 | DS17: 0 | DT17: 3.5 | DU17: 3.4 | DV17: 2.7 | DW17: 0.4 | DX17: 0 | DY17: 19.8 | DZ17: 8.2 | EA17: 19.9 | EB17: 20.1 | EC17: 0.6 | ED17: 0.5 | EE17: 0 | EF17: 22 | EG17: 64.6 | EH17: 2.5 | EI17: 0.9 | EJ17: 0 | EK17: 21 | EL17: 6.2 | EM17: 0 | EN17: 20.4 | EO17: 20.4 | EP17: 20.1 | EQ17: 0 | ER17: 0 | ES17: 0 | ET17: 0 | EU17: 0 | EV17: 10.1 | EW17: 15.4 | EX17: 0 | EY17: 3.7 | EZ17: 1.1 | FA17: 2.4 | FB17: 0.9 | FC17: 0 | FD17: 8.4 | FE17: 19.9 | FF17: 19.9 | FG17: 9.1 | FH17: 27.9 | FI17: 34.8 | FJ17: 14.5 | FK17: 17.1 | FL17: 8.1 | FM17: 11.7 | FN17: 22 | FO17: 6244.4 | FQ17: 24.6 | FR17: 7.95 | FS17: 11.9 | FT17: 13.2 | FU17: 25.4 | FV17: 18.94304 | FW17: 12 | FX17: 15.7 | FY17: 129.69304
A18: 10/02/2026 | B18: 04:00 | C18: 198.2 | D18: 626.3 | E18: 212.3 | H18: 88.4 | I18: 240 | L18: 105.6 | M18: 105.9 | N18: 105.9 | O18: 211.5 | P18: 162.9 | Q18: 91.9 | R18: 541.7 | S18: 10 | X18: 161 | Y18: 7.1 | Z18: 5.1 | AA18: 0 | AB18: 6.7 | AD18: 140.9 | AI18: 109.2 | AJ18: 168.1 | AN18: 6.5 | AO18: 456.9 | AP18: 80.2 | AQ18: 129.2 | AR18: 41.9 | AS18: 18.5 | AT18: 18.8 | AU18: 87.6 | AY18: 104.5 | AZ18: 0 | BA18: 44.6 | BB18: 4 | BC18: 32.3 | BD18: 85.2 | BG18: 0 | BJ18: 0 | BN18: 125.7 | BP18: 0 | BQ18: 0 | BS18: 38.1 | BT18: 27.8 | CA18: 0.6 | CB18: 37.4 | CC18: 81.7 | CD18: 61.7 | CE18: 72 | CF18: 29.3 | CJ18: 102.7 | CK18: 102.5 | CL18: 121.3 | CR18: 208.8 | CS18: 100.3 | CT18: 6.9 | CU18: 4.3 | CV18: 13.5 | CW18: 0 | CX18: 19 | CY18: 0 | CZ18: 0 | DA18: 0 | DB18: 20.1 | DC18: 9.9 | DD18: 5.4 | DE18: 0 | DG18: 2.1 | DH18: 1.8 | DI18: 5 | DJ18: 19.9 | DK18: 20 | DL18: 18.9 | DM18: 2.7 | DN18: 18.4 | DO18: 0 | DP18: 0 | DQ18: 16 | DR18: 27 | DS18: 0 | DT18: 3.5 | DU18: 3.4 | DV18: 2.7 | DW18: 0.4 | DX18: 0 | DY18: 19.8 | DZ18: 8.2 | EA18: 19.8 | EB18: 20.1 | EC18: 0.4 | ED18: 1 | EE18: 0 | EF18: 36.4 | EG18: 79.7 | EH18: 2.3 | EI18: 1.9 | EJ18: 0 | EK18: 21 | EL18: 6.2 | EM18: 0 | EN18: 20.4 | EO18: 20.4 | EP18: 20.1 | EQ18: 0.21 | ER18: 0 | ES18: 0 | ET18: 0 | EU18: 0 | EV18: 21.4 | EW18: 18.2 | EX18: 0 | EY18: 3.7 | EZ18: 1.1 | FA18: 2.4 | FB18: 0.9 | FC18: 0 | FD18: 8.4 | FE18: 20 | FF18: 20 | FG18: 9.3 | FH18: 27.7 | FI18: 34.5 | FJ18: 14.5 | FK18: 17.1 | FL18: 8.1 | FM18: 11.6 | FN18: 21.7 | FO18: 6258.21 | FQ18: 24.5 | FR18: 7.95 | FS18: 11.9 | FT18: 13.2 | FU18: 25.3 | FV18: 18.94285 | FW18: 12 | FX18: 15.7 | FY18: 129.49285
A19: 10/02/2026 | B19: 04:30 | C19: 201.2 | D19: 635.2 | E19: 214.8 | H19: 89.9 | I19: 241.9 | L19: 118.3 | M19: 118.9 | N19: 118.4 | O19: 211.4 | P19: 107.7 | Q19: 71.5 | R19: 558.6 | S19: 10.1 | X19: 156.5 | Y19: 7.5 | Z19: 5.5 | AA19: 0 | AB19: 6.7 | AD19: 142 | AI19: 110.1 | AJ19: 159.4 | AN19: 6.5 | AO19: 458 | AP19: 79.8 | AQ19: 141.4 | AR19: 42.1 | AS19: 18.5 | AT19: 18.8 | AU19: 90.8 | AY19: 105.5 | AZ19: 0 | BA19: 45.5 | BB19: 4 | BC19: 33.1 | BD19: 89 | BG19: 0 | BJ19: 0 | BN19: 127.9 | BP19: 0 | BQ19: 0 | BS19: 37.9 | BT19: 27.7 | CA19: 0.3 | CB19: 45.2 | CC19: 113.8 | CD19: 63.1 | CE19: 70.9 | CF19: 30 | CJ19: 103 | CK19: 102.9 | CL19: 121.2 | CR19: 208.3 | CS19: 100.2 | CT19: 6.9 | CU19: 4.3 | CV19: 19.5 | CW19: 0 | CX19: 13 | CY19: 0 | CZ19: 0 | DA19: 0 | DB19: 20.2 | DC19: 10 | DD19: 5.4 | DE19: 0 | DG19: 2.1 | DH19: 1.8 | DI19: 4.9 | DJ19: 20.1 | DK19: 20 | DL19: 18.7 | DM19: 2.7 | DN19: 18.4 | DO19: 0 | DP19: 0 | DQ19: 14.9 | DR19: 28.5 | DS19: 0 | DT19: 3.5 | DU19: 3.4 | DV19: 2.7 | DW19: 0.4 | DX19: 0 | DY19: 19.8 | DZ19: 8.1 | EA19: 19.8 | EB19: 20.2 | EC19: 1 | ED19: 1.6 | EE19: 0 | EF19: 34 | EG19: 72 | EH19: 4.3 | EI19: 2.2 | EJ19: 0 | EK19: 21 | EL19: 6.2 | EM19: 0 | EN19: 20.4 | EO19: 20.4 | EP19: 20.1 | EQ19: 0.29 | ER19: 0 | ES19: 0 | ET19: 0 | EU19: 0 | EV19: 35.7 | EW19: 42.5 | EX19: 0 | EY19: 3.7 | EZ19: 1.1 | FA19: 2.4 | FB19: 0.9 | FC19: 0 | FD19: 8.4 | FE19: 20 | FF19: 19.9 | FG19: 9.4 | FH19: 27.4 | FI19: 34.1 | FJ19: 15 | FK19: 17.1 | FL19: 8.4 | FM19: 11.7 | FN19: 22 | FO19: 6343.49 | FQ19: 24.6 | FR19: 7.95 | FS19: 11.8 | FT19: 13.2 | FU19: 25.3 | FV19: 18.94279 | FW19: 12 | FX19: 15.6 | FY19: 129.39279
A20: 10/02/2026 | B20: 05:00 | C20: 202.1 | D20: 633.4 | E20: 214.3 | H20: 89.7 | I20: 241.7 | L20: 115.6 | M20: 117 | N20: 117 | O20: 210.7 | P20: 107.1 | Q20: 66.8 | R20: 559.1 | S20: 10.3 | X20: 166.9 | Y20: 7.4 | Z20: 5.5 | AA20: 0 | AB20: 6.7 | AD20: 142.1 | AI20: 110.2 | AJ20: 162.5 | AN20: 6.5 | AO20: 455.1 | AP20: 80.2 | AQ20: 137.9 | AR20: 42.1 | AS20: 18.5 | AT20: 18.8 | AU20: 91.4 | AY20: 105.7 | AZ20: 0 | BA20: 45.7 | BB20: 4 | BC20: 33.2 | BD20: 77.8 | BG20: 0 | BJ20: 0 | BN20: 127.5 | BP20: 0 | BQ20: 0 | BS20: 37.9 | BT20: 27.6 | CA20: 1 | CB20: 44.2 | CC20: 109.8 | CD20: 62.9 | CE20: 70.9 | CF20: 29.8 | CJ20: 102.6 | CK20: 102.5 | CL20: 121.1 | CR20: 208.5 | CS20: 100 | CT20: 6.9 | CU20: 4.2 | CV20: 20 | CW20: 0 | CX20: 20.8 | CY20: 0 | CZ20: 0.15 | DA20: 0 | DB20: 20.2 | DC20: 9.9 | DD20: 5.3 | DE20: 0 | DG20: 2.1 | DH20: 1.8 | DI20: 4.9 | DJ20: 20 | DK20: 20 | DL20: 18.8 | DM20: 2.6 | DN20: 18.4 | DO20: 0 | DP20: 0 | DQ20: 9.9 | DR20: 19.3 | DS20: 0 | DT20: 3.5 | DU20: 3.4 | DV20: 2.7 | DW20: 0.4 | DX20: 0 | DY20: 19.8 | DZ20: 8.2 | EA20: 19.9 | EB20: 20.2 | EC20: 1.1 | ED20: 5.1 | EE20: 0 | EF20: 23.8 | EG20: 49.6 | EH20: 1.8 | EI20: 0.8 | EJ20: 0 | EK20: 21 | EL20: 6.2 | EM20: 0 | EN20: 20.4 | EO20: 20.4 | EP20: 20.1 | EQ20: 0.56 | ER20: 0 | ES20: 0 | ET20: 0 | EU20: 0 | EV20: 63.4 | EW20: 45.2 | EX20: 0 | EY20: 3.7 | EZ20: 1.1 | FA20: 2.4 | FB20: 0.9 | FC20: 0 | FD20: 8.4 | FE20: 19.8 | FF20: 19.8 | FG20: 9.1 | FH20: 26.9 | FI20: 33.4 | FJ20: 15.4 | FK20: 17.1 | FL20: 8.4 | FM20: 11.7 | FN20: 22 | FO20: 6312.21 | FQ20: 24.5 | FR20: 7.95 | FS20: 11.8 | FT20: 13.2 | FU20: 24.8 | FV20: 18.94249 | FW20: 12 | FX20: 15.6 | FY20: 128.79249
A21: 10/02/2026 | B21: 05:30 | C21: 202.1 | D21: 639.2 | E21: 216.3 | H21: 90.1 | I21: 241.8 | L21: 137.2 | M21: 136.2 | N21: 136.1 | O21: 228.8 | P21: 107.9 | Q21: 66.5 | R21: 561 | S21: 10.3 | X21: 165.4 | Y21: 7.6 | Z21: 5.5 | AA21: 0 | AB21: 1.7 | AD21: 142.6 | AI21: 110.2 | AJ21: 208 | AN21: 6.5 | AO21: 460.2 | AP21: 79.5 | AQ21: 152.3 | AR21: 42.1 | AS21: 18.6 | AT21: 18.8 | AU21: 90.5 | AY21: 107 | AZ21: 0 | BA21: 46.4 | BB21: 4 | BC21: 34 | BD21: 92.9 | BG21: 0 | BJ21: 0 | BN21: 128 | BP21: 0 | BQ21: 0 | BS21: 37.6 | BT21: 27.8 | CA21: 2 | CB21: 58.9 | CC21: 124 | CD21: 63.7 | CE21: 71 | CF21: 30.2 | CJ21: 103.7 | CK21: 103.2 | CL21: 122.1 | CR21: 209 | CS21: 100.8 | CT21: 7 | CU21: 4.3 | CV21: 20 | CW21: 0 | CX21: 34.5 | CY21: 0 | CZ21: 0.49 | DA21: 0 | DB21: 20.3 | DC21: 9.9 | DD21: 5.4 | DE21: 0 | DG21: 2.1 | DH21: 1.8 | DI21: 5 | DJ21: 20.3 | DK21: 20 | DL21: 18.9 | DM21: 2.6 | DN21: 18.4 | DO21: 0.1 | DP21: 0 | DQ21: 11.3 | DR21: 31.5 | DS21: 0 | DT21: 3.5 | DU21: 3.4 | DV21: 2.7 | DW21: 0.4 | DX21: 0 | DY21: 19.8 | DZ21: 8.2 | EA21: 19.9 | EB21: 20.2 | EC21: 0.7 | ED21: 3.8 | EE21: 0 | EF21: 14.4 | EG21: 51.7 | EH21: 0.6 | EI21: 0 | EJ21: 0 | EK21: 21 | EL21: 6.2 | EM21: 0 | EN21: 20.4 | EO21: 20.4 | EP21: 20.1 | EQ21: 0.8 | ER21: 0 | ES21: 0 | ET21: 0 | EU21: 0 | EV21: 42.2 | EW21: 27.4 | EX21: 0 | EY21: 3.7 | EZ21: 1.1 | FA21: 2.4 | FB21: 0.9 | FC21: 0 | FD21: 8.4 | FE21: 20 | FF21: 20 | FG21: 8.8 | FH21: 27.1 | FI21: 33.6 | FJ21: 15.4 | FK21: 17.2 | FL21: 6.9 | FM21: 11.7 | FN21: 20.7 | FO21: 6488.89 | FQ21: 24.6 | FR21: 7.96 | FS21: 10.5 | FT21: 13.2 | FU21: 25.2 | FV21: 18.94265 | FW21: 12 | FX21: 15.8 | FY21: 128.20265
A22: 10/02/2026 | B22: 06:00 | C22: 203.7 | D22: 635.1 | E22: 215.3 | H22: 90.6 | I22: 241.3 | L22: 140.6 | M22: 140.5 | N22: 140.6 | O22: 239.8 | P22: 108.5 | Q22: 67.4 | R22: 555.7 | S22: 10.2 | X22: 167.7 | Y22: 7.5 | Z22: 5.4 | AA22: 0 | AB22: 6.5 | AD22: 142.4 | AI22: 110.4 | AJ22: 222.1 | AN22: 6.5 | AO22: 456.5 | AP22: 79.7 | AQ22: 152.2 | AR22: 42.1 | AS22: 18.6 | AT22: 18.8 | AU22: 92.2 | AY22: 106.3 | AZ22: 0 | BA22: 45.8 | BB22: 4 | BC22: 33.4 | BD22: 92 | BG22: 0 | BJ22: 0 | BN22: 127.8 | BP22: 0 | BQ22: 0 | BS22: 38.1 | BT22: 27.8 | CA22: 2.4 | CB22: 73.7 | CC22: 123 | CD22: 63.5 | CE22: 69 | CF22: 30.2 | CJ22: 103.2 | CK22: 103.1 | CL22: 122 | CR22: 209.3 | CS22: 101.1 | CT22: 6.9 | CU22: 4.3 | CV22: 20 | CW22: 0 | CX22: 38.5 | CY22: 0.7 | CZ22: 0 | DA22: 0 | DB22: 20.4 | DC22: 10 | DD22: 5.4 | DE22: 0 | DG22: 2.1 | DH22: 1.8 | DI22: 5.1 | DJ22: 20.5 | DK22: 20 | DL22: 18.9 | DM22: 2.6 | DN22: 18.4 | DO22: 2.4 | DP22: 3 | DQ22: 13.5 | DR22: 39.5 | DS22: 0.8 | DT22: 3.5 | DU22: 3.4 | DV22: 2.7 | DW22: 0.4 | DX22: 0 | DY22: 19.7 | DZ22: 8.1 | EA22: 20.1 | EB22: 20.2 | EC22: 0.3 | ED22: 1.8 | EE22: 0.4 | EF22: 21.5 | EG22: 55.3 | EH22: 1.9 | EI22: 2.1 | EJ22: 0 | EK22: 21 | EL22: 6.2 | EM22: 0 | EN22: 20.4 | EO22: 20.4 | EP22: 20.1 | EQ22: 0 | ER22: 4 | ES22: 0.3 | ET22: 4.7 | EU22: 0 | EV22: 42.1 | EW22: 30.7 | EX22: 3.8 | EY22: 3.7 | EZ22: 1.1 | FA22: 2.4 | FB22: 0.9 | FC22: 0 | FD22: 8.4 | FE22: 20 | FF22: 20 | FG22: 8.8 | FH22: 27.3 | FI22: 34 | FJ22: 15.1 | FK22: 17.2 | FL22: 7.3 | FM22: 11.6 | FN22: 20.7 | FO22: 6582 | FQ22: 24.5 | FR22: 7.96 | FS22: 9.8 | FT22: 13.2 | FU22: 25 | FV22: 18.94243 | FW22: 11.9 | FX22: 15.6 | FY22: 126.90243
... A58: 11/02/2026 | B58: 00:00 | C58: 202.8 | D58: 642.3 | E58: 216.1 | H58: 90.3 | I58: 241.2 | L58: 138 | M58: 136.4 | N58: 138.8 | O58: 241.8 | P58: 204.7 | Q58: 108.3 | R58: 542.6 | S58: 10.5 | X58: 167.7 | Y58: 8.6 | Z58: 6.2 | AA58: 0 | AB58: 6.7 | AD58: 142.5 | AI58: 110.4 | AJ58: 190 | AN58: 6.5 | AO58: 458.2 | AP58: 73.5 | AQ58: 152.5 | AR58: 42 | AS58: 18.4 | AT58: 18.9 | AU58: 91.3 | AY58: 106.3 | AZ58: 15.9 | BA58: 45.1 | BB58: 4 | BC58: 34.2 | BD58: 161.4 | BG58: 0 | BJ58: 0 | BN58: 125.29 | BP58: 0 | BQ58: 0 | BS58: 37.65 | BT58: 27.35 | CA58: 2.1 | CB58: 109.4 | CC58: 101.2 | CD58: 63.1 | CE58: 73.3 | CF58: 30.2 | CJ58: 140.3 | CK58: 141 | CL58: 146.6 | CR58: 207.7 | CS58: 99.8 | CT58: 7 | CU58: 4.4 | CV58: 14 | CW58: 0 | CX58: 58.7 | CY58: 0 | CZ58: 1.15 | DA58: 0 | DB58: 20.3 | DC58: 10 | DD58: 5.5 | DE58: 0 | DG58: 1.7 | DH58: 1.8 | DI58: 5 | DJ58: 20.4 | DK58: 20 | DL58: 18.9 | DM58: 2.6 | DN58: 18.4 | DO58: 0 | DP58: 0 | DQ58: 20.4 | DR58: 60.6 | DS58: 0 | DT58: 3.4 | DU58: 3 | DV58: 2.8 | DW58: 0.3 | DX58: 0 | DY58: 19.7 | DZ58: 8 | EA58: 20.2 | EB58: 20.2 | EC58: 1.7 | ED58: 13.3 | EE58: 0 | EF58: 50.99 | EG58: 99.7 | EH58: 4.4397 | EI58: 2.4206 | EJ58: 0 | EK58: 18.2 | EL58: 5.8 | EM58: 0 | EN58: 20.4 | EO58: 20.4 | EP58: 20 | EQ58: 1.86 | ER58: 0 | ES58: 0 | ET58: 0 | EU58: 0 | EV58: 97.9 | EW58: 78.5 | EX58: 0 | EY58: 3.8 | EZ58: 2.1 | FA58: 2.4 | FB58: 0.9 | FC58: 0 | FD58: 8.1 | FE58: 20 | FF58: 20 | FG58: 8.9 | FH58: 27.2 | FI58: 34 | FJ58: 14.5 | FK58: 14.7 | FL58: 8.3 | FM58: 11.6 | FN58: 23 | FO58: 7082.6503 | FQ58: 24.6 | FR58: 7.91 | FS58: 11.6 | FT58: 13.2 | FU58: 25.5 | FV58: 18.9488 | FW58: 11.8 | FX58: 15.6 | FY58: 129.1588
A59: EJEC | C59: 4846.65 | D59: 15255.75 | E59: 5160.8 | F59: 0 | G59: 0 | H59: 2157.05 | I59: 5790.5 | J59: 0 | K59: 0 | L59: 3284.35 | M59: 3282.8 | N59: 3282.45 | O59: 5601.5 | P59: 4311.15 | Q59: 2345.6 | R59: 13288.35 | S59: 244.65 | T59: 0 | U59: 0 | V59: 0 | W59: 0 | X59: 3963.3 | Y59: 189.25 | Z59: 134.45 | AA59: 162.15 | AB59: 158 | AC59: 0 | AD59: 3410.75 | AE59: 0 | AF59: 0 | AG59: 0 | AH59: 0 | AI59: 2642.85 | AJ59: 4631.6 | AK59: 0 | AL59: 0 | AM59: 0 | AN59: 156 | AO59: 10777.85 | AP59: 1859.9 | AQ59: 3621.75 | AR59: 1008.95 | AS59: 442.7 | AT59: 451.75 | AU59: 2183 | AV59: 0 | AW59: 0 | AX59: 0 | AY59: 2538.85 | AZ59: 436.9 | BA59: 1078.55 | BB59: 96 | BC59: 795.1 | BD59: 3112 | BE59: 0 | BF59: 0 | BG59: 678.15 | BH59: 0 | BI59: 0 | BJ59: 664.75 | BK59: 0 | BL59: 0 | BM59: 0 | BN59: 3052.205 | BO59: 0 | BP59: 696.055 | BQ59: 1811.015 | BR59: 0 | BS59: 1304.675 | BT59: 745.765 | BU59: 0 | BV59: 0 | BW59: 0 | BX59: 0 | BY59: 0 | BZ59: 0 | CA59: 51.25 | CB59: 2511.15 | CC59: 2659.65 | CD59: 1521.25 | CE59: 1786.3 | CF59: 661.5 | CG59: 0 | CH59: 0 | CI59: 0 | CJ59: 3085.3 | CK59: 3095.25 | CL59: 3407.95 | CM59: 0 | CN59: 0 | CO59: 0 | CP59: 0 | CQ59: 0 | CR59: 4382.75 | CS59: 2199.65 | CT59: 166.65 | CU59: 102.7 | CV59: 435.45 | CW59: 7 | CX59: 1538.7 | CY59: 767.95 | CZ59: 39.495 | DA59: 1.45 | DB59: 486.15 | DC59: 238.3 | DD59: 130.1 | DE59: 1902.8 | DF59: 0 | DG59: 42.35 | DH59: 40.5 | DI59: 119.85 | DJ59: 485.2 | DK59: 452.35 | DL59: 451.15 | DM59: 63.3 | DN59: 441.6 | DO59: 148.3 | DP59: 181.5 | DQ59: 448.05 | DR59: 1312.1 | DS59: 143.75 | DT59: 78.5 | DU59: 230.4 | DV59: 64.15 | DW59: 7.75 | DX59: 3.05 | DY59: 474.85 | DZ59: 167.25 | EA59: 483 | EB59: 484.65 | EC59: 65.9 | ED59: 287.15 | EE59: 269.7 | EF59: 1018.925 | EG59: 1675.285 | EH59: 117.64705 | EI59: 110.61245 | EJ59: 347.5 | EK59: 475.8 | EL59: 145.45 | EM59: 7.05 | EN59: 489.6 | EO59: 489.6 | EP59: 481.4 | EQ59: 45.92 | ER59: 2243.65 | ES59: 137.5 | ET59: 1249.15 | EU59: 4.8 | EV59: 1606.85 | EW59: 1745.3 | EX59: 958.35 | EY59: 82.85 | EZ59: 26.95 | FA59: 54.75 | FB59: 21.6 | FC59: 117.35 | FD59: 197.95 | FE59: 479.75 | FF59: 479.45 | FG59: 216.45 | FH59: 658.05 | FI59: 818.25 | FJ59: 358.15 | FK59: 333.35 | FL59: 187 | FM59: 270.05 | FN59: 529.85 | FO59: 177963.15 | FQ59: 589.4 | FR59: 190.565 | FS59: 266.05 | FT59: 316.8 | FU59: 596.55 | FV59: 454.713 | FW59: 277.15 | FX59: 373.95 | FY59: 3065.178

Sheet REACTIVA
B3: martes, 10 de Febrero del 2026
A5: POTENCIA REACTIVA EJECUTADA DE LAS UNIDADES DE GENERACIÓN DEL COES (MVAR) | FQ5: CENTRALES NO INTEGRANTES COES
A6: FECHA | B6: HORA | C6: 65333 | D6: 101 | E6: 102 | F6: 42667 | G6: 42668 | H6: 126 | I6: 127 | J6: 138 | K6: 139 | L6: 197 | M6: 203 | N6: 204 | O6: 230 | P6: 209 | Q6: 56677 | R6: 796 | S6: 2146 | T6: 142 | U6: 143 | V6: 125 | W6: 187 | X6: 163 | Y6: 298 | Z6: 299 | AA6: 219 | AB6: 151 | AC6: 152 | AD6: 153 | AE6: 154 | AF6: 756 | AG6: 156 | AH6: 155 | AI6: 182 | AJ6: 212 | AK6: 758 | AL6: 263 | AM6: 265 | AN6: 775 | AO6: 777 | AP6: 2154 | AQ6: 150 | AR6: 149 | AS6: 188 | AT6: 2131 | AU6: 755 | AV6: 252 | AW6: 249 | AX6: 250 | AY6: 117 | AZ6: 119 | BA6: 120 | BB6: 189 | BC6: 122 | BD6: 266 | BE6: 337 | BF6: 338 | BG6: 251 | BH6: 115 | BI6: 239 | BJ6: 288 | BK6: 240 | BL6: 241 | BM6: 242 | BN6: 191 | BO6: 194 | BP6: 196 | BQ6: 207 | BR6: 236 | BS6: 795 | BT6: 285 | BU6: 995 | BV6: 996 | BW6: 997 | BX6: 766 | BY6: 926 | BZ6: 924 | CA6: 121 | CB6: 103 | CC6: 104 | CD6: 106 | CE6: 105 | CF6: 107 | CG6: 110 | CH6: 109 | CI6: 144 | CJ6: 113 | CK6: 114 | CL6: 193 | CM6: 208 | CN6: 786 | CO6: 787 | CP6: 788 | CQ6: 789 | CR6: 248 | CS6: 2159 | CT6: 267 | CU6: 268 | CV6: 2194 | CW6: 303 | CX6: 59715 | CY6: 62255 | CZ6: 1263 | DA6: 61800 | DB6: 69125 | DC6: 216 | DD6: 198 | DE6: 70400 | DF6: 76068 | DG6: 49607 | DH6: 214 | DI6: 260 | DJ6: 2152 | DK6: 2128 | DL6: 247 | DM6: 228 | DN6: 2135 | DO6: 261 | DP6: 237 | DQ6: 253 | DR6: 770 | DS6: 235 | DT6: 238 | DU6: 2184 | DV6: 61855 | DW6: 223 | DX6: 75566 | DY6: 226 | DZ6: 201 | EA6: 258 | EB6: 259 | EC6: 257 | ED6: 256 | EE6: 2148 | EF6: 58288 | EG6: 58289 | EH6: 58839 | EI6: 58840 | EJ6: 75260 | EK6: 296 | EL6: 297 | EM6: 211 | EN6: 2175 | EO6: 2178 | EP6: 2181 | EQ6: 1262 | ER6: 63425 | ES6: 233 | ET6: 2150 | EU6: 2165 | EV6: 2161 | EW6: 61197 | EX6: 58851 | EY6: 225 | EZ6: 2201 | FA6: 2171 | FB6: 760 | FC6: 234 | FD6: 215 | FE6: 917 | FF6: 920 | FG6: 289 | FH6: 58333 | FI6: 58336 | FJ6: 213 | FK6: 232 | FL6: 2190 | FM6: 69867 | FN6: 75066 | FO6: TOTAL COES | FQ6: 221 | FR6: 222 | FS6: 224 | FT6: 2187 | FU6: 227 | FV6: 49400 | FW6: 199 | FX6: 200 | FY6: TOTAL NO COES
C7: SUR | D7: CENTRO | E7: CENTRO | F7: NORTE | G7: NORTE | H7: NORTE | I7: NORTE | J7: CENTRO | K7: CENTRO | L7: CENTRO | M7: CENTRO | N7: CENTRO | O7: CENTRO | P7: CENTRO | Q7: CENTRO | R7: CENTRO | S7: CENTRO | T7: CENTRO | U7: CENTRO | V7: CENTRO | W7: CENTRO | X7: SUR | Y7: SUR | Z7: SUR | AA7: CENTRO | AB7: SUR | AC7: SUR | AD7: SUR | AE7: SUR | AF7: SUR | AG7: SUR | AH7: SUR | AI7: SUR | AJ7: CENTRO | AK7: NORTE | AL7: NORTE | AM7: NORTE | AN7: CENTRO | AO7: CENTRO | AP7: CENTRO | AQ7: CENTRO | AR7: CENTRO | AS7: CENTRO | AT7: CENTRO | AU7: SUR | AV7: CENTRO | AW7: CENTRO | AX7: CENTRO | AY7: CENTRO | AZ7: CENTRO | BA7: CENTRO | BB7: SUR | BC7: NORTE | BD7: CENTRO | BE7: CENTRO | BF7: CENTRO | BG7: CENTRO | BH7: NORTE | BI7: NORTE | BJ7: NORTE | BK7: SUR | BL7: SUR | BM7: SUR | BN7: CENTRO | BO7: CENTRO | BP7: CENTRO | BQ7: CENTRO | BR7: CENTRO | BS7: CENTRO | BT7: CENTRO | BU7: SUR | BV7: SUR | BW7: SUR | BX7: NORTE | BY7: SUR | BZ7: CENTRO | CA7: NORTE | CB7: CENTRO | CC7: CENTRO | CD7: CENTRO | CE7: CENTRO | CF7: CENTRO | CG7: CENTRO | CH7: CENTRO | CI7: CENTRO | CJ7: CENTRO | CK7: CENTRO | CL7: CENTRO | CM7: CENTRO | CN7: SUR | CO7: SUR | CP7: SUR | CQ7: SUR | CR7: CENTRO | CS7: CENTRO | CT7: CENTRO | CU7: CENTRO | CV7: NORTE | CW7: CENTRO | CX7: CENTRO | CY7: SUR | CZ7: NORTE | DA7: NORTE | DB7: CENTRO | DC7: NORTE | DD7: NORTE | DE7: SUR | DG7: SUR | DH7: CENTRO | DI7: CENTRO | DJ7: CENTRO | DK7: NORTE | DL7: NORTE | DM7: CENTRO | DN7: CENTRO | DO7: SUR | DP7: SUR | DQ7: CENTRO | DR7: CENTRO | DS7: SUR | DT7: CENTRO | DU7: CENTRO | DV7: NORTE | DW7: CENTRO | DX7: CENTRO | DY7: CENTRO | DZ7: NORTE | EA7: CENTRO | EB7: CENTRO | EC7: NORTE | ED7: NORTE | EE7: SUR | EF7: CENTRO | EG7: CENTRO | EH7: CENTRO | EI7: CENTRO | EJ7: SUR | EK7: CENTRO | EL7: CENTRO | EM7: SUR | EN7: SUR | EO7: SUR | EP7: SUR | EQ7: NORTE | ER7: SUR | ES7: SUR | ET7: SUR | EU7: CENTRO | EV7: CENTRO | EW7: CENTRO | EX7: SUR | EY7: CENTRO | EZ7: CENTRO | FA7: CENTRO | FB7: CENTRO | FC7: SUR | FD7: NORTE | FE7: CENTRO | FF7: CENTRO | FG7: NORTE | FH7: NORTE | FI7: NORTE | FJ7: CENTRO | FK7: NORTE | FL7: NORTE | FM7: NORTE | FN7: NORTE | FQ7: NORTE | FR7: CENTRO | FS7: NORTE | FT7: NORTE | FU7: NORTE | FV7: NORTE | FW7: NORTE | FX7: NORTE
C8: HIDROELÉCTRICA | D8: HIDROELÉCTRICA | E8: HIDROELÉCTRICA | F8: TERMOELÉCTRICA | G8: TERMOELÉCTRICA | H8: HIDROELÉCTRICA | I8: HIDROELÉCTRICA | J8: TERMOELÉCTRICA | K8: TERMOELÉCTRICA | L8: TERMOELÉCTRICA | M8: TERMOELÉCTRICA | N8: TERMOELÉCTRICA | O8: TERMOELÉCTRICA | P8: TERMOELÉCTRICA | Q8: TERMOELÉCTRICA | R8: HIDROELÉCTRICA | S8: HIDROELÉCTRICA | T8: TERMOELÉCTRICA | U8: TERMOELÉCTRICA | V8: TERMOELÉCTRICA | W8: TERMOELÉCTRICA | X8: HIDROELÉCTRICA | Y8: HIDROELÉCTRICA | Z8: HIDROELÉCTRICA | AA8: TERMOELÉCTRICA | AB8: HIDROELÉCTRICA | AC8: HIDROELÉCTRICA | AD8: HIDROELÉCTRICA | AE8: HIDROELÉCTRICA | AF8: TERMOELÉCTRICA | AG8: TERMOELÉCTRICA | AH8: TERMOELÉCTRICA | AI8: HIDROELÉCTRICA | AJ8: HIDROELÉCTRICA | AK8: TERMOELÉCTRICA | AL8: TERMOELÉCTRICA | AM8: TERMOELÉCTRICA | AN8: HIDROELÉCTRICA | AO8: HIDROELÉCTRICA | AP8: HIDROELÉCTRICA | AQ8: HIDROELÉCTRICA | AR8: HIDROELÉCTRICA | AS8: HIDROELÉCTRICA | AT8: HIDROELÉCTRICA | AU8: HIDROELÉCTRICA | AV8: TERMOELÉCTRICA | AW8: TERMOELÉCTRICA | AX8: TERMOELÉCTRICA | AY8: HIDROELÉCTRICA | AZ8: HIDROELÉCTRICA | BA8: HIDROELÉCTRICA | BB8: HIDROELÉCTRICA | BC8: HIDROELÉCTRICA | BD8: HIDROELÉCTRICA | BE8: HIDROELÉCTRICA | BF8: HIDROELÉCTRICA | BG8: HIDROELÉCTRICA | BH8: TERMOELÉCTRICA | BI8: TERMOELÉCTRICA | BJ8: TERMOELÉCTRICA | BK8: TERMOELÉCTRICA | BL8: TERMOELÉCTRICA | BM8: TERMOELÉCTRICA | BN8: HIDROELÉCTRICA | BO8: TERMOELÉCTRICA | BP8: TERMOELÉCTRICA | BQ8: TERMOELÉCTRICA | BR8: TERMOELÉCTRICA | BS8: TERMOELÉCTRICA | BT8: TERMOELÉCTRICA | BU8: TERMOELÉCTRICA | BV8: TERMOELÉCTRICA | BW8: TERMOELÉCTRICA | BX8: HIDROELÉCTRICA | BY8: TERMOELÉCTRICA | BZ8: TERMOELÉCTRICA | CA8: HIDROELÉCTRICA | CB8: HIDROELÉCTRICA | CC8: HIDROELÉCTRICA | CD8: HIDROELÉCTRICA | CE8: HIDROELÉCTRICA | CF8: HIDROELÉCTRICA | CG8: TERMOELÉCTRICA | CH8: TERMOELÉCTRICA | CI8: TERMOELÉCTRICA | CJ8: TERMOELÉCTRICA | CK8: TERMOELÉCTRICA | CL8: TERMOELÉCTRICA | CM8: TERMOELÉCTRICA | CN8: TERMOELÉCTRICA | CO8: TERMOELÉCTRICA | CP8: TERMOELÉCTRICA | CQ8: TERMOELÉCTRICA | CR8: TERMOELÉCTRICA | CS8: TERMOELÉCTRICA | CT8: HIDROELÉCTRICA | CU8: HIDROELÉCTRICA | CV8: HIDROELÉCTRICA | CW8: SOLAR | CX8: EÓLICA | CY8: SOLAR | CZ8: EÓLICA | DA8: SOLAR | DB8: HIDROELÉCTRICA | DC8: HIDROELÉCTRICA | DD8: HIDROELÉCTRICA | DE8: SOLAR | DF8: SOLAR | DG8: HIDROELÉCTRICA | DH8: HIDROELÉCTRICA | DI8: HIDROELÉCTRICA | DJ8: HIDROELÉCTRICA | DK8: HIDROELÉCTRICA | DL8: HIDROELÉCTRICA | DM8: HIDROELÉCTRICA | DN8: HIDROELÉCTRICA | DO8: SOLAR | DP8: SOLAR | DQ8: EÓLICA | DR8: EÓLICA | DS8: SOLAR | DT8: HIDROELÉCTRICA | DU8: HIDROELÉCTRICA | DV8: HIDROELÉCTRICA | DW8: HIDROELÉCTRICA | DX8: SOLAR | DY8: HIDROELÉCTRICA | DZ8: HIDROELÉCTRICA | EA8: HIDROELÉCTRICA | EB8: HIDROELÉCTRICA | EC8: EÓLICA | ED8: EÓLICA | EE8: SOLAR | EF8: EÓLICA | EG8: EÓLICA | EH8: EÓLICA | EI8: EÓLICA | EJ8: SOLAR | EK8: HIDROELÉCTRICA | EL8: HIDROELÉCTRICA | EM8: HIDROELÉCTRICA | EN8: HIDROELÉCTRICA | EO8: HIDROELÉCTRICA | EP8: HIDROELÉCTRICA | EQ8: EÓLICA | ER8: SOLAR | ES8: SOLAR | ET8: SOLAR | EU8: HIDROELÉCTRICA | EV8: EÓLICA | EW8: EÓLICA | EX8: SOLAR | EY8: TERMOELÉCTRICA | EZ8: TERMOELÉCTRICA | FA8: TERMOELÉCTRICA | FB8: TERMOELÉCTRICA | FC8: SOLAR | FD8: HIDROELÉCTRICA | FE8: HIDROELÉCTRICA | FF8: HIDROELÉCTRICA | FG8: TERMOELÉCTRICA | FH8: TERMOELÉCTRICA | FI8: TERMOELÉCTRICA | FJ8: TERMOELÉCTRICA | FK8: TERMOELÉCTRICA | FL8: TERMOELÉCTRICA | FM8: TERMOELÉCTRICA | FN8: TERMOELÉCTRICA | FQ8: HIDROELÉCTRICA | FR8: HIDROELÉCTRICA | FS8: HIDROELÉCTRICA | FT8: HIDROELÉCTRICA | FU8: TERMOELÉCTRICA | FV8: TERMOELÉCTRICA | FW8: HIDROELÉCTRICA | FX8: HIDROELÉCTRICA
