Workbook

Sheet EVENTOS
B3: jueves, 5 de Junio del 2025
B5: INFORMACIÓN DE EVENTOS PRINCIPALES EN SUS INSTALACIONES
B6: TIPO DE EVENTO | C6: EMPRESA | D6: UBICACIÓN | E6: TIPO DE EQUIPO | F6: EQUIPO | G6: INICIO | H6: FINAL | I6: DESCRIPCIÓN | J6: MW INDISP. | K6: INTERRUPCIÓN (SI/NO) | L6: TENSIÓN DE FALLA (kV)
B7: FALLA | C7: CELEPSA RENOVABLES S.R.L. | D7: MARAÑON | E7: GENERADOR HIDROELÉCTRICO | F7: G1 | G7: 05/06/2025 12:15:00 | H7: 05/06/2025 12:34:00 | I7: DESCONEXIÓN DEL GENERADOR G1 DE LA C.H. MARAÑÓN POR FALLA | K7: NO | L7: 13.8
B8: EVENTO | C8: CONELSUR LT SAC | D8: PORTILLO | E8: SUBESTACION | F8: SS.EE. | G8: 05/06/2025 00:00:00 | H8: 06/06/2025 00:00:00 | I8: DECLARACIÓN DE SITUACIÓN EXCEPCIONAL EN LA S.E. PORTILLO DE 60 kV | K8: NO
B9: FALLA | C9: EMPRESA ELECTRICA RIO DOBLE | D9: LAS PIZARRAS | E9: GENERADOR HIDROELÉCTRICO | F9: G1 | G9: 05/06/2025 11:16:27 | H9: 05/06/2025 11:36:46 | I9: DESCONEXIÓN DEL GENERADOR G1 DE LA C.H. LAS PIZARRAS | K9: NO | L9: 6.6
B10: FALLA | C10: EMPRESA ELECTRICA RIO DOBLE | D10: LAS PIZARRAS | E10: GENERADOR HIDROELÉCTRICO | F10: G1 | G10: 05/06/2025 11:38:41 | H10: 05/06/2025 15:03:03 | I10: DESCONEXIÓN DEL GENERADOR G1 DE LA C.H. LAS PIZARRAS | K10: NO | L10: 6.6

Sheet RESTRIC_OPE
B3: jueves, 5 de Junio del 2025
B5: RESTRICCIONES OPERATIVAS
B6: FECHA | C6: HORA INICIO | D6: HORA FINAL | E6: EMPRESA | F6: UBICACIÓN | G6: T.Eq. | H6: EQUIPO | I6: DESCRIPCIÓN
B7: 05/06/2025 | C7: 00:00 | D7: 24:00 | E7: CELEPSA | F7: C.H. EL PLATANAL | G7: CH | H7: CENTRAL | I7: Debido al incremento del caudal del rio cañete y establecimiento de la temporada de avenida, se declara la C.H. El Platanal como CENTRAL HIDRÁULICA DE PASADA (correo 03/01/2025).
B8: 05/06/2025 | C8: 00:00 | D8: 24:00 | E8: EGASA | F8: C.H. CHARCANI II | G8: GH | H8: G2 | I8: El Grupo N°02 esta operando con una potencia no mayor a 0.07MW en referencia a 0.18MW de su potencia efectiva, con el fin de no generar daños mayores hasta la reparación de su cojinete.
B9: 05/06/2025 | C9: 00:00 | D9: 24:00 | E9: EGASA | F9: S.E. CONVERTIDOR | G9: BARRA | H9: BARRA138KV | I9: EGASA limitó la capacidad del transformador 138 kV/33 kV a 50 MVA por deterioro del aislamiento.
B10: 05/06/2025 | C10: 00:00 | D10: 24:00 | E10: ENEL GENERACION PIURA S.A. | F10: C.T. MALACAS | G10: CT | H10: CENTRAL | I10: De acuerdo con la comunicación vía correo del día 24.10.2024. ENEL GENERACIÓN PIURA informa una restricción de potencia para alcanzar 105 MW en simultaneo (TG6+TGN4).
B11: 05/06/2025 | C11: 00:00 | D11: 24:00 | E11: ENEL GENERACION PIURA S.A. | F11: C.T. MALACAS | G11: GT | H11: TG4 | I11: De acuerdo a lo informado mediante correo electronico el día 19.05, la TG4 solo puede operar a máxima generación dos horas y el resto a carga a mínima carga.
B12: 05/06/2025 | C12: 00:00 | D12: 24:00 | E12: ENGIE | F12: C.E. PUNTA LOMITAS | G12: CE | H12: CENTRAL | I12: De acuerdo a la carta ENG/737-2024 (Exp:202400007555). Limitación de cables de media tensión a 100 MW de los transformadores PLT1 y PLT2 de la CE Punta Lomitas. Quedan limitados a 200 MW la generación de CE Punta Lomitas y Punta Lomitas Extensión.
B13: 05/06/2025 | C13: 00:00 | D13: 24:00 | E13: ENGIE | F13: C.H. QUITARACSA | G13: CH | H13: CENTRAL | I13: De acuerdo con el correo del 23.04 se considera la operación continua de la CH Quitaracsa debido a que el sistema de refrigeración de la CH Cañón del Pato se alimenta desde la descarga del caudal turbinado por la CH Quitaracsa.
B14: 05/06/2025 | C14: 00:00 | D14: 24:00 | E14: ENGIE | F14: C.H. YUNCÁN | G14: GH | H14: G3 | I14: Según la carta N° ENG/ 198-2024 enviada por su representada, se opera de forma continua el G3 de la CH Yuncán, debido a la ejecución de mantenimientos necesarios para evitar daños en los sellos de seguridad de la válvula esférica del grupo.
B15: 05/06/2025 | C15: 00:00 | D15: 24:00 | E15: ENGIE | F15: C.T. CHILCA 1 | G15: CT | H15: CENTRAL | I15: Restricción de temperatura de la C.T Chilca, ver valor en el modelo de despacho.
B16: 05/06/2025 | C16: 00:00 | D16: 24:00 | E16: ENGIE | F16: C.T. CHILCA 1 | G16: CT | H16: CENTRAL | I16: Con carta ENG/971-2023, indica que no puede cumplir con las IO considerada en el PDO_17122023 dado que vulneran la seguridad de sus activos. Indican que se debe tomar TMO=168h.
B17: 05/06/2025 | C17: 00:00 | D17: 24:00 | E17: ENGIE | F17: C.T. CHILCA 2 | G17: CT | H17: CENTRAL | I17: Restricción de temperatura de la C.T Chilca2, ver valor en el modelo de despacho.
... B47: 05/06/2025 | C47: 00:00 | D47: 24:00 | E47: TERMOSELVA | F47: C.T. AGUAYTÍA | G47: CT | H47: CENTRAL | I47: Restricción total de GN para la CT Aguaytía.

Sheet MANTENIMIENTO EJECUTADOS
B3: jueves, 5 de Junio del 2025
B5: Mantenimiento Ejecutado
B6: Empresa | C6: Ubicación | D6: Equipo | E6: Inicio | F6: Final | G6: Descripción | H6: MW Indisp. | I6: Prog. | J6: Dispon | K6: Interrupc. | L6: Tipo | M6: CodEq | N6: TipoEq_Osinerg
B7: AGROAURORA S.A.C. | C7: MAPLE ETANOL | D7: CENTRAL | E7: 05/06/2025 00:00 | F7: 06/06/2025 00:00 | G7: CENTRAL TERMOELECTRICA FUERA DE SERVICIO POR FALTA DE MATERIA PRIMA PARA LOS REQUERIMIENTOS DE CALOR UTIL EN FABRICA. | H7: 17 | I7: P | J7: F/S | K7: N | L7: OTROS | M7: 13417 | N7: G
B8: AGROAURORA S.A.C. | C8: MAPLE ETANOL | D8: CENTRAL | E8: 05/06/2025 00:00 | F8: 06/06/2025 00:00 | G8: MANTENIMIENTO PREVENTIVO PROGRAMADO DE LA CENTRAL TERMOELECTRICA Y EQUIPOS AUXILIARES. | H8: 17 | I8: P | J8: F/S | K8: N | L8: PREV. | M8: 13417 | N8: G
B9: ATLANTICA TRANSMISION SUR S.A. | C9: MONTALVO | D9: ACOPLE 220 | E9: 05/06/2025 00:00 | F9: 06/06/2025 00:00 | G9: Proyecto Refuerzos: Reemplazo del HMI existente, Pruebas y Configuracion. No se contara con nivel 1 de operacion. | H9: 0 | I9: P | J9: E/S | K9: N | L9: P.ENERG | M9: 14767 | N9: T
B10: ATLANTICA TRANSMISION SUR S.A. | C10: MONTALVO | D10: BARRA A_220KV | E10: 05/06/2025 00:00 | F10: 06/06/2025 00:00 | G10: Proyecto Refuerzos: Indisponibilidad de la proteccion diferencial de barras 220 kV por Conexion de la nueva UB-87B hacia la UC existente,Configuracion y Pruebas. | H10: 0 | I10: P | J10: E/S | K10: N | L10: P.ENERG | M10: 13869 | N10: T
B11: ATLANTICA TRANSMISION SUR S.A. | C11: MONTALVO | D11: BARRA A_500KV | E11: 05/06/2025 00:00 | F11: 06/06/2025 00:00 | G11: Proyecto Refuerzos: Indisponibilidad de la proteccion diferencial de barras 500kV por conexion de nueva UB-87B hacia la UC existente, Configuracion y Pruebas. | H11: 0 | I11: P | J11: E/S | K11: N | L11: P.ENERG | M11: 13870 | N11: T
B12: ATLANTICA TRANSMISION SUR S.A. | C12: MONTALVO | D12: BARRA B_220kV | E12: 05/06/2025 00:00 | F12: 06/06/2025 00:00 | G12: Proyecto Refuerzos: Indisponibilidad de la proteccion diferencial de barras 220 kV por Conexion de la nueva UB-87B hacia la UC existente,Configuracion y Pruebas. | H12: 0 | I12: P | J12: E/S | K12: N | L12: P.ENERG | M12: 14765 | N12: T
B13: ATLANTICA TRANSMISION SUR S.A. | C13: MONTALVO | D13: BARRA B_500KV | E13: 05/06/2025 00:00 | F13: 06/06/2025 00:00 | G13: Proyecto Refuerzos: Indisponibilidad de la proteccion diferencial de barras 500kV por conexion de nueva UB-87B hacia la UC existente, Configuracion y Pruebas. | H13: 0 | I13: P | J13: E/S | K13: N | L13: P.ENERG | M13: 13871 | N13: T
B14: ATLANTICA TRANSMISION SUR S.A. | C14: MONTALVO | D14: CL-2057 | E14: 05/06/2025 00:00 | F14: 06/06/2025 00:00 | G14: Proyecto Refuerzos: Reemplazo del HMI existente, Pruebas y Configuracion. No se contara con nivel 1 de operacion. | H14: 0 | I14: P | J14: E/S | K14: N | L14: P.ENERG | M14: 13812 | N14: T
B15: ATLANTICA TRANSMISION SUR S.A. | C15: MONTALVO | D15: CL-AUT-5671_500 | E15: 05/06/2025 00:00 | F15: 06/06/2025 00:00 | G15: Proyecto Refuerzos: Reemplazo del HMI existente, Pruebas y Configuracion. No se contara con nivel 1 de operacion en INT-5671, INT-5652 y SAT-5671. | H15: 0 | I15: P | J15: E/S | K15: N | L15: P.ENERG | M15: 13809 | N15: T
B16: ATLANTICA TRANSMISION SUR S.A. | C16: MONTALVO | D16: INT-5652 | E16: 05/06/2025 00:00 | F16: 06/06/2025 00:00 | G16: Proyecto Refuerzos: Indisponible por Implementacion de Conexion de corrientes, disparos, posiciones, enclavamientos hacia los equipos del nuevo Autotransformador. AUT-5671 en servicio solo por Barra A 500kV. | H16: 0 | I16: P | J16: F/S | K16: N | L16: P.ENERG | M16: 13765 | N16: T
B17: ATLANTICA TRANSMISION SUR S.A. | C17: OCONA | D17: INT-5450 | E17: 05/06/2025 00:00 | F17: 06/06/2025 00:00 | G17: Interruptor INT-5450 cerrado con restriccion operativa, REB-5450 en servicio y suministrando los SS.AA. de la S.E. Oco?a. | H17: 0 | I17: P | J17: E/S | K17: N | L17: OTROS | M17: 13761 | N17: T
B18: ATLANTICA TRANSMISION SUR S.A. | C18: OCONA | D18: INT-5462 | E18: 05/06/2025 00:00 | F18: 06/06/2025 00:00 | G18: Seccionador SBA-5462 fase T indisponible por problemas mecanicos, el seccionador permanece cerrado y bloqueado | H18: 0 | I18: P | J18: E/S | K18: N | L18: OTROS | M18: 13758 | N18: T
... B143: TRANSMANTARO | C143: YARABAMBA | D143: IN-5120 | E143: 05/06/2025 00:00 | F143: 06/06/2025 00:00 | G143: INTERRUPTOR INDISPONIBLE POR FALLA EN LOS MANDOS DE CONTROL DE N1, N2 Y N3. | H143: 0 | I143: P | J143: F/S | K143: N | L143: OTROS | M143: 17437 | N143: T

Sheet INGRESO OC
A3: jueves, 5 de Junio del 2025
A5: INGRESO A OPERACIÓN COMERCIAL
A6: EMPRESA | B6: TIPO DE EQUIPO | C6: UBICACIÓN | D6: EQUIPO | E6: Fecha y hora de Ingreso a Operación Comercial

Sheet DESPACHO_EJECUTADO
B3: jueves, 5 de Junio del 2025
A5: POTENCIA ACTIVA EJECUTADA DE LAS UNIDADES DE GENERACIÓN DEL SEIN (MW) | FL5: CENTRALES NO INTEGRANTES COES
A6: FECHA | B6: HORA | C6: 65333 | D6: 101 | E6: 102 | F6: 42667 | G6: 42668 | H6: 126 | I6: 127 | J6: 138 | K6: 139 | L6: 197 | M6: 203 | N6: 204 | O6: 230 | P6: 209 | Q6: 56677 | R6: 796 | S6: 2146 | T6: 142 | U6: 143 | V6: 125 | W6: 187 | X6: 163 | Y6: 298 | Z6: 299 | AA6: 219 | AB6: 151 | AC6: 152 | AD6: 153 | AE6: 154 | AF6: 756 | AG6: 156 | AH6: 155 | AI6: 182 | AJ6: 212 | AK6: 758 | AL6: 263 | AM6: 265 | AN6: 775 | AO6: 777 | AP6: 2154 | AQ6: 150 | AR6: 149 | AS6: 188 | AT6: 2131 | AU6: 755 | AV6: 252 | AW6: 249 | AX6: 250 | AY6: 117 | AZ6: 267 | BA6: 268 | BB6: 119 | BC6: 120 | BD6: 189 | BE6: 122 | BF6: 266 | BG6: 337 | BH6: 338 | BI6: 251 | BJ6: 115 | BK6: 239 | BL6: 288 | BM6: 240 | BN6: 241 | BO6: 242 | BP6: 191 | BQ6: 194 | BR6: 196 | BS6: 207 | BT6: 236 | BU6: 795 | BV6: 285 | BW6: 995 | BX6: 996 | BY6: 997 | BZ6: 766 | CA6: 926 | CB6: 924 | CC6: 121 | CD6: 103 | CE6: 104 | CF6: 106 | CG6: 105 | CH6: 107 | CI6: 110 | CJ6: 109 | CK6: 144 | CL6: 113 | CM6: 114 | CN6: 193 | CO6: 208 | CP6: 786 | CQ6: 787 | CR6: 788 | CS6: 789 | CT6: 248 | CU6: 2159 | CV6: 303 | CW6: 59715 | CX6: 62255 | CY6: 1263 | CZ6: 61800 | DA6: 2194 | DB6: 216 | DC6: 198 | DD6: 49607 | DE6: 214 | DF6: 260 | DG6: 2152 | DH6: 2128 | DI6: 247 | DJ6: 228 | DK6: 2135 | DL6: 261 | DM6: 237 | DN6: 253 | DO6: 770 | DP6: 225 | DQ6: 2201 | DR6: 2171 | DS6: 760 | DT6: 235 | DU6: 238 | DV6: 2184 | DW6: 61855 | DX6: 223 | DY6: 226 | DZ6: 201 | EA6: 258 | EB6: 259 | EC6: 920 | ED6: 257 | EE6: 256 | EF6: 2148 | EG6: 58288 | EH6: 58289 | EI6: 58839 | EJ6: 58840 | EK6: 296 | EL6: 297 | EM6: 211 | EN6: 2175 | EO6: 2178 | EP6: 2181 | EQ6: 1262 | ER6: 63425 | ES6: 233 | ET6: 2150 | EU6: 2165 | EV6: 2161 | EW6: 61197 | EX6: 58851 | EY6: 234 | EZ6: 215 | FA6: 917 | FB6: 289 | FC6: 58333 | FD6: 58336 | FE6: 202 | FF6: 58487 | FG6: 213 | FH6: 232 | FI6: 2190 | FJ6: TOTAL COES | FL6: 221 | FM6: 222 | FN6: 224 | FO6: 2187 | FP6: 227 | FQ6: 49400 | FR6: 199 | FS6: 200 | FT6: TOTAL NO COES
C7: SUR | D7: CENTRO | E7: CENTRO | F7: NORTE | G7: NORTE | H7: NORTE | I7: NORTE | J7: CENTRO | K7: CENTRO | L7: CENTRO | M7: CENTRO | N7: CENTRO | O7: CENTRO | P7: CENTRO | Q7: CENTRO | R7: CENTRO | S7: CENTRO | T7: CENTRO | U7: CENTRO | V7: CENTRO | W7: CENTRO | X7: SUR | Y7: SUR | Z7: SUR | AA7: CENTRO | AB7: SUR | AC7: SUR | AD7: SUR | AE7: SUR | AF7: SUR | AG7: SUR | AH7: SUR | AI7: SUR | AJ7: CENTRO | AK7: NORTE | AL7: NORTE | AM7: NORTE | AN7: CENTRO | AO7: CENTRO | AP7: CENTRO | AQ7: CENTRO | AR7: CENTRO | AS7: CENTRO | AT7: CENTRO | AU7: SUR | AV7: CENTRO | AW7: CENTRO | AX7: CENTRO | AY7: CENTRO | AZ7: CENTRO | BA7: CENTRO | BB7: CENTRO | BC7: CENTRO | BD7: SUR | BE7: NORTE | BF7: CENTRO | BG7: CENTRO | BH7: CENTRO | BI7: CENTRO | BJ7: NORTE | BK7: NORTE | BL7: NORTE | BM7: SUR | BN7: SUR | BO7: SUR | BP7: CENTRO | BQ7: CENTRO | BR7: CENTRO | BS7: CENTRO | BT7: CENTRO | BU7: CENTRO | BV7: CENTRO | BW7: SUR | BX7: SUR | BY7: SUR | BZ7: NORTE | CA7: SUR | CB7: CENTRO | CC7: NORTE | CD7: CENTRO | CE7: CENTRO | CF7: CENTRO | CG7: CENTRO | CH7: CENTRO | CI7: CENTRO | CJ7: CENTRO | CK7: CENTRO | CL7: CENTRO | CM7: CENTRO | CN7: CENTRO | CO7: CENTRO | CP7: SUR | CQ7: SUR | CR7: SUR | CS7: SUR | CT7: CENTRO | CU7: CENTRO | CV7: CENTRO | CW7: CENTRO | CX7: SUR | CY7: NORTE | CZ7: NORTE | DA7: NORTE | DB7: NORTE | DC7: NORTE | DD7: SUR | DE7: CENTRO | DF7: CENTRO | DG7: CENTRO | DH7: NORTE | DI7: NORTE | DJ7: CENTRO | DK7: CENTRO | DL7: SUR | DM7: SUR | DN7: CENTRO | DO7: CENTRO | DP7: CENTRO | DQ7: CENTRO | DR7: CENTRO | DS7: CENTRO | DT7: SUR | DU7: CENTRO | DV7: CENTRO | DW7: NORTE | DX7: CENTRO | DY7: CENTRO | DZ7: NORTE | EA7: CENTRO | EB7: CENTRO | EC7: CENTRO | ED7: NORTE | EE7: NORTE | EF7: SUR | EG7: CENTRO | EH7: CENTRO | EI7: CENTRO | EJ7: CENTRO | EK7: CENTRO | EL7: CENTRO | EM7: SUR | EN7: SUR | EO7: SUR | EP7: SUR | EQ7: NORTE | ER7: SUR | ES7: SUR | ET7: SUR | EU7: CENTRO | EV7: CENTRO | EW7: CENTRO | EX7: SUR | EY7: SUR | EZ7: NORTE | FA7: CENTRO | FB7: NORTE | FC7: NORTE | FD7: NORTE | FE7: CENTRO | FF7: CENTRO | FG7: CENTRO | FH7: NORTE | FI7: NORTE | FL7: NORTE | FM7: CENTRO | FN7: NORTE | FO7: NORTE | FP7: NORTE | FQ7: NORTE | FR7: NORTE | FS7: NORTE
C8: HIDROELÉCTRICA | D8: HIDROELÉCTRICA | E8: HIDROELÉCTRICA | F8: TERMOELÉCTRICA | G8: TERMOELÉCTRICA | H8: HIDROELÉCTRICA | I8: HIDROELÉCTRICA | J8: TERMOELÉCTRICA | K8: TERMOELÉCTRICA | L8: TERMOELÉCTRICA | M8: TERMOELÉCTRICA | N8: TERMOELÉCTRICA | O8: TERMOELÉCTRICA | P8: TERMOELÉCTRICA | Q8: TERMOELÉCTRICA | R8: HIDROELÉCTRICA | S8: HIDROELÉCTRICA | T8: TERMOELÉCTRICA | U8: TERMOELÉCTRICA | V8: TERMOELÉCTRICA | W8: TERMOELÉCTRICA | X8: HIDROELÉCTRICA | Y8: HIDROELÉCTRICA | Z8: HIDROELÉCTRICA | AA8: TERMOELÉCTRICA | AB8: HIDROELÉCTRICA | AC8: HIDROELÉCTRICA | AD8: HIDROELÉCTRICA | AE8: HIDROELÉCTRICA | AF8: TERMOELÉCTRICA | AG8: TERMOELÉCTRICA | AH8: TERMOELÉCTRICA | AI8: HIDROELÉCTRICA | AJ8: HIDROELÉCTRICA | AK8: TERMOELÉCTRICA | AL8: TERMOELÉCTRICA | AM8: TERMOELÉCTRICA | AN8: HIDROELÉCTRICA | AO8: HIDROELÉCTRICA | AP8: HIDROELÉCTRICA | AQ8: HIDROELÉCTRICA | AR8: HIDROELÉCTRICA | AS8: HIDROELÉCTRICA | AT8: HIDROELÉCTRICA | AU8: HIDROELÉCTRICA | AV8: TERMOELÉCTRICA | AW8: TERMOELÉCTRICA | AX8: TERMOELÉCTRICA | AY8: HIDROELÉCTRICA | AZ8: HIDROELÉCTRICA | BA8: HIDROELÉCTRICA | BB8: HIDROELÉCTRICA | BC8: HIDROELÉCTRICA | BD8: HIDROELÉCTRICA | BE8: HIDROELÉCTRICA | BF8: HIDROELÉCTRICA | BG8: HIDROELÉCTRICA | BH8: HIDROELÉCTRICA | BI8: HIDROELÉCTRICA | BJ8: TERMOELÉCTRICA | BK8: TERMOELÉCTRICA | BL8: TERMOELÉCTRICA | BM8: TERMOELÉCTRICA | BN8: TERMOELÉCTRICA | BO8: TERMOELÉCTRICA | BP8: HIDROELÉCTRICA | BQ8: TERMOELÉCTRICA | BR8: TERMOELÉCTRICA | BS8: TERMOELÉCTRICA | BT8: TERMOELÉCTRICA | BU8: TERMOELÉCTRICA | BV8: TERMOELÉCTRICA | BW8: TERMOELÉCTRICA | BX8: TERMOELÉCTRICA | BY8: TERMOELÉCTRICA | BZ8: HIDROELÉCTRICA | CA8: TERMOELÉCTRICA | CB8: TERMOELÉCTRICA | CC8: HIDROELÉCTRICA | CD8: HIDROELÉCTRICA | CE8: HIDROELÉCTRICA | CF8: HIDROELÉCTRICA | CG8: HIDROELÉCTRICA | CH8: HIDROELÉCTRICA | CI8: TERMOELÉCTRICA | CJ8: TERMOELÉCTRICA | CK8: TERMOELÉCTRICA | CL8: TERMOELÉCTRICA | CM8: TERMOELÉCTRICA | CN8: TERMOELÉCTRICA | CO8: TERMOELÉCTRICA | CP8: TERMOELÉCTRICA | CQ8: TERMOELÉCTRICA | CR8: TERMOELÉCTRICA | CS8: TERMOELÉCTRICA | CT8: TERMOELÉCTRICA | CU8: TERMOELÉCTRICA | CV8: SOLAR | CW8: EÓLICA | CX8: SOLAR | CY8: EÓLICA | CZ8: SOLAR | DA8: HIDROELÉCTRICA | DB8: HIDROELÉCTRICA | DC8: HIDROELÉCTRICA | DD8: HIDROELÉCTRICA | DE8: HIDROELÉCTRICA | DF8: HIDROELÉCTRICA | DG8: HIDROELÉCTRICA | DH8: HIDROELÉCTRICA | DI8: HIDROELÉCTRICA | DJ8: HIDROELÉCTRICA | DK8: HIDROELÉCTRICA | DL8: SOLAR | DM8: SOLAR | DN8: EÓLICA | DO8: EÓLICA | DP8: TERMOELÉCTRICA | DQ8: TERMOELÉCTRICA | DR8: TERMOELÉCTRICA | DS8: TERMOELÉCTRICA | DT8: SOLAR | DU8: HIDROELÉCTRICA | DV8: HIDROELÉCTRICA | DW8: HIDROELÉCTRICA | DX8: HIDROELÉCTRICA | DY8: HIDROELÉCTRICA | DZ8: HIDROELÉCTRICA | EA8: HIDROELÉCTRICA | EB8: HIDROELÉCTRICA | EC8: HIDROELÉCTRICA | ED8: EÓLICA | EE8: EÓLICA | EF8: SOLAR | EG8: EÓLICA | EH8: EÓLICA | EI8: EÓLICA | EJ8: EÓLICA | EK8: HIDROELÉCTRICA | EL8: HIDROELÉCTRICA | EM8: HIDROELÉCTRICA | EN8: HIDROELÉCTRICA | EO8: HIDROELÉCTRICA | EP8: HIDROELÉCTRICA | EQ8: EÓLICA | ER8: SOLAR | ES8: SOLAR | ET8: SOLAR | EU8: HIDROELÉCTRICA | EV8: EÓLICA | EW8: EÓLICA | EX8: SOLAR | EY8: SOLAR | EZ8: HIDROELÉCTRICA | FA8: HIDROELÉCTRICA | FB8: TERMOELÉCTRICA | FC8: TERMOELÉCTRICA | FD8: TERMOELÉCTRICA | FE8: TERMOELÉCTRICA | FF8: TERMOELÉCTRICA | FG8: TERMOELÉCTRICA | FH8: TERMOELÉCTRICA | FI8: TERMOELÉCTRICA | FL8: HIDROELÉCTRICA | FM8: HIDROELÉCTRICA | FN8: HIDROELÉCTRICA | FO8: HIDROELÉCTRICA | FP8: TERMOELÉCTRICA | FQ8: TERMOELÉCTRICA | FR8: HIDROELÉCTRICA | FS8: HIDROELÉCTRICA
C9: HYDRO GLOBAL PERÚ S.A.C. | D9: ELECTROPERU | E9: ELECTROPERU | F9: ELECTROPERU | G9: ELECTROPERU | H9: ORAZUL ENERGY PERÚ | I9: ORAZUL ENERGY PERÚ | J9: TERMOSELVA | K9: TERMOSELVA | L9: KALLPA GENERACION S.A. | M9: KALLPA GENERACION S.A. | N9: KALLPA GENERACION S.A. | O9: KALLPA GENERACION S.A. | P9: KALLPA GENERACION S.A. | Q9: KALLPA GENERACION S.A. | R9: KALLPA GENERACION S.A. | S9: KALLPA GENERACION S.A. | T9: SHOUGESA | U9: SHOUGESA | V9: SHOUGESA | W9: SHOUGESA | X9: EGEMSA | Y9: EGESUR | Z9: EGESUR | AA9: EGESUR | AB9: EGASA | AC9: EGASA | AD9: EGASA | AE9: EGASA | AF9: EGASA | AG9: EGASA | AH9: EGASA | AI9: SAN GABAN | AJ9: CELEPSA | AK9: MINERA CERRO VERDE | AL9: PLANTA DE RESERVA FRIA DE GENERACION DE ETEN S.A. | AM9: PLANTA DE RESERVA FRIA DE GENERACION DE ETEN S.A. | AN9: EMPRESA DE GENERACION HUALLAGA | AO9: EMPRESA DE GENERACION HUALLAGA | AP9: LA VIRGEN | AQ9: CHINANGO S.A.C. | AR9: CHINANGO S.A.C. | AS9: HIDROELECTRICA HUANCHOR S.A.C. | AT9: CELEPSA RENOVABLES S.R.L. | AU9: INLAND ENERGY SAC | AV9: FENIX POWER PERÚ | AW9: FENIX POWER PERÚ | AX9: FENIX POWER PERÚ | AY9: STATKRAFT S.A | AZ9: STATKRAFT S.A | BA9: STATKRAFT S.A | BB9: STATKRAFT S.A | BC9: STATKRAFT S.A | BD9: STATKRAFT S.A | BE9: STATKRAFT S.A | BF9: STATKRAFT S.A | BG9: CENTRALES SANTA ROSA S.A.C. | BH9: CENTRALES SANTA ROSA S.A.C. | BI9: EMPRESA DE GENERACION HUANZA | BJ9: ENEL GENERACION PIURA S.A. | BK9: ENEL GENERACION PIURA S.A. | BL9: ENEL GENERACION PIURA S.A. | BM9: ENGIE | BN9: ENGIE | BO9: ENGIE | BP9: ENGIE | BQ9: ENGIE | BR9: ENGIE | BS9: ENGIE | BT9: ENGIE | BU9: ENGIE | BV9: ENGIE | BW9: ENGIE | BX9: ENGIE | BY9: ENGIE | BZ9: ENGIE | CA9: INFRAESTRUCTURAS Y ENERGIAS DEL PERU S.A.C. | CB9: INFRAESTRUCTURAS Y ENERGIAS DEL PERU S.A.C. | CC9: INVERSIONES SHAQSHA S.A.C. | CD9: ORYGEN PERU S.A.A. | CE9: ORYGEN PERU S.A.A. | CF9: ORYGEN PERU S.A.A. | CG9: ORYGEN PERU S.A.A. | CH9: ORYGEN PERU S.A.A. | CI9: ORYGEN PERU S.A.A. | CJ9: ORYGEN PERU S.A.A. | CK9: ORYGEN PERU S.A.A. | CL9: ORYGEN PERU S.A.A. | CM9: ORYGEN PERU S.A.A. | CN9: ORYGEN PERU S.A.A. | CO9: ORYGEN PERU S.A.A. | CP9: SAMAY I S.A.C | CQ9: SAMAY I S.A.C | CR9: SAMAY I S.A.C | CS9: SAMAY I S.A.C | CT9: TERMOCHILCA S.A.C. | CU9: TERMOCHILCA S.A.C. | CV9: COLCA SOLAR S.A.C. | CW9: ENERGIA RENOVABLE DEL SUR S.A. | CX9: GR CORTARRAMA SOCIEDAD ANONIMA CERRADA | CY9: GR TARUCA SOCIEDAD ANONIMA CERRADA | CZ9: KONDU SAC | DA9: PERUANA DE INVERSIONES EN ENERGIAS RENOVABLES S.A. | DB9: ORAZUL ENERGY PERÚ | DC9: ORAZUL ENERGY PERÚ | DD9: SAN GABAN | DE9: MAJA ENERGIA S.A.C. | DF9: EMPRESA DE GENERACION ELECTRICA CANCHAYLLO SAC | DG9: EMPRESA DE GENERACION ELECTRICA SANTA ANA S.A.C. | DH9: EMPRESA ELECTRICA AGUA AZUL | DI9: EMPRESA ELECTRICA RIO DOBLE | DJ9: HIDROCAÑETE S.A. | DK9: HUAURA POWER GROUP S.A. | DL9: MOQUEGUA FV S.A.C. | DM9: PANAMERICANA SOLAR SAC. | DN9: PARQUE EOLICO MARCONA S.A.C. | DO9: PARQUE EOLICO TRES HERMANAS S.A.C. | DP9: PETRAMAS | DQ9: PETRAMAS | DR9: PETRAMAS | DS9: PETRAMAS | DT9: TACNA SOLAR SAC. | DU9: ELECTRICA YANAPAMPA SAC | DV9: ANDEAN POWER S.A.C. | DW9: ASOCIACIÓN SANTA LUCIA DE CHACAS | DX9: ATRIA ENERGIA S.A.C. | DY9: EGEJUNIN | DZ9: EGEJUNIN | EA9: EGEJUNIN | EB9: EGEJUNIN | EC9: EMPRESA DE GENERACION ELECTRICA RIO BAÑOS S.A.C. | ED9: ENERGÍA EÓLICA S.A. | EE9: ENERGÍA EÓLICA S.A. | EF9: ENGIE | EG9: ENGIE | EH9: ENGIE | EI9: ENGIE | EJ9: ENGIE | EK9: GENERACIÓN ANDINA S.A.C. | EL9: GENERACIÓN ANDINA S.A.C. | EM9: GENERADORA DE ENERGÍA DEL PERÚ | EN9: GENERADORA DE ENERGÍA DEL PERÚ | EO9: GENERADORA DE ENERGÍA DEL PERÚ | EP9: GENERADORA DE ENERGÍA DEL PERÚ | EQ9: GR PAINO SOCIEDAD ANONIMA CERRADA | ER9: JOYA SOLAR S.A.C. | ES9: MAJES ARCUS S.A.C. | ET9: ORYGEN PERU S.A.A. | EU9: ORYGEN PERU S.A.A. | EV9: ORYGEN PERU S.A.A. | EW9: ORYGEN PERU S.A.A. | EX9: ORYGEN PERU S.A.A. | EY9: REPARTICIÓN ARCUS S.A.C. | EZ9: SINERSA | FA9: SINERSA | FB9: BIOENERGIA DEL CHIRA S.A. | FC9: GM OPERACIONES S.A.C. | FD9: GM OPERACIONES S.A.C. | FE9: SDF ENERGIA SAC | FF9: SDF ENERGIA SAC | FG9: AGRO INDUSTRIAL PARAMONGA S.A. | FH9: AGROAURORA S.A.C. | FI9: AGROINDUSTRIAS SAN JACINTO S.A.A. | FL9: UNACEM PERU S.A. | FM9: ELECTRO ORIENTE | FN9: AGUAS Y ENERGIA PERU | FO9: ELECTRO ZAÑA S.A.C. | FP9: ELECTRONOROESTE S.A. | FQ9: SDE PIURA | FR9: SINERSA | FS9: SINERSA
C10: SAN GABAN III | D10: MANTARO | E10: RESTITUCION | F10: TUMBES MAK 1 | G10: TUMBES MAK 2 | H10: CARHUAQUERO | I10: CAÑON DEL PATO | J10: AGUAYTIA TG1 | K10: AGUAYTIA TG2 | L10: KALLPA TG1 | M10: KALLPA TG2 | N10: KALLPA TG3 | O10: KALLPA TV | P10: LFLORES TG1 | Q10: LFLORES TV | R10: CERRO DEL AGUILA | S10: CERRODELAGUILAG4 | T10: SHOUGESA TV1 | U10: SHOUGESA TV2 | V10: SHOUGESA TV3 | W10: SHOUGESA CUMMINS | X10: MACHUPICCHU | Y10: ARICOTA 1 | Z10: ARICOTA 2 | AA10: INDEPENDENCIA | AB10: CHARCANI I,II,III | AC10: CHARCANI IV | AD10: CHARCANI V | AE10: CHARCANI VI | AF10: CHILINA TG | AG10: MOLLENDO 1, 2, 3 | AH10: CHILINA (SULZ 1,2) | AI10: SAN GABAN II | AJ10: PLATANAL | AK10: RECKA | AL10: RF ETEN TG1 | AM10: RF ETEN TG2 | AN10: CHAGLLA GP1 | AO10: CHAGLLA | AP10: LA VIRGEN | AQ10: CHIMAY | AR10: YANANGO | AS10: HUANCHOR | AT10: MARAÑON | AU10: STA TERESA | AV10: FENIX GT11 | AW10: FENIX GT12 | AX10: FENIX TV10 | AY10: YAUPI | AZ10: OROYA | BA10: PACHACHACA | BB10: MALPASO | BC10: CAHUA | BD10: ARCATA | BE10: GALLITO CIEGO | BF10: CHEVES | BG10: SANTA ROSA 1 | BH10: SANTA ROSA 2 | BI10: HUANZA | BJ10: MALACAS2 TG4 | BK10: MALACAS3 TG 5 | BL10: MALACAS1 TG6 | BM10: RF ILO2 TG1 | BN10: RF ILO2 TG2 | BO10: RF ILO2 TG3 | BP10: YUNCAN | BQ10: CHILCA1 TG1 | BR10: CHILCA1 TG2 | BS10: CHILCA1 TG3 | BT10: CHILCA-TV | BU10: CHILCA2 TG41 | BV10: CHILCA2-TV | BW10: CTNEPI_TG41 | BX10: CTNEPI_TG42 | BY10: CTNEPI_TG43 | BZ10: QUITARACSA | CA10: RF PTO MALDONADO | CB10: RF PUCALLPA | CC10: PARIAC | CD10: HUINCO | CE10: MATUCANA | CF10: MOYOPAMPA | CG10: CALLAHUANCA | CH10: HUAMPANI | CI10: STA ROSA WEST TG7 | CJ10: UTI_5 | CK10: UTI_6 | CL10: VENTANILLA 3 | CM10: VENTANILLA 4 | CN10: VENTANILLA TV | CO10: STAROSA TG8 | CP10: PTO_BRVO TG1 | CQ10: PTO_BRVO TG2 | CR10: PTO_BRVO TG3 | CS10: PTO_BRVO TG4 | CT10: OLLEROS TG1 | CU10: OLLEROS TV | CV10: CS YARUCAYA | CW10: SAN JUAN | CX10: MATARANI | CY10: DUNA | CZ10: CARHUAQUERO (CS) | DA10: MANTA I | DB10: CARHUAQUERO4 | DC10: CAÑA BRAVA | DD10: TUPURI | DE10: RONCADOR | DF10: CANCHAYLLO | DG10: RENOVANDESH1 | DH10: POTRERO | DI10: PIZARRAS | DJ10: NIMPERIAL | DK10: YARUCAYA | DL10: MOQUEGUA-SOLAR | DM10: PANAMERICANA-SOLAR | DN10: PQE-EOLICO-MARCONA | DO10: PQE-EOLICO-3-HERMANAS | DP10: HUAYCOLORO | DQ10: CALLAO | DR10: DONA_CATALINA | DS10: LAGRINGAV | DT10: TACNA-SOLAR | DU10: YANAPAMPA | DV10: CARHUAC | DW10: HUALLIN | DX10: PURMACANA | DY10: HUASAHUASI | DZ10: STACRUZ_1_2 | EA10: RUNATULLO_II | EB10: RUNATULLO_III | EC10: RUCUY | ED10: PQE-EOLICO-TALARA | EE10: PQE-EOLICO-CUPISNIQUE | EF10: INTIPAMPA | EG10: PUNTA LOMITAS-BL1 | EH10: PUNTA LOMITAS-BL2 | EI10: PUN LOMITAS_EXP-BL1 | EJ10: PUN LOMITAS_EXP-BL2 | EK10: 8AGOSTO | EL10: EL CARMEN | EM10: LA JOYA | EN10: ANGEL_I | EO10: ANGEL_II | EP10: ANGEL_III | EQ10: HUAMBOS | ER10: SAN MARTIN SOLAR | ES10: MAJES | ET10: RUBI | EU10: CH_HER1 | EV10: WAYRA-I | EW10: WAYRA EXTENSION | EX10: CLEMESI | EY10: REPARTICION | EZ10: POECHOS2 | FA10: CHANCAY | FB10: CANA BRAVA | FC10: REFINERIA TALARA TV1 | FD10: REFINERÍA TALARA TV2 | FE10: OQUENDO TG1 | FF10: OQUENDO TV1 | FG10: PARAMONGA | FH10: MAPLE | FI10: SAN_JACINTO | FJ10: MW | FL10: CARPAPATA | FM10: CENTRALES ELOR | FN10: PIAS1 | FO10: ZANA | FP10: TABLAZO | FQ10: TALLANCA | FR10: CURUMUY | FS10: POECHOS1 | FT10: MW
A11: 05/06/2025 | B11: 00:30 | C11: 141 | D11: 599.9 | E11: 200.3 | H11: 66.3 | I11: 154 | M11: 207.1 | N11: 209.9 | O11: 200.6 | R11: 556.3 | S11: 4.7 | X11: 163.8 | Y11: 6.9 | Z11: 5.3 | AB11: 6.8 | AC11: 14.6 | AD11: 60.8 | AI11: 69.5 | AJ11: 116.4 | AN11: 6.5 | AO11: 162.9 | AP11: 52.4 | AQ11: 53.5 | AR11: 28.1 | AS11: 18.8 | AT11: 13.2 | AU11: 90.1 | AV11: 181.6 | AW11: 179.3 | AX11: 184.8 | AY11: 106.1 | AZ11: 8.4 | BA11: 2.7 | BB11: 16.7 | BC11: 42.9 | BE11: 15.3 | BF11: 136.2 | BP11: 82.4 | BQ11: 179.1 | BR11: 177 | BS11: 200 | BT11: 276.3 | CC11: 4.1 | CD11: 89.1 | CE11: 112.4 | CF11: 63.3 | CG11: 72.5 | CH11: 30.3 | CL11: 147.8 | CM11: 149 | CN11: 150.1 | CT11: 6.1 | CU11: 0 | CV11: 0 | CW11: 43.5 | CX11: 0 | CY11: 9.1 | CZ11: 0 | DA11: 16.5 | DB11: 9.8 | DC11: 5.3 | DD11: 0.7 | DE11: 0 | DF11: 4.2 | DG11: 19.9 | DH11: 20 | DI11: 13.2 | DJ11: 3.5 | DK11: 18.5 | DL11: 0 | DM11: 0 | DN11: 15.2 | DO11: 40.8 | DP11: 3 | DQ11: 1.1 | DR11: 2.4 | DS11: 3.1 | DT11: 0 | DU11: 3.1 | DV11: 10.3 | DW11: 2 | DY11: 13.8 | DZ11: 5.6 | EA11: 7.2 | EB11: 10 | EC11: 19.8 | ED11: 9.4 | EE11: 9.8 | EF11: 0 | EG11: 37.2 | EH11: 49.5 | EI11: 5.7 | EJ11: 3.7 | EK11: 10.2 | EL11: 3.4 | EM11: 8.1 | EN11: 8.5 | EO11: 9.1 | EP11: 9.4 | EQ11: 5.6 | ER11: 0 | ES11: 0 | ET11: 0 | EU11: 0.6 | EV11: 70.5 | EW11: 81.3 | EX11: 0 | EY11: 0 | EZ11: 9.7 | FA11: 20 | FB11: 9.2 | FC11: 44.1 | FD11: 16.4 | FG11: 16.2 | FI11: 6.2 | FJ11: 6568.6 | FL11: 24.10214 | FM11: 0 | FO11: 13.2 | FP11: 3.86452 | FQ11: 18.93516 | FR11: 11.5 | FS11: 16.1 | FT11: 87.70182
A12: 05/06/2025 | B12: 01:00 | C12: 139.7 | D12: 599.5 | E12: 199.7 | H12: 60.2 | I12: 157.3 | M12: 205.5 | N12: 209.8 | O12: 199.8 | R12: 558.3 | S12: 4.9 | X12: 161.8 | Y12: 7.2 | Z12: 5.5 | AB12: 6.8 | AC12: 12 | AD12: 60.2 | AI12: 70.7 | AJ12: 86 | AN12: 6.5 | AO12: 153.2 | AP12: 53.2 | AQ12: 52.3 | AR12: 28.2 | AS12: 18.8 | AT12: 13.2 | AU12: 89.9 | AV12: 182.3 | AW12: 183.7 | AX12: 184.3 | AY12: 107.3 | AZ12: 8.4 | BA12: 2.7 | BB12: 18.2 | BC12: 43.5 | BE12: 16.1 | BF12: 100.2 | BP12: 83.9 | BQ12: 178.5 | BR12: 176.5 | BS12: 200 | BT12: 276.1 | CC12: 4 | CD12: 87.1 | CE12: 109.1 | CF12: 64.2 | CG12: 74.1 | CH12: 30.7 | CL12: 147.1 | CM12: 148.6 | CN12: 149.5 | CT12: 9 | CU12: 0 | CV12: 0 | CW12: 44.8 | CX12: 0 | CY12: 7.1 | CZ12: 0 | DA12: 16.6 | DB12: 9.9 | DC12: 4.7 | DD12: 0.7 | DE12: 0 | DF12: 4.3 | DG12: 20.1 | DH12: 20 | DI12: 13.2 | DJ12: 3.5 | DK12: 18.5 | DL12: 0 | DM12: 0 | DN12: 16.4 | DO12: 42.5 | DP12: 3 | DQ12: 1.1 | DR12: 2.4 | DS12: 3.1 | DT12: 0 | DU12: 3.2 | DV12: 10.3 | DW12: 2 | DY12: 13.8 | DZ12: 5.6 | EA12: 7.3 | EB12: 9.9 | EC12: 19.9 | ED12: 6.9 | EE12: 7.1 | EF12: 0 | EG12: 33.9 | EH12: 46.9 | EI12: 6.6 | EJ12: 3.8 | EK12: 10.2 | EL12: 3.4 | EM12: 8.1 | EN12: 8.5 | EO12: 9.1 | EP12: 9.4 | EQ12: 4 | ER12: 0 | ES12: 0 | ET12: 0 | EU12: 0.6 | EV12: 58.5 | EW12: 83.5 | EX12: 0 | EY12: 0 | EZ12: 9.8 | FA12: 20 | FB12: 9.3 | FC12: 43.8 | FD12: 16.5 | FG12: 16.1 | FI12: 6.7 | FJ12: 6471.9 | FL12: 24.10293 | FM12: 0 | FO12: 13.2 | FP12: 0 | FQ12: 18.93478 | FR12: 11.6 | FS12: 16.1 | FT12: 83.93771
A13: 05/06/2025 | B13: 01:30 | C13: 139.6 | D13: 600.9 | E13: 197.9 | H13: 59.4 | I13: 156 | M13: 206.5 | N13: 209.6 | O13: 200.2 | R13: 559.5 | S13: 4.9 | X13: 165.8 | Y13: 7.3 | Z13: 5.3 | AB13: 6.8 | AC13: 11.8 | AD13: 59.9 | AI13: 70.4 | AJ13: 92.1 | AN13: 6.5 | AO13: 0 | AP13: 54 | AQ13: 53.3 | AR13: 28.5 | AS13: 18.8 | AT13: 13.2 | AU13: 90 | AV13: 188.1 | AW13: 188.1 | AX13: 190.2 | AY13: 107.6 | AZ13: 8.4 | BA13: 2.7 | BB13: 18.3 | BC13: 43.2 | BE13: 16 | BF13: 111.3 | BP13: 84.1 | BQ13: 177.9 | BR13: 175.6 | BS13: 200 | BT13: 275.3 | CC13: 4 | CD13: 92.3 | CE13: 111.1 | CF13: 63.2 | CG13: 74.1 | CH13: 30.7 | CL13: 147.1 | CM13: 148.3 | CN13: 149.1 | CT13: 9.9 | CU13: 0 | CV13: 0 | CW13: 38.4 | CX13: 0 | CY13: 6.2 | CZ13: 0 | DA13: 16.7 | DB13: 9.9 | DC13: 4.8 | DD13: 0.7 | DE13: 0 | DF13: 4.3 | DG13: 20.1 | DH13: 20 | DI13: 13.2 | DJ13: 3.5 | DK13: 18.5 | DL13: 0 | DM13: 0 | DN13: 17.8 | DO13: 43.8 | DP13: 3 | DQ13: 1.1 | DR13: 2.4 | DS13: 3.1 | DT13: 0 | DU13: 3.1 | DV13: 10.3 | DW13: 2 | DY13: 13.8 | DZ13: 5.6 | EA13: 7.2 | EB13: 10 | EC13: 19.9 | ED13: 9.4 | EE13: 9.2 | EF13: 0 | EG13: 20.8 | EH13: 36.8 | EI13: 4.8 | EJ13: 2.8 | EK13: 10.1 | EL13: 3.4 | EM13: 8.1 | EN13: 8.5 | EO13: 9.1 | EP13: 9.4 | EQ13: 4.5 | ER13: 0 | ES13: 0 | ET13: 0 | EU13: 0.6 | EV13: 50.2 | EW13: 60.1 | EX13: 0 | EY13: 0 | EZ13: 9.8 | FA13: 20 | FB13: 9.6 | FC13: 44 | FD13: 16.4 | FG13: 16.2 | FI13: 6.3 | FJ13: 6304.3 | FL13: 24.10124 | FM13: 0 | FO13: 13.2 | FP13: 0 | FQ13: 18.93436 | FR13: 11.5 | FS13: 16.1 | FT13: 83.8356
A14: 05/06/2025 | B14: 02:00 | C14: 139.8 | D14: 592.7 | E14: 197.4 | H14: 59.4 | I14: 153.4 | M14: 205.9 | N14: 208.1 | O14: 199.1 | R14: 548.4 | S14: 4.8 | X14: 160.2 | Y14: 6.7 | Z14: 5.1 | AB14: 6.8 | AC14: 11.8 | AD14: 60.6 | AI14: 68.4 | AJ14: 98.3 | AN14: 6.5 | AO14: 0 | AP14: 53.6 | AQ14: 49.7 | AR14: 28.5 | AS14: 18.8 | AT14: 13.2 | AU14: 86.6 | AV14: 176 | AW14: 178.1 | AX14: 185.8 | AY14: 105.3 | AZ14: 8.3 | BA14: 2.7 | BB14: 17.3 | BC14: 43.7 | BE14: 11.4 | BF14: 81.8 | BP14: 83.1 | BQ14: 177.4 | BR14: 175 | BS14: 200 | BT14: 276 | CC14: 4 | CD14: 69.3 | CE14: 100.3 | CF14: 61.6 | CG14: 71.6 | CH14: 30.2 | CL14: 146.6 | CM14: 147.4 | CN14: 148 | CT14: 48.8 | CU14: 0 | CV14: 0 | CW14: 34.5 | CX14: 0 | CY14: 6.8 | CZ14: 0 | DA14: 16.6 | DB14: 9.9 | DC14: 4.8 | DD14: 0.7 | DE14: 0 | DF14: 4.2 | DG14: 19.4 | DH14: 20 | DI14: 13.2 | DJ14: 3.5 | DK14: 18.5 | DL14: 0 | DM14: 0 | DN14: 17.8 | DO14: 46.2 | DP14: 3 | DQ14: 1.1 | DR14: 2.4 | DS14: 3.1 | DT14: 0 | DU14: 3.1 | DV14: 10.3 | DW14: 2 | DY14: 13.8 | DZ14: 5.6 | EA14: 7 | EB14: 9.5 | EC14: 19.9 | ED14: 10.6 | EE14: 18.5 | EF14: 0 | EG14: 17.2 | EH14: 37.5 | EI14: 2.4 | EJ14: 0.9 | EK14: 10.1 | EL14: 3.4 | EM14: 8.1 | EN14: 8.5 | EO14: 9.1 | EP14: 9.4 | EQ14: 3.9 | ER14: 0 | ES14: 0 | ET14: 0 | EU14: 0.6 | EV14: 49.9 | EW14: 44.8 | EX14: 0 | EY14: 0 | EZ14: 9.8 | FA14: 20 | FB14: 9.4 | FC14: 44.3 | FD14: 16.4 | FG14: 16.3 | FI14: 6.5 | FJ14: 6188 | FL14: 24.10037 | FM14: 0 | FO14: 13.2 | FP14: 0 | FQ14: 18.92767 | FR14: 11.5 | FS14: 16 | FT14: 83.72804
A15: 05/06/2025 | B15: 02:30 | C15: 140.6 | D15: 598.8 | E15: 199.7 | H15: 60 | I15: 159.1 | M15: 206.4 | N15: 208.9 | O15: 199.2 | R15: 555 | S15: 4.9 | X15: 165.8 | Y15: 7.3 | Z15: 5.2 | AB15: 6.8 | AC15: 11.8 | AD15: 91.4 | AI15: 70.3 | AJ15: 81.1 | AN15: 6.5 | AO15: 0 | AP15: 55 | AQ15: 55.6 | AR15: 30.1 | AS15: 18.8 | AT15: 13.2 | AU15: 88.7 | AV15: 182.7 | AW15: 183.8 | AX15: 184.1 | AY15: 106.9 | AZ15: 8.3 | BA15: 2.7 | BB15: 18.2 | BC15: 43.4 | BE15: 11.5 | BF15: 85.9 | BP15: 83.9 | BQ15: 177.8 | BR15: 175.7 | BS15: 200 | BT15: 276 | CC15: 4.1 | CD15: 81.5 | CE15: 106.1 | CF15: 63.1 | CG15: 72.1 | CH15: 30.6 | CL15: 147 | CM15: 148.3 | CN15: 149 | CT15: 50.4 | CU15: 0 | CV15: 0 | CW15: 32 | CX15: 0 | CY15: 6.5 | CZ15: 0 | DA15: 16.7 | DB15: 9.9 | DC15: 4.8 | DD15: 0.7 | DE15: 0 | DF15: 4.2 | DG15: 20 | DH15: 20 | DI15: 12.4 | DJ15: 3.5 | DK15: 18.5 | DL15: 0 | DM15: 0 | DN15: 14.8 | DO15: 37.5 | DP15: 3 | DQ15: 1.1 | DR15: 2.4 | DS15: 3.1 | DT15: 0 | DU15: 3.2 | DV15: 10.3 | DW15: 1.9 | DY15: 13.8 | DZ15: 5.6 | EA15: 7.1 | EB15: 9.7 | EC15: 19.9 | ED15: 12.1 | EE15: 12.5 | EF15: 0 | EG15: 36.3 | EH15: 44.4 | EI15: 3.2 | EJ15: 4.6 | EK15: 10.1 | EL15: 3.4 | EM15: 8.1 | EN15: 8.5 | EO15: 9.1 | EP15: 9.4 | EQ15: 3.7 | ER15: 0 | ES15: 0 | ET15: 0 | EU15: 0.6 | EV15: 37.8 | EW15: 32.4 | EX15: 0 | EY15: 0 | EZ15: 9.8 | FA15: 20 | FB15: 9.7 | FC15: 44.3 | FD15: 16.4 | FG15: 16.4 | FI15: 4.9 | FJ15: 6273.6 | FL15: 24.1029 | FM15: 0 | FO15: 13.2 | FP15: 0 | FQ15: 18.92753 | FR15: 11.5 | FS15: 16 | FT15: 83.73043
A16: 05/06/2025 | B16: 03:00 | C16: 139.7 | D16: 599 | E16: 198.5 | H16: 60.2 | I16: 160.8 | M16: 205.8 | N16: 208.6 | O16: 200.5 | R16: 557.9 | S16: 4.9 | X16: 163.9 | Y16: 7.3 | Z16: 5.2 | AB16: 6.9 | AC16: 11.8 | AD16: 61.1 | AI16: 70.4 | AJ16: 93.6 | AN16: 6.5 | AO16: 0 | AP16: 55 | AQ16: 54.5 | AR16: 29.8 | AS16: 18.8 | AT16: 13.2 | AU16: 89.3 | AV16: 180.9 | AW16: 182.6 | AX16: 184 | AY16: 105.8 | AZ16: 8.4 | BA16: 2.8 | BB16: 18.2 | BC16: 43.3 | BE16: 11.6 | BF16: 124.5 | BP16: 83.9 | BQ16: 177.5 | BR16: 175.5 | BS16: 200 | BT16: 276.5 | CC16: 4 | CD16: 98.7 | CE16: 112.9 | CF16: 63.1 | CG16: 72 | CH16: 30.6 | CL16: 147.5 | CM16: 148.2 | CN16: 149.4 | CT16: 50.5 | CU16: 0 | CV16: 0 | CW16: 27.9 | CX16: 0 | CY16: 4.8 | CZ16: 0 | DA16: 16.7 | DB16: 9.9 | DC16: 4.7 | DD16: 0.7 | DE16: 0 | DF16: 4.1 | DG16: 20 | DH16: 20 | DI16: 12.4 | DJ16: 3.5 | DK16: 18.5 | DL16: 0 | DM16: 0 | DN16: 12.9 | DO16: 36.4 | DP16: 3 | DQ16: 1.1 | DR16: 2.4 | DS16: 3.1 | DT16: 0 | DU16: 3.2 | DV16: 10.3 | DW16: 1.9 | DY16: 13.8 | DZ16: 5.6 | EA16: 7.2 | EB16: 9.8 | EC16: 19.9 | ED16: 14.6 | EE16: 7.3 | EF16: 0 | EG16: 14.4 | EH16: 37 | EI16: 1.2 | EJ16: 0.2 | EK16: 10.1 | EL16: 3.4 | EM16: 8.1 | EN16: 8.5 | EO16: 9.1 | EP16: 9.4 | EQ16: 2.3 | ER16: 0 | ES16: 0 | ET16: 0 | EU16: 0.6 | EV16: 15.9 | EW16: 17.4 | EX16: 0 | EY16: 0 | EZ16: 9.7 | FA16: 20 | FB16: 8.6 | FC16: 44.3 | FD16: 16.5 | FG16: 16.2 | FI16: 6.5 | FJ16: 6230.7 | FL16: 24.09977 | FM16: 0 | FO16: 13.2 | FP16: 0 | FQ16: 18.92741 | FR16: 11.5 | FS16: 16.2 | FT16: 83.92718
A17: 05/06/2025 | B17: 03:30 | C17: 138.9 | D17: 596 | E17: 198.3 | H17: 59.9 | I17: 158.9 | M17: 206.8 | N17: 208.8 | O17: 199.6 | R17: 554.1 | S17: 4.9 | X17: 162.5 | Y17: 6.9 | Z17: 5.1 | AB17: 6.8 | AC17: 11.7 | AD17: 60 | AI17: 69.9 | AJ17: 129 | AN17: 6.5 | AO17: 0 | AP17: 55 | AQ17: 51.7 | AR17: 30.8 | AS17: 18.8 | AT17: 13.2 | AU17: 86.2 | AV17: 181.8 | AW17: 182.4 | AX17: 183.5 | AY17: 106.6 | AZ17: 8.4 | BA17: 2.7 | BB17: 17.7 | BC17: 43.2 | BE17: 11.3 | BF17: 53.9 | BP17: 83.8 | BQ17: 177.4 | BR17: 175.2 | BS17: 200 | BT17: 275.4 | CC17: 4 | CD17: 73.2 | CE17: 105.5 | CF17: 62.9 | CG17: 75 | CH17: 30.6 | CL17: 147.3 | CM17: 148.2 | CN17: 149.2 | CT17: 50.5 | CU17: 0 | CV17: 0 | CW17: 29.3 | CX17: 0 | CY17: 8.5 | CZ17: 0 | DA17: 16.7 | DB17: 9.9 | DC17: 4.8 | DD17: 0.7 | DE17: 0 | DF17: 4.1 | DG17: 19.8 | DH17: 20 | DI17: 12.4 | DJ17: 3.5 | DK17: 18.5 | DL17: 0 | DM17: 0 | DN17: 11.6 | DO17: 30.3 | DP17: 3 | DQ17: 1.1 | DR17: 2.4 | DS17: 3.1 | DT17: 0 | DU17: 3.2 | DV17: 10.3 | DW17: 1.9 | DY17: 12.6 | DZ17: 5.6 | EA17: 7 | EB17: 9.5 | EC17: 20 | ED17: 14.5 | EE17: 6.1 | EF17: 0 | EG17: 13.2 | EH17: 27.6 | EI17: 1.1 | EJ17: 0.5 | EK17: 10.1 | EL17: 3.4 | EM17: 8.1 | EN17: 8.6 | EO17: 9.2 | EP17: 9.5 | EQ17: 3.2 | ER17: 0 | ES17: 0 | ET17: 0 | EU17: 0.6 | EV17: 20.6 | EW17: 13.4 | EX17: 0 | EY17: 0 | EZ17: 9.8 | FA17: 20 | FB17: 9.1 | FC17: 44.4 | FD17: 16.5 | FG17: 16.3 | FI17: 6.3 | FJ17: 6131.9 | FL17: 24.09961 | FM17: 0 | FO17: 13.2 | FP17: 0 | FQ17: 18.92696 | FR17: 11.7 | FS17: 16.1 | FT17: 84.02657
A18: 05/06/2025 | B18: 04:00 | C18: 140 | D18: 602.8 | E18: 198.5 | H18: 34.3 | I18: 162.5 | M18: 206 | N18: 209.4 | O18: 198.9 | R18: 560.4 | S18: 4.9 | X18: 165.7 | Y18: 7.7 | Z18: 5.3 | AB18: 6.8 | AC18: 11.5 | AD18: 61.6 | AI18: 70.7 | AJ18: 78 | AN18: 6.5 | AO18: 152.2 | AP18: 55.8 | AQ18: 53.1 | AR18: 29.7 | AS18: 18.8 | AT18: 13.2 | AU18: 91 | AV18: 183.9 | AW18: 184.4 | AX18: 184.7 | AY18: 107.7 | AZ18: 8.3 | BA18: 2.7 | BB18: 18.9 | BC18: 44 | BE18: 11.6 | BF18: 72.6 | BP18: 84 | BQ18: 177.7 | BR18: 175.6 | BS18: 200 | BT18: 274.8 | CC18: 4 | CD18: 84.8 | CE18: 108.1 | CF18: 63.4 | CG18: 75.1 | CH18: 30.8 | CL18: 147.4 | CM18: 148.3 | CN18: 149.4 | CT18: 50.4 | CU18: 0 | CV18: 0 | CW18: 26.7 | CX18: 0 | CY18: 8.5 | CZ18: 0 | DA18: 16.7 | DB18: 10 | DC18: 2.8 | DD18: 0.7 | DE18: 0 | DF18: 4.4 | DG18: 20.2 | DH18: 20 | DI18: 12.4 | DJ18: 3.5 | DK18: 18.5 | DL18: 0 | DM18: 0 | DN18: 11.6 | DO18: 29.4 | DP18: 3 | DQ18: 1.1 | DR18: 2.4 | DS18: 3.1 | DT18: 0 | DU18: 3.2 | DV18: 10.3 | DW18: 1.9 | DY18: 12.5 | DZ18: 5.6 | EA18: 7.3 | EB18: 10.2 | EC18: 20 | ED18: 15.1 | EE18: 5 | EF18: 0 | EG18: 8.8 | EH18: 13.5 | EI18: 0.7 | EJ18: 1 | EK18: 10 | EL18: 3.4 | EM18: 8.3 | EN18: 8.6 | EO18: 9.2 | EP18: 9.5 | EQ18: 3.4 | ER18: 0 | ES18: 0 | ET18: 0 | EU18: 0.6 | EV18: 11.2 | EW18: 5.9 | EX18: 0 | EY18: 0 | EZ18: 9.8 | FA18: 20 | FB18: 9.3 | FC18: 44.4 | FD18: 16.4 | FG18: 16.2 | FI18: 5.8 | FJ18: 6240 | FL18: 24.09673 | FM18: 0 | FO18: 13.2 | FP18: 0 | FQ18: 18.92648 | FR18: 11.5 | FS18: 16.2 | FT18: 83.92321
A19: 05/06/2025 | B19: 04:30 | C19: 140 | D19: 593.6 | E19: 198 | H19: 32.4 | I19: 159.8 | M19: 207.2 | N19: 209.1 | O19: 200 | R19: 550.7 | S19: 4.7 | X19: 161.1 | Y19: 6.7 | Z19: 5.1 | AB19: 6.8 | AC19: 11.6 | AD19: 59.7 | AI19: 68.4 | AJ19: 55.2 | AN19: 6.5 | AO19: 145.9 | AP19: 54.7 | AQ19: 0 | AR19: 29.5 | AS19: 18.8 | AT19: 13.2 | AU19: 88.7 | AV19: 179.2 | AW19: 179.4 | AX19: 183.5 | AY19: 105.5 | AZ19: 8.4 | BA19: 2.8 | BB19: 16.9 | BC19: 42.5 | BE19: 11.1 | BF19: 72.4 | BP19: 82.7 | BQ19: 178.2 | BR19: 176.1 | BS19: 200 | BT19: 275.4 | CC19: 4 | CD19: 55.3 | CE19: 92 | CF19: 61.8 | CG19: 77.2 | CH19: 30.2 | CL19: 147.3 | CM19: 148.4 | CN19: 149.2 | CT19: 97.2 | CU19: 37.6 | CV19: 0 | CW19: 29 | CX19: 0 | CY19: 8.7 | CZ19: 0 | DA19: 16.8 | DB19: 9.9 | DC19: 2.9 | DD19: 0.7 | DE19: 0 | DF19: 4.4 | DG19: 19.6 | DH19: 20 | DI19: 12.4 | DJ19: 3.5 | DK19: 18.5 | DL19: 0 | DM19: 0 | DN19: 9.5 | DO19: 28.9 | DP19: 3 | DQ19: 1.1 | DR19: 2.4 | DS19: 3.1 | DT19: 0 | DU19: 3.1 | DV19: 10.3 | DW19: 1.9 | DY19: 12.4 | DZ19: 5.6 | EA19: 7 | EB19: 9.4 | EC19: 19.8 | ED19: 16.1 | EE19: 5.6 | EF19: 0 | EG19: 5.7 | EH19: 8.4 | EI19: 0.6 | EJ19: 0.4 | EK19: 10 | EL19: 3.3 | EM19: 8.3 | EN19: 8.6 | EO19: 9.2 | EP19: 9.5 | EQ19: 3 | ER19: 0 | ES19: 0 | ET19: 0 | EU19: 0.6 | EV19: 5.4 | EW19: 3.4 | EX19: 0 | EY19: 0 | EZ19: 9.8 | FA19: 20 | FB19: 9.4 | FC19: 44.4 | FD19: 16.5 | FG19: 16.1 | FI19: 6.4 | FJ19: 6126.3 | FL19: 24.09669 | FM19: 0 | FO19: 13.2 | FP19: 0 | FQ19: 18.92628 | FR19: 11.5 | FS19: 16.2 | FT19: 83.92297
A20: 05/06/2025 | B20: 05:00 | C20: 139.8 | D20: 600.5 | E20: 200.2 | H20: 34.3 | I20: 165.5 | M20: 207.3 | N20: 208.2 | O20: 200.2 | R20: 559.6 | S20: 4.9 | X20: 164 | Y20: 7.5 | Z20: 5.6 | AB20: 6.8 | AC20: 11.6 | AD20: 60.9 | AI20: 70.5 | AJ20: 88.3 | AN20: 6.5 | AO20: 150.4 | AP20: 56 | AQ20: 0 | AR20: 31.2 | AS20: 18.8 | AT20: 13.2 | AU20: 90 | AV20: 182.8 | AW20: 184.5 | AX20: 184.7 | AY20: 106.8 | AZ20: 8.4 | BA20: 2.8 | BB20: 18.4 | BC20: 43.7 | BE20: 11.6 | BF20: 88.4 | BP20: 84 | BQ20: 177.5 | BR20: 175.8 | BS20: 200 | BT20: 274.8 | CC20: 4 | CD20: 96.2 | CE20: 109.5 | CF20: 63.2 | CG20: 78.1 | CH20: 30.7 | CL20: 102.9 | CM20: 101.8 | CN20: 121.4 | CT20: 145.5 | CU20: 74.9 | CV20: 0 | CW20: 26 | CX20: 0 | CY20: 9.5 | CZ20: 0 | DA20: 16.8 | DB20: 9.9 | DC20: 2.9 | DD20: 0.7 | DE20: 0 | DF20: 4.4 | DG20: 20.1 | DH20: 20 | DI20: 12.5 | DJ20: 3.5 | DK20: 18.5 | DL20: 0 | DM20: 0 | DN20: 9.6 | DO20: 18.1 | DP20: 3 | DQ20: 1.1 | DR20: 2.4 | DS20: 3.1 | DT20: 0 | DU20: 3.1 | DV20: 10.3 | DW20: 1.8 | DY20: 12.3 | DZ20: 5.6 | EA20: 7.2 | EB20: 9.7 | EC20: 19.8 | ED20: 21.3 | EE20: 5.2 | EF20: 0 | EG20: 5.6 | EH20: 12.3 | EI20: 1 | EJ20: 0.8 | EK20: 10 | EL20: 3.3 | EM20: 8.2 | EN20: 8.7 | EO20: 9.2 | EP20: 9.6 | EQ20: 4.7 | ER20: 0 | ES20: 0 | ET20: 0 | EU20: 0.6 | EV20: 3.4 | EW20: 4.8 | EX20: 0 | EY20: 0 | EZ20: 9.8 | FA20: 20 | FB20: 9.4 | FC20: 44.5 | FD20: 16.5 | FG20: 16.3 | FI20: 3.6 | FJ20: 6254.9 | FL20: 24.1263 | FM20: 0 | FO20: 13.2 | FP20: 0 | FQ20: 18.92603 | FR20: 11.7 | FS20: 16.2 | FT20: 84.15233
A21: 05/06/2025 | B21: 05:30 | C21: 139.8 | D21: 601.6 | E21: 200.1 | H21: 34.3 | I21: 167.7 | M21: 209.6 | N21: 209 | O21: 200.3 | R21: 561.6 | S21: 4.9 | X21: 162.6 | Y21: 7.5 | Z21: 5.4 | AB21: 6.9 | AC21: 11.6 | AD21: 61.3 | AI21: 90.4 | AJ21: 59.1 | AN21: 6.5 | AO21: 156.7 | AP21: 55 | AQ21: 0 | AR21: 29.6 | AS21: 18.8 | AT21: 13.2 | AU21: 87.9 | AV21: 182.3 | AW21: 183.9 | AX21: 185.3 | AY21: 105.6 | AZ21: 8.3 | BA21: 2.8 | BB21: 18.4 | BC21: 43.7 | BE21: 11.3 | BF21: 133.3 | BP21: 84.1 | BQ21: 178.2 | BR21: 176.5 | BS21: 200 | BT21: 275.3 | CC21: 4.1 | CD21: 110.2 | CE21: 113.5 | CF21: 63.3 | CG21: 78.2 | CH21: 30.6 | CL21: 103.4 | CM21: 102 | CN21: 121.5 | CT21: 213.6 | CU21: 98.4 | CV21: 0 | CW21: 22.8 | CX21: 0 | CY21: 11.9 | CZ21: 0 | DA21: 16.8 | DB21: 9.9 | DC21: 3 | DD21: 0.7 | DE21: 0 | DF21: 4.4 | DG21: 20 | DH21: 20 | DI21: 12.4 | DJ21: 3.5 | DK21: 18.5 | DL21: 0 | DM21: 0 | DN21: 7.7 | DO21: 16.2 | DP21: 3 | DQ21: 1.1 | DR21: 2.4 | DS21: 3.1 | DT21: 0 | DU21: 3.2 | DV21: 10.3 | DW21: 1.8 | DY21: 12.5 | DZ21: 5.6 | EA21: 7.3 | EB21: 9.9 | EC21: 20 | ED21: 17.6 | EE21: 3.4 | EF21: 0 | EG21: 3.7 | EH21: 6.6 | EI21: 1 | EJ21: 0.3 | EK21: 10 | EL21: 3.3 | EM21: 8.1 | EN21: 8.7 | EO21: 9.3 | EP21: 9.6 | EQ21: 6.4 | ER21: 0 | ES21: 0 | ET21: 0 | EU21: 0.6 | EV21: 3.1 | EW21: 8.8 | EX21: 0 | EY21: 0 | EZ21: 9.8 | FA21: 20 | FB21: 9.5 | FC21: 44.4 | FD21: 16.4 | FG21: 16.2 | FI21: 6.3 | FJ21: 6400.3 | FL21: 24.19051 | FM21: 0 | FO21: 13.2 | FP21: 0 | FQ21: 18.92618 | FR21: 11.5 | FS21: 16.2 | FT21: 84.01669
A22: 05/06/2025 | B22: 06:00 | C22: 119.1 | D22: 599.9 | E22: 200.3 | H22: 34.1 | I22: 170.1 | M22: 207.1 | N22: 207.8 | O22: 200 | R22: 558.6 | S22: 5 | X22: 165 | Y22: 7.7 | Z22: 5.5 | AB22: 6.8 | AC22: 11.6 | AD22: 60.7 | AI22: 90.9 | AJ22: 97.1 | AN22: 6.5 | AO22: 164.8 | AP22: 55.6 | AQ22: 0 | AR22: 31.4 | AS22: 18.8 | AT22: 13.2 | AU22: 88.8 | AV22: 184.3 | AW22: 183.5 | AX22: 184.3 | AY22: 105.7 | AZ22: 8.4 | BA22: 2.8 | BB22: 29.9 | BC22: 44 | BE22: 11.5 | BF22: 139.4 | BP22: 84.1 | BQ22: 178.3 | BR22: 175.9 | BS22: 200 | BT22: 275.2 | CC22: 4 | CD22: 171.1 | CE22: 123.4 | CF22: 63.6 | CG22: 78.1 | CH22: 30.8 | CL22: 103.9 | CM22: 101 | CN22: 120.9 | CT22: 217.6 | CU22: 103 | CV22: 0 | CW22: 25.3 | CX22: 0 | CY22: 10.8 | CZ22: 0 | DA22: 16.7 | DB22: 9.9 | DC22: 2.9 | DD22: 0.7 | DE22: 0 | DF22: 4.3 | DG22: 20.3 | DH22: 20 | DI22: 13.2 | DJ22: 3.5 | DK22: 18.5 | DL22: 0.1 | DM22: 0 | DN22: 9.8 | DO22: 15.6 | DP22: 3 | DQ22: 1.1 | DR22: 2.4 | DS22: 3.1 | DT22: 0 | DU22: 3.1 | DV22: 10.3 | DW22: 1.8 | DY22: 12.3 | DZ22: 5.6 | EA22: 7.5 | EB22: 9.9 | EC22: 20 | ED22: 14.2 | EE22: 0.3 | EF22: 0 | EG22: 3 | EH22: 4.6 | EI22: 0.5 | EJ22: 0.1 | EK22: 10 | EL22: 3.3 | EM22: 8.1 | EN22: 8.7 | EO22: 9.3 | EP22: 9.6 | EQ22: 5.6 | ER22: 0 | ES22: 0 | ET22: 0 | EU22: 0.6 | EV22: 8.5 | EW22: 22.3 | EX22: 0 | EY22: 0 | EZ22: 9.8 | FA22: 20 | FB22: 9.2 | FC22: 44.3 | FD22: 16.4 | FG22: 8 | FI22: 6.5 | FJ22: 6525.7 | FL22: 24.28962 | FM22: 0 | FO22: 13.2 | FP22: 0 | FQ22: 18.92581 | FR22: 11.6 | FS22: 16.1 | FT22: 84.11543
... A58: 06/06/2025 | B58: 00:00 | C58: 135.2 | D58: 639.4 | E58: 216.6 | H58: 90.2 | I58: 147.4 | M58: 164.7 | N58: 165 | O58: 169.5 | R58: 544.8 | S58: 4.6 | X58: 162.9 | Y58: 6.8 | Z58: 5 | AB58: 6.8 | AC58: 14.1 | AD58: 60.4 | AI58: 109.1 | AJ58: 136.2 | AN58: 6.5 | AO58: 151.4 | AP58: 48.7 | AQ58: 45.6 | AR58: 26 | AS58: 18.6 | AT58: 13.2 | AU58: 88.4 | AV58: 119.8 | AW58: 120.2 | AX58: 151 | AY58: 103.8 | AZ58: 8.4 | BA58: 2.8 | BB58: 17.4 | BC58: 43.8 | BE58: 10.7 | BF58: 75.4 | BP58: 80.5 | BQ58: 178.6 | BR58: 176 | BS58: 200 | BT58: 276.2 | CC58: 4 | CD58: 57.1 | CE58: 99.5 | CF58: 62.9 | CG58: 75.8 | CH58: 29.5 | CL58: 102.4 | CM58: 101.9 | CN58: 121.4 | CT58: 218.6 | CU58: 104 | CV58: 0 | CW58: 50.3 | CX58: 0 | CY58: 15.5 | CZ58: 0 | DA58: 15.9 | DB58: 9.9 | DC58: 5.4 | DD58: 0.6 | DE58: 1.5 | DF58: 4.2 | DG58: 19.6 | DH58: 20 | DI58: 12.4 | DJ58: 3.6 | DK58: 18.5 | DL58: 0 | DM58: 0 | DN58: 14.2 | DO58: 36.2 | DP58: 4.4 | DQ58: 1 | DR58: 2.2 | DS58: 3 | DT58: 0 | DU58: 3 | DV58: 10.1 | DW58: 1.9 | DY58: 11.5 | DZ58: 5.4 | EA58: 6.8 | EB58: 8.9 | EC58: 19.9 | ED58: 7.5 | EE58: 15.5 | EF58: 0 | EG58: 70.2 | EH58: 84.1 | EI58: 7.7 | EJ58: 5.4 | EK58: 9.3 | EL58: 3.2 | EM58: 8.1 | EN58: 8.3 | EO58: 9.1 | EP58: 9.2 | EQ58: 13.6 | ER58: 0 | ES58: 0 | ET58: 0 | EU58: 0.6 | EV58: 84.1 | EW58: 80.3 | EX58: 0 | EY58: 0 | EZ58: 9.8 | FA58: 20 | FB58: 9.4 | FC58: 44 | FD58: 13.2 | FG58: 17.8 | FI58: 7.3 | FJ58: 6562.4 | FL58: 24.17401 | FM58: 0.642 | FO58: 13.2 | FP58: 27.14595 | FQ58: 18.927 | FR58: 11.5 | FS58: 16.1 | FT58: 111.68896
A59: EJEC | C59: 3106.9 | D59: 15233.7 | E59: 5110.4 | F59: 0 | G59: 0 | H59: 1804.2 | I59: 3801.6 | J59: 0 | K59: 0 | L59: 0 | M59: 4651.2 | N59: 4688.3 | O59: 4590.9 | P59: 0 | Q59: 0 | R59: 12137.1 | S59: 115.75 | T59: 0 | U59: 0 | V59: 0 | W59: 0 | X59: 3918.4 | Y59: 173.75 | Z59: 127.2 | AA59: 0 | AB59: 163.65 | AC59: 310.5 | AD59: 1981.05 | AE59: 0 | AF59: 0 | AG59: 0 | AH59: 0 | AI59: 2194.25 | AJ59: 3591.4 | AK59: 0 | AL59: 0 | AM59: 0 | AN59: 156 | AO59: 5367.9 | AP59: 1238.5 | AQ59: 1810.7 | AR59: 644.75 | AS59: 450.7 | AT59: 257.65 | AU59: 2139.5 | AV59: 3818.75 | AW59: 3829.2 | AX59: 4133.1 | AY59: 2507.05 | AZ59: 199.5 | BA59: 65.5 | BB59: 470 | BC59: 1041.1 | BD59: 0 | BE59: 389.65 | BF59: 2494.9 | BG59: 0 | BH59: 0 | BI59: 0 | BJ59: 0 | BK59: 0 | BL59: 0 | BM59: 0 | BN59: 0 | BO59: 0 | BP59: 1965.35 | BQ59: 4250.8 | BR59: 4200 | BS59: 4774.8 | BT59: 6589.3 | BU59: 0 | BV59: 0 | BW59: 0 | BX59: 0 | BY59: 0 | BZ59: 0 | CA59: 0 | CB59: 0 | CC59: 95.05 | CD59: 2371.75 | CE59: 2613.65 | CF59: 1537.55 | CG59: 1823.15 | CH59: 723.1 | CI59: 0 | CJ59: 0 | CK59: 0 | CL59: 3099.85 | CM59: 3100.75 | CN59: 3318.8 | CO59: 0 | CP59: 0 | CQ59: 0 | CR59: 0 | CS59: 0 | CT59: 4308.95 | CU59: 2014 | CV59: 8.15 | CW59: 1123.05 | CX59: 598 | CY59: 320.85 | CZ59: 2.6 | DA59: 394.1 | DB59: 237.2 | DC59: 120.1 | DD59: 16.4 | DE59: 27 | DF59: 102.5 | DG59: 478.35 | DH59: 480 | DI59: 294.05 | DJ59: 85 | DK59: 444 | DL59: 117 | DM59: 140.7 | DN59: 334.15 | DO59: 1010.45 | DP59: 68.7 | DQ59: 24.8 | DR59: 56 | DS59: 73.1 | DT59: 106.1 | DU59: 75.6 | DV59: 244.5 | DW59: 46.45 | DX59: 0 | DY59: 294 | DZ59: 126.35 | EA59: 172.45 | EB59: 242.95 | EC59: 478.4 | ED59: 282.4 | EE59: 544.2 | EF59: 247.4 | EG59: 918.9 | EH59: 1086.3 | EI59: 133.2 | EJ59: 86.7 | EK59: 233.05 | EL59: 79.5 | EM59: 199.45 | EN59: 206.85 | EO59: 224.8 | EP59: 228.1 | EQ59: 252.8 | ER59: 1890.8 | ES59: 114.2 | ET59: 1029.4 | EU59: 14.4 | EV59: 1306.05 | EW59: 1488.1 | EX59: 766.65 | EY59: 114.25 | EZ59: 234.8 | FA59: 479.4 | FB59: 220.9 | FC59: 1060.65 | FD59: 348.3 | FE59: 0 | FF59: 0 | FG59: 354.1 | FH59: 0 | FI59: 152.85 | FJ59: 168143.1 | FL59: 559.68205 | FM59: 79.4765 | FN59: 0 | FO59: 316.8 | FP59: 471.11372 | FQ59: 454.31721 | FR59: 276.5 | FS59: 387.2 | FT59: 2545.0895
FJ61: 168385.19
FJ63: =+FJ61-FJ59 -> 242.08645

Sheet REACTIVA
B3: jueves, 5 de Junio del 2025
A5: POTENCIA REACTIVA EJECUTADA DE LAS UNIDADES DE GENERACIÓN DEL COES (MVAR) | FK5: CENTRALES NO INTEGRANTES COES
A6: FECHA | B6: HORA | C6: 65333 | D6: 101 | E6: 102 | F6: 42667 | G6: 42668 | H6: 126 | I6: 127 | J6: 138 | K6: 139 | L6: 197 | M6: 203 | N6: 204 | O6: 230 | P6: 209 | Q6: 56677 | R6: 796 | S6: 2146 | T6: 142 | U6: 143 | V6: 125 | W6: 187 | X6: 163 | Y6: 298 | Z6: 219 | AA6: 151 | AB6: 152 | AC6: 153 | AD6: 154 | AE6: 756 | AF6: 156 | AG6: 155 | AH6: 182 | AI6: 212 | AJ6: 758 | AK6: 263 | AL6: 265 | AM6: 775 | AN6: 777 | AO6: 2154 | AP6: 150 | AQ6: 149 | AR6: 188 | AS6: 2131 | AT6: 755 | AU6: 252 | AV6: 249 | AW6: 250 | AX6: 117 | AY6: 267 | AZ6: 268 | BA6: 119 | BB6: 120 | BC6: 189 | BD6: 122 | BE6: 266 | BF6: 337 | BG6: 338 | BH6: 251 | BI6: 115 | BJ6: 239 | BK6: 288 | BL6: 240 | BM6: 241 | BN6: 242 | BO6: 191 | BP6: 194 | BQ6: 196 | BR6: 207 | BS6: 236 | BT6: 795 | BU6: 285 | BV6: 995 | BW6: 996 | BX6: 997 | BY6: 766 | BZ6: 926 | CA6: 924 | CB6: 121 | CC6: 103 | CD6: 104 | CE6: 106 | CF6: 105 | CG6: 107 | CH6: 110 | CI6: 109 | CJ6: 144 | CK6: 113 | CL6: 114 | CM6: 193 | CN6: 208 | CO6: 786 | CP6: 787 | CQ6: 788 | CR6: 789 | CS6: 248 | CT6: 2159 | CU6: 303 | CV6: 59715 | CW6: 62255 | CX6: 1263 | CY6: 61800 | CZ6: 2194 | DA6: 216 | DB6: 198 | DC6: 49607 | DD6: 214 | DE6: 260 | DF6: 2152 | DG6: 2128 | DH6: 247 | DI6: 228 | DJ6: 2135 | DK6: 261 | DL6: 237 | DM6: 253 | DN6: 770 | DO6: 225 | DP6: 2201 | DQ6: 2171 | DR6: 760 | DS6: 235 | DT6: 238 | DU6: 2184 | DV6: 61855 | DW6: 223 | DX6: 226 | DY6: 201 | DZ6: 258 | EA6: 259 | EB6: 920 | EC6: 257 | ED6: 256 | EE6: 2148 | EF6: 58288 | EG6: 58289 | EH6: 58839 | EI6: 58840 | EJ6: 296 | EK6: 297 | EL6: 211 | EM6: 2175 | EN6: 2178 | EO6: 2181 | EP6: 1262 | EQ6: 63425 | ER6: 233 | ES6: 2150 | ET6: 2165 | EU6: 2161 | EV6: 61197 | EW6: 58851 | EX6: 234 | EY6: 215 | EZ6: 917 | FA6: 289 | FB6: 58333 | FC6: 58336 | FD6: 202 | FE6: 58487 | FF6: 213 | FG6: 232 | FH6: 2190 | FI6: TOTAL COES | FK6: 221 | FL6: 222 | FM6: 224 | FN6: 2187 | FO6: 227 | FP6: 49400 | FQ6: 199 | FR6: 200 | FS6: TOTAL NO COES
C7: SUR | D7: CENTRO | E7: CENTRO | F7: NORTE | G7: NORTE | H7: NORTE | I7: NORTE | J7: CENTRO | K7: CENTRO | L7: CENTRO | M7: CENTRO | N7: CENTRO | O7: CENTRO | P7: CENTRO | Q7: CENTRO | R7: CENTRO | S7: CENTRO | T7: CENTRO | U7: CENTRO | V7: CENTRO | W7: CENTRO | X7: SUR | Y7: SUR | Z7: CENTRO | AA7: SUR | AB7: SUR | AC7: SUR | AD7: SUR | AE7: SUR | AF7: SUR | AG7: SUR | AH7: SUR | AI7: CENTRO | AJ7: NORTE | AK7: NORTE | AL7: NORTE | AM7: CENTRO | AN7: CENTRO | AO7: CENTRO | AP7: CENTRO | AQ7: CENTRO | AR7: CENTRO | AS7: CENTRO | AT7: SUR | AU7: CENTRO | AV7: CENTRO | AW7: CENTRO | AX7: CENTRO | AY7: CENTRO | AZ7: CENTRO | BA7: CENTRO | BB7: CENTRO | BC7: SUR | BD7: NORTE | BE7: CENTRO | BF7: CENTRO | BG7: CENTRO | BH7: CENTRO | BI7: NORTE | BJ7: NORTE | BK7: NORTE | BL7: SUR | BM7: SUR | BN7: SUR | BO7: CENTRO | BP7: CENTRO | BQ7: CENTRO | BR7: CENTRO | BS7: CENTRO | BT7: CENTRO | BU7: CENTRO | BV7: SUR | BW7: SUR | BX7: SUR | BY7: NORTE | BZ7: SUR | CA7: CENTRO | CB7: NORTE | CC7: CENTRO | CD7: CENTRO | CE7: CENTRO | CF7: CENTRO | CG7: CENTRO | CH7: CENTRO | CI7: CENTRO | CJ7: CENTRO | CK7: CENTRO | CL7: CENTRO | CM7: CENTRO | CN7: CENTRO | CO7: SUR | CP7: SUR | CQ7: SUR | CR7: SUR | CS7: CENTRO | CT7: CENTRO | CU7: CENTRO | CV7: CENTRO | CW7: SUR | CX7: NORTE | CY7: NORTE | CZ7: NORTE | DA7: NORTE | DB7: NORTE | DC7: SUR | DD7: CENTRO | DE7: CENTRO | DF7: CENTRO | DG7: NORTE | DH7: NORTE | DI7: CENTRO | DJ7: CENTRO | DK7: SUR | DL7: SUR | DM7: CENTRO | DN7: CENTRO | DO7: CENTRO | DP7: CENTRO | DQ7: CENTRO | DR7: CENTRO | DS7: SUR | DT7: CENTRO | DU7: CENTRO | DV7: NORTE | DW7: CENTRO | DX7: CENTRO | DY7: NORTE | DZ7: CENTRO | EA7: CENTRO | EB7: CENTRO | EC7: NORTE | ED7: NORTE | EE7: SUR | EF7: CENTRO | EG7: CENTRO | EH7: CENTRO | EI7: CENTRO | EJ7: CENTRO | EK7: CENTRO | EL7: SUR | EM7: SUR | EN7: SUR | EO7: SUR | EP7: NORTE | EQ7: SUR | ER7: SUR | ES7: SUR | ET7: CENTRO | EU7: CENTRO | EV7: CENTRO | EW7: SUR | EX7: SUR | EY7: NORTE | EZ7: CENTRO | FA7: NORTE | FB7: NORTE | FC7: NORTE | FD7: CENTRO | FE7: CENTRO | FF7: CENTRO | FG7: NORTE | FH7: NORTE | FK7: NORTE | FL7: CENTRO | FM7: NORTE | FN7: NORTE | FO7: NORTE | FP7: NORTE | FQ7: NORTE | FR7: NORTE
C8: HIDROELÉCTRICA | D8: HIDROELÉCTRICA | E8: HIDROELÉCTRICA | F8: TERMOELÉCTRICA | G8: TERMOELÉCTRICA | H8: HIDROELÉCTRICA | I8: HIDROELÉCTRICA | J8: TERMOELÉCTRICA | K8: TERMOELÉCTRICA | L8: TERMOELÉCTRICA | M8: TERMOELÉCTRICA | N8: TERMOELÉCTRICA | O8: TERMOELÉCTRICA | P8: TERMOELÉCTRICA | Q8: TERMOELÉCTRICA | R8: HIDROELÉCTRICA | S8: HIDROELÉCTRICA | T8: TERMOELÉCTRICA | U8: TERMOELÉCTRICA | V8: TERMOELÉCTRICA | W8: TERMOELÉCTRICA | X8: HIDROELÉCTRICA | Y8: HIDROELÉCTRICA | Z8: TERMOELÉCTRICA | AA8: HIDROELÉCTRICA | AB8: HIDROELÉCTRICA | AC8: HIDROELÉCTRICA | AD8: HIDROELÉCTRICA | AE8: TERMOELÉCTRICA | AF8: TERMOELÉCTRICA | AG8: TERMOELÉCTRICA | AH8: HIDROELÉCTRICA | AI8: HIDROELÉCTRICA | AJ8: TERMOELÉCTRICA | AK8: TERMOELÉCTRICA | AL8: TERMOELÉCTRICA | AM8: HIDROELÉCTRICA | AN8: HIDROELÉCTRICA | AO8: HIDROELÉCTRICA | AP8: HIDROELÉCTRICA | AQ8: HIDROELÉCTRICA | AR8: HIDROELÉCTRICA | AS8: HIDROELÉCTRICA | AT8: HIDROELÉCTRICA | AU8: TERMOELÉCTRICA | AV8: TERMOELÉCTRICA | AW8: TERMOELÉCTRICA | AX8: HIDROELÉCTRICA | AY8: HIDROELÉCTRICA | AZ8: HIDROELÉCTRICA | BA8: HIDROELÉCTRICA | BB8: HIDROELÉCTRICA | BC8: HIDROELÉCTRICA | BD8: HIDROELÉCTRICA | BE8: HIDROELÉCTRICA | BF8: HIDROELÉCTRICA | BG8: HIDROELÉCTRICA | BH8: HIDROELÉCTRICA | BI8: TERMOELÉCTRICA | BJ8: TERMOELÉCTRICA | BK8: TERMOELÉCTRICA | BL8: TERMOELÉCTRICA | BM8: TERMOELÉCTRICA | BN8: TERMOELÉCTRICA | BO8: HIDROELÉCTRICA | BP8: TERMOELÉCTRICA | BQ8: TERMOELÉCTRICA | BR8: TERMOELÉCTRICA | BS8: TERMOELÉCTRICA | BT8: TERMOELÉCTRICA | BU8: TERMOELÉCTRICA | BV8: TERMOELÉCTRICA | BW8: TERMOELÉCTRICA | BX8: TERMOELÉCTRICA | BY8: HIDROELÉCTRICA | BZ8: TERMOELÉCTRICA | CA8: TERMOELÉCTRICA | CB8: HIDROELÉCTRICA | CC8: HIDROELÉCTRICA | CD8: HIDROELÉCTRICA | CE8: HIDROELÉCTRICA | CF8: HIDROELÉCTRICA | CG8: HIDROELÉCTRICA | CH8: TERMOELÉCTRICA | CI8: TERMOELÉCTRICA | CJ8: TERMOELÉCTRICA | CK8: TERMOELÉCTRICA | CL8: TERMOELÉCTRICA | CM8: TERMOELÉCTRICA | CN8: TERMOELÉCTRICA | CO8: TERMOELÉCTRICA | CP8: TERMOELÉCTRICA | CQ8: TERMOELÉCTRICA | CR8: TERMOELÉCTRICA | CS8: TERMOELÉCTRICA | CT8: TERMOELÉCTRICA | CU8: SOLAR | CV8: EÓLICA | CW8: SOLAR | CX8: EÓLICA | CY8: SOLAR | CZ8: HIDROELÉCTRICA | DA8: HIDROELÉCTRICA | DB8: HIDROELÉCTRICA | DC8: HIDROELÉCTRICA | DD8: HIDROELÉCTRICA | DE8: HIDROELÉCTRICA | DF8: HIDROELÉCTRICA | DG8: HIDROELÉCTRICA | DH8: HIDROELÉCTRICA | DI8: HIDROELÉCTRICA | DJ8: HIDROELÉCTRICA | DK8: SOLAR | DL8: SOLAR | DM8: EÓLICA | DN8: EÓLICA | DO8: TERMOELÉCTRICA | DP8: TERMOELÉCTRICA | DQ8: TERMOELÉCTRICA | DR8: TERMOELÉCTRICA | DS8: SOLAR | DT8: HIDROELÉCTRICA | DU8: HIDROELÉCTRICA | DV8: HIDROELÉCTRICA | DW8: HIDROELÉCTRICA | DX8: HIDROELÉCTRICA | DY8: HIDROELÉCTRICA | DZ8: HIDROELÉCTRICA | EA8: HIDROELÉCTRICA | EB8: HIDROELÉCTRICA | EC8: EÓLICA | ED8: EÓLICA | EE8: SOLAR | EF8: EÓLICA | EG8: EÓLICA | EH8: EÓLICA | EI8: EÓLICA | EJ8: HIDROELÉCTRICA | EK8: HIDROELÉCTRICA | EL8: HIDROELÉCTRICA | EM8: HIDROELÉCTRICA | EN8: HIDROELÉCTRICA | EO8: HIDROELÉCTRICA | EP8: EÓLICA | EQ8: SOLAR | ER8: SOLAR | ES8: SOLAR | ET8: HIDROELÉCTRICA | EU8: EÓLICA | EV8: EÓLICA | EW8: SOLAR | EX8: SOLAR | EY8: HIDROELÉCTRICA | EZ8: HIDROELÉCTRICA | FA8: TERMOELÉCTRICA | FB8: TERMOELÉCTRICA | FC8: TERMOELÉCTRICA | FD8: TERMOELÉCTRICA | FE8: TERMOELÉCTRICA | FF8: TERMOELÉCTRICA | FG8: TERMOELÉCTRICA | FH8: TERMOELÉCTRICA | FK8: HIDROELÉCTRICA | FL8: HIDROELÉCTRICA | FM8: HIDROELÉCTRICA | FN8: HIDROELÉCTRICA | FO8: TERMOELÉCTRICA | FP8: TERMOELÉCTRICA | FQ8: HIDROELÉCTRICA | FR8: HIDROELÉCTRICA
C9: HYDRO GLOBAL PERÚ S.A.C. | D9: ELECTROPERU | E9: ELECTROPERU | F9: ELECTROPERU | G9: ELECTROPERU | H9: ORAZUL ENERGY PERÚ | I9: ORAZUL ENERGY PERÚ | J9: TERMOSELVA | K9: TERMOSELVA | L9: KALLPA GENERACION S.A. | M9: KALLPA GENERACION S.A. | N9: KALLPA GENERACION S.A. | O9: KALLPA GENERACION S.A. | P9: KALLPA GENERACION S.A. | Q9: KALLPA GENERACION S.A. | R9: KALLPA GENERACION S.A. | S9: KALLPA GENERACION S.A. | T9: SHOUGESA | U9: SHOUGESA | V9: SHOUGESA | W9: SHOUGESA | X9: EGEMSA | Y9: EGESUR | Z9: EGESUR | AA9: EGASA | AB9: EGASA | AC9: EGASA | AD9: EGASA | AE9: EGASA | AF9: EGASA | AG9: EGASA | AH9: SAN GABAN | AI9: CELEPSA | AJ9: MINERA CERRO VERDE | AK9: PLANTA DE RESERVA FRIA DE GENERACION DE ETEN S.A. | AL9: PLANTA DE RESERVA FRIA DE GENERACION DE ETEN S.A. | AM9: EMPRESA DE GENERACION HUALLAGA | AN9: EMPRESA DE GENERACION HUALLAGA | AO9: LA VIRGEN | AP9: CHINANGO S.A.C. | AQ9: CHINANGO S.A.C. | AR9: HIDROELECTRICA HUANCHOR S.A.C. | AS9: CELEPSA RENOVABLES S.R.L. | AT9: INLAND ENERGY SAC | AU9: FENIX POWER PERÚ | AV9: FENIX POWER PERÚ | AW9: FENIX POWER PERÚ | AX9: STATKRAFT S.A | AY9: STATKRAFT S.A | AZ9: STATKRAFT S.A | BA9: STATKRAFT S.A | BB9: STATKRAFT S.A | BC9: STATKRAFT S.A | BD9: STATKRAFT S.A | BE9: STATKRAFT S.A | BF9: CENTRALES SANTA ROSA S.A.C. | BG9: CENTRALES SANTA ROSA S.A.C. | BH9: EMPRESA DE GENERACION HUANZA | BI9: ENEL GENERACION PIURA S.A. | BJ9: ENEL GENERACION PIURA S.A. | BK9: ENEL GENERACION PIURA S.A. | BL9: ENGIE | BM9: ENGIE | BN9: ENGIE | BO9: ENGIE | BP9: ENGIE | BQ9: ENGIE | BR9: ENGIE | BS9: ENGIE | BT9: ENGIE | BU9: ENGIE | BV9: ENGIE | BW9: ENGIE | BX9: ENGIE | BY9: ENGIE | BZ9: INFRAESTRUCTURAS Y ENERGIAS DEL PERU S.A.C. | CA9: INFRAESTRUCTURAS Y ENERGIAS DEL PERU S.A.C. | CB9: INVERSIONES SHAQSHA S.A.C. | CC9: ORYGEN PERU S.A.A. | CD9: ORYGEN PERU S.A.A. | CE9: ORYGEN PERU S.A.A. | CF9: ORYGEN PERU S.A.A. | CG9: ORYGEN PERU S.A.A. | CH9: ORYGEN PERU S.A.A. | CI9: ORYGEN PERU S.A.A. | CJ9: ORYGEN PERU S.A.A. | CK9: ORYGEN PERU S.A.A. | CL9: ORYGEN PERU S.A.A. | CM9: ORYGEN PERU S.A.A. | CN9: ORYGEN PERU S.A.A. | CO9: SAMAY I S.A.C | CP9: SAMAY I S.A.C | CQ9: SAMAY I S.A.C | CR9: SAMAY I S.A.C | CS9: TERMOCHILCA S.A.C. | CT9: TERMOCHILCA S.A.C. | CU9: COLCA SOLAR S.A.C. | CV9: ENERGIA RENOVABLE DEL SUR S.A. | CW9: GR CORTARRAMA SOCIEDAD ANONIMA CERRADA | CX9: GR TARUCA SOCIEDAD ANONIMA CERRADA | CY9: KONDU SAC | CZ9: PERUANA DE INVERSIONES EN ENERGIAS RENOVABLES S.A. | DA9: ORAZUL ENERGY PERÚ | DB9: ORAZUL ENERGY PERÚ | DC9: SAN GABAN | DD9: MAJA ENERGIA S.A.C. | DE9: EMPRESA DE GENERACION ELECTRICA CANCHAYLLO SAC | DF9: EMPRESA DE GENERACION ELECTRICA SANTA ANA S.A.C. | DG9: EMPRESA ELECTRICA AGUA AZUL | DH9: EMPRESA ELECTRICA RIO DOBLE | DI9: HIDROCAÑETE S.A. | DJ9: HUAURA POWER GROUP S.A. | DK9: MOQUEGUA FV S.A.C. | DL9: PANAMERICANA SOLAR SAC. | DM9: PARQUE EOLICO MARCONA S.A.C. | DN9: PARQUE EOLICO TRES HERMANAS S.A.C. | DO9: PETRAMAS | DP9: PETRAMAS | DQ9: PETRAMAS | DR9: PETRAMAS | DS9: TACNA SOLAR SAC. | DT9: ELECTRICA YANAPAMPA SAC | DU9: ANDEAN POWER S.A.C. | DV9: ASOCIACIÓN SANTA LUCIA DE CHACAS | DW9: ATRIA ENERGIA S.A.C. | DX9: EGEJUNIN | DY9: EGEJUNIN | DZ9: EGEJUNIN | EA9: EGEJUNIN | EB9: EMPRESA DE GENERACION ELECTRICA RIO BAÑOS S.A.C. | EC9: ENERGÍA EÓLICA S.A. | ED9: ENERGÍA EÓLICA S.A. | EE9: ENGIE | EF9: ENGIE | EG9: ENGIE | EH9: ENGIE | EI9: ENGIE | EJ9: GENERACIÓN ANDINA S.A.C. | EK9: GENERACIÓN ANDINA S.A.C. | EL9: GENERADORA DE ENERGÍA DEL PERÚ | EM9: GENERADORA DE ENERGÍA DEL PERÚ | EN9: GENERADORA DE ENERGÍA DEL PERÚ | EO9: GENERADORA DE ENERGÍA DEL PERÚ | EP9: GR PAINO SOCIEDAD ANONIMA CERRADA | EQ9: JOYA SOLAR S.A.C. | ER9: MAJES ARCUS S.A.C. | ES9: ORYGEN PERU S.A.A. | ET9: ORYGEN PERU S.A.A. | EU9: ORYGEN PERU S.A.A. | EV9: ORYGEN PERU S.A.A. | EW9: ORYGEN PERU S.A.A. | EX9: REPARTICIÓN ARCUS S.A.C. | EY9: SINERSA | EZ9: SINERSA | FA9: BIOENERGIA DEL CHIRA S.A. | FB9: GM OPERACIONES S.A.C. | FC9: GM OPERACIONES S.A.C. | FD9: SDF ENERGIA SAC | FE9: SDF ENERGIA SAC | FF9: AGRO INDUSTRIAL PARAMONGA S.A. | FG9: AGROAURORA S.A.C. | FH9: AGROINDUSTRIAS SAN JACINTO S.A.A. | FK9: UNACEM PERU S.A. | FL9: ELECTRO ORIENTE | FM9: AGUAS Y ENERGIA PERU | FN9: ELECTRO ZAÑA S.A.C. | FO9: ELECTRONOROESTE S.A. | FP9: SDE PIURA | FQ9: SINERSA | FR9: SINERSA
