Workbook

Sheet EVENTOS
B3: jueves, 28 de Agosto del 2025
B5: INFORMACIÓN DE EVENTOS PRINCIPALES EN SUS INSTALACIONES
B6: TIPO DE EVENTO | C6: EMPRESA | D6: UBICACIÓN | E6: TIPO DE EQUIPO | F6: EQUIPO | G6: INICIO | H6: FINAL | I6: DESCRIPCIÓN | J6: MW INDISP. | K6: INTERRUPCIÓN (SI/NO) | L6: TENSIÓN DE FALLA (kV)
B7: EVENTO | C7: CONELSUR LT SAC | D7: PORTILLO | E7: SUBESTACION | F7: SS.EE. | G7: 28/08/2025 00:00:00 | H7: 29/08/2025 00:00:00 | I7: DECLARACIÓN DE SITUACIÓN EXCEPCIONAL EN LA S.E. PORTILLO DE 60 kV | K7: NO
B8: FALLA | C8: EGESUR | D8: INDEPENDENCIA | E8: GENERADOR TERMOELÉCTRICO | F8: INDEP_G2 | G8: 28/08/2025 14:39:00 | H8: 28/08/2025 14:45:00 | I8: DESCONECTO EL GENERADOR G2 DE LA C.T. INDEPENDENCIA, POR FALLA. | K8: NO | L8: 0
B9: FALLA | C9: SAN GABAN | D9: PCH TUPURI | E9: CENTRAL HIDROELÉCTRICA | F9: CENTRAL | G9: 28/08/2025 13:12:00 | H9: 28/08/2025 14:50:00 | I9: DESCONEXIÓN DE LA P.C.H. TUPURI | K9: NO | L9: 2.4
B10: EVENTO | C10: STATKRAFT S.A | D10: OROYA NUEVA - ALAMBRÓN | E10: LINEA DE TRANSMISION | F10: L-6513 | G10: 28/08/2025 07:46:00 | H10: 28/08/2025 08:47:00 | I10: DESCONECTÓ LA LÍNEA L-6513 (OROYA NUEVA – ALAMBRÓN) DE 50 KV POR FALLA QUE SE INVESTIGA | J10: 0.98 | K10: SI

Sheet RESTRIC_OPE
B3: jueves, 28 de Agosto del 2025
B5: RESTRICCIONES OPERATIVAS
B6: FECHA | C6: HORA INICIO | D6: HORA FINAL | E6: EMPRESA | F6: UBICACIÓN | G6: T.Eq. | H6: EQUIPO | I6: DESCRIPCIÓN
B7: 28/08/2025 | C7: 00:00 | D7: 24:00 | E7: EGASA | F7: S.E. CONVERTIDOR | G7: BARRA | H7: BARRA138KV | I7: EGASA limitó la capacidad del transformador 138 kV/33 kV a 50 MVA por deterioro del aislamiento.
B8: 28/08/2025 | C8: 00:00 | D8: 24:00 | E8: ELECTROPERU | F8: C.H. MANTARO | G8: CH | H8: CENTRAL | I8: De acuerdo con el correo del día 25.08.2025, la central tiene una limitación de potencia máxima de 650 MW por seguridad de la central.
B9: 28/08/2025 | C9: 00:00 | D9: 24:00 | E9: ENEL GENERACION PIURA S.A. | F9: C.T. MALACAS | G9: CT | H9: CENTRAL | I9: De acuerdo con la comunicación vía correo del día 24.10.2024. ENEL GENERACIÓN PIURA informa una restricción de potencia para alcanzar 105 MW en simultaneo (TG6+TGN4).
B10: 28/08/2025 | C10: 00:00 | D10: 24:00 | E10: ENEL GENERACION PIURA S.A. | F10: C.T. MALACAS | G10: GT | H10: TG4 | I10: De acuerdo a lo informado mediante correo electronico el día 04.07, la uniadTG4 puede operar a potencia efectiva durante 3 horas o con 80MW durante 4 horas, y el resto de los periodos a mínima generación.
B11: 28/08/2025 | C11: 00:00 | D11: 24:00 | E11: ENGIE | F11: C.H. YUNCÁN | G11: GH | H11: G3 | I11: Según la carta N° ENG/ 198-2024 enviada por su representada, se opera de forma continua el G3 de la CH Yuncán, debido a la ejecución de mantenimientos necesarios para evitar daños en los sellos de seguridad de la válvula esférica del grupo.
B12: 28/08/2025 | C12: 00:00 | D12: 24:00 | E12: ENGIE | F12: C.T. CHILCA 1 | G12: CT | H12: CENTRAL | I12: Restricción de temperatura de la C.T Chilca, ver valor en el modelo de despacho.
B13: 28/08/2025 | C13: 00:00 | D13: 24:00 | E13: ENGIE | F13: C.T. CHILCA 1 | G13: CT | H13: CENTRAL | I13: Con carta ENG/971-2023, indica que no puede cumplir con las IO considerada en el PDO_17122023 dado que vulneran la seguridad de sus activos. Indican que se debe tomar TMO=168h.
B14: 28/08/2025 | C14: 00:00 | D14: 24:00 | E14: ENGIE | F14: C.T. CHILCA 2 | G14: CT | H14: CENTRAL | I14: Con carta ENG/971-2023, indica que no puede cumplir con las IO considerada en el PDO_17122023 dado que vulneran la seguridad de sus activos. Indican que se debe tomar TMO=168h.
B15: 28/08/2025 | C15: 00:00 | D15: 24:00 | E15: FENIX POWER PERÚ | F15: C.T. FENIX | G15: CT | H15: CENTRAL | I15: De acuerdo con lo comunicado en el correo del día 06.05.2024, la CT Fenix cuenta con TMO de 168 hrs en todos su modos de operación.
B16: 28/08/2025 | C16: 00:00 | D16: 24:00 | E16: KALLPA GENERACION S.A. | F16: C.H. CERRO DEL AGUILA | G16: CH | H16: CENTRAL | I16: De acuerdo con el correo del 22.08.2025 la central se encuentra indisponible para dar RSF hasta el 29.08.2025.
B17: 28/08/2025 | C17: 00:00 | D17: 24:00 | E17: KALLPA GENERACION S.A. | F17: C.H. MINI CENTRAL CERRO DEL AGUILA | G17: CH | H17: CENTRAL | I17: De acuerdo con lo informado por Kallpa el día 20.08.2025, la MCH Cerro del Águila tiene TA=0.07h, TMO=0.08h, TMA=0.16h.
... B45: 28/08/2025 | C45: 00:00 | D45: 24:00 | E45: TERMOSELVA | F45: C.T. AGUAYTÍA | G45: CT | H45: CENTRAL | I45: Disponibilidad de 23.5 MMSCF para la CT Aguaytía.

Sheet MANTENIMIENTO EJECUTADOS
B3: jueves, 28 de Agosto del 2025
B5: Mantenimiento Ejecutado
B6: Empresa | C6: Ubicación | D6: Equipo | E6: Inicio | F6: Final | G6: Descripción | H6: MW Indisp. | I6: Prog. | J6: Dispon | K6: Interrupc. | L6: Tipo | M6: CodEq | N6: TipoEq_Osinerg
B7: ATLANTICA TRANSMISION SUR S.A. | C7: MONTALVO | D7: AUT-5672 | E7: 28/08/2025 00:00 | F7: 29/08/2025 00:00 | G7: Energizado por pruebas de puesta de servicio previo a su integracion. | H7: 0 | I7: P | J7: E/S | K7: N | L7: PRUEBA | M7: 24276 | N7: T
B8: ATLANTICA TRANSMISION SUR S.A. | C8: MONTALVO | D8: BARRA A_220KV | E8: 28/08/2025 00:00 | F8: 29/08/2025 00:00 | G8: Proyecto Refuerzos: Indisponibilidad de la proteccion diferencial de barras 220 kV por Conexion de la nueva UB-87B hacia la UC existente,Configuracion y Pruebas. | H8: 0 | I8: P | J8: E/S | K8: N | L8: P.ENERG | M8: 13869 | N8: T
B9: ATLANTICA TRANSMISION SUR S.A. | C9: MONTALVO | D9: BARRA A_500KV | E9: 28/08/2025 00:00 | F9: 29/08/2025 00:00 | G9: Proyecto Refuerzos: Indisponibilidad de la proteccion diferencial de barras 500kV por conexion de nueva UB-87B hacia la UC existente, Configuracion y Pruebas. | H9: 0 | I9: P | J9: E/S | K9: N | L9: P.ENERG | M9: 13870 | N9: T
B10: ATLANTICA TRANSMISION SUR S.A. | C10: MONTALVO | D10: BARRA B_220kV | E10: 28/08/2025 00:00 | F10: 29/08/2025 00:00 | G10: Proyecto Refuerzos: Indisponibilidad de la proteccion diferencial de barras 220 kV por Conexion de la nueva UB-87B hacia la UC existente,Configuracion y Pruebas. | H10: 0 | I10: P | J10: E/S | K10: N | L10: P.ENERG | M10: 14765 | N10: T
B11: ATLANTICA TRANSMISION SUR S.A. | C11: MONTALVO | D11: BARRA B_500KV | E11: 28/08/2025 00:00 | F11: 29/08/2025 00:00 | G11: Proyecto Refuerzos: Indisponibilidad de la proteccion diferencial de barras 500kV por conexion de nueva UB-87B hacia la UC existente, Configuracion y Pruebas. | H11: 0 | I11: P | J11: E/S | K11: N | L11: P.ENERG | M11: 13871 | N11: T
B12: ATLANTICA TRANSMISION SUR S.A. | C12: OCONA | D12: INT-5450 | E12: 28/08/2025 00:00 | F12: 29/08/2025 00:00 | G12: Interruptor INT-5450 cerrado con restriccion operativa, REB-5450 en servicio y suministrando los SS.AA. de la S.E. Oco?a. | H12: 0 | I12: P | J12: E/S | K12: N | L12: OTROS | M12: 13761 | N12: T
B13: ATLANTICA TRANSMISION SUR S.A. | C13: OCONA | D13: INT-5462 | E13: 28/08/2025 00:00 | F13: 29/08/2025 00:00 | G13: Seccionador SBA-5462 fase T indisponible por problemas mecanicos, el seccionador permanece cerrado y bloqueado | H13: 0 | I13: P | J13: E/S | K13: N | L13: OTROS | M13: 13758 | N13: T
B14: ATLANTICA TRANSMISION SUR S.A. | C14: POROMA | D14: AUT-5372 | E14: 28/08/2025 00:00 | F14: 29/08/2025 00:00 | G14: Energizado por pruebas de puesta de servicio previo a su integracion. | H14: 0 | I14: P | J14: E/S | K14: N | L14: PRUEBA | M14: 24298 | N14: T
B15: ATLANTICA TRANSMISION SUR S.A. | C15: POROMA | D15: BARRA A_220KV | E15: 28/08/2025 00:00 | F15: 29/08/2025 00:00 | G15: Proyecto Refuerzos: Indisponibilidad de la proteccion diferencial de barras 220 kV por Conexion de la nueva UB-87B hacia la UC existente,Configuracion y Pruebas. | H15: 0 | I15: P | J15: E/S | K15: N | L15: P.ENERG | M15: 13860 | N15: T
B16: ATLANTICA TRANSMISION SUR S.A. | C16: POROMA | D16: BARRA A_500KV | E16: 28/08/2025 00:00 | F16: 29/08/2025 00:00 | G16: Proyecto Refuerzos: Indisponibilidad de la proteccion diferencial de barras 500kV por conexion de nueva UB-87B hacia la UC existente, Configuracion y Pruebas. | H16: 0 | I16: P | J16: E/S | K16: N | L16: P.ENERG | M16: 13862 | N16: T
B17: ATLANTICA TRANSMISION SUR S.A. | C17: POROMA | D17: BARRA B_220KV | E17: 28/08/2025 00:00 | F17: 29/08/2025 00:00 | G17: Proyecto Refuerzos: Indisponibilidad de la proteccion diferencial de barras 220 kV por Conexion de la nueva UB-87B hacia la UC existente,Configuracion y Pruebas. | H17: 0 | I17: P | J17: E/S | K17: N | L17: P.ENERG | M17: 13861 | N17: T
B18: ATLANTICA TRANSMISION SUR S.A. | C18: POROMA | D18: BARRA B_500KV | E18: 28/08/2025 00:00 | F18: 29/08/2025 00:00 | G18: Proyecto Refuerzos: Indisponibilidad de la proteccion diferencial de barras 500kV por conexion de nueva UB-87B hacia la UC existente, Configuracion y Pruebas. | H18: 0 | I18: P | J18: E/S | K18: N | L18: P.ENERG | M18: 13863 | N18: T
... B122: VARI ENERGIA S.A.C. | C122: ANASHIRONI | D122: G1 | E122: 28/08/2025 00:00 | F122: 29/08/2025 00:00 | G122: CH. Anashironi en Servicio 5 MW en modo prueba por mantenimiento correctivo: * Revision de equipo caudalimetro de Sistema de Lubricacion. * Pruebas del sistema de lubricacion con grupo en vacio y con carga de 5 MW. | H122: 0 | I122: P | J122: E/S | K122: N | L122: CORR. | M122: 24348 | N122: G

Sheet INGRESO OC
A3: jueves, 28 de Agosto del 2025
A5: INGRESO A OPERACIÓN COMERCIAL
A6: EMPRESA | B6: TIPO DE EQUIPO | C6: UBICACIÓN | D6: EQUIPO | E6: Fecha y hora de Ingreso a Operación Comercial

Sheet DESPACHO_EJECUTADO
B3: jueves, 28 de Agosto del 2025
A5: POTENCIA ACTIVA EJECUTADA DE LAS UNIDADES DE GENERACIÓN DEL SEIN (MW) | FL5: CENTRALES NO INTEGRANTES COES
A6: FECHA | B6: HORA | C6: 65333 | D6: 101 | E6: 102 | F6: 42667 | G6: 42668 | H6: 126 | I6: 127 | J6: 138 | K6: 139 | L6: 197 | M6: 203 | N6: 204 | O6: 230 | P6: 209 | Q6: 56677 | R6: 796 | S6: 2146 | T6: 142 | U6: 143 | V6: 125 | W6: 187 | X6: 163 | Y6: 298 | Z6: 299 | AA6: 219 | AB6: 151 | AC6: 152 | AD6: 153 | AE6: 154 | AF6: 756 | AG6: 156 | AH6: 155 | AI6: 182 | AJ6: 212 | AK6: 758 | AL6: 263 | AM6: 265 | AN6: 775 | AO6: 777 | AP6: 2154 | AQ6: 150 | AR6: 149 | AS6: 188 | AT6: 2131 | AU6: 755 | AV6: 252 | AW6: 249 | AX6: 250 | AY6: 117 | AZ6: 267 | BA6: 268 | BB6: 119 | BC6: 120 | BD6: 189 | BE6: 122 | BF6: 266 | BG6: 337 | BH6: 338 | BI6: 251 | BJ6: 115 | BK6: 239 | BL6: 288 | BM6: 240 | BN6: 241 | BO6: 242 | BP6: 191 | BQ6: 194 | BR6: 196 | BS6: 207 | BT6: 236 | BU6: 795 | BV6: 285 | BW6: 995 | BX6: 996 | BY6: 997 | BZ6: 766 | CA6: 926 | CB6: 924 | CC6: 121 | CD6: 103 | CE6: 104 | CF6: 106 | CG6: 105 | CH6: 107 | CI6: 110 | CJ6: 109 | CK6: 144 | CL6: 113 | CM6: 114 | CN6: 193 | CO6: 208 | CP6: 786 | CQ6: 787 | CR6: 788 | CS6: 789 | CT6: 248 | CU6: 2159 | CV6: 303 | CW6: 59715 | CX6: 62255 | CY6: 1263 | CZ6: 61800 | DA6: 2194 | DB6: 69125 | DC6: 216 | DD6: 198 | DE6: 49607 | DF6: 214 | DG6: 260 | DH6: 2152 | DI6: 2128 | DJ6: 247 | DK6: 228 | DL6: 2135 | DM6: 261 | DN6: 237 | DO6: 253 | DP6: 770 | DQ6: 225 | DR6: 2201 | DS6: 2171 | DT6: 760 | DU6: 235 | DV6: 238 | DW6: 2184 | DX6: 61855 | DY6: 223 | DZ6: 226 | EA6: 201 | EB6: 258 | EC6: 259 | ED6: 920 | EE6: 257 | EF6: 256 | EG6: 2148 | EH6: 58288 | EI6: 58289 | EJ6: 58839 | EK6: 58840 | EL6: 296 | EM6: 297 | EN6: 211 | EO6: 2175 | EP6: 2178 | EQ6: 2181 | ER6: 1262 | ES6: 63425 | ET6: 233 | EU6: 2150 | EV6: 2165 | EW6: 2161 | EX6: 61197 | EY6: 58851 | EZ6: 234 | FA6: 215 | FB6: 917 | FC6: 289 | FD6: 58333 | FE6: 58336 | FF6: 213 | FG6: 232 | FH6: 2190 | FI6: 69867 | FJ6: TOTAL COES | FL6: 221 | FM6: 222 | FN6: 224 | FO6: 2187 | FP6: 227 | FQ6: 49400 | FR6: 199 | FS6: 200 | FT6: 70400 | FU6: TOTAL NO COES
C7: SUR | D7: CENTRO | E7: CENTRO | F7: NORTE | G7: NORTE | H7: NORTE | I7: NORTE | J7: CENTRO | K7: CENTRO | L7: CENTRO | M7: CENTRO | N7: CENTRO | O7: CENTRO | P7: CENTRO | Q7: CENTRO | R7: CENTRO | S7: CENTRO | T7: CENTRO | U7: CENTRO | V7: CENTRO | W7: CENTRO | X7: SUR | Y7: SUR | Z7: SUR | AA7: CENTRO | AB7: SUR | AC7: SUR | AD7: SUR | AE7: SUR | AF7: SUR | AG7: SUR | AH7: SUR | AI7: SUR | AJ7: CENTRO | AK7: NORTE | AL7: NORTE | AM7: NORTE | AN7: CENTRO | AO7: CENTRO | AP7: CENTRO | AQ7: CENTRO | AR7: CENTRO | AS7: CENTRO | AT7: CENTRO | AU7: SUR | AV7: CENTRO | AW7: CENTRO | AX7: CENTRO | AY7: CENTRO | AZ7: CENTRO | BA7: CENTRO | BB7: CENTRO | BC7: CENTRO | BD7: SUR | BE7: NORTE | BF7: CENTRO | BG7: CENTRO | BH7: CENTRO | BI7: CENTRO | BJ7: NORTE | BK7: NORTE | BL7: NORTE | BM7: SUR | BN7: SUR | BO7: SUR | BP7: CENTRO | BQ7: CENTRO | BR7: CENTRO | BS7: CENTRO | BT7: CENTRO | BU7: CENTRO | BV7: CENTRO | BW7: SUR | BX7: SUR | BY7: SUR | BZ7: NORTE | CA7: SUR | CB7: CENTRO | CC7: NORTE | CD7: CENTRO | CE7: CENTRO | CF7: CENTRO | CG7: CENTRO | CH7: CENTRO | CI7: CENTRO | CJ7: CENTRO | CK7: CENTRO | CL7: CENTRO | CM7: CENTRO | CN7: CENTRO | CO7: CENTRO | CP7: SUR | CQ7: SUR | CR7: SUR | CS7: SUR | CT7: CENTRO | CU7: CENTRO | CV7: CENTRO | CW7: CENTRO | CX7: SUR | CY7: NORTE | CZ7: NORTE | DA7: NORTE | DB7: CENTRO | DC7: NORTE | DD7: NORTE | DE7: SUR | DF7: CENTRO | DG7: CENTRO | DH7: CENTRO | DI7: NORTE | DJ7: NORTE | DK7: CENTRO | DL7: CENTRO | DM7: SUR | DN7: SUR | DO7: CENTRO | DP7: CENTRO | DQ7: CENTRO | DR7: CENTRO | DS7: CENTRO | DT7: CENTRO | DU7: SUR | DV7: CENTRO | DW7: CENTRO | DX7: NORTE | DY7: CENTRO | DZ7: CENTRO | EA7: NORTE | EB7: CENTRO | EC7: CENTRO | ED7: CENTRO | EE7: NORTE | EF7: NORTE | EG7: SUR | EH7: CENTRO | EI7: CENTRO | EJ7: CENTRO | EK7: CENTRO | EL7: CENTRO | EM7: CENTRO | EN7: SUR | EO7: SUR | EP7: SUR | EQ7: SUR | ER7: NORTE | ES7: SUR | ET7: SUR | EU7: SUR | EV7: CENTRO | EW7: CENTRO | EX7: CENTRO | EY7: SUR | EZ7: SUR | FA7: NORTE | FB7: CENTRO | FC7: NORTE | FD7: NORTE | FE7: NORTE | FF7: CENTRO | FG7: NORTE | FH7: NORTE | FI7: NORTE | FL7: NORTE | FM7: CENTRO | FN7: NORTE | FO7: NORTE | FP7: NORTE | FQ7: NORTE | FR7: NORTE | FS7: NORTE | FT7: SUR
C8: HIDROELÉCTRICA | D8: HIDROELÉCTRICA | E8: HIDROELÉCTRICA | F8: TERMOELÉCTRICA | G8: TERMOELÉCTRICA | H8: HIDROELÉCTRICA | I8: HIDROELÉCTRICA | J8: TERMOELÉCTRICA | K8: TERMOELÉCTRICA | L8: TERMOELÉCTRICA | M8: TERMOELÉCTRICA | N8: TERMOELÉCTRICA | O8: TERMOELÉCTRICA | P8: TERMOELÉCTRICA | Q8: TERMOELÉCTRICA | R8: HIDROELÉCTRICA | S8: HIDROELÉCTRICA | T8: TERMOELÉCTRICA | U8: TERMOELÉCTRICA | V8: TERMOELÉCTRICA | W8: TERMOELÉCTRICA | X8: HIDROELÉCTRICA | Y8: HIDROELÉCTRICA | Z8: HIDROELÉCTRICA | AA8: TERMOELÉCTRICA | AB8: HIDROELÉCTRICA | AC8: HIDROELÉCTRICA | AD8: HIDROELÉCTRICA | AE8: HIDROELÉCTRICA | AF8: TERMOELÉCTRICA | AG8: TERMOELÉCTRICA | AH8: TERMOELÉCTRICA | AI8: HIDROELÉCTRICA | AJ8: HIDROELÉCTRICA | AK8: TERMOELÉCTRICA | AL8: TERMOELÉCTRICA | AM8: TERMOELÉCTRICA | AN8: HIDROELÉCTRICA | AO8: HIDROELÉCTRICA | AP8: HIDROELÉCTRICA | AQ8: HIDROELÉCTRICA | AR8: HIDROELÉCTRICA | AS8: HIDROELÉCTRICA | AT8: HIDROELÉCTRICA | AU8: HIDROELÉCTRICA | AV8: TERMOELÉCTRICA | AW8: TERMOELÉCTRICA | AX8: TERMOELÉCTRICA | AY8: HIDROELÉCTRICA | AZ8: HIDROELÉCTRICA | BA8: HIDROELÉCTRICA | BB8: HIDROELÉCTRICA | BC8: HIDROELÉCTRICA | BD8: HIDROELÉCTRICA | BE8: HIDROELÉCTRICA | BF8: HIDROELÉCTRICA | BG8: HIDROELÉCTRICA | BH8: HIDROELÉCTRICA | BI8: HIDROELÉCTRICA | BJ8: TERMOELÉCTRICA | BK8: TERMOELÉCTRICA | BL8: TERMOELÉCTRICA | BM8: TERMOELÉCTRICA | BN8: TERMOELÉCTRICA | BO8: TERMOELÉCTRICA | BP8: HIDROELÉCTRICA | BQ8: TERMOELÉCTRICA | BR8: TERMOELÉCTRICA | BS8: TERMOELÉCTRICA | BT8: TERMOELÉCTRICA | BU8: TERMOELÉCTRICA | BV8: TERMOELÉCTRICA | BW8: TERMOELÉCTRICA | BX8: TERMOELÉCTRICA | BY8: TERMOELÉCTRICA | BZ8: HIDROELÉCTRICA | CA8: TERMOELÉCTRICA | CB8: TERMOELÉCTRICA | CC8: HIDROELÉCTRICA | CD8: HIDROELÉCTRICA | CE8: HIDROELÉCTRICA | CF8: HIDROELÉCTRICA | CG8: HIDROELÉCTRICA | CH8: HIDROELÉCTRICA | CI8: TERMOELÉCTRICA | CJ8: TERMOELÉCTRICA | CK8: TERMOELÉCTRICA | CL8: TERMOELÉCTRICA | CM8: TERMOELÉCTRICA | CN8: TERMOELÉCTRICA | CO8: TERMOELÉCTRICA | CP8: TERMOELÉCTRICA | CQ8: TERMOELÉCTRICA | CR8: TERMOELÉCTRICA | CS8: TERMOELÉCTRICA | CT8: TERMOELÉCTRICA | CU8: TERMOELÉCTRICA | CV8: SOLAR | CW8: EÓLICA | CX8: SOLAR | CY8: EÓLICA | CZ8: SOLAR | DA8: HIDROELÉCTRICA | DB8: HIDROELÉCTRICA | DC8: HIDROELÉCTRICA | DD8: HIDROELÉCTRICA | DE8: HIDROELÉCTRICA | DF8: HIDROELÉCTRICA | DG8: HIDROELÉCTRICA | DH8: HIDROELÉCTRICA | DI8: HIDROELÉCTRICA | DJ8: HIDROELÉCTRICA | DK8: HIDROELÉCTRICA | DL8: HIDROELÉCTRICA | DM8: SOLAR | DN8: SOLAR | DO8: EÓLICA | DP8: EÓLICA | DQ8: TERMOELÉCTRICA | DR8: TERMOELÉCTRICA | DS8: TERMOELÉCTRICA | DT8: TERMOELÉCTRICA | DU8: SOLAR | DV8: HIDROELÉCTRICA | DW8: HIDROELÉCTRICA | DX8: HIDROELÉCTRICA | DY8: HIDROELÉCTRICA | DZ8: HIDROELÉCTRICA | EA8: HIDROELÉCTRICA | EB8: HIDROELÉCTRICA | EC8: HIDROELÉCTRICA | ED8: HIDROELÉCTRICA | EE8: EÓLICA | EF8: EÓLICA | EG8: SOLAR | EH8: EÓLICA | EI8: EÓLICA | EJ8: EÓLICA | EK8: EÓLICA | EL8: HIDROELÉCTRICA | EM8: HIDROELÉCTRICA | EN8: HIDROELÉCTRICA | EO8: HIDROELÉCTRICA | EP8: HIDROELÉCTRICA | EQ8: HIDROELÉCTRICA | ER8: EÓLICA | ES8: SOLAR | ET8: SOLAR | EU8: SOLAR | EV8: HIDROELÉCTRICA | EW8: EÓLICA | EX8: EÓLICA | EY8: SOLAR | EZ8: SOLAR | FA8: HIDROELÉCTRICA | FB8: HIDROELÉCTRICA | FC8: TERMOELÉCTRICA | FD8: TERMOELÉCTRICA | FE8: TERMOELÉCTRICA | FF8: TERMOELÉCTRICA | FG8: TERMOELÉCTRICA | FH8: TERMOELÉCTRICA | FI8: TERMOELÉCTRICA | FL8: HIDROELÉCTRICA | FM8: HIDROELÉCTRICA | FN8: HIDROELÉCTRICA | FO8: HIDROELÉCTRICA | FP8: TERMOELÉCTRICA | FQ8: TERMOELÉCTRICA | FR8: HIDROELÉCTRICA | FS8: HIDROELÉCTRICA | FT8: SOLAR
C9: HYDRO GLOBAL PERÚ S.A.C. | D9: ELECTROPERU | E9: ELECTROPERU | F9: ELECTROPERU | G9: ELECTROPERU | H9: ORAZUL ENERGY PERÚ | I9: ORAZUL ENERGY PERÚ | J9: TERMOSELVA | K9: TERMOSELVA | L9: KALLPA GENERACION S.A. | M9: KALLPA GENERACION S.A. | N9: KALLPA GENERACION S.A. | O9: KALLPA GENERACION S.A. | P9: KALLPA GENERACION S.A. | Q9: KALLPA GENERACION S.A. | R9: KALLPA GENERACION S.A. | S9: KALLPA GENERACION S.A. | T9: SHOUGESA | U9: SHOUGESA | V9: SHOUGESA | W9: SHOUGESA | X9: EGEMSA | Y9: EGESUR | Z9: EGESUR | AA9: EGESUR | AB9: EGASA | AC9: EGASA | AD9: EGASA | AE9: EGASA | AF9: EGASA | AG9: EGASA | AH9: EGASA | AI9: SAN GABAN | AJ9: CELEPSA | AK9: MINERA CERRO VERDE | AL9: PLANTA DE RESERVA FRIA DE GENERACION DE ETEN S.A. | AM9: PLANTA DE RESERVA FRIA DE GENERACION DE ETEN S.A. | AN9: EMPRESA DE GENERACION HUALLAGA | AO9: EMPRESA DE GENERACION HUALLAGA | AP9: LA VIRGEN | AQ9: CHINANGO S.A.C. | AR9: CHINANGO S.A.C. | AS9: HIDROELECTRICA HUANCHOR S.A.C. | AT9: CELEPSA RENOVABLES S.R.L. | AU9: INLAND ENERGY SAC | AV9: FENIX POWER PERÚ | AW9: FENIX POWER PERÚ | AX9: FENIX POWER PERÚ | AY9: STATKRAFT S.A | AZ9: STATKRAFT S.A | BA9: STATKRAFT S.A | BB9: STATKRAFT S.A | BC9: STATKRAFT S.A | BD9: STATKRAFT S.A | BE9: STATKRAFT S.A | BF9: STATKRAFT S.A | BG9: CENTRALES SANTA ROSA S.A.C. | BH9: CENTRALES SANTA ROSA S.A.C. | BI9: EMPRESA DE GENERACION HUANZA | BJ9: ENEL GENERACION PIURA S.A. | BK9: ENEL GENERACION PIURA S.A. | BL9: ENEL GENERACION PIURA S.A. | BM9: ENGIE | BN9: ENGIE | BO9: ENGIE | BP9: ENGIE | BQ9: ENGIE | BR9: ENGIE | BS9: ENGIE | BT9: ENGIE | BU9: ENGIE | BV9: ENGIE | BW9: ENGIE | BX9: ENGIE | BY9: ENGIE | BZ9: ENGIE | CA9: INFRAESTRUCTURAS Y ENERGIAS DEL PERU S.A.C. | CB9: INFRAESTRUCTURAS Y ENERGIAS DEL PERU S.A.C. | CC9: INVERSIONES SHAQSHA S.A.C. | CD9: ORYGEN PERU S.A.A. | CE9: ORYGEN PERU S.A.A. | CF9: ORYGEN PERU S.A.A. | CG9: ORYGEN PERU S.A.A. | CH9: ORYGEN PERU S.A.A. | CI9: ORYGEN PERU S.A.A. | CJ9: ORYGEN PERU S.A.A. | CK9: ORYGEN PERU S.A.A. | CL9: ORYGEN PERU S.A.A. | CM9: ORYGEN PERU S.A.A. | CN9: ORYGEN PERU S.A.A. | CO9: ORYGEN PERU S.A.A. | CP9: SAMAY I S.A.C | CQ9: SAMAY I S.A.C | CR9: SAMAY I S.A.C | CS9: SAMAY I S.A.C | CT9: TERMOCHILCA S.A.C. | CU9: TERMOCHILCA S.A.C. | CV9: COLCA SOLAR S.A.C. | CW9: ENERGIA RENOVABLE DEL SUR S.A. | CX9: GR CORTARRAMA SOCIEDAD ANONIMA CERRADA | CY9: GR TARUCA SOCIEDAD ANONIMA CERRADA | CZ9: KONDU SAC | DA9: PERUANA DE INVERSIONES EN ENERGIAS RENOVABLES S.A. | DB9: VARI ENERGIA S.A.C. | DC9: ORAZUL ENERGY PERÚ | DD9: ORAZUL ENERGY PERÚ | DE9: SAN GABAN | DF9: MAJA ENERGIA S.A.C. | DG9: EMPRESA DE GENERACION ELECTRICA CANCHAYLLO SAC | DH9: EMPRESA DE GENERACION ELECTRICA SANTA ANA S.A.C. | DI9: EMPRESA ELECTRICA AGUA AZUL | DJ9: EMPRESA ELECTRICA RIO DOBLE | DK9: HIDROCAÑETE S.A. | DL9: HUAURA POWER GROUP S.A. | DM9: MOQUEGUA FV S.A.C. | DN9: PANAMERICANA SOLAR SAC. | DO9: PARQUE EOLICO MARCONA S.A.C. | DP9: PARQUE EOLICO TRES HERMANAS S.A.C. | DQ9: PETRAMAS | DR9: PETRAMAS | DS9: PETRAMAS | DT9: PETRAMAS | DU9: TACNA SOLAR SAC. | DV9: ELECTRICA YANAPAMPA SAC | DW9: ANDEAN POWER S.A.C. | DX9: ASOCIACIÓN SANTA LUCIA DE CHACAS | DY9: ATRIA ENERGIA S.A.C. | DZ9: EGEJUNIN | EA9: EGEJUNIN | EB9: EGEJUNIN | EC9: EGEJUNIN | ED9: EMPRESA DE GENERACION ELECTRICA RIO BAÑOS S.A.C. | EE9: ENERGÍA EÓLICA S.A. | EF9: ENERGÍA EÓLICA S.A. | EG9: ENGIE | EH9: ENGIE | EI9: ENGIE | EJ9: ENGIE | EK9: ENGIE | EL9: GENERACIÓN ANDINA S.A.C. | EM9: GENERACIÓN ANDINA S.A.C. | EN9: GENERADORA DE ENERGÍA DEL PERÚ | EO9: GENERADORA DE ENERGÍA DEL PERÚ | EP9: GENERADORA DE ENERGÍA DEL PERÚ | EQ9: GENERADORA DE ENERGÍA DEL PERÚ | ER9: GR PAINO SOCIEDAD ANONIMA CERRADA | ES9: JOYA SOLAR S.A.C. | ET9: MAJES ARCUS S.A.C. | EU9: ORYGEN PERU S.A.A. | EV9: ORYGEN PERU S.A.A. | EW9: ORYGEN PERU S.A.A. | EX9: ORYGEN PERU S.A.A. | EY9: ORYGEN PERU S.A.A. | EZ9: REPARTICIÓN ARCUS S.A.C. | FA9: SINERSA | FB9: SINERSA | FC9: BIOENERGIA DEL CHIRA S.A. | FD9: GM OPERACIONES S.A.C. | FE9: GM OPERACIONES S.A.C. | FF9: AGRO INDUSTRIAL PARAMONGA S.A. | FG9: AGROAURORA S.A.C. | FH9: AGROINDUSTRIAS SAN JACINTO S.A.A. | FI9: AGROLMOS SOCIEDAD ANONIMA - AGROLMOS S.A. | FL9: UNACEM PERU S.A. | FM9: ELECTRO ORIENTE | FN9: AGUAS Y ENERGIA PERU | FO9: ELECTRO ZAÑA S.A.C. | FP9: ELECTRONOROESTE S.A. | FQ9: SDE PIURA | FR9: SINERSA | FS9: SINERSA | FT9: KALLPA GENERACION S.A.
C10: SAN GABAN III | D10: MANTARO | E10: RESTITUCION | F10: TUMBES MAK 1 | G10: TUMBES MAK 2 | H10: CARHUAQUERO | I10: CAÑON DEL PATO | J10: AGUAYTIA TG1 | K10: AGUAYTIA TG2 | L10: KALLPA TG1 | M10: KALLPA TG2 | N10: KALLPA TG3 | O10: KALLPA TV | P10: LFLORES TG1 | Q10: LFLORES TV | R10: CERRO DEL AGUILA | S10: CERRODELAGUILAG4 | T10: SHOUGESA TV1 | U10: SHOUGESA TV2 | V10: SHOUGESA TV3 | W10: SHOUGESA CUMMINS | X10: MACHUPICCHU | Y10: ARICOTA 1 | Z10: ARICOTA 2 | AA10: INDEPENDENCIA | AB10: CHARCANI I,II,III | AC10: CHARCANI IV | AD10: CHARCANI V | AE10: CHARCANI VI | AF10: CHILINA TG | AG10: MOLLENDO 1, 2, 3 | AH10: CHILINA (SULZ 1,2) | AI10: SAN GABAN II | AJ10: PLATANAL | AK10: RECKA | AL10: RF ETEN TG1 | AM10: RF ETEN TG2 | AN10: CHAGLLA GP1 | AO10: CHAGLLA | AP10: LA VIRGEN | AQ10: CHIMAY | AR10: YANANGO | AS10: HUANCHOR | AT10: MARAÑON | AU10: STA TERESA | AV10: FENIX GT11 | AW10: FENIX GT12 | AX10: FENIX TV10 | AY10: YAUPI | AZ10: OROYA | BA10: PACHACHACA | BB10: MALPASO | BC10: CAHUA | BD10: ARCATA | BE10: GALLITO CIEGO | BF10: CHEVES | BG10: SANTA ROSA 1 | BH10: SANTA ROSA 2 | BI10: HUANZA | BJ10: MALACAS2 TG4 | BK10: MALACAS3 TG 5 | BL10: MALACAS1 TG6 | BM10: RF ILO2 TG1 | BN10: RF ILO2 TG2 | BO10: RF ILO2 TG3 | BP10: YUNCAN | BQ10: CHILCA1 TG1 | BR10: CHILCA1 TG2 | BS10: CHILCA1 TG3 | BT10: CHILCA-TV | BU10: CHILCA2 TG41 | BV10: CHILCA2-TV | BW10: CTNEPI_TG41 | BX10: CTNEPI_TG42 | BY10: CTNEPI_TG43 | BZ10: QUITARACSA | CA10: RF PTO MALDONADO | CB10: RF PUCALLPA | CC10: PARIAC | CD10: HUINCO | CE10: MATUCANA | CF10: MOYOPAMPA | CG10: CALLAHUANCA | CH10: HUAMPANI | CI10: STA ROSA WEST TG7 | CJ10: UTI_5 | CK10: UTI_6 | CL10: VENTANILLA 3 | CM10: VENTANILLA 4 | CN10: VENTANILLA TV | CO10: STAROSA TG8 | CP10: PTO_BRVO TG1 | CQ10: PTO_BRVO TG2 | CR10: PTO_BRVO TG3 | CS10: PTO_BRVO TG4 | CT10: OLLEROS TG1 | CU10: OLLEROS TV | CV10: CS YARUCAYA | CW10: SAN JUAN | CX10: MATARANI | CY10: DUNA | CZ10: CARHUAQUERO (CS) | DA10: MANTA I | DB10: ANASHIRONI | DC10: CARHUAQUERO4 | DD10: CAÑA BRAVA | DE10: TUPURI | DF10: RONCADOR | DG10: CANCHAYLLO | DH10: RENOVANDESH1 | DI10: POTRERO | DJ10: PIZARRAS | DK10: NIMPERIAL | DL10: YARUCAYA | DM10: MOQUEGUA-SOLAR | DN10: PANAMERICANA-SOLAR | DO10: PQE-EOLICO-MARCONA | DP10: PQE-EOLICO-3-HERMANAS | DQ10: HUAYCOLORO | DR10: CALLAO | DS10: DONA_CATALINA | DT10: LAGRINGAV | DU10: TACNA-SOLAR | DV10: YANAPAMPA | DW10: CARHUAC | DX10: HUALLIN | DY10: PURMACANA | DZ10: HUASAHUASI | EA10: STACRUZ_1_2 | EB10: RUNATULLO_II | EC10: RUNATULLO_III | ED10: RUCUY | EE10: PQE-EOLICO-TALARA | EF10: PQE-EOLICO-CUPISNIQUE | EG10: INTIPAMPA | EH10: PUNTA LOMITAS-BL1 | EI10: PUNTA LOMITAS-BL2 | EJ10: PUN LOMITAS_EXP-BL1 | EK10: PUN LOMITAS_EXP-BL2 | EL10: 8AGOSTO | EM10: EL CARMEN | EN10: LA JOYA | EO10: ANGEL_I | EP10: ANGEL_II | EQ10: ANGEL_III | ER10: HUAMBOS | ES10: SAN MARTIN SOLAR | ET10: MAJES | EU10: RUBI | EV10: CH_HER1 | EW10: WAYRA-I | EX10: WAYRA EXTENSION | EY10: CLEMESI | EZ10: REPARTICION | FA10: POECHOS2 | FB10: CHANCAY | FC10: CANA BRAVA | FD10: REFINERIA TALARA TV1 | FE10: REFINERÍA TALARA TV2 | FF10: PARAMONGA | FG10: MAPLE | FH10: SAN_JACINTO | FI10: AGROLMOS | FJ10: MW | FL10: CARPAPATA | FM10: CENTRALES ELOR | FN10: PIAS1 | FO10: ZANA | FP10: TABLAZO | FQ10: TALLANCA | FR10: CURUMUY | FS10: POECHOS1 | FT10: SUNNY | FU10: MW
A11: 28/08/2025 | B11: 00:30 | C11: 99.9 | D11: 639.8 | E11: 214.7 | H11: 8.1 | I11: 78.1 | L11: 189.3 | M11: 204.6 | N11: 204.1 | O11: 284.5 | P11: 217.8 | Q11: 111.1 | R11: 198.9 | S11: 3.2 | T11: 0 | X11: 120.5 | Y11: 7.4 | Z11: 3.3 | AA11: 0 | AB11: 6.34 | AC11: 9.66 | AD11: 40.31 | AI11: 60.7 | AJ11: 99.84518 | AN11: 6.5 | AO11: 154 | AP11: 29.5 | AQ11: 55.8 | AR11: 17.2 | AS11: 18.4 | AT11: 10.9 | AU11: 63.3 | AV11: 183 | AW11: 182.9 | AX11: 184.7 | AY11: 66.8 | BA11: 0 | BB11: 15.6 | BC11: 32.9 | BD11: 2 | BE11: 0 | BF11: 85.1 | BI11: 0 | BL11: 47.5 | BP11: 34.1 | BQ11: 179.1 | BR11: 176.7 | BS11: 211.5 | BT11: 274.8 | BU11: 12 | BV11: 0 | CC11: 0.4 | CD11: 143.7 | CE11: 92.2 | CF11: 63 | CG11: 70 | CH11: 29.3 | CL11: 147.5 | CM11: 149.8 | CN11: 150 | CO11: 0 | CT11: 218.3 | CU11: 104.7 | CV11: 0 | CW11: 26.9 | CX11: 0 | CY11: 18.1 | CZ11: 0 | DA11: 4.9 | DB11: 5.1 | DC11: 6.5 | DD11: 2.5 | DE11: 0.3 | DF11: 1.8 | DG11: 4.4 | DH11: 15.9 | DI11: 3.9 | DJ11: 3.1 | DK11: 3.3 | DL11: 18.5 | DM11: 0 | DN11: 0 | DO11: 5 | DP11: 23.7 | DQ11: 3.6 | DR11: 1.1 | DS11: 1.2 | DT11: 2.4 | DU11: 0 | DV11: 2.3 | DW11: 8.8 | DX11: 1.3 | DZ11: 5.5 | EA11: 3 | EB11: 5.1 | EC11: 6.8 | ED11: 10 | EE11: 22.5 | EF11: 9.2 | EG11: 0 | EH11: 34.5 | EI11: 49.1 | EJ11: 3.4 | EK11: 3 | EL11: 8.2 | EM11: 1.8 | EO11: 4 | EP11: 4.5 | EQ11: 5.2 | ER11: 16.7 | ES11: 0 | ET11: 0 | EU11: 0 | EV11: 0.6 | EW11: 22.2 | EX11: 22.1 | EY11: 0 | EZ11: 0 | FA11: 7.6 | FB11: 19.7 | FC11: 9.6 | FD11: 33.8 | FE11: 29.4 | FF11: 14.5 | FG11: 18.3 | FH11: 9.1 | FI11: 11.09 | FJ11: 6570.4452 | FL11: 18.66829 | FM11: 8.07 | FN11: 6.1 | FO11: 6.2 | FP11: 27.5 | FQ11: 18.91854 | FR11: 5 | FS11: 5 | FU11: 95.45683
A12: 28/08/2025 | B12: 01:00 | C12: 99.7 | D12: 638.5 | E12: 214.3 | H12: 0 | I12: 79.3 | L12: 190 | M12: 203.7 | N12: 203.8 | O12: 285 | P12: 216.5 | Q12: 111.4 | R12: 198.9 | S12: 3.3 | T12: 0 | X12: 126.7 | Y12: 7.4 | Z12: 3.4 | AA12: 0 | AB12: 6.38 | AC12: 9.66 | AD12: 41.08 | AI12: 60.5 | AJ12: 109.89748 | AN12: 6.5 | AO12: 154.3 | AP12: 29.2 | AQ12: 53.5 | AR12: 17.9 | AS12: 18.4 | AT12: 10.9 | AU12: 63.7 | AV12: 183.2 | AW12: 184.6 | AX12: 184.2 | AY12: 51.5 | BA12: 0 | BB12: 12.8 | BC12: 33.3 | BD12: 2 | BE12: 0 | BF12: 81.9 | BI12: 0 | BL12: 47 | BP12: 34.9 | BQ12: 179.8 | BR12: 176.9 | BS12: 212 | BT12: 274.9 | BU12: 12.3 | BV12: 0 | CC12: 0.4 | CD12: 137.3 | CE12: 91.5 | CF12: 63.2 | CG12: 69.7 | CH12: 29.2 | CL12: 146.7 | CM12: 149.1 | CN12: 149.8 | CO12: 0 | CT12: 218.4 | CU12: 104.6 | CV12: 0 | CW12: 19.5 | CX12: 0 | CY12: 18.1 | CZ12: 0 | DA12: 4.9 | DB12: 5.1 | DC12: 0 | DD12: 0 | DE12: 0.3 | DF12: 1.8 | DG12: 4.4 | DH12: 15.6 | DI12: 3.9 | DJ12: 3.1 | DK12: 3.3 | DL12: 18.5 | DM12: 0 | DN12: 0 | DO12: 4.7 | DP12: 20.9 | DQ12: 3.7 | DR12: 0.8 | DS12: 1.2 | DT12: 2.4 | DU12: 0 | DV12: 2.4 | DW12: 0.6 | DX12: 1.3 | DZ12: 5.4 | EA12: 3.2 | EB12: 4.8 | EC12: 6.8 | ED12: 10 | EE12: 26.8 | EF12: 7.3 | EG12: 0 | EH12: 28.9 | EI12: 45.5 | EJ12: 3.9 | EK12: 3.1 | EL12: 8 | EM12: 1.8 | EO12: 4 | EP12: 4.5 | EQ12: 4.7 | ER12: 17.4 | ES12: 0 | ET12: 0 | EU12: 0 | EV12: 0.6 | EW12: 21 | EX12: 22.8 | EY12: 0 | EZ12: 0 | FA12: 7.1 | FB12: 19.5 | FC12: 9 | FD12: 33.5 | FE12: 29.2 | FF12: 14.6 | FG12: 18.3 | FH12: 8.6 | FI12: 11.01 | FJ12: 6512.8275 | FL12: 19.03531 | FM12: 0.41 | FN12: 6.1 | FO12: 6.2 | FP12: 27.5 | FQ12: 18.91825 | FR12: 5 | FS12: 5.1 | FU12: 88.26356
A13: 28/08/2025 | B13: 01:30 | C13: 97.1 | D13: 630.4 | E13: 211.5 | H13: 0 | I13: 76.9 | L13: 189.2 | M13: 203.6 | N13: 203.4 | O13: 286.9 | P13: 217.3 | Q13: 110.7 | R13: 191.9 | S13: 2.9 | T13: 0 | X13: 119.6 | Y13: 6.8 | Z13: 3.1 | AA13: 0 | AB13: 6.37 | AC13: 9.65 | AD13: 38.92 | AI13: 58.7 | AJ13: 107.52872 | AN13: 6.5 | AO13: 0 | AP13: 30.4 | AQ13: 58.5 | AR13: 17.5 | AS13: 18.5 | AT13: 10.9 | AU13: 61 | AV13: 178.4 | AW13: 178.3 | AX13: 184.1 | AY13: 52.2 | BA13: 0 | BB13: 3 | BC13: 32.3 | BD13: 2 | BE13: 0 | BF13: 82.8 | BI13: 0 | BL13: 46.9 | BP13: 33.7 | BQ13: 178.8 | BR13: 177.3 | BS13: 211.8 | BT13: 274.9 | BU13: 12 | BV13: 0 | CC13: 0.4 | CD13: 139.6 | CE13: 81.9 | CF13: 61.4 | CG13: 69.3 | CH13: 28.5 | CL13: 147.5 | CM13: 149.8 | CN13: 149.6 | CO13: 0 | CT13: 218.3 | CU13: 104.7 | CV13: 0 | CW13: 22.1 | CX13: 0 | CY13: 17.8 | CZ13: 0 | DA13: 5 | DB13: 4.9 | DC13: 0 | DD13: 0 | DE13: 0.3 | DF13: 1.8 | DG13: 4.8 | DH13: 15.2 | DI13: 4.1 | DJ13: 3.1 | DK13: 3.3 | DL13: 18.5 | DM13: 0 | DN13: 0 | DO13: 6.1 | DP13: 21.8 | DQ13: 4.1 | DR13: 0.7 | DS13: 1.2 | DT13: 3 | DU13: 0 | DV13: 2.5 | DW13: 0 | DX13: 1.3 | DZ13: 5.4 | EA13: 3.2 | EB13: 5 | EC13: 7 | ED13: 10 | EE13: 26.8 | EF13: 6.4 | EG13: 0 | EH13: 23.6 | EI13: 39.1 | EJ13: 2.9 | EK13: 2.8 | EL13: 8 | EM13: 1.8 | EO13: 4.2 | EP13: 4.5 | EQ13: 4.7 | ER13: 16.2 | ES13: 0 | ET13: 0 | EU13: 0 | EV13: 0.6 | EW13: 20.6 | EX13: 17.7 | EY13: 0 | EZ13: 0 | FA13: 7.1 | FB13: 19.2 | FC13: 8.9 | FD13: 33.6 | FE13: 29.5 | FF13: 13.5 | FG13: 18.3 | FH13: 9.4 | FI13: 10.73 | FJ13: 6277.5987 | FL13: 19.19653 | FM13: 0 | FN13: 6.1 | FO13: 6.2 | FP13: 27.5 | FQ13: 18.91818 | FR13: 5.1 | FS13: 5 | FU13: 88.01471
A14: 28/08/2025 | B14: 02:00 | C14: 99.8 | D14: 639.9 | E14: 214.9 | H14: 0 | I14: 78.5 | L14: 189.9 | M14: 205.7 | N14: 203.6 | O14: 283.2 | P14: 216.9 | Q14: 111 | R14: 250.9 | S14: 3.2 | T14: 0 | X14: 120.9 | Y14: 7.6 | Z14: 3.4 | AA14: 0 | AB14: 6.37 | AC14: 9.66 | AD14: 40.4 | AI14: 60.5 | AJ14: 104.20957 | AN14: 6.5 | AO14: 0 | AP14: 28.2 | AQ14: 59.2 | AR14: 18 | AS14: 18.4 | AT14: 10.9 | AU14: 63.7 | AV14: 183.2 | AW14: 183.3 | AX14: 185.1 | AY14: 53.4 | BA14: 0 | BB14: 13.3 | BC14: 34.7 | BD14: 2 | BE14: 0 | BF14: 29.1 | BI14: 0 | BL14: 47.2 | BP14: 34.8 | BQ14: 179.1 | BR14: 176.4 | BS14: 211.3 | BT14: 274.3 | BU14: 12 | BV14: 0 | CC14: 0.4 | CD14: 138.5 | CE14: 87.8 | CF14: 63 | CG14: 66.9 | CH14: 29.3 | CL14: 147.3 | CM14: 149.7 | CN14: 149.9 | CO14: 0 | CT14: 217.8 | CU14: 104.4 | CV14: 0 | CW14: 22.4 | CX14: 0 | CY14: 17.2 | CZ14: 0 | DA14: 5 | DB14: 5.1 | DC14: 0 | DD14: 0 | DE14: 0.3 | DF14: 1.8 | DG14: 4.8 | DH14: 15.9 | DI14: 4.2 | DJ14: 3.1 | DK14: 3.3 | DL14: 18.5 | DM14: 0 | DN14: 0 | DO14: 5.9 | DP14: 20.2 | DQ14: 4.4 | DR14: 1.1 | DS14: 1.2 | DT14: 3 | DU14: 0 | DV14: 2.5 | DW14: 0 | DX14: 1.3 | DZ14: 5.4 | EA14: 3.2 | EB14: 5 | EC14: 7.2 | ED14: 10 | EE14: 27.2 | EF14: 4.7 | EG14: 0 | EH14: 22.3 | EI14: 32.9 | EJ14: 3 | EK14: 2.3 | EL14: 7.8 | EM14: 1.8 | EO14: 4.5 | EP14: 4.5 | EQ14: 4.7 | ER14: 13.9 | ES14: 0 | ET14: 0 | EU14: 0 | EV14: 0.6 | EW14: 19.9 | EX14: 17.3 | EY14: 0 | EZ14: 0 | FA14: 7.1 | FB14: 19.2 | FC14: 9.3 | FD14: 33.7 | FE14: 29.5 | FF14: 13.5 | FG14: 18.3 | FH14: 7.9 | FI14: 11.05 | FJ14: 6318.5896 | FL14: 19.41718 | FM14: 0 | FN14: 6.1 | FO14: 6.2 | FP14: 27.5 | FQ14: 18.91809 | FR14: 5.1 | FS14: 5.1 | FU14: 88.33527
A15: 28/08/2025 | B15: 02:30 | C15: 99.6 | D15: 637.3 | E15: 213.8 | H15: 0 | I15: 79 | L15: 189.4 | M15: 205 | N15: 204 | O15: 282.2 | P15: 217.1 | Q15: 111 | R15: 245.7 | S15: 3.2 | T15: 0 | X15: 119.9 | Y15: 7.2 | Z15: 3.2 | AA15: 0 | AB15: 6.36 | AC15: 9.67 | AD15: 40.02 | AI15: 60.1 | AJ15: 98.42813 | AN15: 6.5 | AO15: 0 | AP15: 31 | AQ15: 48.4 | AR15: 19.3 | AS15: 18.5 | AT15: 10.9 | AU15: 62.4 | AV15: 181.9 | AW15: 182.4 | AX15: 184.1 | AY15: 52.7 | BA15: 0 | BB15: 11.7 | BC15: 19.9 | BD15: 2 | BE15: 0 | BF15: 25.5 | BI15: 0 | BL15: 47.4 | BP15: 34.8 | BQ15: 179.2 | BR15: 176.8 | BS15: 211.4 | BT15: 274.6 | BU15: 12.2 | BV15: 0 | CC15: 0.4 | CD15: 84 | CE15: 79.7 | CF15: 63.9 | CG15: 67.6 | CH15: 29.2 | CL15: 147.6 | CM15: 150.1 | CN15: 150.3 | CO15: 0 | CT15: 218.2 | CU15: 104.8 | CV15: 0 | CW15: 21.2 | CX15: 0 | CY15: 14.6 | CZ15: 0 | DA15: 5.1 | DB15: 5.1 | DC15: 0 | DD15: 0 | DE15: 0.3 | DF15: 1.8 | DG15: 4.8 | DH15: 15.6 | DI15: 4.2 | DJ15: 3.1 | DK15: 3.3 | DL15: 18.5 | DM15: 0 | DN15: 0 | DO15: 5.1 | DP15: 20.6 | DQ15: 4.4 | DR15: 1.1 | DS15: 1.2 | DT15: 3 | DU15: 0 | DV15: 2.3 | DW15: 0 | DX15: 1.2 | DZ15: 5.4 | EA15: 3.2 | EB15: 4.8 | EC15: 7.1 | ED15: 10 | EE15: 26.8 | EF15: 2.3 | EG15: 0 | EH15: 18.9 | EI15: 31.5 | EJ15: 2.1 | EK15: 1.3 | EL15: 7.7 | EM15: 1.8 | EO15: 4.7 | EP15: 4.5 | EQ15: 4.7 | ER15: 11 | ES15: 0 | ET15: 0 | EU15: 0 | EV15: 0.6 | EW15: 14.9 | EX15: 11.4 | EY15: 0 | EZ15: 0 | FA15: 7.1 | FB15: 19.2 | FC15: 9.2 | FD15: 33.6 | FE15: 29.4 | FF15: 14 | FG15: 18.3 | FH15: 7.3 | FI15: 11.05 | FJ15: 6181.9281 | FL15: 20.00964 | FM15: 0 | FN15: 6.1 | FO15: 6.2 | FP15: 27.4 | FQ15: 18.91806 | FR15: 5.2 | FS15: 5.1 | FU15: 88.9277
A16: 28/08/2025 | B16: 03:00 | C16: 99.4 | D16: 639.2 | E16: 214.5 | H16: 0 | I16: 81.9 | L16: 189 | M16: 206.2 | N16: 206.6 | O16: 282 | P16: 217.7 | Q16: 110.9 | R16: 179 | S16: 3.2 | T16: 0 | X16: 122.2 | Y16: 7.4 | Z16: 3.3 | AA16: 0 | AB16: 6.33 | AC16: 9.66 | AD16: 40.68 | AI16: 60.8 | AJ16: 71.31502 | AN16: 6.5 | AO16: 0 | AP16: 29.4 | AQ16: 61.4 | AR16: 19.6 | AS16: 18.6 | AT16: 10.9 | AU16: 62.7 | AV16: 184.2 | AW16: 184.6 | AX16: 184.9 | AY16: 53.4 | BA16: 0 | BB16: 21.7 | BC16: 36.5 | BD16: 2 | BE16: 0 | BF16: 84.5 | BI16: 0 | BL16: 46.8 | BP16: 35 | BQ16: 178.9 | BR16: 176.7 | BS16: 211.4 | BT16: 274.5 | BU16: 13.2 | BV16: 0 | CC16: 0.4 | CD16: 163 | CE16: 96.6 | CF16: 64.1 | CG16: 69.9 | CH16: 29.3 | CL16: 147.7 | CM16: 150.2 | CN16: 150.4 | CO16: 0 | CT16: 217.9 | CU16: 104.6 | CV16: 0 | CW16: 19.2 | CX16: 0 | CY16: 12.5 | CZ16: 0 | DA16: 5 | DB16: 5.2 | DC16: 0 | DD16: 0 | DE16: 0.3 | DF16: 1.8 | DG16: 4.7 | DH16: 15.8 | DI16: 4.3 | DJ16: 3.1 | DK16: 3.3 | DL16: 18.5 | DM16: 0 | DN16: 0 | DO16: 4.4 | DP16: 14.6 | DQ16: 4.4 | DR16: 1.1 | DS16: 1.2 | DT16: 3 | DU16: 0 | DV16: 2.4 | DW16: 0 | DX16: 1.2 | DZ16: 5.5 | EA16: 3.2 | EB16: 4.8 | EC16: 7.2 | ED16: 10 | EE16: 26.1 | EF16: 2.6 | EG16: 0 | EH16: 15.5 | EI16: 26.8 | EJ16: 2.1 | EK16: 1.3 | EL16: 7.6 | EM16: 1.8 | EO16: 4.5 | EP16: 5.2 | EQ16: 5.2 | ER16: 11.6 | ES16: 0 | ET16: 0 | EU16: 0 | EV16: 0.6 | EW16: 14.1 | EX16: 9 | EY16: 0 | EZ16: 0 | FA16: 7.1 | FB16: 19.5 | FC16: 9.5 | FD16: 33.5 | FE16: 29.2 | FF16: 13.7 | FG16: 18.3 | FH16: 8.2 | FI16: 11.06 | FJ16: 6283.545 | FL16: 20.18062 | FM16: 0 | FN16: 6.1 | FO16: 6.2 | FP16: 27.4 | FQ16: 18.91821 | FR16: 5.3 | FS16: 5 | FU16: 89.09883
A17: 28/08/2025 | B17: 03:30 | C17: 99.6 | D17: 642.2 | E17: 215.7 | H17: 0 | I17: 82.4 | L17: 189.3 | M17: 206.6 | N17: 205.7 | O17: 283.4 | P17: 216.2 | Q17: 110.7 | R17: 178.8 | S17: 3.2 | T17: 0 | X17: 122 | Y17: 7.7 | Z17: 3.4 | AA17: 0 | AB17: 6.36 | AC17: 9.63 | AD17: 40.15 | AI17: 61 | AJ17: 52.57629 | AN17: 6.5 | AO17: 0 | AP17: 31.7 | AQ17: 69.5 | AR17: 21.9 | AS17: 18.6 | AT17: 10.9 | AU17: 65.4 | AV17: 183.4 | AW17: 184 | AX17: 184.5 | AY17: 53.5 | BA17: 0 | BB17: 4.7 | BC17: 24.4 | BD17: 2 | BE17: 0 | BF17: 85.2 | BI17: 0 | BL17: 47.8 | BP17: 35.3 | BQ17: 178.4 | BR17: 176 | BS17: 211.1 | BT17: 274.6 | BU17: 14.9 | BV17: 0 | CC17: 0.4 | CD17: 163.3 | CE17: 99 | CF17: 64.5 | CG17: 69.9 | CH17: 29.5 | CL17: 148 | CM17: 150.3 | CN17: 150.8 | CO17: 0 | CT17: 218.2 | CU17: 104.6 | CV17: 0 | CW17: 18.2 | CX17: 0 | CY17: 15.1 | CZ17: 0 | DA17: 5 | DB17: 5.2 | DC17: 0 | DD17: 0 | DE17: 0.3 | DF17: 1.8 | DG17: 4.7 | DH17: 16.1 | DI17: 4.4 | DJ17: 3.1 | DK17: 3.3 | DL17: 18.5 | DM17: 0 | DN17: 0 | DO17: 2.7 | DP17: 10.1 | DQ17: 4.4 | DR17: 1.1 | DS17: 1.2 | DT17: 3 | DU17: 0 | DV17: 2.4 | DW17: 0 | DX17: 1.2 | DZ17: 5.5 | EA17: 3.2 | EB17: 5.1 | EC17: 7.2 | ED17: 10 | EE17: 23 | EF17: 5.7 | EG17: 0 | EH17: 15.1 | EI17: 23.3 | EJ17: 1.6 | EK17: 1.4 | EL17: 7.6 | EM17: 1.8 | EO17: 4.5 | EP17: 5.2 | EQ17: 5.4 | ER17: 10.2 | ES17: 0 | ET17: 0 | EU17: 0 | EV17: 0.6 | EW17: 10.3 | EX17: 5 | EY17: 0 | EZ17: 0 | FA17: 7.1 | FB17: 19.5 | FC17: 8.8 | FD17: 33.4 | FE17: 29.5 | FF17: 13.5 | FG17: 18.3 | FH17: 7.5 | FI17: 11.05 | FJ17: 6241.5663 | FL17: 20.27794 | FM17: 0 | FN17: 6.1 | FO17: 6.2 | FP17: 27.5 | FQ17: 18.91822 | FR17: 5.3 | FS17: 5 | FU17: 89.29616
A18: 28/08/2025 | B18: 04:00 | C18: 99.2 | D18: 640.6 | E18: 214.8 | H18: 0 | I18: 81.8 | L18: 189.4 | M18: 205.2 | N18: 204.3 | O18: 283.2 | P18: 214.8 | Q18: 110.3 | R18: 184.2 | S18: 3.2 | T18: 0 | X18: 120.2 | Y18: 7.6 | Z18: 3.4 | AA18: 0 | AB18: 6.31 | AC18: 7.52 | AD18: 40.9 | AI18: 61.2 | AJ18: 83.22815 | AN18: 6.5 | AO18: 0 | AP18: 32.8 | AQ18: 74.7 | AR18: 20.5 | AS18: 18.6 | AT18: 10.9 | AU18: 63.4 | AV18: 183.2 | AW18: 183.5 | AX18: 184.6 | AY18: 54.1 | BA18: 0 | BB18: 5.4 | BC18: 24.5 | BD18: 2 | BE18: 0 | BF18: 84.7 | BI18: 0 | BL18: 47.1 | BP18: 35.5 | BQ18: 178 | BR18: 175.5 | BS18: 210.5 | BT18: 273.7 | BU18: 29.6 | BV18: 3.6 | CC18: 0.4 | CD18: 196.2 | CE18: 110.8 | CF18: 64.6 | CG18: 70.2 | CH18: 29.5 | CL18: 146.5 | CM18: 149.1 | CN18: 149 | CO18: 0 | CT18: 218 | CU18: 104.6 | CV18: 0 | CW18: 9.4 | CX18: 0 | CY18: 15.7 | CZ18: 0 | DA18: 4.9 | DB18: 5.2 | DC18: 0 | DD18: 0 | DE18: 0.3 | DF18: 1.8 | DG18: 4.6 | DH18: 15 | DI18: 4.4 | DJ18: 3.1 | DK18: 3.3 | DL18: 18.5 | DM18: 0 | DN18: 0 | DO18: 1.1 | DP18: 4.4 | DQ18: 4.4 | DR18: 1.2 | DS18: 1.2 | DT18: 3 | DU18: 0 | DV18: 1.6 | DW18: 0 | DX18: 1.2 | DZ18: 5.4 | EA18: 3.2 | EB18: 4.8 | EC18: 7.2 | ED18: 10 | EE18: 20.6 | EF18: 4.7 | EG18: 0 | EH18: 6.5 | EI18: 18.9 | EJ18: 0.8 | EK18: 0.8 | EL18: 7.6 | EM18: 1.8 | EO18: 4.5 | EP18: 5.2 | EQ18: 5.4 | ER18: 13.5 | ES18: 0 | ET18: 0 | EU18: 0 | EV18: 0.6 | EW18: 2.3 | EX18: 1.1 | EY18: 0 | EZ18: 0 | FA18: 7.1 | FB18: 19.7 | FC18: 7.1 | FD18: 33.3 | FE18: 29.2 | FF18: 13.5 | FG18: 18.3 | FH18: 7.2 | FI18: 11.01 | FJ18: 6278.7681 | FL18: 20.901 | FM18: 0 | FN18: 6.1 | FO18: 6.2 | FP18: 27.5 | FQ18: 18.91841 | FR18: 5.2 | FS18: 5 | FU18: 89.81941
A19: 28/08/2025 | B19: 04:30 | C19: 97.4 | D19: 635.8 | E19: 213.3 | H19: 0 | I19: 80.4 | L19: 190 | M19: 206.7 | N19: 205.7 | O19: 283.1 | P19: 216.4 | Q19: 111.5 | R19: 248.7 | S19: 3.2 | T19: 0 | X19: 115 | Y19: 7 | Z19: 3.2 | AA19: 0 | AB19: 6.29 | AC19: 7.53 | AD19: 40.02 | AI19: 59.1 | AJ19: 81.11302 | AN19: 6.5 | AO19: 0 | AP19: 32.1 | AQ19: 57.5 | AR19: 20.9 | AS19: 18.6 | AT19: 10.9 | AU19: 61.6 | AV19: 179.6 | AW19: 180.6 | AX19: 184.9 | AY19: 52.1 | BA19: 0 | BB19: 11.2 | BC19: 33.6 | BD19: 2 | BE19: 0 | BF19: 81.2 | BI19: 40.4 | BL19: 47.7 | BP19: 34.1 | BQ19: 179.8 | BR19: 176.9 | BS19: 211.6 | BT19: 274.9 | BU19: 30.3 | BV19: 5.6 | CC19: 0.4 | CD19: 103.8 | CE19: 91.8 | CF19: 63.2 | CG19: 69.5 | CH19: 28.8 | CL19: 148 | CM19: 150.3 | CN19: 150.3 | CO19: 0 | CT19: 218.1 | CU19: 104.5 | CV19: 0 | CW19: 12.6 | CX19: 0 | CY19: 15.5 | CZ19: 0 | DA19: 5 | DB19: 5 | DC19: 0 | DD19: 0 | DE19: 0.3 | DF19: 1.8 | DG19: 4.5 | DH19: 14.9 | DI19: 4.5 | DJ19: 3.1 | DK19: 3.3 | DL19: 18.5 | DM19: 0 | DN19: 0 | DO19: 0.8 | DP19: 2.7 | DQ19: 4.4 | DR19: 1.2 | DS19: 1.2 | DT19: 3 | DU19: 0 | DV19: 1.6 | DW19: 2.4 | DX19: 1.2 | DZ19: 5.5 | EA19: 3.2 | EB19: 5 | EC19: 7.1 | ED19: 10 | EE19: 15.6 | EF19: 4.1 | EG19: 0 | EH19: 5 | EI19: 16.8 | EJ19: 0.5 | EK19: 0 | EL19: 7.4 | EM19: 1.8 | EO19: 4.5 | EP19: 5 | EQ19: 5.2 | ER19: 15.2 | ES19: 0 | ET19: 0 | EU19: 0 | EV19: 0.6 | EW19: 0.3 | EX19: 0.2 | EY19: 0 | EZ19: 0 | FA19: 7.1 | FB19: 19.6 | FC19: 9.2 | FD19: 33.6 | FE19: 29.2 | FF19: 13.9 | FG19: 18.3 | FH19: 7 | FI19: 11.08 | FJ19: 6244.233 | FL19: 21.01298 | FM19: 0 | FN19: 6.1 | FO19: 6.2 | FP19: 27.4 | FQ19: 18.91924 | FR19: 5.3 | FS19: 5 | FU19: 89.93222
A20: 28/08/2025 | B20: 05:00 | C20: 99.4 | D20: 641.6 | E20: 215.4 | H20: 0 | I20: 85.9 | L20: 189.1 | M20: 205.5 | N20: 205 | O20: 283.4 | P20: 217.4 | Q20: 111.1 | R20: 251 | S20: 3.2 | T20: 8.8 | X20: 120.7 | Y20: 7.7 | Z20: 3.4 | AA20: 0 | AB20: 6.32 | AC20: 7.69 | AD20: 40.76 | AI20: 60.9 | AJ20: 61.49795 | AN20: 6.5 | AO20: 0 | AP20: 34.5 | AQ20: 71.6 | AR20: 24.1 | AS20: 18.6 | AT20: 10.9 | AU20: 63.1 | AV20: 183.7 | AW20: 183.8 | AX20: 184.9 | AY20: 52.8 | BA20: 0 | BB20: 10.1 | BC20: 32.6 | BD20: 2 | BE20: 0 | BF20: 84.9 | BI20: 41.3 | BL20: 47.1 | BP20: 35.2 | BQ20: 179.1 | BR20: 176.2 | BS20: 211.1 | BT20: 274.8 | BU20: 29.6 | BV20: 13.6 | CC20: 0.4 | CD20: 186.1 | CE20: 100.3 | CF20: 64.4 | CG20: 69.9 | CH20: 29.5 | CL20: 147.6 | CM20: 149.9 | CN20: 149.9 | CO20: 0 | CT20: 218.5 | CU20: 104.7 | CV20: 0 | CW20: 14.5 | CX20: 0 | CY20: 17.1 | CZ20: 0 | DA20: 5 | DB20: 5.1 | DC20: 0 | DD20: 0 | DE20: 0.3 | DF20: 1.8 | DG20: 4.5 | DH20: 15.6 | DI20: 4.9 | DJ20: 3.1 | DK20: 3.3 | DL20: 18.5 | DM20: 0 | DN20: 0 | DO20: 1.7 | DP20: 3.2 | DQ20: 4.4 | DR20: 1.2 | DS20: 1.2 | DT20: 3 | DU20: 0 | DV20: 2 | DW20: 10.4 | DX20: 1.2 | DZ20: 5.6 | EA20: 3.2 | EB20: 5 | EC20: 7.2 | ED20: 10 | EE20: 11.1 | EF20: 5.9 | EG20: 0 | EH20: 4.3 | EI20: 12.3 | EJ20: 0.6 | EK20: 0.1 | EL20: 7.4 | EM20: 1.8 | EO20: 4.5 | EP20: 5 | EQ20: 5.2 | ER20: 15.6 | ES20: 0 | ET20: 0.0777 | EU20: 0 | EV20: 0.6 | EW20: 0 | EX20: 0 | EY20: 0 | EZ20: 0 | FA20: 7.1 | FB20: 19.5 | FC20: 9.3 | FD20: 33.3 | FE20: 29.1 | FF20: 14 | FG20: 18.3 | FH20: 7.9 | FI20: 10.8 | FJ20: 6395.8457 | FL20: 20.43463 | FM20: 0 | FN20: 6.1 | FO20: 6.2 | FP20: 27.4 | FQ20: 18.92075 | FR20: 5.3 | FS20: 5.1 | FU20: 89.45538
A21: 28/08/2025 | B21: 05:30 | C21: 100 | D21: 639.3 | E21: 214.7 | H21: 0 | I21: 85.3 | L21: 189.8 | M21: 203.8 | N21: 203 | O21: 282.4 | P21: 217.8 | Q21: 111.4 | R21: 376.6 | S21: 3.2 | T21: 11.6 | X21: 120.3 | Y21: 7.4 | Z21: 3.3 | AA21: 0 | AB21: 6.32 | AC21: 7.68 | AD21: 40.32 | AI21: 100.2 | AJ21: 41.57422 | AN21: 6.5 | AO21: 0 | AP21: 32.5 | AQ21: 51.7 | AR21: 21.1 | AS21: 18.6 | AT21: 10.9 | AU21: 62.4 | AV21: 181.9 | AW21: 182.6 | AX21: 184.7 | AY21: 78.9 | BA21: 0 | BB21: 9.9 | BC21: 30 | BD21: 2 | BE21: 0 | BF21: 69.7 | BI21: 82.7 | BL21: 47.3 | BP21: 65.8 | BQ21: 180.6 | BR21: 177.9 | BS21: 212.1 | BT21: 275.2 | BU21: 38 | BV21: 26.8 | CC21: 0.4 | CD21: 100.3 | CE21: 90.2 | CF21: 62.9 | CG21: 69.7 | CH21: 29.1 | CL21: 147.8 | CM21: 150.2 | CN21: 150.5 | CO21: 0 | CT21: 218.3 | CU21: 104.7 | CV21: 0 | CW21: 14.7 | CX21: 0 | CY21: 17.3 | CZ21: 0 | DA21: 5.1 | DB21: 5.1 | DC21: 0 | DD21: 0 | DE21: 0.3 | DF21: 1.8 | DG21: 4.5 | DH21: 15.5 | DI21: 5 | DJ21: 3.1 | DK21: 3.3 | DL21: 18.5 | DM21: 0 | DN21: 0 | DO21: 0.9 | DP21: 2.1 | DQ21: 4.4 | DR21: 1.2 | DS21: 1.2 | DT21: 3 | DU21: 0 | DV21: 2.6 | DW21: 14.6 | DX21: 1.2 | DZ21: 5.6 | EA21: 3 | EB21: 4.8 | EC21: 7.2 | ED21: 10 | EE21: 10.1 | EF21: 6.6 | EG21: 0 | EH21: 3.1 | EI21: 12.1 | EJ21: 0.2 | EK21: 0 | EL21: 7.4 | EM21: 1.8 | EO21: 4.5 | EP21: 5 | EQ21: 5.2 | ER21: 16 | ES21: 0 | ET21: 0.0778 | EU21: 0 | EV21: 0.6 | EW21: 0 | EX21: 0.1 | EY21: 0 | EZ21: 0 | FA21: 7.1 | FB21: 19.5 | FC21: 9.1 | FD21: 33.7 | FE21: 29.4 | FF21: 14 | FG21: 18.3 | FH21: 9.1 | FI21: 9.95 | FJ21: 6518.822 | FL21: 20.16783 | FM21: 0 | FN21: 6.1 | FO21: 6.2 | FP21: 27.5 | FQ21: 18.9216 | FR21: 5.3 | FS21: 5.1 | FU21: 89.28943
A22: 28/08/2025 | B22: 06:00 | C22: 99.2 | D22: 644.4 | E22: 216.2 | H22: 0 | I22: 84.6 | L22: 190.3 | M22: 200.9 | N22: 200.1 | O22: 282.1 | P22: 216.6 | Q22: 111.4 | R22: 380.7 | S22: 3.2 | T22: 12.8 | X22: 125.9 | Y22: 7.9 | Z22: 3.4 | AA22: 0 | AB22: 6.35 | AC22: 7.71 | AD22: 40.5 | AI22: 101.4 | AJ22: 30.81606 | AN22: 6.5 | AO22: 0 | AP22: 33.6 | AQ22: 51.9 | AR22: 22.4 | AS22: 18.6 | AT22: 10.9 | AU22: 67 | AV22: 184.1 | AW22: 184.2 | AX22: 184.8 | AY22: 80.8 | BA22: 0 | BB22: 10.8 | BC22: 29.8 | BD22: 2 | BE22: 0 | BF22: 64.1 | BI22: 83.9 | BL22: 47.5 | BP22: 66.3 | BQ22: 179.4 | BR22: 176 | BS22: 210.5 | BT22: 275.1 | BU22: 77 | BV22: 37 | CC22: 0.4 | CD22: 107.8 | CE22: 78.5 | CF22: 66.9 | CG22: 72 | CH22: 29.7 | CL22: 147.9 | CM22: 150.4 | CN22: 150.7 | CO22: 0 | CT22: 218.7 | CU22: 104.8 | CV22: 0 | CW22: 21.8 | CX22: 0 | CY22: 18.1 | CZ22: 0 | DA22: 5.1 | DB22: 5.2 | DC22: 0 | DD22: 0 | DE22: 0.3 | DF22: 1.8 | DG22: 4.5 | DH22: 15.8 | DI22: 5.1 | DJ22: 3.1 | DK22: 3.3 | DL22: 18.5 | DM22: 1.1 | DN22: 1.2 | DO22: 2.6 | DP22: 5.5 | DQ22: 4.4 | DR22: 0.7 | DS22: 1.2 | DT22: 3 | DU22: 0 | DV22: 2.6 | DW22: 20.1 | DX22: 1.2 | DZ22: 5.6 | EA22: 2.9 | EB22: 4.8 | EC22: 7.3 | ED22: 10 | EE22: 9.5 | EF22: 10.6 | EG22: 0 | EH22: 7.8 | EI22: 16 | EJ22: 0.6 | EK22: 1.1 | EL22: 7.4 | EM22: 1.8 | EO22: 4.5 | EP22: 5 | EQ22: 5.2 | ER22: 17.2 | ES22: 1.4 | ET22: 0.1278 | EU22: 0.6 | EV22: 0.6 | EW22: 14.6 | EX22: 13.6 | EY22: 0.6 | EZ22: 0 | FA22: 7.1 | FB22: 19.5 | FC22: 9.2 | FD22: 33.6 | FE22: 29.4 | FF22: 13.9 | FG22: 18.3 | FH22: 9.4 | FI22: 10.05 | FJ22: 6643.9539 | FL22: 20.51399 | FM22: 0 | FN22: 6.1 | FO22: 6.2 | FP22: 27.4 | FQ22: 18.92235 | FR22: 5.2 | FS22: 5.1 | FU22: 89.43634
... A58: 29/08/2025 | B58: 00:00 | C58: 99.8 | D58: 638.4 | E58: 217.2 | H58: 11.8 | I58: 79.2 | L58: 189.4 | M58: 191.4 | N58: 191.3 | O58: 275.1 | P58: 217.7 | Q58: 111.1 | R58: 296.6 | S58: 3.2 | T58: 0 | X58: 121.2 | Y58: 7.6 | Z58: 3.3 | AA58: 22.5 | AB58: 6.39 | AC58: 10.14 | AD58: 73.39 | AI58: 74.5 | AJ58: 132.93014 | AN58: 6.5 | AO58: 0 | AP58: 26.1 | AQ58: 0 | AR58: 18.5 | AS58: 18.4 | AT58: 10.8 | AU58: 63.3 | AV58: 184.7 | AW58: 185 | AX58: 184.3 | AY58: 71.5 | BA58: 5.8 | BB58: 0 | BC58: 28.3 | BD58: 2 | BE58: 0 | BF58: 28.5 | BI58: 82 | BL58: 47.9 | BP58: 55.9 | BQ58: 179.1 | BR58: 176.7 | BS58: 106.6 | BT58: 252.5 | BU58: 76.7 | BV58: 37.2 | CC58: 0.4 | CD58: 67.7 | CE58: 81.4 | CF58: 64.3 | CG58: 69.8 | CH58: 29.6 | CL58: 147.4 | CM58: 149.8 | CN58: 172.1 | CO58: 193 | CT58: 218.4 | CU58: 104.6 | CV58: 0 | CW58: 22 | CX58: 0 | CY58: 16.5 | CZ58: 0 | DA58: 4.9 | DB58: 5.2 | DC58: 9.9 | DD58: 1 | DE58: 0.3 | DF58: 1.8 | DG58: 4.6 | DH58: 14.8 | DI58: 4.1 | DJ58: 3.1 | DK58: 3.3 | DL58: 18.5 | DM58: 0 | DN58: 0 | DO58: 7.7 | DP58: 25.2 | DQ58: 4.4 | DR58: 1.2 | DS58: 1.2 | DT58: 3 | DU58: 0 | DV58: 2.6 | DW58: 20.1 | DX58: 1.4 | DZ58: 4.9 | EA58: 3.1 | EB58: 4.2 | EC58: 6.3 | ED58: 10 | EE58: 22.8 | EF58: 16.3 | EG58: 0 | EH58: 47.2 | EI58: 51.9 | EJ58: 6.3 | EK58: 2.3 | EL58: 5.8 | EM58: 1.8 | EO58: 4 | EP58: 4.5 | EQ58: 4.7 | ER58: 12.8 | ES58: 0 | ET58: 0 | EU58: 0 | EV58: 0.6 | EW58: 26.4 | EX58: 36.5 | EY58: 0 | EZ58: 0 | FA58: 7.2 | FB58: 19 | FC58: 9.7 | FD58: 34.1 | FE58: 26.9 | FF58: 13.2 | FG58: 18.3 | FH58: 7 | FI58: 11.03 | FJ58: 6716.5801 | FL58: 18.84181 | FM58: 0 | FN58: 6.1 | FO58: 6.2 | FP58: 27.6 | FQ58: 18.91949 | FR58: 5.7 | FS58: 5 | FU58: 88.3613
A59: EJEC | C59: 2375.2 | D59: 15292.75 | E59: 5174.15 | F59: 0 | G59: 0 | H59: 229.65 | I59: 1984.5 | J59: 0 | K59: 0 | L59: 4535.3 | M59: 4875.6 | N59: 4880.75 | O59: 6802.75 | P59: 5190.25 | Q59: 2659.95 | R59: 6758.55 | S59: 76.5 | T59: 157.1 | U59: 0 | V59: 0 | W59: 0 | X59: 2873.7 | Y59: 177.05 | Z59: 79.2 | AA59: 209.45 | AB59: 152.305 | AC59: 231.91 | AD59: 1496.375 | AE59: 0 | AF59: 0 | AG59: 0 | AH59: 0 | AI59: 1840.5 | AJ59: 2335.4856 | AK59: 0 | AL59: 0 | AM59: 0 | AN59: 156 | AO59: 301.45 | AP59: 721.05 | AQ59: 1531.6 | AR59: 456.75 | AS59: 443.05 | AT59: 261 | AU59: 1499.3 | AV59: 4374.65 | AW59: 4384.15 | AX59: 4432.55 | AY59: 1803.1 | AZ59: 0 | BA59: 30.6 | BB59: 183.35 | BC59: 691.1 | BD59: 48 | BE59: 256.55 | BF59: 1757.15 | BG59: 0 | BH59: 0 | BI59: 1319.6 | BJ59: 0 | BK59: 0 | BL59: 1134.75 | BM59: 0 | BN59: 0 | BO59: 0 | BP59: 1460.85 | BQ59: 4291.1 | BR59: 4233.9 | BS59: 5009.65 | BT59: 6546.75 | BU59: 1526.15 | BV59: 710.55 | BW59: 0 | BX59: 0 | BY59: 0 | BZ59: 0 | CA59: 0 | CB59: 0 | CC59: 9.6 | CD59: 3001.05 | CE59: 2078.15 | CF59: 1536.2 | CG59: 1677.55 | CH59: 697.3 | CI59: 0 | CJ59: 0 | CK59: 0 | CL59: 3532.6 | CM59: 3592.15 | CN59: 3795.9 | CO59: 1412.35 | CP59: 0 | CQ59: 0 | CR59: 0 | CS59: 0 | CT59: 5241 | CU59: 2511.6 | CV59: 9.1 | CW59: 685 | CX59: 745.9 | CY59: 415.35 | CZ59: 3 | DA59: 119.25 | DB59: 122.2 | DC59: 181.6 | DD59: 21.5 | DE59: 170.55 | DF59: 43.2 | DG59: 112.7 | DH59: 362.6 | DI59: 109.2 | DJ59: 64.15 | DK59: 78.6 | DL59: 444 | DM59: 145.8 | DN59: 174.45 | DO59: 186.8 | DP59: 661.55 | DQ59: 104.45 | DR59: 27.7 | DS59: 18.65 | DT59: 70.9 | DU59: 128.7 | DV59: 57.9 | DW59: 325.3 | DX59: 30.2 | DY59: 0 | DZ59: 132.85 | EA59: 63.05 | EB59: 111.75 | EC59: 159.55 | ED59: 240.6 | EE59: 468.45 | EF59: 678.8 | EG59: 318.6 | EH59: 847.55 | EI59: 1106.75 | EJ59: 126.85 | EK59: 93.75 | EL59: 131.55 | EM59: 34.75 | EN59: 0 | EO59: 101.05 | EP59: 112.6 | EQ59: 117.1 | ER59: 392.85 | ES59: 2404.85 | ET59: 125.42555 | EU59: 1317.85 | EV59: 14.4 | EW59: 1319.9 | EX59: 1545.65 | EY59: 968.6 | EZ59: 134.2 | FA59: 172.15 | FB59: 460.7 | FC59: 224 | FD59: 807.95 | FE59: 701.2 | FF59: 332.05 | FG59: 437.5 | FH59: 196.25 | FI59: 250.465 | FJ59: 171311.02 | FL59: 462.50774 | FM59: 82.355 | FN59: 146.4 | FO59: 150.2 | FP59: 652.1 | FQ59: 454.12763 | FR59: 127.25 | FS59: 180.55 | FT59: 0 | FU59: 2255.4904

Sheet REACTIVA
B3: jueves, 28 de Agosto del 2025
A5: POTENCIA REACTIVA EJECUTADA DE LAS UNIDADES DE GENERACIÓN DEL COES (MVAR) | FL5: CENTRALES NO INTEGRANTES COES
A6: FECHA | B6: HORA | C6: 65333 | D6: 101 | E6: 102 | F6: 42667 | G6: 42668 | H6: 126 | I6: 127 | J6: 138 | K6: 139 | L6: 197 | M6: 203 | N6: 204 | O6: 230 | P6: 209 | Q6: 56677 | R6: 796 | S6: 2146 | T6: 142 | U6: 143 | V6: 125 | W6: 187 | X6: 163 | Y6: 298 | Z6: 299 | AA6: 219 | AB6: 151 | AC6: 152 | AD6: 153 | AE6: 154 | AF6: 756 | AG6: 156 | AH6: 155 | AI6: 182 | AJ6: 212 | AK6: 758 | AL6: 263 | AM6: 265 | AN6: 775 | AO6: 777 | AP6: 2154 | AQ6: 150 | AR6: 149 | AS6: 188 | AT6: 2131 | AU6: 755 | AV6: 252 | AW6: 249 | AX6: 250 | AY6: 117 | AZ6: 267 | BA6: 268 | BB6: 119 | BC6: 120 | BD6: 189 | BE6: 122 | BF6: 266 | BG6: 337 | BH6: 338 | BI6: 251 | BJ6: 115 | BK6: 239 | BL6: 288 | BM6: 240 | BN6: 241 | BO6: 242 | BP6: 191 | BQ6: 194 | BR6: 196 | BS6: 207 | BT6: 236 | BU6: 795 | BV6: 285 | BW6: 995 | BX6: 996 | BY6: 997 | BZ6: 766 | CA6: 926 | CB6: 924 | CC6: 121 | CD6: 103 | CE6: 104 | CF6: 106 | CG6: 105 | CH6: 107 | CI6: 110 | CJ6: 109 | CK6: 144 | CL6: 113 | CM6: 114 | CN6: 193 | CO6: 208 | CP6: 786 | CQ6: 787 | CR6: 788 | CS6: 789 | CT6: 248 | CU6: 2159 | CV6: 303 | CW6: 59715 | CX6: 62255 | CY6: 1263 | CZ6: 61800 | DA6: 2194 | DB6: 69125 | DC6: 216 | DD6: 198 | DE6: 49607 | DF6: 214 | DG6: 260 | DH6: 2152 | DI6: 2128 | DJ6: 247 | DK6: 228 | DL6: 2135 | DM6: 261 | DN6: 237 | DO6: 253 | DP6: 770 | DQ6: 225 | DR6: 2201 | DS6: 2171 | DT6: 760 | DU6: 235 | DV6: 238 | DW6: 2184 | DX6: 61855 | DY6: 223 | DZ6: 226 | EA6: 201 | EB6: 258 | EC6: 259 | ED6: 920 | EE6: 257 | EF6: 256 | EG6: 2148 | EH6: 58288 | EI6: 58289 | EJ6: 58839 | EK6: 58840 | EL6: 296 | EM6: 297 | EN6: 211 | EO6: 2175 | EP6: 2178 | EQ6: 2181 | ER6: 1262 | ES6: 63425 | ET6: 233 | EU6: 2150 | EV6: 2165 | EW6: 2161 | EX6: 61197 | EY6: 58851 | EZ6: 234 | FA6: 215 | FB6: 917 | FC6: 289 | FD6: 58333 | FE6: 58336 | FF6: 213 | FG6: 232 | FH6: 2190 | FI6: 69867 | FJ6: TOTAL COES | FL6: 221 | FM6: 222 | FN6: 224 | FO6: 2187 | FP6: 227 | FQ6: 49400 | FR6: 199 | FS6: 200 | FT6: 70400 | FU6: TOTAL NO COES
C7: SUR | D7: CENTRO | E7: CENTRO | F7: NORTE | G7: NORTE | H7: NORTE | I7: NORTE | J7: CENTRO | K7: CENTRO | L7: CENTRO | M7: CENTRO | N7: CENTRO | O7: CENTRO | P7: CENTRO | Q7: CENTRO | R7: CENTRO | S7: CENTRO | T7: CENTRO | U7: CENTRO | V7: CENTRO | W7: CENTRO | X7: SUR | Y7: SUR | Z7: SUR | AA7: CENTRO | AB7: SUR | AC7: SUR | AD7: SUR | AE7: SUR | AF7: SUR | AG7: SUR | AH7: SUR | AI7: SUR | AJ7: CENTRO | AK7: NORTE | AL7: NORTE | AM7: NORTE | AN7: CENTRO | AO7: CENTRO | AP7: CENTRO | AQ7: CENTRO | AR7: CENTRO | AS7: CENTRO | AT7: CENTRO | AU7: SUR | AV7: CENTRO | AW7: CENTRO | AX7: CENTRO | AY7: CENTRO | AZ7: CENTRO | BA7: CENTRO | BB7: CENTRO | BC7: CENTRO | BD7: SUR | BE7: NORTE | BF7: CENTRO | BG7: CENTRO | BH7: CENTRO | BI7: CENTRO | BJ7: NORTE | BK7: NORTE | BL7: NORTE | BM7: SUR | BN7: SUR | BO7: SUR | BP7: CENTRO | BQ7: CENTRO | BR7: CENTRO | BS7: CENTRO | BT7: CENTRO | BU7: CENTRO | BV7: CENTRO | BW7: SUR | BX7: SUR | BY7: SUR | BZ7: NORTE | CA7: SUR | CB7: CENTRO | CC7: NORTE | CD7: CENTRO | CE7: CENTRO | CF7: CENTRO | CG7: CENTRO | CH7: CENTRO | CI7: CENTRO | CJ7: CENTRO | CK7: CENTRO | CL7: CENTRO | CM7: CENTRO | CN7: CENTRO | CO7: CENTRO | CP7: SUR | CQ7: SUR | CR7: SUR | CS7: SUR | CT7: CENTRO | CU7: CENTRO | CV7: CENTRO | CW7: CENTRO | CX7: SUR | CY7: NORTE | CZ7: NORTE | DA7: NORTE | DB7: CENTRO | DC7: NORTE | DD7: NORTE | DE7: SUR | DF7: CENTRO | DG7: CENTRO | DH7: CENTRO | DI7: NORTE | DJ7: NORTE | DK7: CENTRO | DL7: CENTRO | DM7: SUR | DN7: SUR | DO7: CENTRO | DP7: CENTRO | DQ7: CENTRO | DR7: CENTRO | DS7: CENTRO | DT7: CENTRO | DU7: SUR | DV7: CENTRO | DW7: CENTRO | DX7: NORTE | DY7: CENTRO | DZ7: CENTRO | EA7: NORTE | EB7: CENTRO | EC7: CENTRO | ED7: CENTRO | EE7: NORTE | EF7: NORTE | EG7: SUR | EH7: CENTRO | EI7: CENTRO | EJ7: CENTRO | EK7: CENTRO | EL7: CENTRO | EM7: CENTRO | EN7: SUR | EO7: SUR | EP7: SUR | EQ7: SUR | ER7: NORTE | ES7: SUR | ET7: SUR | EU7: SUR | EV7: CENTRO | EW7: CENTRO | EX7: CENTRO | EY7: SUR | EZ7: SUR | FA7: NORTE | FB7: CENTRO | FC7: NORTE | FD7: NORTE | FE7: NORTE | FF7: CENTRO | FG7: NORTE | FH7: NORTE | FI7: NORTE | FL7: NORTE | FM7: CENTRO | FN7: NORTE | FO7: NORTE | FP7: NORTE | FQ7: NORTE | FR7: NORTE | FS7: NORTE | FT7: SUR
C8: HIDROELÉCTRICA | D8: HIDROELÉCTRICA | E8: HIDROELÉCTRICA | F8: TERMOELÉCTRICA | G8: TERMOELÉCTRICA | H8: HIDROELÉCTRICA | I8: HIDROELÉCTRICA | J8: TERMOELÉCTRICA | K8: TERMOELÉCTRICA | L8: TERMOELÉCTRICA | M8: TERMOELÉCTRICA | N8: TERMOELÉCTRICA | O8: TERMOELÉCTRICA | P8: TERMOELÉCTRICA | Q8: TERMOELÉCTRICA | R8: HIDROELÉCTRICA | S8: HIDROELÉCTRICA | T8: TERMOELÉCTRICA | U8: TERMOELÉCTRICA | V8: TERMOELÉCTRICA | W8: TERMOELÉCTRICA | X8: HIDROELÉCTRICA | Y8: HIDROELÉCTRICA | Z8: HIDROELÉCTRICA | AA8: TERMOELÉCTRICA | AB8: HIDROELÉCTRICA | AC8: HIDROELÉCTRICA | AD8: HIDROELÉCTRICA | AE8: HIDROELÉCTRICA | AF8: TERMOELÉCTRICA | AG8: TERMOELÉCTRICA | AH8: TERMOELÉCTRICA | AI8: HIDROELÉCTRICA | AJ8: HIDROELÉCTRICA | AK8: TERMOELÉCTRICA | AL8: TERMOELÉCTRICA | AM8: TERMOELÉCTRICA | AN8: HIDROELÉCTRICA | AO8: HIDROELÉCTRICA | AP8: HIDROELÉCTRICA | AQ8: HIDROELÉCTRICA | AR8: HIDROELÉCTRICA | AS8: HIDROELÉCTRICA | AT8: HIDROELÉCTRICA | AU8: HIDROELÉCTRICA | AV8: TERMOELÉCTRICA | AW8: TERMOELÉCTRICA | AX8: TERMOELÉCTRICA | AY8: HIDROELÉCTRICA | AZ8: HIDROELÉCTRICA | BA8: HIDROELÉCTRICA | BB8: HIDROELÉCTRICA | BC8: HIDROELÉCTRICA | BD8: HIDROELÉCTRICA | BE8: HIDROELÉCTRICA | BF8: HIDROELÉCTRICA | BG8: HIDROELÉCTRICA | BH8: HIDROELÉCTRICA | BI8: HIDROELÉCTRICA | BJ8: TERMOELÉCTRICA | BK8: TERMOELÉCTRICA | BL8: TERMOELÉCTRICA | BM8: TERMOELÉCTRICA | BN8: TERMOELÉCTRICA | BO8: TERMOELÉCTRICA | BP8: HIDROELÉCTRICA | BQ8: TERMOELÉCTRICA | BR8: TERMOELÉCTRICA | BS8: TERMOELÉCTRICA | BT8: TERMOELÉCTRICA | BU8: TERMOELÉCTRICA | BV8: TERMOELÉCTRICA | BW8: TERMOELÉCTRICA | BX8: TERMOELÉCTRICA | BY8: TERMOELÉCTRICA | BZ8: HIDROELÉCTRICA | CA8: TERMOELÉCTRICA | CB8: TERMOELÉCTRICA | CC8: HIDROELÉCTRICA | CD8: HIDROELÉCTRICA | CE8: HIDROELÉCTRICA | CF8: HIDROELÉCTRICA | CG8: HIDROELÉCTRICA | CH8: HIDROELÉCTRICA | CI8: TERMOELÉCTRICA | CJ8: TERMOELÉCTRICA | CK8: TERMOELÉCTRICA | CL8: TERMOELÉCTRICA | CM8: TERMOELÉCTRICA | CN8: TERMOELÉCTRICA | CO8: TERMOELÉCTRICA | CP8: TERMOELÉCTRICA | CQ8: TERMOELÉCTRICA | CR8: TERMOELÉCTRICA | CS8: TERMOELÉCTRICA | CT8: TERMOELÉCTRICA | CU8: TERMOELÉCTRICA | CV8: SOLAR | CW8: EÓLICA | CX8: SOLAR | CY8: EÓLICA | CZ8: SOLAR | DA8: HIDROELÉCTRICA | DB8: HIDROELÉCTRICA | DC8: HIDROELÉCTRICA | DD8: HIDROELÉCTRICA | DE8: HIDROELÉCTRICA | DF8: HIDROELÉCTRICA | DG8: HIDROELÉCTRICA | DH8: HIDROELÉCTRICA | DI8: HIDROELÉCTRICA | DJ8: HIDROELÉCTRICA | DK8: HIDROELÉCTRICA | DL8: HIDROELÉCTRICA | DM8: SOLAR | DN8: SOLAR | DO8: EÓLICA | DP8: EÓLICA | DQ8: TERMOELÉCTRICA | DR8: TERMOELÉCTRICA | DS8: TERMOELÉCTRICA | DT8: TERMOELÉCTRICA | DU8: SOLAR | DV8: HIDROELÉCTRICA | DW8: HIDROELÉCTRICA | DX8: HIDROELÉCTRICA | DY8: HIDROELÉCTRICA | DZ8: HIDROELÉCTRICA | EA8: HIDROELÉCTRICA | EB8: HIDROELÉCTRICA | EC8: HIDROELÉCTRICA | ED8: HIDROELÉCTRICA | EE8: EÓLICA | EF8: EÓLICA | EG8: SOLAR | EH8: EÓLICA | EI8: EÓLICA | EJ8: EÓLICA | EK8: EÓLICA | EL8: HIDROELÉCTRICA | EM8: HIDROELÉCTRICA | EN8: HIDROELÉCTRICA | EO8: HIDROELÉCTRICA | EP8: HIDROELÉCTRICA | EQ8: HIDROELÉCTRICA | ER8: EÓLICA | ES8: SOLAR | ET8: SOLAR | EU8: SOLAR | EV8: HIDROELÉCTRICA | EW8: EÓLICA | EX8: EÓLICA | EY8: SOLAR | EZ8: SOLAR | FA8: HIDROELÉCTRICA | FB8: HIDROELÉCTRICA | FC8: TERMOELÉCTRICA | FD8: TERMOELÉCTRICA | FE8: TERMOELÉCTRICA | FF8: TERMOELÉCTRICA | FG8: TERMOELÉCTRICA | FH8: TERMOELÉCTRICA | FI8: TERMOELÉCTRICA | FL8: HIDROELÉCTRICA | FM8: HIDROELÉCTRICA | FN8: HIDROELÉCTRICA | FO8: HIDROELÉCTRICA | FP8: TERMOELÉCTRICA | FQ8: TERMOELÉCTRICA | FR8: HIDROELÉCTRICA | FS8: HIDROELÉCTRICA | FT8: SOLAR
