Workbook

Sheet EVENTOS
B3: martes, 13 de Enero del 2026
B5: INFORMACIÓN DE EVENTOS PRINCIPALES EN SUS INSTALACIONES
B6: TIPO DE EVENTO | C6: EMPRESA | D6: UBICACIÓN | E6: TIPO DE EQUIPO | F6: EQUIPO | G6: INICIO | H6: FINAL | I6: DESCRIPCIÓN | J6: MW INDISP. | K6: INTERRUPCIÓN (SI/NO) | L6: TENSIÓN DE FALLA (kV)
B7: EVENTO | C7: CONELSUR LT SAC | D7: PORTILLO | E7: SUBESTACION | F7: SS.EE. | G7: 13/01/2026 00:00:00 | H7: 14/01/2026 00:00:00 | I7: DECLARACIÓN DE SITUACIÓN EXCEPCIONAL EN LA S.E. PORTILLO 60 kV | K7: NO
B8: EVENTO | C8: ELECTRO ORIENTE | D8: BELAUNDE TERRY - TARAPOTO | E8: LINEA DE TRANSMISION | F8: L-1018 | G8: 13/01/2026 11:25:00 | H8: 13/01/2026 11:57:00 | I8: DECLARACIÓN DE SITUACIÓN EXCEPCIONAL EN LA LÍNEA L-1018 (BELAUNDE TERRY - TARAPOTO) DE 138 kV | K8: NO
B9: FALLA | C9: PLUZ ENERGÍA PERÚ S.A.A. | D9: CHAVARRÍA | E9: BARRA | F9: SCV_CH | G9: 13/01/2026 14:04:51 | H9: 13/01/2026 15:21:00 | I9: DESCONEXIÓN DEL SVC DE LA S.E. CHAVARRIA | K9: NO | L9: 0
B10: EVENTO | C10: RED DE ENERGIA DEL PERU S.A. | D10: QUENCORO | E10: TRANSFORMADOR 3D | F10: T47-131 | G10: 13/01/2026 11:49:00 | H10: 13/01/2026 18:35:00 | I10: RECHAZO MANUAL DE CARGA POR SOBRECARGA DEL TRANSFORMADOR T47-131 DE 138/34,5/10,5 kV DE LA S.E. QUENCORO | K10: SI

Sheet RESTRIC_OPE
B3: martes, 13 de Enero del 2026
B5: RESTRICCIONES OPERATIVAS
B6: FECHA | C6: HORA INICIO | D6: HORA FINAL | E6: EMPRESA | F6: UBICACIÓN | G6: T.Eq. | H6: EQUIPO | I6: DESCRIPCIÓN
B7: 13/01/2026 | C7: 00:00 | D7: 24:00 | E7: ATLANTICA TRANSMISION SUR S.A. | F7: L. POROMA - OCONA | G7: LINEA | H7: L-5034 | I7: Capacidad limitado a 750 MVA debido a corte de hilo conductor caído(FASE S) en el tramo T50-T51.
B8: 13/01/2026 | C8: 00:00 | D8: 24:00 | E8: EGASA | F8: S.E. CONVERTIDOR | G8: BARRA | H8: BARRA138KV | I8: EGASA limitó la capacidad del transformador 138 kV/33 kV a 50 MVA por deterioro del aislamiento.
B9: 13/01/2026 | C9: 00:00 | D9: 24:00 | E9: ELECTROPERU | F9: C.H. MANTARO | G9: CH | H9: CENTRAL | I9: De acuerdo con el correo del día 25.08.2025, la central tiene una limitación de potencia máxima de 650 MW por seguridad de la central.
B10: 13/01/2026 | C10: 00:00 | D10: 12:29 | E10: EMPRESA DE GENERACION ELECTRICA SANTA ANA S.A.C. | F10: C.H. RENOVANDES H1 | G10: CH | H10: CENTRAL | I10: Indisponible por alta concentración de sólidos en suspensión
B11: 13/01/2026 | C11: 00:00 | D11: 24:00 | E11: ENEL GENERACION PIURA S.A. | F11: C.T. MALACAS | G11: CT | H11: CENTRAL | I11: De acuerdo con la comunicación vía correo del día 24.10.2024. ENEL GENERACIÓN PIURA informa una restricción de potencia para alcanzar 105 MW en simultaneo (TG6+TGN4).
B12: 13/01/2026 | C12: 00:00 | D12: 24:00 | E12: ENEL GENERACION PIURA S.A. | F12: C.T. MALACAS | G12: GT | H12: TG4 | I12: De acuerdo a lo informado mediante correo electrónico el día 25.10, con la disponibilidad actual de aproximadamente 13 MMPCD (368.12 Mm³) la unidad TG4 puede con una generación de 80 MW durante 5 horas, y a potencia mínima durante el resto de los periodos
B13: 13/01/2026 | C13: 00:00 | D13: 24:00 | E13: ENGIE ENERGIA PERU S.A.A. | F13: C.H. YUNCÁN | G13: GH | H13: G3 | I13: Según la carta N° ENG/ 198-2024 enviada por su representada, se opera de forma continua el G3 de la CH Yuncán, debido a la ejecución de mantenimientos necesarios para evitar daños en los sellos de seguridad de la válvula esférica del grupo.
B14: 13/01/2026 | C14: 00:00 | D14: 24:00 | E14: ENGIE ENERGIA PERU S.A.A. | F14: C.T. CHILCA 1 | G14: CT | H14: CENTRAL | I14: Restricción de temperatura de la C.T Chilca, ver valor en el modelo de despacho.
B15: 13/01/2026 | C15: 00:00 | D15: 24:00 | E15: ENGIE ENERGIA PERU S.A.A. | F15: C.T. CHILCA 1 | G15: CT | H15: CENTRAL | I15: Con carta ENG/971-2023, indica que no puede cumplir con las IO considerada en el PDO_17122023 dado que vulneran la seguridad de sus activos. Indican que se debe tomar TMO=168h.
B16: 13/01/2026 | C16: 00:00 | D16: 24:00 | E16: ENGIE ENERGIA PERU S.A.A. | F16: C.T. CHILCA 2 | G16: CT | H16: CENTRAL | I16: Con carta ENG/971-2023, indica que no puede cumplir con las IO considerada en el PDO_17122023 dado que vulneran la seguridad de sus activos. Indican que se debe tomar TMO=168h.
B17: 13/01/2026 | C17: 00:00 | D17: 24:00 | E17: FENIX POWER PERÚ | F17: C.T. FENIX | G17: CT | H17: CENTRAL | I17: De acuerdo con lo comunicado en el correo del día 06.05.2025, la CT Fenix cuenta con TMO de 168 hrs en todos sus modos de operación.
... B58: 13/01/2026 | C58: 00:00 | D58: 12:23 | E58: VARI ENERGIA S.A.C. | F58: C.H. ANASHIRONI | G58: CH | H58: C.H. ANASHIRONI | I58: Indisponible por alta concentración de sólidos en suspensión

Sheet MANTENIMIENTO EJECUTADOS
B3: martes, 13 de Enero del 2026
B5: Mantenimiento Ejecutado
B6: Empresa | C6: Ubicación | D6: Equipo | E6: Inicio | F6: Final | G6: Descripción | H6: MW Indisp. | I6: Prog. | J6: Dispon | K6: Interrupc. | L6: Tipo | M6: CodEq | N6: TipoEq_Osinerg
B7: ATLANTICA TRANSMISION SUR S.A. | C7: OCONA | D7: INT-5450 | E7: 13/01/2026 00:00 | F7: 14/01/2026 00:00 | G7: Interruptor INT-5450 cerrado con restriccion operativa, REB-5450 en servicio y suministrando los SS.AA. de la S.E. Oco?a. | H7: 0 | I7: P | J7: E/S | K7: N | L7: OTROS | M7: 13761 | N7: T
B8: ATLANTICA TRANSMISION SUR S.A. | C8: POROMA | D8: INT-5371 | E8: 13/01/2026 00:00 | F8: 14/01/2026 00:00 | G8: Seccionador SBB-5371 fase T indisponible por problemas mecanicos, el seccionador permanece cerrado y bloqueado | H8: 0 | I8: P | J8: E/S | K8: N | L8: OTROS | M8: 13751 | N8: T
B9: ATLANTICA TRANSMISION SUR S.A. | C9: POROMA | D9: REB-5350 | E9: 13/01/2026 00:00 | F9: 14/01/2026 00:00 | G9: Fuera de servicio por falla en el equipo. | H9: 0 | I9: P | J9: F/S | K9: N | L9: OTROS | M9: 13771 | N9: T
B10: ATLANTICA TRANSMISION SUR S.A. | C10: POROMA - OCONA | D10: L-5034 | E10: 13/01/2026 08:49 | F10: 13/01/2026 17:51 | G10: Mantenimiento en pedestales de torres de la L-5034. | H10: 0 | I10: P | J10: E/S | K10: N | L10: PREV. | M10: 13743 | N10: T
B11: ATN 2 S.A. | C11: COTARUSE - LAS BAMBAS | D11: L-2055 | E11: 13/01/2026 07:47 | F11: 13/01/2026 14:37 | G11: A solicitud de REP: Revision y pruebas de disparo al interruptor IN-2786 | H11: 0 | I11: P | J11: F/S | K11: N | L11: OTROS | M11: 14930 | N11: T
B12: ATN S.A. | C12: KIMAN AYLLU | D12: AUT-501 | E12: 13/01/2026 00:00 | F12: 14/01/2026 00:00 | G12: Restriccion Operativa en el circuito de control de cambiador de tap s del AUT-501 | H12: 0 | I12: P | J12: E/S | K12: N | L12: OTROS | M12: 13099 | N12: T
B13: CHINANGO S.A.C. | C13: CHIMAY | D13: CENTRAL | E13: 13/01/2026 00:00 | F13: 14/01/2026 00:00 | G13: Fuera de servicio por alta concentracion de solidos 2.3 gr/lt y caudal 170 m3/seg. | H13: 150 | I13: F | J13: F/S | K13: N | L13: OTROS | M13: 1191 | N13: G
B14: CHINANGO S.A.C. | C14: YANANGO | D14: G1 | E14: 13/01/2026 07:14 | F14: 14/01/2026 00:00 | G14: FUERA DE SERVICIO POR ALTA CONCENTRACION DE SOLIDOS 6.2 gr/lt Y CAUDAL 65 m3/seg. | H14: 42 | I14: F | J14: F/S | K14: N | L14: OTROS | M14: 108 | N14: G
B15: CONELSUR LT SAC | C15: CALLAHUANCA (CNS) | D15: S.E. | E15: 13/01/2026 00:00 | F15: 14/01/2026 00:00 | G15: RELE DIFERENCIAL DE BARRAS DE CALLAHUANCA 220KV INOPERATIVO | H15: 0 | I15: P | J15: E/S | K15: N | L15: OTROS | M15: 316 | N15: T
B16: EGASA | C16: SANTUARIO | D16: ACOPLE 138 | E16: 13/01/2026 00:00 | F16: 14/01/2026 00:00 | G16: En servicio barra 2,uso en grupo N1 Charcani V con interruptor de acoplamiento, por falla | H16: 0 | I16: P | J16: E/S | K16: N | L16: OTROS | M16: 11052 | N16: T
B17: EGESUR | C17: CT INDEPENDENCIA | D17: TR1 (Reserva) | E17: 13/01/2026 00:00 | F17: 14/01/2026 00:00 | G17: Transformador E/S con el Conmutador de Taps sin carga Deshabilitado | H17: 0 | I17: P | J17: E/S | K17: N | L17: OTROS | M17: 19961 | N17: T
B18: EGESUR | C18: INDEPENDENCIA | D18: INDEP_G3 | E18: 13/01/2026 00:00 | F18: 14/01/2026 00:00 | G18: Mantenimiento correctivo de lazo de comunicacion WECS - PLC | H18: 5.732 | I18: P | J18: F/S | K18: N | L18: CORR. | M18: 12779 | N18: G
... B120: TRANSMANTARO | C120: YARABAMBA | D120: CL-R-30 | E120: 13/01/2026 00:00 | F120: 14/01/2026 00:00 | G120: CL-R30 CON MANDO SINCRONIZADO ASOCIADO AL INTERRUPTOR IN-5147 INDISPONIBLE. EL 20.11.25 NO PUDO SER AJUSTADO DEBIDO A ANOMALIA EN LA CUCHILLA DE PUESTA A TIERRA ST-5027. | H120: 0 | I120: P | J120: E/S | K120: N | L120: OTROS | M120: 17424 | N120: T

Sheet INGRESO OC
A3: martes, 13 de Enero del 2026
A5: INGRESO A OPERACIÓN COMERCIAL
A6: EMPRESA | B6: TIPO DE EQUIPO | C6: UBICACIÓN | D6: EQUIPO | E6: Fecha y hora de Ingreso a Operación Comercial

Sheet DESPACHO_EJECUTADO
B3: martes, 13 de Enero del 2026
A5: POTENCIA ACTIVA EJECUTADA DE LAS UNIDADES DE GENERACIÓN DEL SEIN (MW) | FP5: CENTRALES NO INTEGRANTES COES
A6: FECHA | B6: HORA | C6: 65333 | D6: 101 | E6: 102 | F6: 42667 | G6: 42668 | H6: 126 | I6: 127 | J6: 138 | K6: 139 | L6: 197 | M6: 203 | N6: 204 | O6: 230 | P6: 209 | Q6: 56677 | R6: 796 | S6: 2146 | T6: 142 | U6: 143 | V6: 125 | W6: 187 | X6: 163 | Y6: 298 | Z6: 299 | AA6: 219 | AB6: 151 | AC6: 152 | AD6: 153 | AE6: 154 | AF6: 756 | AG6: 156 | AH6: 155 | AI6: 182 | AJ6: 212 | AK6: 758 | AL6: 263 | AM6: 265 | AN6: 775 | AO6: 777 | AP6: 2154 | AQ6: 150 | AR6: 149 | AS6: 188 | AT6: 2131 | AU6: 755 | AV6: 252 | AW6: 249 | AX6: 250 | AY6: 117 | AZ6: 119 | BA6: 120 | BB6: 189 | BC6: 122 | BD6: 266 | BE6: 337 | BF6: 338 | BG6: 251 | BH6: 115 | BI6: 239 | BJ6: 288 | BK6: 240 | BL6: 241 | BM6: 242 | BN6: 191 | BO6: 194 | BP6: 196 | BQ6: 207 | BR6: 236 | BS6: 795 | BT6: 285 | BU6: 995 | BV6: 996 | BW6: 997 | BX6: 766 | BY6: 926 | BZ6: 924 | CA6: 121 | CB6: 103 | CC6: 104 | CD6: 106 | CE6: 105 | CF6: 107 | CG6: 110 | CH6: 109 | CI6: 144 | CJ6: 113 | CK6: 114 | CL6: 193 | CM6: 208 | CN6: 786 | CO6: 787 | CP6: 788 | CQ6: 789 | CR6: 248 | CS6: 2159 | CT6: 267 | CU6: 268 | CV6: 2194 | CW6: 303 | CX6: 59715 | CY6: 62255 | CZ6: 1263 | DA6: 61800 | DB6: 69125 | DC6: 216 | DD6: 198 | DE6: 70400 | DF6: 49607 | DG6: 214 | DH6: 260 | DI6: 2152 | DJ6: 2128 | DK6: 247 | DL6: 228 | DM6: 2135 | DN6: 261 | DO6: 237 | DP6: 253 | DQ6: 770 | DR6: 235 | DS6: 238 | DT6: 2184 | DU6: 61855 | DV6: 223 | DW6: 75566 | DX6: 226 | DY6: 201 | DZ6: 258 | EA6: 259 | EB6: 920 | EC6: 257 | ED6: 256 | EE6: 2148 | EF6: 58288 | EG6: 58289 | EH6: 58839 | EI6: 58840 | EJ6: 75260 | EK6: 296 | EL6: 297 | EM6: 211 | EN6: 2175 | EO6: 2178 | EP6: 2181 | EQ6: 1262 | ER6: 63425 | ES6: 233 | ET6: 2150 | EU6: 2165 | EV6: 2161 | EW6: 61197 | EX6: 58851 | EY6: 225 | EZ6: 2201 | FA6: 2171 | FB6: 760 | FC6: 234 | FD6: 215 | FE6: 917 | FF6: 289 | FG6: 58333 | FH6: 58336 | FI6: 213 | FJ6: 232 | FK6: 2190 | FL6: 69867 | FM6: 75066 | FN6: TOTAL COES | FP6: 221 | FQ6: 222 | FR6: 224 | FS6: 2187 | FT6: 227 | FU6: 49400 | FV6: 199 | FW6: 200 | FX6: TOTAL NO COES
C7: SUR | D7: CENTRO | E7: CENTRO | F7: NORTE | G7: NORTE | H7: NORTE | I7: NORTE | J7: CENTRO | K7: CENTRO | L7: CENTRO | M7: CENTRO | N7: CENTRO | O7: CENTRO | P7: CENTRO | Q7: CENTRO | R7: CENTRO | S7: CENTRO | T7: CENTRO | U7: CENTRO | V7: CENTRO | W7: CENTRO | X7: SUR | Y7: SUR | Z7: SUR | AA7: CENTRO | AB7: SUR | AC7: SUR | AD7: SUR | AE7: SUR | AF7: SUR | AG7: SUR | AH7: SUR | AI7: SUR | AJ7: CENTRO | AK7: NORTE | AL7: NORTE | AM7: NORTE | AN7: CENTRO | AO7: CENTRO | AP7: CENTRO | AQ7: CENTRO | AR7: CENTRO | AS7: CENTRO | AT7: CENTRO | AU7: SUR | AV7: CENTRO | AW7: CENTRO | AX7: CENTRO | AY7: CENTRO | AZ7: CENTRO | BA7: CENTRO | BB7: SUR | BC7: NORTE | BD7: CENTRO | BE7: CENTRO | BF7: CENTRO | BG7: CENTRO | BH7: NORTE | BI7: NORTE | BJ7: NORTE | BK7: SUR | BL7: SUR | BM7: SUR | BN7: CENTRO | BO7: CENTRO | BP7: CENTRO | BQ7: CENTRO | BR7: CENTRO | BS7: CENTRO | BT7: CENTRO | BU7: SUR | BV7: SUR | BW7: SUR | BX7: NORTE | BY7: SUR | BZ7: CENTRO | CA7: NORTE | CB7: CENTRO | CC7: CENTRO | CD7: CENTRO | CE7: CENTRO | CF7: CENTRO | CG7: CENTRO | CH7: CENTRO | CI7: CENTRO | CJ7: CENTRO | CK7: CENTRO | CL7: CENTRO | CM7: CENTRO | CN7: SUR | CO7: SUR | CP7: SUR | CQ7: SUR | CR7: CENTRO | CS7: CENTRO | CT7: CENTRO | CU7: CENTRO | CV7: NORTE | CW7: CENTRO | CX7: CENTRO | CY7: SUR | CZ7: NORTE | DA7: NORTE | DB7: CENTRO | DC7: NORTE | DD7: NORTE | DE7: SUR | DF7: SUR | DG7: CENTRO | DH7: CENTRO | DI7: CENTRO | DJ7: NORTE | DK7: NORTE | DL7: CENTRO | DM7: CENTRO | DN7: SUR | DO7: SUR | DP7: CENTRO | DQ7: CENTRO | DR7: SUR | DS7: CENTRO | DT7: CENTRO | DU7: NORTE | DV7: CENTRO | DW7: CENTRO | DX7: CENTRO | DY7: NORTE | DZ7: CENTRO | EA7: CENTRO | EB7: CENTRO | EC7: NORTE | ED7: NORTE | EE7: SUR | EF7: CENTRO | EG7: CENTRO | EH7: CENTRO | EI7: CENTRO | EJ7: SUR | EK7: CENTRO | EL7: CENTRO | EM7: SUR | EN7: SUR | EO7: SUR | EP7: SUR | EQ7: NORTE | ER7: SUR | ES7: SUR | ET7: SUR | EU7: CENTRO | EV7: CENTRO | EW7: CENTRO | EX7: SUR | EY7: CENTRO | EZ7: CENTRO | FA7: CENTRO | FB7: CENTRO | FC7: SUR | FD7: NORTE | FE7: CENTRO | FF7: NORTE | FG7: NORTE | FH7: NORTE | FI7: CENTRO | FJ7: NORTE | FK7: NORTE | FL7: NORTE | FM7: NORTE | FP7: NORTE | FQ7: CENTRO | FR7: NORTE | FS7: NORTE | FT7: NORTE | FU7: NORTE | FV7: NORTE | FW7: NORTE
C8: HIDROELÉCTRICA | D8: HIDROELÉCTRICA | E8: HIDROELÉCTRICA | F8: TERMOELÉCTRICA | G8: TERMOELÉCTRICA | H8: HIDROELÉCTRICA | I8: HIDROELÉCTRICA | J8: TERMOELÉCTRICA | K8: TERMOELÉCTRICA | L8: TERMOELÉCTRICA | M8: TERMOELÉCTRICA | N8: TERMOELÉCTRICA | O8: TERMOELÉCTRICA | P8: TERMOELÉCTRICA | Q8: TERMOELÉCTRICA | R8: HIDROELÉCTRICA | S8: HIDROELÉCTRICA | T8: TERMOELÉCTRICA | U8: TERMOELÉCTRICA | V8: TERMOELÉCTRICA | W8: TERMOELÉCTRICA | X8: HIDROELÉCTRICA | Y8: HIDROELÉCTRICA | Z8: HIDROELÉCTRICA | AA8: TERMOELÉCTRICA | AB8: HIDROELÉCTRICA | AC8: HIDROELÉCTRICA | AD8: HIDROELÉCTRICA | AE8: HIDROELÉCTRICA | AF8: TERMOELÉCTRICA | AG8: TERMOELÉCTRICA | AH8: TERMOELÉCTRICA | AI8: HIDROELÉCTRICA | AJ8: HIDROELÉCTRICA | AK8: TERMOELÉCTRICA | AL8: TERMOELÉCTRICA | AM8: TERMOELÉCTRICA | AN8: HIDROELÉCTRICA | AO8: HIDROELÉCTRICA | AP8: HIDROELÉCTRICA | AQ8: HIDROELÉCTRICA | AR8: HIDROELÉCTRICA | AS8: HIDROELÉCTRICA | AT8: HIDROELÉCTRICA | AU8: HIDROELÉCTRICA | AV8: TERMOELÉCTRICA | AW8: TERMOELÉCTRICA | AX8: TERMOELÉCTRICA | AY8: HIDROELÉCTRICA | AZ8: HIDROELÉCTRICA | BA8: HIDROELÉCTRICA | BB8: HIDROELÉCTRICA | BC8: HIDROELÉCTRICA | BD8: HIDROELÉCTRICA | BE8: HIDROELÉCTRICA | BF8: HIDROELÉCTRICA | BG8: HIDROELÉCTRICA | BH8: TERMOELÉCTRICA | BI8: TERMOELÉCTRICA | BJ8: TERMOELÉCTRICA | BK8: TERMOELÉCTRICA | BL8: TERMOELÉCTRICA | BM8: TERMOELÉCTRICA | BN8: HIDROELÉCTRICA | BO8: TERMOELÉCTRICA | BP8: TERMOELÉCTRICA | BQ8: TERMOELÉCTRICA | BR8: TERMOELÉCTRICA | BS8: TERMOELÉCTRICA | BT8: TERMOELÉCTRICA | BU8: TERMOELÉCTRICA | BV8: TERMOELÉCTRICA | BW8: TERMOELÉCTRICA | BX8: HIDROELÉCTRICA | BY8: TERMOELÉCTRICA | BZ8: TERMOELÉCTRICA | CA8: HIDROELÉCTRICA | CB8: HIDROELÉCTRICA | CC8: HIDROELÉCTRICA | CD8: HIDROELÉCTRICA | CE8: HIDROELÉCTRICA | CF8: HIDROELÉCTRICA | CG8: TERMOELÉCTRICA | CH8: TERMOELÉCTRICA | CI8: TERMOELÉCTRICA | CJ8: TERMOELÉCTRICA | CK8: TERMOELÉCTRICA | CL8: TERMOELÉCTRICA | CM8: TERMOELÉCTRICA | CN8: TERMOELÉCTRICA | CO8: TERMOELÉCTRICA | CP8: TERMOELÉCTRICA | CQ8: TERMOELÉCTRICA | CR8: TERMOELÉCTRICA | CS8: TERMOELÉCTRICA | CT8: HIDROELÉCTRICA | CU8: HIDROELÉCTRICA | CV8: HIDROELÉCTRICA | CW8: SOLAR | CX8: EÓLICA | CY8: SOLAR | CZ8: EÓLICA | DA8: SOLAR | DB8: HIDROELÉCTRICA | DC8: HIDROELÉCTRICA | DD8: HIDROELÉCTRICA | DE8: SOLAR | DF8: HIDROELÉCTRICA | DG8: HIDROELÉCTRICA | DH8: HIDROELÉCTRICA | DI8: HIDROELÉCTRICA | DJ8: HIDROELÉCTRICA | DK8: HIDROELÉCTRICA | DL8: HIDROELÉCTRICA | DM8: HIDROELÉCTRICA | DN8: SOLAR | DO8: SOLAR | DP8: EÓLICA | DQ8: EÓLICA | DR8: SOLAR | DS8: HIDROELÉCTRICA | DT8: HIDROELÉCTRICA | DU8: HIDROELÉCTRICA | DV8: HIDROELÉCTRICA | DW8: SOLAR | DX8: HIDROELÉCTRICA | DY8: HIDROELÉCTRICA | DZ8: HIDROELÉCTRICA | EA8: HIDROELÉCTRICA | EB8: HIDROELÉCTRICA | EC8: EÓLICA | ED8: EÓLICA | EE8: SOLAR | EF8: EÓLICA | EG8: EÓLICA | EH8: EÓLICA | EI8: EÓLICA | EJ8: SOLAR | EK8: HIDROELÉCTRICA | EL8: HIDROELÉCTRICA | EM8: HIDROELÉCTRICA | EN8: HIDROELÉCTRICA | EO8: HIDROELÉCTRICA | EP8: HIDROELÉCTRICA | EQ8: EÓLICA | ER8: SOLAR | ES8: SOLAR | ET8: SOLAR | EU8: HIDROELÉCTRICA | EV8: EÓLICA | EW8: EÓLICA | EX8: SOLAR | EY8: TERMOELÉCTRICA | EZ8: TERMOELÉCTRICA | FA8: TERMOELÉCTRICA | FB8: TERMOELÉCTRICA | FC8: SOLAR | FD8: HIDROELÉCTRICA | FE8: HIDROELÉCTRICA | FF8: TERMOELÉCTRICA | FG8: TERMOELÉCTRICA | FH8: TERMOELÉCTRICA | FI8: TERMOELÉCTRICA | FJ8: TERMOELÉCTRICA | FK8: TERMOELÉCTRICA | FL8: TERMOELÉCTRICA | FM8: TERMOELÉCTRICA | FP8: HIDROELÉCTRICA | FQ8: HIDROELÉCTRICA | FR8: HIDROELÉCTRICA | FS8: HIDROELÉCTRICA | FT8: TERMOELÉCTRICA | FU8: TERMOELÉCTRICA | FV8: HIDROELÉCTRICA | FW8: HIDROELÉCTRICA
C9: HYDRO GLOBAL PERÚ S.A.C. | D9: ELECTROPERU | E9: ELECTROPERU | F9: ELECTROPERU | G9: ELECTROPERU | H9: ORAZUL ENERGY PERÚ | I9: ORAZUL ENERGY PERÚ | J9: TERMOSELVA | K9: TERMOSELVA | L9: KALLPA GENERACION S.A. | M9: KALLPA GENERACION S.A. | N9: KALLPA GENERACION S.A. | O9: KALLPA GENERACION S.A. | P9: KALLPA GENERACION S.A. | Q9: KALLPA GENERACION S.A. | R9: KALLPA GENERACION S.A. | S9: KALLPA GENERACION S.A. | T9: SHOUGESA | U9: SHOUGESA | V9: SHOUGESA | W9: SHOUGESA | X9: EGEMSA | Y9: EGESUR | Z9: EGESUR | AA9: EGESUR | AB9: EGASA | AC9: EGASA | AD9: EGASA | AE9: EGASA | AF9: EGASA | AG9: EGASA | AH9: EGASA | AI9: SAN GABAN | AJ9: CELEPSA | AK9: MINERA CERRO VERDE | AL9: PLANTA DE RESERVA FRIA DE GENERACION DE ETEN S.A. | AM9: PLANTA DE RESERVA FRIA DE GENERACION DE ETEN S.A. | AN9: EMPRESA DE GENERACION HUALLAGA | AO9: EMPRESA DE GENERACION HUALLAGA | AP9: LA VIRGEN | AQ9: CHINANGO S.A.C. | AR9: CHINANGO S.A.C. | AS9: HIDROELECTRICA HUANCHOR S.A.C. | AT9: CELEPSA RENOVABLES S.R.L. | AU9: INLAND ENERGY SAC | AV9: FENIX POWER PERÚ | AW9: FENIX POWER PERÚ | AX9: FENIX POWER PERÚ | AY9: STATKRAFT S.A | AZ9: STATKRAFT S.A | BA9: STATKRAFT S.A | BB9: STATKRAFT S.A | BC9: STATKRAFT S.A | BD9: STATKRAFT S.A | BE9: CENTRALES SANTA ROSA S.A.C. | BF9: CENTRALES SANTA ROSA S.A.C. | BG9: EMPRESA DE GENERACION HUANZA | BH9: ENEL GENERACION PIURA S.A. | BI9: ENEL GENERACION PIURA S.A. | BJ9: ENEL GENERACION PIURA S.A. | BK9: ENGIE ENERGIA PERU S.A.A. | BL9: ENGIE ENERGIA PERU S.A.A. | BM9: ENGIE ENERGIA PERU S.A.A. | BN9: ENGIE ENERGIA PERU S.A.A. | BO9: ENGIE ENERGIA PERU S.A.A. | BP9: ENGIE ENERGIA PERU S.A.A. | BQ9: ENGIE ENERGIA PERU S.A.A. | BR9: ENGIE ENERGIA PERU S.A.A. | BS9: ENGIE ENERGIA PERU S.A.A. | BT9: ENGIE ENERGIA PERU S.A.A. | BU9: ENGIE ENERGIA PERU S.A.A. | BV9: ENGIE ENERGIA PERU S.A.A. | BW9: ENGIE ENERGIA PERU S.A.A. | BX9: ENGIE ENERGIA PERU S.A.A. | BY9: INFRAESTRUCTURAS Y ENERGIAS DEL PERU S.A.C. | BZ9: INFRAESTRUCTURAS Y ENERGIAS DEL PERU S.A.C. | CA9: INVERSIONES SHAQSHA S.A.C. | CB9: ORYGEN PERU S.A.A. | CC9: ORYGEN PERU S.A.A. | CD9: ORYGEN PERU S.A.A. | CE9: ORYGEN PERU S.A.A. | CF9: ORYGEN PERU S.A.A. | CG9: ORYGEN PERU S.A.A. | CH9: ORYGEN PERU S.A.A. | CI9: ORYGEN PERU S.A.A. | CJ9: ORYGEN PERU S.A.A. | CK9: ORYGEN PERU S.A.A. | CL9: ORYGEN PERU S.A.A. | CM9: ORYGEN PERU S.A.A. | CN9: SAMAY I S.A.C | CO9: SAMAY I S.A.C | CP9: SAMAY I S.A.C | CQ9: SAMAY I S.A.C | CR9: TERMOCHILCA S.A.C. | CS9: TERMOCHILCA S.A.C. | CT9: TRANSMISION ANDINA DE GENERACION S.A.C. | CU9: TRANSMISION ANDINA DE GENERACION S.A.C. | CV9: CELARIS ENERGY S.A. | CW9: COLCA SOLAR S.A.C. | CX9: ENERGIA RENOVABLE DEL SUR S.A. | CY9: GR CORTARRAMA SOCIEDAD ANONIMA CERRADA | CZ9: GR TARUCA SOCIEDAD ANONIMA CERRADA | DA9: KONDU SAC | DB9: VARI ENERGIA S.A.C. | DC9: ORAZUL ENERGY PERÚ | DD9: ORAZUL ENERGY PERÚ | DE9: KALLPA GENERACION S.A. | DF9: SAN GABAN | DG9: MAJA ENERGIA S.A.C. | DH9: EMPRESA DE GENERACION ELECTRICA CANCHAYLLO SAC | DI9: EMPRESA DE GENERACION ELECTRICA SANTA ANA S.A.C. | DJ9: EMPRESA ELECTRICA AGUA AZUL | DK9: EMPRESA ELECTRICA RIO DOBLE | DL9: HIDROCAÑETE S.A. | DM9: HUAURA POWER GROUP S.A. | DN9: MOQUEGUA FV S.A.C. | DO9: PANAMERICANA SOLAR SAC. | DP9: PARQUE EOLICO MARCONA S.A.C. | DQ9: PARQUE EOLICO TRES HERMANAS S.A.C. | DR9: TACNA SOLAR SAC. | DS9: ELECTRICA YANAPAMPA SAC | DT9: ANDEAN POWER S.A.C. | DU9: ASOCIACIÓN SANTA LUCIA DE CHACAS | DV9: ATRIA ENERGIA S.A.C. | DW9: COENERGY S.A.C. | DX9: EGEJUNIN | DY9: EGEJUNIN | DZ9: EGEJUNIN | EA9: EGEJUNIN | EB9: EMPRESA DE GENERACION ELECTRICA RIO BAÑOS S.A.C. | EC9: ENERGÍA EÓLICA S.A. | ED9: ENERGÍA EÓLICA S.A. | EE9: ENGIE ENERGIA PERU S.A.A. | EF9: ENGIE ENERGIA PERU S.A.A. | EG9: ENGIE ENERGIA PERU S.A.A. | EH9: ENGIE ENERGIA PERU S.A.A. | EI9: ENGIE ENERGIA PERU S.A.A. | EJ9: ENGIE ENERGIA PERU S.A.A. | EK9: GENERACIÓN ANDINA S.A.C. | EL9: GENERACIÓN ANDINA S.A.C. | EM9: GENERADORA DE ENERGÍA DEL PERÚ | EN9: GENERADORA DE ENERGÍA DEL PERÚ | EO9: GENERADORA DE ENERGÍA DEL PERÚ | EP9: GENERADORA DE ENERGÍA DEL PERÚ | EQ9: GR PAINO SOCIEDAD ANONIMA CERRADA | ER9: JOYA SOLAR S.A.C. | ES9: MAJES ARCUS S.A.C. | ET9: ORYGEN PERU S.A.A. | EU9: ORYGEN PERU S.A.A. | EV9: ORYGEN PERU S.A.A. | EW9: ORYGEN PERU S.A.A. | EX9: ORYGEN PERU S.A.A. | EY9: PETRAMAS | EZ9: PETRAMAS | FA9: PETRAMAS | FB9: PETRAMAS | FC9: REPARTICIÓN ARCUS S.A.C. | FD9: SINERSA | FE9: SINERSA | FF9: BIOENERGIA DEL CHIRA S.A. | FG9: GM OPERACIONES S.A.C. | FH9: GM OPERACIONES S.A.C. | FI9: AGRO INDUSTRIAL PARAMONGA S.A. | FJ9: AGROAURORA S.A.C. | FK9: AGROINDUSTRIAS SAN JACINTO S.A.A. | FL9: AGROLMOS SOCIEDAD ANONIMA - AGROLMOS S.A. | FM9: CASA GRANDE S.A.A. | FP9: UNACEM PERU S.A. | FQ9: ELECTRO ORIENTE | FR9: AGUAS Y ENERGIA PERU | FS9: ELECTRO ZAÑA S.A.C. | FT9: ELECTRONOROESTE S.A. | FU9: SDE PIURA | FV9: SINERSA | FW9: SINERSA
C10: SAN GABAN III | D10: MANTARO | E10: RESTITUCION | F10: TUMBES MAK 1 | G10: TUMBES MAK 2 | H10: CARHUAQUERO | I10: CAÑON DEL PATO | J10: AGUAYTIA TG1 | K10: AGUAYTIA TG2 | L10: KALLPA TG1 | M10: KALLPA TG2 | N10: KALLPA TG3 | O10: KALLPA TV | P10: LFLORES TG1 | Q10: LFLORES TV | R10: CERRO DEL AGUILA | S10: CERRODELAGUILAG4 | T10: SHOUGESA TV1 | U10: SHOUGESA TV2 | V10: SHOUGESA TV3 | W10: SHOUGESA CUMMINS | X10: MACHUPICCHU | Y10: ARICOTA 1 | Z10: ARICOTA 2 | AA10: INDEPENDENCIA | AB10: CHARCANI I,II,III | AC10: CHARCANI IV | AD10: CHARCANI V | AE10: CHARCANI VI | AF10: CHILINA TG | AG10: MOLLENDO 1, 2, 3 | AH10: CHILINA (SULZ 1,2) | AI10: SAN GABAN II | AJ10: PLATANAL | AK10: RECKA | AL10: RF ETEN TG1 | AM10: RF ETEN TG2 | AN10: CHAGLLA GP1 | AO10: CHAGLLA | AP10: LA VIRGEN | AQ10: CHIMAY | AR10: YANANGO | AS10: HUANCHOR | AT10: MARAÑON | AU10: STA TERESA | AV10: FENIX GT11 | AW10: FENIX GT12 | AX10: FENIX TV10 | AY10: YAUPI | AZ10: MALPASO | BA10: CAHUA | BB10: ARCATA | BC10: GALLITO CIEGO | BD10: CHEVES | BE10: SANTA ROSA 1 | BF10: SANTA ROSA 2 | BG10: HUANZA | BH10: MALACAS2 TG4 | BI10: MALACAS3 TG 5 | BJ10: MALACAS1 TG6 | BK10: RF ILO2 TG1 | BL10: RF ILO2 TG2 | BM10: RF ILO2 TG3 | BN10: YUNCAN | BO10: CHILCA1 TG1 | BP10: CHILCA1 TG2 | BQ10: CHILCA1 TG3 | BR10: CHILCA-TV | BS10: CHILCA2 TG41 | BT10: CHILCA2-TV | BU10: CTNEPI_TG41 | BV10: CTNEPI_TG42 | BW10: CTNEPI_TG43 | BX10: QUITARACSA | BY10: RF PTO MALDONADO | BZ10: RF PUCALLPA | CA10: PARIAC | CB10: HUINCO | CC10: MATUCANA | CD10: MOYOPAMPA | CE10: CALLAHUANCA | CF10: HUAMPANI | CG10: STA ROSA WEST TG7 | CH10: UTI_5 | CI10: UTI_6 | CJ10: VENTANILLA 3 | CK10: VENTANILLA 4 | CL10: VENTANILLA TV | CM10: STAROSA TG8 | CN10: PTO_BRVO TG1 | CO10: PTO_BRVO TG2 | CP10: PTO_BRVO TG3 | CQ10: PTO_BRVO TG4 | CR10: OLLEROS TG1 | CS10: OLLEROS TV | CT10: OROYA | CU10: PACHACHACA | CV10: MANTA I | CW10: CS YARUCAYA | CX10: SAN JUAN | CY10: MATARANI | CZ10: DUNA | DA10: CARHUAQUERO (CS) | DB10: ANASHIRONI | DC10: CARHUAQUERO4 | DD10: CAÑA BRAVA | DE10: SUNNY | DF10: TUPURI | DG10: RONCADOR | DH10: CANCHAYLLO | DI10: RENOVANDESH1 | DJ10: POTRERO | DK10: PIZARRAS | DL10: NIMPERIAL | DM10: YARUCAYA | DN10: MOQUEGUA-SOLAR | DO10: PANAMERICANA-SOLAR | DP10: PQE-EOLICO-MARCONA | DQ10: PQE-EOLICO-3-HERMANAS | DR10: TACNA-SOLAR | DS10: YANAPAMPA | DT10: CARHUAC | DU10: HUALLIN | DV10: PURMACANA | DW10: COENERGY | DX10: HUASAHUASI | DY10: STACRUZ_1_2 | DZ10: RUNATULLO_II | EA10: RUNATULLO_III | EB10: RUCUY | EC10: PQE-EOLICO-TALARA | ED10: PQE-EOLICO-CUPISNIQUE | EE10: INTIPAMPA | EF10: PUNTA LOMITAS-BL1 | EG10: PUNTA LOMITAS-BL2 | EH10: PUN LOMITAS_EXP-BL1 | EI10: PUN LOMITAS_EXP-BL2 | EJ10: EXPANSIÓN INTIPAMPA | EK10: 8AGOSTO | EL10: EL CARMEN | EM10: LA JOYA | EN10: ANGEL_I | EO10: ANGEL_II | EP10: ANGEL_III | EQ10: HUAMBOS | ER10: SAN MARTIN SOLAR | ES10: MAJES | ET10: RUBI | EU10: CH_HER1 | EV10: WAYRA-I | EW10: WAYRA EXTENSION | EX10: CLEMESI | EY10: HUAYCOLORO | EZ10: CALLAO | FA10: DONA_CATALINA | FB10: LAGRINGAV | FC10: REPARTICION | FD10: POECHOS2 | FE10: CHANCAY | FF10: CANA BRAVA | FG10: REFINERIA TALARA TV1 | FH10: REFINERÍA TALARA TV2 | FI10: PARAMONGA | FJ10: MAPLE | FK10: SAN_JACINTO | FL10: AGROLMOS | FM10: CASA GRANDE | FN10: MW | FP10: CARPAPATA | FQ10: CENTRALES ELOR | FR10: PIAS1 | FS10: ZANA | FT10: TABLAZO | FU10: TALLANCA | FV10: CURUMUY | FW10: POECHOS1 | FX10: MW
A11: 13/01/2026 | B11: 00:30 | C11: 204.3 | D11: 629.6 | E11: 214.8 | H11: 91.9 | I11: 246.3 | L11: 0 | M11: 0 | N11: 203.1 | P11: 0 | R11: 147.4 | S11: 9.7 | X11: 167.5 | Y11: 7.8 | Z11: 4.8 | AA11: 0 | AB11: 6.9 | AC11: 13.7 | AD11: 80.6 | AI11: 110.6 | AJ11: 221.7 | AN11: 6.5 | AO11: 462.1 | AP11: 81 | AR11: 42.2 | AS11: 18.4 | AT11: 16.40847 | AU11: 92 | AV11: 183 | AW11: 183.1 | AX11: 183.9 | AY11: 109.4 | AZ11: 22.3 | BA11: 30.8 | BB11: 2 | BC11: 31.7 | BD11: 171.5 | BG11: 0 | BJ11: 46.2 | BN11: 128.3 | BO11: 159.9 | BP11: 159.8 | BQ11: 160.8 | BR11: 253.9 | BS11: 72.5 | BT11: 35.7 | BX11: 0 | CA11: 2.1 | CB11: 181.9 | CC11: 135 | CD11: 63.6 | CE11: 79.3 | CF11: 30.4 | CG11: 0 | CJ11: 142.6 | CK11: 143.7 | CL11: 147.4 | CT11: 6 | CU11: 1.7 | CV11: 20 | CW11: 0 | CX11: 59.6 | CY11: 0 | CZ11: 3.1 | DA11: 0 | DB11: 0 | DC11: 10 | DD11: 5.3 | DE11: 0 | DF11: 1.3 | DG11: 3.6 | DH11: 5.2 | DI11: 0 | DJ11: 20 | DK11: 18.3 | DL11: 3.4 | DM11: 18.6 | DN11: 0 | DO11: 0 | DP11: 20.6 | DQ11: 56.9 | DR11: 0 | DS11: 3 | DT11: 6 | DU11: 3.04 | DV11: 0 | DW11: 0 | DX11: 19.833 | DY11: 12.848 | DZ11: 20.3 | EA11: 20.22 | EB11: 20 | EC11: 3.8 | ED11: 7.8 | EE11: 0 | EF11: 41 | EG11: 75.3 | EH11: 2.5 | EI11: 1.8 | EJ11: 0 | EK11: 20.9 | EL11: 8.2 | EM11: 8.5 | EN11: 20.4 | EO11: 20.4 | EP11: 20.1 | EQ11: 1.6 | ER11: 0 | ES11: 0 | ET11: 0 | EU11: 0.6 | EV11: 34.6 | EW11: 22.5 | EX11: 0 | EY11: 3.6 | FA11: 2.2 | FB11: 1 | FC11: 0 | FD11: 8.1 | FE11: 20 | FF11: 9.9 | FG11: 26.7 | FH11: 32.2 | FI11: 12.9 | FJ11: 19.1 | FK11: 7.82 | FL11: 11.22 | FM11: 24.3 | FN11: 6767.9895 | FP11: 24.4796 | FQ11: 8.1 | FS11: 13.2 | FT11: 26.13492 | FU11: 18.94368 | FV11: 9.8 | FW11: 15.8 | FX11: 116.4582
A12: 13/01/2026 | B12: 01:00 | C12: 206.2 | D12: 627.3 | E12: 213.4 | H12: 89.9 | I12: 244.9 | L12: 0 | M12: 0 | N12: 199.8 | P12: 0 | R12: 180.7 | S12: 9.7 | X12: 168.9 | Y12: 7.4 | Z12: 4.8 | AA12: 0 | AB12: 7.1 | AC12: 13.7 | AD12: 80.4 | AI12: 110.8 | AJ12: 221.5 | AN12: 6.5 | AO12: 462.7 | AP12: 81 | AR12: 41.7 | AS12: 18.2 | AT12: 16.35187 | AU12: 90.6 | AV12: 181 | AW12: 181 | AX12: 184.3 | AY12: 109.5 | AZ12: 19.6 | BA12: 32.7 | BB12: 2 | BC12: 31.8 | BD12: 169.5 | BG12: 0 | BJ12: 45.7 | BN12: 127.9 | BO12: 169.1 | BP12: 166.6 | BQ12: 170.5 | BR12: 250.6 | BS12: 72.8 | BT12: 35.6 | BX12: 0 | CA12: 2 | CB12: 105.8 | CC12: 133.1 | CD12: 63 | CE12: 79.2 | CF12: 30.2 | CG12: 0 | CJ12: 141.7 | CK12: 142.5 | CL12: 146.3 | CT12: 5.8 | CU12: 1.8 | CV12: 20 | CW12: 0 | CX12: 45.6 | CY12: 0 | CZ12: 1.9 | DA12: 0 | DB12: 0 | DC12: 9.9 | DD12: 5.4 | DE12: 0 | DF12: 1.3 | DG12: 3.6 | DH12: 5.1 | DI12: 0 | DJ12: 20 | DK12: 18.4 | DL12: 3.4 | DM12: 18.6 | DN12: 0 | DO12: 0 | DP12: 17.1 | DQ12: 44.1 | DR12: 0 | DS12: 3 | DT12: 6 | DU12: 3.04 | DV12: 0 | DW12: 0 | DX12: 19.832 | DY12: 12.824 | DZ12: 20.05 | EA12: 20.19 | EB12: 20 | EC12: 4.4 | ED12: 7.5 | EE12: 0 | EF12: 53.5 | EG12: 51.7 | EH12: 4.3 | EI12: 1.9 | EJ12: 0 | EK12: 20.9 | EL12: 8 | EM12: 8.5 | EN12: 20.4 | EO12: 20.4 | EP12: 20.1 | EQ12: 2.9 | ER12: 0 | ES12: 0 | ET12: 0 | EU12: 0.6 | EV12: 27.7 | EW12: 19.2 | EX12: 0 | EY12: 3.6 | FA12: 2.2 | FB12: 1 | FC12: 0 | FD12: 8.2 | FE12: 20 | FF12: 9.1 | FG12: 27.1 | FH12: 31.9 | FI12: 12.9 | FJ12: 19.1 | FK12: 7.34 | FL12: 11.22 | FM12: 24.1 | FN12: 6674.2479 | FP12: 24.47872 | FQ12: 8.1 | FS12: 13.2 | FT12: 26.07052 | FU12: 18.94347 | FV12: 9.8 | FW12: 15.9 | FX12: 116.49271
A13: 13/01/2026 | B13: 01:30 | C13: 199.3 | D13: 620.4 | E13: 211.8 | H13: 85.5 | I13: 240.9 | L13: 0 | M13: 0 | N13: 204.1 | P13: 0 | R13: 246.1 | S13: 9.7 | X13: 164.9 | Y13: 7 | Z13: 4.9 | AA13: 0 | AB13: 7.1 | AC13: 13.6 | AD13: 79.4 | AI13: 109.4 | AJ13: 221.7 | AN13: 6.5 | AO13: 462.2 | AP13: 81 | AR13: 41.1 | AS13: 18.4 | AT13: 16.14023 | AU13: 90.9 | AV13: 176.3 | AW13: 176.3 | AX13: 185.4 | AY13: 108.5 | AZ13: 16.7 | BA13: 31 | BB13: 2 | BC13: 31.4 | BD13: 169.9 | BG13: 0 | BJ13: 46.2 | BN13: 127.1 | BO13: 164.5 | BP13: 164.4 | BQ13: 163.8 | BR13: 253.4 | BS13: 73.3 | BT13: 35.6 | BX13: 0 | CA13: 2 | CB13: 89.4 | CC13: 119.2 | CD13: 61.2 | CE13: 79.3 | CF13: 29.4 | CG13: 0 | CJ13: 144 | CK13: 145 | CL13: 148.9 | CT13: 5.9 | CU13: 1.7 | CV13: 20 | CW13: 0 | CX13: 44 | CY13: 0 | CZ13: 2.3 | DA13: 0 | DB13: 0 | DC13: 9.9 | DD13: 5.4 | DE13: 0 | DF13: 1.3 | DG13: 3.6 | DH13: 4.4 | DI13: 0 | DJ13: 20 | DK13: 18.4 | DL13: 3.4 | DM13: 18.7 | DN13: 0 | DO13: 0 | DP13: 16.7 | DQ13: 45.8 | DR13: 0 | DS13: 3 | DT13: 5.9 | DU13: 3.04 | DV13: 0 | DW13: 0 | DX13: 19.846 | DY13: 12.848 | DZ13: 19.83 | EA13: 20.1 | EB13: 20 | EC13: 4.8 | ED13: 5.9 | EE13: 0 | EF13: 28.6 | EG13: 58 | EH13: 2.4 | EI13: 1.6 | EJ13: 0 | EK13: 20.9 | EL13: 7.9 | EM13: 8.5 | EN13: 20.4 | EO13: 20.4 | EP13: 20.1 | EQ13: 2 | ER13: 0 | ES13: 0 | ET13: 0 | EU13: 0.6 | EV13: 10.9 | EW13: 7.6 | EX13: 0 | EY13: 3.6 | FA13: 2.2 | FB13: 1 | FC13: 0 | FD13: 8.2 | FE13: 20 | FF13: 9.8 | FG13: 26.7 | FH13: 32.3 | FI13: 13.8 | FJ13: 19.1 | FK13: 7.2 | FL13: 11.24 | FM13: 23 | FN13: 6611.0442 | FP13: 24.48916 | FQ13: 8.1 | FS13: 13.2 | FT13: 26.05156 | FU13: 18.94324 | FV13: 10 | FW13: 15.8 | FX13: 116.58396
A14: 13/01/2026 | B14: 02:00 | C14: 203.8 | D14: 622.9 | E14: 212.7 | H14: 90.9 | I14: 247.1 | L14: 0 | M14: 0 | N14: 202.2 | P14: 0 | R14: 131.1 | S14: 9.8 | X14: 169.1 | Y14: 7.6 | Z14: 5.4 | AA14: 0 | AB14: 6.9 | AC14: 13.7 | AD14: 80.1 | AI14: 110.5 | AJ14: 220.7 | AN14: 6.5 | AO14: 455.9 | AP14: 81 | AR14: 41.7 | AS14: 18.2 | AT14: 15.9809 | AU14: 89 | AV14: 180 | AW14: 180.4 | AX14: 183.1 | AY14: 108.9 | AZ14: 18.6 | BA14: 31.4 | BB14: 2 | BC14: 31.7 | BD14: 170.8 | BG14: 0 | BJ14: 46 | BN14: 127.7 | BO14: 142.6 | BP14: 142.6 | BQ14: 142 | BR14: 239.1 | BS14: 72.2 | BT14: 35.7 | BX14: 0 | CA14: 2 | CB14: 129.6 | CC14: 113.3 | CD14: 62.7 | CE14: 78.8 | CF14: 30 | CG14: 0 | CJ14: 141.1 | CK14: 142.3 | CL14: 146.1 | CT14: 5.8 | CU14: 1.8 | CV14: 20 | CW14: 0 | CX14: 34.1 | CY14: 0 | CZ14: 2.6 | DA14: 0 | DB14: 0 | DC14: 10 | DD14: 5.4 | DE14: 0 | DF14: 1.3 | DG14: 3.6 | DH14: 5.1 | DI14: 0 | DJ14: 20 | DK14: 18.3 | DL14: 3.4 | DM14: 18.6 | DN14: 0 | DO14: 0 | DP14: 12.9 | DQ14: 40.7 | DR14: 0 | DS14: 2.9 | DT14: 5.8 | DU14: 3.04 | DV14: 0 | DW14: 0 | DX14: 19.844 | DY14: 12.816 | DZ14: 19.91 | EA14: 20.17 | EB14: 19.9 | EC14: 4.2 | ED14: 5.2 | EE14: 0 | EF14: 23 | EG14: 34.7 | EH14: 2 | EI14: 1.5 | EJ14: 0 | EK14: 20.9 | EL14: 7.9 | EM14: 8.5 | EN14: 20.4 | EO14: 20.4 | EP14: 20.1 | EQ14: 2.2 | ER14: 0 | ES14: 0 | ET14: 0 | EU14: 0.6 | EV14: 21.5 | EW14: 20.1 | EX14: 0 | EY14: 3.6 | FA14: 2.2 | FB14: 1 | FC14: 0 | FD14: 8.2 | FE14: 19.8 | FF14: 9.8 | FG14: 27.2 | FH14: 32.4 | FI14: 14 | FJ14: 19.1 | FK14: 7.08 | FL14: 11.24 | FM14: 23.7 | FN14: 6443.9809 | FP14: 24.48783 | FQ14: 8.1 | FS14: 13.2 | FT14: 26.0753 | FU14: 18.94331 | FV14: 9.8 | FW14: 15.9 | FX14: 116.50644
A15: 13/01/2026 | B15: 02:30 | C15: 201.8 | D15: 625.8 | E15: 214 | H15: 89.9 | I15: 244.6 | L15: 0 | M15: 0 | N15: 202.1 | P15: 0 | R15: 159.3 | S15: 9.8 | X15: 160.6 | Y15: 7.8 | Z15: 5.4 | AA15: 0 | AB15: 7.1 | AC15: 13.7 | AD15: 80.2 | AI15: 110.7 | AJ15: 221.1 | AN15: 6.5 | AO15: 459.7 | AP15: 81 | AR15: 42 | AS15: 18.3 | AT15: 15.73645 | AU15: 91.5 | AV15: 151.3 | AW15: 151.6 | AX15: 167.1 | AY15: 108.6 | AZ15: 45.2 | BA15: 34.4 | BB15: 2 | BC15: 31.8 | BD15: 172.3 | BG15: 0 | BJ15: 45.7 | BN15: 127.9 | BO15: 149.5 | BP15: 149.4 | BQ15: 149.6 | BR15: 245.7 | BS15: 72.8 | BT15: 35.8 | BX15: 0 | CA15: 2 | CB15: 82.7 | CC15: 124.2 | CD15: 63.1 | CE15: 78.8 | CF15: 30.2 | CG15: 0 | CJ15: 142.1 | CK15: 142.9 | CL15: 147 | CT15: 5.8 | CU15: 1.8 | CV15: 20 | CW15: 0 | CX15: 39.1 | CY15: 0 | CZ15: 3.3 | DA15: 0 | DB15: 0 | DC15: 9.9 | DD15: 5.4 | DE15: 0 | DF15: 1.2 | DG15: 3.6 | DH15: 5.1 | DI15: 0 | DJ15: 19.7 | DK15: 18.3 | DL15: 3.4 | DM15: 18.6 | DN15: 0 | DO15: 0 | DP15: 8.9 | DQ15: 35.3 | DR15: 0 | DS15: 2.9 | DT15: 5.8 | DU15: 3.04 | DV15: 0 | DW15: 0 | DX15: 19.849 | DY15: 12.847 | DZ15: 19.95 | EA15: 20.22 | EB15: 20 | EC15: 4 | ED15: 2.8 | EE15: 0 | EF15: 13.4 | EG15: 40.3 | EH15: 1.8 | EI15: 0.8 | EJ15: 0 | EK15: 20.9 | EL15: 7.9 | EM15: 8.5 | EN15: 20.4 | EO15: 20.4 | EP15: 20.1 | EQ15: 2.3 | ER15: 0 | ES15: 0 | ET15: 0 | EU15: 0.6 | EV15: 27.3 | EW15: 19.1 | EX15: 0 | EY15: 3.6 | FA15: 2.2 | FB15: 1 | FC15: 0 | FD15: 8.2 | FE15: 20 | FF15: 9.5 | FG15: 27 | FH15: 32.4 | FI15: 14.4 | FJ15: 19.1 | FK15: 8.29 | FL15: 11.25 | FM15: 16.4 | FN15: 6410.2824 | FP15: 24.47561 | FQ15: 8.1 | FS15: 13.2 | FT15: 26.05125 | FU15: 18.94326 | FV15: 9.9 | FW15: 15.8 | FX15: 116.47012
A16: 13/01/2026 | B16: 03:00 | C16: 202.6 | D16: 626.4 | E16: 214.1 | H16: 90 | I16: 244.3 | L16: 0 | M16: 0 | N16: 202.5 | P16: 0 | R16: 169.8 | S16: 9.7 | X16: 165 | Y16: 7.8 | Z16: 5.4 | AA16: 0 | AB16: 7.1 | AC16: 13.7 | AD16: 80.5 | AI16: 110.9 | AJ16: 221.2 | AN16: 6.5 | AO16: 461.5 | AP16: 81 | AR16: 41.8 | AS16: 18.4 | AT16: 15.49478 | AU16: 88.5 | AV16: 151.3 | AW16: 151.8 | AX16: 167.4 | AY16: 108.5 | AZ16: 0 | BA16: 34.3 | BB16: 2 | BC16: 31.8 | BD16: 164.8 | BG16: 0 | BJ16: 45.9 | BN16: 127.9 | BO16: 147.8 | BP16: 147.7 | BQ16: 148.4 | BR16: 238.2 | BS16: 73 | BT16: 35.8 | BX16: 0 | CA16: 2 | CB16: 79.5 | CC16: 122.3 | CD16: 65.5 | CE16: 78.9 | CF16: 30.2 | CG16: 0 | CJ16: 142.5 | CK16: 143.2 | CL16: 147.2 | CT16: 5.8 | CU16: 1.8 | CV16: 20 | CW16: 0 | CX16: 44.3 | CY16: 0 | CZ16: 3.4 | DA16: 0 | DB16: 0 | DC16: 9.9 | DD16: 5.4 | DE16: 0 | DF16: 1.2 | DG16: 3.6 | DH16: 5.2 | DI16: 0 | DJ16: 20 | DK16: 18.3 | DL16: 3.5 | DM16: 18.6 | DN16: 0 | DO16: 0 | DP16: 11.8 | DQ16: 31.1 | DR16: 0 | DS16: 3 | DT16: 5.8 | DU16: 3.04 | DV16: 0 | DW16: 0 | DX16: 19.849 | DY16: 12.823 | DZ16: 19.95 | EA16: 20.2 | EB16: 20 | EC16: 4.8 | ED16: 2.2 | EE16: 0 | EF16: 17.8 | EG16: 30.4 | EH16: 1.2 | EI16: 1.1 | EJ16: 0 | EK16: 20.9 | EL16: 7.9 | EM16: 8.5 | EN16: 20.4 | EO16: 20.4 | EP16: 20.1 | EQ16: 1.8 | ER16: 0 | ES16: 0 | ET16: 0 | EU16: 0.6 | EV16: 33.1 | EW16: 30.6 | EX16: 0 | EY16: 3.6 | FA16: 2.2 | FB16: 1 | FC16: 0 | FD16: 8.2 | FE16: 20 | FF16: 9.8 | FG16: 26.9 | FH16: 32.4 | FI16: 14.5 | FJ16: 19.1 | FK16: 8.21 | FL16: 11.21 | FM16: 22.7 | FN16: 6382.2768 | FP16: 24.46123 | FQ16: 8.1 | FS16: 13.2 | FT16: 26.10846 | FU16: 18.94313 | FV16: 9.8 | FW16: 15.9 | FX16: 116.51282
A17: 13/01/2026 | B17: 03:30 | C17: 206.3 | D17: 629.3 | E17: 214.9 | H17: 91.8 | I17: 247.4 | L17: 0 | M17: 0 | N17: 200.4 | P17: 0 | R17: 207.1 | S17: 9.8 | X17: 170.7 | Y17: 7.8 | Z17: 5.5 | AA17: 0 | AB17: 7 | AC17: 13.7 | AD17: 80.7 | AI17: 110.8 | AJ17: 220.6 | AN17: 6.5 | AO17: 459 | AP17: 81 | AR17: 42.1 | AS17: 18.4 | AT17: 15.9968 | AU17: 91.2 | AV17: 154.1 | AW17: 154 | AX17: 167.3 | AY17: 108.6 | AZ17: 0 | BA17: 37 | BB17: 2 | BC17: 31.8 | BD17: 154.1 | BG17: 0 | BJ17: 45.7 | BN17: 129.4 | BO17: 150.7 | BP17: 150.6 | BQ17: 150.5 | BR17: 239.7 | BS17: 71.8 | BT17: 35.6 | BX17: 0 | CA17: 2 | CB17: 84.3 | CC17: 126.2 | CD17: 66.4 | CE17: 79.1 | CF17: 30.5 | CG17: 0 | CJ17: 142.7 | CK17: 143.2 | CL17: 146.9 | CT17: 5.8 | CU17: 1.8 | CV17: 20 | CW17: 0 | CX17: 44.8 | CY17: 0 | CZ17: 3.4 | DA17: 0 | DB17: 0 | DC17: 9.9 | DD17: 5.5 | DE17: 0 | DF17: 1.2 | DG17: 3.6 | DH17: 5.2 | DI17: 0 | DJ17: 20 | DK17: 18.3 | DL17: 3.5 | DM17: 18.6 | DN17: 0 | DO17: 0 | DP17: 11 | DQ17: 28.2 | DR17: 0 | DS17: 3 | DT17: 5.9 | DU17: 3.04 | DV17: 0 | DW17: 0 | DX17: 19.852 | DY17: 12.816 | DZ17: 19.92 | EA17: 20.3 | EB17: 20 | EC17: 4.5 | ED17: 0.5 | EE17: 0 | EF17: 13.2 | EG17: 40.4 | EH17: 0.7 | EI17: 0.4 | EJ17: 0 | EK17: 20.9 | EL17: 7.7 | EM17: 8.9 | EN17: 20.4 | EO17: 20.4 | EP17: 20.1 | EQ17: 2.2 | ER17: 0 | ES17: 0 | ET17: 0 | EU17: 0.6 | EV17: 27.7 | EW17: 18.2 | EX17: 0 | EY17: 3.6 | FA17: 2.2 | FB17: 1 | FC17: 0 | FD17: 8.2 | FE17: 20 | FF17: 9.8 | FG17: 26.9 | FH17: 32.3 | FI17: 14.2 | FJ17: 18.6 | FK17: 8.45 | FL17: 10.09 | FM17: 22.7 | FN17: 6432.6648 | FP17: 24.49385 | FQ17: 8.1 | FS17: 13.2 | FT17: 26.05462 | FU17: 18.94313 | FV17: 9.8 | FW17: 15.9 | FX17: 116.4916
A18: 13/01/2026 | B18: 04:00 | C18: 198.1 | D18: 622 | E18: 212.2 | H18: 87.5 | I18: 242.2 | L18: 0 | M18: 0 | N18: 202.7 | P18: 0 | R18: 205.7 | S18: 9.7 | X18: 163.2 | Y18: 6.8 | Z18: 5.3 | AA18: 12.8 | AB18: 7.1 | AC18: 13.7 | AD18: 79.8 | AI18: 109.6 | AJ18: 221.6 | AN18: 6.5 | AO18: 459 | AP18: 81 | AR18: 41.2 | AS18: 18.4 | AT18: 16.07179 | AU18: 91 | AV18: 155.1 | AW18: 155.4 | AX18: 175.6 | AY18: 108.7 | AZ18: 0 | BA18: 29.2 | BB18: 2 | BC18: 32.3 | BD18: 149.4 | BG18: 0 | BJ18: 45.9 | BN18: 126.4 | BO18: 169 | BP18: 167.1 | BQ18: 170.9 | BR18: 253.5 | BS18: 72 | BT18: 35.6 | BX18: 0 | CA18: 2 | CB18: 103.8 | CC18: 127.3 | CD18: 64 | CE18: 77.8 | CF18: 29.4 | CG18: 0 | CJ18: 143.7 | CK18: 144.6 | CL18: 148.4 | CT18: 5.9 | CU18: 1.8 | CV18: 20 | CW18: 0 | CX18: 33.1 | CY18: 0 | CZ18: 3.3 | DA18: 0 | DB18: 0 | DC18: 9.8 | DD18: 5.4 | DE18: 0 | DF18: 1.2 | DG18: 3.6 | DH18: 5.2 | DI18: 0 | DJ18: 20 | DK18: 18.3 | DL18: 3.4 | DM18: 18.7 | DN18: 0 | DO18: 0 | DP18: 8.9 | DQ18: 24.2 | DR18: 0 | DS18: 3 | DT18: 5.9 | DU18: 3.04 | DV18: 0 | DW18: 0 | DX18: 19.853 | DY18: 12.808 | DZ18: 19.71 | EA18: 20.19 | EB18: 20 | EC18: 4.9 | ED18: 0 | EE18: 0 | EF18: 12.8 | EG18: 40.5 | EH18: 0.2 | EI18: 0 | EJ18: 0 | EK18: 20.9 | EL18: 7.7 | EM18: 8.9 | EN18: 20.4 | EO18: 20.4 | EP18: 20.1 | EQ18: 2.8 | ER18: 0 | ES18: 0 | ET18: 0 | EU18: 0.6 | EV18: 17.8 | EW18: 18.6 | EX18: 0 | EY18: 3.7 | FA18: 2.2 | FB18: 1 | FC18: 0 | FD18: 8.2 | FE18: 20 | FF18: 9.5 | FG18: 26.9 | FH18: 32.3 | FI18: 13 | FJ18: 18.3 | FK18: 7.82 | FL18: 11.11 | FM18: 22.4 | FN18: 6462.6028 | FP18: 24.49314 | FQ18: 8.1 | FS18: 13.2 | FT18: 26.02214 | FU18: 18.94315 | FV18: 9.9 | FW18: 16 | FX18: 116.65843
A19: 13/01/2026 | B19: 04:30 | C19: 205.2 | D19: 628.4 | E19: 214.5 | H19: 91.4 | I19: 244.8 | L19: 0 | M19: 0 | N19: 201.1 | P19: 0 | R19: 261.5 | S19: 9.8 | X19: 168.6 | Y19: 7.3 | Z19: 5.1 | AA19: 17 | AB19: 6.9 | AC19: 13.7 | AD19: 81 | AI19: 110.7 | AJ19: 221.7 | AN19: 6.5 | AO19: 461.1 | AP19: 81 | AR19: 41.9 | AS19: 18.4 | AT19: 15.668 | AU19: 91 | AV19: 164 | AW19: 164.1 | AX19: 170.8 | AY19: 109 | AZ19: 0 | BA19: 30.8 | BB19: 2 | BC19: 31.5 | BD19: 161 | BG19: 0 | BJ19: 45.3 | BN19: 128.3 | BO19: 168.4 | BP19: 166.5 | BQ19: 170.7 | BR19: 253.8 | BS19: 72.2 | BT19: 35.6 | BX19: 0 | CA19: 2 | CB19: 137.3 | CC19: 132.4 | CD19: 65.8 | CE19: 78.6 | CF19: 30.2 | CG19: 0 | CJ19: 141.5 | CK19: 142.4 | CL19: 146.1 | CT19: 5.8 | CU19: 1.8 | CV19: 20 | CW19: 0 | CX19: 34 | CY19: 0 | CZ19: 2.8 | DA19: 0 | DB19: 0 | DC19: 10 | DD19: 5.5 | DE19: 0 | DF19: 1.2 | DG19: 3.6 | DH19: 5.2 | DI19: 0 | DJ19: 20 | DK19: 18.3 | DL19: 3.4 | DM19: 18.6 | DN19: 0 | DO19: 0 | DP19: 6.9 | DQ19: 18.2 | DR19: 0 | DS19: 2.9 | DT19: 5.8 | DU19: 3.04 | DV19: 0 | DW19: 0 | DX19: 19.859 | DY19: 12.809 | DZ19: 19.87 | EA19: 20.24 | EB19: 20 | EC19: 0.8 | ED19: 0 | EE19: 0 | EF19: 17.8 | EG19: 33.6 | EH19: 1.2 | EI19: 0.3 | EJ19: 0 | EK19: 20.9 | EL19: 7.7 | EM19: 8.9 | EN19: 20.4 | EO19: 20.4 | EP19: 20.1 | EQ19: 2.8 | ER19: 0 | ES19: 0 | ET19: 0 | EU19: 0.6 | EV19: 24 | EW19: 17.1 | EX19: 0 | EY19: 3.7 | FA19: 2.2 | FB19: 1 | FC19: 0 | FD19: 8.2 | FE19: 20 | FF19: 10.6 | FG19: 26.6 | FH19: 32.3 | FI19: 13.4 | FJ19: 18.3 | FK19: 7.89 | FL19: 11.11 | FM19: 22.7 | FN19: 6608.986 | FP19: 24.48691 | FQ19: 8.1 | FS19: 13.2 | FT19: 25.94046 | FU19: 18.94289 | FV19: 9.7 | FW19: 3.7 | FX19: 104.07026
A20: 13/01/2026 | B20: 05:00 | C20: 202.5 | D20: 626.5 | E20: 214 | H20: 89.7 | I20: 246.2 | L20: 0 | M20: 0 | N20: 201.9 | P20: 0 | R20: 305.9 | S20: 9.8 | X20: 166.8 | Y20: 6.9 | Z20: 5.4 | AA20: 16.9 | AB20: 7 | AC20: 13.7 | AD20: 81 | AI20: 110.7 | AJ20: 221.9 | AN20: 6.5 | AO20: 461.2 | AP20: 81 | AR20: 42 | AS20: 18.4 | AT20: 14.51891 | AU20: 89.9 | AV20: 163.4 | AW20: 163.9 | AX20: 170.9 | AY20: 108.9 | AZ20: 0 | BA20: 39.8 | BB20: 2 | BC20: 31.6 | BD20: 159.3 | BG20: 0 | BJ20: 45.6 | BN20: 127.7 | BO20: 167.8 | BP20: 166.6 | BQ20: 170.9 | BR20: 253 | BS20: 72.7 | BT20: 35.7 | BX20: 0 | CA20: 2.1 | CB20: 150.3 | CC20: 131.3 | CD20: 65.4 | CE20: 78.7 | CF20: 30 | CG20: 0 | CJ20: 142 | CK20: 143.8 | CL20: 147.6 | CT20: 5.8 | CU20: 1.8 | CV20: 20 | CW20: 0 | CX20: 29.7 | CY20: 0 | CZ20: 3.9 | DA20: 0 | DB20: 0 | DC20: 9.9 | DD20: 5.4 | DE20: 0 | DF20: 1.2 | DG20: 3.6 | DH20: 5.2 | DI20: 0 | DJ20: 20 | DK20: 18.3 | DL20: 3.4 | DM20: 14.7 | DN20: 0 | DO20: 0 | DP20: 8.9 | DQ20: 19.1 | DR20: 0 | DS20: 2.9 | DT20: 5.6 | DU20: 3.04 | DV20: 0 | DW20: 0 | DX20: 19.863 | DY20: 12.805 | DZ20: 19.89 | EA20: 20.25 | EB20: 20 | EC20: 5.5 | ED20: 0 | EE20: 0 | EF20: 10.2 | EG20: 27.1 | EH20: 0.2 | EI20: 0 | EJ20: 0 | EK20: 20.9 | EL20: 7.8 | EM20: 8.9 | EN20: 20.4 | EO20: 20.4 | EP20: 20.1 | EQ20: 3.7 | ER20: 0 | ES20: 0 | ET20: 0 | EU20: 0.6 | EV20: 13.4 | EW20: 10.5 | EX20: 0 | EY20: 3.7 | FA20: 2.2 | FB20: 1 | FC20: 0 | FD20: 8.2 | FE20: 20 | FF20: 10 | FG20: 25.8 | FH20: 32.1 | FI20: 13.5 | FJ20: 18.9 | FK20: 8.11 | FL20: 11.07 | FM20: 22.4 | FN20: 6633.2469 | FP20: 24.48951 | FQ20: 8.1 | FS20: 13.2 | FT20: 25.88232 | FU20: 18.94289 | FV20: 9.7 | FW20: 3.7 | FX20: 104.01472
A21: 13/01/2026 | B21: 05:30 | C21: 202.4 | D21: 628.1 | E21: 216.4 | H21: 90.2 | I21: 245.4 | L21: 0 | M21: 0 | N21: 200.8 | P21: 0 | R21: 284.7 | S21: 9.7 | X21: 166.3 | Y21: 7.2 | Z21: 5.3 | AA21: 16.9 | AB21: 7.1 | AC21: 13.7 | AD21: 80.7 | AI21: 110.9 | AJ21: 221.4 | AN21: 6.5 | AO21: 461.2 | AP21: 81 | AR21: 41.9 | AS21: 18 | AT21: 13.9109 | AU21: 88.5 | AV21: 161.5 | AW21: 162.2 | AX21: 172.4 | AY21: 108.9 | AZ21: 0 | BA21: 38.1 | BB21: 2 | BC21: 31.5 | BD21: 169.2 | BG21: 32.4 | BJ21: 45.6 | BN21: 127.8 | BO21: 169.5 | BP21: 167.1 | BQ21: 170.3 | BR21: 254.7 | BS21: 72.9 | BT21: 35.8 | BX21: 0 | CA21: 2 | CB21: 137.1 | CC21: 131.8 | CD21: 65.6 | CE21: 78.9 | CF21: 30.2 | CG21: 0 | CJ21: 142.2 | CK21: 143.2 | CL21: 147.4 | CT21: 5.9 | CU21: 1.8 | CV21: 20 | CW21: 0 | CX21: 33.9 | CY21: 0 | CZ21: 3.8 | DA21: 0 | DB21: 0 | DC21: 9.9 | DD21: 5.4 | DE21: 0.5 | DF21: 1.1 | DG21: 3.6 | DH21: 5.1 | DI21: 0 | DJ21: 20 | DK21: 18.3 | DL21: 3.4 | DM21: 11.1 | DN21: 0.5 | DO21: 0.5 | DP21: 9.4 | DQ21: 17.3 | DR21: 0 | DS21: 3.2 | DT21: 5.7 | DU21: 3.04 | DV21: 0 | DW21: 0 | DX21: 19.863 | DY21: 12.815 | DZ21: 19.99 | EA21: 20.27 | EB21: 20 | EC21: 5.2 | ED21: 0 | EE21: 0.1 | EF21: 6.7 | EG21: 23.6 | EH21: 0 | EI21: 0 | EJ21: 0 | EK21: 20.9 | EL21: 7.8 | EM21: 8.9 | EN21: 20.4 | EO21: 20.4 | EP21: 20.1 | EQ21: 3 | ER21: 0.3 | ES21: 0 | ET21: 1.6 | EU21: 0.6 | EV21: 16.7 | EW21: 18.2 | EX21: 1.3 | EY21: 3.7 | FA21: 2.2 | FB21: 1 | FC21: 0 | FD21: 8.1 | FE21: 20 | FF21: 9.8 | FG21: 26.6 | FH21: 31.8 | FI21: 14 | FJ21: 18.8 | FK21: 8.02 | FL21: 11.07 | FM21: 22.1 | FN21: 6647.8789 | FP21: 24.47663 | FQ21: 8 | FS21: 13.2 | FT21: 25.85952 | FU21: 18.9428 | FV21: 9.7 | FW21: 3.8 | FX21: 103.97895
A22: 13/01/2026 | B22: 06:00 | C22: 198.1 | D22: 622.5 | E22: 214 | H22: 87.5 | I22: 243.4 | L22: 0 | M22: 0 | N22: 202.5 | P22: 0 | R22: 433.5 | S22: 9.7 | X22: 165.2 | Y22: 6.5 | Z22: 5.2 | AA22: 16.9 | AB22: 7.1 | AC22: 13.7 | AD22: 59.5 | AI22: 109.5 | AJ22: 220.9 | AN22: 6.5 | AO22: 457.3 | AP22: 81 | AR22: 41.3 | AS22: 18.4 | AT22: 13.87155 | AU22: 91.5 | AV22: 148.4 | AW22: 148.7 | AX22: 167.1 | AY22: 107.5 | AZ22: 0 | BA22: 37.1 | BB22: 2 | BC22: 31.2 | BD22: 169.8 | BG22: 29.4 | BJ22: 45.5 | BN22: 83.3 | BO22: 147.8 | BP22: 147.6 | BQ22: 146.7 | BR22: 240.1 | BS22: 72.9 | BT22: 35.7 | BX22: 0 | CA22: 2 | CB22: 70.7 | CC22: 115.5 | CD22: 64.1 | CE22: 77.7 | CF22: 29.5 | CG22: 0 | CJ22: 142 | CK22: 143 | CL22: 147.1 | CT22: 5.6 | CU22: 1.8 | CV22: 19.8 | CW22: 0 | CX22: 26.4 | CY22: 6 | CZ22: 4.6 | DA22: 0 | DB22: 0 | DC22: 9.9 | DD22: 5.4 | DE22: 19.1 | DF22: 1.1 | DG22: 3.6 | DH22: 5.1 | DI22: 0 | DJ22: 20 | DK22: 18.3 | DL22: 3.4 | DM22: 11.3 | DN22: 0.9 | DO22: 1.3 | DP22: 13.3 | DQ22: 15.8 | DR22: 0.2 | DS22: 3.2 | DT22: 10.7 | DU22: 3 | DV22: 0 | DW22: 0 | DX22: 19.878 | DY22: 12.801 | DZ22: 20.12 | EA22: 20.24 | EB22: 19.9 | EC22: 4.9 | ED22: 0 | EE22: 1.4 | EF22: 5.7 | EG22: 22.3 | EH22: 0 | EI22: 0 | EJ22: 0.5 | EK22: 20.9 | EL22: 7.8 | EM22: 8.9 | EN22: 20.4 | EO22: 20.4 | EP22: 20.1 | EQ22: 3.1 | ER22: 15.7 | ES22: 0 | ET22: 13.8 | EU22: 0.6 | EV22: 20.5 | EW22: 27.8 | EX22: 10.9 | EY22: 3.7 | FA22: 2.2 | FB22: 1 | FC22: 0.6 | FD22: 8.2 | FE22: 20 | FF22: 9.9 | FG22: 27.1 | FH22: 32.3 | FI22: 14 | FJ22: 19.4 | FK22: 8.07 | FL22: 11.09 | FM22: 17.4 | FN22: 6581.3705 | FP22: 24.4737 | FQ22: 8 | FS22: 13.2 | FT22: 26.00929 | FU22: 18.94268 | FV22: 9.6 | FW22: 3.8 | FX22: 104.02567
... A58: 14/01/2026 | B58: 00:00 | C58: 200.3 | D58: 626.8 | E58: 214.8 | H58: 90.8 | I58: 243 | L58: 0 | M58: 204.4 | N58: 202.3 | P58: 208.8 | R58: 370.5 | S58: 9.5 | X58: 163.9 | Y58: 7.5 | Z58: 5.2 | AA58: 16.9 | AB58: 7.1 | AC58: 13.6 | AD58: 65.9 | AI58: 110.6 | AJ58: 220.8 | AN58: 6.5 | AO58: 452.8 | AP58: 45.7 | AR58: 0 | AS58: 18.4 | AT58: 16.56065 | AU58: 95.6 | AV58: 180 | AW58: 180.8 | AX58: 185.2 | AY58: 109.3 | AZ58: 17.4 | BA58: 46 | BB58: 2 | BC58: 31.3 | BD58: 134.4 | BG58: 41.9 | BJ58: 45.6 | BN58: 127 | BO58: 160.5 | BP58: 160.5 | BQ58: 161 | BR58: 238.7 | BS58: 73.9 | BT58: 36 | BX58: 26.1 | CA58: 2 | CB58: 131.4 | CC58: 134 | CD58: 62.8 | CE58: 78.2 | CF58: 29.8 | CG58: 0 | CJ58: 142.5 | CK58: 143.8 | CL58: 148 | CT58: 5.8 | CU58: 1.8 | CV58: 20 | CW58: 0 | CX58: 11.4 | CY58: 0 | CZ58: 0 | DA58: 0 | DB58: 20.2 | DC58: 9.9 | DD58: 5.5 | DE58: 0 | DF58: 1.9 | DG58: 3.5 | DH58: 5.1 | DI58: 20.2 | DJ58: 20 | DK58: 18.7 | DL58: 3.5 | DM58: 18.5 | DN58: 0 | DO58: 0 | DP58: 2.1 | DQ58: 2.3 | DR58: 0 | DS58: 3.3 | DT58: 16.5 | DU58: 2.96 | DV58: 0.4 | DW58: 0 | DX58: 19.886 | DY58: 12.519 | DZ58: 20.22 | EA58: 20.18 | EB58: 20 | EC58: 3.2 | ED58: 2 | EE58: 0 | EF58: 12 | EG58: 0 | EH58: 0.9 | EI58: 0.3 | EJ58: 0 | EK58: 20.9 | EL58: 8.3 | EM58: 0 | EN58: 20.4 | EO58: 20.4 | EP58: 20.1 | EQ58: 0.4 | ER58: 0 | ES58: 0 | ET58: 0 | EU58: 0.6 | EV58: 8.6 | EW58: 4.6 | EX58: 0 | EY58: 3.7 | FA58: 2.2 | FB58: 1 | FC58: 0 | FD58: 8.2 | FE58: 20 | FF58: 8.9 | FG58: 26.7 | FH58: 31.7 | FI58: 14.4 | FJ58: 19.1 | FK58: 8.27 | FL58: 11.31 | FM58: 23.4 | FN58: 7036.3057 | FP58: 24.49031 | FQ58: 8.1 | FS58: 13.2 | FT58: 25.76022 | FU58: 18.94382 | FV58: 9.7 | FW58: 3.7 | FX58: 103.89435
A59: EJEC | C59: 4853.8 | D59: 15053.75 | E59: 5155.95 | F59: 0 | G59: 0 | H59: 2158.4 | I59: 5746.45 | J59: 0 | K59: 0 | L59: 2159.2 | M59: 3238.85 | N59: 4795.35 | O59: 0 | P59: 3153.15 | Q59: 0 | R59: 8340.75 | S59: 230.05 | T59: 0 | U59: 0 | V59: 0 | W59: 0 | X59: 3990.55 | Y59: 189.25 | Z59: 132.9 | AA59: 338.85 | AB59: 168.55 | AC59: 324.8 | AD59: 2008.55 | AE59: 0 | AF59: 0 | AG59: 0 | AH59: 0 | AI59: 2653.45 | AJ59: 5314 | AK59: 0 | AL59: 0 | AM59: 0 | AN59: 156 | AO59: 10988 | AP59: 1017.8 | AQ59: 0 | AR59: 274.55 | AS59: 436.3 | AT59: 361.13256 | AU59: 2172.9 | AV59: 3869.35 | AW59: 3879.25 | AX59: 4166.5 | AY59: 2608.05 | AZ59: 275.8 | BA59: 969.5 | BB59: 50.25 | BC59: 754.45 | BD59: 3622.2 | BE59: 0 | BF59: 0 | BG59: 855.4 | BH59: 0 | BI59: 0 | BJ59: 1086.15 | BK59: 0 | BL59: 0 | BM59: 0 | BN59: 2595.1 | BO59: 3830.95 | BP59: 3811.15 | BQ59: 3863.3 | BR59: 5886.65 | BS59: 1735.35 | BT59: 848.25 | BU59: 0 | BV59: 0 | BW59: 0 | BX59: 433.3 | BY59: 0 | BZ59: 0 | CA59: 48.25 | CB59: 3482.5 | CC59: 3008.1 | CD59: 1536.75 | CE59: 1885.1 | CF59: 721.35 | CG59: 899.75 | CH59: 0 | CI59: 0 | CJ59: 3384.6 | CK59: 3405.95 | CL59: 3848.6 | CM59: 0 | CN59: 0 | CO59: 0 | CP59: 0 | CQ59: 0 | CR59: 0 | CS59: 0 | CT59: 141.1 | CU59: 42.9 | CV59: 480.05 | CW59: 2.5 | CX59: 876.2 | CY59: 593 | CZ59: 95.95 | DA59: 0.95 | DB59: 236.45 | DC59: 237.7 | DD59: 130.05 | DE59: 1577.8 | DF59: 38.55 | DG59: 85 | DH59: 122.95 | DI59: 232.9 | DJ59: 479.7 | DK59: 434.55 | DL59: 82 | DM59: 417.05 | DN59: 118.95 | DO59: 157 | DP59: 201.65 | DQ59: 571 | DR59: 97.3 | DS59: 72.85 | DT59: 304 | DU59: 72.22 | DV59: 5.4 | DW59: 1.85 | DX59: 397.313 | DY59: 307.279 | DZ59: 483.145 | EA59: 485.2 | EB59: 479.7 | EC59: 82.5 | ED59: 188.2 | EE59: 228.6 | EF59: 658.45 | EG59: 1124.55 | EH59: 83.5 | EI59: 48.85 | EJ59: 297.05 | EK59: 446.85 | EL59: 192.8 | EM59: 190.25 | EN59: 489.6 | EO59: 489.6 | EP59: 482.4 | EQ59: 84.25 | ER59: 1812.05 | ES59: 117.9 | ET59: 1088.05 | EU59: 14.4 | EV59: 712.35 | EW59: 651.4 | EX59: 867.9 | EY59: 75.05 | EZ59: 0 | FA59: 52.8 | FB59: 24 | FC59: 75.85 | FD59: 196.2 | FE59: 479.9 | FF59: 204.55 | FG59: 642 | FH59: 772.35 | FI59: 320.7 | FJ59: 456.45 | FK59: 166.145 | FL59: 269.765 | FM59: 556 | FN59: 177480.65 | FP59: 586.62413 | FQ59: 194.2 | FR59: 0 | FS59: 316.8 | FT59: 617.04489 | FU59: 454.69673 | FV59: 228 | FW59: 194.75 | FX59: 2592.1158

Sheet REACTIVA
B3: martes, 13 de Enero del 2026
A5: POTENCIA REACTIVA EJECUTADA DE LAS UNIDADES DE GENERACIÓN DEL COES (MVAR) | FP5: CENTRALES NO INTEGRANTES COES
A6: FECHA | B6: HORA | C6: 65333 | D6: 101 | E6: 102 | F6: 42667 | G6: 42668 | H6: 126 | I6: 127 | J6: 138 | K6: 139 | L6: 197 | M6: 203 | N6: 204 | O6: 230 | P6: 209 | Q6: 56677 | R6: 796 | S6: 2146 | T6: 142 | U6: 143 | V6: 125 | W6: 187 | X6: 163 | Y6: 298 | Z6: 299 | AA6: 219 | AB6: 151 | AC6: 152 | AD6: 153 | AE6: 154 | AF6: 756 | AG6: 156 | AH6: 155 | AI6: 182 | AJ6: 212 | AK6: 758 | AL6: 263 | AM6: 265 | AN6: 775 | AO6: 777 | AP6: 2154 | AQ6: 150 | AR6: 149 | AS6: 188 | AT6: 2131 | AU6: 755 | AV6: 252 | AW6: 249 | AX6: 250 | AY6: 117 | AZ6: 119 | BA6: 120 | BB6: 189 | BC6: 122 | BD6: 266 | BE6: 337 | BF6: 338 | BG6: 251 | BH6: 115 | BI6: 239 | BJ6: 288 | BK6: 240 | BL6: 241 | BM6: 242 | BN6: 191 | BO6: 194 | BP6: 196 | BQ6: 207 | BR6: 236 | BS6: 795 | BT6: 285 | BU6: 995 | BV6: 996 | BW6: 997 | BX6: 766 | BY6: 926 | BZ6: 924 | CA6: 121 | CB6: 103 | CC6: 104 | CD6: 106 | CE6: 105 | CF6: 107 | CG6: 110 | CH6: 109 | CI6: 144 | CJ6: 113 | CK6: 114 | CL6: 193 | CM6: 208 | CN6: 786 | CO6: 787 | CP6: 788 | CQ6: 789 | CR6: 248 | CS6: 2159 | CT6: 267 | CU6: 268 | CV6: 2194 | CW6: 303 | CX6: 59715 | CY6: 62255 | CZ6: 1263 | DA6: 61800 | DB6: 69125 | DC6: 216 | DD6: 198 | DE6: 70400 | DF6: 49607 | DG6: 214 | DH6: 260 | DI6: 2152 | DJ6: 2128 | DK6: 247 | DL6: 228 | DM6: 2135 | DN6: 261 | DO6: 237 | DP6: 253 | DQ6: 770 | DR6: 235 | DS6: 238 | DT6: 2184 | DU6: 61855 | DV6: 223 | DW6: 75566 | DX6: 226 | DY6: 201 | DZ6: 258 | EA6: 259 | EB6: 920 | EC6: 257 | ED6: 256 | EE6: 2148 | EF6: 58288 | EG6: 58289 | EH6: 58839 | EI6: 58840 | EJ6: 75260 | EK6: 296 | EL6: 297 | EM6: 211 | EN6: 2175 | EO6: 2178 | EP6: 2181 | EQ6: 1262 | ER6: 63425 | ES6: 233 | ET6: 2150 | EU6: 2165 | EV6: 2161 | EW6: 61197 | EX6: 58851 | EY6: 225 | EZ6: 2201 | FA6: 2171 | FB6: 760 | FC6: 234 | FD6: 215 | FE6: 917 | FF6: 289 | FG6: 58333 | FH6: 58336 | FI6: 213 | FJ6: 232 | FK6: 2190 | FL6: 69867 | FM6: 75066 | FN6: TOTAL COES | FP6: 221 | FQ6: 222 | FR6: 224 | FS6: 2187 | FT6: 227 | FU6: 49400 | FV6: 199 | FW6: 200 | FX6: TOTAL NO COES
C7: SUR | D7: CENTRO | E7: CENTRO | F7: NORTE | G7: NORTE | H7: NORTE | I7: NORTE | J7: CENTRO | K7: CENTRO | L7: CENTRO | M7: CENTRO | N7: CENTRO | O7: CENTRO | P7: CENTRO | Q7: CENTRO | R7: CENTRO | S7: CENTRO | T7: CENTRO | U7: CENTRO | V7: CENTRO | W7: CENTRO | X7: SUR | Y7: SUR | Z7: SUR | AA7: CENTRO | AB7: SUR | AC7: SUR | AD7: SUR | AE7: SUR | AF7: SUR | AG7: SUR | AH7: SUR | AI7: SUR | AJ7: CENTRO | AK7: NORTE | AL7: NORTE | AM7: NORTE | AN7: CENTRO | AO7: CENTRO | AP7: CENTRO | AQ7: CENTRO | AR7: CENTRO | AS7: CENTRO | AT7: CENTRO | AU7: SUR | AV7: CENTRO | AW7: CENTRO | AX7: CENTRO | AY7: CENTRO | AZ7: CENTRO | BA7: CENTRO | BB7: SUR | BC7: NORTE | BD7: CENTRO | BE7: CENTRO | BF7: CENTRO | BG7: CENTRO | BH7: NORTE | BI7: NORTE | BJ7: NORTE | BK7: SUR | BL7: SUR | BM7: SUR | BN7: CENTRO | BO7: CENTRO | BP7: CENTRO | BQ7: CENTRO | BR7: CENTRO | BS7: CENTRO | BT7: CENTRO | BU7: SUR | BV7: SUR | BW7: SUR | BX7: NORTE | BY7: SUR | BZ7: CENTRO | CA7: NORTE | CB7: CENTRO | CC7: CENTRO | CD7: CENTRO | CE7: CENTRO | CF7: CENTRO | CG7: CENTRO | CH7: CENTRO | CI7: CENTRO | CJ7: CENTRO | CK7: CENTRO | CL7: CENTRO | CM7: CENTRO | CN7: SUR | CO7: SUR | CP7: SUR | CQ7: SUR | CR7: CENTRO | CS7: CENTRO | CT7: CENTRO | CU7: CENTRO | CV7: NORTE | CW7: CENTRO | CX7: CENTRO | CY7: SUR | CZ7: NORTE | DA7: NORTE | DB7: CENTRO | DC7: NORTE | DD7: NORTE | DE7: SUR | DF7: SUR | DG7: CENTRO | DH7: CENTRO | DI7: CENTRO | DJ7: NORTE | DK7: NORTE | DL7: CENTRO | DM7: CENTRO | DN7: SUR | DO7: SUR | DP7: CENTRO | DQ7: CENTRO | DR7: SUR | DS7: CENTRO | DT7: CENTRO | DU7: NORTE | DV7: CENTRO | DW7: CENTRO | DX7: CENTRO | DY7: NORTE | DZ7: CENTRO | EA7: CENTRO | EB7: CENTRO | EC7: NORTE | ED7: NORTE | EE7: SUR | EF7: CENTRO | EG7: CENTRO | EH7: CENTRO | EI7: CENTRO | EJ7: SUR | EK7: CENTRO | EL7: CENTRO | EM7: SUR | EN7: SUR | EO7: SUR | EP7: SUR | EQ7: NORTE | ER7: SUR | ES7: SUR | ET7: SUR | EU7: CENTRO | EV7: CENTRO | EW7: CENTRO | EX7: SUR | EY7: CENTRO | EZ7: CENTRO | FA7: CENTRO | FB7: CENTRO | FC7: SUR | FD7: NORTE | FE7: CENTRO | FF7: NORTE | FG7: NORTE | FH7: NORTE | FI7: CENTRO | FJ7: NORTE | FK7: NORTE | FL7: NORTE | FM7: NORTE | FP7: NORTE | FQ7: CENTRO | FR7: NORTE | FS7: NORTE | FT7: NORTE | FU7: NORTE | FV7: NORTE | FW7: NORTE
C8: HIDROELÉCTRICA | D8: HIDROELÉCTRICA | E8: HIDROELÉCTRICA | F8: TERMOELÉCTRICA | G8: TERMOELÉCTRICA | H8: HIDROELÉCTRICA | I8: HIDROELÉCTRICA | J8: TERMOELÉCTRICA | K8: TERMOELÉCTRICA | L8: TERMOELÉCTRICA | M8: TERMOELÉCTRICA | N8: TERMOELÉCTRICA | O8: TERMOELÉCTRICA | P8: TERMOELÉCTRICA | Q8: TERMOELÉCTRICA | R8: HIDROELÉCTRICA | S8: HIDROELÉCTRICA | T8: TERMOELÉCTRICA | U8: TERMOELÉCTRICA | V8: TERMOELÉCTRICA | W8: TERMOELÉCTRICA | X8: HIDROELÉCTRICA | Y8: HIDROELÉCTRICA | Z8: HIDROELÉCTRICA | AA8: TERMOELÉCTRICA | AB8: HIDROELÉCTRICA | AC8: HIDROELÉCTRICA | AD8: HIDROELÉCTRICA | AE8: HIDROELÉCTRICA | AF8: TERMOELÉCTRICA | AG8: TERMOELÉCTRICA | AH8: TERMOELÉCTRICA | AI8: HIDROELÉCTRICA | AJ8: HIDROELÉCTRICA | AK8: TERMOELÉCTRICA | AL8: TERMOELÉCTRICA | AM8: TERMOELÉCTRICA | AN8: HIDROELÉCTRICA | AO8: HIDROELÉCTRICA | AP8: HIDROELÉCTRICA | AQ8: HIDROELÉCTRICA | AR8: HIDROELÉCTRICA | AS8: HIDROELÉCTRICA | AT8: HIDROELÉCTRICA | AU8: HIDROELÉCTRICA | AV8: TERMOELÉCTRICA | AW8: TERMOELÉCTRICA | AX8: TERMOELÉCTRICA | AY8: HIDROELÉCTRICA | AZ8: HIDROELÉCTRICA | BA8: HIDROELÉCTRICA | BB8: HIDROELÉCTRICA | BC8: HIDROELÉCTRICA | BD8: HIDROELÉCTRICA | BE8: HIDROELÉCTRICA | BF8: HIDROELÉCTRICA | BG8: HIDROELÉCTRICA | BH8: TERMOELÉCTRICA | BI8: TERMOELÉCTRICA | BJ8: TERMOELÉCTRICA | BK8: TERMOELÉCTRICA | BL8: TERMOELÉCTRICA | BM8: TERMOELÉCTRICA | BN8: HIDROELÉCTRICA | BO8: TERMOELÉCTRICA | BP8: TERMOELÉCTRICA | BQ8: TERMOELÉCTRICA | BR8: TERMOELÉCTRICA | BS8: TERMOELÉCTRICA | BT8: TERMOELÉCTRICA | BU8: TERMOELÉCTRICA | BV8: TERMOELÉCTRICA | BW8: TERMOELÉCTRICA | BX8: HIDROELÉCTRICA | BY8: TERMOELÉCTRICA | BZ8: TERMOELÉCTRICA | CA8: HIDROELÉCTRICA | CB8: HIDROELÉCTRICA | CC8: HIDROELÉCTRICA | CD8: HIDROELÉCTRICA | CE8: HIDROELÉCTRICA | CF8: HIDROELÉCTRICA | CG8: TERMOELÉCTRICA | CH8: TERMOELÉCTRICA | CI8: TERMOELÉCTRICA | CJ8: TERMOELÉCTRICA | CK8: TERMOELÉCTRICA | CL8: TERMOELÉCTRICA | CM8: TERMOELÉCTRICA | CN8: TERMOELÉCTRICA | CO8: TERMOELÉCTRICA | CP8: TERMOELÉCTRICA | CQ8: TERMOELÉCTRICA | CR8: TERMOELÉCTRICA | CS8: TERMOELÉCTRICA | CT8: HIDROELÉCTRICA | CU8: HIDROELÉCTRICA | CV8: HIDROELÉCTRICA | CW8: SOLAR | CX8: EÓLICA | CY8: SOLAR | CZ8: EÓLICA | DA8: SOLAR | DB8: HIDROELÉCTRICA | DC8: HIDROELÉCTRICA | DD8: HIDROELÉCTRICA | DE8: SOLAR | DF8: HIDROELÉCTRICA | DG8: HIDROELÉCTRICA | DH8: HIDROELÉCTRICA | DI8: HIDROELÉCTRICA | DJ8: HIDROELÉCTRICA | DK8: HIDROELÉCTRICA | DL8: HIDROELÉCTRICA | DM8: HIDROELÉCTRICA | DN8: SOLAR | DO8: SOLAR | DP8: EÓLICA | DQ8: EÓLICA | DR8: SOLAR | DS8: HIDROELÉCTRICA | DT8: HIDROELÉCTRICA | DU8: HIDROELÉCTRICA | DV8: HIDROELÉCTRICA | DW8: SOLAR | DX8: HIDROELÉCTRICA | DY8: HIDROELÉCTRICA | DZ8: HIDROELÉCTRICA | EA8: HIDROELÉCTRICA | EB8: HIDROELÉCTRICA | EC8: EÓLICA | ED8: EÓLICA | EE8: SOLAR | EF8: EÓLICA | EG8: EÓLICA | EH8: EÓLICA | EI8: EÓLICA | EJ8: SOLAR | EK8: HIDROELÉCTRICA | EL8: HIDROELÉCTRICA | EM8: HIDROELÉCTRICA | EN8: HIDROELÉCTRICA | EO8: HIDROELÉCTRICA | EP8: HIDROELÉCTRICA | EQ8: EÓLICA | ER8: SOLAR | ES8: SOLAR | ET8: SOLAR | EU8: HIDROELÉCTRICA | EV8: EÓLICA | EW8: EÓLICA | EX8: SOLAR | EY8: TERMOELÉCTRICA | EZ8: TERMOELÉCTRICA | FA8: TERMOELÉCTRICA | FB8: TERMOELÉCTRICA | FC8: SOLAR | FD8: HIDROELÉCTRICA | FE8: HIDROELÉCTRICA | FF8: TERMOELÉCTRICA | FG8: TERMOELÉCTRICA | FH8: TERMOELÉCTRICA | FI8: TERMOELÉCTRICA | FJ8: TERMOELÉCTRICA | FK8: TERMOELÉCTRICA | FL8: TERMOELÉCTRICA | FM8: TERMOELÉCTRICA | FP8: HIDROELÉCTRICA | FQ8: HIDROELÉCTRICA | FR8: HIDROELÉCTRICA | FS8: HIDROELÉCTRICA | FT8: TERMOELÉCTRICA | FU8: TERMOELÉCTRICA | FV8: HIDROELÉCTRICA | FW8: HIDROELÉCTRICA
