Workbook

Sheet EVENTOS
B3: sábado, 21 de Febrero del 2026
B5: INFORMACIÓN DE EVENTOS PRINCIPALES EN SUS INSTALACIONES
B6: TIPO DE EVENTO | C6: EMPRESA | D6: UBICACIÓN | E6: TIPO DE EQUIPO | F6: EQUIPO | G6: INICIO | H6: FINAL | I6: DESCRIPCIÓN | J6: MW INDISP. | K6: INTERRUPCIÓN (SI/NO) | L6: TENSIÓN DE FALLA (kV)
B7: EVENTO | C7: STATKRAFT S.A | D7: MISAPUQUIO | E7: CENTRAL HIDROELÉCTRICA | F7: CENTRAL | G7: 21/02/2026 18:52:00 | H7: 21/02/2026 18:56:00 | I7: DESCONECTÓ LA LINEA L-1040 (CALLALLI - TALTA) DE 138 KV | K7: SI
B8: EVENTO | C8: CONELSUR LT SAC | D8: PORTILLO | E8: CELDA | F8: ACOPLE 60 | G8: 21/02/2026 00:00:00 | H8: 22/02/2026 00:00:00 | I8: DECLARACIÓN DE SITUACIÓN EXCEPCIONAL EN LA S.E. PORTILLO 60 kV | K8: NO
B9: EVENTO | C9: EGESUR | D9: INDEPENDENCIA | E9: GENERADOR TERMOELÉCTRICO | F9: INDEP_G2 | G9: 21/02/2026 20:43:00 | H9: 21/02/2026 20:43:00 | I9: DESCONEXIÓN DEL GENERADOR G2 DE LA C.T. INDEPENDENCIA POR FALLA | K9: NO
B10: FALLA | C10: ELECTRO PUNO | D10: PUNO - POMATA - ILAVE | E10: LINEA DE TRANSMISION | F10: L-6027 | G10: 21/02/2026 02:12:00 | H10: 21/02/2026 02:14:00 | I10: DESCONEXIÓN DE LA LINEA L-6027 (PUNO - ILAVE - POMATA) DE 60 KV | K10: SI | L10: 60
B11: FALLA | C11: ORYGEN PERU S.A.A. | D11: HUINCO | E11: GENERADOR HIDROELÉCTRICO | F11: G1 | G11: 21/02/2026 05:42:00 | H11: 21/02/2026 10:37:00 | I11: DESCONEXIÓN DEL GENERADOR G1 DE LA C.H. HUINCO | K11: NO | L11: 12.5
B12: FALLA | C12: SEAL | D12: CAMANA - LA HUERTA | E12: LINEA DE TRANSMISION | F12: L-1057 | G12: 21/02/2026 05:48:28 | H12: 21/02/2026 06:01:11 | I12: DESCONEXIÓN DE LA LÍNEA L-1057 (CAMANÁ - LA HUERTA) DE 138 KV | K12: SI | L12: 138
B13: FALLA | C13: STATKRAFT S.A | D13: MISAPUQUIO | E13: GENERADOR HIDROELÉCTRICO | F13: G2 | G13: 21/02/2026 13:17:00 | H13: 21/02/2026 13:17:00 | I13: DESCEONEXIÓN DEL GENERADOR G2 DE LA C.H. MISAPUQUIO POR FALLA | K13: NO | L13: 0

Sheet RESTRIC_OPE
B3: sábado, 21 de Febrero del 2026
B5: RESTRICCIONES OPERATIVAS
B6: FECHA | C6: HORA INICIO | D6: HORA FINAL | E6: EMPRESA | F6: UBICACIÓN | G6: T.Eq. | H6: EQUIPO | I6: DESCRIPCIÓN
B7: 21/02/2026 | C7: 00:00 | D7: 24:00 | E7: CELEPSA | F7: C.H. EL PLATANAL | G7: CH | H7: CENTRAL | I7: De acuerdo con lo informado por CELEPSA mediante correo el dia 17.01, declaran que la CH Platanal se encontrará de pasada.
B8: 21/02/2026 | C8: 00:00 | D8: 24:00 | E8: EGASA | F8: S.E. CONVERTIDOR | G8: BARRA | H8: BARRA138KV | I8: EGASA limitó la capacidad del transformador 138 kV/33 kV a 50 MVA por deterioro del aislamiento.
B9: 21/02/2026 | C9: 00:00 | D9: 24:00 | E9: ELECTROPERU | F9: C.H. MANTARO | G9: CH | H9: CENTRAL | I9: De acuerdo con el correo del día 25.08.2025, la central tiene una limitación de potencia máxima de 650 MW por seguridad de la central.
B10: 21/02/2026 | C10: 00:00 | D10: 24:00 | E10: ENEL GENERACION PIURA S.A. | F10: C.T. MALACAS | G10: CT | H10: CENTRAL | I10: De acuerdo con la comunicación vía correo del día 24.10.2024. ENEL GENERACIÓN PIURA informa una restricción de potencia para alcanzar 105 MW en simultaneo (TG6+TGN4).
B11: 21/02/2026 | C11: 00:00 | D11: 24:00 | E11: ENEL GENERACION PIURA S.A. | F11: C.T. MALACAS | G11: GT | H11: TG4 | I11: De acuerdo a lo informado por correo electrónico el día 16.01, con la disponibilidad de aproximadamente 12 MMPCD (339.8Mm³) la unidad TG4 puede con una generación de 80 MW durante 4 horas, y a potencia mínima durante el resto de los periodos
B12: 21/02/2026 | C12: 00:00 | D12: 24:00 | E12: ENGIE ENERGIA PERU S.A.A. | F12: C.H. YUNCÁN | G12: GH | H12: G3 | I12: Según la carta N° ENG/ 198-2024 enviada por su representada, se opera de forma continua el G3 de la CH Yuncán, debido a la ejecución de mantenimientos necesarios para evitar daños en los sellos de seguridad de la válvula esférica del grupo.
B13: 21/02/2026 | C13: 00:00 | D13: 24:00 | E13: ENGIE ENERGIA PERU S.A.A. | F13: C.T. CHILCA 1 | G13: CT | H13: CENTRAL | I13: Con carta ENG/971-2023, indica que no puede cumplir con las IO considerada en el PDO_17122023 dado que vulneran la seguridad de sus activos. Indican que se debe tomar TMO=168h.
B14: 21/02/2026 | C14: 00:00 | D14: 24:00 | E14: ENGIE ENERGIA PERU S.A.A. | F14: C.T. CHILCA 1 | G14: CT | H14: CENTRAL | I14: Restricción de temperatura de la C.T Chilca, ver valor en el modelo de despacho.
B15: 21/02/2026 | C15: 00:00 | D15: 24:00 | E15: ENGIE ENERGIA PERU S.A.A. | F15: C.T. CHILCA 2 | G15: CT | H15: CENTRAL | I15: Con carta ENG/971-2023, indica que no puede cumplir con las IO considerada en el PDO_17122023 dado que vulneran la seguridad de sus activos. Indican que se debe tomar TMO=168h.
B16: 21/02/2026 | C16: 00:00 | D16: 24:00 | E16: FENIX POWER PERÚ | F16: C.T. FENIX | G16: CT | H16: CENTRAL | I16: De acuerdo con lo comunicado en el correo del día 06.05.2025, la CT Fenix cuenta con TMO de 168 hrs en todos sus modos de operación.
B17: 21/02/2026 | C17: 00:00 | D17: 24:00 | E17: KALLPA GENERACION S.A. | F17: C.H. CERRO DEL AGUILA | G17: GH | H17: G1 | I17: De acuerdo a lo informado el día 17/11 por la empresa KALLPA, el G1 tiene un TA = 15min
... B59: 21/02/2026 | C59: 00:00 | D59: 24:00 | E59: TERMOSELVA | F59: C.T. AGUAYTÍA | G59: CT | H59: CENTRAL | I59: Disponibilidad de 23.5 MMSCF para la CT Aguaytía.

Sheet MANTENIMIENTO EJECUTADOS
B3: sábado, 21 de Febrero del 2026
B5: Mantenimiento Ejecutado
B6: Empresa | C6: Ubicación | D6: Equipo | E6: Inicio | F6: Final | G6: Descripción | H6: MW Indisp. | I6: Prog. | J6: Dispon | K6: Interrupc. | L6: Tipo | M6: CodEq | N6: TipoEq_Osinerg
B7: ATLANTICA TRANSMISION SUR S.A. | C7: OCONA | D7: INT-5450 | E7: 21/02/2026 00:00 | F7: 22/02/2026 00:00 | G7: Interruptor INT-5450 cerrado con restriccion operativa, REB-5450 en servicio y suministrando los SS.AA. de la S.E. Oco?a. | H7: 0 | I7: P | J7: E/S | K7: N | L7: OTROS | M7: 13761 | N7: T
B8: ATLANTICA TRANSMISION SUR S.A. | C8: POROMA | D8: REB-5350 | E8: 21/02/2026 00:00 | F8: 22/02/2026 00:00 | G8: Fuera de servicio por falla en el equipo. | H8: 0 | I8: P | J8: F/S | K8: N | L8: OTROS | M8: 13771 | N8: T
B9: ATN S.A. | C9: KIMAN AYLLU | D9: AUT-501 | E9: 21/02/2026 00:00 | F9: 22/02/2026 00:00 | G9: Restriccion Operativa en el circuito de control de cambiador de tap s del AUT-501 | H9: 0 | I9: P | J9: E/S | K9: N | L9: OTROS | M9: 13099 | N9: T
B10: CONELSUR LT SAC | C10: CAJAMARQUILLA | D10: BARRA A 220kV | E10: 21/02/2026 00:00 | F10: 22/02/2026 00:00 | G10: NO SE PUEDE INDISPONER LA BARRA A POR RESTRICCION OPERATIVA DEL SECCIONADOR DE BARRA B DE LA CL-TR1 | H10: 0 | I10: P | J10: E/S | K10: N | L10: OTROS | M10: 1103 | N10: T
B11: CONELSUR LT SAC | C11: CAJAMARQUILLA | D11: CL-TRAFO | E11: 21/02/2026 00:00 | F11: 22/02/2026 00:00 | G11: INDISPONIBLE SECCIONADOR DE BARRA B SB-20011 DE CL-TR1 | H11: 0 | I11: F | J11: E/S | K11: N | L11: OTROS | M11: 1906 | N11: T
B12: CONELSUR LT SAC | C12: CALLAHUANCA (CNS) | D12: CL-2008 | E12: 21/02/2026 00:00 | F12: 22/02/2026 00:00 | G12: RELE DE RESPALDO INOPERATIVO | H12: 0 | I12: F | J12: E/S | K12: N | L12: OTROS | M12: 1337 | N12: T
B13: CONELSUR LT SAC | C13: CALLAHUANCA (CNS) | D13: S.E. | E13: 21/02/2026 00:00 | F13: 22/02/2026 00:00 | G13: RELE DIFERENCIAL DE BARRAS DE CALLAHUANCA 220KV INOPERATIVO | H13: 0 | I13: P | J13: E/S | K13: N | L13: OTROS | M13: 316 | N13: T
B14: CONELSUR LT SAC | C14: HUAMPANI | D14: S.E. | E14: 21/02/2026 00:18 | F14: 21/02/2026 00:32 | G14: NO FUE NECESARIO DEJAR FUERA DE SERVICIO LA SUBESTACION PARA LA ACTIVIDAD DE DESHABILITAR SISTEMA DE PROTECCION Y CONTROL DE LAS CELDAS 6544, 6040, T1 Y T4, DESCONECTANDO SISTEMA 125VDC EN 60kV A SOLICITUD DE ORYGEN PARA HALLAZGO DE FALLA. | H14: 0 | I14: P | J14: E/S | K14: N | L14: OTROS | M14: 15560 | N14: T
B15: CONELSUR LT SAC | C15: LOMERA | D15: BARRA A 220 kV | E15: 21/02/2026 06:25 | F15: 21/02/2026 09:06 | G15: A SOLICITUD DE PLUZ: DESCONEXION POR INTERVENCION EN TRANSFORMADOR TR-2 220/60 KV | H15: 0 | I15: P | J15: F/S | K15: N | L15: PREV. | M15: 16951 | N15: T
B16: CONELSUR LT SAC | C16: LOMERA | D16: BARRA B 220 kV | E16: 21/02/2026 09:12 | F16: 22/02/2026 00:00 | G16: A SOLICITUD DE PLUZ: DESCONEXION POR INTERVENCION EN TRANSFORMADOR TR-2 220/60 KV | H16: 0 | I16: P | J16: F/S | K16: N | L16: PREV. | M16: 16952 | N16: T
B17: EGASA | C17: CHARCANI 123 | D17: T-123 | E17: 21/02/2026 08:10 | F17: 21/02/2026 11:08 | G17: Mantenimiento correctivo sobre pasamuros 33 kV Transformador Charcani 1 | H17: 0 | I17: R | J17: F/S | K17: N | L17: CORR. | M17: 8587 | N17: T
B18: EGASA | C18: CHARCANI I | D18: CENTRAL | E18: 21/02/2026 00:00 | F18: 21/02/2026 00:05 | G18: Central F.S. por solidos en suspension | H18: 1.6 | I18: F | J18: F/S | K18: N | L18: OTROS | M18: 1195 | N18: G
... B126: TRANSMANTARO | C126: YARABAMBA | D126: SS.EE. | E126: 21/02/2026 00:00 | F126: 22/02/2026 00:00 | G126: PROTECCION DIFERENCIAL DE BARRAS 87B 220 KV SE ENCUENTRA BLOQUEADO, LUEGO DE TENER UNA ACTUACION INDESEADA DURANTE EL EVENTO DEL 11.01.2026. | H126: 0 | I126: P | J126: E/S | K126: N | L126: OTROS | M126: 17419 | N126: T

Sheet INGRESO OC
A3: sábado, 21 de Febrero del 2026
A5: INGRESO A OPERACIÓN COMERCIAL
A6: EMPRESA | B6: TIPO DE EQUIPO | C6: UBICACIÓN | D6: EQUIPO | E6: Fecha y hora de Ingreso a Operación Comercial

Sheet DESPACHO_EJECUTADO
B3: sábado, 21 de Febrero del 2026
A5: POTENCIA ACTIVA EJECUTADA DE LAS UNIDADES DE GENERACIÓN DEL SEIN (MW) | FQ5: CENTRALES NO INTEGRANTES COES
A6: FECHA | B6: HORA | C6: 65333 | D6: 101 | E6: 102 | F6: 42667 | G6: 42668 | H6: 126 | I6: 127 | J6: 138 | K6: 139 | L6: 197 | M6: 203 | N6: 204 | O6: 230 | P6: 209 | Q6: 56677 | R6: 796 | S6: 2146 | T6: 142 | U6: 143 | V6: 125 | W6: 187 | X6: 163 | Y6: 298 | Z6: 299 | AA6: 219 | AB6: 151 | AC6: 152 | AD6: 153 | AE6: 154 | AF6: 756 | AG6: 156 | AH6: 155 | AI6: 182 | AJ6: 212 | AK6: 758 | AL6: 263 | AM6: 265 | AN6: 775 | AO6: 777 | AP6: 2154 | AQ6: 150 | AR6: 149 | AS6: 188 | AT6: 2131 | AU6: 755 | AV6: 252 | AW6: 249 | AX6: 250 | AY6: 117 | AZ6: 119 | BA6: 120 | BB6: 189 | BC6: 122 | BD6: 266 | BE6: 337 | BF6: 338 | BG6: 251 | BH6: 115 | BI6: 239 | BJ6: 288 | BK6: 240 | BL6: 241 | BM6: 242 | BN6: 191 | BO6: 194 | BP6: 196 | BQ6: 207 | BR6: 236 | BS6: 795 | BT6: 285 | BU6: 995 | BV6: 996 | BW6: 997 | BX6: 766 | BY6: 926 | BZ6: 924 | CA6: 121 | CB6: 103 | CC6: 104 | CD6: 106 | CE6: 105 | CF6: 107 | CG6: 110 | CH6: 109 | CI6: 144 | CJ6: 113 | CK6: 114 | CL6: 193 | CM6: 208 | CN6: 786 | CO6: 787 | CP6: 788 | CQ6: 789 | CR6: 248 | CS6: 2159 | CT6: 267 | CU6: 268 | CV6: 2194 | CW6: 303 | CX6: 59715 | CY6: 62255 | CZ6: 1263 | DA6: 61800 | DB6: 69125 | DC6: 216 | DD6: 198 | DE6: 70400 | DF6: 76068 | DG6: 49607 | DH6: 214 | DI6: 260 | DJ6: 2152 | DK6: 2128 | DL6: 247 | DM6: 228 | DN6: 2135 | DO6: 261 | DP6: 237 | DQ6: 253 | DR6: 770 | DS6: 235 | DT6: 238 | DU6: 2184 | DV6: 61855 | DW6: 223 | DX6: 75566 | DY6: 226 | DZ6: 201 | EA6: 258 | EB6: 259 | EC6: 257 | ED6: 256 | EE6: 2148 | EF6: 58288 | EG6: 58289 | EH6: 58839 | EI6: 58840 | EJ6: 75260 | EK6: 296 | EL6: 297 | EM6: 211 | EN6: 2175 | EO6: 2178 | EP6: 2181 | EQ6: 1262 | ER6: 63425 | ES6: 233 | ET6: 2150 | EU6: 2165 | EV6: 2161 | EW6: 61197 | EX6: 58851 | EY6: 225 | EZ6: 2201 | FA6: 2171 | FB6: 760 | FC6: 234 | FD6: 215 | FE6: 917 | FF6: 920 | FG6: 289 | FH6: 58333 | FI6: 58336 | FJ6: 213 | FK6: 232 | FL6: 2190 | FM6: 69867 | FN6: 75066 | FO6: TOTAL COES | FQ6: 221 | FR6: 222 | FS6: 224 | FT6: 2187 | FU6: 227 | FV6: 49400 | FW6: 199 | FX6: 200 | FY6: TOTAL NO COES
C7: SUR | D7: CENTRO | E7: CENTRO | F7: NORTE | G7: NORTE | H7: NORTE | I7: NORTE | J7: CENTRO | K7: CENTRO | L7: CENTRO | M7: CENTRO | N7: CENTRO | O7: CENTRO | P7: CENTRO | Q7: CENTRO | R7: CENTRO | S7: CENTRO | T7: CENTRO | U7: CENTRO | V7: CENTRO | W7: CENTRO | X7: SUR | Y7: SUR | Z7: SUR | AA7: CENTRO | AB7: SUR | AC7: SUR | AD7: SUR | AE7: SUR | AF7: SUR | AG7: SUR | AH7: SUR | AI7: SUR | AJ7: CENTRO | AK7: NORTE | AL7: NORTE | AM7: NORTE | AN7: CENTRO | AO7: CENTRO | AP7: CENTRO | AQ7: CENTRO | AR7: CENTRO | AS7: CENTRO | AT7: CENTRO | AU7: SUR | AV7: CENTRO | AW7: CENTRO | AX7: CENTRO | AY7: CENTRO | AZ7: CENTRO | BA7: CENTRO | BB7: SUR | BC7: NORTE | BD7: CENTRO | BE7: CENTRO | BF7: CENTRO | BG7: CENTRO | BH7: NORTE | BI7: NORTE | BJ7: NORTE | BK7: SUR | BL7: SUR | BM7: SUR | BN7: CENTRO | BO7: CENTRO | BP7: CENTRO | BQ7: CENTRO | BR7: CENTRO | BS7: CENTRO | BT7: CENTRO | BU7: SUR | BV7: SUR | BW7: SUR | BX7: NORTE | BY7: SUR | BZ7: CENTRO | CA7: NORTE | CB7: CENTRO | CC7: CENTRO | CD7: CENTRO | CE7: CENTRO | CF7: CENTRO | CG7: CENTRO | CH7: CENTRO | CI7: CENTRO | CJ7: CENTRO | CK7: CENTRO | CL7: CENTRO | CM7: CENTRO | CN7: SUR | CO7: SUR | CP7: SUR | CQ7: SUR | CR7: CENTRO | CS7: CENTRO | CT7: CENTRO | CU7: CENTRO | CV7: NORTE | CW7: CENTRO | CX7: CENTRO | CY7: SUR | CZ7: NORTE | DA7: NORTE | DB7: CENTRO | DC7: NORTE | DD7: NORTE | DE7: SUR | DF7: SUR | DG7: SUR | DH7: CENTRO | DI7: CENTRO | DJ7: CENTRO | DK7: NORTE | DL7: NORTE | DM7: CENTRO | DN7: CENTRO | DO7: SUR | DP7: SUR | DQ7: CENTRO | DR7: CENTRO | DS7: SUR | DT7: CENTRO | DU7: CENTRO | DV7: NORTE | DW7: CENTRO | DX7: CENTRO | DY7: CENTRO | DZ7: NORTE | EA7: CENTRO | EB7: CENTRO | EC7: NORTE | ED7: NORTE | EE7: SUR | EF7: CENTRO | EG7: CENTRO | EH7: CENTRO | EI7: CENTRO | EJ7: SUR | EK7: CENTRO | EL7: CENTRO | EM7: SUR | EN7: SUR | EO7: SUR | EP7: SUR | EQ7: NORTE | ER7: SUR | ES7: SUR | ET7: SUR | EU7: CENTRO | EV7: CENTRO | EW7: CENTRO | EX7: SUR | EY7: CENTRO | EZ7: CENTRO | FA7: CENTRO | FB7: CENTRO | FC7: SUR | FD7: NORTE | FE7: CENTRO | FF7: CENTRO | FG7: NORTE | FH7: NORTE | FI7: NORTE | FJ7: CENTRO | FK7: NORTE | FL7: NORTE | FM7: NORTE | FN7: NORTE | FQ7: NORTE | FR7: CENTRO | FS7: NORTE | FT7: NORTE | FU7: NORTE | FV7: NORTE | FW7: NORTE | FX7: NORTE
C8: HIDROELÉCTRICA | D8: HIDROELÉCTRICA | E8: HIDROELÉCTRICA | F8: TERMOELÉCTRICA | G8: TERMOELÉCTRICA | H8: HIDROELÉCTRICA | I8: HIDROELÉCTRICA | J8: TERMOELÉCTRICA | K8: TERMOELÉCTRICA | L8: TERMOELÉCTRICA | M8: TERMOELÉCTRICA | N8: TERMOELÉCTRICA | O8: TERMOELÉCTRICA | P8: TERMOELÉCTRICA | Q8: TERMOELÉCTRICA | R8: HIDROELÉCTRICA | S8: HIDROELÉCTRICA | T8: TERMOELÉCTRICA | U8: TERMOELÉCTRICA | V8: TERMOELÉCTRICA | W8: TERMOELÉCTRICA | X8: HIDROELÉCTRICA | Y8: HIDROELÉCTRICA | Z8: HIDROELÉCTRICA | AA8: TERMOELÉCTRICA | AB8: HIDROELÉCTRICA | AC8: HIDROELÉCTRICA | AD8: HIDROELÉCTRICA | AE8: HIDROELÉCTRICA | AF8: TERMOELÉCTRICA | AG8: TERMOELÉCTRICA | AH8: TERMOELÉCTRICA | AI8: HIDROELÉCTRICA | AJ8: HIDROELÉCTRICA | AK8: TERMOELÉCTRICA | AL8: TERMOELÉCTRICA | AM8: TERMOELÉCTRICA | AN8: HIDROELÉCTRICA | AO8: HIDROELÉCTRICA | AP8: HIDROELÉCTRICA | AQ8: HIDROELÉCTRICA | AR8: HIDROELÉCTRICA | AS8: HIDROELÉCTRICA | AT8: HIDROELÉCTRICA | AU8: HIDROELÉCTRICA | AV8: TERMOELÉCTRICA | AW8: TERMOELÉCTRICA | AX8: TERMOELÉCTRICA | AY8: HIDROELÉCTRICA | AZ8: HIDROELÉCTRICA | BA8: HIDROELÉCTRICA | BB8: HIDROELÉCTRICA | BC8: HIDROELÉCTRICA | BD8: HIDROELÉCTRICA | BE8: HIDROELÉCTRICA | BF8: HIDROELÉCTRICA | BG8: HIDROELÉCTRICA | BH8: TERMOELÉCTRICA | BI8: TERMOELÉCTRICA | BJ8: TERMOELÉCTRICA | BK8: TERMOELÉCTRICA | BL8: TERMOELÉCTRICA | BM8: TERMOELÉCTRICA | BN8: HIDROELÉCTRICA | BO8: TERMOELÉCTRICA | BP8: TERMOELÉCTRICA | BQ8: TERMOELÉCTRICA | BR8: TERMOELÉCTRICA | BS8: TERMOELÉCTRICA | BT8: TERMOELÉCTRICA | BU8: TERMOELÉCTRICA | BV8: TERMOELÉCTRICA | BW8: TERMOELÉCTRICA | BX8: HIDROELÉCTRICA | BY8: TERMOELÉCTRICA | BZ8: TERMOELÉCTRICA | CA8: HIDROELÉCTRICA | CB8: HIDROELÉCTRICA | CC8: HIDROELÉCTRICA | CD8: HIDROELÉCTRICA | CE8: HIDROELÉCTRICA | CF8: HIDROELÉCTRICA | CG8: TERMOELÉCTRICA | CH8: TERMOELÉCTRICA | CI8: TERMOELÉCTRICA | CJ8: TERMOELÉCTRICA | CK8: TERMOELÉCTRICA | CL8: TERMOELÉCTRICA | CM8: TERMOELÉCTRICA | CN8: TERMOELÉCTRICA | CO8: TERMOELÉCTRICA | CP8: TERMOELÉCTRICA | CQ8: TERMOELÉCTRICA | CR8: TERMOELÉCTRICA | CS8: TERMOELÉCTRICA | CT8: HIDROELÉCTRICA | CU8: HIDROELÉCTRICA | CV8: HIDROELÉCTRICA | CW8: SOLAR | CX8: EÓLICA | CY8: SOLAR | CZ8: EÓLICA | DA8: SOLAR | DB8: HIDROELÉCTRICA | DC8: HIDROELÉCTRICA | DD8: HIDROELÉCTRICA | DE8: SOLAR | DF8: SOLAR | DG8: HIDROELÉCTRICA | DH8: HIDROELÉCTRICA | DI8: HIDROELÉCTRICA | DJ8: HIDROELÉCTRICA | DK8: HIDROELÉCTRICA | DL8: HIDROELÉCTRICA | DM8: HIDROELÉCTRICA | DN8: HIDROELÉCTRICA | DO8: SOLAR | DP8: SOLAR | DQ8: EÓLICA | DR8: EÓLICA | DS8: SOLAR | DT8: HIDROELÉCTRICA | DU8: HIDROELÉCTRICA | DV8: HIDROELÉCTRICA | DW8: HIDROELÉCTRICA | DX8: SOLAR | DY8: HIDROELÉCTRICA | DZ8: HIDROELÉCTRICA | EA8: HIDROELÉCTRICA | EB8: HIDROELÉCTRICA | EC8: EÓLICA | ED8: EÓLICA | EE8: SOLAR | EF8: EÓLICA | EG8: EÓLICA | EH8: EÓLICA | EI8: EÓLICA | EJ8: SOLAR | EK8: HIDROELÉCTRICA | EL8: HIDROELÉCTRICA | EM8: HIDROELÉCTRICA | EN8: HIDROELÉCTRICA | EO8: HIDROELÉCTRICA | EP8: HIDROELÉCTRICA | EQ8: EÓLICA | ER8: SOLAR | ES8: SOLAR | ET8: SOLAR | EU8: HIDROELÉCTRICA | EV8: EÓLICA | EW8: EÓLICA | EX8: SOLAR | EY8: TERMOELÉCTRICA | EZ8: TERMOELÉCTRICA | FA8: TERMOELÉCTRICA | FB8: TERMOELÉCTRICA | FC8: SOLAR | FD8: HIDROELÉCTRICA | FE8: HIDROELÉCTRICA | FF8: HIDROELÉCTRICA | FG8: TERMOELÉCTRICA | FH8: TERMOELÉCTRICA | FI8: TERMOELÉCTRICA | FJ8: TERMOELÉCTRICA | FK8: TERMOELÉCTRICA | FL8: TERMOELÉCTRICA | FM8: TERMOELÉCTRICA | FN8: TERMOELÉCTRICA | FQ8: HIDROELÉCTRICA | FR8: HIDROELÉCTRICA | FS8: HIDROELÉCTRICA | FT8: HIDROELÉCTRICA | FU8: TERMOELÉCTRICA | FV8: TERMOELÉCTRICA | FW8: HIDROELÉCTRICA | FX8: HIDROELÉCTRICA
C9: HYDRO GLOBAL PERÚ S.A.C. | D9: ELECTROPERU | E9: ELECTROPERU | F9: ELECTROPERU | G9: ELECTROPERU | H9: ORAZUL ENERGY PERÚ | I9: ORAZUL ENERGY PERÚ | J9: TERMOSELVA | K9: TERMOSELVA | L9: KALLPA GENERACION S.A. | M9: KALLPA GENERACION S.A. | N9: KALLPA GENERACION S.A. | O9: KALLPA GENERACION S.A. | P9: KALLPA GENERACION S.A. | Q9: KALLPA GENERACION S.A. | R9: KALLPA GENERACION S.A. | S9: KALLPA GENERACION S.A. | T9: SHOUGESA | U9: SHOUGESA | V9: SHOUGESA | W9: SHOUGESA | X9: EGEMSA | Y9: EGESUR | Z9: EGESUR | AA9: EGESUR | AB9: EGASA | AC9: EGASA | AD9: EGASA | AE9: EGASA | AF9: EGASA | AG9: EGASA | AH9: EGASA | AI9: SAN GABAN | AJ9: CELEPSA | AK9: MINERA CERRO VERDE | AL9: PLANTA DE RESERVA FRIA DE GENERACION DE ETEN S.A. | AM9: PLANTA DE RESERVA FRIA DE GENERACION DE ETEN S.A. | AN9: EMPRESA DE GENERACION HUALLAGA | AO9: EMPRESA DE GENERACION HUALLAGA | AP9: LA VIRGEN | AQ9: CHINANGO S.A.C. | AR9: CHINANGO S.A.C. | AS9: HIDROELECTRICA HUANCHOR S.A.C. | AT9: CELEPSA RENOVABLES S.R.L. | AU9: INLAND ENERGY SAC | AV9: FENIX POWER PERÚ | AW9: FENIX POWER PERÚ | AX9: FENIX POWER PERÚ | AY9: STATKRAFT S.A | AZ9: STATKRAFT S.A | BA9: STATKRAFT S.A | BB9: STATKRAFT S.A | BC9: STATKRAFT S.A | BD9: STATKRAFT S.A | BE9: CENTRALES SANTA ROSA S.A.C. | BF9: CENTRALES SANTA ROSA S.A.C. | BG9: EMPRESA DE GENERACION HUANZA | BH9: ENEL GENERACION PIURA S.A. | BI9: ENEL GENERACION PIURA S.A. | BJ9: ENEL GENERACION PIURA S.A. | BK9: ENGIE ENERGIA PERU S.A.A. | BL9: ENGIE ENERGIA PERU S.A.A. | BM9: ENGIE ENERGIA PERU S.A.A. | BN9: ENGIE ENERGIA PERU S.A.A. | BO9: ENGIE ENERGIA PERU S.A.A. | BP9: ENGIE ENERGIA PERU S.A.A. | BQ9: ENGIE ENERGIA PERU S.A.A. | BR9: ENGIE ENERGIA PERU S.A.A. | BS9: ENGIE ENERGIA PERU S.A.A. | BT9: ENGIE ENERGIA PERU S.A.A. | BU9: ENGIE ENERGIA PERU S.A.A. | BV9: ENGIE ENERGIA PERU S.A.A. | BW9: ENGIE ENERGIA PERU S.A.A. | BX9: ENGIE ENERGIA PERU S.A.A. | BY9: INFRAESTRUCTURAS Y ENERGIAS DEL PERU S.A.C. | BZ9: INFRAESTRUCTURAS Y ENERGIAS DEL PERU S.A.C. | CA9: INVERSIONES SHAQSHA S.A.C. | CB9: ORYGEN PERU S.A.A. | CC9: ORYGEN PERU S.A.A. | CD9: ORYGEN PERU S.A.A. | CE9: ORYGEN PERU S.A.A. | CF9: ORYGEN PERU S.A.A. | CG9: ORYGEN PERU S.A.A. | CH9: ORYGEN PERU S.A.A. | CI9: ORYGEN PERU S.A.A. | CJ9: ORYGEN PERU S.A.A. | CK9: ORYGEN PERU S.A.A. | CL9: ORYGEN PERU S.A.A. | CM9: ORYGEN PERU S.A.A. | CN9: SAMAY I S.A.C | CO9: SAMAY I S.A.C | CP9: SAMAY I S.A.C | CQ9: SAMAY I S.A.C | CR9: TERMOCHILCA S.A.C. | CS9: TERMOCHILCA S.A.C. | CT9: TRANSMISION ANDINA DE GENERACION S.A.C. | CU9: TRANSMISION ANDINA DE GENERACION S.A.C. | CV9: CELARIS ENERGY S.A. | CW9: COLCA SOLAR S.A.C. | CX9: ENERGIA RENOVABLE DEL SUR S.A. | CY9: GR CORTARRAMA SOCIEDAD ANONIMA CERRADA | CZ9: GR TARUCA SOCIEDAD ANONIMA CERRADA | DA9: KONDU SAC | DB9: VARI ENERGIA S.A.C. | DC9: ORAZUL ENERGY PERÚ | DD9: ORAZUL ENERGY PERÚ | DE9: KALLPA GENERACION S.A. | DF9: KALLPA GENERACION S.A. | DG9: SAN GABAN | DH9: MAJA ENERGIA S.A.C. | DI9: EMPRESA DE GENERACION ELECTRICA CANCHAYLLO SAC | DJ9: EMPRESA DE GENERACION ELECTRICA SANTA ANA S.A.C. | DK9: EMPRESA ELECTRICA AGUA AZUL | DL9: EMPRESA ELECTRICA RIO DOBLE | DM9: HIDROCAÑETE S.A. | DN9: HUAURA POWER GROUP S.A. | DO9: MOQUEGUA FV S.A.C. | DP9: PANAMERICANA SOLAR SAC. | DQ9: PARQUE EOLICO MARCONA S.A.C. | DR9: PARQUE EOLICO TRES HERMANAS S.A.C. | DS9: TACNA SOLAR SAC. | DT9: ELECTRICA YANAPAMPA SAC | DU9: ANDEAN POWER S.A.C. | DV9: ASOCIACIÓN SANTA LUCIA DE CHACAS | DW9: ATRIA ENERGIA S.A.C. | DX9: COENERGY S.A.C. | DY9: EGEJUNIN | DZ9: EGEJUNIN | EA9: EGEJUNIN | EB9: EGEJUNIN | EC9: ENERGÍA EÓLICA S.A. | ED9: ENERGÍA EÓLICA S.A. | EE9: ENGIE ENERGIA PERU S.A.A. | EF9: ENGIE ENERGIA PERU S.A.A. | EG9: ENGIE ENERGIA PERU S.A.A. | EH9: ENGIE ENERGIA PERU S.A.A. | EI9: ENGIE ENERGIA PERU S.A.A. | EJ9: ENGIE ENERGIA PERU S.A.A. | EK9: GENERACIÓN ANDINA S.A.C. | EL9: GENERACIÓN ANDINA S.A.C. | EM9: GENERADORA DE ENERGÍA DEL PERÚ | EN9: GENERADORA DE ENERGÍA DEL PERÚ | EO9: GENERADORA DE ENERGÍA DEL PERÚ | EP9: GENERADORA DE ENERGÍA DEL PERÚ | EQ9: GR PAINO SOCIEDAD ANONIMA CERRADA | ER9: JOYA SOLAR S.A.C. | ES9: MAJES ARCUS S.A.C. | ET9: ORYGEN PERU S.A.A. | EU9: ORYGEN PERU S.A.A. | EV9: ORYGEN PERU S.A.A. | EW9: ORYGEN PERU S.A.A. | EX9: ORYGEN PERU S.A.A. | EY9: PETRAMAS | EZ9: PETRAMAS | FA9: PETRAMAS | FB9: PETRAMAS | FC9: REPARTICIÓN ARCUS S.A.C. | FD9: SINERSA | FE9: SINERSA | FF9: SINERSA | FG9: BIOENERGIA DEL CHIRA S.A. | FH9: GM OPERACIONES S.A.C. | FI9: GM OPERACIONES S.A.C. | FJ9: AGRO INDUSTRIAL PARAMONGA S.A. | FK9: AGROAURORA S.A.C. | FL9: AGROINDUSTRIAS SAN JACINTO S.A.A. | FM9: AGROLMOS SOCIEDAD ANONIMA - AGROLMOS S.A. | FN9: CASA GRANDE S.A.A. | FQ9: UNACEM PERU S.A. | FR9: ELECTRO ORIENTE | FS9: AGUAS Y ENERGIA PERU | FT9: ELECTRO ZAÑA S.A.C. | FU9: ELECTRONOROESTE S.A. | FV9: SDE PIURA | FW9: SINERSA | FX9: SINERSA
C10: SAN GABAN III | D10: MANTARO | E10: RESTITUCION | F10: TUMBES MAK 1 | G10: TUMBES MAK 2 | H10: CARHUAQUERO | I10: CAÑON DEL PATO | J10: AGUAYTIA TG1 | K10: AGUAYTIA TG2 | L10: KALLPA TG1 | M10: KALLPA TG2 | N10: KALLPA TG3 | O10: KALLPA TV | P10: LFLORES TG1 | Q10: LFLORES TV | R10: CERRO DEL AGUILA | S10: CERRODELAGUILAG4 | T10: SHOUGESA TV1 | U10: SHOUGESA TV2 | V10: SHOUGESA TV3 | W10: SHOUGESA CUMMINS | X10: MACHUPICCHU | Y10: ARICOTA 1 | Z10: ARICOTA 2 | AA10: INDEPENDENCIA | AB10: CHARCANI I,II,III | AC10: CHARCANI IV | AD10: CHARCANI V | AE10: CHARCANI VI | AF10: CHILINA TG | AG10: MOLLENDO 1, 2, 3 | AH10: CHILINA (SULZ 1,2) | AI10: SAN GABAN II | AJ10: PLATANAL | AK10: RECKA | AL10: RF ETEN TG1 | AM10: RF ETEN TG2 | AN10: CHAGLLA GP1 | AO10: CHAGLLA | AP10: LA VIRGEN | AQ10: CHIMAY | AR10: YANANGO | AS10: HUANCHOR | AT10: MARAÑON | AU10: STA TERESA | AV10: FENIX GT11 | AW10: FENIX GT12 | AX10: FENIX TV10 | AY10: YAUPI | AZ10: MALPASO | BA10: CAHUA | BB10: ARCATA | BC10: GALLITO CIEGO | BD10: CHEVES | BE10: SANTA ROSA 1 | BF10: SANTA ROSA 2 | BG10: HUANZA | BH10: MALACAS2 TG4 | BI10: MALACAS3 TG 5 | BJ10: MALACAS1 TG6 | BK10: RF ILO2 TG1 | BL10: RF ILO2 TG2 | BM10: RF ILO2 TG3 | BN10: YUNCAN | BO10: CHILCA1 TG1 | BP10: CHILCA1 TG2 | BQ10: CHILCA1 TG3 | BR10: CHILCA-TV | BS10: CHILCA2 TG41 | BT10: CHILCA2-TV | BU10: CTNEPI_TG41 | BV10: CTNEPI_TG42 | BW10: CTNEPI_TG43 | BX10: QUITARACSA | BY10: RF PTO MALDONADO | BZ10: RF PUCALLPA | CA10: PARIAC | CB10: HUINCO | CC10: MATUCANA | CD10: MOYOPAMPA | CE10: CALLAHUANCA | CF10: HUAMPANI | CG10: STA ROSA WEST TG7 | CH10: UTI_5 | CI10: UTI_6 | CJ10: VENTANILLA 3 | CK10: VENTANILLA 4 | CL10: VENTANILLA TV | CM10: STAROSA TG8 | CN10: PTO_BRVO TG1 | CO10: PTO_BRVO TG2 | CP10: PTO_BRVO TG3 | CQ10: PTO_BRVO TG4 | CR10: OLLEROS TG1 | CS10: OLLEROS TV | CT10: OROYA | CU10: PACHACHACA | CV10: MANTA I | CW10: CS YARUCAYA | CX10: SAN JUAN | CY10: MATARANI | CZ10: DUNA | DA10: CARHUAQUERO (CS) | DB10: ANASHIRONI | DC10: CARHUAQUERO4 | DD10: CAÑA BRAVA | DE10: SUNNY | DF10: SUNNY EXPANSION | DG10: TUPURI | DH10: RONCADOR | DI10: CANCHAYLLO | DJ10: RENOVANDESH1 | DK10: POTRERO | DL10: PIZARRAS | DM10: NIMPERIAL | DN10: YARUCAYA | DO10: MOQUEGUA-SOLAR | DP10: PANAMERICANA-SOLAR | DQ10: PQE-EOLICO-MARCONA | DR10: PQE-EOLICO-3-HERMANAS | DS10: TACNA-SOLAR | DT10: YANAPAMPA | DU10: CARHUAC | DV10: HUALLIN | DW10: PURMACANA | DX10: COENERGY | DY10: HUASAHUASI | DZ10: STACRUZ_1_2 | EA10: RUNATULLO_II | EB10: RUNATULLO_III | EC10: PQE-EOLICO-TALARA | ED10: PQE-EOLICO-CUPISNIQUE | EE10: INTIPAMPA | EF10: PUNTA LOMITAS-BL1 | EG10: PUNTA LOMITAS-BL2 | EH10: PUN LOMITAS_EXP-BL1 | EI10: PUN LOMITAS_EXP-BL2 | EJ10: EXPANSIÓN INTIPAMPA | EK10: 8AGOSTO | EL10: EL CARMEN | EM10: LA JOYA | EN10: ANGEL_I | EO10: ANGEL_II | EP10: ANGEL_III | EQ10: HUAMBOS | ER10: SAN MARTIN SOLAR | ES10: MAJES | ET10: RUBI | EU10: CH_HER1 | EV10: WAYRA-I | EW10: WAYRA EXTENSION | EX10: CLEMESI | EY10: HUAYCOLORO | EZ10: CALLAO | FA10: DONA_CATALINA | FB10: LAGRINGAV | FC10: REPARTICION | FD10: POECHOS2 | FE10: CHANCAY | FF10: RUCUY | FG10: CANA BRAVA | FH10: REFINERIA TALARA TV1 | FI10: REFINERÍA TALARA TV2 | FJ10: PARAMONGA | FK10: MAPLE | FL10: SAN_JACINTO | FM10: AGROLMOS | FN10: CASA GRANDE | FO10: MW | FQ10: CARPAPATA | FR10: CENTRALES ELOR | FS10: PIAS1 | FT10: ZANA | FU10: TABLAZO | FV10: TALLANCA | FW10: CURUMUY | FX10: POECHOS1 | FY10: MW
A11: 21/02/2026 | B11: 00:30 | C11: 198.2 | D11: 625.1 | E11: 213.1 | H11: 88.1 | I11: 230.1 | J11: 26.6 | L11: 176 | M11: 182.2 | N11: 180.8 | O11: 263 | P11: 204.8 | Q11: 108.4 | R11: 370.8 | S11: 9.9 | T11: 13.9 | X11: 164.1 | Y11: 8.269 | Z11: 6.036 | AA11: 0 | AB11: 5.47 | AD11: 142.12 | AI11: 109.4 | AJ11: 214.8 | AN11: 6.5 | AO11: 458.3 | AP11: 81.6 | AQ11: 150 | AR11: 40.9 | AS11: 18.4 | AT11: 18.8 | AU11: 89.2 | AV11: 175.9 | AW11: 176.2 | AX11: 185.5 | AY11: 104.9 | AZ11: 44 | BA11: 44 | BB11: 2 | BC11: 31.6 | BD11: 166.7 | BG11: 61.1 | BJ11: 45.4 | BN11: 125.8 | BO11: 0 | BP11: 0 | BQ11: 0 | BS11: 72.2 | BT11: 34.9 | BY11: 0 | CA11: 2.1 | CB11: 255.4 | CC11: 128.6 | CD11: 61.1 | CE11: 63.8 | CF11: 0 | CJ11: 113.7 | CL11: 57.8 | CM11: 0 | CR11: 206.1 | CS11: 98.6 | CT11: 7.2 | CW11: 0 | CX11: 4.8 | CY11: 0 | CZ11: 1.8 | DA11: 0 | DB11: 20.1 | DC11: 10 | DD11: 5.5 | DE11: 0 | DG11: 2.2 | DH11: 2 | DI11: 5 | DJ11: 20.1 | DK11: 20 | DL11: 18.9 | DM11: 3.6 | DN11: 18.5 | DO11: 0 | DP11: 0 | DQ11: 1.1 | DR11: 2.4 | DS11: 0 | DT11: 3.1 | DU11: 20 | DV11: 3.2 | DX11: 0 | DY11: 19.8 | DZ11: 13.1 | EA11: 20.2 | EB11: 20.2 | EC11: 1.9 | ED11: 18.6 | EE11: 0 | EF11: 0 | EG11: 0.9 | EH11: 0 | EI11: 0 | EJ11: 0 | EK11: 0 | EL11: 0 | EN11: 20.4 | EO11: 20.4 | EP11: 20 | EQ11: 1.8 | ER11: 0 | ES11: 0 | ET11: 0 | EU11: 0 | EV11: 9.5 | EW11: 7 | EX11: 0 | EY11: 3 | EZ11: 2.4 | FA11: 2 | FB11: 0.7 | FC11: 0 | FD11: 8.1 | FE11: 20 | FF11: 20 | FG11: 8.9 | FI11: 29.8 | FJ11: 16 | FK11: 12.49 | FL11: 8.22 | FM11: 4.97 | FN11: 14.69 | FO11: 7156.865 | FQ11: 24.41085 | FR11: 7.934 | FS11: 9.952 | FT11: 0 | FU11: 24.19363 | FV11: 18.95134 | FW11: 11.7 | FX11: 16 | FY11: 113.14182
A12: 21/02/2026 | B12: 01:00 | C12: 202 | D12: 635.7 | E12: 216.7 | H12: 90 | I12: 232.5 | J12: 27.2 | L12: 135.2 | M12: 134.2 | N12: 134.6 | O12: 231.4 | P12: 203.5 | Q12: 107.9 | R12: 380.5 | S12: 10.2 | T12: 15.8 | X12: 167 | Y12: 6.678 | Z12: 6.698 | AA12: 0 | AB12: 6.17 | AD12: 142.9 | AI12: 110 | AJ12: 211.4 | AN12: 6.5 | AO12: 462.6 | AP12: 81.5 | AQ12: 151.3 | AR12: 42.1 | AS12: 18.4 | AT12: 18.8 | AU12: 88.8 | AV12: 179.6 | AW12: 179.9 | AX12: 184.8 | AY12: 107.2 | AZ12: 45.3 | BA12: 45.7 | BB12: 2 | BC12: 31.5 | BD12: 171.6 | BG12: 63.4 | BJ12: 45.4 | BN12: 127.5 | BO12: 0 | BP12: 0 | BQ12: 0 | BS12: 71.7 | BT12: 34.8 | BY12: 0 | CA12: 2.1 | CB12: 262.4 | CC12: 132.2 | CD12: 62.7 | CE12: 64.4 | CF12: 0 | CJ12: 113.2 | CL12: 56.7 | CM12: 0 | CR12: 206.3 | CS12: 98.6 | CT12: 7.2 | CW12: 0 | CX12: 7.2 | CY12: 0 | CZ12: 2 | DA12: 0 | DB12: 20.4 | DC12: 9.9 | DD12: 5.5 | DE12: 0 | DG12: 2.2 | DH12: 2 | DI12: 4.9 | DJ12: 20.6 | DK12: 20 | DL12: 18.9 | DM12: 3.5 | DN12: 18.5 | DO12: 0 | DP12: 0 | DQ12: 0.6 | DR12: 1.8 | DS12: 0 | DT12: 3.1 | DU12: 20.1 | DV12: 3.2 | DX12: 0 | DY12: 19.8 | DZ12: 13.1 | EA12: 20.3 | EB12: 20.2 | EC12: 3.5 | ED12: 13.2 | EE12: 0 | EF12: 0 | EG12: 0 | EH12: 0 | EI12: 0 | EJ12: 0 | EK12: 0 | EL12: 0 | EN12: 20.4 | EO12: 20.4 | EP12: 20 | EQ12: 2 | ER12: 0 | ES12: 0 | ET12: 0 | EU12: 0 | EV12: 3.3 | EW12: 1.7 | EX12: 0 | EY12: 3 | EZ12: 2.4 | FA12: 2 | FB12: 0.7 | FC12: 0 | FD12: 8.2 | FE12: 20 | FF12: 20 | FG12: 8.8 | FI12: 30 | FJ12: 16.2 | FK12: 12.49 | FL12: 7.88 | FM12: 4.97 | FN12: 15.64 | FO12: 7049.026 | FQ12: 24.41123 | FR12: 7.931 | FS12: 9.922 | FT12: 0 | FU12: 24.25291 | FV12: 18.95101 | FW12: 11.7 | FX12: 16 | FY12: 113.16815
A13: 21/02/2026 | B13: 01:30 | C13: 202.4 | D13: 632.6 | E13: 216.1 | H13: 90.1 | I13: 231.8 | J13: 26.9 | L13: 118.6 | M13: 117.6 | N13: 119.2 | O13: 220.9 | P13: 204.6 | Q13: 108.5 | R13: 375.2 | S13: 10.2 | T13: 16.1 | X13: 161.3 | Y13: 7.305 | Z13: 5.948 | AA13: 0 | AB13: 6.39 | AD13: 142.54 | AI13: 110 | AJ13: 177.3 | AN13: 6.5 | AO13: 461.1 | AP13: 81.5 | AQ13: 151.2 | AR13: 41.9 | AS13: 18.5 | AT13: 18.8 | AU13: 89.9 | AV13: 180.4 | AW13: 180.6 | AX13: 184.9 | AY13: 106 | AZ13: 45 | BA13: 45.3 | BB13: 2 | BC13: 31.6 | BD13: 171 | BG13: 63.2 | BJ13: 14.4 | BN13: 127.5 | BO13: 0 | BP13: 0 | BQ13: 0 | BS13: 71.9 | BT13: 34.9 | BY13: 0 | CA13: 2.1 | CB13: 244.3 | CC13: 126.8 | CD13: 62.6 | CE13: 64.3 | CF13: 0 | CJ13: 113.5 | CL13: 56.4 | CM13: 0 | CR13: 206.2 | CS13: 98.9 | CT13: 7.2 | CW13: 0 | CX13: 14.5 | CY13: 0 | CZ13: 1.8 | DA13: 0 | DB13: 20.4 | DC13: 9.9 | DD13: 5.5 | DE13: 0 | DG13: 2.2 | DH13: 2 | DI13: 5.1 | DJ13: 20.6 | DK13: 20 | DL13: 18.9 | DM13: 3.5 | DN13: 18.5 | DO13: 0 | DP13: 0 | DQ13: 1.4 | DR13: 4 | DS13: 0 | DT13: 3.1 | DU13: 20.1 | DV13: 3.2 | DX13: 0 | DY13: 19.8 | DZ13: 13 | EA13: 20.2 | EB13: 20.2 | EC13: 2 | ED13: 7.3 | EE13: 0 | EF13: 0 | EG13: 0 | EH13: 0 | EI13: 0 | EJ13: 0 | EK13: 0 | EL13: 0 | EN13: 20.4 | EO13: 20.4 | EP13: 20 | EQ13: 1.8 | ER13: 0 | ES13: 0 | ET13: 0 | EU13: 0 | EV13: 1.7 | EW13: 0.3 | EX13: 0 | EY13: 3 | EZ13: 2.4 | FA13: 2 | FB13: 0.7 | FC13: 0 | FD13: 8.1 | FE13: 20 | FF13: 19.9 | FG13: 8.5 | FI13: 29.8 | FJ13: 16.5 | FK13: 12.49 | FL13: 8.23 | FM13: 4.97 | FN13: 15.42 | FO13: 6885.793 | FQ13: 24.41372 | FR13: 7.927 | FS13: 9.908 | FT13: 0 | FU13: 24.20662 | FV13: 18.95089 | FW13: 11.8 | FX13: 16 | FY13: 113.20623
A14: 21/02/2026 | B14: 02:00 | C14: 203.7 | D14: 632.8 | E14: 216 | H14: 90 | I14: 233 | J14: 27.3 | L14: 121.4 | M14: 120.3 | N14: 121.3 | O14: 209.6 | P14: 202.5 | Q14: 108.1 | R14: 379.6 | S14: 10.3 | T14: 16.1 | X14: 168.6 | Y14: 7.301 | Z14: 5.408 | AA14: 0 | AB14: 6.5 | AD14: 142.78 | AI14: 110.1 | AJ14: 165.3 | AN14: 6.5 | AO14: 458.9 | AP14: 81.5 | AQ14: 151.2 | AR14: 42 | AS14: 18.4 | AT14: 18.8 | AU14: 92.5 | AV14: 179.9 | AW14: 179.9 | AX14: 185.1 | AY14: 105.9 | AZ14: 45.4 | BA14: 45.2 | BB14: 2 | BC14: 31.4 | BD14: 170.5 | BG14: 63.1 | BJ14: 0 | BN14: 127.5 | BO14: 0 | BP14: 0 | BQ14: 0 | BS14: 72.1 | BT14: 35 | BY14: 0 | CA14: 2.1 | CB14: 244.7 | CC14: 125.8 | CD14: 62.3 | CE14: 64.4 | CF14: 30.1 | CJ14: 69.6 | CL14: 0 | CM14: 0 | CR14: 206.1 | CS14: 98.7 | CT14: 7.2 | CW14: 0 | CX14: 16.4 | CY14: 0 | CZ14: 2 | DA14: 0 | DB14: 20.3 | DC14: 9.9 | DD14: 5.5 | DE14: 0 | DG14: 2.2 | DH14: 2.7 | DI14: 5.1 | DJ14: 20.4 | DK14: 20 | DL14: 18.9 | DM14: 3.5 | DN14: 18.5 | DO14: 0 | DP14: 0 | DQ14: 1.6 | DR14: 3.6 | DS14: 0 | DT14: 3.1 | DU14: 20.1 | DV14: 3.2 | DX14: 0 | DY14: 19.8 | DZ14: 13 | EA14: 20.3 | EB14: 20.2 | EC14: 0 | ED14: 7.3 | EE14: 0 | EF14: 0 | EG14: 1.5 | EH14: 0 | EI14: 0 | EJ14: 0 | EK14: 0 | EL14: 0 | EN14: 20.4 | EO14: 20.4 | EP14: 20 | EQ14: 2 | ER14: 0 | ES14: 0 | ET14: 0 | EU14: 0 | EV14: 1.7 | EW14: 1.8 | EX14: 0 | EY14: 3 | EZ14: 2.4 | FA14: 2 | FB14: 0.7 | FC14: 0 | FD14: 8.1 | FE14: 20 | FF14: 20 | FG14: 8.2 | FI14: 29.8 | FJ14: 17 | FK14: 12.48 | FL14: 8.07 | FM14: 4.97 | FN14: 15.69 | FO14: 6799.599 | FQ14: 24.41212 | FR14: 7.926 | FS14: 9.872 | FT14: 0 | FU14: 24.23611 | FV14: 18.95041 | FW14: 11.7 | FX14: 16 | FY14: 113.09664
A15: 21/02/2026 | B15: 02:30 | C15: 203.5 | D15: 633.6 | E15: 216.4 | H15: 90.4 | I15: 233 | J15: 0 | L15: 117.2 | M15: 116.8 | N15: 117.4 | O15: 222 | P15: 161.5 | Q15: 95.9 | R15: 376 | S15: 10.3 | T15: 16.1 | X15: 167.2 | Y15: 7.616 | Z15: 5.367 | AA15: 0 | AB15: 6.51 | AD15: 142.53 | AI15: 110.3 | AJ15: 197.6 | AN15: 6.5 | AO15: 460.8 | AP15: 81.5 | AQ15: 151.5 | AR15: 42 | AS15: 18.5 | AT15: 18.8 | AU15: 91.8 | AV15: 180.1 | AW15: 180.5 | AX15: 184.7 | AY15: 106.1 | AZ15: 44 | BA15: 45.3 | BB15: 2 | BC15: 31.4 | BD15: 170.6 | BG15: 63.2 | BJ15: 0 | BN15: 127.4 | BO15: 0 | BP15: 0 | BQ15: 0 | BS15: 40.2 | BT15: 27.7 | BY15: 0 | CA15: 2.1 | CB15: 244.1 | CC15: 126.2 | CD15: 62.6 | CE15: 64.5 | CF15: 30 | CJ15: 0 | CL15: 0 | CM15: 0 | CR15: 206.6 | CS15: 99 | CT15: 7.2 | CW15: 0 | CX15: 15.3 | CY15: 0 | CZ15: 2 | DA15: 0 | DB15: 20.3 | DC15: 9.9 | DD15: 5.5 | DE15: 0 | DG15: 2.2 | DH15: 2.7 | DI15: 5.1 | DJ15: 20.4 | DK15: 20 | DL15: 18.9 | DM15: 3.5 | DN15: 18.5 | DO15: 0 | DP15: 0 | DQ15: 0.8 | DR15: 2.4 | DS15: 0 | DT15: 3.1 | DU15: 20.2 | DV15: 3.2 | DX15: 0 | DY15: 19.8 | DZ15: 13 | EA15: 20.3 | EB15: 20.3 | EC15: 0 | ED15: 7.7 | EE15: 0 | EF15: 0 | EG15: 0 | EH15: 0 | EI15: 0 | EJ15: 0 | EK15: 0 | EL15: 0 | EN15: 20.4 | EO15: 20.4 | EP15: 20 | EQ15: 2 | ER15: 0 | ES15: 0 | ET15: 0 | EU15: 0 | EV15: 0 | EW15: 0 | EX15: 0 | EY15: 3 | EZ15: 2.4 | FA15: 2 | FB15: 0.7 | FC15: 0 | FD15: 8.1 | FE15: 20 | FF15: 20 | FG15: 8.2 | FI15: 30.3 | FJ15: 16.7 | FK15: 12.5 | FL15: 8.04 | FM15: 4.97 | FN15: 16.51 | FO15: 6635.443 | FQ15: 24.4144 | FR15: 7.921 | FS15: 9.84 | FT15: 0 | FU15: 24.26561 | FV15: 18.95056 | FW15: 11.8 | FX15: 15.7 | FY15: 112.89157
A16: 21/02/2026 | B16: 03:00 | C16: 198.5 | D16: 623.5 | E16: 212.3 | H16: 88.1 | I16: 228.3 | J16: 0 | L16: 124.4 | M16: 124.3 | N16: 124.1 | O16: 242.4 | P16: 111.2 | Q16: 71.9 | R16: 526.8 | S16: 10 | T16: 16.1 | X16: 163.5 | Y16: 7.136 | Z16: 4.929 | AA16: 0 | AB16: 6.51 | AD16: 141.06 | AI16: 109.8 | AJ16: 219.7 | AN16: 6.5 | AO16: 454.6 | AP16: 81.5 | AQ16: 134.8 | AR16: 41 | AS16: 18.4 | AT16: 18.8 | AU16: 88.2 | AV16: 176.1 | AW16: 176.5 | AX16: 183.1 | AY16: 105 | AZ16: 42.9 | BA16: 41 | BB16: 2 | BC16: 31.4 | BD16: 167 | BG16: 61.2 | BJ16: 0 | BN16: 126 | BO16: 0 | BP16: 0 | BQ16: 0 | BS16: 40.1 | BT16: 28 | BY16: 0 | CA16: 2.1 | CB16: 231.6 | CC16: 116.3 | CD16: 61.2 | CE16: 63.9 | CF16: 29.5 | CJ16: 0 | CL16: 0 | CM16: 0 | CR16: 206.8 | CS16: 99.2 | CT16: 7.2 | CW16: 0 | CX16: 16.4 | CY16: 0 | CZ16: 0.8 | DA16: 0 | DB16: 20.1 | DC16: 9.9 | DD16: 5.5 | DE16: 0 | DG16: 2.2 | DH16: 2.7 | DI16: 5.1 | DJ16: 20.1 | DK16: 20 | DL16: 18.9 | DM16: 3.6 | DN16: 18.5 | DO16: 0 | DP16: 0 | DQ16: 1.9 | DR16: 5.5 | DS16: 0 | DT16: 3.2 | DU16: 20.2 | DV16: 3.2 | DX16: 0 | DY16: 19.8 | DZ16: 13 | EA16: 20.2 | EB16: 20.2 | EC16: 0.4 | ED16: 9.3 | EE16: 0 | EF16: 0 | EG16: 0 | EH16: 0 | EI16: 0 | EJ16: 0 | EK16: 0 | EL16: 0 | EN16: 20.4 | EO16: 20.4 | EP16: 20 | EQ16: 0.8 | ER16: 0 | ES16: 0 | ET16: 0 | EU16: 0.6 | EV16: 0 | EW16: 0 | EX16: 0 | EY16: 3 | EZ16: 2.4 | FA16: 2 | FB16: 0.7 | FC16: 0 | FD16: 8.1 | FE16: 20 | FF16: 20 | FG16: 8.5 | FI16: 30.8 | FJ16: 17.2 | FK16: 12.5 | FL16: 7.33 | FM16: 4.97 | FN16: 15.79 | FO16: 6672.625 | FQ16: 24.4113 | FR16: 7.915 | FS16: 9.778 | FT16: 13.2 | FU16: 24.37856 | FV16: 18.9509 | FW16: 11.7 | FX16: 15.8 | FY16: 126.13376
A17: 21/02/2026 | B17: 03:30 | C17: 199.6 | D17: 623.9 | E17: 212.6 | H17: 89.2 | I17: 230.7 | J17: 0 | L17: 114.3 | M17: 114.4 | N17: 114.6 | O17: 214.9 | P17: 108.8 | Q17: 68.1 | R17: 547.5 | S17: 10.1 | T17: 16.3 | X17: 150.2 | Y17: 7.173 | Z17: 5.007 | AA17: 0 | AB17: 6.51 | AD17: 141.69 | AI17: 109.8 | AJ17: 162.1 | AN17: 6.5 | AO17: 459.9 | AP17: 81.4 | AQ17: 150.2 | AR17: 41 | AS17: 18.4 | AT17: 18.8 | AU17: 78.6 | AV17: 177.2 | AW17: 177.8 | AX17: 184 | AY17: 104.9 | AZ17: 42.8 | BA17: 44.7 | BB17: 2 | BC17: 31.5 | BD17: 166.7 | BG17: 61.5 | BJ17: 0 | BN17: 126.1 | BO17: 0 | BP17: 0 | BQ17: 0 | BS17: 39.9 | BT17: 28.1 | BY17: 0 | CA17: 2.1 | CB17: 227.1 | CC17: 115.8 | CD17: 66.2 | CE17: 64.1 | CF17: 29.6 | CJ17: 0 | CL17: 0 | CM17: 0 | CR17: 153.6 | CS17: 85.5 | CT17: 7.3 | CW17: 0 | CX17: 17.4 | CY17: 0 | CZ17: 1.5 | DA17: 0 | DB17: 20.3 | DC17: 10 | DD17: 5.4 | DE17: 0 | DG17: 2.2 | DH17: 2.1 | DI17: 5.1 | DJ17: 20.2 | DK17: 20 | DL17: 18.9 | DM17: 3.6 | DN17: 18.5 | DO17: 0 | DP17: 0 | DQ17: 1.9 | DR17: 4.3 | DS17: 0 | DT17: 3.2 | DU17: 20.1 | DV17: 3.2 | DX17: 0 | DY17: 19.8 | DZ17: 13 | EA17: 20.3 | EB17: 20.2 | EC17: 1.5 | ED17: 11 | EE17: 0 | EF17: 0 | EG17: 0 | EH17: 0 | EI17: 0 | EJ17: 0 | EK17: 0 | EL17: 0 | EN17: 20.4 | EO17: 20.4 | EP17: 20 | EQ17: 1.5 | ER17: 0 | ES17: 0 | ET17: 0 | EU17: 0.6 | EV17: 0 | EW17: 0 | EX17: 0 | EY17: 3 | EZ17: 2.4 | FA17: 2 | FB17: 0.7 | FC17: 0 | FD17: 8.1 | FE17: 19.9 | FF17: 19.8 | FG17: 8.9 | FI17: 30.7 | FJ17: 17.2 | FK17: 12.5 | FL17: 7.21 | FM17: 4.97 | FN17: 15.86 | FO17: 6520.62 | FQ17: 24.41109 | FR17: 7.913 | FS17: 9.742 | FT17: 13.2 | FU17: 24.4672 | FV17: 18.9513 | FW17: 11.7 | FX17: 15.9 | FY17: 126.28459
A18: 21/02/2026 | B18: 04:00 | C18: 202.1 | D18: 634.1 | E18: 216 | H18: 91.2 | I18: 232.7 | J18: 0 | L18: 142.2 | M18: 141.7 | N18: 141.9 | O18: 226.8 | P18: 107.6 | Q18: 68.1 | R18: 561.4 | S18: 10.2 | T18: 16.2 | X18: 166.5 | Y18: 7.596 | Z18: 5.229 | AA18: 0 | AB18: 6.51 | AD18: 143.42 | AI18: 110.1 | AJ18: 195.4 | AN18: 6.5 | AO18: 460.6 | AP18: 81.6 | AQ18: 151.2 | AR18: 42.1 | AS18: 18.4 | AT18: 18.8 | AU18: 91.6 | AV18: 132.9 | AW18: 132.1 | AX18: 162.4 | AY18: 105.7 | AZ18: 43.3 | BA18: 45.9 | BB18: 2 | BC18: 31.8 | BD18: 171.4 | BG18: 63 | BJ18: 0 | BN18: 127.2 | BO18: 0 | BP18: 0 | BQ18: 0 | BS18: 40.4 | BT18: 28.3 | BY18: 0 | CA18: 2.1 | CB18: 270.5 | CC18: 131.8 | CD18: 66.2 | CE18: 64.5 | CF18: 30.1 | CJ18: 0 | CL18: 0 | CM18: 0 | CR18: 137.2 | CS18: 77.6 | CT18: 7.2 | CW18: 0 | CX18: 13.7 | CY18: 0 | CZ18: 1 | DA18: 0 | DB18: 20.2 | DC18: 9.9 | DD18: 5.5 | DE18: 0 | DG18: 2.2 | DH18: 2.5 | DI18: 5.1 | DJ18: 20.2 | DK18: 20 | DL18: 18.9 | DM18: 3.6 | DN18: 18.5 | DO18: 0 | DP18: 0 | DQ18: 1.2 | DR18: 2.9 | DS18: 0 | DT18: 3.2 | DU18: 20.3 | DV18: 3.2 | DX18: 0 | DY18: 19.8 | DZ18: 13 | EA18: 20.4 | EB18: 20.2 | EC18: 0.8 | ED18: 6.4 | EE18: 0 | EF18: 0 | EG18: 0 | EH18: 0 | EI18: 0 | EJ18: 0 | EK18: 0 | EL18: 0 | EN18: 20.4 | EO18: 20.4 | EP18: 20 | EQ18: 1 | ER18: 0 | ES18: 0 | ET18: 0 | EU18: 0.6 | EV18: 0 | EW18: 0 | EX18: 0 | EY18: 3 | EZ18: 2.4 | FA18: 2 | FB18: 0.7 | FC18: 0 | FD18: 8 | FE18: 20.1 | FF18: 20 | FG18: 8.9 | FI18: 31.2 | FJ18: 17.3 | FK18: 12.49 | FL18: 6.76 | FM18: 4.97 | FN18: 16.4 | FO18: 6640.675 | FQ18: 24.41521 | FR18: 7.914 | FS18: 9.72 | FT18: 13.2 | FU18: 24.29612 | FV18: 18.95074 | FW18: 11.7 | FX18: 15.7 | FY18: 125.89607
A19: 21/02/2026 | B19: 04:30 | C19: 206.1 | D19: 636.3 | E19: 216.4 | H19: 92.1 | I19: 235.6 | J19: 0 | L19: 129.8 | M19: 130.4 | N19: 129.3 | O19: 229.7 | P19: 109.4 | Q19: 68.4 | R19: 563.4 | S19: 10.3 | T19: 16.1 | X19: 169.5 | Y19: 7.684 | Z19: 5.837 | AA19: 0 | AB19: 6.51 | AD19: 143.21 | AI19: 110.3 | AJ19: 218.9 | AN19: 6.5 | AO19: 461.4 | AP19: 81.4 | AQ19: 152.4 | AR19: 42.3 | AS19: 18.4 | AT19: 18.8 | AU19: 93.1 | AV19: 125.3 | AW19: 125.8 | AX19: 152.4 | AY19: 106.8 | AZ19: 44.8 | BA19: 46.4 | BB19: 2 | BC19: 31.8 | BD19: 172.2 | BG19: 64.1 | BJ19: 0 | BN19: 128.1 | BO19: 0 | BP19: 0 | BQ19: 0 | BS19: 40.4 | BT19: 28.2 | BY19: 0 | CA19: 2.1 | CB19: 271.4 | CC19: 133.8 | CD19: 66.8 | CE19: 64.6 | CF19: 30.4 | CJ19: 0 | CL19: 0 | CM19: 0 | CR19: 137.2 | CS19: 77.6 | CT19: 7.2 | CW19: 0 | CX19: 18.4 | CY19: 0 | CZ19: 1.6 | DA19: 0 | DB19: 20.5 | DC19: 9.8 | DD19: 5.4 | DE19: 0 | DG19: 2.2 | DH19: 2.6 | DI19: 5 | DJ19: 20.6 | DK19: 20 | DL19: 18.9 | DM19: 3.6 | DN19: 18.5 | DO19: 0 | DP19: 0 | DQ19: 1.5 | DR19: 4.4 | DS19: 0 | DT19: 3.2 | DU19: 20.2 | DV19: 3.2 | DX19: 0 | DY19: 19.8 | DZ19: 13 | EA19: 20.3 | EB19: 20.3 | EC19: 0.1 | ED19: 3.1 | EE19: 0 | EF19: 0 | EG19: 0.2 | EH19: 0 | EI19: 0 | EJ19: 0 | EK19: 0 | EL19: 0 | EN19: 20.4 | EO19: 20.4 | EP19: 20 | EQ19: 1.6 | ER19: 0 | ES19: 0 | ET19: 0 | EU19: 0.6 | EV19: 0 | EW19: 0 | EX19: 0 | EY19: 3 | EZ19: 2.4 | FA19: 2 | FB19: 0.7 | FC19: 0 | FD19: 8 | FE19: 20 | FF19: 20 | FG19: 8.4 | FI19: 30.9 | FJ19: 16.7 | FK19: 12.5 | FL19: 5.92 | FM19: 4.97 | FN19: 16.66 | FO19: 6640.491 | FQ19: 24.41036 | FR19: 7.909 | FS19: 9.684 | FT19: 13.2 | FU19: 24.368 | FV19: 18.95083 | FW19: 11.9 | FX19: 15.8 | FY19: 126.22219
A20: 21/02/2026 | B20: 05:00 | C20: 205.1 | D20: 625.3 | E20: 212.9 | H20: 92.5 | I20: 230.4 | J20: 0 | L20: 111.6 | M20: 112.1 | N20: 111.3 | O20: 224.4 | P20: 109.5 | Q20: 68.3 | R20: 547.1 | S20: 10.5 | T20: 16.4 | X20: 168 | Y20: 7.353 | Z20: 5.704 | AA20: 0 | AB20: 6.48 | AD20: 142.03 | AI20: 110.2 | AJ20: 209.5 | AN20: 6.5 | AO20: 460.4 | AP20: 81.5 | AQ20: 155.1 | AR20: 41.7 | AS20: 18.4 | AT20: 18.8 | AU20: 90.8 | AV20: 162.1 | AW20: 161.8 | AX20: 170.1 | AY20: 105.9 | AZ20: 45.3 | BA20: 45.7 | BB20: 2 | BC20: 31.7 | BD20: 167.9 | BG20: 63.3 | BJ20: 0 | BN20: 127.6 | BO20: 0 | BP20: 0 | BQ20: 0 | BS20: 39.5 | BT20: 28.1 | BY20: 0 | CA20: 2.1 | CB20: 236.8 | CC20: 121.5 | CD20: 66.1 | CE20: 64.6 | CF20: 30.3 | CJ20: 0 | CL20: 0 | CM20: 0 | CR20: 137.2 | CS20: 77.7 | CT20: 7.2 | CW20: 0 | CX20: 25.7 | CY20: 0 | CZ20: 1.6 | DA20: 0 | DB20: 20.3 | DC20: 9.9 | DD20: 5.5 | DE20: 0 | DG20: 2.2 | DH20: 2.6 | DI20: 5 | DJ20: 20.1 | DK20: 20 | DL20: 18.9 | DM20: 3.7 | DN20: 18.5 | DO20: 0 | DP20: 0 | DQ20: 1.8 | DR20: 3.6 | DS20: 0 | DT20: 3.1 | DU20: 20.2 | DV20: 3.2 | DX20: 0 | DY20: 19.8 | DZ20: 13 | EA20: 20.3 | EB20: 20.2 | EC20: 0.4 | ED20: 3.9 | EE20: 0 | EF20: 0 | EG20: 0 | EH20: 0 | EI20: 0 | EJ20: 0 | EK20: 0 | EL20: 0 | EN20: 20.4 | EO20: 20.4 | EP20: 20 | EQ20: 1.6 | ER20: 0 | ES20: 0 | ET20: 0 | EU20: 0.6 | EV20: 0 | EW20: 0 | EX20: 0 | EY20: 3 | EZ20: 2.4 | FA20: 2 | FB20: 0.7 | FC20: 0 | FD20: 8 | FE20: 20 | FF20: 20 | FG20: 8.5 | FI20: 30.7 | FJ20: 16.6 | FK20: 12.51 | FL20: 8.44 | FM20: 4.98 | FN20: 16.2 | FO20: 6574.897 | FQ20: 24.40671 | FR20: 7.909 | FS20: 9.65 | FT20: 13.2 | FU20: 24.40064 | FV20: 18.95075 | FW20: 11.7 | FX20: 15.9 | FY20: 126.1171
A21: 21/02/2026 | B21: 05:30 | C21: 201.3 | D21: 631 | E21: 215.5 | H21: 89.1 | I21: 232.7 | J21: 0 | L21: 126 | M21: 125.9 | N21: 125.9 | O21: 227.4 | P21: 109.3 | Q21: 68.2 | R21: 557 | S21: 10.1 | T21: 16.4 | X21: 164.9 | Y21: 7.384 | Z21: 5.503 | AA21: 0 | AB21: 6.51 | AD21: 142.25 | AI21: 110.3 | AJ21: 213.3 | AN21: 6.5 | AO21: 462.1 | AP21: 81.6 | AQ21: 151.1 | AR21: 41.7 | AS21: 18.4 | AT21: 18.8 | AU21: 88.8 | AV21: 158.3 | AW21: 158.5 | AX21: 171.3 | AY21: 105.9 | AZ21: 43.2 | BA21: 45.7 | BB21: 2 | BC21: 31.1 | BD21: 169.6 | BG21: 62.5 | BJ21: 0 | BN21: 127.1 | BO21: 0 | BP21: 0 | BQ21: 0 | BS21: 40.3 | BT21: 28.2 | BY21: 0 | CA21: 2.1 | CB21: 262.8 | CC21: 129.7 | CD21: 65.7 | CE21: 64.4 | CF21: 30 | CJ21: 0 | CL21: 0 | CM21: 0 | CR21: 137.2 | CS21: 77.6 | CT21: 7.2 | CW21: 0 | CX21: 22 | CY21: 0 | CZ21: 2 | DA21: 0 | DB21: 20.3 | DC21: 10 | DD21: 5.5 | DE21: 0 | DG21: 2.2 | DH21: 2 | DI21: 5.1 | DJ21: 20.4 | DK21: 20 | DL21: 18.9 | DM21: 3.6 | DN21: 18.5 | DO21: 0.1 | DP21: 0 | DQ21: 1.2 | DR21: 4 | DS21: 0 | DT21: 3 | DU21: 20.2 | DV21: 3.2 | DX21: 0 | DY21: 19.8 | DZ21: 13 | EA21: 20.2 | EB21: 20.2 | EC21: 0.1 | ED21: 3 | EE21: 0 | EF21: 0 | EG21: 0 | EH21: 0 | EI21: 0 | EJ21: 0 | EK21: 0 | EL21: 0 | EN21: 20.4 | EO21: 20.4 | EP21: 20 | EQ21: 2 | ER21: 0 | ES21: 0 | ET21: 0 | EU21: 0.6 | EV21: 0 | EW21: 0 | EX21: 0 | EY21: 3 | EZ21: 2.4 | FA21: 2 | FB21: 0.7 | FC21: 0 | FD21: 8 | FE21: 20 | FF21: 20 | FG21: 8.7 | FI21: 30.8 | FJ21: 16.3 | FK21: 11.53 | FL21: 8.12 | FM21: 5.27 | FN21: 17.93 | FO21: 6651.997 | FQ21: 24.40998 | FR21: 7.907 | FS21: 9.61 | FT21: 13.2 | FU21: 24.28266 | FV21: 18.95043 | FW21: 11.9 | FX21: 15.8 | FY21: 126.06007
A22: 21/02/2026 | B22: 06:00 | C22: 200.2 | D22: 631.8 | E22: 213.5 | H22: 89.1 | I22: 231.6 | J22: 0 | L22: 125 | M22: 125.2 | N22: 125.3 | O22: 229.5 | P22: 109.3 | Q22: 68.4 | R22: 558.2 | S22: 10.2 | T22: 16.3 | X22: 164.8 | Y22: 7.154 | Z22: 5.474 | AA22: 0 | AB22: 6.6 | AD22: 142.22 | AI22: 110.4 | AJ22: 215.8 | AN22: 6.5 | AO22: 459.1 | AP22: 81.5 | AQ22: 151.3 | AR22: 41.8 | AS22: 18.4 | AT22: 18.8 | AU22: 89.8 | AV22: 177.9 | AW22: 178.6 | AX22: 180.7 | AY22: 105.6 | AZ22: 43.4 | BA22: 45.3 | BB22: 2 | BC22: 31.4 | BD22: 169.7 | BG22: 62.5 | BJ22: 0 | BN22: 127.1 | BO22: 0 | BP22: 0 | BQ22: 0 | BS22: 40.2 | BT22: 28.1 | BY22: 0 | CA22: 2.1 | CB22: 199 | CC22: 129.7 | CD22: 65.8 | CE22: 64.3 | CF22: 30 | CJ22: 0 | CL22: 0 | CM22: 0 | CR22: 137.2 | CS22: 77.9 | CT22: 7.2 | CW22: 0 | CX22: 18.6 | CY22: 0 | CZ22: 2 | DA22: 0 | DB22: 20.3 | DC22: 10.1 | DD22: 5.5 | DE22: 1.7 | DG22: 2.2 | DH22: 2.1 | DI22: 5.1 | DJ22: 20.3 | DK22: 20 | DL22: 18.9 | DM22: 3.6 | DN22: 18.5 | DO22: 2.1 | DP22: 2.3 | DQ22: 1.1 | DR22: 2.8 | DS22: 1.2 | DT22: 3.2 | DU22: 20.2 | DV22: 3.2 | DX22: 0 | DY22: 19.8 | DZ22: 13 | EA22: 20.3 | EB22: 20.3 | EC22: 0.6 | ED22: 5.6 | EE22: 0 | EF22: 0 | EG22: 0 | EH22: 0 | EI22: 0 | EJ22: 0 | EK22: 0 | EL22: 0 | EN22: 20.4 | EO22: 20.4 | EP22: 20 | EQ22: 2 | ER22: 2.6 | ES22: 0 | ET22: 1 | EU22: 0.6 | EV22: 0 | EW22: 0 | EX22: 1 | EY22: 3 | EZ22: 2.4 | FA22: 2 | FB22: 0.7 | FC22: 0 | FD22: 8 | FE22: 20 | FF22: 20 | FG22: 8.8 | FI22: 30.9 | FJ22: 17 | FK22: 11.44 | FL22: 7.77 | FM22: 5.27 | FN22: 17.96 | FO22: 6646.788 | FQ22: 24.41001 | FR22: 7.906 | FS22: 9.584 | FT22: 13.2 | FU22: 24.36347 | FV22: 18.95045 | FW22: 11.8 | FX22: 15.9 | FY22: 126.11393
... A58: 22/02/2026 | B58: 00:00 | C58: 202.8 | D58: 642 | E58: 216.2 | H58: 89.8 | I58: 159.9 | J58: 0 | L58: 130.5 | M58: 130.7 | N58: 130.8 | O58: 231.3 | P58: 203.8 | Q58: 108 | R58: 557.1 | S58: 10.2 | T58: 0 | X58: 167.1 | Y58: 8.52 | Z58: 6.313 | AA58: 0 | AB58: 6.81 | AD58: 142.67 | AI58: 110.4 | AJ58: 194.7 | AN58: 6.5 | AO58: 461 | AP58: 81.6 | AQ58: 151.6 | AR58: 41.9 | AS58: 18.4 | AT58: 18.8 | AU58: 91.3 | AV58: 180.4 | AW58: 180.7 | AX58: 184.9 | AY58: 106 | AZ58: 44.6 | BA58: 26.1 | BB58: 0 | BC58: 32.4 | BD58: 171.1 | BG58: 94.2 | BJ58: 44 | BN58: 127.4 | BO58: 0 | BP58: 0 | BQ58: 19.1 | BS58: 72.1 | BT58: 35.1 | BY58: 0 | CA58: 2.1 | CB58: 254.6 | CC58: 131.6 | CD58: 62.9 | CE58: 64.3 | CF58: 29.7 | CJ58: 0 | CL58: 0 | CM58: 0 | CR58: 206.2 | CS58: 99.1 | CT58: 7.3 | CW58: 0 | CX58: 27 | CY58: 0 | CZ58: 0 | DA58: 0 | DB58: 20.3 | DC58: 9.9 | DD58: 5.6 | DE58: 0 | DG58: 2.1 | DH58: 2.1 | DI58: 5.1 | DJ58: 20.5 | DK58: 20 | DL58: 18 | DM58: 3.5 | DN58: 18.5 | DO58: 0 | DP58: 0 | DQ58: 4.9 | DR58: 19.9 | DS58: 0 | DT58: 3.2 | DU58: 20.3 | DV58: 3.2 | DX58: 0 | DY58: 19.8 | DZ58: 13 | EA58: 20.3 | EB58: 20.3 | EC58: 0 | ED58: 2.2 | EE58: 0 | EF58: 9.8 | EG58: 33.5 | EH58: 0.4 | EI58: 0 | EJ58: 0 | EK58: 20.9 | EL58: 8.2 | EN58: 20.4 | EO58: 20.4 | EP58: 20 | EQ58: 0.2 | ER58: 0 | ES58: 0 | ET58: 0 | EU58: 0.6 | EV58: 12.1 | EW58: 13.9 | EX58: 0 | EY58: 3 | EZ58: 2.4 | FA58: 2 | FB58: 0.7 | FC58: 0 | FD58: 7.5 | FE58: 20 | FF58: 20 | FG58: 8.8 | FI58: 17.9 | FJ58: 17 | FK58: 13.01 | FL58: 6.74 | FM58: 11 | FN58: 16.32 | FO58: 7083.083 | FQ58: 24.55751 | FR58: 7.879 | FS58: 11.864 | FT58: 0 | FU58: 24.37518 | FV58: 18.95309 | FW58: 11.6 | FX58: 15.3 | FY58: 114.52878
A59: EJEC | C59: 4851.7 | D59: 13850.75 | E59: 4663.9 | F59: 0 | G59: 0 | H59: 2158.45 | I59: 5430.45 | J59: 54 | K59: 0 | L59: 3183.25 | M59: 3205.5 | N59: 3205.25 | O59: 5584.1 | P59: 4006.7 | Q59: 2229.15 | R59: 12876.45 | S59: 244.85 | T59: 146.7 | U59: 0 | V59: 0 | W59: 0 | X59: 3964.15 | Y59: 189.404 | Z59: 142.713 | AA59: 130.7315 | AB59: 131.555 | AC59: 0 | AD59: 3421.115 | AE59: 0 | AF59: 0 | AG59: 0 | AH59: 0 | AI59: 2644.55 | AJ59: 4668.5 | AK59: 0 | AL59: 0 | AM59: 0 | AN59: 156 | AO59: 10945.9 | AP59: 1947.7 | AQ59: 3617.25 | AR59: 999 | AS59: 441.95 | AT59: 451.2 | AU59: 2162.55 | AV59: 4076.5 | AW59: 4080.45 | AX59: 4305.25 | AY59: 2542.65 | AZ59: 1061.05 | BA59: 1042.7 | BB59: 33.6 | BC59: 762.2 | BD59: 4059.2 | BE59: 0 | BF59: 0 | BG59: 1415.3 | BH59: 0 | BI59: 0 | BJ59: 764.35 | BK59: 0 | BL59: 0 | BM59: 0 | BN59: 3052.05 | BO59: 720.2 | BP59: 963 | BQ59: 1855.7 | BR59: 0 | BS59: 1352.3 | BT59: 752.7 | BU59: 0 | BV59: 0 | BW59: 0 | BX59: 0 | BY59: 0.9 | BZ59: 0 | CA59: 50.4 | CB59: 5642.45 | CC59: 3112.05 | CD59: 1528.05 | CE59: 1541.6 | CF59: 672.4 | CG59: 0 | CH59: 0 | CI59: 0 | CJ59: 950.1 | CK59: 0 | CL59: 85.45 | CM59: 721.95 | CN59: 0 | CO59: 0 | CP59: 0 | CQ59: 0 | CR59: 4093.95 | CS59: 2103.85 | CT59: 173.8 | CU59: 0 | CV59: 0 | CW59: 6.8 | CX59: 1131.95 | CY59: 550.3 | CZ59: 31.5 | DA59: 1.75 | DB59: 416.5 | DC59: 238.5 | DD59: 132.25 | DE59: 1320.8 | DF59: 0 | DG59: 52.65 | DH59: 50.7 | DI59: 121.35 | DJ59: 407.15 | DK59: 478.55 | DL59: 451.85 | DM59: 84.8 | DN59: 444 | DO59: 85.35 | DP59: 84.3 | DQ59: 216.4 | DR59: 706.55 | DS59: 134.45 | DT59: 76.05 | DU59: 463.3 | DV59: 76.8 | DW59: 0 | DX59: 2.9 | DY59: 475.4 | DZ59: 275.05 | EA59: 486.4 | EB59: 485.6 | EC59: 24.95 | ED59: 301.8 | EE59: 135.5 | EF59: 620.25 | EG59: 1064.55 | EH59: 76.2 | EI59: 52.4 | EJ59: 182.05 | EK59: 132.9 | EL59: 49.85 | EM59: 0 | EN59: 489.6 | EO59: 489.6 | EP59: 480 | EQ59: 34.35 | ER59: 1614.55 | ES59: 115.75 | ET59: 588.85 | EU59: 12.95 | EV59: 747.7 | EW59: 1009.2 | EX59: 439.75 | EY59: 69.85 | EZ59: 54.45 | FA59: 45.8 | FB59: 16.8 | FC59: 82.45 | FD59: 188.8 | FE59: 480.25 | FF59: 479.9 | FG59: 207.25 | FH59: 0 | FI59: 692.85 | FJ59: 401.25 | FK59: 303.83 | FL59: 185.455 | FM59: 157.67 | FN59: 398.86 | FO59: 177139.78 | FQ59: 584.87208 | FR59: 189.1365 | FS59: 224.527 | FT59: 191.4 | FU59: 577.69539 | FV59: 454.85462 | FW59: 282.75 | FX59: 376.2 | FY59: 2881.4356

Sheet REACTIVA
B3: sábado, 21 de Febrero del 2026
A5: POTENCIA REACTIVA EJECUTADA DE LAS UNIDADES DE GENERACIÓN DEL COES (MVAR) | FQ5: CENTRALES NO INTEGRANTES COES
A6: FECHA | B6: HORA | C6: 65333 | D6: 101 | E6: 102 | F6: 42667 | G6: 42668 | H6: 126 | I6: 127 | J6: 138 | K6: 139 | L6: 197 | M6: 203 | N6: 204 | O6: 230 | P6: 209 | Q6: 56677 | R6: 796 | S6: 2146 | T6: 142 | U6: 143 | V6: 125 | W6: 187 | X6: 163 | Y6: 298 | Z6: 299 | AA6: 219 | AB6: 151 | AC6: 152 | AD6: 153 | AE6: 154 | AF6: 756 | AG6: 156 | AH6: 155 | AI6: 182 | AJ6: 212 | AK6: 758 | AL6: 263 | AM6: 265 | AN6: 775 | AO6: 777 | AP6: 2154 | AQ6: 150 | AR6: 149 | AS6: 188 | AT6: 2131 | AU6: 755 | AV6: 252 | AW6: 249 | AX6: 250 | AY6: 117 | AZ6: 119 | BA6: 120 | BB6: 189 | BC6: 122 | BD6: 266 | BE6: 337 | BF6: 338 | BG6: 251 | BH6: 115 | BI6: 239 | BJ6: 288 | BK6: 240 | BL6: 241 | BM6: 242 | BN6: 191 | BO6: 194 | BP6: 196 | BQ6: 207 | BR6: 236 | BS6: 795 | BT6: 285 | BU6: 995 | BV6: 996 | BW6: 997 | BX6: 766 | BY6: 926 | BZ6: 924 | CA6: 121 | CB6: 103 | CC6: 104 | CD6: 106 | CE6: 105 | CF6: 107 | CG6: 110 | CH6: 109 | CI6: 144 | CJ6: 113 | CK6: 114 | CL6: 193 | CM6: 208 | CN6: 786 | CO6: 787 | CP6: 788 | CQ6: 789 | CR6: 248 | CS6: 2159 | CT6: 267 | CU6: 268 | CV6: 2194 | CW6: 303 | CX6: 59715 | CY6: 62255 | CZ6: 1263 | DA6: 61800 | DB6: 69125 | DC6: 216 | DD6: 198 | DE6: 70400 | DF6: 76068 | DG6: 49607 | DH6: 214 | DI6: 260 | DJ6: 2152 | DK6: 2128 | DL6: 247 | DM6: 228 | DN6: 2135 | DO6: 261 | DP6: 237 | DQ6: 253 | DR6: 770 | DS6: 235 | DT6: 238 | DU6: 2184 | DV6: 61855 | DW6: 223 | DX6: 75566 | DY6: 226 | DZ6: 201 | EA6: 258 | EB6: 259 | EC6: 257 | ED6: 256 | EE6: 2148 | EF6: 58288 | EG6: 58289 | EH6: 58839 | EI6: 58840 | EJ6: 75260 | EK6: 296 | EL6: 297 | EM6: 211 | EN6: 2175 | EO6: 2178 | EP6: 2181 | EQ6: 1262 | ER6: 63425 | ES6: 233 | ET6: 2150 | EU6: 2165 | EV6: 2161 | EW6: 61197 | EX6: 58851 | EY6: 225 | EZ6: 2201 | FA6: 2171 | FB6: 760 | FC6: 234 | FD6: 215 | FE6: 917 | FF6: 920 | FG6: 289 | FH6: 58333 | FI6: 58336 | FJ6: 213 | FK6: 232 | FL6: 2190 | FM6: 69867 | FN6: 75066 | FO6: TOTAL COES | FQ6: 221 | FR6: 222 | FS6: 224 | FT6: 2187 | FU6: 227 | FV6: 49400 | FW6: 199 | FX6: 200 | FY6: TOTAL NO COES
C7: SUR | D7: CENTRO | E7: CENTRO | F7: NORTE | G7: NORTE | H7: NORTE | I7: NORTE | J7: CENTRO | K7: CENTRO | L7: CENTRO | M7: CENTRO | N7: CENTRO | O7: CENTRO | P7: CENTRO | Q7: CENTRO | R7: CENTRO | S7: CENTRO | T7: CENTRO | U7: CENTRO | V7: CENTRO | W7: CENTRO | X7: SUR | Y7: SUR | Z7: SUR | AA7: CENTRO | AB7: SUR | AC7: SUR | AD7: SUR | AE7: SUR | AF7: SUR | AG7: SUR | AH7: SUR | AI7: SUR | AJ7: CENTRO | AK7: NORTE | AL7: NORTE | AM7: NORTE | AN7: CENTRO | AO7: CENTRO | AP7: CENTRO | AQ7: CENTRO | AR7: CENTRO | AS7: CENTRO | AT7: CENTRO | AU7: SUR | AV7: CENTRO | AW7: CENTRO | AX7: CENTRO | AY7: CENTRO | AZ7: CENTRO | BA7: CENTRO | BB7: SUR | BC7: NORTE | BD7: CENTRO | BE7: CENTRO | BF7: CENTRO | BG7: CENTRO | BH7: NORTE | BI7: NORTE | BJ7: NORTE | BK7: SUR | BL7: SUR | BM7: SUR | BN7: CENTRO | BO7: CENTRO | BP7: CENTRO | BQ7: CENTRO | BR7: CENTRO | BS7: CENTRO | BT7: CENTRO | BU7: SUR | BV7: SUR | BW7: SUR | BX7: NORTE | BY7: SUR | BZ7: CENTRO | CA7: NORTE | CB7: CENTRO | CC7: CENTRO | CD7: CENTRO | CE7: CENTRO | CF7: CENTRO | CG7: CENTRO | CH7: CENTRO | CI7: CENTRO | CJ7: CENTRO | CK7: CENTRO | CL7: CENTRO | CM7: CENTRO | CN7: SUR | CO7: SUR | CP7: SUR | CQ7: SUR | CR7: CENTRO | CS7: CENTRO | CT7: CENTRO | CU7: CENTRO | CV7: NORTE | CW7: CENTRO | CX7: CENTRO | CY7: SUR | CZ7: NORTE | DA7: NORTE | DB7: CENTRO | DC7: NORTE | DD7: NORTE | DE7: SUR | DF7: SUR | DG7: SUR | DH7: CENTRO | DI7: CENTRO | DJ7: CENTRO | DK7: NORTE | DL7: NORTE | DM7: CENTRO | DN7: CENTRO | DO7: SUR | DP7: SUR | DQ7: CENTRO | DR7: CENTRO | DS7: SUR | DT7: CENTRO | DU7: CENTRO | DV7: NORTE | DW7: CENTRO | DX7: CENTRO | DY7: CENTRO | DZ7: NORTE | EA7: CENTRO | EB7: CENTRO | EC7: NORTE | ED7: NORTE | EE7: SUR | EF7: CENTRO | EG7: CENTRO | EH7: CENTRO | EI7: CENTRO | EJ7: SUR | EK7: CENTRO | EL7: CENTRO | EM7: SUR | EN7: SUR | EO7: SUR | EP7: SUR | EQ7: NORTE | ER7: SUR | ES7: SUR | ET7: SUR | EU7: CENTRO | EV7: CENTRO | EW7: CENTRO | EX7: SUR | EY7: CENTRO | EZ7: CENTRO | FA7: CENTRO | FB7: CENTRO | FC7: SUR | FD7: NORTE | FE7: CENTRO | FF7: CENTRO | FG7: NORTE | FH7: NORTE | FI7: NORTE | FJ7: CENTRO | FK7: NORTE | FL7: NORTE | FM7: NORTE | FN7: NORTE | FQ7: NORTE | FR7: CENTRO | FS7: NORTE | FT7: NORTE | FU7: NORTE | FV7: NORTE | FW7: NORTE | FX7: NORTE
C8: HIDROELÉCTRICA | D8: HIDROELÉCTRICA | E8: HIDROELÉCTRICA | F8: TERMOELÉCTRICA | G8: TERMOELÉCTRICA | H8: HIDROELÉCTRICA | I8: HIDROELÉCTRICA | J8: TERMOELÉCTRICA | K8: TERMOELÉCTRICA | L8: TERMOELÉCTRICA | M8: TERMOELÉCTRICA | N8: TERMOELÉCTRICA | O8: TERMOELÉCTRICA | P8: TERMOELÉCTRICA | Q8: TERMOELÉCTRICA | R8: HIDROELÉCTRICA | S8: HIDROELÉCTRICA | T8: TERMOELÉCTRICA | U8: TERMOELÉCTRICA | V8: TERMOELÉCTRICA | W8: TERMOELÉCTRICA | X8: HIDROELÉCTRICA | Y8: HIDROELÉCTRICA | Z8: HIDROELÉCTRICA | AA8: TERMOELÉCTRICA | AB8: HIDROELÉCTRICA | AC8: HIDROELÉCTRICA | AD8: HIDROELÉCTRICA | AE8: HIDROELÉCTRICA | AF8: TERMOELÉCTRICA | AG8: TERMOELÉCTRICA | AH8: TERMOELÉCTRICA | AI8: HIDROELÉCTRICA | AJ8: HIDROELÉCTRICA | AK8: TERMOELÉCTRICA | AL8: TERMOELÉCTRICA | AM8: TERMOELÉCTRICA | AN8: HIDROELÉCTRICA | AO8: HIDROELÉCTRICA | AP8: HIDROELÉCTRICA | AQ8: HIDROELÉCTRICA | AR8: HIDROELÉCTRICA | AS8: HIDROELÉCTRICA | AT8: HIDROELÉCTRICA | AU8: HIDROELÉCTRICA | AV8: TERMOELÉCTRICA | AW8: TERMOELÉCTRICA | AX8: TERMOELÉCTRICA | AY8: HIDROELÉCTRICA | AZ8: HIDROELÉCTRICA | BA8: HIDROELÉCTRICA | BB8: HIDROELÉCTRICA | BC8: HIDROELÉCTRICA | BD8: HIDROELÉCTRICA | BE8: HIDROELÉCTRICA | BF8: HIDROELÉCTRICA | BG8: HIDROELÉCTRICA | BH8: TERMOELÉCTRICA | BI8: TERMOELÉCTRICA | BJ8: TERMOELÉCTRICA | BK8: TERMOELÉCTRICA | BL8: TERMOELÉCTRICA | BM8: TERMOELÉCTRICA | BN8: HIDROELÉCTRICA | BO8: TERMOELÉCTRICA | BP8: TERMOELÉCTRICA | BQ8: TERMOELÉCTRICA | BR8: TERMOELÉCTRICA | BS8: TERMOELÉCTRICA | BT8: TERMOELÉCTRICA | BU8: TERMOELÉCTRICA | BV8: TERMOELÉCTRICA | BW8: TERMOELÉCTRICA | BX8: HIDROELÉCTRICA | BY8: TERMOELÉCTRICA | BZ8: TERMOELÉCTRICA | CA8: HIDROELÉCTRICA | CB8: HIDROELÉCTRICA | CC8: HIDROELÉCTRICA | CD8: HIDROELÉCTRICA | CE8: HIDROELÉCTRICA | CF8: HIDROELÉCTRICA | CG8: TERMOELÉCTRICA | CH8: TERMOELÉCTRICA | CI8: TERMOELÉCTRICA | CJ8: TERMOELÉCTRICA | CK8: TERMOELÉCTRICA | CL8: TERMOELÉCTRICA | CM8: TERMOELÉCTRICA | CN8: TERMOELÉCTRICA | CO8: TERMOELÉCTRICA | CP8: TERMOELÉCTRICA | CQ8: TERMOELÉCTRICA | CR8: TERMOELÉCTRICA | CS8: TERMOELÉCTRICA | CT8: HIDROELÉCTRICA | CU8: HIDROELÉCTRICA | CV8: HIDROELÉCTRICA | CW8: SOLAR | CX8: EÓLICA | CY8: SOLAR | CZ8: EÓLICA | DA8: SOLAR | DB8: HIDROELÉCTRICA | DC8: HIDROELÉCTRICA | DD8: HIDROELÉCTRICA | DE8: SOLAR | DF8: SOLAR | DG8: HIDROELÉCTRICA | DH8: HIDROELÉCTRICA | DI8: HIDROELÉCTRICA | DJ8: HIDROELÉCTRICA | DK8: HIDROELÉCTRICA | DL8: HIDROELÉCTRICA | DM8: HIDROELÉCTRICA | DN8: HIDROELÉCTRICA | DO8: SOLAR | DP8: SOLAR | DQ8: EÓLICA | DR8: EÓLICA | DS8: SOLAR | DT8: HIDROELÉCTRICA | DU8: HIDROELÉCTRICA | DV8: HIDROELÉCTRICA | DW8: HIDROELÉCTRICA | DX8: SOLAR | DY8: HIDROELÉCTRICA | DZ8: HIDROELÉCTRICA | EA8: HIDROELÉCTRICA | EB8: HIDROELÉCTRICA | EC8: EÓLICA | ED8: EÓLICA | EE8: SOLAR | EF8: EÓLICA | EG8: EÓLICA | EH8: EÓLICA | EI8: EÓLICA | EJ8: SOLAR | EK8: HIDROELÉCTRICA | EL8: HIDROELÉCTRICA | EM8: HIDROELÉCTRICA | EN8: HIDROELÉCTRICA | EO8: HIDROELÉCTRICA | EP8: HIDROELÉCTRICA | EQ8: EÓLICA | ER8: SOLAR | ES8: SOLAR | ET8: SOLAR | EU8: HIDROELÉCTRICA | EV8: EÓLICA | EW8: EÓLICA | EX8: SOLAR | EY8: TERMOELÉCTRICA | EZ8: TERMOELÉCTRICA | FA8: TERMOELÉCTRICA | FB8: TERMOELÉCTRICA | FC8: SOLAR | FD8: HIDROELÉCTRICA | FE8: HIDROELÉCTRICA | FF8: HIDROELÉCTRICA | FG8: TERMOELÉCTRICA | FH8: TERMOELÉCTRICA | FI8: TERMOELÉCTRICA | FJ8: TERMOELÉCTRICA | FK8: TERMOELÉCTRICA | FL8: TERMOELÉCTRICA | FM8: TERMOELÉCTRICA | FN8: TERMOELÉCTRICA | FQ8: HIDROELÉCTRICA | FR8: HIDROELÉCTRICA | FS8: HIDROELÉCTRICA | FT8: HIDROELÉCTRICA | FU8: TERMOELÉCTRICA | FV8: TERMOELÉCTRICA | FW8: HIDROELÉCTRICA | FX8: HIDROELÉCTRICA
