Workbook

Sheet EVENTOS
B3: viernes, 4 de Julio del 2025
B5: INFORMACIÓN DE EVENTOS PRINCIPALES EN SUS INSTALACIONES
B6: TIPO DE EVENTO | C6: EMPRESA | D6: UBICACIÓN | E6: TIPO DE EQUIPO | F6: EQUIPO | G6: INICIO | H6: FINAL | I6: DESCRIPCIÓN | J6: MW INDISP. | K6: INTERRUPCIÓN (SI/NO) | L6: TENSIÓN DE FALLA (kV)
B7: EVENTO | C7: CONELSUR LT SAC | D7: PORTILLO | E7: SUBESTACION | F7: SS.EE. | G7: 04/07/2025 00:00:00 | H7: 05/07/2025 00:00:00 | I7: DECLARACIÓN DE SITUACIÓN EXCEPCIONAL EN LA S.E. PORTILLO DE 60 kV | K7: NO
B8: FALLA | C8: GM OPERACIONES S.A.C. | D8: REFINERIA TALARA | E8: CENTRAL TERMOELÉCTRICA | F8: CENTRAL | G8: 04/07/2025 20:30:00 | H8: 04/07/2025 20:30:00 | I8: DESCONEXIÓN DE LA C.T. REFINERÍA TALARA POR FALLA EN CALDERA | K8: SI | L8: 13.8
B9: P.ENERG | C9: RED DE ENERGIA DEL PERU S.A. | D9: PIURA OESTE - MIGUEL GRAU | E9: LINEA DE TRANSMISION | F9: L-2143 | G9: 04/07/2025 19:30:00 | H9: 04/07/2025 19:30:00 | I9: PRIMERA ENERGIZACION DE LA LINEA L-2143 (PIURA OESTE - MIGUEL GRAU) DE 220 kV | K9: NO
B10: FALLA | C10: RED DE ENERGIA DEL PERU S.A. | D10: COMBAPATA | E10: TRANSFORMADOR 3D | F10: T46-162 | G10: 04/07/2025 08:38:00 | H10: 04/07/2025 08:52:00 | I10: DESCONEXIÓN DE LA BARRA DE 24 kV DE LA SE COMBAPATA POR FALLA | K10: SI | L10: 0

Sheet RESTRIC_OPE
B3: viernes, 4 de Julio del 2025
B5: RESTRICCIONES OPERATIVAS
B6: FECHA | C6: HORA INICIO | D6: HORA FINAL | E6: EMPRESA | F6: UBICACIÓN | G6: T.Eq. | H6: EQUIPO | I6: DESCRIPCIÓN
B7: 04/07/2025 | C7: 00:00 | D7: 24:00 | E7: EGASA | F7: C.H. CHARCANI II | G7: GH | H7: G2 | I7: El Grupo N°02 esta operando con una potencia no mayor a 0.07MW en referencia a 0.18MW de su potencia efectiva, con el fin de no generar daños mayores hasta la reparación de su cojinete.
B8: 04/07/2025 | C8: 00:00 | D8: 24:00 | E8: EGASA | F8: S.E. CONVERTIDOR | G8: BARRA | H8: BARRA138KV | I8: EGASA limitó la capacidad del transformador 138 kV/33 kV a 50 MVA por deterioro del aislamiento.
B9: 04/07/2025 | C9: 00:00 | D9: 24:00 | E9: ENEL GENERACION PIURA S.A. | F9: C.T. MALACAS | G9: CT | H9: CENTRAL | I9: De acuerdo con la comunicación vía correo del día 24.10.2024. ENEL GENERACIÓN PIURA informa una restricción de potencia para alcanzar 105 MW en simultaneo (TG6+TGN4).
B10: 04/07/2025 | C10: 00:00 | D10: 24:00 | E10: ENEL GENERACION PIURA S.A. | F10: C.T. MALACAS | G10: GT | H10: TG4 | I10: De acuerdo a lo informado mediante correo electronico el día 19.05, la TG4 solo puede operar a máxima generación dos horas y el resto a carga a mínima carga.
B11: 04/07/2025 | C11: 00:00 | D11: 24:00 | E11: ENGIE | F11: C.E. PUNTA LOMITAS | G11: CE | H11: CENTRAL | I11: De acuerdo a la carta ENG/737-2024 (Exp:202400007555). Limitación de cables de media tensión a 100 MW de los transformadores PLT1 y PLT2 de la CE Punta Lomitas. Quedan limitados a 200 MW la generación de CE Punta Lomitas y Punta Lomitas Extensión.
B12: 04/07/2025 | C12: 00:00 | D12: 24:00 | E12: ENGIE | F12: C.H. YUNCÁN | G12: GH | H12: G3 | I12: Según la carta N° ENG/ 198-2024 enviada por su representada, se opera de forma continua el G3 de la CH Yuncán, debido a la ejecución de mantenimientos necesarios para evitar daños en los sellos de seguridad de la válvula esférica del grupo.
B13: 04/07/2025 | C13: 00:00 | D13: 24:00 | E13: ENGIE | F13: C.T. CHILCA 1 | G13: CT | H13: CENTRAL | I13: Restricción de temperatura de la C.T Chilca, ver valor en el modelo de despacho.
B14: 04/07/2025 | C14: 00:00 | D14: 24:00 | E14: ENGIE | F14: C.T. CHILCA 1 | G14: CT | H14: CENTRAL | I14: Con carta ENG/971-2023, indica que no puede cumplir con las IO considerada en el PDO_17122023 dado que vulneran la seguridad de sus activos. Indican que se debe tomar TMO=168h.
B15: 04/07/2025 | C15: 00:00 | D15: 24:00 | E15: ENGIE | F15: C.T. CHILCA 2 | G15: CT | H15: CENTRAL | I15: Restricción de temperatura de la C.T Chilca2, ver valor en el modelo de despacho.
B16: 04/07/2025 | C16: 00:00 | D16: 24:00 | E16: ENGIE | F16: C.T. CHILCA 2 | G16: CT | H16: CENTRAL | I16: Con carta ENG/971-2023, indica que no puede cumplir con las IO considerada en el PDO_17122023 dado que vulneran la seguridad de sus activos. Indican que se debe tomar TMO=168h.
B17: 04/07/2025 | C17: 00:00 | D17: 24:00 | E17: FENIX POWER PERÚ | F17: C.T. FENIX | G17: CT | H17: CENTRAL | I17: De acuerdo con lo comunicado en el correo del día 06.05.2024, la CT Fenix cuenta con TMO de 168 hrs en todos su modos de operación.
... B41: 04/07/2025 | C41: 00:00 | D41: 24:00 | E41: TERMOSELVA | F41: C.T. AGUAYTÍA | G41: CT | H41: CENTRAL | I41: Disponibilidad de 23.5 MMSCF para la CT Aguaytía.

Sheet MANTENIMIENTO EJECUTADOS
B3: viernes, 4 de Julio del 2025
B5: Mantenimiento Ejecutado
B6: Empresa | C6: Ubicación | D6: Equipo | E6: Inicio | F6: Final | G6: Descripción | H6: MW Indisp. | I6: Prog. | J6: Dispon | K6: Interrupc. | L6: Tipo | M6: CodEq | N6: TipoEq_Osinerg
B7: AGROAURORA S.A.C. | C7: MAPLE ETANOL | D7: CENTRAL | E7: 04/07/2025 00:00 | F7: 05/07/2025 00:00 | G7: CENTRAL TERMOELECTRICA FUERA DE SERVICIO POR FALTA DE MATERIA PRIMA PARA LOS REQUERIMIENTOS DE CALOR UTIL EN FABRICA. | H7: 17 | I7: P | J7: F/S | K7: N | L7: OTROS | M7: 13417 | N7: G
B8: ATLANTICA TRANSMISION SUR S.A. | C8: MONTALVO | D8: ACOPLE 220 | E8: 04/07/2025 00:00 | F8: 05/07/2025 00:00 | G8: Proyecto Refuerzos: Reemplazo del HMI existente, Pruebas y Configuracion. No se contara con nivel 1 de operacion. | H8: 0 | I8: P | J8: E/S | K8: N | L8: P.ENERG | M8: 14767 | N8: T
B9: ATLANTICA TRANSMISION SUR S.A. | C9: MONTALVO | D9: BARRA A_220KV | E9: 04/07/2025 00:00 | F9: 05/07/2025 00:00 | G9: Proyecto Refuerzos: Indisponibilidad de la proteccion diferencial de barras 220 kV por Conexion de la nueva UB-87B hacia la UC existente,Configuracion y Pruebas. | H9: 0 | I9: P | J9: E/S | K9: N | L9: P.ENERG | M9: 13869 | N9: T
B10: ATLANTICA TRANSMISION SUR S.A. | C10: MONTALVO | D10: BARRA A_500KV | E10: 04/07/2025 00:00 | F10: 05/07/2025 00:00 | G10: Proyecto Refuerzos: Indisponibilidad de la proteccion diferencial de barras 500kV por conexion de nueva UB-87B hacia la UC existente, Configuracion y Pruebas. | H10: 0 | I10: P | J10: E/S | K10: N | L10: P.ENERG | M10: 13870 | N10: T
B11: ATLANTICA TRANSMISION SUR S.A. | C11: MONTALVO | D11: BARRA B_220kV | E11: 04/07/2025 00:00 | F11: 05/07/2025 00:00 | G11: Proyecto Refuerzos: Indisponibilidad de la proteccion diferencial de barras 220 kV por Conexion de la nueva UB-87B hacia la UC existente,Configuracion y Pruebas. | H11: 0 | I11: P | J11: E/S | K11: N | L11: P.ENERG | M11: 14765 | N11: T
B12: ATLANTICA TRANSMISION SUR S.A. | C12: MONTALVO | D12: BARRA B_500KV | E12: 04/07/2025 00:00 | F12: 05/07/2025 00:00 | G12: Proyecto Refuerzos: Indisponibilidad de la proteccion diferencial de barras 500kV por conexion de nueva UB-87B hacia la UC existente, Configuracion y Pruebas. | H12: 0 | I12: P | J12: E/S | K12: N | L12: P.ENERG | M12: 13871 | N12: T
B13: ATLANTICA TRANSMISION SUR S.A. | C13: MONTALVO | D13: CL-2057 | E13: 04/07/2025 00:00 | F13: 05/07/2025 00:00 | G13: Proyecto Refuerzos: Reemplazo del HMI existente, Pruebas y Configuracion. No se contara con nivel 1 de operacion. | H13: 0 | I13: P | J13: E/S | K13: N | L13: P.ENERG | M13: 13812 | N13: T
B14: ATLANTICA TRANSMISION SUR S.A. | C14: MONTALVO | D14: CL-AUT-5671_500 | E14: 04/07/2025 00:00 | F14: 05/07/2025 00:00 | G14: Proyecto Refuerzos: Reemplazo del HMI existente, Pruebas y Configuracion. No se contara con nivel 1 de operacion en INT-5671, INT-5652 y SAT-5671. | H14: 0 | I14: P | J14: E/S | K14: N | L14: P.ENERG | M14: 13809 | N14: T
B15: ATLANTICA TRANSMISION SUR S.A. | C15: MONTALVO | D15: INT-5652 | E15: 04/07/2025 00:00 | F15: 05/07/2025 00:00 | G15: Proyecto Refuerzos: Indisponible por Implementacion de Conexion de corrientes, disparos, posiciones, enclavamientos hacia los equipos del nuevo Autotransformador. AUT-5671 en servicio solo por Barra A 500kV. | H15: 0 | I15: P | J15: F/S | K15: N | L15: P.ENERG | M15: 13765 | N15: T
B16: ATLANTICA TRANSMISION SUR S.A. | C16: OCONA | D16: INT-5450 | E16: 04/07/2025 00:00 | F16: 05/07/2025 00:00 | G16: Interruptor INT-5450 cerrado con restriccion operativa, REB-5450 en servicio y suministrando los SS.AA. de la S.E. Oco?a. | H16: 0 | I16: P | J16: E/S | K16: N | L16: OTROS | M16: 13761 | N16: T
B17: ATLANTICA TRANSMISION SUR S.A. | C17: OCONA | D17: INT-5462 | E17: 04/07/2025 00:00 | F17: 05/07/2025 00:00 | G17: Seccionador SBA-5462 fase T indisponible por problemas mecanicos, el seccionador permanece cerrado y bloqueado | H17: 0 | I17: P | J17: E/S | K17: N | L17: OTROS | M17: 13758 | N17: T
B18: ATLANTICA TRANSMISION SUR S.A. | C18: POROMA | D18: ACOPLE 220 | E18: 04/07/2025 00:00 | F18: 05/07/2025 00:00 | G18: Proyecto Refuerzos: Reemplazo del HMI existente, Pruebas y Configuracion. No se contara con nivel 1 de operacion. | H18: 0 | I18: P | J18: E/S | K18: N | L18: P.ENERG | M18: 13797 | N18: T
... B147: VARI ENERGIA S.A.C. | C147: ANASHIRONI | D147: G1 | E147: 04/07/2025 15:19 | F147: 04/07/2025 18:00 | G147: * Pruebas de regulacion grupo generador Anashironi Subir y bajar potencia entre 2 y 20MW * Culminada las pruebas CH ANASHIRONI queda en servicio (segun disponibilidad hidrica) maximo hasta 15 MW por restriccion EDAG. | H147: 0 | I147: P | J147: E/S | K147: N | L147: PRUEBA | M147: 24348 | N147: G

Sheet INGRESO OC
A3: viernes, 4 de Julio del 2025
A5: INGRESO A OPERACIÓN COMERCIAL
A6: EMPRESA | B6: TIPO DE EQUIPO | C6: UBICACIÓN | D6: EQUIPO | E6: Fecha y hora de Ingreso a Operación Comercial

Sheet DESPACHO_EJECUTADO
B3: viernes, 4 de Julio del 2025
A5: POTENCIA ACTIVA EJECUTADA DE LAS UNIDADES DE GENERACIÓN DEL SEIN (MW) | FL5: CENTRALES NO INTEGRANTES COES
A6: FECHA | B6: HORA | C6: 65333 | D6: 101 | E6: 102 | F6: 42667 | G6: 42668 | H6: 126 | I6: 127 | J6: 138 | K6: 139 | L6: 197 | M6: 203 | N6: 204 | O6: 230 | P6: 209 | Q6: 56677 | R6: 796 | S6: 2146 | T6: 142 | U6: 143 | V6: 125 | W6: 187 | X6: 163 | Y6: 298 | Z6: 299 | AA6: 219 | AB6: 151 | AC6: 152 | AD6: 153 | AE6: 154 | AF6: 756 | AG6: 156 | AH6: 155 | AI6: 182 | AJ6: 212 | AK6: 758 | AL6: 263 | AM6: 265 | AN6: 775 | AO6: 777 | AP6: 2154 | AQ6: 150 | AR6: 149 | AS6: 188 | AT6: 2131 | AU6: 755 | AV6: 252 | AW6: 249 | AX6: 250 | AY6: 117 | AZ6: 267 | BA6: 268 | BB6: 119 | BC6: 120 | BD6: 189 | BE6: 122 | BF6: 266 | BG6: 337 | BH6: 338 | BI6: 251 | BJ6: 115 | BK6: 239 | BL6: 288 | BM6: 240 | BN6: 241 | BO6: 242 | BP6: 191 | BQ6: 194 | BR6: 196 | BS6: 207 | BT6: 236 | BU6: 795 | BV6: 285 | BW6: 995 | BX6: 996 | BY6: 997 | BZ6: 766 | CA6: 926 | CB6: 924 | CC6: 121 | CD6: 103 | CE6: 104 | CF6: 106 | CG6: 105 | CH6: 107 | CI6: 110 | CJ6: 109 | CK6: 144 | CL6: 113 | CM6: 114 | CN6: 193 | CO6: 208 | CP6: 786 | CQ6: 787 | CR6: 788 | CS6: 789 | CT6: 248 | CU6: 2159 | CV6: 303 | CW6: 59715 | CX6: 62255 | CY6: 1263 | CZ6: 61800 | DA6: 2194 | DB6: 216 | DC6: 198 | DD6: 49607 | DE6: 214 | DF6: 260 | DG6: 2152 | DH6: 2128 | DI6: 247 | DJ6: 228 | DK6: 2135 | DL6: 261 | DM6: 237 | DN6: 253 | DO6: 770 | DP6: 225 | DQ6: 2201 | DR6: 2171 | DS6: 760 | DT6: 235 | DU6: 238 | DV6: 2184 | DW6: 61855 | DX6: 223 | DY6: 226 | DZ6: 201 | EA6: 258 | EB6: 259 | EC6: 920 | ED6: 257 | EE6: 256 | EF6: 2148 | EG6: 58288 | EH6: 58289 | EI6: 58839 | EJ6: 58840 | EK6: 296 | EL6: 297 | EM6: 211 | EN6: 2175 | EO6: 2178 | EP6: 2181 | EQ6: 1262 | ER6: 63425 | ES6: 233 | ET6: 2150 | EU6: 2165 | EV6: 2161 | EW6: 61197 | EX6: 58851 | EY6: 234 | EZ6: 215 | FA6: 917 | FB6: 289 | FC6: 58333 | FD6: 58336 | FE6: 213 | FF6: 232 | FG6: 2190 | FH6: 202 | FI6: 58487 | FJ6: TOTAL COES | FL6: 221 | FM6: 222 | FN6: 224 | FO6: 2187 | FP6: 227 | FQ6: 49400 | FR6: 199 | FS6: 200 | FT6: TOTAL NO COES
C7: SUR | D7: CENTRO | E7: CENTRO | F7: NORTE | G7: NORTE | H7: NORTE | I7: NORTE | J7: CENTRO | K7: CENTRO | L7: CENTRO | M7: CENTRO | N7: CENTRO | O7: CENTRO | P7: CENTRO | Q7: CENTRO | R7: CENTRO | S7: CENTRO | T7: CENTRO | U7: CENTRO | V7: CENTRO | W7: CENTRO | X7: SUR | Y7: SUR | Z7: SUR | AA7: CENTRO | AB7: SUR | AC7: SUR | AD7: SUR | AE7: SUR | AF7: SUR | AG7: SUR | AH7: SUR | AI7: SUR | AJ7: CENTRO | AK7: NORTE | AL7: NORTE | AM7: NORTE | AN7: CENTRO | AO7: CENTRO | AP7: CENTRO | AQ7: CENTRO | AR7: CENTRO | AS7: CENTRO | AT7: CENTRO | AU7: SUR | AV7: CENTRO | AW7: CENTRO | AX7: CENTRO | AY7: CENTRO | AZ7: CENTRO | BA7: CENTRO | BB7: CENTRO | BC7: CENTRO | BD7: SUR | BE7: NORTE | BF7: CENTRO | BG7: CENTRO | BH7: CENTRO | BI7: CENTRO | BJ7: NORTE | BK7: NORTE | BL7: NORTE | BM7: SUR | BN7: SUR | BO7: SUR | BP7: CENTRO | BQ7: CENTRO | BR7: CENTRO | BS7: CENTRO | BT7: CENTRO | BU7: CENTRO | BV7: CENTRO | BW7: SUR | BX7: SUR | BY7: SUR | BZ7: NORTE | CA7: SUR | CB7: CENTRO | CC7: NORTE | CD7: CENTRO | CE7: CENTRO | CF7: CENTRO | CG7: CENTRO | CH7: CENTRO | CI7: CENTRO | CJ7: CENTRO | CK7: CENTRO | CL7: CENTRO | CM7: CENTRO | CN7: CENTRO | CO7: CENTRO | CP7: SUR | CQ7: SUR | CR7: SUR | CS7: SUR | CT7: CENTRO | CU7: CENTRO | CV7: CENTRO | CW7: CENTRO | CX7: SUR | CY7: NORTE | CZ7: NORTE | DA7: NORTE | DB7: NORTE | DC7: NORTE | DD7: SUR | DE7: CENTRO | DF7: CENTRO | DG7: CENTRO | DH7: NORTE | DI7: NORTE | DJ7: CENTRO | DK7: CENTRO | DL7: SUR | DM7: SUR | DN7: CENTRO | DO7: CENTRO | DP7: CENTRO | DQ7: CENTRO | DR7: CENTRO | DS7: CENTRO | DT7: SUR | DU7: CENTRO | DV7: CENTRO | DW7: NORTE | DX7: CENTRO | DY7: CENTRO | DZ7: NORTE | EA7: CENTRO | EB7: CENTRO | EC7: CENTRO | ED7: NORTE | EE7: NORTE | EF7: SUR | EG7: CENTRO | EH7: CENTRO | EI7: CENTRO | EJ7: CENTRO | EK7: CENTRO | EL7: CENTRO | EM7: SUR | EN7: SUR | EO7: SUR | EP7: SUR | EQ7: NORTE | ER7: SUR | ES7: SUR | ET7: SUR | EU7: CENTRO | EV7: CENTRO | EW7: CENTRO | EX7: SUR | EY7: SUR | EZ7: NORTE | FA7: CENTRO | FB7: NORTE | FC7: NORTE | FD7: NORTE | FE7: CENTRO | FF7: NORTE | FG7: NORTE | FH7: CENTRO | FI7: CENTRO | FL7: NORTE | FM7: CENTRO | FN7: NORTE | FO7: NORTE | FP7: NORTE | FQ7: NORTE | FR7: NORTE | FS7: NORTE
C8: HIDROELÉCTRICA | D8: HIDROELÉCTRICA | E8: HIDROELÉCTRICA | F8: TERMOELÉCTRICA | G8: TERMOELÉCTRICA | H8: HIDROELÉCTRICA | I8: HIDROELÉCTRICA | J8: TERMOELÉCTRICA | K8: TERMOELÉCTRICA | L8: TERMOELÉCTRICA | M8: TERMOELÉCTRICA | N8: TERMOELÉCTRICA | O8: TERMOELÉCTRICA | P8: TERMOELÉCTRICA | Q8: TERMOELÉCTRICA | R8: HIDROELÉCTRICA | S8: HIDROELÉCTRICA | T8: TERMOELÉCTRICA | U8: TERMOELÉCTRICA | V8: TERMOELÉCTRICA | W8: TERMOELÉCTRICA | X8: HIDROELÉCTRICA | Y8: HIDROELÉCTRICA | Z8: HIDROELÉCTRICA | AA8: TERMOELÉCTRICA | AB8: HIDROELÉCTRICA | AC8: HIDROELÉCTRICA | AD8: HIDROELÉCTRICA | AE8: HIDROELÉCTRICA | AF8: TERMOELÉCTRICA | AG8: TERMOELÉCTRICA | AH8: TERMOELÉCTRICA | AI8: HIDROELÉCTRICA | AJ8: HIDROELÉCTRICA | AK8: TERMOELÉCTRICA | AL8: TERMOELÉCTRICA | AM8: TERMOELÉCTRICA | AN8: HIDROELÉCTRICA | AO8: HIDROELÉCTRICA | AP8: HIDROELÉCTRICA | AQ8: HIDROELÉCTRICA | AR8: HIDROELÉCTRICA | AS8: HIDROELÉCTRICA | AT8: HIDROELÉCTRICA | AU8: HIDROELÉCTRICA | AV8: TERMOELÉCTRICA | AW8: TERMOELÉCTRICA | AX8: TERMOELÉCTRICA | AY8: HIDROELÉCTRICA | AZ8: HIDROELÉCTRICA | BA8: HIDROELÉCTRICA | BB8: HIDROELÉCTRICA | BC8: HIDROELÉCTRICA | BD8: HIDROELÉCTRICA | BE8: HIDROELÉCTRICA | BF8: HIDROELÉCTRICA | BG8: HIDROELÉCTRICA | BH8: HIDROELÉCTRICA | BI8: HIDROELÉCTRICA | BJ8: TERMOELÉCTRICA | BK8: TERMOELÉCTRICA | BL8: TERMOELÉCTRICA | BM8: TERMOELÉCTRICA | BN8: TERMOELÉCTRICA | BO8: TERMOELÉCTRICA | BP8: HIDROELÉCTRICA | BQ8: TERMOELÉCTRICA | BR8: TERMOELÉCTRICA | BS8: TERMOELÉCTRICA | BT8: TERMOELÉCTRICA | BU8: TERMOELÉCTRICA | BV8: TERMOELÉCTRICA | BW8: TERMOELÉCTRICA | BX8: TERMOELÉCTRICA | BY8: TERMOELÉCTRICA | BZ8: HIDROELÉCTRICA | CA8: TERMOELÉCTRICA | CB8: TERMOELÉCTRICA | CC8: HIDROELÉCTRICA | CD8: HIDROELÉCTRICA | CE8: HIDROELÉCTRICA | CF8: HIDROELÉCTRICA | CG8: HIDROELÉCTRICA | CH8: HIDROELÉCTRICA | CI8: TERMOELÉCTRICA | CJ8: TERMOELÉCTRICA | CK8: TERMOELÉCTRICA | CL8: TERMOELÉCTRICA | CM8: TERMOELÉCTRICA | CN8: TERMOELÉCTRICA | CO8: TERMOELÉCTRICA | CP8: TERMOELÉCTRICA | CQ8: TERMOELÉCTRICA | CR8: TERMOELÉCTRICA | CS8: TERMOELÉCTRICA | CT8: TERMOELÉCTRICA | CU8: TERMOELÉCTRICA | CV8: SOLAR | CW8: EÓLICA | CX8: SOLAR | CY8: EÓLICA | CZ8: SOLAR | DA8: HIDROELÉCTRICA | DB8: HIDROELÉCTRICA | DC8: HIDROELÉCTRICA | DD8: HIDROELÉCTRICA | DE8: HIDROELÉCTRICA | DF8: HIDROELÉCTRICA | DG8: HIDROELÉCTRICA | DH8: HIDROELÉCTRICA | DI8: HIDROELÉCTRICA | DJ8: HIDROELÉCTRICA | DK8: HIDROELÉCTRICA | DL8: SOLAR | DM8: SOLAR | DN8: EÓLICA | DO8: EÓLICA | DP8: TERMOELÉCTRICA | DQ8: TERMOELÉCTRICA | DR8: TERMOELÉCTRICA | DS8: TERMOELÉCTRICA | DT8: SOLAR | DU8: HIDROELÉCTRICA | DV8: HIDROELÉCTRICA | DW8: HIDROELÉCTRICA | DX8: HIDROELÉCTRICA | DY8: HIDROELÉCTRICA | DZ8: HIDROELÉCTRICA | EA8: HIDROELÉCTRICA | EB8: HIDROELÉCTRICA | EC8: HIDROELÉCTRICA | ED8: EÓLICA | EE8: EÓLICA | EF8: SOLAR | EG8: EÓLICA | EH8: EÓLICA | EI8: EÓLICA | EJ8: EÓLICA | EK8: HIDROELÉCTRICA | EL8: HIDROELÉCTRICA | EM8: HIDROELÉCTRICA | EN8: HIDROELÉCTRICA | EO8: HIDROELÉCTRICA | EP8: HIDROELÉCTRICA | EQ8: EÓLICA | ER8: SOLAR | ES8: SOLAR | ET8: SOLAR | EU8: HIDROELÉCTRICA | EV8: EÓLICA | EW8: EÓLICA | EX8: SOLAR | EY8: SOLAR | EZ8: HIDROELÉCTRICA | FA8: HIDROELÉCTRICA | FB8: TERMOELÉCTRICA | FC8: TERMOELÉCTRICA | FD8: TERMOELÉCTRICA | FE8: TERMOELÉCTRICA | FF8: TERMOELÉCTRICA | FG8: TERMOELÉCTRICA | FH8: TERMOELÉCTRICA | FI8: TERMOELÉCTRICA | FL8: HIDROELÉCTRICA | FM8: HIDROELÉCTRICA | FN8: HIDROELÉCTRICA | FO8: HIDROELÉCTRICA | FP8: TERMOELÉCTRICA | FQ8: TERMOELÉCTRICA | FR8: HIDROELÉCTRICA | FS8: HIDROELÉCTRICA
C9: HYDRO GLOBAL PERÚ S.A.C. | D9: ELECTROPERU | E9: ELECTROPERU | F9: ELECTROPERU | G9: ELECTROPERU | H9: ORAZUL ENERGY PERÚ | I9: ORAZUL ENERGY PERÚ | J9: TERMOSELVA | K9: TERMOSELVA | L9: KALLPA GENERACION S.A. | M9: KALLPA GENERACION S.A. | N9: KALLPA GENERACION S.A. | O9: KALLPA GENERACION S.A. | P9: KALLPA GENERACION S.A. | Q9: KALLPA GENERACION S.A. | R9: KALLPA GENERACION S.A. | S9: KALLPA GENERACION S.A. | T9: SHOUGESA | U9: SHOUGESA | V9: SHOUGESA | W9: SHOUGESA | X9: EGEMSA | Y9: EGESUR | Z9: EGESUR | AA9: EGESUR | AB9: EGASA | AC9: EGASA | AD9: EGASA | AE9: EGASA | AF9: EGASA | AG9: EGASA | AH9: EGASA | AI9: SAN GABAN | AJ9: CELEPSA | AK9: MINERA CERRO VERDE | AL9: PLANTA DE RESERVA FRIA DE GENERACION DE ETEN S.A. | AM9: PLANTA DE RESERVA FRIA DE GENERACION DE ETEN S.A. | AN9: EMPRESA DE GENERACION HUALLAGA | AO9: EMPRESA DE GENERACION HUALLAGA | AP9: LA VIRGEN | AQ9: CHINANGO S.A.C. | AR9: CHINANGO S.A.C. | AS9: HIDROELECTRICA HUANCHOR S.A.C. | AT9: CELEPSA RENOVABLES S.R.L. | AU9: INLAND ENERGY SAC | AV9: FENIX POWER PERÚ | AW9: FENIX POWER PERÚ | AX9: FENIX POWER PERÚ | AY9: STATKRAFT S.A | AZ9: STATKRAFT S.A | BA9: STATKRAFT S.A | BB9: STATKRAFT S.A | BC9: STATKRAFT S.A | BD9: STATKRAFT S.A | BE9: STATKRAFT S.A | BF9: STATKRAFT S.A | BG9: CENTRALES SANTA ROSA S.A.C. | BH9: CENTRALES SANTA ROSA S.A.C. | BI9: EMPRESA DE GENERACION HUANZA | BJ9: ENEL GENERACION PIURA S.A. | BK9: ENEL GENERACION PIURA S.A. | BL9: ENEL GENERACION PIURA S.A. | BM9: ENGIE | BN9: ENGIE | BO9: ENGIE | BP9: ENGIE | BQ9: ENGIE | BR9: ENGIE | BS9: ENGIE | BT9: ENGIE | BU9: ENGIE | BV9: ENGIE | BW9: ENGIE | BX9: ENGIE | BY9: ENGIE | BZ9: ENGIE | CA9: INFRAESTRUCTURAS Y ENERGIAS DEL PERU S.A.C. | CB9: INFRAESTRUCTURAS Y ENERGIAS DEL PERU S.A.C. | CC9: INVERSIONES SHAQSHA S.A.C. | CD9: ORYGEN PERU S.A.A. | CE9: ORYGEN PERU S.A.A. | CF9: ORYGEN PERU S.A.A. | CG9: ORYGEN PERU S.A.A. | CH9: ORYGEN PERU S.A.A. | CI9: ORYGEN PERU S.A.A. | CJ9: ORYGEN PERU S.A.A. | CK9: ORYGEN PERU S.A.A. | CL9: ORYGEN PERU S.A.A. | CM9: ORYGEN PERU S.A.A. | CN9: ORYGEN PERU S.A.A. | CO9: ORYGEN PERU S.A.A. | CP9: SAMAY I S.A.C | CQ9: SAMAY I S.A.C | CR9: SAMAY I S.A.C | CS9: SAMAY I S.A.C | CT9: TERMOCHILCA S.A.C. | CU9: TERMOCHILCA S.A.C. | CV9: COLCA SOLAR S.A.C. | CW9: ENERGIA RENOVABLE DEL SUR S.A. | CX9: GR CORTARRAMA SOCIEDAD ANONIMA CERRADA | CY9: GR TARUCA SOCIEDAD ANONIMA CERRADA | CZ9: KONDU SAC | DA9: PERUANA DE INVERSIONES EN ENERGIAS RENOVABLES S.A. | DB9: ORAZUL ENERGY PERÚ | DC9: ORAZUL ENERGY PERÚ | DD9: SAN GABAN | DE9: MAJA ENERGIA S.A.C. | DF9: EMPRESA DE GENERACION ELECTRICA CANCHAYLLO SAC | DG9: EMPRESA DE GENERACION ELECTRICA SANTA ANA S.A.C. | DH9: EMPRESA ELECTRICA AGUA AZUL | DI9: EMPRESA ELECTRICA RIO DOBLE | DJ9: HIDROCAÑETE S.A. | DK9: HUAURA POWER GROUP S.A. | DL9: MOQUEGUA FV S.A.C. | DM9: PANAMERICANA SOLAR SAC. | DN9: PARQUE EOLICO MARCONA S.A.C. | DO9: PARQUE EOLICO TRES HERMANAS S.A.C. | DP9: PETRAMAS | DQ9: PETRAMAS | DR9: PETRAMAS | DS9: PETRAMAS | DT9: TACNA SOLAR SAC. | DU9: ELECTRICA YANAPAMPA SAC | DV9: ANDEAN POWER S.A.C. | DW9: ASOCIACIÓN SANTA LUCIA DE CHACAS | DX9: ATRIA ENERGIA S.A.C. | DY9: EGEJUNIN | DZ9: EGEJUNIN | EA9: EGEJUNIN | EB9: EGEJUNIN | EC9: EMPRESA DE GENERACION ELECTRICA RIO BAÑOS S.A.C. | ED9: ENERGÍA EÓLICA S.A. | EE9: ENERGÍA EÓLICA S.A. | EF9: ENGIE | EG9: ENGIE | EH9: ENGIE | EI9: ENGIE | EJ9: ENGIE | EK9: GENERACIÓN ANDINA S.A.C. | EL9: GENERACIÓN ANDINA S.A.C. | EM9: GENERADORA DE ENERGÍA DEL PERÚ | EN9: GENERADORA DE ENERGÍA DEL PERÚ | EO9: GENERADORA DE ENERGÍA DEL PERÚ | EP9: GENERADORA DE ENERGÍA DEL PERÚ | EQ9: GR PAINO SOCIEDAD ANONIMA CERRADA | ER9: JOYA SOLAR S.A.C. | ES9: MAJES ARCUS S.A.C. | ET9: ORYGEN PERU S.A.A. | EU9: ORYGEN PERU S.A.A. | EV9: ORYGEN PERU S.A.A. | EW9: ORYGEN PERU S.A.A. | EX9: ORYGEN PERU S.A.A. | EY9: REPARTICIÓN ARCUS S.A.C. | EZ9: SINERSA | FA9: SINERSA | FB9: BIOENERGIA DEL CHIRA S.A. | FC9: GM OPERACIONES S.A.C. | FD9: GM OPERACIONES S.A.C. | FE9: AGRO INDUSTRIAL PARAMONGA S.A. | FF9: AGROAURORA S.A.C. | FG9: AGROINDUSTRIAS SAN JACINTO S.A.A. | FH9: SDF ENERGIA SAC | FI9: SDF ENERGIA SAC | FL9: UNACEM PERU S.A. | FM9: ELECTRO ORIENTE | FN9: AGUAS Y ENERGIA PERU | FO9: ELECTRO ZAÑA S.A.C. | FP9: ELECTRONOROESTE S.A. | FQ9: SDE PIURA | FR9: SINERSA | FS9: SINERSA
C10: SAN GABAN III | D10: MANTARO | E10: RESTITUCION | F10: TUMBES MAK 1 | G10: TUMBES MAK 2 | H10: CARHUAQUERO | I10: CAÑON DEL PATO | J10: AGUAYTIA TG1 | K10: AGUAYTIA TG2 | L10: KALLPA TG1 | M10: KALLPA TG2 | N10: KALLPA TG3 | O10: KALLPA TV | P10: LFLORES TG1 | Q10: LFLORES TV | R10: CERRO DEL AGUILA | S10: CERRODELAGUILAG4 | T10: SHOUGESA TV1 | U10: SHOUGESA TV2 | V10: SHOUGESA TV3 | W10: SHOUGESA CUMMINS | X10: MACHUPICCHU | Y10: ARICOTA 1 | Z10: ARICOTA 2 | AA10: INDEPENDENCIA | AB10: CHARCANI I,II,III | AC10: CHARCANI IV | AD10: CHARCANI V | AE10: CHARCANI VI | AF10: CHILINA TG | AG10: MOLLENDO 1, 2, 3 | AH10: CHILINA (SULZ 1,2) | AI10: SAN GABAN II | AJ10: PLATANAL | AK10: RECKA | AL10: RF ETEN TG1 | AM10: RF ETEN TG2 | AN10: CHAGLLA GP1 | AO10: CHAGLLA | AP10: LA VIRGEN | AQ10: CHIMAY | AR10: YANANGO | AS10: HUANCHOR | AT10: MARAÑON | AU10: STA TERESA | AV10: FENIX GT11 | AW10: FENIX GT12 | AX10: FENIX TV10 | AY10: YAUPI | AZ10: OROYA | BA10: PACHACHACA | BB10: MALPASO | BC10: CAHUA | BD10: ARCATA | BE10: GALLITO CIEGO | BF10: CHEVES | BG10: SANTA ROSA 1 | BH10: SANTA ROSA 2 | BI10: HUANZA | BJ10: MALACAS2 TG4 | BK10: MALACAS3 TG 5 | BL10: MALACAS1 TG6 | BM10: RF ILO2 TG1 | BN10: RF ILO2 TG2 | BO10: RF ILO2 TG3 | BP10: YUNCAN | BQ10: CHILCA1 TG1 | BR10: CHILCA1 TG2 | BS10: CHILCA1 TG3 | BT10: CHILCA-TV | BU10: CHILCA2 TG41 | BV10: CHILCA2-TV | BW10: CTNEPI_TG41 | BX10: CTNEPI_TG42 | BY10: CTNEPI_TG43 | BZ10: QUITARACSA | CA10: RF PTO MALDONADO | CB10: RF PUCALLPA | CC10: PARIAC | CD10: HUINCO | CE10: MATUCANA | CF10: MOYOPAMPA | CG10: CALLAHUANCA | CH10: HUAMPANI | CI10: STA ROSA WEST TG7 | CJ10: UTI_5 | CK10: UTI_6 | CL10: VENTANILLA 3 | CM10: VENTANILLA 4 | CN10: VENTANILLA TV | CO10: STAROSA TG8 | CP10: PTO_BRVO TG1 | CQ10: PTO_BRVO TG2 | CR10: PTO_BRVO TG3 | CS10: PTO_BRVO TG4 | CT10: OLLEROS TG1 | CU10: OLLEROS TV | CV10: CS YARUCAYA | CW10: SAN JUAN | CX10: MATARANI | CY10: DUNA | CZ10: CARHUAQUERO (CS) | DA10: MANTA I | DB10: CARHUAQUERO4 | DC10: CAÑA BRAVA | DD10: TUPURI | DE10: RONCADOR | DF10: CANCHAYLLO | DG10: RENOVANDESH1 | DH10: POTRERO | DI10: PIZARRAS | DJ10: NIMPERIAL | DK10: YARUCAYA | DL10: MOQUEGUA-SOLAR | DM10: PANAMERICANA-SOLAR | DN10: PQE-EOLICO-MARCONA | DO10: PQE-EOLICO-3-HERMANAS | DP10: HUAYCOLORO | DQ10: CALLAO | DR10: DONA_CATALINA | DS10: LAGRINGAV | DT10: TACNA-SOLAR | DU10: YANAPAMPA | DV10: CARHUAC | DW10: HUALLIN | DX10: PURMACANA | DY10: HUASAHUASI | DZ10: STACRUZ_1_2 | EA10: RUNATULLO_II | EB10: RUNATULLO_III | EC10: RUCUY | ED10: PQE-EOLICO-TALARA | EE10: PQE-EOLICO-CUPISNIQUE | EF10: INTIPAMPA | EG10: PUNTA LOMITAS-BL1 | EH10: PUNTA LOMITAS-BL2 | EI10: PUN LOMITAS_EXP-BL1 | EJ10: PUN LOMITAS_EXP-BL2 | EK10: 8AGOSTO | EL10: EL CARMEN | EM10: LA JOYA | EN10: ANGEL_I | EO10: ANGEL_II | EP10: ANGEL_III | EQ10: HUAMBOS | ER10: SAN MARTIN SOLAR | ES10: MAJES | ET10: RUBI | EU10: CH_HER1 | EV10: WAYRA-I | EW10: WAYRA EXTENSION | EX10: CLEMESI | EY10: REPARTICION | EZ10: POECHOS2 | FA10: CHANCAY | FB10: CANA BRAVA | FC10: REFINERIA TALARA TV1 | FD10: REFINERÍA TALARA TV2 | FE10: PARAMONGA | FF10: MAPLE | FG10: SAN_JACINTO | FH10: OQUENDO TG1 | FI10: OQUENDO TV1 | FJ10: MW | FL10: CARPAPATA | FM10: CENTRALES ELOR | FN10: PIAS1 | FO10: ZANA | FP10: TABLAZO | FQ10: TALLANCA | FR10: CURUMUY | FS10: POECHOS1 | FT10: MW
A11: 04/07/2025 | B11: 00:30 | C11: 144.6 | D11: 596.7 | E11: 201.81 | H11: 60.1 | I11: 87.2 | L11: 188.9 | M11: 201.8 | N11: 201.4 | O11: 288 | P11: 216.8 | Q11: 111.7 | R11: 451.1 | S11: 4.3 | X11: 127.6 | Y11: 7.5 | Z11: 5.2 | AB11: 6.8 | AC11: 12.4 | AD11: 84 | AI11: 45.3 | AJ11: 109.8 | AN11: 6.4 | AO11: 0 | AP11: 41.1 | AQ11: 55.8 | AR11: 27.5 | AS11: 18 | AT11: 19.7 | AU11: 70.1 | AV11: 182.559 | AW11: 182.833 | AX11: 184.041 | AY11: 86.2 | AZ11: 6.3 | BA11: 1.5 | BB11: 33.7 | BC11: 30.4 | BD11: 3.8 | BE11: 0 | BF11: 40.6 | BI11: 14.5 | BL11: 0 | BP11: 65.7 | BQ11: 177.9 | BR11: 176.1 | BS11: 200 | BT11: 274.8 | BZ11: 0 | CC11: 1.2 | CD11: 91.1 | CE11: 84.3 | CF11: 64.5 | CG11: 70.6 | CH11: 29.3 | CL11: 146.4 | CM11: 148.8 | CN11: 150.6 | CT11: 147.5 | CU11: 79.4 | CV11: 0 | CW11: 0.1 | CX11: 0 | CY11: 15.6 | CZ11: 0 | DA11: 11.3 | DB11: 9.9 | DC11: 4.9 | DD11: 0.4 | DE11: 2.7 | DF11: 2.6 | DG11: 19.9 | DH11: 13.2 | DI11: 8.9 | DJ11: 3.3 | DK11: 18.5 | DL11: 0 | DM11: 0 | DN11: 0 | DO11: 0 | DP11: 4.5 | DQ11: 2.2 | DR11: 1 | DS11: 2.7 | DT11: 0 | DU11: 2.2 | DV11: 14.4 | DW11: 1.4 | DX11: 0 | DY11: 8.6 | DZ11: 3.9 | EA11: 5.1 | EB11: 7.2 | EC11: 13.6 | ED11: 8.1 | EE11: 3.9 | EF11: 0 | EG11: 0 | EH11: 0 | EI11: 0 | EJ11: 0 | EK11: 10.5 | EL11: 4 | EM11: 7.6 | EN11: 4.9 | EO11: 5.4 | EP11: 5.4 | EQ11: 10.7 | ER11: 0 | ES11: 0 | ET11: 0 | EU11: 0.6 | EV11: 0 | EW11: 4.9 | EX11: 0 | EY11: 0 | EZ11: 10 | FA11: 18 | FB11: 9.3 | FC11: 42.62 | FD11: 35.15 | FE11: 15.2 | FG11: 7.3 | FJ11: 6447.913 | FL11: 23.00829 | FM11: 7.881 | FN11: 0 | FO11: 9.4 | FP11: 27.07262 | FQ11: 18.92109 | FR11: 11.6 | FS11: 16 | FT11: 113.883
A12: 04/07/2025 | B12: 01:00 | C12: 138.2 | D12: 591.08 | E12: 205.28 | H12: 49.2 | I12: 85.1 | L12: 169.5 | M12: 170 | N12: 170 | O12: 264.8 | P12: 217.3 | Q12: 111.4 | R12: 433.7 | S12: 4.1 | X12: 129.8 | Y12: 6.9 | Z12: 5.2 | AB12: 6.9 | AC12: 11.7 | AD12: 38 | AI12: 43.8 | AJ12: 108.1 | AN12: 6.5 | AO12: 0 | AP12: 39.8 | AQ12: 43.9 | AR12: 27.3 | AS12: 17.8 | AT12: 19.7 | AU12: 72.5 | AV12: 178.941 | AW12: 179.439 | AX12: 183.254 | AY12: 74.8 | AZ12: 6.3 | BA12: 1.5 | BB12: 32.6 | BC12: 29 | BD12: 3.8 | BE12: 0 | BF12: 20 | BI12: 13.2 | BL12: 0 | BP12: 54 | BQ12: 177.6 | BR12: 175.6 | BS12: 200 | BT12: 274.7 | BZ12: 0 | CC12: 1.2 | CD12: 81 | CE12: 80.9 | CF12: 63.3 | CG12: 70.3 | CH12: 28.8 | CL12: 146.3 | CM12: 149.2 | CN12: 150.3 | CT12: 216.8 | CU12: 103 | CV12: 0 | CW12: 0.1 | CX12: 0 | CY12: 14 | CZ12: 0 | DA12: 11.3 | DB12: 10 | DC12: 4.8 | DD12: 0.4 | DE12: 2.7 | DF12: 2.6 | DG12: 19.6 | DH12: 13.2 | DI12: 8.9 | DJ12: 3.3 | DK12: 18.5 | DL12: 0 | DM12: 0 | DN12: 0.2 | DO12: 0.3 | DP12: 4.5 | DQ12: 2.2 | DR12: 1 | DS12: 2.7 | DT12: 0 | DU12: 2.2 | DV12: 3.4 | DW12: 1.4 | DX12: 0 | DY12: 8.5 | DZ12: 3.8 | EA12: 4.8 | EB12: 7 | EC12: 13.1 | ED12: 5.2 | EE12: 4.9 | EF12: 0 | EG12: 0 | EH12: 0 | EI12: 0 | EJ12: 0 | EK12: 10.5 | EL12: 4 | EM12: 7.7 | EN12: 5.2 | EO12: 5.4 | EP12: 5.4 | EQ12: 11.1 | ER12: 0 | ES12: 0 | ET12: 0 | EU12: 0.6 | EV12: 0 | EW12: 9.2 | EX12: 0 | EY12: 0 | EZ12: 9.9 | FA12: 17.8 | FB12: 9.3 | FC12: 42.59 | FD12: 36.06 | FE12: 15.3 | FG12: 7.5 | FJ12: 6255.544 | FL12: 23.32322 | FM12: 7.883 | FN12: 0 | FO12: 9.4 | FP12: 27.02249 | FQ12: 18.92102 | FR12: 11.6 | FS12: 16 | FT12: 114.14973
A13: 04/07/2025 | B13: 01:30 | C13: 143.5 | D13: 598.22 | E13: 200.99 | H13: 50 | I13: 85.9 | L13: 167.4 | M13: 167.8 | N13: 168 | O13: 254.9 | P13: 215.5 | Q13: 111.8 | R13: 351.1 | S13: 4.3 | X13: 135.6 | Y13: 7.3 | Z13: 5.3 | AB13: 6.8 | AC13: 12.1 | AD13: 39.6 | AI13: 45 | AJ13: 107.9 | AN13: 6.5 | AO13: 0 | AP13: 43.2 | AQ13: 45.1 | AR13: 27.4 | AS13: 18 | AT13: 19.7 | AU13: 73.5 | AV13: 182.507 | AW13: 182.832 | AX13: 184.43 | AY13: 76.4 | AZ13: 6.3 | BA13: 1.6 | BB13: 33.2 | BC13: 29.5 | BD13: 3.8 | BE13: 0 | BF13: 21.5 | BI13: 14.3 | BL13: 0 | BP13: 55.3 | BQ13: 178.2 | BR13: 176.5 | BS13: 200 | BT13: 274.6 | BZ13: 0 | CC13: 1.2 | CD13: 75.2 | CE13: 84 | CF13: 64.4 | CG13: 70.7 | CH13: 29.1 | CL13: 147.1 | CM13: 149.6 | CN13: 150.8 | CT13: 216.2 | CU13: 103.6 | CV13: 0 | CW13: 0.1 | CX13: 0 | CY13: 15.1 | CZ13: 0 | DA13: 11.4 | DB13: 9.9 | DC13: 3.9 | DD13: 0.4 | DE13: 2.7 | DF13: 2.6 | DG13: 19.8 | DH13: 13 | DI13: 8.9 | DJ13: 3.3 | DK13: 18.5 | DL13: 0 | DM13: 0 | DN13: 0 | DO13: 0 | DP13: 4.5 | DQ13: 2.2 | DR13: 1 | DS13: 2.7 | DT13: 0 | DU13: 2.1 | DV13: 4.4 | DW13: 1.4 | DX13: 0 | DY13: 8.6 | DZ13: 3.8 | EA13: 5 | EB13: 7.2 | EC13: 13.2 | ED13: 4.8 | EE13: 5.5 | EF13: 0 | EG13: 0 | EH13: 0 | EI13: 0 | EJ13: 0 | EK13: 10.5 | EL13: 4 | EM13: 7.8 | EN13: 5.6 | EO13: 5.4 | EP13: 5.4 | EQ13: 12.7 | ER13: 0 | ES13: 0 | ET13: 0 | EU13: 0.6 | EV13: 0 | EW13: 11.7 | EX13: 0 | EY13: 0 | EZ13: 10 | FA13: 17.9 | FB13: 9.6 | FC13: 42.68 | FD13: 35.21 | FE13: 15.4 | FG13: 7.3 | FJ13: 6203.069 | FL13: 23.41913 | FM13: 7.882 | FN13: 0 | FO13: 9.5 | FP13: 26.90449 | FQ13: 18.92145 | FR13: 11.7 | FS13: 16.1 | FT13: 114.42707
A14: 04/07/2025 | B14: 02:00 | C14: 75.4 | D14: 603.44 | E14: 203.76 | H14: 50.4 | I14: 87.4 | L14: 165.6 | M14: 166.4 | N14: 166.2 | O14: 265.6 | P14: 217.7 | Q14: 111.8 | R14: 253.1 | S14: 4.4 | X14: 139.2 | Y14: 7.8 | Z14: 5.5 | AB14: 6.8 | AC14: 12.2 | AD14: 41.6 | AI14: 43.8 | AJ14: 107.7 | AN14: 6.5 | AO14: 0 | AP14: 43.5 | AQ14: 45.8 | AR14: 30.3 | AS14: 18 | AT14: 19.7 | AU14: 71.8 | AV14: 185.014 | AW14: 185.329 | AX14: 183.989 | AY14: 79.8 | AZ14: 6.4 | BA14: 1.5 | BB14: 33.9 | BC14: 30 | BD14: 3.8 | BE14: 0 | BF14: 22.9 | BI14: 15.5 | BL14: 0 | BP14: 55.6 | BQ14: 178.7 | BR14: 176.9 | BS14: 200 | BT14: 274.7 | BZ14: 0 | CC14: 1.2 | CD14: 76.3 | CE14: 86.5 | CF14: 65.7 | CG14: 69.1 | CH14: 29.4 | CL14: 147.5 | CM14: 150.2 | CN14: 151.8 | CT14: 216.1 | CU14: 103.7 | CV14: 0 | CW14: 0.1 | CX14: 0 | CY14: 15.7 | CZ14: 0 | DA14: 11.5 | DB14: 10 | DC14: 4.1 | DD14: 0.4 | DE14: 2.4 | DF14: 2.6 | DG14: 20.3 | DH14: 13 | DI14: 9 | DJ14: 3.4 | DK14: 18.5 | DL14: 0 | DM14: 0 | DN14: 0 | DO14: 0 | DP14: 4.5 | DQ14: 2.2 | DR14: 1 | DS14: 2.7 | DT14: 0 | DU14: 2.1 | DV14: 4.8 | DW14: 1.3 | DX14: 0 | DY14: 8.6 | DZ14: 3.9 | EA14: 5.3 | EB14: 7.4 | EC14: 13.4 | ED14: 6.9 | EE14: 3.2 | EF14: 0 | EG14: 0 | EH14: 0 | EI14: 0 | EJ14: 0 | EK14: 10.5 | EL14: 4 | EM14: 7.8 | EN14: 5.5 | EO14: 5.4 | EP14: 5.4 | EQ14: 12.6 | ER14: 0 | ES14: 0 | ET14: 0 | EU14: 0.6 | EV14: 0 | EW14: 8.7 | EX14: 0 | EY14: 0 | EZ14: 10 | FA14: 17.9 | FB14: 9.4 | FC14: 42.63 | FD14: 35.18 | FE14: 15.3 | FG14: 7.4 | FJ14: 6079.542 | FL14: 23.48189 | FM14: 7.882 | FN14: 0 | FO14: 9.6 | FP14: 26.91826 | FQ14: 18.92132 | FR14: 11.8 | FS14: 16 | FT14: 114.60347
A15: 04/07/2025 | B15: 02:30 | C15: 66.6 | D15: 598.57 | E15: 201.81 | H15: 50 | I15: 86 | L15: 174.6 | M15: 174.5 | N15: 175 | O15: 265.3 | P15: 217.2 | Q15: 111.6 | R15: 248.1 | S15: 4.3 | X15: 134.5 | Y15: 7.4 | Z15: 5.4 | AB15: 6.8 | AC15: 12.1 | AD15: 40.2 | AI15: 42.3 | AJ15: 108 | AN15: 6.5 | AO15: 0 | AP15: 43.5 | AQ15: 73.1 | AR15: 29.6 | AS15: 18.2 | AT15: 19.7 | AU15: 73.4 | AV15: 181.963 | AW15: 182.169 | AX15: 184.085 | AY15: 77.6 | AZ15: 6.3 | BA15: 1.5 | BB15: 33.4 | BC15: 29.7 | BD15: 3.8 | BE15: 0 | BF15: 21.5 | BI15: 14.7 | BL15: 0 | BP15: 55.3 | BQ15: 178.3 | BR15: 176.1 | BS15: 200 | BT15: 275 | BZ15: 0 | CC15: 1.2 | CD15: 111.3 | CE15: 83.9 | CF15: 64.8 | CG15: 68.7 | CH15: 28.9 | CL15: 146.5 | CM15: 149.3 | CN15: 150.3 | CT15: 216.4 | CU15: 103.7 | CV15: 0 | CW15: 0.1 | CX15: 0 | CY15: 14.3 | CZ15: 0 | DA15: 11.5 | DB15: 9.9 | DC15: 4 | DD15: 0.4 | DE15: 2.4 | DF15: 2.6 | DG15: 20 | DH15: 13 | DI15: 8.9 | DJ15: 3.4 | DK15: 18.5 | DL15: 0 | DM15: 0 | DN15: 0 | DO15: 0 | DP15: 4.5 | DQ15: 2.2 | DR15: 1 | DS15: 2.7 | DT15: 0 | DU15: 2.1 | DV15: 5.2 | DW15: 1.3 | DX15: 0 | DY15: 8.6 | DZ15: 3.8 | EA15: 5.2 | EB15: 7.3 | EC15: 13.6 | ED15: 6.6 | EE15: 1.3 | EF15: 0 | EG15: 0 | EH15: 0 | EI15: 0 | EJ15: 0 | EK15: 10.5 | EL15: 4.1 | EM15: 7.8 | EN15: 5.5 | EO15: 5.4 | EP15: 5.4 | EQ15: 10.1 | ER15: 0 | ES15: 0 | ET15: 0 | EU15: 0.6 | EV15: 0 | EW15: 3.3 | EX15: 0 | EY15: 0 | EZ15: 10 | FA15: 18 | FB15: 9.5 | FC15: 42.68 | FD15: 35.17 | FE15: 15.2 | FG15: 7.1 | FJ15: 6105.447 | FL15: 23.50843 | FM15: 7.883 | FN15: 0 | FO15: 9.4 | FP15: 26.90302 | FQ15: 18.92128 | FR15: 11.6 | FS15: 16.2 | FT15: 114.41573
A16: 04/07/2025 | B16: 03:00 | C16: 71.1 | D16: 601.03 | E16: 204.31 | H16: 50.7 | I16: 87.9 | L16: 169.9 | M16: 169.4 | N16: 170.7 | O16: 262.5 | P16: 214.2 | Q16: 111.9 | R16: 246.5 | S16: 4.3 | X16: 137.1 | Y16: 7.7 | Z16: 5.5 | AB16: 6.8 | AC16: 12.1 | AD16: 40.6 | AI16: 43.4 | AJ16: 109 | AN16: 6.5 | AO16: 0 | AP16: 43.5 | AQ16: 65.9 | AR16: 30.9 | AS16: 18.2 | AT16: 19.7 | AU16: 72.6 | AV16: 184.458 | AW16: 185.347 | AX16: 183.821 | AY16: 78.5 | AZ16: 6.3 | BA16: 1.5 | BB16: 34 | BC16: 30.2 | BD16: 3.8 | BE16: 0 | BF16: 23.8 | BI16: 15.2 | BL16: 0 | BP16: 55.9 | BQ16: 177.6 | BR16: 175.7 | BS16: 200 | BT16: 275.7 | BZ16: 0 | CC16: 1.2 | CD16: 99.7 | CE16: 86.7 | CF16: 65.2 | CG16: 68.7 | CH16: 29.2 | CL16: 146.4 | CM16: 149.5 | CN16: 150.1 | CT16: 216.4 | CU16: 103.8 | CV16: 0 | CW16: 0.2 | CX16: 0 | CY16: 11.4 | CZ16: 0 | DA16: 11.5 | DB16: 9.9 | DC16: 4 | DD16: 0.4 | DE16: 2.5 | DF16: 2.6 | DG16: 20.3 | DH16: 13.2 | DI16: 8.9 | DJ16: 3.4 | DK16: 18.5 | DL16: 0 | DM16: 0 | DN16: 0.5 | DO16: 1 | DP16: 4.5 | DQ16: 2.2 | DR16: 1 | DS16: 2.7 | DT16: 0 | DU16: 2.1 | DV16: 5.8 | DW16: 1.3 | DX16: 0 | DY16: 8.5 | DZ16: 3.9 | EA16: 5.3 | EB16: 7.4 | EC16: 13.6 | ED16: 4.4 | EE16: 0.2 | EF16: 0 | EG16: 0 | EH16: 0 | EI16: 0 | EJ16: 0 | EK16: 10.5 | EL16: 3.7 | EM16: 7.8 | EN16: 5.4 | EO16: 5.4 | EP16: 5.4 | EQ16: 8 | ER16: 0 | ES16: 0 | ET16: 0 | EU16: 0.6 | EV16: 0 | EW16: 2.6 | EX16: 0 | EY16: 0 | EZ16: 10 | FA16: 18 | FB16: 9.6 | FC16: 42.68 | FD16: 35.18 | FE16: 15.3 | FG16: 7.5 | FJ16: 6091.526 | FL16: 23.56228 | FM16: 7.882 | FN16: 0 | FO16: 9.4 | FP16: 26.85076 | FQ16: 18.92153 | FR16: 11.6 | FS16: 16 | FT16: 114.21657
A17: 04/07/2025 | B17: 03:30 | C17: 64 | D17: 598.91 | E17: 200.89 | H17: 50.4 | I17: 86.6 | L17: 189.8 | M17: 195.1 | N17: 194.6 | O17: 275.3 | P17: 218.2 | Q17: 112.3 | R17: 249.4 | S17: 4.3 | X17: 135.1 | Y17: 7.2 | Z17: 5.3 | AB17: 6.9 | AC17: 12 | AD17: 39.4 | AI17: 42.4 | AJ17: 108.1 | AN17: 6.5 | AO17: 0 | AP17: 43.5 | AQ17: 0 | AR17: 28.7 | AS17: 18 | AT17: 19.7 | AU17: 74.3 | AV17: 181.807 | AW17: 182.288 | AX17: 184.432 | AY17: 77.2 | AZ17: 6.4 | BA17: 1.6 | BB17: 33.1 | BC17: 29.2 | BD17: 3.8 | BE17: 0 | BF17: 21.5 | BI17: 14.6 | BL17: 0 | BP17: 55.3 | BQ17: 178.7 | BR17: 176.6 | BS17: 200 | BT17: 275.4 | BZ17: 0 | CC17: 1.2 | CD17: 70 | CE17: 74.5 | CF17: 64.5 | CG17: 67.8 | CH17: 28.8 | CL17: 146.7 | CM17: 149.9 | CN17: 150.8 | CT17: 216.3 | CU17: 103.7 | CV17: 0 | CW17: 0.4 | CX17: 0 | CY17: 11.1 | CZ17: 0 | DA17: 11.4 | DB17: 9.9 | DC17: 4 | DD17: 0.4 | DE17: 2.5 | DF17: 2.6 | DG17: 20 | DH17: 13.3 | DI17: 8.9 | DJ17: 3.4 | DK17: 18.5 | DL17: 0 | DM17: 0 | DN17: 0.3 | DO17: 1.5 | DP17: 4.5 | DQ17: 1.7 | DR17: 1 | DS17: 2.7 | DT17: 0 | DU17: 2.1 | DV17: 5.8 | DW17: 1.3 | DX17: 0 | DY17: 8.6 | DZ17: 3.8 | EA17: 5 | EB17: 7.2 | EC17: 13.6 | ED17: 7.7 | EE17: 0 | EF17: 0 | EG17: 0 | EH17: 0 | EI17: 0 | EJ17: 0 | EK17: 10.5 | EL17: 3.7 | EM17: 7.8 | EN17: 5.4 | EO17: 5.4 | EP17: 5.4 | EQ17: 7.8 | ER17: 0 | ES17: 0 | ET17: 0 | EU17: 0.6 | EV17: 0 | EW17: 4.7 | EX17: 0 | EY17: 0 | EZ17: 10 | FA17: 18 | FB17: 9.5 | FC17: 42.7 | FD17: 35.02 | FE17: 15.3 | FG17: 7.6 | FJ17: 6045.647 | FL17: 23.58276 | FM17: 7.882 | FN17: 0 | FO17: 9.4 | FP17: 26.95729 | FQ17: 18.92138 | FR17: 11.5 | FS17: 16.1 | FT17: 114.34343
A18: 04/07/2025 | B18: 04:00 | C18: 71 | D18: 601.06 | E18: 203.41 | H18: 60.7 | I18: 88.8 | L18: 175.3 | M18: 175.7 | N18: 175.6 | O18: 274.5 | P18: 215.8 | Q18: 112 | R18: 249.2 | S18: 4.3 | X18: 139.2 | Y18: 7.6 | Z18: 5.1 | AB18: 6.8 | AC18: 12 | AD18: 41.1 | AI18: 43.2 | AJ18: 107.6 | AN18: 6.4 | AO18: 0 | AP18: 43.9 | AQ18: 0 | AR18: 30.8 | AS18: 18 | AT18: 19.7 | AU18: 74.1 | AV18: 185.802 | AW18: 186.197 | AX18: 183.215 | AY18: 78.3 | AZ18: 6.4 | BA18: 1.5 | BB18: 34.1 | BC18: 30 | BD18: 3.8 | BE18: 0 | BF18: 22.5 | BI18: 15.4 | BL18: 0 | BP18: 56.3 | BQ18: 178.8 | BR18: 176.8 | BS18: 200 | BT18: 275.2 | BZ18: 0 | CC18: 1.2 | CD18: 68.6 | CE18: 71.8 | CF18: 65.3 | CG18: 67.9 | CH18: 29.2 | CL18: 147 | CM18: 150 | CN18: 151.4 | CT18: 216.3 | CU18: 103.7 | CV18: 0 | CW18: 0 | CX18: 0 | CY18: 10.6 | CZ18: 0 | DA18: 11.6 | DB18: 9.9 | DC18: 4.8 | DD18: 0.4 | DE18: 2.5 | DF18: 2.6 | DG18: 20.3 | DH18: 13.6 | DI18: 8.9 | DJ18: 3.4 | DK18: 18.5 | DL18: 0 | DM18: 0 | DN18: 0 | DO18: 0 | DP18: 4.5 | DQ18: 2.2 | DR18: 1 | DS18: 2.7 | DT18: 0 | DU18: 2.1 | DV18: 5.8 | DW18: 1.3 | DX18: 0 | DY18: 8.5 | DZ18: 3.8 | EA18: 5.2 | EB18: 7.3 | EC18: 13.6 | ED18: 10.2 | EE18: 2.1 | EF18: 0 | EG18: 0 | EH18: 0 | EI18: 0 | EJ18: 0 | EK18: 10.5 | EL18: 3.7 | EM18: 7.8 | EN18: 5.4 | EO18: 5.4 | EP18: 5.4 | EQ18: 5.7 | ER18: 0 | ES18: 0 | ET18: 0 | EU18: 0.6 | EV18: 0 | EW18: 4.5 | EX18: 0 | EY18: 0 | EZ18: 10 | FA18: 18 | FB18: 9.4 | FC18: 42.83 | FD18: 35.25 | FE18: 15.3 | FG18: 8 | FJ18: 6034.764 | FL18: 23.57874 | FM18: 7.881 | FN18: 0 | FO18: 9.5 | FP18: 26.8716 | FQ18: 18.92143 | FR18: 11.8 | FS18: 16.1 | FT18: 114.65277
A19: 04/07/2025 | B19: 04:30 | C19: 71.8 | D19: 600.35 | E19: 202.67 | H19: 60.5 | I19: 88.6 | L19: 188.8 | M19: 188.8 | N19: 189.3 | O19: 283.3 | P19: 218.4 | Q19: 111.8 | R19: 248.8 | S19: 4.3 | X19: 138.8 | Y19: 7.6 | Z19: 5.2 | AB19: 6.8 | AC19: 12 | AD19: 40.2 | AI19: 42.9 | AJ19: 108.2 | AN19: 6.5 | AO19: 0 | AP19: 44 | AQ19: 0 | AR19: 30.6 | AS19: 18 | AT19: 19.7 | AU19: 70.5 | AV19: 183.771 | AW19: 183.945 | AX19: 184.112 | AY19: 78 | AZ19: 6.3 | BA19: 1.5 | BB19: 33.5 | BC19: 29.8 | BD19: 3.8 | BE19: 0 | BF19: 21.7 | BI19: 15.1 | BL19: 0 | BP19: 55.5 | BQ19: 178.2 | BR19: 176 | BS19: 200 | BT19: 274.6 | BZ19: 0 | CC19: 1.2 | CD19: 68.2 | CE19: 72.2 | CF19: 65.1 | CG19: 67.9 | CH19: 29.1 | CL19: 146.7 | CM19: 149.3 | CN19: 150.6 | CT19: 216.3 | CU19: 103.7 | CV19: 0 | CW19: 0 | CX19: 0 | CY19: 10.4 | CZ19: 0 | DA19: 11.7 | DB19: 10 | DC19: 4.8 | DD19: 0.4 | DE19: 2.5 | DF19: 2.6 | DG19: 20.2 | DH19: 13.7 | DI19: 8.9 | DJ19: 3.4 | DK19: 18.5 | DL19: 0 | DM19: 0 | DN19: 0 | DO19: 0 | DP19: 4.5 | DQ19: 2.2 | DR19: 1 | DS19: 2.7 | DT19: 0 | DU19: 2.1 | DV19: 5.8 | DW19: 1.3 | DX19: 0 | DY19: 8.6 | DZ19: 3.6 | EA19: 5.2 | EB19: 7.3 | EC19: 13.7 | ED19: 11.1 | EE19: 3.6 | EF19: 0 | EG19: 0 | EH19: 0 | EI19: 0 | EJ19: 0 | EK19: 10.5 | EL19: 3.7 | EM19: 8 | EN19: 5.4 | EO19: 5.4 | EP19: 5.4 | EQ19: 5.2 | ER19: 0 | ES19: 0 | ET19: 0 | EU19: 0.6 | EV19: 0 | EW19: 2.1 | EX19: 0 | EY19: 0 | EZ19: 10 | FA19: 18.1 | FB19: 9.5 | FC19: 42.72 | FD19: 35.13 | FE19: 15.2 | FG19: 7.6 | FJ19: 6068.898 | FL19: 23.64534 | FM19: 7.883 | FN19: 0 | FO19: 9.4 | FP19: 26.9604 | FQ19: 18.92146 | FR19: 11.7 | FS19: 16 | FT19: 114.5102
A20: 04/07/2025 | B20: 05:00 | C20: 119.2 | D20: 597.33 | E20: 201.75 | H20: 60 | I20: 89 | L20: 183.1 | M20: 183.4 | N20: 183.5 | O20: 274.7 | P20: 214.2 | Q20: 111.4 | R20: 246.3 | S20: 4.3 | X20: 135.4 | Y20: 7.1 | Z20: 5.1 | AB20: 6.8 | AC20: 11.7 | AD20: 41.2 | AI20: 42.1 | AJ20: 107.6 | AN20: 6.4 | AO20: 0 | AP20: 44 | AQ20: 0 | AR20: 29 | AS20: 18 | AT20: 19.7 | AU20: 72.3 | AV20: 180.231 | AW20: 180.814 | AX20: 183.959 | AY20: 76.9 | AZ20: 6.1 | BA20: 1.5 | BB20: 33 | BC20: 29.9 | BD20: 3.8 | BE20: 0 | BF20: 40 | BI20: 14.5 | BL20: 0 | BP20: 54.9 | BQ20: 177.9 | BR20: 175.9 | BS20: 200 | BT20: 275.4 | BZ20: 0 | CC20: 1.2 | CD20: 66.3 | CE20: 71.6 | CF20: 63 | CG20: 67.7 | CH20: 28.8 | CL20: 146 | CM20: 149.2 | CN20: 150.3 | CT20: 216.3 | CU20: 103.6 | CV20: 0 | CW20: 0 | CX20: 0 | CY20: 9.3 | CZ20: 0 | DA20: 11.7 | DB20: 10 | DC20: 4.8 | DD20: 0.4 | DE20: 2.6 | DF20: 2.6 | DG20: 19.8 | DH20: 14 | DI20: 8 | DJ20: 3.4 | DK20: 18.5 | DL20: 0 | DM20: 0 | DN20: 0 | DO20: 0 | DP20: 4.5 | DQ20: 2.2 | DR20: 1.1 | DS20: 2.7 | DT20: 0 | DU20: 2.1 | DV20: 5.8 | DW20: 1.3 | DX20: 0 | DY20: 8.6 | DZ20: 3.5 | EA20: 5.2 | EB20: 7.2 | EC20: 13.6 | ED20: 8.2 | EE20: 3.2 | EF20: 0 | EG20: 0 | EH20: 0 | EI20: 0 | EJ20: 0 | EK20: 10.5 | EL20: 3.7 | EM20: 8 | EN20: 5 | EO20: 5.4 | EP20: 5.4 | EQ20: 4.4 | ER20: 0 | ES20: 0 | ET20: 0 | EU20: 0.6 | EV20: 0 | EW20: 0.3 | EX20: 0 | EY20: 0 | EZ20: 10 | FA20: 18 | FB20: 9.6 | FC20: 42.49 | FD20: 34.92 | FE20: 15.1 | FG20: 7.4 | FJ20: 6068.494 | FL20: 23.66286 | FM20: 7.88 | FN20: 0 | FO20: 9.4 | FP20: 26.95778 | FQ20: 18.92137 | FR20: 11.8 | FS20: 16 | FT20: 114.62201
A21: 04/07/2025 | B21: 05:30 | C21: 118.6 | D21: 597.14 | E21: 201.25 | H21: 60 | I21: 90 | L21: 183.2 | M21: 183.2 | N21: 183.5 | O21: 266.8 | P21: 217.4 | Q21: 111.4 | R21: 250.1 | S21: 4.2 | X21: 133.7 | Y21: 7.1 | Z21: 5.5 | AB21: 6.8 | AC21: 12 | AD21: 41.4 | AI21: 45.2 | AJ21: 108.3 | AN21: 6.5 | AO21: 147.2 | AP21: 44 | AQ21: 0 | AR21: 28.9 | AS21: 18 | AT21: 19.7 | AU21: 72.3 | AV21: 180.759 | AW21: 181.123 | AX21: 183.841 | AY21: 76.8 | AZ21: 6.1 | BA21: 1.5 | BB21: 33.4 | BC21: 30.4 | BD21: 3.8 | BE21: 0 | BF21: 39.9 | BI21: 14.4 | BL21: 0 | BP21: 55.2 | BQ21: 178.1 | BR21: 175.8 | BS21: 200 | BT21: 274.9 | BZ21: 0 | CC21: 1.2 | CD21: 76.5 | CE21: 71.6 | CF21: 62.9 | CG21: 67.8 | CH21: 27.8 | CL21: 146.2 | CM21: 149.4 | CN21: 150 | CT21: 216.3 | CU21: 103.7 | CV21: 0 | CW21: 0 | CX21: 0 | CY21: 10.9 | CZ21: 0 | DA21: 11.6 | DB21: 9.9 | DC21: 4.8 | DD21: 0.4 | DE21: 2.6 | DF21: 2.6 | DG21: 19.8 | DH21: 14 | DI21: 8 | DJ21: 3.4 | DK21: 18.5 | DL21: 0 | DM21: 0 | DN21: 0.1 | DO21: 0 | DP21: 4.5 | DQ21: 2.2 | DR21: 1.1 | DS21: 2.7 | DT21: 0 | DU21: 2.1 | DV21: 5.8 | DW21: 1.2 | DX21: 0 | DY21: 8.6 | DZ21: 3.5 | EA21: 5.1 | EB21: 7.2 | EC21: 13.6 | ED21: 7.2 | EE21: 4.5 | EF21: 0 | EG21: 0 | EH21: 0 | EI21: 0 | EJ21: 0 | EK21: 10.5 | EL21: 3.7 | EM21: 8 | EN21: 5 | EO21: 5.4 | EP21: 5.4 | EQ21: 4.8 | ER21: 0 | ES21: 0 | ET21: 0 | EU21: 0.6 | EV21: 0 | EW21: 0 | EX21: 0 | EY21: 0 | EZ21: 10 | FA21: 18.1 | FB21: 9.7 | FC21: 42.37 | FD21: 34.81 | FE21: 15 | FG21: 7.5 | FJ21: 6229.593 | FL21: 24.17068 | FM21: 7.881 | FN21: 0 | FO21: 9.4 | FP21: 26.89368 | FQ21: 18.92156 | FR21: 11.6 | FS21: 16 | FT21: 114.86692
A22: 04/07/2025 | B22: 06:00 | C22: 115.9 | D22: 599.39 | E22: 202.47 | H22: 59.7 | I22: 88.6 | L22: 190.2 | M22: 190.2 | N22: 190.6 | O22: 275.2 | P22: 213.9 | Q22: 111.8 | R22: 250.9 | S22: 4.2 | X22: 130.8 | Y22: 7.1 | Z22: 5.3 | AB22: 6.8 | AC22: 12.6 | AD22: 39.4 | AI22: 44.6 | AJ22: 108.8 | AN22: 6.5 | AO22: 146.7 | AP22: 44 | AQ22: 0 | AR22: 30 | AS22: 18.1 | AT22: 19.7 | AU22: 70.1 | AV22: 181.085 | AW22: 181.26 | AX22: 184.754 | AY22: 77 | AZ22: 6.1 | BA22: 1.5 | BB22: 32.3 | BC22: 29.9 | BD22: 3.8 | BE22: 0 | BF22: 53 | BI22: 14.3 | BL22: 0 | BP22: 55.1 | BQ22: 178.8 | BR22: 176.8 | BS22: 200 | BT22: 275.3 | BZ22: 0 | CC22: 1.2 | CD22: 74.8 | CE22: 70.7 | CF22: 62.9 | CG22: 67.7 | CH22: 27.8 | CL22: 147 | CM22: 150.2 | CN22: 151.3 | CT22: 216.6 | CU22: 103.7 | CV22: 0 | CW22: 0 | CX22: 0 | CY22: 11.4 | CZ22: 0 | DA22: 11.5 | DB22: 9.9 | DC22: 4.9 | DD22: 0.4 | DE22: 2.7 | DF22: 2.6 | DG22: 19.8 | DH22: 14 | DI22: 8 | DJ22: 3.4 | DK22: 18.5 | DL22: 0.1 | DM22: 0 | DN22: 0 | DO22: 0 | DP22: 4.5 | DQ22: 2.2 | DR22: 1.1 | DS22: 2.7 | DT22: 0 | DU22: 2.2 | DV22: 5.8 | DW22: 1.2 | DX22: 0 | DY22: 8.5 | DZ22: 3.5 | EA22: 5.1 | EB22: 7.2 | EC22: 13.5 | ED22: 8.6 | EE22: 7.9 | EF22: 0 | EG22: 0 | EH22: 0 | EI22: 0 | EJ22: 0 | EK22: 10.5 | EL22: 3.7 | EM22: 7.9 | EN22: 5 | EO22: 5.4 | EP22: 5.4 | EQ22: 5.5 | ER22: 0 | ES22: 0 | ET22: 0 | EU22: 0.6 | EV22: 0 | EW22: 0 | EX22: 0 | EY22: 0 | EZ22: 10.1 | FA22: 18.1 | FB22: 9.8 | FC22: 42.49 | FD22: 34.92 | FE22: 15.3 | FG22: 7.5 | FJ22: 6271.869 | FL22: 23.85031 | FM22: 7.879 | FN22: 0 | FO22: 9.6 | FP22: 26.92222 | FQ22: 18.92073 | FR22: 11.8 | FS22: 16 | FT22: 114.97226
... A58: 05/07/2025 | B58: 00:00 | C58: 137.2 | D58: 647.26 | E58: 215.51 | H58: 55 | I58: 84.1 | L58: 166.7 | M58: 167.3 | N58: 167.8 | O58: 254.3 | P58: 217.3 | Q58: 111.4 | R58: 448 | S58: 4.3 | X58: 136.7 | Y58: 7.3 | Z58: 5.1 | AB58: 6.9 | AC58: 15 | AD58: 88 | AI58: 64.3 | AJ58: 100.9 | AN58: 6.5 | AO58: 230.5 | AP58: 39.9 | AQ58: 73.2 | AR58: 26.6 | AS58: 17.8 | AT58: 19 | AU58: 73.1 | AV58: 182.76622 | AW58: 0 | AX58: 92.5424 | AY58: 76.1 | AZ58: 5.8 | BA58: 1.2 | BB58: 33.2 | BC58: 28.9 | BD58: 3.8 | BE58: 0 | BF58: 47.6 | BI58: 16.9 | BL58: 46.9 | BP58: 55.3 | BQ58: 178.3 | BR58: 176.2 | BS58: 200 | BT58: 274.4 | BZ58: 0 | CC58: 1.2 | CD58: 160.3 | CE58: 71.8 | CF58: 66.3 | CG58: 68.9 | CH58: 29 | CL58: 147.2 | CM58: 150 | CN58: 150.5 | CT58: 216 | CU58: 103.4 | CV58: 0 | CW58: 16.7 | CX58: 0 | CY58: 17 | CZ58: 0 | DA58: 10.9 | DB58: 9.9 | DC58: 4.4 | DD58: 0.4 | DE58: 2.2 | DF58: 2.5 | DG58: 20.1 | DH58: 12 | DI58: 8.7 | DJ58: 3.4 | DK58: 18.5 | DL58: 0 | DM58: 0 | DN58: 4.5 | DO58: 8.9 | DP58: 4.5 | DQ58: 2.2 | DR58: 1.1 | DS58: 2.9 | DT58: 0 | DU58: 2.1 | DV58: 5.6 | DW58: 1.3 | DX58: 0.3 | DY58: 8.1 | DZ58: 3.5 | EA58: 5.1 | EB58: 7.2 | EC58: 13.5 | ED58: 1.7 | EE58: 17.2 | EF58: 0 | EG58: 6.8 | EH58: 13.1 | EI58: 0.3 | EJ58: 0 | EK58: 10.5 | EL58: 3.3 | EM58: 7.5 | EN58: 5.1 | EO58: 5.7 | EP58: 5.7 | EQ58: 12 | ER58: 0 | ES58: 0 | ET58: 0 | EU58: 0.6 | EV58: 0 | EW58: 0 | EX58: 0 | EY58: 0 | EZ58: 10 | FA58: 17.9 | FB58: 8.9 | FC58: 0 | FD58: 0 | FE58: 15 | FG58: 8.4 | FJ58: 6518.6786 | FL58: 22.12026 | FM58: 7.909 | FN58: 6.13 | FO58: 9.4 | FP58: 26.99043 | FQ58: 18.92148 | FR58: 11.6 | FS58: 16 | FT58: 119.07117
A59: EJEC | C59: 2321.55 | D59: 14799.655 | E59: 4977.64 | F59: 0 | G59: 0 | H59: 1323.05 | I59: 2081.1 | J59: 0 | K59: 0 | L59: 4329.25 | M59: 4499.85 | N59: 4512.4 | O59: 6606.1 | P59: 5138.05 | Q59: 2665.7 | R59: 9202.7 | S59: 102.65 | T59: 0 | U59: 0 | V59: 0 | W59: 0 | X59: 3300.8 | Y59: 176.8 | Z59: 126.2 | AA59: 0 | AB59: 164.15 | AC59: 286.25 | AD59: 1817.7 | AE59: 0 | AF59: 0 | AG59: 0 | AH59: 0 | AI59: 1573.65 | AJ59: 2535.35 | AK59: 0 | AL59: 0 | AM59: 0 | AN59: 155.45 | AO59: 3924.95 | AP59: 984.15 | AQ59: 1723.05 | AR59: 664.4 | AS59: 431.85 | AT59: 467.5 | AU59: 1759.55 | AV59: 4284.1525 | AW59: 4196.948 | AX59: 4319.5261 | AY59: 1851.45 | AZ59: 143.1 | BA59: 35.9 | BB59: 799.65 | BC59: 699.85 | BD59: 91.2 | BE59: 212.8 | BF59: 1615.7 | BG59: 0 | BH59: 0 | BI59: 1274.25 | BJ59: 0 | BK59: 0 | BL59: 818.85 | BM59: 0 | BN59: 0 | BO59: 0 | BP59: 1331.7 | BQ59: 4241.4 | BR59: 4194 | BS59: 4800 | BT59: 6568.4 | BU59: 0 | BV59: 0 | BW59: 0 | BX59: 0 | BY59: 0 | BZ59: 379.9 | CA59: 0 | CB59: 0 | CC59: 29.45 | CD59: 3010.25 | CE59: 1936.45 | CF59: 1544.7 | CG59: 1626.6 | CH59: 695.05 | CI59: 0 | CJ59: 0 | CK59: 0 | CL59: 3507.15 | CM59: 3573.7 | CN59: 3603 | CO59: 0 | CP59: 0 | CQ59: 0 | CR59: 0 | CS59: 0 | CT59: 5136.9 | CU59: 2462.3 | CV59: 8.35 | CW59: 80.45 | CX59: 555.35 | CY59: 334.35 | CZ59: 2.65 | DA59: 272 | DB59: 238.15 | DC59: 106.9 | DD59: 9.6 | DE59: 58.25 | DF59: 62.2 | DG59: 480.1 | DH59: 314.5 | DI59: 204.8 | DJ59: 80.05 | DK59: 444 | DL59: 115.7 | DM59: 138.8 | DN59: 22.85 | DO59: 77 | DP59: 98.75 | DQ59: 51.65 | DR59: 25.75 | DS59: 62.7 | DT59: 134.2 | DU59: 51.15 | DV59: 330.65 | DW59: 30.55 | DX59: 4.4 | DY59: 197.15 | DZ59: 79.75 | EA59: 122.9 | EB59: 176.25 | EC59: 325.9 | ED59: 132.1 | EE59: 262.7 | EF59: 249.9 | EG59: 54.8 | EH59: 96.2 | EI59: 6.5 | EJ59: 2.9 | EK59: 252 | EL59: 86.1 | EM59: 189 | EN59: 124.55 | EO59: 134.15 | EP59: 134.5 | EQ59: 249.85 | ER59: 1886.85 | ES59: 115.7 | ET59: 1048.35 | EU59: 14.4 | EV59: 188.2 | EW59: 181.15 | EX59: 781.5 | EY59: 115.85 | EZ59: 239.95 | FA59: 431.95 | FB59: 229.65 | FC59: 880.19 | FD59: 707.585 | FE59: 335.95 | FF59: 0 | FG59: 171.1 | FH59: 0 | FI59: 0 | FJ59: 166237.25 | FL59: 538.20416 | FM59: 170.765 | FN59: 95.659 | FO59: 226.25 | FP59: 640.05471 | FQ59: 454.16694 | FR59: 280.5 | FS59: 385.7 | FT59: 2791.2998

Sheet REACTIVA
B3: viernes, 4 de Julio del 2025
A5: POTENCIA REACTIVA EJECUTADA DE LAS UNIDADES DE GENERACIÓN DEL COES (MVAR) | FK5: CENTRALES NO INTEGRANTES COES
A6: FECHA | B6: HORA | C6: 65333 | D6: 101 | E6: 102 | F6: 42667 | G6: 42668 | H6: 126 | I6: 127 | J6: 138 | K6: 139 | L6: 197 | M6: 203 | N6: 204 | O6: 230 | P6: 209 | Q6: 56677 | R6: 796 | S6: 2146 | T6: 142 | U6: 143 | V6: 125 | W6: 187 | X6: 163 | Y6: 298 | Z6: 219 | AA6: 151 | AB6: 152 | AC6: 153 | AD6: 154 | AE6: 756 | AF6: 156 | AG6: 155 | AH6: 182 | AI6: 212 | AJ6: 758 | AK6: 263 | AL6: 265 | AM6: 775 | AN6: 777 | AO6: 2154 | AP6: 150 | AQ6: 149 | AR6: 188 | AS6: 2131 | AT6: 755 | AU6: 252 | AV6: 249 | AW6: 250 | AX6: 117 | AY6: 267 | AZ6: 268 | BA6: 119 | BB6: 120 | BC6: 189 | BD6: 122 | BE6: 266 | BF6: 337 | BG6: 338 | BH6: 251 | BI6: 115 | BJ6: 239 | BK6: 288 | BL6: 240 | BM6: 241 | BN6: 242 | BO6: 191 | BP6: 194 | BQ6: 196 | BR6: 207 | BS6: 236 | BT6: 795 | BU6: 285 | BV6: 995 | BW6: 996 | BX6: 997 | BY6: 766 | BZ6: 926 | CA6: 924 | CB6: 121 | CC6: 103 | CD6: 104 | CE6: 106 | CF6: 105 | CG6: 107 | CH6: 110 | CI6: 109 | CJ6: 144 | CK6: 113 | CL6: 114 | CM6: 193 | CN6: 208 | CO6: 786 | CP6: 787 | CQ6: 788 | CR6: 789 | CS6: 248 | CT6: 2159 | CU6: 303 | CV6: 59715 | CW6: 62255 | CX6: 1263 | CY6: 61800 | CZ6: 2194 | DA6: 216 | DB6: 198 | DC6: 49607 | DD6: 214 | DE6: 260 | DF6: 2152 | DG6: 2128 | DH6: 247 | DI6: 228 | DJ6: 2135 | DK6: 261 | DL6: 237 | DM6: 253 | DN6: 770 | DO6: 225 | DP6: 2201 | DQ6: 2171 | DR6: 760 | DS6: 235 | DT6: 238 | DU6: 2184 | DV6: 61855 | DW6: 223 | DX6: 226 | DY6: 201 | DZ6: 258 | EA6: 259 | EB6: 920 | EC6: 257 | ED6: 256 | EE6: 2148 | EF6: 58288 | EG6: 58289 | EH6: 58839 | EI6: 58840 | EJ6: 296 | EK6: 297 | EL6: 211 | EM6: 2175 | EN6: 2178 | EO6: 2181 | EP6: 1262 | EQ6: 63425 | ER6: 233 | ES6: 2150 | ET6: 2165 | EU6: 2161 | EV6: 61197 | EW6: 58851 | EX6: 234 | EY6: 215 | EZ6: 917 | FA6: 289 | FB6: 58333 | FC6: 58336 | FD6: 213 | FE6: 232 | FF6: 2190 | FG6: 202 | FH6: 58487 | FI6: TOTAL COES | FK6: 221 | FL6: 222 | FM6: 224 | FN6: 2187 | FO6: 227 | FP6: 49400 | FQ6: 199 | FR6: 200 | FS6: TOTAL NO COES
C7: SUR | D7: CENTRO | E7: CENTRO | F7: NORTE | G7: NORTE | H7: NORTE | I7: NORTE | J7: CENTRO | K7: CENTRO | L7: CENTRO | M7: CENTRO | N7: CENTRO | O7: CENTRO | P7: CENTRO | Q7: CENTRO | R7: CENTRO | S7: CENTRO | T7: CENTRO | U7: CENTRO | V7: CENTRO | W7: CENTRO | X7: SUR | Y7: SUR | Z7: CENTRO | AA7: SUR | AB7: SUR | AC7: SUR | AD7: SUR | AE7: SUR | AF7: SUR | AG7: SUR | AH7: SUR | AI7: CENTRO | AJ7: NORTE | AK7: NORTE | AL7: NORTE | AM7: CENTRO | AN7: CENTRO | AO7: CENTRO | AP7: CENTRO | AQ7: CENTRO | AR7: CENTRO | AS7: CENTRO | AT7: SUR | AU7: CENTRO | AV7: CENTRO | AW7: CENTRO | AX7: CENTRO | AY7: CENTRO | AZ7: CENTRO | BA7: CENTRO | BB7: CENTRO | BC7: SUR | BD7: NORTE | BE7: CENTRO | BF7: CENTRO | BG7: CENTRO | BH7: CENTRO | BI7: NORTE | BJ7: NORTE | BK7: NORTE | BL7: SUR | BM7: SUR | BN7: SUR | BO7: CENTRO | BP7: CENTRO | BQ7: CENTRO | BR7: CENTRO | BS7: CENTRO | BT7: CENTRO | BU7: CENTRO | BV7: SUR | BW7: SUR | BX7: SUR | BY7: NORTE | BZ7: SUR | CA7: CENTRO | CB7: NORTE | CC7: CENTRO | CD7: CENTRO | CE7: CENTRO | CF7: CENTRO | CG7: CENTRO | CH7: CENTRO | CI7: CENTRO | CJ7: CENTRO | CK7: CENTRO | CL7: CENTRO | CM7: CENTRO | CN7: CENTRO | CO7: SUR | CP7: SUR | CQ7: SUR | CR7: SUR | CS7: CENTRO | CT7: CENTRO | CU7: CENTRO | CV7: CENTRO | CW7: SUR | CX7: NORTE | CY7: NORTE | CZ7: NORTE | DA7: NORTE | DB7: NORTE | DC7: SUR | DD7: CENTRO | DE7: CENTRO | DF7: CENTRO | DG7: NORTE | DH7: NORTE | DI7: CENTRO | DJ7: CENTRO | DK7: SUR | DL7: SUR | DM7: CENTRO | DN7: CENTRO | DO7: CENTRO | DP7: CENTRO | DQ7: CENTRO | DR7: CENTRO | DS7: SUR | DT7: CENTRO | DU7: CENTRO | DV7: NORTE | DW7: CENTRO | DX7: CENTRO | DY7: NORTE | DZ7: CENTRO | EA7: CENTRO | EB7: CENTRO | EC7: NORTE | ED7: NORTE | EE7: SUR | EF7: CENTRO | EG7: CENTRO | EH7: CENTRO | EI7: CENTRO | EJ7: CENTRO | EK7: CENTRO | EL7: SUR | EM7: SUR | EN7: SUR | EO7: SUR | EP7: NORTE | EQ7: SUR | ER7: SUR | ES7: SUR | ET7: CENTRO | EU7: CENTRO | EV7: CENTRO | EW7: SUR | EX7: SUR | EY7: NORTE | EZ7: CENTRO | FA7: NORTE | FB7: NORTE | FC7: NORTE | FD7: CENTRO | FE7: NORTE | FF7: NORTE | FG7: CENTRO | FH7: CENTRO | FK7: NORTE | FL7: CENTRO | FM7: NORTE | FN7: NORTE | FO7: NORTE | FP7: NORTE | FQ7: NORTE | FR7: NORTE
C8: HIDROELÉCTRICA | D8: HIDROELÉCTRICA | E8: HIDROELÉCTRICA | F8: TERMOELÉCTRICA | G8: TERMOELÉCTRICA | H8: HIDROELÉCTRICA | I8: HIDROELÉCTRICA | J8: TERMOELÉCTRICA | K8: TERMOELÉCTRICA | L8: TERMOELÉCTRICA | M8: TERMOELÉCTRICA | N8: TERMOELÉCTRICA | O8: TERMOELÉCTRICA | P8: TERMOELÉCTRICA | Q8: TERMOELÉCTRICA | R8: HIDROELÉCTRICA | S8: HIDROELÉCTRICA | T8: TERMOELÉCTRICA | U8: TERMOELÉCTRICA | V8: TERMOELÉCTRICA | W8: TERMOELÉCTRICA | X8: HIDROELÉCTRICA | Y8: HIDROELÉCTRICA | Z8: TERMOELÉCTRICA | AA8: HIDROELÉCTRICA | AB8: HIDROELÉCTRICA | AC8: HIDROELÉCTRICA | AD8: HIDROELÉCTRICA | AE8: TERMOELÉCTRICA | AF8: TERMOELÉCTRICA | AG8: TERMOELÉCTRICA | AH8: HIDROELÉCTRICA | AI8: HIDROELÉCTRICA | AJ8: TERMOELÉCTRICA | AK8: TERMOELÉCTRICA | AL8: TERMOELÉCTRICA | AM8: HIDROELÉCTRICA | AN8: HIDROELÉCTRICA | AO8: HIDROELÉCTRICA | AP8: HIDROELÉCTRICA | AQ8: HIDROELÉCTRICA | AR8: HIDROELÉCTRICA | AS8: HIDROELÉCTRICA | AT8: HIDROELÉCTRICA | AU8: TERMOELÉCTRICA | AV8: TERMOELÉCTRICA | AW8: TERMOELÉCTRICA | AX8: HIDROELÉCTRICA | AY8: HIDROELÉCTRICA | AZ8: HIDROELÉCTRICA | BA8: HIDROELÉCTRICA | BB8: HIDROELÉCTRICA | BC8: HIDROELÉCTRICA | BD8: HIDROELÉCTRICA | BE8: HIDROELÉCTRICA | BF8: HIDROELÉCTRICA | BG8: HIDROELÉCTRICA | BH8: HIDROELÉCTRICA | BI8: TERMOELÉCTRICA | BJ8: TERMOELÉCTRICA | BK8: TERMOELÉCTRICA | BL8: TERMOELÉCTRICA | BM8: TERMOELÉCTRICA | BN8: TERMOELÉCTRICA | BO8: HIDROELÉCTRICA | BP8: TERMOELÉCTRICA | BQ8: TERMOELÉCTRICA | BR8: TERMOELÉCTRICA | BS8: TERMOELÉCTRICA | BT8: TERMOELÉCTRICA | BU8: TERMOELÉCTRICA | BV8: TERMOELÉCTRICA | BW8: TERMOELÉCTRICA | BX8: TERMOELÉCTRICA | BY8: HIDROELÉCTRICA | BZ8: TERMOELÉCTRICA | CA8: TERMOELÉCTRICA | CB8: HIDROELÉCTRICA | CC8: HIDROELÉCTRICA | CD8: HIDROELÉCTRICA | CE8: HIDROELÉCTRICA | CF8: HIDROELÉCTRICA | CG8: HIDROELÉCTRICA | CH8: TERMOELÉCTRICA | CI8: TERMOELÉCTRICA | CJ8: TERMOELÉCTRICA | CK8: TERMOELÉCTRICA | CL8: TERMOELÉCTRICA | CM8: TERMOELÉCTRICA | CN8: TERMOELÉCTRICA | CO8: TERMOELÉCTRICA | CP8: TERMOELÉCTRICA | CQ8: TERMOELÉCTRICA | CR8: TERMOELÉCTRICA | CS8: TERMOELÉCTRICA | CT8: TERMOELÉCTRICA | CU8: SOLAR | CV8: EÓLICA | CW8: SOLAR | CX8: EÓLICA | CY8: SOLAR | CZ8: HIDROELÉCTRICA | DA8: HIDROELÉCTRICA | DB8: HIDROELÉCTRICA | DC8: HIDROELÉCTRICA | DD8: HIDROELÉCTRICA | DE8: HIDROELÉCTRICA | DF8: HIDROELÉCTRICA | DG8: HIDROELÉCTRICA | DH8: HIDROELÉCTRICA | DI8: HIDROELÉCTRICA | DJ8: HIDROELÉCTRICA | DK8: SOLAR | DL8: SOLAR | DM8: EÓLICA | DN8: EÓLICA | DO8: TERMOELÉCTRICA | DP8: TERMOELÉCTRICA | DQ8: TERMOELÉCTRICA | DR8: TERMOELÉCTRICA | DS8: SOLAR | DT8: HIDROELÉCTRICA | DU8: HIDROELÉCTRICA | DV8: HIDROELÉCTRICA | DW8: HIDROELÉCTRICA | DX8: HIDROELÉCTRICA | DY8: HIDROELÉCTRICA | DZ8: HIDROELÉCTRICA | EA8: HIDROELÉCTRICA | EB8: HIDROELÉCTRICA | EC8: EÓLICA | ED8: EÓLICA | EE8: SOLAR | EF8: EÓLICA | EG8: EÓLICA | EH8: EÓLICA | EI8: EÓLICA | EJ8: HIDROELÉCTRICA | EK8: HIDROELÉCTRICA | EL8: HIDROELÉCTRICA | EM8: HIDROELÉCTRICA | EN8: HIDROELÉCTRICA | EO8: HIDROELÉCTRICA | EP8: EÓLICA | EQ8: SOLAR | ER8: SOLAR | ES8: SOLAR | ET8: HIDROELÉCTRICA | EU8: EÓLICA | EV8: EÓLICA | EW8: SOLAR | EX8: SOLAR | EY8: HIDROELÉCTRICA | EZ8: HIDROELÉCTRICA | FA8: TERMOELÉCTRICA | FB8: TERMOELÉCTRICA | FC8: TERMOELÉCTRICA | FD8: TERMOELÉCTRICA | FE8: TERMOELÉCTRICA | FF8: TERMOELÉCTRICA | FG8: TERMOELÉCTRICA | FH8: TERMOELÉCTRICA | FK8: HIDROELÉCTRICA | FL8: HIDROELÉCTRICA | FM8: HIDROELÉCTRICA | FN8: HIDROELÉCTRICA | FO8: TERMOELÉCTRICA | FP8: TERMOELÉCTRICA | FQ8: HIDROELÉCTRICA | FR8: HIDROELÉCTRICA
