Workbook

Sheet EVENTOS
B3: jueves, 12 de Febrero del 2026
B5: INFORMACIÓN DE EVENTOS PRINCIPALES EN SUS INSTALACIONES
B6: TIPO DE EVENTO | C6: EMPRESA | D6: UBICACIÓN | E6: TIPO DE EQUIPO | F6: EQUIPO | G6: INICIO | H6: FINAL | I6: DESCRIPCIÓN | J6: MW INDISP. | K6: INTERRUPCIÓN (SI/NO) | L6: TENSIÓN DE FALLA (kV)
B7: FALLA | C7: AGROLMOS SOCIEDAD ANONIMA - AGROLMOS S.A. | D7: AGROLMOS | E7: GENERADOR TERMOELÉCTRICO | F7: TV2 | G7: 12/02/2026 13:11:45 | H7: 12/02/2026 13:51:16 | I7: DESCONEXIÓN DEL GENERADOR TV2 DE LA CT AGROLMOS | K7: NO | L7: 13.8
B8: EVENTO | C8: CONELSUR LT SAC | D8: PORTILLO | E8: SUBESTACION | F8: SS.EE. | G8: 12/02/2026 00:00:00 | H8: 13/02/2026 00:00:00 | I8: DECLARACIÓN DE SITUACIÓN EXCEPCIONAL EN LA S.E. PORTILLO 60 kV | K8: NO
B9: EVENTO | C9: ELECTRO ORIENTE | D9: BELAUNDE TERRY - TARAPOTO | E9: LINEA DE TRANSMISION | F9: L-1018 | G9: 12/02/2026 18:46:00 | H9: 12/02/2026 19:59:00 | I9: DECLARACIÓN DE SITUACIÓN EXCEPCIONAL EN LA LÍNEA L-1018 (BELAUNDE TERRY - TARAPOTO) DE 138 kV | K9: NO
B10: FALLA | C10: SAN GABAN | D10: PCH TUPURI | E10: CENTRAL HIDROELÉCTRICA | F10: CENTRAL | G10: 12/02/2026 15:55:00 | H10: 12/02/2026 16:36:00 | I10: DESCONEXIÓN DE LA C.H. TUPURI POR FALLA. | K10: NO | L10: 2.4
B11: FALLA | C11: SAN GABAN | D11: PCH TUPURI | E11: CENTRAL HIDROELÉCTRICA | F11: CENTRAL | G11: 12/02/2026 16:43:00 | H11: 13/02/2026 00:00:00 | I11: DESCONEXIÓN DE LA C.H. TUPURI POR FALLA. | K11: NO | L11: 2.4
B12: FALLA | C12: STATKRAFT S.A | D12: CAHUA | E12: GENERADOR HIDROELÉCTRICO | F12: G2 | G12: 12/02/2026 19:23:06 | H12: 12/02/2026 20:50:21 | I12: DESCONEXIÓN DEL GENERADOR G2 DE LA C.H. CAHUA POR FALLA | K12: NO | L12: 10
B13: FALLA | C13: STATKRAFT S.A | D13: CAHUA | E13: GENERADOR HIDROELÉCTRICO | F13: G1 | G13: 12/02/2026 19:30:23 | H13: 12/02/2026 22:30:59 | I13: DESCONEXIÓN DEL GENERADOR G1 DE LA C.H. CAHUA POR FALLA | K13: NO | L13: 10

Sheet RESTRIC_OPE
B3: jueves, 12 de Febrero del 2026
B5: RESTRICCIONES OPERATIVAS
B6: FECHA | C6: HORA INICIO | D6: HORA FINAL | E6: EMPRESA | F6: UBICACIÓN | G6: T.Eq. | H6: EQUIPO | I6: DESCRIPCIÓN
B7: 12/02/2026 | C7: 00:00 | D7: 24:00 | E7: CELEPSA | F7: C.H. EL PLATANAL | G7: CH | H7: CENTRAL | I7: De acuerdo con lo informado por CELEPSA mediante correo el dia 17.01, declaran que la CH Platanal se encontrará de pasada.
B8: 12/02/2026 | C8: 00:00 | D8: 24:00 | E8: EGASA | F8: S.E. CONVERTIDOR | G8: BARRA | H8: BARRA138KV | I8: EGASA limitó la capacidad del transformador 138 kV/33 kV a 50 MVA por deterioro del aislamiento.
B9: 12/02/2026 | C9: 00:00 | D9: 24:00 | E9: ELECTROPERU | F9: C.H. MANTARO | G9: CH | H9: CENTRAL | I9: De acuerdo con el correo del día 25.08.2025, la central tiene una limitación de potencia máxima de 650 MW por seguridad de la central.
B10: 12/02/2026 | C10: 00:00 | D10: 24:00 | E10: ENEL GENERACION PIURA S.A. | F10: C.T. MALACAS | G10: CT | H10: CENTRAL | I10: De acuerdo con la comunicación vía correo del día 24.10.2024. ENEL GENERACIÓN PIURA informa una restricción de potencia para alcanzar 105 MW en simultaneo (TG6+TGN4).
B11: 12/02/2026 | C11: 00:00 | D11: 24:00 | E11: ENEL GENERACION PIURA S.A. | F11: C.T. MALACAS | G11: GT | H11: TG4 | I11: De acuerdo a lo informado por correo electrónico el día 16.01, con la disponibilidad de aproximadamente 12 MMPCD (339.8Mm³) la unidad TG4 puede con una generación de 80 MW durante 4 horas, y a potencia mínima durante el resto de los periodos
B12: 12/02/2026 | C12: 00:00 | D12: 24:00 | E12: ENGIE ENERGIA PERU S.A.A. | F12: C.H. YUNCÁN | G12: GH | H12: G3 | I12: Según la carta N° ENG/ 198-2024 enviada por su representada, se opera de forma continua el G3 de la CH Yuncán, debido a la ejecución de mantenimientos necesarios para evitar daños en los sellos de seguridad de la válvula esférica del grupo.
B13: 12/02/2026 | C13: 00:00 | D13: 24:00 | E13: ENGIE ENERGIA PERU S.A.A. | F13: C.T. CHILCA 1 | G13: CT | H13: CENTRAL | I13: Con carta ENG/971-2023, indica que no puede cumplir con las IO considerada en el PDO_17122023 dado que vulneran la seguridad de sus activos. Indican que se debe tomar TMO=168h.
B14: 12/02/2026 | C14: 00:00 | D14: 24:00 | E14: ENGIE ENERGIA PERU S.A.A. | F14: C.T. CHILCA 1 | G14: CT | H14: CENTRAL | I14: Restricción de temperatura de la C.T Chilca, ver valor en el modelo de despacho.
B15: 12/02/2026 | C15: 00:00 | D15: 24:00 | E15: ENGIE ENERGIA PERU S.A.A. | F15: C.T. CHILCA 2 | G15: CT | H15: CENTRAL | I15: Con carta ENG/971-2023, indica que no puede cumplir con las IO considerada en el PDO_17122023 dado que vulneran la seguridad de sus activos. Indican que se debe tomar TMO=168h.
B16: 12/02/2026 | C16: 00:00 | D16: 24:00 | E16: FENIX POWER PERÚ | F16: C.T. FENIX | G16: CT | H16: CENTRAL | I16: De acuerdo con lo comunicado en el correo del día 06.05.2025, la CT Fenix cuenta con TMO de 168 hrs en todos sus modos de operación.
B17: 12/02/2026 | C17: 00:00 | D17: 24:00 | E17: KALLPA GENERACION S.A. | F17: C.H. CERRO DEL AGUILA | G17: GH | H17: G1 | I17: De acuerdo a lo informado el día 17/11 por la empresa KALLPA, el G1 tiene un TA = 15min
... B58: 12/02/2026 | C58: 00:00 | D58: 24:00 | E58: TERMOSELVA | F58: C.T. AGUAYTÍA | G58: CT | H58: CENTRAL | I58: Disponibilidad de 23.5 MMSCF para la CT Aguaytía.

Sheet MANTENIMIENTO EJECUTADOS
B3: jueves, 12 de Febrero del 2026
B5: Mantenimiento Ejecutado
B6: Empresa | C6: Ubicación | D6: Equipo | E6: Inicio | F6: Final | G6: Descripción | H6: MW Indisp. | I6: Prog. | J6: Dispon | K6: Interrupc. | L6: Tipo | M6: CodEq | N6: TipoEq_Osinerg
B7: ATLANTICA TRANSMISION SUR S.A. | C7: CHILCA CTM - POROMA | D7: L-5032 | E7: 12/02/2026 07:17 | F7: 12/02/2026 16:38 | G7: Inspeccion Anual en LLTT | H7: 0 | I7: P | J7: E/S | K7: N | L7: PREV. | M7: 13652 | N7: T
B8: ATLANTICA TRANSMISION SUR S.A. | C8: OCONA | D8: INT-5450 | E8: 12/02/2026 00:00 | F8: 13/02/2026 00:00 | G8: Interruptor INT-5450 cerrado con restriccion operativa, REB-5450 en servicio y suministrando los SS.AA. de la S.E. Oco?a. | H8: 0 | I8: P | J8: E/S | K8: N | L8: OTROS | M8: 13761 | N8: T
B9: ATLANTICA TRANSMISION SUR S.A. | C9: OCONA | D9: SE OCOÑA | E9: 12/02/2026 08:27 | F9: 12/02/2026 17:37 | G9: Inspeccion anual y termografica. | H9: 0 | I9: P | J9: E/S | K9: N | L9: PREV. | M9: 13741 | N9: T
B10: ATLANTICA TRANSMISION SUR S.A. | C10: POROMA | D10: INT-5371 | E10: 12/02/2026 00:00 | F10: 13/02/2026 00:00 | G10: Seccionador SBB-5371 fase T indisponible por problemas mecanicos, el seccionador permanece cerrado y bloqueado | H10: 0 | I10: P | J10: E/S | K10: N | L10: OTROS | M10: 13751 | N10: T
B11: ATLANTICA TRANSMISION SUR S.A. | C11: POROMA | D11: REB-5350 | E11: 12/02/2026 00:00 | F11: 13/02/2026 00:00 | G11: Fuera de servicio por falla en el equipo. | H11: 0 | I11: P | J11: F/S | K11: N | L11: OTROS | M11: 13771 | N11: T
B12: ATLANTICA TRANSMISION SUR S.A. | C12: POROMA - OCONA | D12: L-5034 | E12: 12/02/2026 09:46 | F12: 12/02/2026 17:12 | G12: Actividad de reparacion de pedestales para la Linea L5034. | H12: 0 | I12: P | J12: E/S | K12: N | L12: PREV. | M12: 13743 | N12: T
B13: ATN 2 S.A. | C13: COTARUSE - LAS BAMBAS | D13: L-2055 | E13: 12/02/2026 08:48 | F13: 12/02/2026 17:32 | G13: Inspeccion anual de LLTT | H13: 0 | I13: P | J13: E/S | K13: N | L13: PREV. | M13: 14930 | N13: T
B14: ATN 2 S.A. | C14: COTARUSE - LAS BAMBAS | D14: L-2056 | E14: 12/02/2026 08:48 | F14: 12/02/2026 17:32 | G14: Inspeccion anual de LLTT | H14: 0 | I14: P | J14: E/S | K14: N | L14: PREV. | M14: 14929 | N14: T
B15: ATN S.A. | C15: KIMAN AYLLU | D15: AUT-501 | E15: 12/02/2026 00:00 | F15: 13/02/2026 00:00 | G15: Restriccion Operativa en el circuito de control de cambiador de tap s del AUT-501 | H15: 0 | I15: P | J15: E/S | K15: N | L15: OTROS | M15: 13099 | N15: T
B16: CHINANGO S.A.C. | C16: YANANGO | D16: G1 | E16: 12/02/2026 10:50 | F16: 12/02/2026 17:06 | G16: AJUSTE DE PSS Y COMPLETAR AJUSTES PARA 42 MW - EN SERVICIO | H16: 42 | I16: P | J16: F/S | K16: N | L16: PREV. | M16: 108 | N16: G
B17: CONELSUR LT SAC | C17: CAJAMARQUILLA | D17: BARRA A 220kV | E17: 12/02/2026 07:30 | F17: 12/02/2026 17:30 | G17: POR MANTENIMIENTO EN CL-2014. | H17: 0 | I17: P | J17: F/S | K17: N | L17: PREV. | M17: 1103 | N17: T
B18: CONELSUR LT SAC | C18: CAJAMARQUILLA | D18: CL-2014 | E18: 12/02/2026 07:30 | F18: 12/02/2026 17:30 | G18: REEMPLAZO DE PASTA SILICONA | H18: 0 | I18: P | J18: F/S | K18: N | L18: PREV. | M18: 12717 | N18: T
... B123: TRANSMANTARO | C123: YARABAMBA | D123: IN-5120 | E123: 12/02/2026 00:00 | F123: 13/02/2026 00:00 | G123: SE. YARABAMBA 500KV: INTERRRUPTOR INDISPONIBLE POR PROBLEMAS DE MANDOS. REACTOR R-31 SERA OPERADO CON EL INTERRRUPTOR IN-5116. | H123: 0 | I123: P | J123: F/S | K123: N | L123: OTROS | M123: 17437 | N123: T

Sheet INGRESO OC
A3: jueves, 12 de Febrero del 2026
A5: INGRESO A OPERACIÓN COMERCIAL
A6: EMPRESA | B6: TIPO DE EQUIPO | C6: UBICACIÓN | D6: EQUIPO | E6: Fecha y hora de Ingreso a Operación Comercial

Sheet DESPACHO_EJECUTADO
B3: jueves, 12 de Febrero del 2026
A5: POTENCIA ACTIVA EJECUTADA DE LAS UNIDADES DE GENERACIÓN DEL SEIN (MW) | FQ5: CENTRALES NO INTEGRANTES COES
A6: FECHA | B6: HORA | C6: 65333 | D6: 101 | E6: 102 | F6: 42667 | G6: 42668 | H6: 126 | I6: 127 | J6: 138 | K6: 139 | L6: 197 | M6: 203 | N6: 204 | O6: 230 | P6: 209 | Q6: 56677 | R6: 796 | S6: 2146 | T6: 142 | U6: 143 | V6: 125 | W6: 187 | X6: 163 | Y6: 298 | Z6: 299 | AA6: 219 | AB6: 151 | AC6: 152 | AD6: 153 | AE6: 154 | AF6: 756 | AG6: 156 | AH6: 155 | AI6: 182 | AJ6: 212 | AK6: 758 | AL6: 263 | AM6: 265 | AN6: 775 | AO6: 777 | AP6: 2154 | AQ6: 150 | AR6: 149 | AS6: 188 | AT6: 2131 | AU6: 755 | AV6: 252 | AW6: 249 | AX6: 250 | AY6: 117 | AZ6: 119 | BA6: 120 | BB6: 189 | BC6: 122 | BD6: 266 | BE6: 337 | BF6: 338 | BG6: 251 | BH6: 115 | BI6: 239 | BJ6: 288 | BK6: 240 | BL6: 241 | BM6: 242 | BN6: 191 | BO6: 194 | BP6: 196 | BQ6: 207 | BR6: 236 | BS6: 795 | BT6: 285 | BU6: 995 | BV6: 996 | BW6: 997 | BX6: 766 | BY6: 926 | BZ6: 924 | CA6: 121 | CB6: 103 | CC6: 104 | CD6: 106 | CE6: 105 | CF6: 107 | CG6: 110 | CH6: 109 | CI6: 144 | CJ6: 113 | CK6: 114 | CL6: 193 | CM6: 208 | CN6: 786 | CO6: 787 | CP6: 788 | CQ6: 789 | CR6: 248 | CS6: 2159 | CT6: 267 | CU6: 268 | CV6: 2194 | CW6: 303 | CX6: 59715 | CY6: 62255 | CZ6: 1263 | DA6: 61800 | DB6: 69125 | DC6: 216 | DD6: 198 | DE6: 70400 | DF6: 76068 | DG6: 49607 | DH6: 214 | DI6: 260 | DJ6: 2152 | DK6: 2128 | DL6: 247 | DM6: 228 | DN6: 2135 | DO6: 261 | DP6: 237 | DQ6: 253 | DR6: 770 | DS6: 235 | DT6: 238 | DU6: 2184 | DV6: 61855 | DW6: 223 | DX6: 75566 | DY6: 226 | DZ6: 201 | EA6: 258 | EB6: 259 | EC6: 257 | ED6: 256 | EE6: 2148 | EF6: 58288 | EG6: 58289 | EH6: 58839 | EI6: 58840 | EJ6: 75260 | EK6: 296 | EL6: 297 | EM6: 211 | EN6: 2175 | EO6: 2178 | EP6: 2181 | EQ6: 1262 | ER6: 63425 | ES6: 233 | ET6: 2150 | EU6: 2165 | EV6: 2161 | EW6: 61197 | EX6: 58851 | EY6: 225 | EZ6: 2201 | FA6: 2171 | FB6: 760 | FC6: 234 | FD6: 215 | FE6: 917 | FF6: 920 | FG6: 289 | FH6: 58333 | FI6: 58336 | FJ6: 213 | FK6: 232 | FL6: 2190 | FM6: 69867 | FN6: 75066 | FO6: TOTAL COES | FQ6: 221 | FR6: 222 | FS6: 224 | FT6: 2187 | FU6: 227 | FV6: 49400 | FW6: 199 | FX6: 200 | FY6: TOTAL NO COES
C7: SUR | D7: CENTRO | E7: CENTRO | F7: NORTE | G7: NORTE | H7: NORTE | I7: NORTE | J7: CENTRO | K7: CENTRO | L7: CENTRO | M7: CENTRO | N7: CENTRO | O7: CENTRO | P7: CENTRO | Q7: CENTRO | R7: CENTRO | S7: CENTRO | T7: CENTRO | U7: CENTRO | V7: CENTRO | W7: CENTRO | X7: SUR | Y7: SUR | Z7: SUR | AA7: CENTRO | AB7: SUR | AC7: SUR | AD7: SUR | AE7: SUR | AF7: SUR | AG7: SUR | AH7: SUR | AI7: SUR | AJ7: CENTRO | AK7: NORTE | AL7: NORTE | AM7: NORTE | AN7: CENTRO | AO7: CENTRO | AP7: CENTRO | AQ7: CENTRO | AR7: CENTRO | AS7: CENTRO | AT7: CENTRO | AU7: SUR | AV7: CENTRO | AW7: CENTRO | AX7: CENTRO | AY7: CENTRO | AZ7: CENTRO | BA7: CENTRO | BB7: SUR | BC7: NORTE | BD7: CENTRO | BE7: CENTRO | BF7: CENTRO | BG7: CENTRO | BH7: NORTE | BI7: NORTE | BJ7: NORTE | BK7: SUR | BL7: SUR | BM7: SUR | BN7: CENTRO | BO7: CENTRO | BP7: CENTRO | BQ7: CENTRO | BR7: CENTRO | BS7: CENTRO | BT7: CENTRO | BU7: SUR | BV7: SUR | BW7: SUR | BX7: NORTE | BY7: SUR | BZ7: CENTRO | CA7: NORTE | CB7: CENTRO | CC7: CENTRO | CD7: CENTRO | CE7: CENTRO | CF7: CENTRO | CG7: CENTRO | CH7: CENTRO | CI7: CENTRO | CJ7: CENTRO | CK7: CENTRO | CL7: CENTRO | CM7: CENTRO | CN7: SUR | CO7: SUR | CP7: SUR | CQ7: SUR | CR7: CENTRO | CS7: CENTRO | CT7: CENTRO | CU7: CENTRO | CV7: NORTE | CW7: CENTRO | CX7: CENTRO | CY7: SUR | CZ7: NORTE | DA7: NORTE | DB7: CENTRO | DC7: NORTE | DD7: NORTE | DE7: SUR | DG7: SUR | DH7: CENTRO | DI7: CENTRO | DJ7: CENTRO | DK7: NORTE | DL7: NORTE | DM7: CENTRO | DN7: CENTRO | DO7: SUR | DP7: SUR | DQ7: CENTRO | DR7: CENTRO | DS7: SUR | DT7: CENTRO | DU7: CENTRO | DV7: NORTE | DW7: CENTRO | DX7: CENTRO | DY7: CENTRO | DZ7: NORTE | EA7: CENTRO | EB7: CENTRO | EC7: NORTE | ED7: NORTE | EE7: SUR | EF7: CENTRO | EG7: CENTRO | EH7: CENTRO | EI7: CENTRO | EJ7: SUR | EK7: CENTRO | EL7: CENTRO | EM7: SUR | EN7: SUR | EO7: SUR | EP7: SUR | EQ7: NORTE | ER7: SUR | ES7: SUR | ET7: SUR | EU7: CENTRO | EV7: CENTRO | EW7: CENTRO | EX7: SUR | EY7: CENTRO | EZ7: CENTRO | FA7: CENTRO | FB7: CENTRO | FC7: SUR | FD7: NORTE | FE7: CENTRO | FF7: CENTRO | FG7: NORTE | FH7: NORTE | FI7: NORTE | FJ7: CENTRO | FK7: NORTE | FL7: NORTE | FM7: NORTE | FN7: NORTE | FQ7: NORTE | FR7: CENTRO | FS7: NORTE | FT7: NORTE | FU7: NORTE | FV7: NORTE | FW7: NORTE | FX7: NORTE
C8: HIDROELÉCTRICA | D8: HIDROELÉCTRICA | E8: HIDROELÉCTRICA | F8: TERMOELÉCTRICA | G8: TERMOELÉCTRICA | H8: HIDROELÉCTRICA | I8: HIDROELÉCTRICA | J8: TERMOELÉCTRICA | K8: TERMOELÉCTRICA | L8: TERMOELÉCTRICA | M8: TERMOELÉCTRICA | N8: TERMOELÉCTRICA | O8: TERMOELÉCTRICA | P8: TERMOELÉCTRICA | Q8: TERMOELÉCTRICA | R8: HIDROELÉCTRICA | S8: HIDROELÉCTRICA | T8: TERMOELÉCTRICA | U8: TERMOELÉCTRICA | V8: TERMOELÉCTRICA | W8: TERMOELÉCTRICA | X8: HIDROELÉCTRICA | Y8: HIDROELÉCTRICA | Z8: HIDROELÉCTRICA | AA8: TERMOELÉCTRICA | AB8: HIDROELÉCTRICA | AC8: HIDROELÉCTRICA | AD8: HIDROELÉCTRICA | AE8: HIDROELÉCTRICA | AF8: TERMOELÉCTRICA | AG8: TERMOELÉCTRICA | AH8: TERMOELÉCTRICA | AI8: HIDROELÉCTRICA | AJ8: HIDROELÉCTRICA | AK8: TERMOELÉCTRICA | AL8: TERMOELÉCTRICA | AM8: TERMOELÉCTRICA | AN8: HIDROELÉCTRICA | AO8: HIDROELÉCTRICA | AP8: HIDROELÉCTRICA | AQ8: HIDROELÉCTRICA | AR8: HIDROELÉCTRICA | AS8: HIDROELÉCTRICA | AT8: HIDROELÉCTRICA | AU8: HIDROELÉCTRICA | AV8: TERMOELÉCTRICA | AW8: TERMOELÉCTRICA | AX8: TERMOELÉCTRICA | AY8: HIDROELÉCTRICA | AZ8: HIDROELÉCTRICA | BA8: HIDROELÉCTRICA | BB8: HIDROELÉCTRICA | BC8: HIDROELÉCTRICA | BD8: HIDROELÉCTRICA | BE8: HIDROELÉCTRICA | BF8: HIDROELÉCTRICA | BG8: HIDROELÉCTRICA | BH8: TERMOELÉCTRICA | BI8: TERMOELÉCTRICA | BJ8: TERMOELÉCTRICA | BK8: TERMOELÉCTRICA | BL8: TERMOELÉCTRICA | BM8: TERMOELÉCTRICA | BN8: HIDROELÉCTRICA | BO8: TERMOELÉCTRICA | BP8: TERMOELÉCTRICA | BQ8: TERMOELÉCTRICA | BR8: TERMOELÉCTRICA | BS8: TERMOELÉCTRICA | BT8: TERMOELÉCTRICA | BU8: TERMOELÉCTRICA | BV8: TERMOELÉCTRICA | BW8: TERMOELÉCTRICA | BX8: HIDROELÉCTRICA | BY8: TERMOELÉCTRICA | BZ8: TERMOELÉCTRICA | CA8: HIDROELÉCTRICA | CB8: HIDROELÉCTRICA | CC8: HIDROELÉCTRICA | CD8: HIDROELÉCTRICA | CE8: HIDROELÉCTRICA | CF8: HIDROELÉCTRICA | CG8: TERMOELÉCTRICA | CH8: TERMOELÉCTRICA | CI8: TERMOELÉCTRICA | CJ8: TERMOELÉCTRICA | CK8: TERMOELÉCTRICA | CL8: TERMOELÉCTRICA | CM8: TERMOELÉCTRICA | CN8: TERMOELÉCTRICA | CO8: TERMOELÉCTRICA | CP8: TERMOELÉCTRICA | CQ8: TERMOELÉCTRICA | CR8: TERMOELÉCTRICA | CS8: TERMOELÉCTRICA | CT8: HIDROELÉCTRICA | CU8: HIDROELÉCTRICA | CV8: HIDROELÉCTRICA | CW8: SOLAR | CX8: EÓLICA | CY8: SOLAR | CZ8: EÓLICA | DA8: SOLAR | DB8: HIDROELÉCTRICA | DC8: HIDROELÉCTRICA | DD8: HIDROELÉCTRICA | DE8: SOLAR | DF8: SOLAR | DG8: HIDROELÉCTRICA | DH8: HIDROELÉCTRICA | DI8: HIDROELÉCTRICA | DJ8: HIDROELÉCTRICA | DK8: HIDROELÉCTRICA | DL8: HIDROELÉCTRICA | DM8: HIDROELÉCTRICA | DN8: HIDROELÉCTRICA | DO8: SOLAR | DP8: SOLAR | DQ8: EÓLICA | DR8: EÓLICA | DS8: SOLAR | DT8: HIDROELÉCTRICA | DU8: HIDROELÉCTRICA | DV8: HIDROELÉCTRICA | DW8: HIDROELÉCTRICA | DX8: SOLAR | DY8: HIDROELÉCTRICA | DZ8: HIDROELÉCTRICA | EA8: HIDROELÉCTRICA | EB8: HIDROELÉCTRICA | EC8: EÓLICA | ED8: EÓLICA | EE8: SOLAR | EF8: EÓLICA | EG8: EÓLICA | EH8: EÓLICA | EI8: EÓLICA | EJ8: SOLAR | EK8: HIDROELÉCTRICA | EL8: HIDROELÉCTRICA | EM8: HIDROELÉCTRICA | EN8: HIDROELÉCTRICA | EO8: HIDROELÉCTRICA | EP8: HIDROELÉCTRICA | EQ8: EÓLICA | ER8: SOLAR | ES8: SOLAR | ET8: SOLAR | EU8: HIDROELÉCTRICA | EV8: EÓLICA | EW8: EÓLICA | EX8: SOLAR | EY8: TERMOELÉCTRICA | EZ8: TERMOELÉCTRICA | FA8: TERMOELÉCTRICA | FB8: TERMOELÉCTRICA | FC8: SOLAR | FD8: HIDROELÉCTRICA | FE8: HIDROELÉCTRICA | FF8: HIDROELÉCTRICA | FG8: TERMOELÉCTRICA | FH8: TERMOELÉCTRICA | FI8: TERMOELÉCTRICA | FJ8: TERMOELÉCTRICA | FK8: TERMOELÉCTRICA | FL8: TERMOELÉCTRICA | FM8: TERMOELÉCTRICA | FN8: TERMOELÉCTRICA | FQ8: HIDROELÉCTRICA | FR8: HIDROELÉCTRICA | FS8: HIDROELÉCTRICA | FT8: HIDROELÉCTRICA | FU8: TERMOELÉCTRICA | FV8: TERMOELÉCTRICA | FW8: HIDROELÉCTRICA | FX8: HIDROELÉCTRICA
C9: HYDRO GLOBAL PERÚ S.A.C. | D9: ELECTROPERU | E9: ELECTROPERU | F9: ELECTROPERU | G9: ELECTROPERU | H9: ORAZUL ENERGY PERÚ | I9: ORAZUL ENERGY PERÚ | J9: TERMOSELVA | K9: TERMOSELVA | L9: KALLPA GENERACION S.A. | M9: KALLPA GENERACION S.A. | N9: KALLPA GENERACION S.A. | O9: KALLPA GENERACION S.A. | P9: KALLPA GENERACION S.A. | Q9: KALLPA GENERACION S.A. | R9: KALLPA GENERACION S.A. | S9: KALLPA GENERACION S.A. | T9: SHOUGESA | U9: SHOUGESA | V9: SHOUGESA | W9: SHOUGESA | X9: EGEMSA | Y9: EGESUR | Z9: EGESUR | AA9: EGESUR | AB9: EGASA | AC9: EGASA | AD9: EGASA | AE9: EGASA | AF9: EGASA | AG9: EGASA | AH9: EGASA | AI9: SAN GABAN | AJ9: CELEPSA | AK9: MINERA CERRO VERDE | AL9: PLANTA DE RESERVA FRIA DE GENERACION DE ETEN S.A. | AM9: PLANTA DE RESERVA FRIA DE GENERACION DE ETEN S.A. | AN9: EMPRESA DE GENERACION HUALLAGA | AO9: EMPRESA DE GENERACION HUALLAGA | AP9: LA VIRGEN | AQ9: CHINANGO S.A.C. | AR9: CHINANGO S.A.C. | AS9: HIDROELECTRICA HUANCHOR S.A.C. | AT9: CELEPSA RENOVABLES S.R.L. | AU9: INLAND ENERGY SAC | AV9: FENIX POWER PERÚ | AW9: FENIX POWER PERÚ | AX9: FENIX POWER PERÚ | AY9: STATKRAFT S.A | AZ9: STATKRAFT S.A | BA9: STATKRAFT S.A | BB9: STATKRAFT S.A | BC9: STATKRAFT S.A | BD9: STATKRAFT S.A | BE9: CENTRALES SANTA ROSA S.A.C. | BF9: CENTRALES SANTA ROSA S.A.C. | BG9: EMPRESA DE GENERACION HUANZA | BH9: ENEL GENERACION PIURA S.A. | BI9: ENEL GENERACION PIURA S.A. | BJ9: ENEL GENERACION PIURA S.A. | BK9: ENGIE ENERGIA PERU S.A.A. | BL9: ENGIE ENERGIA PERU S.A.A. | BM9: ENGIE ENERGIA PERU S.A.A. | BN9: ENGIE ENERGIA PERU S.A.A. | BO9: ENGIE ENERGIA PERU S.A.A. | BP9: ENGIE ENERGIA PERU S.A.A. | BQ9: ENGIE ENERGIA PERU S.A.A. | BR9: ENGIE ENERGIA PERU S.A.A. | BS9: ENGIE ENERGIA PERU S.A.A. | BT9: ENGIE ENERGIA PERU S.A.A. | BU9: ENGIE ENERGIA PERU S.A.A. | BV9: ENGIE ENERGIA PERU S.A.A. | BW9: ENGIE ENERGIA PERU S.A.A. | BX9: ENGIE ENERGIA PERU S.A.A. | BY9: INFRAESTRUCTURAS Y ENERGIAS DEL PERU S.A.C. | BZ9: INFRAESTRUCTURAS Y ENERGIAS DEL PERU S.A.C. | CA9: INVERSIONES SHAQSHA S.A.C. | CB9: ORYGEN PERU S.A.A. | CC9: ORYGEN PERU S.A.A. | CD9: ORYGEN PERU S.A.A. | CE9: ORYGEN PERU S.A.A. | CF9: ORYGEN PERU S.A.A. | CG9: ORYGEN PERU S.A.A. | CH9: ORYGEN PERU S.A.A. | CI9: ORYGEN PERU S.A.A. | CJ9: ORYGEN PERU S.A.A. | CK9: ORYGEN PERU S.A.A. | CL9: ORYGEN PERU S.A.A. | CM9: ORYGEN PERU S.A.A. | CN9: SAMAY I S.A.C | CO9: SAMAY I S.A.C | CP9: SAMAY I S.A.C | CQ9: SAMAY I S.A.C | CR9: TERMOCHILCA S.A.C. | CS9: TERMOCHILCA S.A.C. | CT9: TRANSMISION ANDINA DE GENERACION S.A.C. | CU9: TRANSMISION ANDINA DE GENERACION S.A.C. | CV9: CELARIS ENERGY S.A. | CW9: COLCA SOLAR S.A.C. | CX9: ENERGIA RENOVABLE DEL SUR S.A. | CY9: GR CORTARRAMA SOCIEDAD ANONIMA CERRADA | CZ9: GR TARUCA SOCIEDAD ANONIMA CERRADA | DA9: KONDU SAC | DB9: VARI ENERGIA S.A.C. | DC9: ORAZUL ENERGY PERÚ | DD9: ORAZUL ENERGY PERÚ | DE9: KALLPA GENERACION S.A. | DF9: KALLPA GENERACION S.A. | DG9: SAN GABAN | DH9: MAJA ENERGIA S.A.C. | DI9: EMPRESA DE GENERACION ELECTRICA CANCHAYLLO SAC | DJ9: EMPRESA DE GENERACION ELECTRICA SANTA ANA S.A.C. | DK9: EMPRESA ELECTRICA AGUA AZUL | DL9: EMPRESA ELECTRICA RIO DOBLE | DM9: HIDROCAÑETE S.A. | DN9: HUAURA POWER GROUP S.A. | DO9: MOQUEGUA FV S.A.C. | DP9: PANAMERICANA SOLAR SAC. | DQ9: PARQUE EOLICO MARCONA S.A.C. | DR9: PARQUE EOLICO TRES HERMANAS S.A.C. | DS9: TACNA SOLAR SAC. | DT9: ELECTRICA YANAPAMPA SAC | DU9: ANDEAN POWER S.A.C. | DV9: ASOCIACIÓN SANTA LUCIA DE CHACAS | DW9: ATRIA ENERGIA S.A.C. | DX9: COENERGY S.A.C. | DY9: EGEJUNIN | DZ9: EGEJUNIN | EA9: EGEJUNIN | EB9: EGEJUNIN | EC9: ENERGÍA EÓLICA S.A. | ED9: ENERGÍA EÓLICA S.A. | EE9: ENGIE ENERGIA PERU S.A.A. | EF9: ENGIE ENERGIA PERU S.A.A. | EG9: ENGIE ENERGIA PERU S.A.A. | EH9: ENGIE ENERGIA PERU S.A.A. | EI9: ENGIE ENERGIA PERU S.A.A. | EJ9: ENGIE ENERGIA PERU S.A.A. | EK9: GENERACIÓN ANDINA S.A.C. | EL9: GENERACIÓN ANDINA S.A.C. | EM9: GENERADORA DE ENERGÍA DEL PERÚ | EN9: GENERADORA DE ENERGÍA DEL PERÚ | EO9: GENERADORA DE ENERGÍA DEL PERÚ | EP9: GENERADORA DE ENERGÍA DEL PERÚ | EQ9: GR PAINO SOCIEDAD ANONIMA CERRADA | ER9: JOYA SOLAR S.A.C. | ES9: MAJES ARCUS S.A.C. | ET9: ORYGEN PERU S.A.A. | EU9: ORYGEN PERU S.A.A. | EV9: ORYGEN PERU S.A.A. | EW9: ORYGEN PERU S.A.A. | EX9: ORYGEN PERU S.A.A. | EY9: PETRAMAS | EZ9: PETRAMAS | FA9: PETRAMAS | FB9: PETRAMAS | FC9: REPARTICIÓN ARCUS S.A.C. | FD9: SINERSA | FE9: SINERSA | FF9: SINERSA | FG9: BIOENERGIA DEL CHIRA S.A. | FH9: GM OPERACIONES S.A.C. | FI9: GM OPERACIONES S.A.C. | FJ9: AGRO INDUSTRIAL PARAMONGA S.A. | FK9: AGROAURORA S.A.C. | FL9: AGROINDUSTRIAS SAN JACINTO S.A.A. | FM9: AGROLMOS SOCIEDAD ANONIMA - AGROLMOS S.A. | FN9: CASA GRANDE S.A.A. | FQ9: UNACEM PERU S.A. | FR9: ELECTRO ORIENTE | FS9: AGUAS Y ENERGIA PERU | FT9: ELECTRO ZAÑA S.A.C. | FU9: ELECTRONOROESTE S.A. | FV9: SDE PIURA | FW9: SINERSA | FX9: SINERSA
C10: SAN GABAN III | D10: MANTARO | E10: RESTITUCION | F10: TUMBES MAK 1 | G10: TUMBES MAK 2 | H10: CARHUAQUERO | I10: CAÑON DEL PATO | J10: AGUAYTIA TG1 | K10: AGUAYTIA TG2 | L10: KALLPA TG1 | M10: KALLPA TG2 | N10: KALLPA TG3 | O10: KALLPA TV | P10: LFLORES TG1 | Q10: LFLORES TV | R10: CERRO DEL AGUILA | S10: CERRODELAGUILAG4 | T10: SHOUGESA TV1 | U10: SHOUGESA TV2 | V10: SHOUGESA TV3 | W10: SHOUGESA CUMMINS | X10: MACHUPICCHU | Y10: ARICOTA 1 | Z10: ARICOTA 2 | AA10: INDEPENDENCIA | AB10: CHARCANI I,II,III | AC10: CHARCANI IV | AD10: CHARCANI V | AE10: CHARCANI VI | AF10: CHILINA TG | AG10: MOLLENDO 1, 2, 3 | AH10: CHILINA (SULZ 1,2) | AI10: SAN GABAN II | AJ10: PLATANAL | AK10: RECKA | AL10: RF ETEN TG1 | AM10: RF ETEN TG2 | AN10: CHAGLLA GP1 | AO10: CHAGLLA | AP10: LA VIRGEN | AQ10: CHIMAY | AR10: YANANGO | AS10: HUANCHOR | AT10: MARAÑON | AU10: STA TERESA | AV10: FENIX GT11 | AW10: FENIX GT12 | AX10: FENIX TV10 | AY10: YAUPI | AZ10: MALPASO | BA10: CAHUA | BB10: ARCATA | BC10: GALLITO CIEGO | BD10: CHEVES | BE10: SANTA ROSA 1 | BF10: SANTA ROSA 2 | BG10: HUANZA | BH10: MALACAS2 TG4 | BI10: MALACAS3 TG 5 | BJ10: MALACAS1 TG6 | BK10: RF ILO2 TG1 | BL10: RF ILO2 TG2 | BM10: RF ILO2 TG3 | BN10: YUNCAN | BO10: CHILCA1 TG1 | BP10: CHILCA1 TG2 | BQ10: CHILCA1 TG3 | BR10: CHILCA-TV | BS10: CHILCA2 TG41 | BT10: CHILCA2-TV | BU10: CTNEPI_TG41 | BV10: CTNEPI_TG42 | BW10: CTNEPI_TG43 | BX10: QUITARACSA | BY10: RF PTO MALDONADO | BZ10: RF PUCALLPA | CA10: PARIAC | CB10: HUINCO | CC10: MATUCANA | CD10: MOYOPAMPA | CE10: CALLAHUANCA | CF10: HUAMPANI | CG10: STA ROSA WEST TG7 | CH10: UTI_5 | CI10: UTI_6 | CJ10: VENTANILLA 3 | CK10: VENTANILLA 4 | CL10: VENTANILLA TV | CM10: STAROSA TG8 | CN10: PTO_BRVO TG1 | CO10: PTO_BRVO TG2 | CP10: PTO_BRVO TG3 | CQ10: PTO_BRVO TG4 | CR10: OLLEROS TG1 | CS10: OLLEROS TV | CT10: OROYA | CU10: PACHACHACA | CV10: MANTA I | CW10: CS YARUCAYA | CX10: SAN JUAN | CY10: MATARANI | CZ10: DUNA | DA10: CARHUAQUERO (CS) | DB10: ANASHIRONI | DC10: CARHUAQUERO4 | DD10: CAÑA BRAVA | DE10: SUNNY | DF10: SUNNY EXPANSION | DG10: TUPURI | DH10: RONCADOR | DI10: CANCHAYLLO | DJ10: RENOVANDESH1 | DK10: POTRERO | DL10: PIZARRAS | DM10: NIMPERIAL | DN10: YARUCAYA | DO10: MOQUEGUA-SOLAR | DP10: PANAMERICANA-SOLAR | DQ10: PQE-EOLICO-MARCONA | DR10: PQE-EOLICO-3-HERMANAS | DS10: TACNA-SOLAR | DT10: YANAPAMPA | DU10: CARHUAC | DV10: HUALLIN | DW10: PURMACANA | DX10: COENERGY | DY10: HUASAHUASI | DZ10: STACRUZ_1_2 | EA10: RUNATULLO_II | EB10: RUNATULLO_III | EC10: PQE-EOLICO-TALARA | ED10: PQE-EOLICO-CUPISNIQUE | EE10: INTIPAMPA | EF10: PUNTA LOMITAS-BL1 | EG10: PUNTA LOMITAS-BL2 | EH10: PUN LOMITAS_EXP-BL1 | EI10: PUN LOMITAS_EXP-BL2 | EJ10: EXPANSIÓN INTIPAMPA | EK10: 8AGOSTO | EL10: EL CARMEN | EM10: LA JOYA | EN10: ANGEL_I | EO10: ANGEL_II | EP10: ANGEL_III | EQ10: HUAMBOS | ER10: SAN MARTIN SOLAR | ES10: MAJES | ET10: RUBI | EU10: CH_HER1 | EV10: WAYRA-I | EW10: WAYRA EXTENSION | EX10: CLEMESI | EY10: HUAYCOLORO | EZ10: CALLAO | FA10: DONA_CATALINA | FB10: LAGRINGAV | FC10: REPARTICION | FD10: POECHOS2 | FE10: CHANCAY | FF10: RUCUY | FG10: CANA BRAVA | FH10: REFINERIA TALARA TV1 | FI10: REFINERÍA TALARA TV2 | FJ10: PARAMONGA | FK10: MAPLE | FL10: SAN_JACINTO | FM10: AGROLMOS | FN10: CASA GRANDE | FO10: MW | FQ10: CARPAPATA | FR10: CENTRALES ELOR | FS10: PIAS1 | FT10: ZANA | FU10: TABLAZO | FV10: TALLANCA | FW10: CURUMUY | FX10: POECHOS1 | FY10: MW
A11: 12/02/2026 | B11: 00:30 | C11: 198.3 | D11: 629.3 | E11: 214.5 | H11: 87.5 | I11: 239.1 | K11: 59.6 | L11: 150 | M11: 150.2 | N11: 149.8 | O11: 247.5 | P11: 206.1 | Q11: 108.3 | R11: 551 | S11: 10 | X11: 163.2 | Y11: 8.4 | Z11: 5.7 | AA11: 0 | AB11: 6.7 | AD11: 141.9 | AI11: 109.5 | AJ11: 218.1 | AN11: 6.5 | AO11: 455.7 | AP11: 73.6 | AQ11: 146.9 | AR11: 42.2 | AS11: 17.2 | AT11: 18.9 | AU11: 88 | AY11: 85.5 | AZ11: 0 | BA11: 43.9 | BB11: 4 | BC11: 32.9 | BD11: 128 | BG11: 0 | BJ11: 0 | BK11: 0 | BN11: 82.6 | BO11: 0 | BP11: 0 | BQ11: 0 | BS11: 39.5 | BT11: 27.9 | CA11: 2.4 | CB11: 82.4 | CC11: 127.7 | CD11: 61.1 | CE11: 75.9 | CF11: 29.3 | CJ11: 140.8 | CK11: 141.4 | CL11: 146.6 | CM11: 0 | CR11: 208 | CS11: 99.7 | CT11: 7 | CU11: 4.4 | CV11: 20 | CW11: 0 | CX11: 66.7 | CY11: 0 | CZ11: 0 | DA11: 0 | DB11: 20 | DC11: 9.9 | DD11: 5.5 | DE11: 0 | DG11: 2 | DH11: 2.3 | DI11: 4.9 | DJ11: 20 | DK11: 20 | DL11: 18.9 | DM11: 3.4 | DN11: 18.4 | DO11: 0 | DP11: 0 | DQ11: 19.9 | DR11: 49 | DS11: 0 | DT11: 3.4 | DU11: 3.5 | DV11: 2.9 | DW11: 0.4 | DX11: 0 | DY11: 19.8 | DZ11: 7.8 | EA11: 20 | EB11: 20.1 | EC11: 0 | ED11: 17.8 | EE11: 0 | EF11: 49.8 | EG11: 72 | EH11: 6.1 | EI11: 4.1 | EJ11: 0 | EK11: 17.2 | EL11: 6.5 | EM11: 3.7 | EN11: 20.4 | EO11: 20.4 | EP11: 20 | EQ11: 0.1 | ER11: 0 | ES11: 0 | ET11: 0 | EU11: 0.6 | EV11: 42.5 | EW11: 46 | EX11: 0 | EY11: 3.9 | EZ11: 2.3 | FA11: 2.4 | FB11: 0.8 | FC11: 0 | FD11: 8 | FE11: 20 | FF11: 20 | FG11: 9 | FH11: 27.5 | FI11: 34.3 | FJ11: 15.4 | FK11: 13.5 | FL11: 6.1 | FM11: 11.7 | FN11: 16.2 | FO11: 6951.8 | FQ11: 24.5 | FR11: 2.561 | FS11: 11.86 | FT11: 13.2 | FU11: 25.18735 | FV11: 18.94734 | FW11: 11.6 | FX11: 14.3 | FY11: 122.15569
A12: 12/02/2026 | B12: 01:00 | C12: 203.1 | D12: 634.2 | E12: 215.3 | H12: 90.1 | I12: 242 | K12: 61.7 | L12: 144.4 | M12: 142.6 | N12: 143.8 | O12: 242.6 | P12: 206.5 | Q12: 108.9 | R12: 557.9 | S12: 10.3 | X12: 166.8 | Y12: 7.2 | Z12: 5.8 | AA12: 0 | AB12: 6.7 | AD12: 142.3 | AI12: 110.5 | AJ12: 222.5 | AN12: 6.5 | AO12: 457.1 | AP12: 73.7 | AQ12: 151.7 | AR12: 42.2 | AS12: 18.4 | AT12: 18.9 | AU12: 90.4 | AY12: 85.5 | AZ12: 0 | BA12: 44.9 | BB12: 4 | BC12: 33.6 | BD12: 135.7 | BG12: 0 | BJ12: 0 | BK12: 0 | BN12: 84.4 | BO12: 0 | BP12: 0 | BQ12: 0 | BS12: 39.2 | BT12: 27.7 | CA12: 2.4 | CB12: 25.1 | CC12: 133.9 | CD12: 62.4 | CE12: 76.7 | CF12: 30 | CJ12: 140.5 | CK12: 141.6 | CL12: 147.2 | CM12: 0 | CR12: 207.7 | CS12: 99.5 | CT12: 7 | CU12: 4.4 | CV12: 20 | CW12: 0 | CX12: 57 | CY12: 0 | CZ12: 0 | DA12: 0 | DB12: 20.2 | DC12: 9.9 | DD12: 5.5 | DE12: 0 | DG12: 2 | DH12: 2.3 | DI12: 4.9 | DJ12: 20.2 | DK12: 20 | DL12: 18.9 | DM12: 3.4 | DN12: 18.4 | DO12: 0 | DP12: 0 | DQ12: 17.9 | DR12: 44 | DS12: 0 | DT12: 2.7 | DU12: 3.5 | DV12: 2.9 | DW12: 0.4 | DX12: 0 | DY12: 19.8 | DZ12: 7.8 | EA12: 20.2 | EB12: 20.2 | EC12: 0 | ED12: 13.1 | EE12: 0 | EF12: 29.9 | EG12: 59.6 | EH12: 4.1 | EI12: 2.8 | EJ12: 0 | EK12: 17.2 | EL12: 6.5 | EM12: 3.9 | EN12: 20.4 | EO12: 20.4 | EP12: 20 | EQ12: 0 | ER12: 0 | ES12: 0 | ET12: 0 | EU12: 0.6 | EV12: 28.6 | EW12: 26.7 | EX12: 0 | EY12: 3.9 | EZ12: 2.3 | FA12: 2.4 | FB12: 0.8 | FC12: 0 | FD12: 8 | FE12: 20 | FF12: 20 | FG12: 8.4 | FH12: 27.4 | FI12: 34.3 | FJ12: 15.2 | FK12: 13.5 | FL12: 8.8 | FM12: 11.7 | FN12: 8 | FO12: 6838.1 | FQ12: 24.5 | FR12: 2.559 | FS12: 11.86 | FT12: 13.2 | FU12: 25.21992 | FV12: 18.94792 | FW12: 11.6 | FX12: 14.4 | FY12: 122.28684
A13: 12/02/2026 | B13: 01:30 | C13: 198.3 | D13: 625.7 | E13: 212.2 | H13: 89.1 | I13: 239.4 | K13: 58.9 | L13: 122.8 | M13: 122.7 | N13: 123.1 | O13: 233.6 | P13: 206.7 | Q13: 108.7 | R13: 545.5 | S13: 10 | X13: 161.9 | Y13: 7.3 | Z13: 5.7 | AA13: 0 | AB13: 6.7 | AD13: 141.4 | AI13: 109.6 | AJ13: 219.5 | AN13: 6.5 | AO13: 456.9 | AP13: 73.9 | AQ13: 150 | AR13: 42.1 | AS13: 18.6 | AT13: 18.9 | AU13: 89.5 | AY13: 85.5 | AZ13: 0 | BA13: 43.9 | BB13: 4 | BC13: 33.4 | BD13: 103.6 | BG13: 0 | BJ13: 0 | BK13: 0 | BN13: 83.4 | BO13: 0 | BP13: 0 | BQ13: 0 | BS13: 39 | BT13: 27.9 | CA13: 2.4 | CB13: 22.5 | CC13: 126.2 | CD13: 61.3 | CE13: 76 | CF13: 29.5 | CJ13: 140.9 | CK13: 141.6 | CL13: 147.2 | CM13: 0 | CR13: 208.3 | CS13: 99.7 | CT13: 7 | CU13: 4.3 | CV13: 20 | CW13: 0 | CX13: 58.1 | CY13: 0 | CZ13: 0 | DA13: 0 | DB13: 20.1 | DC13: 10 | DD13: 5.2 | DE13: 0 | DG13: 2 | DH13: 2 | DI13: 4.9 | DJ13: 20 | DK13: 20 | DL13: 18.8 | DM13: 3.4 | DN13: 18.4 | DO13: 0 | DP13: 0 | DQ13: 17.8 | DR13: 47.1 | DS13: 0 | DT13: 2.4 | DU13: 3.4 | DV13: 2.9 | DW13: 0.4 | DX13: 0 | DY13: 19.8 | DZ13: 7.7 | EA13: 20.1 | EB13: 20.2 | EC13: 0 | ED13: 9.5 | EE13: 0 | EF13: 31.6 | EG13: 52.9 | EH13: 2 | EI13: 1.6 | EJ13: 0 | EK13: 17.2 | EL13: 6.5 | EM13: 3.9 | EN13: 20.4 | EO13: 20.4 | EP13: 20 | EQ13: 0 | ER13: 0 | ES13: 0 | ET13: 0 | EU13: 0.6 | EV13: 21.8 | EW13: 17.3 | EX13: 0 | EY13: 3.9 | EZ13: 2.3 | FA13: 2.4 | FB13: 0.8 | FC13: 0 | FD13: 8 | FE13: 19.9 | FF13: 19.9 | FG13: 8.5 | FH13: 27.7 | FI13: 34.6 | FJ13: 14.7 | FK13: 13.5 | FL13: 8.9 | FM13: 11.7 | FN13: 9.8 | FO13: 6649.8 | FQ13: 24.5 | FR13: 2.558 | FS13: 11.86 | FT13: 13.2 | FU13: 25.30053 | FV13: 18.9485 | FW13: 11.6 | FX13: 14.3 | FY13: 122.26703
A14: 12/02/2026 | B14: 02:00 | C14: 201.3 | D14: 636.2 | E14: 216.1 | H14: 91.2 | I14: 242.8 | K14: 61.3 | L14: 122.3 | M14: 122.7 | N14: 122.6 | O14: 218.8 | P14: 206.1 | Q14: 108.1 | R14: 559 | S14: 10.2 | X14: 164.1 | Y14: 7.7 | Z14: 5.5 | AA14: 0 | AB14: 6.7 | AD14: 142.6 | AI14: 110.4 | AJ14: 187.3 | AN14: 6.5 | AO14: 456.6 | AP14: 74.4 | AQ14: 151 | AR14: 42.3 | AS14: 18.4 | AT14: 18.9 | AU14: 95.1 | AY14: 85.5 | AZ14: 0 | BA14: 44.6 | BB14: 4 | BC14: 33.7 | BD14: 125.4 | BG14: 0 | BJ14: 0 | BK14: 0 | BN14: 84.5 | BO14: 0 | BP14: 0 | BQ14: 0 | BS14: 38.7 | BT14: 27.9 | CA14: 2.4 | CB14: 25.3 | CC14: 131.7 | CD14: 62.5 | CE14: 76.7 | CF14: 30.1 | CJ14: 140.3 | CK14: 141.2 | CL14: 146.6 | CM14: 0 | CR14: 208.2 | CS14: 99.8 | CT14: 7 | CU14: 4.4 | CV14: 20 | CW14: 0 | CX14: 66.4 | CY14: 0 | CZ14: 0 | DA14: 0 | DB14: 20.2 | DC14: 9.9 | DD14: 5.2 | DE14: 0 | DG14: 2 | DH14: 2 | DI14: 4.9 | DJ14: 20.2 | DK14: 20 | DL14: 18.8 | DM14: 3.4 | DN14: 18.4 | DO14: 0 | DP14: 0 | DQ14: 18.2 | DR14: 44.7 | DS14: 0 | DT14: 2.4 | DU14: 3.2 | DV14: 2.9 | DW14: 0.4 | DX14: 0 | DY14: 19.8 | DZ14: 7.8 | EA14: 20.1 | EB14: 20.2 | EC14: 0 | ED14: 9.2 | EE14: 0 | EF14: 23.8 | EG14: 49.2 | EH14: 2.7 | EI14: 2.4 | EJ14: 0 | EK14: 17.2 | EL14: 6.5 | EM14: 3.9 | EN14: 20.4 | EO14: 20.4 | EP14: 20 | EQ14: 0 | ER14: 0 | ES14: 0 | ET14: 0 | EU14: 0.6 | EV14: 19.1 | EW14: 13.1 | EX14: 0 | EY14: 3.9 | EZ14: 2.3 | FA14: 2.4 | FB14: 0.8 | FC14: 0 | FD14: 7.9 | FE14: 20 | FF14: 20 | FG14: 8.7 | FH14: 27.8 | FI14: 34.6 | FJ14: 14.9 | FK14: 13.5 | FL14: 8.9 | FM14: 11.6 | FN14: 10 | FO14: 6673.6 | FQ14: 24.5 | FR14: 2.558 | FS14: 11.86 | FT14: 13.2 | FU14: 25.29746 | FV14: 18.94877 | FW14: 11.7 | FX14: 14.3 | FY14: 122.36423
A15: 12/02/2026 | B15: 02:30 | C15: 205.8 | D15: 639.4 | E15: 216.3 | H15: 90.4 | I15: 243.6 | K15: 60.7 | L15: 114.8 | M15: 114.9 | N15: 113.1 | O15: 209 | P15: 203.5 | Q15: 108.1 | R15: 561.5 | S15: 10.3 | X15: 171.7 | Y15: 8 | Z15: 5.4 | AA15: 0 | AB15: 6.7 | AD15: 142.4 | AI15: 110.4 | AJ15: 221.4 | AN15: 6.5 | AO15: 458.8 | AP15: 75.3 | AQ15: 152.5 | AR15: 42.3 | AS15: 18.4 | AT15: 18.9 | AU15: 93.7 | AY15: 85.5 | AZ15: 0 | BA15: 46.1 | BB15: 4 | BC15: 35.2 | BD15: 66.9 | BG15: 0 | BJ15: 0 | BK15: 0 | BN15: 84.8 | BO15: 0 | BP15: 0 | BQ15: 0 | BS15: 38.8 | BT15: 27.8 | CA15: 2.4 | CB15: 33.3 | CC15: 126 | CD15: 63 | CE15: 74.3 | CF15: 30.3 | CJ15: 140.2 | CK15: 141.1 | CL15: 146.5 | CM15: 0 | CR15: 208 | CS15: 99.5 | CT15: 7 | CU15: 4.4 | CV15: 20 | CW15: 0 | CX15: 45.9 | CY15: 0 | CZ15: 0 | DA15: 0 | DB15: 20.4 | DC15: 9.9 | DD15: 5.5 | DE15: 0 | DG15: 2 | DH15: 2 | DI15: 4.9 | DJ15: 20.4 | DK15: 20 | DL15: 18.8 | DM15: 3.4 | DN15: 18.4 | DO15: 0 | DP15: 0 | DQ15: 16.4 | DR15: 49.4 | DS15: 0 | DT15: 3.2 | DU15: 3.2 | DV15: 2.8 | DW15: 0.4 | DX15: 0 | DY15: 19.8 | DZ15: 7.8 | EA15: 19.8 | EB15: 20.2 | EC15: 0 | ED15: 12.6 | EE15: 0 | EF15: 29.4 | EG15: 37.7 | EH15: 2.9 | EI15: 3.9 | EJ15: 0 | EK15: 17.2 | EL15: 6.6 | EM15: 3.9 | EN15: 20.4 | EO15: 20.4 | EP15: 20 | EQ15: 0 | ER15: 0 | ES15: 0 | ET15: 0 | EU15: 0.6 | EV15: 5.9 | EW15: 6.3 | EX15: 0 | EY15: 3.9 | EZ15: 2.3 | FA15: 2.4 | FB15: 0.8 | FC15: 0 | FD15: 8 | FE15: 20 | FF15: 20 | FG15: 9.1 | FH15: 27.8 | FI15: 34.7 | FJ15: 15.2 | FK15: 13.5 | FL15: 8.9 | FM15: 11.6 | FN15: 11.6 | FO15: 6601.1 | FQ15: 24.5 | FR15: 2.559 | FS15: 11.86 | FT15: 13.2 | FU15: 25.2635 | FV15: 18.94844 | FW15: 11.6 | FX15: 14.3 | FY15: 122.23094
A16: 12/02/2026 | B16: 03:00 | C16: 202.4 | D16: 634.6 | E16: 215.5 | H16: 90.3 | I16: 242.5 | K16: 60.7 | L16: 142.3 | M16: 142.5 | N16: 142.5 | O16: 241.9 | P16: 204.3 | Q16: 108.8 | R16: 445.5 | S16: 10.2 | X16: 167.4 | Y16: 7.6 | Z16: 5.3 | AA16: 0 | AB16: 6.7 | AD16: 142.3 | AI16: 110.5 | AJ16: 222.6 | AN16: 6.5 | AO16: 459.4 | AP16: 76.1 | AQ16: 151.6 | AR16: 42.3 | AS16: 18.3 | AT16: 18.9 | AU16: 92.9 | AY16: 85.5 | AZ16: 0 | BA16: 45.2 | BB16: 4 | BC16: 34.3 | BD16: 45.9 | BG16: 0 | BJ16: 0 | BK16: 0 | BN16: 84.5 | BO16: 0 | BP16: 0 | BQ16: 0 | BS16: 39.1 | BT16: 27.9 | CA16: 2.4 | CB16: 51.3 | CC16: 134.5 | CD16: 62.5 | CE16: 74.2 | CF16: 30.2 | CJ16: 141.4 | CK16: 141.8 | CL16: 146.5 | CM16: 0 | CR16: 208 | CS16: 99.7 | CT16: 7 | CU16: 4.4 | CV16: 20.1 | CW16: 0 | CX16: 33.7 | CY16: 0 | CZ16: 0 | DA16: 0 | DB16: 20.3 | DC16: 9.9 | DD16: 5.4 | DE16: 0 | DG16: 2 | DH16: 2.1 | DI16: 4.9 | DJ16: 20.4 | DK16: 20 | DL16: 18.8 | DM16: 3.4 | DN16: 18.4 | DO16: 0 | DP16: 0 | DQ16: 11.4 | DR16: 37.3 | DS16: 0 | DT16: 3.5 | DU16: 3.2 | DV16: 2.8 | DW16: 0.4 | DX16: 0 | DY16: 19.8 | DZ16: 7.8 | EA16: 20 | EB16: 20.2 | EC16: 0 | ED16: 16.1 | EE16: 0 | EF16: 21 | EG16: 49.5 | EH16: 3.1 | EI16: 3.5 | EJ16: 0 | EK16: 17.2 | EL16: 6.6 | EM16: 3.9 | EN16: 20.4 | EO16: 20.4 | EP16: 20 | EQ16: 0 | ER16: 0 | ES16: 0 | ET16: 0 | EU16: 0.6 | EV16: 4.4 | EW16: 9.3 | EX16: 0 | EY16: 3.9 | EZ16: 2.3 | FA16: 2.4 | FB16: 0.8 | FC16: 0 | FD16: 7.9 | FE16: 20 | FF16: 20 | FG16: 9 | FH16: 27.8 | FI16: 34.7 | FJ16: 15.2 | FK16: 13.6 | FL16: 8.9 | FM16: 11.6 | FN16: 11.3 | FO16: 6573.9 | FQ16: 24.5 | FR16: 2.56 | FS16: 11.86 | FT16: 13.2 | FU16: 25.21771 | FV16: 18.94897 | FW16: 11.6 | FX16: 14.3 | FY16: 122.18668
A17: 12/02/2026 | B17: 03:30 | C17: 201.1 | D17: 636.6 | E17: 216.4 | H17: 90.2 | I17: 241.6 | K17: 60.7 | L17: 143.7 | M17: 144.1 | N17: 143.9 | O17: 239.5 | P17: 203.5 | Q17: 108.9 | R17: 449.1 | S17: 10.3 | X17: 166.2 | Y17: 7.5 | Z17: 5.3 | AA17: 0 | AB17: 6.7 | AD17: 142.5 | AI17: 110.3 | AJ17: 222.1 | AN17: 6.5 | AO17: 457.5 | AP17: 76.5 | AQ17: 151.3 | AR17: 42.3 | AS17: 18.4 | AT17: 18.9 | AU17: 89.2 | AY17: 85.5 | AZ17: 0 | BA17: 45.1 | BB17: 4 | BC17: 34 | BD17: 72 | BG17: 0 | BJ17: 0 | BK17: 0 | BN17: 84.4 | BO17: 0 | BP17: 0 | BQ17: 0 | BS17: 38.8 | BT17: 28 | CA17: 2.4 | CB17: 68.5 | CC17: 110.2 | CD17: 66.1 | CE17: 74.8 | CF17: 30.1 | CJ17: 140.9 | CK17: 141.7 | CL17: 146.6 | CM17: 0 | CR17: 208.6 | CS17: 100.5 | CT17: 7 | CU17: 4.3 | CV17: 20 | CW17: 0 | CX17: 37.5 | CY17: 0 | CZ17: 0 | DA17: 0 | DB17: 20.2 | DC17: 10 | DD17: 5.5 | DE17: 0 | DG17: 2 | DH17: 2.1 | DI17: 4.9 | DJ17: 20.3 | DK17: 20 | DL17: 18.8 | DM17: 3.4 | DN17: 18.4 | DO17: 0 | DP17: 0 | DQ17: 9.1 | DR17: 27.8 | DS17: 0 | DT17: 3.4 | DU17: 3.2 | DV17: 2.8 | DW17: 0.4 | DX17: 0 | DY17: 19.8 | DZ17: 7.8 | EA17: 20 | EB17: 20.2 | EC17: 0 | ED17: 11.1 | EE17: 0 | EF17: 19.5 | EG17: 41 | EH17: 1.4 | EI17: 0.8 | EJ17: 0 | EK17: 17.3 | EL17: 6.6 | EM17: 3.9 | EN17: 20.4 | EO17: 20.4 | EP17: 20 | EQ17: 0 | ER17: 0 | ES17: 0 | ET17: 0 | EU17: 0.6 | EV17: 0.2 | EW17: 0.3 | EX17: 0 | EY17: 3.9 | EZ17: 2.3 | FA17: 2.4 | FB17: 0.8 | FC17: 0 | FD17: 7.9 | FE17: 20 | FF17: 20 | FG17: 8.9 | FH17: 27.9 | FI17: 34.8 | FJ17: 15.1 | FK17: 13.5 | FL17: 9 | FM17: 11.6 | FN17: 11.2 | FO17: 6554.7 | FQ17: 24.5 | FR17: 2.562 | FS17: 11.51 | FT17: 13.2 | FU17: 25.20676 | FV17: 18.94911 | FW17: 11.6 | FX17: 14.3 | FY17: 121.82787
A18: 12/02/2026 | B18: 04:00 | C18: 203.6 | D18: 638.6 | E18: 216.4 | H18: 90.6 | I18: 242.1 | K18: 62.1 | L18: 127.3 | M18: 126.7 | N18: 127.9 | O18: 214.2 | P18: 208.1 | Q18: 109 | R18: 488.3 | S18: 10.3 | X18: 166.8 | Y18: 7.6 | Z18: 5.4 | AA18: 0 | AB18: 6.7 | AD18: 143.1 | AI18: 110.5 | AJ18: 175.2 | AN18: 6.5 | AO18: 460.4 | AP18: 75.9 | AQ18: 151 | AR18: 42.2 | AS18: 18.4 | AT18: 18.9 | AU18: 94.4 | AY18: 85.5 | AZ18: 0 | BA18: 44.9 | BB18: 4 | BC18: 34.2 | BD18: 151.8 | BG18: 0 | BJ18: 0 | BK18: 0 | BN18: 84.7 | BO18: 0 | BP18: 0 | BQ18: 0 | BS18: 39.2 | BT18: 28 | CA18: 2.4 | CB18: 69.7 | CC18: 119.4 | CD18: 66.4 | CE18: 74.7 | CF18: 30.2 | CJ18: 113.3 | CK18: 113.4 | CL18: 133 | CM18: 0 | CR18: 208.5 | CS18: 100.4 | CT18: 7 | CU18: 4.4 | CV18: 20 | CW18: 0 | CX18: 38.8 | CY18: 0 | CZ18: 0 | DA18: 0 | DB18: 20.3 | DC18: 9.9 | DD18: 5.3 | DE18: 0 | DG18: 2 | DH18: 2.1 | DI18: 4.9 | DJ18: 20.3 | DK18: 20 | DL18: 18.9 | DM18: 3.4 | DN18: 18.4 | DO18: 0 | DP18: 0 | DQ18: 10.9 | DR18: 25.5 | DS18: 0 | DT18: 3.4 | DU18: 3.2 | DV18: 2.8 | DW18: 0.4 | DX18: 0 | DY18: 19.8 | DZ18: 8.2 | EA18: 20 | EB18: 20.3 | EC18: 0 | ED18: 9.1 | EE18: 0 | EF18: 15.5 | EG18: 25.6 | EH18: 2 | EI18: 1.8 | EJ18: 0 | EK18: 17.9 | EL18: 6.7 | EM18: 3.9 | EN18: 20.4 | EO18: 20.4 | EP18: 20 | EQ18: 0.5 | ER18: 0 | ES18: 0 | ET18: 0 | EU18: 0.6 | EV18: 0.1 | EW18: 0 | EX18: 0 | EY18: 3.9 | EZ18: 2.3 | FA18: 2.4 | FB18: 0.8 | FC18: 0 | FD18: 7.9 | FE18: 20 | FF18: 20 | FG18: 8.9 | FH18: 27.8 | FI18: 34.7 | FJ18: 15.3 | FK18: 13.6 | FL18: 8 | FM18: 11.6 | FN18: 11.4 | FO18: 6495.2 | FQ18: 24.5 | FR18: 2.56 | FS18: 11.51 | FT18: 13.2 | FU18: 25.15103 | FV18: 18.94901 | FW18: 11.5 | FX18: 14.3 | FY18: 121.67004
A19: 12/02/2026 | B19: 04:30 | C19: 199.7 | D19: 629.9 | E19: 214.5 | H19: 89.7 | I19: 241.4 | K19: 59.7 | L19: 133 | M19: 133 | N19: 133.6 | O19: 246.6 | P19: 206.5 | Q19: 108.9 | R19: 549.7 | S19: 10.2 | X19: 165.8 | Y19: 7.3 | Z19: 5.2 | AA19: 0 | AB19: 6.7 | AD19: 141.6 | AI19: 110.3 | AJ19: 222 | AN19: 6.5 | AO19: 460.5 | AP19: 75.5 | AQ19: 150.4 | AR19: 42.3 | AS19: 18.4 | AT19: 18.9 | AU19: 90.8 | AY19: 85.5 | AZ19: 0 | BA19: 44.3 | BB19: 4 | BC19: 32.3 | BD19: 80.2 | BG19: 0 | BJ19: 0 | BK19: 0 | BN19: 83.9 | BO19: 0 | BP19: 0 | BQ19: 0 | BS19: 39.1 | BT19: 27.9 | CA19: 2.4 | CB19: 25 | CC19: 118.8 | CD19: 65.7 | CE19: 74.7 | CF19: 30 | CJ19: 102.8 | CK19: 102.9 | CL19: 122.2 | CM19: 0 | CR19: 208.8 | CS19: 100.4 | CT19: 7 | CU19: 4.4 | CV19: 20 | CW19: 0 | CX19: 31.2 | CY19: 0 | CZ19: 0 | DA19: 0 | DB19: 20.3 | DC19: 10 | DD19: 5.5 | DE19: 0 | DG19: 2 | DH19: 2.1 | DI19: 4.9 | DJ19: 20.2 | DK19: 20 | DL19: 19 | DM19: 3.4 | DN19: 18.4 | DO19: 0 | DP19: 0 | DQ19: 7.4 | DR19: 15.7 | DS19: 0 | DT19: 3.4 | DU19: 3.2 | DV19: 2.7 | DW19: 0.4 | DX19: 0 | DY19: 19.8 | DZ19: 8.4 | EA19: 20 | EB19: 20.2 | EC19: 0.4 | ED19: 8.2 | EE19: 0 | EF19: 12.5 | EG19: 18.3 | EH19: 1 | EI19: 0.3 | EJ19: 0 | EK19: 20.4 | EL19: 7.9 | EM19: 3.9 | EN19: 20.4 | EO19: 20.4 | EP19: 20 | EQ19: 0.5 | ER19: 0 | ES19: 0 | ET19: 0 | EU19: 0.6 | EV19: 0 | EW19: 0 | EX19: 0 | EY19: 3.9 | EZ19: 2.3 | FA19: 2.4 | FB19: 0.8 | FC19: 0 | FD19: 8 | FE19: 20 | FF19: 20 | FG19: 8.8 | FH19: 28.2 | FI19: 35 | FJ19: 15.2 | FK19: 13.5 | FL19: 8.7 | FM19: 11.6 | FN19: 11.2 | FO19: 6443.5 | FQ19: 24.4 | FR19: 2.558 | FS19: 10.76 | FT19: 13.2 | FU19: 25.2259 | FV19: 18.94888 | FW19: 11.6 | FX19: 14.3 | FY19: 120.99278
A20: 12/02/2026 | B20: 05:00 | C20: 202.9 | D20: 632.7 | E20: 215 | H20: 90.1 | I20: 241.3 | K20: 59.8 | L20: 149.1 | M20: 149.3 | N20: 149.2 | O20: 257.4 | P20: 205.2 | Q20: 108.9 | R20: 557.2 | S20: 10.2 | X20: 167.3 | Y20: 7.4 | Z20: 5.3 | AA20: 0 | AB20: 6.7 | AD20: 142.1 | AI20: 110.4 | AJ20: 223 | AN20: 6.5 | AO20: 459.3 | AP20: 76.1 | AQ20: 151.2 | AR20: 42.2 | AS20: 18.4 | AT20: 18.9 | AU20: 91.3 | AY20: 85.5 | AZ20: 0 | BA20: 45.2 | BB20: 4 | BC20: 32.4 | BD20: 94.6 | BG20: 0 | BJ20: 0 | BK20: 0 | BN20: 84.5 | BO20: 0 | BP20: 0 | BQ20: 0 | BS20: 38.8 | BT20: 28.1 | CA20: 2.4 | CB20: 67.2 | CC20: 119.6 | CD20: 66 | CE20: 74.7 | CF20: 30 | CJ20: 120.5 | CK20: 120.5 | CL20: 125.5 | CM20: 0 | CR20: 208.9 | CS20: 100.5 | CT20: 7 | CU20: 4.3 | CV20: 20 | CW20: 0 | CX20: 15.6 | CY20: 0 | CZ20: 0 | DA20: 0 | DB20: 20.2 | DC20: 9.9 | DD20: 5.5 | DE20: 0 | DG20: 2 | DH20: 2.1 | DI20: 4.9 | DJ20: 20.3 | DK20: 20 | DL20: 18.8 | DM20: 3.4 | DN20: 18.4 | DO20: 0 | DP20: 0 | DQ20: 5.1 | DR20: 15.3 | DS20: 0 | DT20: 3.4 | DU20: 3.3 | DV20: 2.7 | DW20: 0.4 | DX20: 0 | DY20: 19.8 | DZ20: 8.3 | EA20: 20 | EB20: 20.2 | EC20: 0.2 | ED20: 3.6 | EE20: 0 | EF20: 8.8 | EG20: 26.5 | EH20: 0.6 | EI20: 0.3 | EJ20: 0 | EK20: 21 | EL20: 8 | EM20: 3.9 | EN20: 20.4 | EO20: 20.4 | EP20: 20 | EQ20: 0 | ER20: 0 | ES20: 0 | ET20: 0 | EU20: 0.6 | EV20: 0 | EW20: 0 | EX20: 0 | EY20: 3.9 | EZ20: 2.3 | FA20: 2.4 | FB20: 0.8 | FC20: 0 | FD20: 8 | FE20: 20.2 | FF20: 20.2 | FG20: 8.5 | FH20: 27.7 | FI20: 34.7 | FJ20: 15.4 | FK20: 13.5 | FL20: 7.8 | FM20: 11.7 | FN20: 11.1 | FO20: 6596.7 | FQ20: 24.5 | FR20: 2.558 | FS20: 11.14 | FT20: 13.2 | FU20: 25.15595 | FV20: 18.9484 | FW20: 11.4 | FX20: 14.4 | FY20: 121.30235
A21: 12/02/2026 | B21: 05:30 | C21: 201.9 | D21: 633.8 | E21: 215.2 | H21: 90.3 | I21: 240.8 | K21: 59.7 | L21: 164.1 | M21: 164.4 | N21: 164.7 | O21: 263.9 | P21: 204.3 | Q21: 108.7 | R21: 558.7 | S21: 10.2 | X21: 164.1 | Y21: 7.4 | Z21: 5.4 | AA21: 0 | AB21: 6.7 | AD21: 142.3 | AI21: 110.4 | AJ21: 221.5 | AN21: 6.5 | AO21: 455.7 | AP21: 76.2 | AQ21: 151.2 | AR21: 42.2 | AS21: 18.4 | AT21: 18.9 | AU21: 88.4 | AY21: 85.5 | AZ21: 0 | BA21: 44.7 | BB21: 4 | BC21: 32.4 | BD21: 100 | BG21: 0 | BJ21: 0 | BK21: 0 | BN21: 84.4 | BO21: 0 | BP21: 0 | BQ21: 0 | BS21: 39 | BT21: 28 | CA21: 2.4 | CB21: 23.9 | CC21: 119.9 | CD21: 66 | CE21: 74.8 | CF21: 30.1 | CJ21: 140.9 | CK21: 141.5 | CL21: 145.8 | CM21: 0 | CR21: 209.2 | CS21: 100.7 | CT21: 7 | CU21: 4.3 | CV21: 20 | CW21: 0 | CX21: 6.1 | CY21: 0 | CZ21: 0 | DA21: 0 | DB21: 20.3 | DC21: 10 | DD21: 5.5 | DE21: 0 | DG21: 2 | DH21: 2.5 | DI21: 4.9 | DJ21: 20.2 | DK21: 20 | DL21: 18.8 | DM21: 3.4 | DN21: 18.4 | DO21: 0 | DP21: 0 | DQ21: 4 | DR21: 9.1 | DS21: 0 | DT21: 3.4 | DU21: 3.2 | DV21: 2.7 | DW21: 0.4 | DX21: 0 | DY21: 19.8 | DZ21: 8.3 | EA21: 20 | EB21: 20.2 | EC21: 0.3 | ED21: 4.8 | EE21: 0 | EF21: 10.3 | EG21: 27 | EH21: 0.4 | EI21: 0 | EJ21: 0 | EK21: 20.9 | EL21: 7.9 | EM21: 4.2 | EN21: 20.4 | EO21: 20.4 | EP21: 20 | EQ21: 0 | ER21: 0 | ES21: 0 | ET21: 0 | EU21: 0.6 | EV21: 0 | EW21: 0 | EX21: 0 | EY21: 3.9 | EZ21: 2.3 | FA21: 2.4 | FB21: 0.8 | FC21: 0 | FD21: 8.1 | FE21: 20 | FF21: 20 | FG21: 9.1 | FH21: 27.8 | FI21: 34.7 | FJ21: 16 | FK21: 13.5 | FL21: 7.3 | FM21: 11.6 | FN21: 11.2 | FO21: 6649.6 | FQ21: 24.5 | FR21: 2.556 | FS21: 10.28 | FT21: 13.2 | FU21: 25.15002 | FV21: 18.94854 | FW21: 11.5 | FX21: 14.4 | FY21: 120.53456
A22: 12/02/2026 | B22: 06:00 | C22: 201.8 | D22: 635.1 | E22: 216.4 | H22: 90.2 | I22: 242.7 | K22: 60.2 | L22: 149.3 | M22: 151.1 | N22: 149.8 | O22: 255.5 | P22: 205.2 | Q22: 108.6 | R22: 551.5 | S22: 10.3 | X22: 166.4 | Y22: 7.5 | Z22: 5.5 | AA22: 0 | AB22: 6.7 | AD22: 141.9 | AI22: 110.3 | AJ22: 213.6 | AN22: 6.5 | AO22: 457.7 | AP22: 75.8 | AQ22: 151.5 | AR22: 42.4 | AS22: 18.4 | AT22: 18.9 | AU22: 88.6 | AY22: 85.5 | AZ22: 0 | BA22: 45.7 | BB22: 4 | BC22: 33.4 | BD22: 111 | BG22: 0 | BJ22: 0 | BK22: 0 | BN22: 84.6 | BO22: 0 | BP22: 0 | BQ22: 0 | BS22: 39 | BT22: 28.1 | CA22: 2.4 | CB22: 21.5 | CC22: 119.8 | CD22: 66.3 | CE22: 74.7 | CF22: 30.3 | CJ22: 141.5 | CK22: 142.2 | CL22: 146.9 | CM22: 0 | CR22: 209.4 | CS22: 100.7 | CT22: 7 | CU22: 4.4 | CV22: 20 | CW22: 0 | CX22: 3.7 | CY22: 0 | CZ22: 0 | DA22: 0 | DB22: 20.3 | DC22: 9.9 | DD22: 5.4 | DE22: 2.9 | DG22: 2 | DH22: 2.5 | DI22: 4.8 | DJ22: 20.5 | DK22: 20 | DL22: 18.8 | DM22: 3.4 | DN22: 18.4 | DO22: 0.5 | DP22: 0.5 | DQ22: 2.3 | DR22: 6.8 | DS22: 0.3 | DT22: 3.4 | DU22: 3.1 | DV22: 2.7 | DW22: 0.4 | DX22: 0 | DY22: 19.8 | DZ22: 8.2 | EA22: 20 | EB22: 20.2 | EC22: 1.3 | ED22: 6.1 | EE22: 0 | EF22: 9 | EG22: 20.5 | EH22: 0.8 | EI22: 0 | EJ22: 0 | EK22: 20.9 | EL22: 7.9 | EM22: 2.9 | EN22: 20.4 | EO22: 20.4 | EP22: 20 | EQ22: 0 | ER22: 2.9 | ES22: 0 | ET22: 2.6 | EU22: 0.6 | EV22: 0 | EW22: 0 | EX22: 2.5 | EY22: 3.9 | EZ22: 2.3 | FA22: 2.4 | FB22: 0.8 | FC22: 0 | FD22: 8 | FE22: 20 | FF22: 20 | FG22: 9.1 | FH22: 27.7 | FI22: 34.7 | FJ22: 16.1 | FK22: 13.5 | FL22: 9.1 | FM22: 11.6 | FN22: 11.2 | FO22: 6607.8 | FQ22: 24.5 | FR22: 2.557 | FS22: 9.55 | FT22: 13.2 | FU22: 25.24646 | FV22: 18.94841 | FW22: 11.5 | FX22: 14.4 | FY22: 119.90187
... A58: 13/02/2026 | B58: 00:00 | C58: 202.3 | D58: 633.7 | E58: 213.9 | H58: 90.2 | I58: 240.9 | K58: 0 | L58: 174.6 | M58: 174.6 | N58: 174.7 | O58: 272.8 | P58: 204.1 | Q58: 108.3 | R58: 553.4 | S58: 10.2 | X58: 165.7 | Y58: 8.1 | Z58: 6.1 | AA58: 0 | AB58: 6.7 | AD58: 142.4 | AI58: 110.1 | AJ58: 223 | AN58: 6.5 | AO58: 457.6 | AP58: 71 | AQ58: 150.9 | AR58: 42.3 | AS58: 18.4 | AT58: 18.9 | AU58: 89.6 | AY58: 104.5 | AZ58: 42.9 | BA58: 45.1 | BB58: 4 | BC58: 27.4 | BD58: 143.9 | BG58: 0 | BJ58: 0 | BK58: 0 | BN58: 127.1 | BO58: 0 | BP58: 0 | BQ58: 0 | BS58: 44.6 | BT58: 28.8 | CA58: 2.4 | CB58: 67.3 | CC58: 112.9 | CD58: 62.5 | CE58: 75.9 | CF58: 29.8 | CJ58: 140 | CK58: 140.7 | CL58: 146.7 | CM58: 0 | CR58: 207.2 | CS58: 99.2 | CT58: 7 | CU58: 4.3 | CV58: 20 | CW58: 0 | CX58: 54.9 | CY58: 0 | CZ58: 0 | DA58: 0 | DB58: 20.1 | DC58: 9.9 | DD58: 5.5 | DE58: 0 | DG58: 0 | DH58: 3.1 | DI58: 4.8 | DJ58: 20 | DK58: 0 | DL58: 18.7 | DM58: 3.4 | DN58: 18.4 | DO58: 0 | DP58: 0 | DQ58: 8.4 | DR58: 17.3 | DS58: 0 | DT58: 3.6 | DU58: 6.1 | DV58: 3 | DW58: 0.4 | DX58: 0 | DY58: 19.5 | DZ58: 7.6 | EA58: 19.4 | EB58: 20.1 | EC58: 1.7 | ED58: 17.9 | EE58: 0 | EF58: 21.3 | EG58: 44.6 | EH58: 1.7 | EI58: 0.4 | EJ58: 0 | EK58: 20.4 | EL58: 7.8 | EM58: 6.3 | EN58: 20.4 | EO58: 20.4 | EP58: 20 | EQ58: 0 | ER58: 0 | ES58: 0 | ET58: 0 | EU58: 0.6 | EV58: 9.4 | EW58: 6 | EX58: 0 | EY58: 4.1 | EZ58: 2.4 | FA58: 2.4 | FB58: 0.8 | FC58: 0 | FD58: 8 | FE58: 20 | FF58: 20 | FG58: 9.1 | FH58: 27.5 | FI58: 34.4 | FJ58: 17.1 | FK58: 17.2 | FL58: 8.7 | FM58: 11.3 | FN58: 20 | FO58: 6921.3 | FQ58: 22.4 | FR58: 6.297 | FS58: 11.72 | FT58: 13.2 | FU58: 24.97974 | FV58: 18.94046 | FW58: 11.2 | FX58: 14.2 | FY58: 122.9372
A59: EJEC | C59: 4845.15 | D59: 15245.95 | E59: 5175.1 | F59: 0 | G59: 0 | H59: 2156.4 | I59: 5792.5 | J59: 0 | K59: 392 | L59: 3568.65 | M59: 3578.1 | N59: 3574.35 | O59: 5940.45 | P59: 4886.45 | Q59: 2591.95 | R59: 13227.9 | S59: 244.75 | T59: 0 | U59: 0 | V59: 0 | W59: 0 | X59: 3979.95 | Y59: 190.5 | Z59: 134.05 | AA59: 190.5 | AB59: 160.7 | AC59: 0 | AD59: 3420.1 | AE59: 0 | AF59: 0 | AG59: 0 | AH59: 0 | AI59: 2645.3 | AJ59: 4995.15 | AK59: 0 | AL59: 0 | AM59: 0 | AN59: 156 | AO59: 10999.6 | AP59: 1553.5 | AQ59: 3622.2 | AR59: 792.85 | AS59: 441.75 | AT59: 453.6 | AU59: 2174.55 | AV59: 0 | AW59: 0 | AX59: 0 | AY59: 2291.85 | AZ59: 613.15 | BA59: 980 | BB59: 96 | BC59: 807.45 | BD59: 3081.5 | BE59: 0 | BF59: 0 | BG59: 689.95 | BH59: 0 | BI59: 0 | BJ59: 702.75 | BK59: 359.6 | BL59: 0 | BM59: 0 | BN59: 2228.15 | BO59: 878.5 | BP59: 1088.4 | BQ59: 2508.45 | BR59: 0 | BS59: 1455.3 | BT59: 776.65 | BU59: 0 | BV59: 0 | BW59: 0 | BX59: 0 | BY59: 0 | BZ59: 0 | CA59: 57.6 | CB59: 2443.7 | CC59: 2784.3 | CD59: 1523.9 | CE59: 1793 | CF59: 722 | CG59: 0 | CH59: 0 | CI59: 0 | CJ59: 3311.15 | CK59: 3322.8 | CL59: 3527.8 | CM59: 1009.05 | CN59: 0 | CO59: 0 | CP59: 0 | CQ59: 0 | CR59: 4512.85 | CS59: 2236.65 | CT59: 168 | CU59: 104.3 | CV59: 480.3 | CW59: 3.4 | CX59: 1170.05 | CY59: 610.5 | CZ59: 43.75 | DA59: 1.5 | DB59: 426.4 | DC59: 238.65 | DD59: 130.45 | DE59: 1304.8 | DF59: 0 | DG59: 31.7 | DH59: 60.5 | DI59: 115.85 | DJ59: 413.75 | DK59: 155.4 | DL59: 446.9 | DM59: 81.6 | DN59: 441.6 | DO59: 124.75 | DP59: 155.45 | DQ59: 222.8 | DR59: 733.9 | DS59: 130.25 | DT59: 80.05 | DU59: 228.45 | DV59: 64.95 | DW59: 9.6 | DX59: 2 | DY59: 467.25 | DZ59: 176.9 | EA59: 479.2 | EB59: 484.65 | EC59: 150.2 | ED59: 512.5 | EE59: 182.7 | EF59: 717.55 | EG59: 1261.1 | EH59: 95.35 | EI59: 57.8 | EJ59: 225.9 | EK59: 486.6 | EL59: 180.95 | EM59: 139.7 | EN59: 489.6 | EO59: 489.6 | EP59: 480 | EQ59: 76.6 | ER59: 1570.7 | ES59: 105.05 | ET59: 1221.95 | EU59: 14.4 | EV59: 533.5 | EW59: 513.15 | EX59: 915.7 | EY59: 93.3 | EZ59: 54.9 | FA59: 57.6 | FB59: 19.2 | FC59: 91.15 | FD59: 191.55 | FE59: 480.95 | FF59: 480.05 | FG59: 195.05 | FH59: 663.8 | FI59: 828.7 | FJ59: 392.25 | FK59: 349.25 | FL59: 201.45 | FM59: 262.4 | FN59: 329.15 | FO59: 177833.45 | FQ59: 476.35 | FR59: 125.591 | FS59: 260.362 | FT59: 316.8 | FU59: 594.54641 | FV59: 454.68333 | FW59: 265.3 | FX59: 343.3 | FY59: 2836.9327

Sheet REACTIVA
B3: jueves, 12 de Febrero del 2026
A5: POTENCIA REACTIVA EJECUTADA DE LAS UNIDADES DE GENERACIÓN DEL COES (MVAR) | FQ5: CENTRALES NO INTEGRANTES COES
A6: FECHA | B6: HORA | C6: 65333 | D6: 101 | E6: 102 | F6: 42667 | G6: 42668 | H6: 126 | I6: 127 | J6: 138 | K6: 139 | L6: 197 | M6: 203 | N6: 204 | O6: 230 | P6: 209 | Q6: 56677 | R6: 796 | S6: 2146 | T6: 142 | U6: 143 | V6: 125 | W6: 187 | X6: 163 | Y6: 298 | Z6: 299 | AA6: 219 | AB6: 151 | AC6: 152 | AD6: 153 | AE6: 154 | AF6: 756 | AG6: 156 | AH6: 155 | AI6: 182 | AJ6: 212 | AK6: 758 | AL6: 263 | AM6: 265 | AN6: 775 | AO6: 777 | AP6: 2154 | AQ6: 150 | AR6: 149 | AS6: 188 | AT6: 2131 | AU6: 755 | AV6: 252 | AW6: 249 | AX6: 250 | AY6: 117 | AZ6: 119 | BA6: 120 | BB6: 189 | BC6: 122 | BD6: 266 | BE6: 337 | BF6: 338 | BG6: 251 | BH6: 115 | BI6: 239 | BJ6: 288 | BK6: 240 | BL6: 241 | BM6: 242 | BN6: 191 | BO6: 194 | BP6: 196 | BQ6: 207 | BR6: 236 | BS6: 795 | BT6: 285 | BU6: 995 | BV6: 996 | BW6: 997 | BX6: 766 | BY6: 926 | BZ6: 924 | CA6: 121 | CB6: 103 | CC6: 104 | CD6: 106 | CE6: 105 | CF6: 107 | CG6: 110 | CH6: 109 | CI6: 144 | CJ6: 113 | CK6: 114 | CL6: 193 | CM6: 208 | CN6: 786 | CO6: 787 | CP6: 788 | CQ6: 789 | CR6: 248 | CS6: 2159 | CT6: 267 | CU6: 268 | CV6: 2194 | CW6: 303 | CX6: 59715 | CY6: 62255 | CZ6: 1263 | DA6: 61800 | DB6: 69125 | DC6: 216 | DD6: 198 | DE6: 70400 | DF6: 76068 | DG6: 49607 | DH6: 214 | DI6: 260 | DJ6: 2152 | DK6: 2128 | DL6: 247 | DM6: 228 | DN6: 2135 | DO6: 261 | DP6: 237 | DQ6: 253 | DR6: 770 | DS6: 235 | DT6: 238 | DU6: 2184 | DV6: 61855 | DW6: 223 | DX6: 75566 | DY6: 226 | DZ6: 201 | EA6: 258 | EB6: 259 | EC6: 257 | ED6: 256 | EE6: 2148 | EF6: 58288 | EG6: 58289 | EH6: 58839 | EI6: 58840 | EJ6: 75260 | EK6: 296 | EL6: 297 | EM6: 211 | EN6: 2175 | EO6: 2178 | EP6: 2181 | EQ6: 1262 | ER6: 63425 | ES6: 233 | ET6: 2150 | EU6: 2165 | EV6: 2161 | EW6: 61197 | EX6: 58851 | EY6: 225 | EZ6: 2201 | FA6: 2171 | FB6: 760 | FC6: 234 | FD6: 215 | FE6: 917 | FF6: 920 | FG6: 289 | FH6: 58333 | FI6: 58336 | FJ6: 213 | FK6: 232 | FL6: 2190 | FM6: 69867 | FN6: 75066 | FO6: TOTAL COES | FQ6: 221 | FR6: 222 | FS6: 224 | FT6: 2187 | FU6: 227 | FV6: 49400 | FW6: 199 | FX6: 200 | FY6: TOTAL NO COES
C7: SUR | D7: CENTRO | E7: CENTRO | F7: NORTE | G7: NORTE | H7: NORTE | I7: NORTE | J7: CENTRO | K7: CENTRO | L7: CENTRO | M7: CENTRO | N7: CENTRO | O7: CENTRO | P7: CENTRO | Q7: CENTRO | R7: CENTRO | S7: CENTRO | T7: CENTRO | U7: CENTRO | V7: CENTRO | W7: CENTRO | X7: SUR | Y7: SUR | Z7: SUR | AA7: CENTRO | AB7: SUR | AC7: SUR | AD7: SUR | AE7: SUR | AF7: SUR | AG7: SUR | AH7: SUR | AI7: SUR | AJ7: CENTRO | AK7: NORTE | AL7: NORTE | AM7: NORTE | AN7: CENTRO | AO7: CENTRO | AP7: CENTRO | AQ7: CENTRO | AR7: CENTRO | AS7: CENTRO | AT7: CENTRO | AU7: SUR | AV7: CENTRO | AW7: CENTRO | AX7: CENTRO | AY7: CENTRO | AZ7: CENTRO | BA7: CENTRO | BB7: SUR | BC7: NORTE | BD7: CENTRO | BE7: CENTRO | BF7: CENTRO | BG7: CENTRO | BH7: NORTE | BI7: NORTE | BJ7: NORTE | BK7: SUR | BL7: SUR | BM7: SUR | BN7: CENTRO | BO7: CENTRO | BP7: CENTRO | BQ7: CENTRO | BR7: CENTRO | BS7: CENTRO | BT7: CENTRO | BU7: SUR | BV7: SUR | BW7: SUR | BX7: NORTE | BY7: SUR | BZ7: CENTRO | CA7: NORTE | CB7: CENTRO | CC7: CENTRO | CD7: CENTRO | CE7: CENTRO | CF7: CENTRO | CG7: CENTRO | CH7: CENTRO | CI7: CENTRO | CJ7: CENTRO | CK7: CENTRO | CL7: CENTRO | CM7: CENTRO | CN7: SUR | CO7: SUR | CP7: SUR | CQ7: SUR | CR7: CENTRO | CS7: CENTRO | CT7: CENTRO | CU7: CENTRO | CV7: NORTE | CW7: CENTRO | CX7: CENTRO | CY7: SUR | CZ7: NORTE | DA7: NORTE | DB7: CENTRO | DC7: NORTE | DD7: NORTE | DE7: SUR | DG7: SUR | DH7: CENTRO | DI7: CENTRO | DJ7: CENTRO | DK7: NORTE | DL7: NORTE | DM7: CENTRO | DN7: CENTRO | DO7: SUR | DP7: SUR | DQ7: CENTRO | DR7: CENTRO | DS7: SUR | DT7: CENTRO | DU7: CENTRO | DV7: NORTE | DW7: CENTRO | DX7: CENTRO | DY7: CENTRO | DZ7: NORTE | EA7: CENTRO | EB7: CENTRO | EC7: NORTE | ED7: NORTE | EE7: SUR | EF7: CENTRO | EG7: CENTRO | EH7: CENTRO | EI7: CENTRO | EJ7: SUR | EK7: CENTRO | EL7: CENTRO | EM7: SUR | EN7: SUR | EO7: SUR | EP7: SUR | EQ7: NORTE | ER7: SUR | ES7: SUR | ET7: SUR | EU7: CENTRO | EV7: CENTRO | EW7: CENTRO | EX7: SUR | EY7: CENTRO | EZ7: CENTRO | FA7: CENTRO | FB7: CENTRO | FC7: SUR | FD7: NORTE | FE7: CENTRO | FF7: CENTRO | FG7: NORTE | FH7: NORTE | FI7: NORTE | FJ7: CENTRO | FK7: NORTE | FL7: NORTE | FM7: NORTE | FN7: NORTE | FQ7: NORTE | FR7: CENTRO | FS7: NORTE | FT7: NORTE | FU7: NORTE | FV7: NORTE | FW7: NORTE | FX7: NORTE
C8: HIDROELÉCTRICA | D8: HIDROELÉCTRICA | E8: HIDROELÉCTRICA | F8: TERMOELÉCTRICA | G8: TERMOELÉCTRICA | H8: HIDROELÉCTRICA | I8: HIDROELÉCTRICA | J8: TERMOELÉCTRICA | K8: TERMOELÉCTRICA | L8: TERMOELÉCTRICA | M8: TERMOELÉCTRICA | N8: TERMOELÉCTRICA | O8: TERMOELÉCTRICA | P8: TERMOELÉCTRICA | Q8: TERMOELÉCTRICA | R8: HIDROELÉCTRICA | S8: HIDROELÉCTRICA | T8: TERMOELÉCTRICA | U8: TERMOELÉCTRICA | V8: TERMOELÉCTRICA | W8: TERMOELÉCTRICA | X8: HIDROELÉCTRICA | Y8: HIDROELÉCTRICA | Z8: HIDROELÉCTRICA | AA8: TERMOELÉCTRICA | AB8: HIDROELÉCTRICA | AC8: HIDROELÉCTRICA | AD8: HIDROELÉCTRICA | AE8: HIDROELÉCTRICA | AF8: TERMOELÉCTRICA | AG8: TERMOELÉCTRICA | AH8: TERMOELÉCTRICA | AI8: HIDROELÉCTRICA | AJ8: HIDROELÉCTRICA | AK8: TERMOELÉCTRICA | AL8: TERMOELÉCTRICA | AM8: TERMOELÉCTRICA | AN8: HIDROELÉCTRICA | AO8: HIDROELÉCTRICA | AP8: HIDROELÉCTRICA | AQ8: HIDROELÉCTRICA | AR8: HIDROELÉCTRICA | AS8: HIDROELÉCTRICA | AT8: HIDROELÉCTRICA | AU8: HIDROELÉCTRICA | AV8: TERMOELÉCTRICA | AW8: TERMOELÉCTRICA | AX8: TERMOELÉCTRICA | AY8: HIDROELÉCTRICA | AZ8: HIDROELÉCTRICA | BA8: HIDROELÉCTRICA | BB8: HIDROELÉCTRICA | BC8: HIDROELÉCTRICA | BD8: HIDROELÉCTRICA | BE8: HIDROELÉCTRICA | BF8: HIDROELÉCTRICA | BG8: HIDROELÉCTRICA | BH8: TERMOELÉCTRICA | BI8: TERMOELÉCTRICA | BJ8: TERMOELÉCTRICA | BK8: TERMOELÉCTRICA | BL8: TERMOELÉCTRICA | BM8: TERMOELÉCTRICA | BN8: HIDROELÉCTRICA | BO8: TERMOELÉCTRICA | BP8: TERMOELÉCTRICA | BQ8: TERMOELÉCTRICA | BR8: TERMOELÉCTRICA | BS8: TERMOELÉCTRICA | BT8: TERMOELÉCTRICA | BU8: TERMOELÉCTRICA | BV8: TERMOELÉCTRICA | BW8: TERMOELÉCTRICA | BX8: HIDROELÉCTRICA | BY8: TERMOELÉCTRICA | BZ8: TERMOELÉCTRICA | CA8: HIDROELÉCTRICA | CB8: HIDROELÉCTRICA | CC8: HIDROELÉCTRICA | CD8: HIDROELÉCTRICA | CE8: HIDROELÉCTRICA | CF8: HIDROELÉCTRICA | CG8: TERMOELÉCTRICA | CH8: TERMOELÉCTRICA | CI8: TERMOELÉCTRICA | CJ8: TERMOELÉCTRICA | CK8: TERMOELÉCTRICA | CL8: TERMOELÉCTRICA | CM8: TERMOELÉCTRICA | CN8: TERMOELÉCTRICA | CO8: TERMOELÉCTRICA | CP8: TERMOELÉCTRICA | CQ8: TERMOELÉCTRICA | CR8: TERMOELÉCTRICA | CS8: TERMOELÉCTRICA | CT8: HIDROELÉCTRICA | CU8: HIDROELÉCTRICA | CV8: HIDROELÉCTRICA | CW8: SOLAR | CX8: EÓLICA | CY8: SOLAR | CZ8: EÓLICA | DA8: SOLAR | DB8: HIDROELÉCTRICA | DC8: HIDROELÉCTRICA | DD8: HIDROELÉCTRICA | DE8: SOLAR | DF8: SOLAR | DG8: HIDROELÉCTRICA | DH8: HIDROELÉCTRICA | DI8: HIDROELÉCTRICA | DJ8: HIDROELÉCTRICA | DK8: HIDROELÉCTRICA | DL8: HIDROELÉCTRICA | DM8: HIDROELÉCTRICA | DN8: HIDROELÉCTRICA | DO8: SOLAR | DP8: SOLAR | DQ8: EÓLICA | DR8: EÓLICA | DS8: SOLAR | DT8: HIDROELÉCTRICA | DU8: HIDROELÉCTRICA | DV8: HIDROELÉCTRICA | DW8: HIDROELÉCTRICA | DX8: SOLAR | DY8: HIDROELÉCTRICA | DZ8: HIDROELÉCTRICA | EA8: HIDROELÉCTRICA | EB8: HIDROELÉCTRICA | EC8: EÓLICA | ED8: EÓLICA | EE8: SOLAR | EF8: EÓLICA | EG8: EÓLICA | EH8: EÓLICA | EI8: EÓLICA | EJ8: SOLAR | EK8: HIDROELÉCTRICA | EL8: HIDROELÉCTRICA | EM8: HIDROELÉCTRICA | EN8: HIDROELÉCTRICA | EO8: HIDROELÉCTRICA | EP8: HIDROELÉCTRICA | EQ8: EÓLICA | ER8: SOLAR | ES8: SOLAR | ET8: SOLAR | EU8: HIDROELÉCTRICA | EV8: EÓLICA | EW8: EÓLICA | EX8: SOLAR | EY8: TERMOELÉCTRICA | EZ8: TERMOELÉCTRICA | FA8: TERMOELÉCTRICA | FB8: TERMOELÉCTRICA | FC8: SOLAR | FD8: HIDROELÉCTRICA | FE8: HIDROELÉCTRICA | FF8: HIDROELÉCTRICA | FG8: TERMOELÉCTRICA | FH8: TERMOELÉCTRICA | FI8: TERMOELÉCTRICA | FJ8: TERMOELÉCTRICA | FK8: TERMOELÉCTRICA | FL8: TERMOELÉCTRICA | FM8: TERMOELÉCTRICA | FN8: TERMOELÉCTRICA | FQ8: HIDROELÉCTRICA | FR8: HIDROELÉCTRICA | FS8: HIDROELÉCTRICA | FT8: HIDROELÉCTRICA | FU8: TERMOELÉCTRICA | FV8: TERMOELÉCTRICA | FW8: HIDROELÉCTRICA | FX8: HIDROELÉCTRICA
