Workbook

Sheet EVENTOS
B3: martes, 16 de Diciembre del 2025
B5: INFORMACIÓN DE EVENTOS PRINCIPALES EN SUS INSTALACIONES
B6: TIPO DE EVENTO | C6: EMPRESA | D6: UBICACIÓN | E6: TIPO DE EQUIPO | F6: EQUIPO | G6: INICIO | H6: FINAL | I6: DESCRIPCIÓN | J6: MW INDISP. | K6: INTERRUPCIÓN (SI/NO) | L6: TENSIÓN DE FALLA (kV)
B7: FALLA | C7: CASA GRANDE S.A.A. | D7: CASA GRANDE | E7: GENERADOR TERMOELÉCTRICO | F7: TV3 | G7: 16/12/2025 21:07:00 | H7: 16/12/2025 21:07:00 | I7: DESCONEXIÓN DEL GENERADOR TV3 DE LA C.T. CASAGRANDE | K7: NO | L7: 13.8
B8: EVENTO | C8: CONELSUR LT SAC | D8: PORTILLO | E8: SUBESTACION | F8: SS.EE. | G8: 16/12/2025 09:43:00 | H8: 17/12/2025 00:00:00 | I8: DECLARACIÓN DE SITUACIÓN EXCEPCIONAL EN LA S.E. PORTILLO 60 kV | K8: NO
B9: EVENTO | C9: ELECTRO ORIENTE | D9: BELAUNDE TERRY - TARAPOTO | E9: LINEA DE TRANSMISION | F9: L-1018 | G9: 16/12/2025 09:43:00 | H9: 16/12/2025 12:19:00 | I9: DECLARACIÓN DE SITUACIÓN EXCEPCIONAL EN LA LÍNEA L-1018 (BELAUNDE TERRY - TARAPOTO) DE 138 kV | K9: NO
B10: EVENTO | C10: ELECTRO ORIENTE | D10: BELAUNDE TERRY - TARAPOTO | E10: LINEA DE TRANSMISION | F10: L-1018 | G10: 16/12/2025 18:17:00 | H10: 16/12/2025 20:59:00 | I10: DECLARACIÓN DE SITUACIÓN EXCEPCIONAL EN LA LÍNEA L-1018 (BELAUNDE TERRY - TARAPOTO) DE 138 kV | K10: NO
B11: FALLA | C11: ELECTRO ORIENTE | D11: TOCACHE - JUANJUI | E11: LINEA DE TRANSMISION | F11: L-1016 | G11: 16/12/2025 16:02:26 | H11: 16/12/2025 16:12:18 | I11: DESCONEXIÓN DE LA LÍNEA L-1016 (TOCACHE - JUANJUI) DE 138 KV | J11: 15.12 | K11: SI | L11: 138
B12: FALLA | C12: VARI ENERGIA S.A.C. | D12: CAMPAS - SANTA ANA | E12: LINEA DE TRANSMISION | F12: L-1184 | G12: 16/12/2025 08:16:38 | H12: 16/12/2025 08:33:14 | I12: DESCONEXIÓN DE LA LÍNEA L-1184 (CAMPAS - SANTA ANA) DE 138 KV | J12: 1.36 | K12: SI | L12: 138

Sheet RESTRIC_OPE
B3: martes, 16 de Diciembre del 2025
B5: RESTRICCIONES OPERATIVAS
B6: FECHA | C6: HORA INICIO | D6: HORA FINAL | E6: EMPRESA | F6: UBICACIÓN | G6: T.Eq. | H6: EQUIPO | I6: DESCRIPCIÓN
B7: 16/12/2025 | C7: 00:00 | D7: 24:00 | E7: CELEPSA | F7: C.H. EL PLATANAL | G7: CH | H7: CENTRAL | I7: De acuerdo con el correo del 13/10/2025. Debido a problemas en el control de la compuerta de bocatoma, informaron que el servicio de RSF queda indisponible.
B8: 16/12/2025 | C8: 00:00 | D8: 24:00 | E8: EGASA | F8: S.E. CONVERTIDOR | G8: BARRA | H8: BARRA138KV | I8: EGASA limitó la capacidad del transformador 138 kV/33 kV a 50 MVA por deterioro del aislamiento.
B9: 16/12/2025 | C9: 00:00 | D9: 24:00 | E9: ELECTROPERU | F9: C.H. MANTARO | G9: CH | H9: CENTRAL | I9: De acuerdo con el correo del día 25.08.2025, la central tiene una limitación de potencia máxima de 650 MW por seguridad de la central.
B10: 16/12/2025 | C10: 00:00 | D10: 24:00 | E10: ENEL GENERACION PIURA S.A. | F10: C.T. MALACAS | G10: CT | H10: CENTRAL | I10: De acuerdo con la comunicación vía correo del día 24.10.2024. ENEL GENERACIÓN PIURA informa una restricción de potencia para alcanzar 105 MW en simultaneo (TG6+TGN4).
B11: 16/12/2025 | C11: 00:00 | D11: 24:00 | E11: ENEL GENERACION PIURA S.A. | F11: C.T. MALACAS | G11: GT | H11: TG4 | I11: De acuerdo a lo informado mediante correo electrónico el día 25.10, con la disponibilidad actual de aproximadamente 13 MMPCD (368.12 Mm³) la unidad TG4 puede con una generación de 80 MW durante 5 horas, y a potencia mínima durante el resto de los periodos
B12: 16/12/2025 | C12: 00:00 | D12: 24:00 | E12: ENGIE ENERGIA PERU S.A.A. | F12: C.H. YUNCÁN | G12: GH | H12: G3 | I12: Según la carta N° ENG/ 198-2024 enviada por su representada, se opera de forma continua el G3 de la CH Yuncán, debido a la ejecución de mantenimientos necesarios para evitar daños en los sellos de seguridad de la válvula esférica del grupo.
B13: 16/12/2025 | C13: 00:00 | D13: 24:00 | E13: ENGIE ENERGIA PERU S.A.A. | F13: C.T. CHILCA 1 | G13: CT | H13: CENTRAL | I13: Con carta ENG/971-2023, indica que no puede cumplir con las IO considerada en el PDO_17122023 dado que vulneran la seguridad de sus activos. Indican que se debe tomar TMO=168h.
B14: 16/12/2025 | C14: 00:00 | D14: 24:00 | E14: ENGIE ENERGIA PERU S.A.A. | F14: C.T. CHILCA 1 | G14: CT | H14: CENTRAL | I14: Restricción de temperatura de la C.T Chilca, ver valor en el modelo de despacho.
B15: 16/12/2025 | C15: 00:00 | D15: 24:00 | E15: ENGIE ENERGIA PERU S.A.A. | F15: C.T. CHILCA 2 | G15: CT | H15: CENTRAL | I15: Con carta ENG/971-2023, indica que no puede cumplir con las IO considerada en el PDO_17122023 dado que vulneran la seguridad de sus activos. Indican que se debe tomar TMO=168h.
B16: 16/12/2025 | C16: 00:00 | D16: 24:00 | E16: FENIX POWER PERÚ | F16: C.T. FENIX | G16: CT | H16: CENTRAL | I16: De acuerdo con lo comunicado en el correo del día 06.05.2025, la CT Fenix cuenta con TMO de 168 hrs en todos sus modos de operación.
B17: 16/12/2025 | C17: 00:00 | D17: 24:00 | E17: KALLPA GENERACION S.A. | F17: C.H. CERRO DEL AGUILA | G17: GH | H17: G1 | I17: De acuerdo a lo informado el día 17/11 por la empresa KALLPA, el G1 tiene un TA = 15min
... B52: 16/12/2025 | C52: 00:00 | D52: 24:00 | E52: TERMOSELVA | F52: C.T. AGUAYTÍA | G52: CT | H52: CENTRAL | I52: Disponibilidad de 23.5 MMSCF para la CT Aguaytía.

Sheet MANTENIMIENTO EJECUTADOS
B3: martes, 16 de Diciembre del 2025
B5: Mantenimiento Ejecutado
B6: Empresa | C6: Ubicación | D6: Equipo | E6: Inicio | F6: Final | G6: Descripción | H6: MW Indisp. | I6: Prog. | J6: Dispon | K6: Interrupc. | L6: Tipo | M6: CodEq | N6: TipoEq_Osinerg
B7: ATLANTICA TRANSMISION SUR S.A. | C7: CHILCA CTM - POROMA | D7: L-5032 | E7: 16/12/2025 00:00 | F7: 16/12/2025 05:55 | G7: Inspeccion por efluvios | H7: 0 | I7: P | J7: E/S | K7: N | L7: PREV. | M7: 13652 | N7: T
B8: ATLANTICA TRANSMISION SUR S.A. | C8: CHILCA CTM - POROMA | D8: L-5032 | E8: 16/12/2025 23:17 | F8: 17/12/2025 00:00 | G8: Inspeccion por efluvios | H8: 0 | I8: P | J8: E/S | K8: N | L8: PREV. | M8: 13652 | N8: T
B9: ATLANTICA TRANSMISION SUR S.A. | C9: MONTALVO | D9: SE MONTALVO | E9: 16/12/2025 00:00 | F9: 16/12/2025 00:16 | G9: Inspeccion por efluvios. | H9: 0 | I9: P | J9: E/S | K9: N | L9: PREV. | M9: 13742 | N9: T
B10: ATLANTICA TRANSMISION SUR S.A. | C10: OCONA | D10: INT-5450 | E10: 16/12/2025 00:00 | F10: 17/12/2025 00:00 | G10: Interruptor INT-5450 cerrado con restriccion operativa, REB-5450 en servicio y suministrando los SS.AA. de la S.E. Oco?a. | H10: 0 | I10: P | J10: E/S | K10: N | L10: OTROS | M10: 13761 | N10: T
B11: ATLANTICA TRANSMISION SUR S.A. | C11: OCONA | D11: CL-5036 | E11: 16/12/2025 08:48 | F11: 16/12/2025 15:40 | G11: Pruebas funcionales de reles de protecciones | H11: 0 | I11: P | J11: F/S | K11: N | L11: PREV. | M11: 13802 | N11: T
B12: ATLANTICA TRANSMISION SUR S.A. | C12: OCONA - SAN JOSE | D12: L-5036 | E12: 16/12/2025 08:28 | F12: 16/12/2025 16:35 | G12: INDISPONIBLE POR MANTENIMIENTO DE MINERA CERRO VERDE EN LA CL-5036 DE LA SE SAN JOSE | H12: 0 | I12: P | J12: F/S | K12: N | L12: OTROS | M12: 14961 | N12: T
B13: ATLANTICA TRANSMISION SUR S.A. | C13: POROMA | D13: REB-5350 | E13: 16/12/2025 00:00 | F13: 17/12/2025 00:00 | G13: Fuera de servicio po falla en el equipo. | H13: 0 | I13: P | J13: F/S | K13: N | L13: OTROS | M13: 13771 | N13: T
B14: ATLANTICA TRANSMISION SUR S.A. | C14: POROMA - OCONA | D14: L-5034 | E14: 16/12/2025 07:32 | F14: 16/12/2025 16:51 | G14: Mantenimiento de pedestales de las torres de la L-5034 | H14: 0 | I14: P | J14: E/S | K14: N | L14: PREV. | M14: 13743 | N14: T
B15: ATN S.A. | C15: KIMAN AYLLU | D15: AUT-501 | E15: 16/12/2025 00:00 | F15: 17/12/2025 00:00 | G15: Restriccion Operativa en el circuito de control de cambiador de tap s del AUT-501 | H15: 0 | I15: P | J15: E/S | K15: N | L15: OTROS | M15: 13099 | N15: T
B16: ATRIA ENERGIA S.A.C. | C16: PURMACANA | D16: CENTRAL | E16: 16/12/2025 00:00 | F16: 17/12/2025 00:00 | G16: mantenimiento correctivo de valvula principal. | H16: 0 | I16: P | J16: F/S | K16: N | L16: CORR. | M16: 13132 | N16: G
B17: CELARIS ENERGY S.A. | C17: MANTA I | D17: CENTRAL | E17: 16/12/2025 08:00 | F17: 16/12/2025 13:00 | G17: MANTENIMIENTO EVALUACION TERMOGRAFICA GENERAL | H17: 0 | I17: P | J17: E/S | K17: N | L17: PREV. | M17: 20667 | N17: G
B18: CONELSUR LT SAC | C18: CALLAHUANCA (CNS) | D18: S.E. | E18: 16/12/2025 00:00 | F18: 17/12/2025 00:00 | G18: RELE DIFERENCIAL DE BARRAS DE CALLAHUANCA 220KV INOPERATIVO | H18: 0 | I18: P | J18: E/S | K18: N | L18: OTROS | M18: 316 | N18: T
... B130: TRANSMANTARO | C130: YARABAMBA | D130: CL-R-30 | E130: 16/12/2025 00:00 | F130: 17/12/2025 00:00 | G130: CL-R30 CON MANDO SINCRONIZADO ASOCIADO AL INTERRUPTOR IN-5147 INDISPONIBLE. EL SABADO 19.04.25 NO PUDO SER AJUSTADO DEBIDO A FALTA DE EQUIPOS DE PARTE DE LA CONTRATISTA HITACHI. | H130: 0 | I130: P | J130: E/S | K130: N | L130: OTROS | M130: 17424 | N130: T

Sheet INGRESO OC
A3: martes, 16 de Diciembre del 2025
A5: INGRESO A OPERACIÓN COMERCIAL
A6: EMPRESA | B6: TIPO DE EQUIPO | C6: UBICACIÓN | D6: EQUIPO | E6: Fecha y hora de Ingreso a Operación Comercial

Sheet DESPACHO_EJECUTADO
B3: martes, 16 de Diciembre del 2025
A5: POTENCIA ACTIVA EJECUTADA DE LAS UNIDADES DE GENERACIÓN DEL SEIN (MW) | FO5: CENTRALES NO INTEGRANTES COES
A6: FECHA | B6: HORA | C6: 65333 | D6: 101 | E6: 102 | F6: 42667 | G6: 42668 | H6: 126 | I6: 127 | J6: 138 | K6: 139 | L6: 197 | M6: 203 | N6: 204 | O6: 230 | P6: 209 | Q6: 56677 | R6: 796 | S6: 2146 | T6: 142 | U6: 143 | V6: 125 | W6: 187 | X6: 163 | Y6: 298 | Z6: 299 | AA6: 219 | AB6: 151 | AC6: 152 | AD6: 153 | AE6: 154 | AF6: 756 | AG6: 156 | AH6: 155 | AI6: 182 | AJ6: 212 | AK6: 758 | AL6: 263 | AM6: 265 | AN6: 775 | AO6: 777 | AP6: 2154 | AQ6: 150 | AR6: 149 | AS6: 188 | AT6: 2131 | AU6: 755 | AV6: 252 | AW6: 249 | AX6: 250 | AY6: 117 | AZ6: 119 | BA6: 120 | BB6: 189 | BC6: 122 | BD6: 266 | BE6: 337 | BF6: 338 | BG6: 251 | BH6: 115 | BI6: 239 | BJ6: 288 | BK6: 240 | BL6: 241 | BM6: 242 | BN6: 191 | BO6: 194 | BP6: 196 | BQ6: 207 | BR6: 236 | BS6: 795 | BT6: 285 | BU6: 995 | BV6: 996 | BW6: 997 | BX6: 766 | BY6: 926 | BZ6: 924 | CA6: 121 | CB6: 103 | CC6: 104 | CD6: 106 | CE6: 105 | CF6: 107 | CG6: 110 | CH6: 109 | CI6: 144 | CJ6: 113 | CK6: 114 | CL6: 193 | CM6: 208 | CN6: 786 | CO6: 787 | CP6: 788 | CQ6: 789 | CR6: 248 | CS6: 2159 | CT6: 267 | CU6: 268 | CV6: 2194 | CW6: 303 | CX6: 59715 | CY6: 62255 | CZ6: 1263 | DA6: 61800 | DB6: 69125 | DC6: 216 | DD6: 198 | DE6: 70400 | DF6: 49607 | DG6: 214 | DH6: 260 | DI6: 2152 | DJ6: 2128 | DK6: 247 | DL6: 228 | DM6: 2135 | DN6: 261 | DO6: 237 | DP6: 253 | DQ6: 770 | DR6: 235 | DS6: 238 | DT6: 2184 | DU6: 61855 | DV6: 223 | DW6: 226 | DX6: 201 | DY6: 258 | DZ6: 259 | EA6: 920 | EB6: 257 | EC6: 256 | ED6: 2148 | EE6: 58288 | EF6: 58289 | EG6: 58839 | EH6: 58840 | EI6: 75260 | EJ6: 296 | EK6: 297 | EL6: 211 | EM6: 2175 | EN6: 2178 | EO6: 2181 | EP6: 1262 | EQ6: 63425 | ER6: 233 | ES6: 2150 | ET6: 2165 | EU6: 2161 | EV6: 61197 | EW6: 58851 | EX6: 225 | EY6: 2201 | EZ6: 2171 | FA6: 760 | FB6: 234 | FC6: 215 | FD6: 917 | FE6: 289 | FF6: 58333 | FG6: 58336 | FH6: 213 | FI6: 232 | FJ6: 2190 | FK6: 69867 | FL6: 75066 | FM6: TOTAL COES | FO6: 221 | FP6: 222 | FQ6: 224 | FR6: 2187 | FS6: 227 | FT6: 49400 | FU6: 199 | FV6: 200 | FW6: TOTAL NO COES
C7: SUR | D7: CENTRO | E7: CENTRO | F7: NORTE | G7: NORTE | H7: NORTE | I7: NORTE | J7: CENTRO | K7: CENTRO | L7: CENTRO | M7: CENTRO | N7: CENTRO | O7: CENTRO | P7: CENTRO | Q7: CENTRO | R7: CENTRO | S7: CENTRO | T7: CENTRO | U7: CENTRO | V7: CENTRO | W7: CENTRO | X7: SUR | Y7: SUR | Z7: SUR | AA7: CENTRO | AB7: SUR | AC7: SUR | AD7: SUR | AE7: SUR | AF7: SUR | AG7: SUR | AH7: SUR | AI7: SUR | AJ7: CENTRO | AK7: NORTE | AL7: NORTE | AM7: NORTE | AN7: CENTRO | AO7: CENTRO | AP7: CENTRO | AQ7: CENTRO | AR7: CENTRO | AS7: CENTRO | AT7: CENTRO | AU7: SUR | AV7: CENTRO | AW7: CENTRO | AX7: CENTRO | AY7: CENTRO | AZ7: CENTRO | BA7: CENTRO | BB7: SUR | BC7: NORTE | BD7: CENTRO | BE7: CENTRO | BF7: CENTRO | BG7: CENTRO | BH7: NORTE | BI7: NORTE | BJ7: NORTE | BK7: SUR | BL7: SUR | BM7: SUR | BN7: CENTRO | BO7: CENTRO | BP7: CENTRO | BQ7: CENTRO | BR7: CENTRO | BS7: CENTRO | BT7: CENTRO | BU7: SUR | BV7: SUR | BW7: SUR | BX7: NORTE | BY7: SUR | BZ7: CENTRO | CA7: NORTE | CB7: CENTRO | CC7: CENTRO | CD7: CENTRO | CE7: CENTRO | CF7: CENTRO | CG7: CENTRO | CH7: CENTRO | CI7: CENTRO | CJ7: CENTRO | CK7: CENTRO | CL7: CENTRO | CM7: CENTRO | CN7: SUR | CO7: SUR | CP7: SUR | CQ7: SUR | CR7: CENTRO | CS7: CENTRO | CT7: CENTRO | CU7: CENTRO | CV7: NORTE | CW7: CENTRO | CX7: CENTRO | CY7: SUR | CZ7: NORTE | DA7: NORTE | DB7: CENTRO | DC7: NORTE | DD7: NORTE | DE7: SUR | DF7: SUR | DG7: CENTRO | DH7: CENTRO | DI7: CENTRO | DJ7: NORTE | DK7: NORTE | DL7: CENTRO | DM7: CENTRO | DN7: SUR | DO7: SUR | DP7: CENTRO | DQ7: CENTRO | DR7: SUR | DS7: CENTRO | DT7: CENTRO | DU7: NORTE | DV7: CENTRO | DW7: CENTRO | DX7: NORTE | DY7: CENTRO | DZ7: CENTRO | EA7: CENTRO | EB7: NORTE | EC7: NORTE | ED7: SUR | EE7: CENTRO | EF7: CENTRO | EG7: CENTRO | EH7: CENTRO | EJ7: CENTRO | EK7: CENTRO | EL7: SUR | EM7: SUR | EN7: SUR | EO7: SUR | EP7: NORTE | EQ7: SUR | ER7: SUR | ES7: SUR | ET7: CENTRO | EU7: CENTRO | EV7: CENTRO | EW7: SUR | EX7: CENTRO | EY7: CENTRO | EZ7: CENTRO | FA7: CENTRO | FB7: SUR | FC7: NORTE | FD7: CENTRO | FE7: NORTE | FF7: NORTE | FG7: NORTE | FH7: CENTRO | FI7: NORTE | FJ7: NORTE | FK7: NORTE | FO7: NORTE | FP7: CENTRO | FQ7: NORTE | FR7: NORTE | FS7: NORTE | FT7: NORTE | FU7: NORTE | FV7: NORTE
C8: HIDROELÉCTRICA | D8: HIDROELÉCTRICA | E8: HIDROELÉCTRICA | F8: TERMOELÉCTRICA | G8: TERMOELÉCTRICA | H8: HIDROELÉCTRICA | I8: HIDROELÉCTRICA | J8: TERMOELÉCTRICA | K8: TERMOELÉCTRICA | L8: TERMOELÉCTRICA | M8: TERMOELÉCTRICA | N8: TERMOELÉCTRICA | O8: TERMOELÉCTRICA | P8: TERMOELÉCTRICA | Q8: TERMOELÉCTRICA | R8: HIDROELÉCTRICA | S8: HIDROELÉCTRICA | T8: TERMOELÉCTRICA | U8: TERMOELÉCTRICA | V8: TERMOELÉCTRICA | W8: TERMOELÉCTRICA | X8: HIDROELÉCTRICA | Y8: HIDROELÉCTRICA | Z8: HIDROELÉCTRICA | AA8: TERMOELÉCTRICA | AB8: HIDROELÉCTRICA | AC8: HIDROELÉCTRICA | AD8: HIDROELÉCTRICA | AE8: HIDROELÉCTRICA | AF8: TERMOELÉCTRICA | AG8: TERMOELÉCTRICA | AH8: TERMOELÉCTRICA | AI8: HIDROELÉCTRICA | AJ8: HIDROELÉCTRICA | AK8: TERMOELÉCTRICA | AL8: TERMOELÉCTRICA | AM8: TERMOELÉCTRICA | AN8: HIDROELÉCTRICA | AO8: HIDROELÉCTRICA | AP8: HIDROELÉCTRICA | AQ8: HIDROELÉCTRICA | AR8: HIDROELÉCTRICA | AS8: HIDROELÉCTRICA | AT8: HIDROELÉCTRICA | AU8: HIDROELÉCTRICA | AV8: TERMOELÉCTRICA | AW8: TERMOELÉCTRICA | AX8: TERMOELÉCTRICA | AY8: HIDROELÉCTRICA | AZ8: HIDROELÉCTRICA | BA8: HIDROELÉCTRICA | BB8: HIDROELÉCTRICA | BC8: HIDROELÉCTRICA | BD8: HIDROELÉCTRICA | BE8: HIDROELÉCTRICA | BF8: HIDROELÉCTRICA | BG8: HIDROELÉCTRICA | BH8: TERMOELÉCTRICA | BI8: TERMOELÉCTRICA | BJ8: TERMOELÉCTRICA | BK8: TERMOELÉCTRICA | BL8: TERMOELÉCTRICA | BM8: TERMOELÉCTRICA | BN8: HIDROELÉCTRICA | BO8: TERMOELÉCTRICA | BP8: TERMOELÉCTRICA | BQ8: TERMOELÉCTRICA | BR8: TERMOELÉCTRICA | BS8: TERMOELÉCTRICA | BT8: TERMOELÉCTRICA | BU8: TERMOELÉCTRICA | BV8: TERMOELÉCTRICA | BW8: TERMOELÉCTRICA | BX8: HIDROELÉCTRICA | BY8: TERMOELÉCTRICA | BZ8: TERMOELÉCTRICA | CA8: HIDROELÉCTRICA | CB8: HIDROELÉCTRICA | CC8: HIDROELÉCTRICA | CD8: HIDROELÉCTRICA | CE8: HIDROELÉCTRICA | CF8: HIDROELÉCTRICA | CG8: TERMOELÉCTRICA | CH8: TERMOELÉCTRICA | CI8: TERMOELÉCTRICA | CJ8: TERMOELÉCTRICA | CK8: TERMOELÉCTRICA | CL8: TERMOELÉCTRICA | CM8: TERMOELÉCTRICA | CN8: TERMOELÉCTRICA | CO8: TERMOELÉCTRICA | CP8: TERMOELÉCTRICA | CQ8: TERMOELÉCTRICA | CR8: TERMOELÉCTRICA | CS8: TERMOELÉCTRICA | CT8: HIDROELÉCTRICA | CU8: HIDROELÉCTRICA | CV8: HIDROELÉCTRICA | CW8: SOLAR | CX8: EÓLICA | CY8: SOLAR | CZ8: EÓLICA | DA8: SOLAR | DB8: HIDROELÉCTRICA | DC8: HIDROELÉCTRICA | DD8: HIDROELÉCTRICA | DE8: SOLAR | DF8: HIDROELÉCTRICA | DG8: HIDROELÉCTRICA | DH8: HIDROELÉCTRICA | DI8: HIDROELÉCTRICA | DJ8: HIDROELÉCTRICA | DK8: HIDROELÉCTRICA | DL8: HIDROELÉCTRICA | DM8: HIDROELÉCTRICA | DN8: SOLAR | DO8: SOLAR | DP8: EÓLICA | DQ8: EÓLICA | DR8: SOLAR | DS8: HIDROELÉCTRICA | DT8: HIDROELÉCTRICA | DU8: HIDROELÉCTRICA | DV8: HIDROELÉCTRICA | DW8: HIDROELÉCTRICA | DX8: HIDROELÉCTRICA | DY8: HIDROELÉCTRICA | DZ8: HIDROELÉCTRICA | EA8: HIDROELÉCTRICA | EB8: EÓLICA | EC8: EÓLICA | ED8: SOLAR | EE8: EÓLICA | EF8: EÓLICA | EG8: EÓLICA | EH8: EÓLICA | EI8: SOLAR | EJ8: HIDROELÉCTRICA | EK8: HIDROELÉCTRICA | EL8: HIDROELÉCTRICA | EM8: HIDROELÉCTRICA | EN8: HIDROELÉCTRICA | EO8: HIDROELÉCTRICA | EP8: EÓLICA | EQ8: SOLAR | ER8: SOLAR | ES8: SOLAR | ET8: HIDROELÉCTRICA | EU8: EÓLICA | EV8: EÓLICA | EW8: SOLAR | EX8: TERMOELÉCTRICA | EY8: TERMOELÉCTRICA | EZ8: TERMOELÉCTRICA | FA8: TERMOELÉCTRICA | FB8: SOLAR | FC8: HIDROELÉCTRICA | FD8: HIDROELÉCTRICA | FE8: TERMOELÉCTRICA | FF8: TERMOELÉCTRICA | FG8: TERMOELÉCTRICA | FH8: TERMOELÉCTRICA | FI8: TERMOELÉCTRICA | FJ8: TERMOELÉCTRICA | FK8: TERMOELÉCTRICA | FL8: TERMOELÉCTRICA | FO8: HIDROELÉCTRICA | FP8: HIDROELÉCTRICA | FQ8: HIDROELÉCTRICA | FR8: HIDROELÉCTRICA | FS8: TERMOELÉCTRICA | FT8: TERMOELÉCTRICA | FU8: HIDROELÉCTRICA | FV8: HIDROELÉCTRICA
C9: HYDRO GLOBAL PERÚ S.A.C. | D9: ELECTROPERU | E9: ELECTROPERU | F9: ELECTROPERU | G9: ELECTROPERU | H9: ORAZUL ENERGY PERÚ | I9: ORAZUL ENERGY PERÚ | J9: TERMOSELVA | K9: TERMOSELVA | L9: KALLPA GENERACION S.A. | M9: KALLPA GENERACION S.A. | N9: KALLPA GENERACION S.A. | O9: KALLPA GENERACION S.A. | P9: KALLPA GENERACION S.A. | Q9: KALLPA GENERACION S.A. | R9: KALLPA GENERACION S.A. | S9: KALLPA GENERACION S.A. | T9: SHOUGESA | U9: SHOUGESA | V9: SHOUGESA | W9: SHOUGESA | X9: EGEMSA | Y9: EGESUR | Z9: EGESUR | AA9: EGESUR | AB9: EGASA | AC9: EGASA | AD9: EGASA | AE9: EGASA | AF9: EGASA | AG9: EGASA | AH9: EGASA | AI9: SAN GABAN | AJ9: CELEPSA | AK9: MINERA CERRO VERDE | AL9: PLANTA DE RESERVA FRIA DE GENERACION DE ETEN S.A. | AM9: PLANTA DE RESERVA FRIA DE GENERACION DE ETEN S.A. | AN9: EMPRESA DE GENERACION HUALLAGA | AO9: EMPRESA DE GENERACION HUALLAGA | AP9: LA VIRGEN | AQ9: CHINANGO S.A.C. | AR9: CHINANGO S.A.C. | AS9: HIDROELECTRICA HUANCHOR S.A.C. | AT9: CELEPSA RENOVABLES S.R.L. | AU9: INLAND ENERGY SAC | AV9: FENIX POWER PERÚ | AW9: FENIX POWER PERÚ | AX9: FENIX POWER PERÚ | AY9: STATKRAFT S.A | AZ9: STATKRAFT S.A | BA9: STATKRAFT S.A | BB9: STATKRAFT S.A | BC9: STATKRAFT S.A | BD9: STATKRAFT S.A | BE9: CENTRALES SANTA ROSA S.A.C. | BF9: CENTRALES SANTA ROSA S.A.C. | BG9: EMPRESA DE GENERACION HUANZA | BH9: ENEL GENERACION PIURA S.A. | BI9: ENEL GENERACION PIURA S.A. | BJ9: ENEL GENERACION PIURA S.A. | BK9: ENGIE ENERGIA PERU S.A.A. | BL9: ENGIE ENERGIA PERU S.A.A. | BM9: ENGIE ENERGIA PERU S.A.A. | BN9: ENGIE ENERGIA PERU S.A.A. | BO9: ENGIE ENERGIA PERU S.A.A. | BP9: ENGIE ENERGIA PERU S.A.A. | BQ9: ENGIE ENERGIA PERU S.A.A. | BR9: ENGIE ENERGIA PERU S.A.A. | BS9: ENGIE ENERGIA PERU S.A.A. | BT9: ENGIE ENERGIA PERU S.A.A. | BU9: ENGIE ENERGIA PERU S.A.A. | BV9: ENGIE ENERGIA PERU S.A.A. | BW9: ENGIE ENERGIA PERU S.A.A. | BX9: ENGIE ENERGIA PERU S.A.A. | BY9: INFRAESTRUCTURAS Y ENERGIAS DEL PERU S.A.C. | BZ9: INFRAESTRUCTURAS Y ENERGIAS DEL PERU S.A.C. | CA9: INVERSIONES SHAQSHA S.A.C. | CB9: ORYGEN PERU S.A.A. | CC9: ORYGEN PERU S.A.A. | CD9: ORYGEN PERU S.A.A. | CE9: ORYGEN PERU S.A.A. | CF9: ORYGEN PERU S.A.A. | CG9: ORYGEN PERU S.A.A. | CH9: ORYGEN PERU S.A.A. | CI9: ORYGEN PERU S.A.A. | CJ9: ORYGEN PERU S.A.A. | CK9: ORYGEN PERU S.A.A. | CL9: ORYGEN PERU S.A.A. | CM9: ORYGEN PERU S.A.A. | CN9: SAMAY I S.A.C | CO9: SAMAY I S.A.C | CP9: SAMAY I S.A.C | CQ9: SAMAY I S.A.C | CR9: TERMOCHILCA S.A.C. | CS9: TERMOCHILCA S.A.C. | CT9: TRANSMISION ANDINA DE GENERACION S.A.C. | CU9: TRANSMISION ANDINA DE GENERACION S.A.C. | CV9: CELARIS ENERGY S.A. | CW9: COLCA SOLAR S.A.C. | CX9: ENERGIA RENOVABLE DEL SUR S.A. | CY9: GR CORTARRAMA SOCIEDAD ANONIMA CERRADA | CZ9: GR TARUCA SOCIEDAD ANONIMA CERRADA | DA9: KONDU SAC | DB9: VARI ENERGIA S.A.C. | DC9: ORAZUL ENERGY PERÚ | DD9: ORAZUL ENERGY PERÚ | DE9: KALLPA GENERACION S.A. | DF9: SAN GABAN | DG9: MAJA ENERGIA S.A.C. | DH9: EMPRESA DE GENERACION ELECTRICA CANCHAYLLO SAC | DI9: EMPRESA DE GENERACION ELECTRICA SANTA ANA S.A.C. | DJ9: EMPRESA ELECTRICA AGUA AZUL | DK9: EMPRESA ELECTRICA RIO DOBLE | DL9: HIDROCAÑETE S.A. | DM9: HUAURA POWER GROUP S.A. | DN9: MOQUEGUA FV S.A.C. | DO9: PANAMERICANA SOLAR SAC. | DP9: PARQUE EOLICO MARCONA S.A.C. | DQ9: PARQUE EOLICO TRES HERMANAS S.A.C. | DR9: TACNA SOLAR SAC. | DS9: ELECTRICA YANAPAMPA SAC | DT9: ANDEAN POWER S.A.C. | DU9: ASOCIACIÓN SANTA LUCIA DE CHACAS | DV9: ATRIA ENERGIA S.A.C. | DW9: EGEJUNIN | DX9: EGEJUNIN | DY9: EGEJUNIN | DZ9: EGEJUNIN | EA9: EMPRESA DE GENERACION ELECTRICA RIO BAÑOS S.A.C. | EB9: ENERGÍA EÓLICA S.A. | EC9: ENERGÍA EÓLICA S.A. | ED9: ENGIE ENERGIA PERU S.A.A. | EE9: ENGIE ENERGIA PERU S.A.A. | EF9: ENGIE ENERGIA PERU S.A.A. | EG9: ENGIE ENERGIA PERU S.A.A. | EH9: ENGIE ENERGIA PERU S.A.A. | EI9: ENGIE ENERGIA PERU S.A.A. | EJ9: GENERACIÓN ANDINA S.A.C. | EK9: GENERACIÓN ANDINA S.A.C. | EL9: GENERADORA DE ENERGÍA DEL PERÚ | EM9: GENERADORA DE ENERGÍA DEL PERÚ | EN9: GENERADORA DE ENERGÍA DEL PERÚ | EO9: GENERADORA DE ENERGÍA DEL PERÚ | EP9: GR PAINO SOCIEDAD ANONIMA CERRADA | EQ9: JOYA SOLAR S.A.C. | ER9: MAJES ARCUS S.A.C. | ES9: ORYGEN PERU S.A.A. | ET9: ORYGEN PERU S.A.A. | EU9: ORYGEN PERU S.A.A. | EV9: ORYGEN PERU S.A.A. | EW9: ORYGEN PERU S.A.A. | EX9: PETRAMAS | EY9: PETRAMAS | EZ9: PETRAMAS | FA9: PETRAMAS | FB9: REPARTICIÓN ARCUS S.A.C. | FC9: SINERSA | FD9: SINERSA | FE9: BIOENERGIA DEL CHIRA S.A. | FF9: GM OPERACIONES S.A.C. | FG9: GM OPERACIONES S.A.C. | FH9: AGRO INDUSTRIAL PARAMONGA S.A. | FI9: AGROAURORA S.A.C. | FJ9: AGROINDUSTRIAS SAN JACINTO S.A.A. | FK9: AGROLMOS SOCIEDAD ANONIMA - AGROLMOS S.A. | FL9: CASA GRANDE S.A.A. | FO9: UNACEM PERU S.A. | FP9: ELECTRO ORIENTE | FQ9: AGUAS Y ENERGIA PERU | FR9: ELECTRO ZAÑA S.A.C. | FS9: ELECTRONOROESTE S.A. | FT9: SDE PIURA | FU9: SINERSA | FV9: SINERSA
C10: SAN GABAN III | D10: MANTARO | E10: RESTITUCION | F10: TUMBES MAK 1 | G10: TUMBES MAK 2 | H10: CARHUAQUERO | I10: CAÑON DEL PATO | J10: AGUAYTIA TG1 | K10: AGUAYTIA TG2 | L10: KALLPA TG1 | M10: KALLPA TG2 | N10: KALLPA TG3 | O10: KALLPA TV | P10: LFLORES TG1 | Q10: LFLORES TV | R10: CERRO DEL AGUILA | S10: CERRODELAGUILAG4 | T10: SHOUGESA TV1 | U10: SHOUGESA TV2 | V10: SHOUGESA TV3 | W10: SHOUGESA CUMMINS | X10: MACHUPICCHU | Y10: ARICOTA 1 | Z10: ARICOTA 2 | AA10: INDEPENDENCIA | AB10: CHARCANI I,II,III | AC10: CHARCANI IV | AD10: CHARCANI V | AE10: CHARCANI VI | AF10: CHILINA TG | AG10: MOLLENDO 1, 2, 3 | AH10: CHILINA (SULZ 1,2) | AI10: SAN GABAN II | AJ10: PLATANAL | AK10: RECKA | AL10: RF ETEN TG1 | AM10: RF ETEN TG2 | AN10: CHAGLLA GP1 | AO10: CHAGLLA | AP10: LA VIRGEN | AQ10: CHIMAY | AR10: YANANGO | AS10: HUANCHOR | AT10: MARAÑON | AU10: STA TERESA | AV10: FENIX GT11 | AW10: FENIX GT12 | AX10: FENIX TV10 | AY10: YAUPI | AZ10: MALPASO | BA10: CAHUA | BB10: ARCATA | BC10: GALLITO CIEGO | BD10: CHEVES | BE10: SANTA ROSA 1 | BF10: SANTA ROSA 2 | BG10: HUANZA | BH10: MALACAS2 TG4 | BI10: MALACAS3 TG 5 | BJ10: MALACAS1 TG6 | BK10: RF ILO2 TG1 | BL10: RF ILO2 TG2 | BM10: RF ILO2 TG3 | BN10: YUNCAN | BO10: CHILCA1 TG1 | BP10: CHILCA1 TG2 | BQ10: CHILCA1 TG3 | BR10: CHILCA-TV | BS10: CHILCA2 TG41 | BT10: CHILCA2-TV | BU10: CTNEPI_TG41 | BV10: CTNEPI_TG42 | BW10: CTNEPI_TG43 | BX10: QUITARACSA | BY10: RF PTO MALDONADO | BZ10: RF PUCALLPA | CA10: PARIAC | CB10: HUINCO | CC10: MATUCANA | CD10: MOYOPAMPA | CE10: CALLAHUANCA | CF10: HUAMPANI | CG10: STA ROSA WEST TG7 | CH10: UTI_5 | CI10: UTI_6 | CJ10: VENTANILLA 3 | CK10: VENTANILLA 4 | CL10: VENTANILLA TV | CM10: STAROSA TG8 | CN10: PTO_BRVO TG1 | CO10: PTO_BRVO TG2 | CP10: PTO_BRVO TG3 | CQ10: PTO_BRVO TG4 | CR10: OLLEROS TG1 | CS10: OLLEROS TV | CT10: OROYA | CU10: PACHACHACA | CV10: MANTA I | CW10: CS YARUCAYA | CX10: SAN JUAN | CY10: MATARANI | CZ10: DUNA | DA10: CARHUAQUERO (CS) | DB10: ANASHIRONI | DC10: CARHUAQUERO4 | DD10: CAÑA BRAVA | DE10: SUNNY | DF10: TUPURI | DG10: RONCADOR | DH10: CANCHAYLLO | DI10: RENOVANDESH1 | DJ10: POTRERO | DK10: PIZARRAS | DL10: NIMPERIAL | DM10: YARUCAYA | DN10: MOQUEGUA-SOLAR | DO10: PANAMERICANA-SOLAR | DP10: PQE-EOLICO-MARCONA | DQ10: PQE-EOLICO-3-HERMANAS | DR10: TACNA-SOLAR | DS10: YANAPAMPA | DT10: CARHUAC | DU10: HUALLIN | DV10: PURMACANA | DW10: HUASAHUASI | DX10: STACRUZ_1_2 | DY10: RUNATULLO_II | DZ10: RUNATULLO_III | EA10: RUCUY | EB10: PQE-EOLICO-TALARA | EC10: PQE-EOLICO-CUPISNIQUE | ED10: INTIPAMPA | EE10: PUNTA LOMITAS-BL1 | EF10: PUNTA LOMITAS-BL2 | EG10: PUN LOMITAS_EXP-BL1 | EH10: PUN LOMITAS_EXP-BL2 | EI10: EXPANSIÓN INTIPAMPA | EJ10: 8AGOSTO | EK10: EL CARMEN | EL10: LA JOYA | EM10: ANGEL_I | EN10: ANGEL_II | EO10: ANGEL_III | EP10: HUAMBOS | EQ10: SAN MARTIN SOLAR | ER10: MAJES | ES10: RUBI | ET10: CH_HER1 | EU10: WAYRA-I | EV10: WAYRA EXTENSION | EW10: CLEMESI | EX10: HUAYCOLORO | EY10: CALLAO | EZ10: DONA_CATALINA | FA10: LAGRINGAV | FB10: REPARTICION | FC10: POECHOS2 | FD10: CHANCAY | FE10: CANA BRAVA | FF10: REFINERIA TALARA TV1 | FG10: REFINERÍA TALARA TV2 | FH10: PARAMONGA | FI10: MAPLE | FJ10: SAN_JACINTO | FK10: AGROLMOS | FL10: CASA GRANDE | FM10: MW | FO10: CARPAPATA | FP10: CENTRALES ELOR | FQ10: PIAS1 | FR10: ZANA | FS10: TABLAZO | FT10: TALLANCA | FU10: CURUMUY | FV10: POECHOS1 | FW10: MW
A11: 16/12/2025 | B11: 00:30 | C11: 199.2 | D11: 594.2 | E11: 202.8 | H11: 89.5 | I11: 114.2 | J11: 0 | L11: 185.4 | M11: 207.4 | N11: 205.6 | P11: 214 | R11: 280.4 | S11: 9.8 | X11: 163.7 | Y11: 7.1 | AA11: 22.6 | AB11: 6.8 | AC11: 15.1 | AD11: 79.2 | AI11: 110.5 | AJ11: 0 | AN11: 6.5 | AO11: 172.9 | AP11: 35.2 | AQ11: 130.5 | AR11: 18.1 | AS11: 18.4 | AT11: 16.5 | AU11: 56.6 | AV11: 181.2 | AW11: 181.3 | AX11: 183.9 | AY11: 89.5 | AZ11: 0 | BA11: 23.2 | BB11: 4 | BC11: 29.4 | BD11: 39.9 | BG11: 40.6 | BJ11: 25 | BN11: 60.29899 | BO11: 151.40144 | BP11: 151.50788 | BQ11: 151.84209 | BR11: 247.59869 | BS11: 74.83033 | BT11: 36.59705 | CB11: 42.2 | CC11: 85.7 | CD11: 61.6 | CE11: 68.7 | CF11: 30.2 | CG11: 65.7 | CH11: 0 | CI11: 0 | CJ11: 144.7 | CK11: 146.2 | CL11: 148.7 | CR11: 213.7 | CS11: 102.3 | CT11: 5.4 | CU11: 1.7 | CV11: 6.3 | CW11: 0 | CX11: 121.2 | CY11: 0 | CZ11: 0.7 | DA11: 0 | DB11: 3 | DC11: 9.9 | DE11: 0 | DF11: 1 | DG11: 1.4 | DH11: 3.8 | DI11: 20.1 | DJ11: 5.4 | DK11: 13.1 | DL11: 2.9 | DM11: 17.6 | DN11: 0 | DO11: 0 | DP11: 30.1 | DQ11: 90 | DR11: 0 | DS11: 2.3 | DT11: 8.7 | DU11: 2.8 | DW11: 6.3 | DX11: 6.7 | DY11: 9.4 | DZ11: 12.4 | EA11: 10 | EB11: 14.5 | EC11: 13 | ED11: 0 | EE11: 53.27947 | EF11: 82.21183 | EG11: 4.15382 | EH11: 1.25523 | EI11: 0 | EJ11: 12.5 | EK11: 4.5 | EL11: 8.5 | EM11: 20.4 | EN11: 20.4 | EO11: 20 | EP11: 0.9 | EQ11: 0 | ER11: 0 | ES11: 0 | ET11: 0.6 | EU11: 46.5 | EV11: 49.3 | EW11: 0 | EX11: 2.9 | EY11: 2.1 | EZ11: 1.2 | FA11: 1.2 | FB11: 0 | FC11: 4.1 | FD11: 20.2 | FE11: 9.2 | FF11: 27.1 | FG11: 34.2 | FH11: 18 | FI11: 18.6 | FJ11: 7 | FK11: 11.1 | FL11: 22.2 | FM11: 6867.2768 | FO11: 15.88539 | FP11: 0 | FQ11: 11.47 | FR11: 9.3 | FS11: 26.89393 | FT11: 18.92824 | FU11: 0 | FV11: 4.9 | FW11: 87.37756
A12: 16/12/2025 | B12: 01:00 | C12: 201 | D12: 549.2 | E12: 182.7 | H12: 89.6 | I12: 116.7 | J12: 0 | L12: 185.4 | M12: 206.7 | N12: 205.1 | P12: 212.6 | R12: 266 | S12: 9.9 | X12: 165.8 | Y12: 7.5 | AA12: 22.4 | AB12: 6.8 | AC12: 15.1 | AD12: 79.7 | AI12: 110.9 | AJ12: 0 | AN12: 6.5 | AO12: 172.2 | AP12: 36 | AQ12: 60.4 | AR12: 18.2 | AS12: 18.5 | AT12: 16.5 | AU12: 57 | AV12: 181.6 | AW12: 181.8 | AX12: 184.3 | AY12: 91.2 | AZ12: 0 | BA12: 23.5 | BB12: 4 | BC12: 29.8 | BD12: 43.5 | BG12: 40.7 | BJ12: 25 | BN12: 60.56278 | BO12: 156.9958 | BP12: 157.4918 | BQ12: 156.12148 | BR12: 238.65975 | BS12: 74.89801 | BT12: 36.61653 | CB12: 68.7 | CC12: 90.9 | CD12: 61.9 | CE12: 65.6 | CF12: 30.3 | CG12: 65.4 | CH12: 0 | CI12: 0 | CJ12: 144 | CK12: 145.6 | CL12: 148.5 | CR12: 213.6 | CS12: 102.3 | CT12: 5 | CU12: 1.7 | CV12: 6.8 | CW12: 0 | CX12: 124.1 | CY12: 0 | CZ12: 0.3 | DA12: 0 | DB12: 3.2 | DC12: 9.9 | DE12: 0 | DF12: 1 | DG12: 1.5 | DH12: 4 | DI12: 20.5 | DJ12: 5.2 | DK12: 13.1 | DL12: 2.9 | DM12: 17.6 | DN12: 0 | DO12: 0 | DP12: 30 | DQ12: 90.8 | DR12: 0 | DS12: 2.1 | DT12: 8.6 | DU12: 2.7 | DW12: 6.3 | DX12: 6.7 | DY12: 9.8 | DZ12: 12.7 | EA12: 10 | EB12: 18.2 | EC12: 8.5 | ED12: 0 | EE12: 62.95876 | EF12: 93.40423 | EG12: 9.35166 | EH12: 2.24653 | EI12: 0 | EJ12: 12.5 | EK12: 4.5 | EL12: 8.5 | EM12: 20.4 | EN12: 20.4 | EO12: 20 | EP12: 1 | EQ12: 0 | ER12: 0 | ES12: 0 | ET12: 0.6 | EU12: 80.4 | EV12: 90 | EW12: 0 | EX12: 2.9 | EY12: 2.1 | EZ12: 1.2 | FA12: 1.2 | FB12: 0 | FC12: 4.1 | FD12: 20 | FE12: 8.7 | FF12: 27 | FG12: 34.2 | FH12: 17.8 | FI12: 19.4 | FJ12: 6 | FK12: 11.1 | FL12: 21.6 | FM12: 6868.7073 | FO12: 15.92637 | FP12: 0 | FQ12: 11.68 | FR12: 9.3 | FS12: 26.82423 | FT12: 18.92833 | FU12: 0 | FV12: 4.9 | FW12: 87.55893
A13: 16/12/2025 | B13: 01:30 | C13: 201.7 | D13: 535.9 | E13: 182.1 | H13: 69.9 | I13: 115 | J13: 0 | L13: 186.6 | M13: 207.9 | N13: 205.2 | P13: 213.5 | R13: 257.7 | S13: 9.9 | X13: 159.6 | Y13: 6.8 | AA13: 22.5 | AB13: 6.8 | AC13: 15.1 | AD13: 78.6 | AI13: 109.6 | AJ13: 0 | AN13: 6.5 | AO13: 171 | AP13: 37.2 | AQ13: 47.2 | AR13: 18.5 | AS13: 18.6 | AT13: 16.5 | AU13: 55.7 | AV13: 180.5 | AW13: 180.9 | AX13: 184 | AY13: 90.7 | AZ13: 0 | BA13: 23 | BB13: 4 | BC13: 29.4 | BD13: 38.4 | BG13: 10.4 | BJ13: 23.4 | BN13: 60.0299 | BO13: 141.03912 | BP13: 140.88191 | BQ13: 141.82612 | BR13: 233.52441 | BS13: 74.75977 | BT13: 36.57257 | CB13: 55.2 | CC13: 86.6 | CD13: 60.8 | CE13: 63.1 | CF13: 29.8 | CG13: 0 | CH13: 0 | CI13: 0 | CJ13: 144.4 | CK13: 146 | CL13: 148.5 | CR13: 213.7 | CS13: 102.3 | CT13: 5 | CU13: 1.7 | CV13: 7.3 | CW13: 0 | CX13: 122.1 | CY13: 0 | CZ13: 0.4 | DA13: 0 | DB13: 3 | DC13: 10 | DE13: 0 | DF13: 1 | DG13: 1.5 | DH13: 4 | DI13: 20 | DJ13: 5.2 | DK13: 13.1 | DL13: 2.9 | DM13: 17.6 | DN13: 0 | DO13: 0 | DP13: 30.1 | DQ13: 89.9 | DR13: 0 | DS13: 2.2 | DT13: 5.6 | DU13: 2.7 | DW13: 6.4 | DX13: 6.7 | DY13: 9 | DZ13: 12.3 | EA13: 10 | EB13: 14.2 | EC13: 8.1 | ED13: 0 | EE13: 62.5564 | EF13: 95.61104 | EG13: 7.6111 | EH13: 3.49574 | EI13: 0 | EJ13: 12.5 | EK13: 4.5 | EL13: 8.5 | EM13: 20.4 | EN13: 20.4 | EO13: 20 | EP13: 0.7 | EQ13: 0 | ER13: 0 | ES13: 0 | ET13: 0.6 | EU13: 97.4 | EV13: 106.2 | EW13: 0 | EX13: 2.9 | EY13: 2.1 | EZ13: 1.2 | FA13: 1.2 | FB13: 0 | FC13: 4.1 | FD13: 20 | FE13: 9 | FF13: 27.1 | FG13: 34.3 | FH13: 17.8 | FI13: 20.3 | FJ13: 7.6 | FK13: 11.1 | FL13: 21.2 | FM13: 6651.7081 | FO13: 16.60826 | FP13: 0 | FQ13: 11.22 | FR13: 9.2 | FS13: 26.76302 | FT13: 18.92816 | FU13: 0 | FV13: 4.9 | FW13: 87.61944
A14: 16/12/2025 | B14: 02:00 | C14: 203.6 | D14: 546.9 | E14: 181.2 | H14: 31.8 | I14: 118.1 | J14: 0 | L14: 185.2 | M14: 207 | N14: 204.5 | P14: 210.9 | R14: 196.8 | S14: 9.9 | X14: 170.6 | Y14: 7.7 | AA14: 22.6 | AB14: 6.8 | AC14: 14.9 | AD14: 79 | AI14: 110.8 | AJ14: 0 | AN14: 6.5 | AO14: 173.1 | AP14: 36 | AQ14: 55.7 | AR14: 19.6 | AS14: 18.4 | AT14: 15.8 | AU14: 57.7 | AV14: 183.4 | AW14: 183.8 | AX14: 182.8 | AY14: 91.6 | AZ14: 0 | BA14: 23.7 | BB14: 4 | BC14: 30.2 | BD14: 43.2 | BG14: 11.6 | BJ14: 23.7 | BN14: 60.67693 | BO14: 133.67645 | BP14: 133.56706 | BQ14: 133.13784 | BR14: 223.51695 | BS14: 74.76055 | BT14: 36.55895 | CB14: 66.7 | CC14: 90.9 | CD14: 62.1 | CE14: 60.8 | CF14: 28.5 | CG14: 0 | CH14: 0 | CI14: 0 | CJ14: 144.1 | CK14: 145.8 | CL14: 148.1 | CR14: 213.9 | CS14: 102.3 | CT14: 5 | CU14: 1.7 | CV14: 7.5 | CW14: 0 | CX14: 121 | CY14: 0 | CZ14: 0.2 | DA14: 0 | DB14: 3.2 | DC14: 9.9 | DE14: 0 | DF14: 1 | DG14: 1.5 | DH14: 3.9 | DI14: 20.6 | DJ14: 5.2 | DK14: 13.1 | DL14: 2.9 | DM14: 17.6 | DN14: 0 | DO14: 0 | DP14: 29.9 | DQ14: 89.7 | DR14: 0 | DS14: 2.2 | DT14: 0.7 | DU14: 2.6 | DW14: 6.4 | DX14: 6.7 | DY14: 9.8 | DZ14: 12.7 | EA14: 10 | EB14: 12.7 | EC14: 9.2 | ED14: 0 | EE14: 75.34746 | EF14: 90.37828 | EG14: 6.24161 | EH14: 1.85502 | EI14: 0 | EJ14: 12.3 | EK14: 4.4 | EL14: 8.5 | EM14: 20.4 | EN14: 20.4 | EO14: 20 | EP14: 0.6 | EQ14: 0 | ER14: 0 | ES14: 0 | ET14: 0.6 | EU14: 109.1 | EV14: 131.4 | EW14: 0 | EX14: 2.9 | EY14: 2.1 | EZ14: 1.2 | FA14: 1.2 | FB14: 0 | FC14: 4.1 | FD14: 20 | FE14: 8.4 | FF14: 27.1 | FG14: 34.3 | FH14: 18 | FI14: 20.3 | FJ14: 8.3 | FK14: 11.1 | FL14: 21 | FM14: 6616.6171 | FO14: 17.80638 | FP14: 0 | FQ14: 11.54 | FR14: 9.3 | FS14: 26.74097 | FT14: 18.92861 | FU14: 0 | FV14: 4.8 | FW14: 89.11596
A15: 16/12/2025 | B15: 02:30 | C15: 202.4 | D15: 538.6 | E15: 182 | H15: 31.5 | I15: 114.8 | J15: 0 | L15: 185.1 | M15: 207 | N15: 204.4 | P15: 213.2 | R15: 105.1 | S15: 9.8 | X15: 163.1 | Y15: 6.9 | AA15: 22.6 | AB15: 6.8 | AC15: 14.9 | AD15: 78.7 | AI15: 109.9 | AJ15: 0 | AN15: 6.5 | AO15: 157 | AP15: 36 | AQ15: 52.3 | AR15: 18.7 | AS15: 18.6 | AT15: 16.1 | AU15: 56.5 | AV15: 180.3 | AW15: 180.4 | AX15: 183.5 | AY15: 89.3 | AZ15: 0 | BA15: 23.1 | BB15: 4 | BC15: 29.5 | BD15: 38.2 | BG15: 10.7 | BJ15: 23.2 | BN15: 60.32673 | BO15: 154.3042 | BP15: 154.32167 | BQ15: 155.04856 | BR15: 247.30942 | BS15: 74.62566 | BT15: 36.61266 | CB15: 65.2 | CC15: 90.6 | CD15: 61.1 | CE15: 59.6 | CF15: 26.6 | CG15: 0 | CH15: 0 | CI15: 0 | CJ15: 144.4 | CK15: 145.9 | CL15: 147.4 | CR15: 213.5 | CS15: 102.4 | CT15: 5.1 | CU15: 1.7 | CV15: 7.2 | CW15: 0 | CX15: 118.8 | CY15: 0 | CZ15: 0 | DA15: 0 | DB15: 2.9 | DC15: 9.9 | DE15: 0 | DF15: 0.9 | DG15: 1.5 | DH15: 3.8 | DI15: 20 | DJ15: 5.2 | DK15: 13 | DL15: 3 | DM15: 17.6 | DN15: 0 | DO15: 0 | DP15: 29.5 | DQ15: 86.9 | DR15: 0 | DS15: 2.1 | DT15: 0 | DU15: 2.6 | DW15: 6.6 | DX15: 6.7 | DY15: 9.2 | DZ15: 12.2 | EA15: 10 | EB15: 14 | EC15: 8.9 | ED15: 0 | EE15: 68.84061 | EF15: 95.81272 | EG15: 7.89959 | EH15: 2.0514 | EI15: 0 | EJ15: 12.2 | EK15: 4.4 | EL15: 8.4 | EM15: 20.4 | EN15: 20.4 | EO15: 20 | EP15: 0.5 | EQ15: 0 | ER15: 0 | ES15: 0 | ET15: 0.6 | EU15: 108.6 | EV15: 132.6 | EW15: 0 | EX15: 2.9 | EY15: 2.1 | EZ15: 1.2 | FA15: 1.2 | FB15: 0 | FC15: 4.1 | FD15: 20 | FE15: 9.4 | FF15: 27.3 | FG15: 34.5 | FH15: 17.9 | FI15: 20.3 | FJ15: 8.4 | FK15: 11.1 | FL15: 18.4 | FM15: 6540.7532 | FO15: 17.99146 | FP15: 0 | FQ15: 11.55 | FR15: 9.2 | FS15: 26.82878 | FT15: 18.92925 | FU15: 0 | FV15: 4.9 | FW15: 89.39949
A16: 16/12/2025 | B16: 03:00 | C16: 203 | D16: 483.1 | E16: 156 | H16: 31.9 | I16: 115.5 | J16: 0 | L16: 185.8 | M16: 206.7 | N16: 204.2 | P16: 210.7 | R16: 111.2 | S16: 9.9 | X16: 163.5 | Y16: 7.7 | AA16: 22.5 | AB16: 6.8 | AC16: 15 | AD16: 80.1 | AI16: 111.1 | AJ16: 0 | AN16: 6.5 | AO16: 157.8 | AP16: 37.1 | AQ16: 76.7 | AR16: 19.8 | AS16: 18.6 | AT16: 16.5 | AU16: 57.9 | AV16: 182.7 | AW16: 183.3 | AX16: 185.1 | AY16: 91.2 | AZ16: 0 | BA16: 23.7 | BB16: 4 | BC16: 30 | BD16: 45.7 | BG16: 11.8 | BJ16: 23.9 | BN16: 60.68127 | BO16: 148.04006 | BP16: 147.96477 | BQ16: 146.74289 | BR16: 217.2023 | BS16: 75.17179 | BT16: 36.67866 | CB16: 68.5 | CC16: 101.8 | CD16: 62 | CE16: 60 | CF16: 27.8 | CG16: 0 | CH16: 0 | CI16: 0 | CJ16: 144.5 | CK16: 146.1 | CL16: 148 | CR16: 214.2 | CS16: 102.4 | CT16: 5 | CU16: 1.7 | CV16: 7 | CW16: 0 | CX16: 112.8 | CY16: 0 | CZ16: 0 | DA16: 0 | DB16: 3.1 | DC16: 9.9 | DE16: 0 | DF16: 1 | DG16: 1.5 | DH16: 3.8 | DI16: 20.6 | DJ16: 5.3 | DK16: 13 | DL16: 3 | DM16: 17.6 | DN16: 0 | DO16: 0 | DP16: 27.6 | DQ16: 78.5 | DR16: 0 | DS16: 2.1 | DT16: 0 | DU16: 2.6 | DW16: 6.6 | DX16: 6.7 | DY16: 10 | DZ16: 12.9 | EA16: 9.9 | EB16: 15.2 | EC16: 8.9 | ED16: 0 | EE16: 83.60353 | EF16: 95.12323 | EG16: 5.7987 | EH16: 4.01097 | EI16: 0 | EJ16: 12.1 | EK16: 4.4 | EL16: 8.4 | EM16: 20.4 | EN16: 20.4 | EO16: 20 | EP16: 0.4 | EQ16: 0 | ER16: 0 | ES16: 0 | ET16: 0.6 | EU16: 106.8 | EV16: 117.1 | EW16: 0 | EX16: 2.9 | EY16: 2.1 | EZ16: 1.2 | FA16: 1.2 | FB16: 0 | FC16: 4.1 | FD16: 20 | FE16: 9.6 | FF16: 27.7 | FG16: 34.8 | FH16: 17.9 | FI16: 20.3 | FJ16: 8.5 | FK16: 11.1 | FL16: 22 | FM16: 6473.6182 | FO16: 18.31084 | FP16: 0 | FQ16: 11.55 | FR16: 9.3 | FS16: 26.8364 | FT16: 18.9291 | FU16: 0 | FV16: 4.8 | FW16: 89.72634
A17: 16/12/2025 | B17: 03:30 | C17: 205.4 | D17: 478 | E17: 156.3 | H17: 33 | I17: 115.8 | J17: 0 | L17: 185.4 | M17: 209.1 | N17: 207.7 | P17: 212 | R17: 124.4 | S17: 10 | X17: 166 | Y17: 7.5 | AA17: 22.5 | AB17: 6.9 | AC17: 15 | AD17: 80 | AI17: 110.8 | AJ17: 0 | AN17: 6.5 | AO17: 148.2 | AP17: 38 | AQ17: 53.5 | AR17: 20.9 | AS17: 18.6 | AT17: 17.4 | AU17: 56.3 | AV17: 184.4 | AW17: 184.5 | AX17: 184.4 | AY17: 93 | AZ17: 0 | BA17: 23.5 | BB17: 4 | BC17: 28.5 | BD17: 46.2 | BG17: 11.6 | BJ17: 23.8 | BN17: 61.14934 | BO17: 168.97716 | BP17: 168.81705 | BQ17: 169.67962 | BR17: 255.94238 | BS17: 74.59111 | BT17: 36.72647 | CB17: 95.8 | CC17: 104.9 | CD17: 62.2 | CE17: 62 | CF17: 27.7 | CG17: 0 | CH17: 0 | CI17: 0 | CJ17: 144.2 | CK17: 145.8 | CL17: 147.9 | CR17: 214.3 | CS17: 102.5 | CT17: 4.9 | CU17: 1.7 | CV17: 7 | CW17: 0 | CX17: 108.1 | CY17: 0 | CZ17: 0 | DA17: 0 | DB17: 3.1 | DC17: 9.9 | DE17: 0 | DF17: 0.9 | DG17: 1.5 | DH17: 4 | DI17: 20.3 | DJ17: 6 | DK17: 13 | DL17: 2.9 | DM17: 17.6 | DN17: 0 | DO17: 0 | DP17: 26 | DQ17: 77 | DR17: 0 | DS17: 2.1 | DT17: 0 | DU17: 2.6 | DW17: 6.6 | DX17: 6.7 | DY17: 10 | DZ17: 12.6 | EA17: 10 | EB17: 15.3 | EC17: 6.3 | ED17: 0 | EE17: 79.85106 | EF17: 90.60809 | EG17: 4.20693 | EH17: 4.95685 | EI17: 0 | EJ17: 12 | EK17: 4.3 | EL17: 8.4 | EM17: 20.4 | EN17: 20.4 | EO17: 20 | EP17: 0 | EQ17: 0 | ER17: 0 | ES17: 0 | ET17: 0.6 | EU17: 103.8 | EV17: 116 | EW17: 0 | EX17: 2.9 | EY17: 2.1 | EZ17: 1.2 | FA17: 1.2 | FB17: 0 | FC17: 4.1 | FD17: 20 | FE17: 9.6 | FF17: 27.6 | FG17: 34.8 | FH17: 18.5 | FI17: 20.3 | FJ17: 8.8 | FK17: 11.1 | FL17: 22.2 | FM17: 6578.3061 | FO17: 18.39252 | FP17: 0 | FQ17: 11.55 | FR17: 9.2 | FS17: 26.80493 | FT17: 18.92857 | FU17: 0 | FV17: 4.9 | FW17: 89.77602
A18: 16/12/2025 | B18: 04:00 | C18: 201.4 | D18: 477.9 | E18: 156.6 | H18: 31.9 | I18: 115.1 | J18: 0 | L18: 186.5 | M18: 207.4 | N18: 208.2 | P18: 214.3 | R18: 156.8 | S18: 10 | X18: 165.5 | Y18: 7.2 | AA18: 22.6 | AB18: 6.8 | AC18: 15 | AD18: 79.7 | AI18: 110.9 | AJ18: 0 | AN18: 6.5 | AO18: 146.5 | AP18: 38 | AQ18: 56 | AR18: 20.3 | AS18: 18.6 | AT18: 17.6 | AU18: 57.1 | AV18: 181.8 | AW18: 182.2 | AX18: 184.8 | AY18: 91.2 | AZ18: 0 | BA18: 23.5 | BB18: 4 | BC18: 27.6 | BD18: 56.5 | BG18: 11.5 | BJ18: 24 | BN18: 60.47961 | BO18: 171.16248 | BP18: 172.03114 | BQ18: 172.14169 | BR18: 254.88077 | BS18: 75.1922 | BT18: 36.66926 | CB18: 105.9 | CC18: 106.5 | CD18: 62 | CE18: 61.9 | CF18: 28 | CG18: 0 | CH18: 0 | CI18: 0 | CJ18: 144.5 | CK18: 146.2 | CL18: 148.1 | CR18: 213.1 | CS18: 102.2 | CT18: 5 | CU18: 1.7 | CV18: 6.9 | CW18: 0 | CX18: 103.6 | CY18: 0 | CZ18: 0 | DA18: 0 | DB18: 2.9 | DC18: 9.9 | DE18: 0 | DF18: 0.9 | DG18: 1.4 | DH18: 3.9 | DI18: 20.3 | DJ18: 6.2 | DK18: 13 | DL18: 2.9 | DM18: 17.6 | DN18: 0 | DO18: 0 | DP18: 27.2 | DQ18: 80.5 | DR18: 0 | DS18: 2.1 | DT18: 0 | DU18: 2.6 | DW18: 6.6 | DX18: 6.7 | DY18: 10.1 | DZ18: 12.7 | EA18: 10 | EB18: 15.1 | EC18: 6.3 | ED18: 0 | EE18: 75.00366 | EF18: 87.11828 | EG18: 2.71504 | EH18: 1.567 | EI18: 0 | EJ18: 11.8 | EK18: 4.3 | EL18: 8.7 | EM18: 20.4 | EN18: 20.4 | EO18: 20 | EP18: 0 | EQ18: 0 | ER18: 0 | ES18: 0 | ET18: 0.6 | EU18: 108.8 | EV18: 106 | EW18: 0 | EX18: 2.9 | EY18: 2.1 | EZ18: 1.2 | FA18: 1.2 | FB18: 0 | FC18: 4.1 | FD18: 20 | FE18: 9.2 | FF18: 27.7 | FG18: 34.9 | FH18: 18.2 | FI18: 20.3 | FJ18: 8.3 | FK18: 11.1 | FL18: 19.7 | FM18: 6606.8611 | FO18: 18.4721 | FP18: 0 | FQ18: 11.55 | FR18: 9.3 | FS18: 26.83447 | FT18: 18.92904 | FU18: 0 | FV18: 4.9 | FW18: 89.98561
A19: 16/12/2025 | B19: 04:30 | C19: 201.4 | D19: 478.6 | E19: 155.9 | H19: 31.7 | I19: 115.1 | J19: 0 | L19: 186.3 | M19: 207.4 | N19: 209.1 | P19: 211.9 | R19: 193.8 | S19: 9.9 | X19: 160.2 | Y19: 7.1 | AA19: 22.6 | AB19: 6.8 | AC19: 15.1 | AD19: 80 | AI19: 110.8 | AJ19: 0 | AN19: 6.5 | AO19: 146.5 | AP19: 38 | AQ19: 61 | AR19: 19.3 | AS19: 18.6 | AT19: 17.7 | AU19: 55.7 | AV19: 182.4 | AW19: 182.9 | AX19: 185.8 | AY19: 90.8 | AZ19: 0 | BA19: 23.5 | BB19: 4 | BC19: 27.8 | BD19: 75.6 | BG19: 11.4 | BJ19: 23.7 | BN19: 60.63366 | BO19: 173.12741 | BP19: 171.23333 | BQ19: 173.85675 | BR19: 247.22745 | BS19: 75.00844 | BT19: 36.63271 | CB19: 104.8 | CC19: 101.4 | CD19: 61.7 | CE19: 62 | CF19: 28 | CG19: 0 | CH19: 0 | CI19: 0 | CJ19: 145.2 | CK19: 146.9 | CL19: 148.7 | CR19: 213.1 | CS19: 102.3 | CT19: 5 | CU19: 1.7 | CV19: 6.9 | CW19: 0 | CX19: 102.6 | CY19: 0 | CZ19: 0 | DA19: 0 | DB19: 2.9 | DC19: 9.9 | DE19: 0 | DF19: 1 | DG19: 1.5 | DH19: 3.8 | DI19: 20.3 | DJ19: 6 | DK19: 13 | DL19: 2.9 | DM19: 17.6 | DN19: 0 | DO19: 0 | DP19: 25.5 | DQ19: 71.9 | DR19: 0 | DS19: 2.1 | DT19: 0 | DU19: 2.5 | DW19: 6.6 | DX19: 6.7 | DY19: 10 | DZ19: 13.7 | EA19: 10 | EB19: 14 | EC19: 8 | ED19: 0 | EE19: 51.53208 | EF19: 74.49966 | EG19: 2.6795 | EH19: 1.12692 | EI19: 0 | EJ19: 11.8 | EK19: 4.3 | EL19: 8.6 | EM19: 20.4 | EN19: 20.4 | EO19: 20 | EP19: 0 | EQ19: 0 | ER19: 0 | ES19: 0 | ET19: 0.6 | EU19: 96.4 | EV19: 93 | EW19: 0 | EX19: 2.9 | EY19: 2.1 | EZ19: 1.2 | FA19: 1.2 | FB19: 0 | FC19: 4.1 | FD19: 20 | FE19: 9.1 | FF19: 27.7 | FG19: 34.8 | FH19: 18.2 | FI19: 20.3 | FJ19: 8.2 | FK19: 11.1 | FL19: 17.4 | FM19: 6576.4579 | FO19: 18.56836 | FP19: 0 | FQ19: 11.55 | FR19: 9.4 | FS19: 26.86825 | FT19: 18.92889 | FU19: 0 | FV19: 4.9 | FW19: 90.2155
A20: 16/12/2025 | B20: 05:00 | C20: 203.6 | D20: 536.9 | E20: 178 | H20: 31.5 | I20: 107.4 | J20: 0 | L20: 185.4 | M20: 207.5 | N20: 207 | P20: 210.2 | R20: 197.1 | S20: 9.9 | X20: 164.6 | Y20: 7.3 | AA20: 22.5 | AB20: 6.8 | AC20: 15 | AD20: 79.3 | AI20: 110.9 | AJ20: 0 | AN20: 6.5 | AO20: 151.5 | AP20: 38 | AQ20: 62.3 | AR20: 21.2 | AS20: 18.6 | AT20: 17.8 | AU20: 57 | AV20: 181.7 | AW20: 182.5 | AX20: 184 | AY20: 91.5 | AZ20: 0 | BA20: 25 | BB20: 4 | BC20: 27.5 | BD20: 43.7 | BG20: 11.4 | BJ20: 23.9 | BN20: 60.6247 | BO20: 163.96995 | BP20: 163.68736 | BQ20: 164.63797 | BR20: 254.58347 | BS20: 74.29614 | BT20: 36.5304 | CB20: 96.4 | CC20: 96.5 | CD20: 61.9 | CE20: 63.9 | CF20: 28.2 | CG20: 0 | CH20: 0 | CI20: 0 | CJ20: 144.9 | CK20: 146.5 | CL20: 148.8 | CR20: 213.8 | CS20: 102.5 | CT20: 5 | CU20: 1.7 | CV20: 6.7 | CW20: 0 | CX20: 97.9 | CY20: 0 | CZ20: 0 | DA20: 0 | DB20: 3 | DC20: 10 | DE20: 0 | DF20: 1 | DG20: 1.5 | DH20: 3.8 | DI20: 20.6 | DJ20: 6 | DK20: 13 | DL20: 2.9 | DM20: 17.6 | DN20: 0 | DO20: 0 | DP20: 24.8 | DQ20: 65.2 | DR20: 0 | DS20: 2.2 | DT20: 0 | DU20: 2.5 | DW20: 6.6 | DX20: 6.7 | DY20: 10 | DZ20: 13.6 | EA20: 10 | EB20: 9.4 | EC20: 9.3 | ED20: 0 | EE20: 57.24551 | EF20: 81.60071 | EG20: 4.51155 | EH20: 1.63258 | EI20: 0 | EJ20: 11.5 | EK20: 4.2 | EL20: 8.6 | EM20: 20.4 | EN20: 20.4 | EO20: 20 | EP20: 0 | EQ20: 0 | ER20: 0 | ES20: 0 | ET20: 0.6 | EU20: 84.2 | EV20: 84 | EW20: 0 | EX20: 2.9 | EY20: 2.1 | EZ20: 1.2 | FA20: 1.2 | FB20: 0 | FC20: 4.1 | FD20: 20 | FE20: 9.3 | FF20: 27.8 | FG20: 34.8 | FH20: 18.1 | FI20: 20.3 | FJ20: 8.1 | FK20: 11.1 | FL20: 17.3 | FM20: 6578.9203 | FO20: 18.88289 | FP20: 0 | FQ20: 11.55 | FR20: 9.2 | FS20: 26.88707 | FT20: 18.92905 | FU20: 0 | FV20: 4.8 | FW20: 90.24901
A21: 16/12/2025 | B21: 05:30 | C21: 203.2 | D21: 594.9 | E21: 192.3 | H21: 31.9 | I21: 104.2 | J21: 0 | L21: 185.9 | M21: 207.4 | N21: 206.4 | P21: 212 | R21: 196.3 | S21: 9.9 | X21: 163.9 | Y21: 7.1 | AA21: 22.6 | AB21: 6.8 | AC21: 14.9 | AD21: 79.6 | AI21: 110.9 | AJ21: 0 | AN21: 6.5 | AO21: 220.8 | AP21: 38.3 | AQ21: 68.5 | AR21: 21 | AS21: 18.6 | AT21: 17.8 | AU21: 57 | AV21: 181.7 | AW21: 182.5 | AX21: 184.1 | AY21: 90.7 | AZ21: 0 | BA21: 24.8 | BB21: 4 | BC21: 27.5 | BD21: 41.6 | BG21: 19.9 | BJ21: 24 | BN21: 60.63085 | BO21: 169.20767 | BP21: 169.02072 | BQ21: 170.16177 | BR21: 256.48916 | BS21: 74.96307 | BT21: 36.6806 | CB21: 78.2 | CC21: 98.2 | CD21: 61.9 | CE21: 65.8 | CF21: 27.5 | CG21: 0 | CH21: 0 | CI21: 0 | CJ21: 144.7 | CK21: 146.2 | CL21: 148.4 | CR21: 213.8 | CS21: 102.4 | CT21: 5 | CU21: 1.7 | CV21: 6.6 | CW21: 0 | CX21: 98.1 | CY21: 0 | CZ21: 0 | DA21: 0 | DB21: 2.9 | DC21: 9.9 | DE21: 4.9 | DF21: 1.1 | DG21: 1.5 | DH21: 3.9 | DI21: 20.3 | DJ21: 5.9 | DK21: 12.3 | DL21: 2.9 | DM21: 17.6 | DN21: 0.2 | DO21: 0.1 | DP21: 25.8 | DQ21: 67 | DR21: 0.4 | DS21: 2.1 | DT21: 0 | DU21: 2.5 | DW21: 6.6 | DX21: 6.7 | DY21: 9.9 | DZ21: 13.6 | EA21: 10 | EB21: 6.1 | EC21: 8.5 | ED21: 1.91957 | EE21: 65.06395 | EF21: 65.50617 | EG21: 1.73332 | EH21: 0.91379 | EI21: 0 | EJ21: 11.5 | EK21: 4.2 | EL21: 8.5 | EM21: 20.4 | EN21: 20.4 | EO21: 20 | EP21: 0 | EQ21: 6 | ER21: 0 | ES21: 6.8 | ET21: 0.6 | EU21: 79.1 | EV21: 69.6 | EW21: 6.5 | EX21: 2.9 | EY21: 2.1 | EZ21: 1.2 | FA21: 1.2 | FB21: 0 | FC21: 4.1 | FD21: 20 | FE21: 8.7 | FF21: 27.8 | FG21: 34.8 | FH21: 18.1 | FI21: 20.3 | FJ21: 8.5 | FK21: 11.1 | FL21: 22.8 | FM21: 6730.1906 | FO21: 18.78173 | FP21: 0 | FQ21: 11.25 | FR21: 9.2 | FS21: 26.94943 | FT21: 18.92956 | FU21: 0 | FV21: 4.9 | FW21: 90.01072
A22: 16/12/2025 | B22: 06:00 | C22: 200.9 | D22: 596.3 | E22: 201.4 | H22: 31.3 | I22: 111.5 | J22: 0 | L22: 185.6 | M22: 208 | N22: 205.6 | P22: 212.3 | R22: 196.7 | S22: 9.9 | X22: 164.2 | Y22: 7.1 | AA22: 22.5 | AB22: 6.9 | AC22: 14.7 | AD22: 79.8 | AI22: 110.3 | AJ22: 0 | AN22: 6.5 | AO22: 147.9 | AP22: 39.3 | AQ22: 60.9 | AR22: 20.3 | AS22: 18.6 | AT22: 17.8 | AU22: 57.4 | AV22: 179.7 | AW22: 180 | AX22: 184.3 | AY22: 90.5 | AZ22: 0 | BA22: 24.9 | BB22: 4 | BC22: 27.9 | BD22: 40.6 | BG22: 19.5 | BJ22: 24.1 | BN22: 60.39896 | BO22: 156.57897 | BP22: 156.49645 | BQ22: 155.4983 | BR22: 235.43433 | BS22: 74.91859 | BT22: 36.56384 | CB22: 73 | CC22: 95.7 | CD22: 61.4 | CE22: 68.9 | CF22: 27.3 | CG22: 0 | CH22: 0 | CI22: 0 | CJ22: 145 | CK22: 146.6 | CL22: 148.6 | CR22: 214.2 | CS22: 102.5 | CT22: 5 | CU22: 1.7 | CV22: 6.7 | CW22: 0 | CX22: 106.2 | CY22: 2.2 | CZ22: 0 | DA22: 0 | DB22: 2.8 | DC22: 9.9 | DE22: 21.4 | DF22: 1.1 | DG22: 1.6 | DH22: 3.9 | DI22: 20 | DJ22: 5.8 | DK22: 12.3 | DL22: 3 | DM22: 17.6 | DN22: 0.5 | DO22: 0.4 | DP22: 26.3 | DQ22: 70.1 | DR22: 1.1 | DS22: 2.1 | DT22: 4 | DU22: 2.4 | DW22: 6.6 | DX22: 6.7 | DY22: 10.1 | DZ22: 13.7 | EA22: 10 | EB22: 5.7 | EC22: 7 | ED22: 11.00892 | EE22: 56.7932 | EF22: 73.82655 | EG22: 4.28153 | EH22: 1.78087 | EI22: 1.72 | EJ22: 11.5 | EK22: 4.2 | EL22: 8.5 | EM22: 20.4 | EN22: 20.4 | EO22: 20 | EP22: 0 | EQ22: 30.6 | ER22: 0.7 | ES22: 32.5 | ET22: 0.6 | EU22: 57.3 | EV22: 55.6 | EW22: 24 | EX22: 2.9 | EY22: 2.1 | EZ22: 1.2 | FA22: 1.2 | FB22: 0.7 | FC22: 4.1 | FD22: 20 | FE22: 8.8 | FF22: 28 | FG22: 35 | FH22: 17.8 | FI22: 20.3 | FJ22: 8.1 | FK22: 11.1 | FL22: 22.4 | FM22: 6675.6005 | FO22: 18.92486 | FP22: 0 | FQ22: 10.57 | FR22: 9.2 | FS22: 26.95987 | FT22: 18.92933 | FU22: 4.9 | FV22: 4.8 | FW22: 94.28406
... A58: 17/12/2025 | B58: 00:00 | C58: 204.5 | D58: 450.3 | E58: 147.3 | H58: 80.4 | I58: 120.6 | J58: 80.4 | L58: 184.4 | M58: 207.1 | N58: 204.1 | P58: 209.3 | R58: 478.1 | S58: 9.9 | X58: 163.7 | Y58: 7.6 | AA58: 16.9 | AB58: 6.9 | AC58: 15.1 | AD58: 85.5 | AI58: 110.9 | AJ58: 65.5 | AN58: 6.5 | AO58: 152.9 | AP58: 45.4 | AQ58: 131.3 | AR58: 22.9 | AS58: 18.4 | AT58: 17.2 | AU58: 57.6 | AV58: 182.6 | AW58: 183.2 | AX58: 184.5 | AY58: 106.5 | AZ58: 0 | BA58: 24.2 | BB58: 4 | BC58: 34.5 | BD58: 42.6 | BG58: 58 | BJ58: 47 | BN58: 81.22009 | BO58: 153.17812 | BP58: 153.40816 | BQ58: 152.88558 | BR58: 233.4293 | BS58: 74.19027 | BT58: 36.39774 | CB58: 80.1 | CC58: 104.6 | CD58: 64 | CE58: 74.8 | CF58: 30.3 | CG58: 118.2 | CH58: 48.2 | CI58: 49.7 | CJ58: 144.2 | CK58: 145.2 | CL58: 170.7 | CR58: 213.3 | CS58: 102.2 | CT58: 5.6 | CU58: 1.6 | CV58: 5.9 | CW58: 0 | CX58: 56.9 | CY58: 0 | CZ58: 0 | DA58: 0 | DB58: 20.2 | DC58: 10 | DE58: 0 | DF58: 1.2 | DG58: 1.7 | DH58: 3.9 | DI58: 20.3 | DJ58: 5.1 | DK58: 13 | DL58: 2.6 | DM58: 16.9 | DN58: 0 | DO58: 0 | DP58: 11.7 | DQ58: 40.9 | DR58: 0 | DS58: 2.2 | DT58: 13.9 | DU58: 3.1 | DW58: 7.1 | DX58: 6.5 | DY58: 19.4 | DZ58: 20.2 | EA58: 18.1 | EB58: 12.7 | EC58: 21.5 | ED58: 0 | EE58: 37.45426 | EF58: 56.3 | EG58: 2.16535 | EH58: 0.31 | EI58: 0 | EJ58: 15.4 | EK58: 3.8 | EL58: 8.3 | EM58: 20.4 | EN58: 20.4 | EO58: 20 | EP58: 0 | EQ58: 0 | ER58: 0 | ES58: 0 | ET58: 0.6 | EU58: 11.9 | EV58: 5.7 | EW58: 0 | EX58: 2.9 | EY58: 2.1 | EZ58: 1.2 | FA58: 1.2 | FB58: 0 | FC58: 4.1 | FD58: 19.3 | FE58: 8.6 | FF58: 27.3 | FG58: 34 | FH58: 17.6 | FI58: 19.2 | FJ58: 7.46 | FK58: 11.1 | FL58: 20 | FM58: 7118.9989 | FO58: 18.97877 | FP58: 1.298 | FQ58: 11.853 | FR58: 9.2 | FS58: 26.78348 | FT58: 9.4373 | FU58: 0 | FV58: 5.1 | FW58: 82.65055
A59: EJEC | C59: 4862.15 | D59: 12264.8 | E59: 4052.6 | F59: 0 | G59: 0 | H59: 1709.7 | I59: 3469.7 | J59: 955.9 | K59: 0 | L59: 4371.85 | M59: 4917.85 | N59: 4879.75 | O59: 0 | P59: 5015.25 | Q59: 0 | R59: 5922.1 | S59: 237.55 | T59: 0 | U59: 0 | V59: 0 | W59: 0 | X59: 3927.9 | Y59: 174.95 | Z59: 0 | AA59: 437.9 | AB59: 165.15 | AC59: 356.05 | AD59: 2230.85 | AE59: 0 | AF59: 0 | AG59: 0 | AH59: 0 | AI59: 2656.5 | AJ59: 1733.6 | AK59: 0 | AL59: 0 | AM59: 0 | AN59: 156 | AO59: 4367.5 | AP59: 1040.1 | AQ59: 2539.65 | AR59: 505.45 | AS59: 443.85 | AT59: 416.7 | AU59: 1368.3 | AV59: 4376.5 | AW59: 4386.5 | AX59: 4433.65 | AY59: 2392.7 | AZ59: 202.9 | BA59: 587.15 | BB59: 96 | BC59: 770.2 | BD59: 929.55 | BE59: 0 | BF59: 0 | BG59: 1094.05 | BH59: 0 | BI59: 0 | BJ59: 890.75 | BK59: 0 | BL59: 0 | BM59: 0 | BN59: 1624.9129 | BO59: 3896.3077 | BP59: 3882.0039 | BQ59: 4027.1191 | BR59: 5961.7851 | BS59: 1763.5293 | BT59: 863.11156 | BU59: 0 | BV59: 0 | BW59: 0 | BX59: 0 | BY59: 0 | BZ59: 0 | CA59: 0 | CB59: 2594.95 | CC59: 2377.7 | CD59: 1528.35 | CE59: 1646.55 | CF59: 674.55 | CG59: 1445.7 | CH59: 72.1 | CI59: 564.5 | CJ59: 3446.95 | CK59: 3480.35 | CL59: 3941.05 | CM59: 0 | CN59: 0 | CO59: 0 | CP59: 0 | CQ59: 0 | CR59: 5075.75 | CS59: 2422.7 | CT59: 134.8 | CU59: 38.4 | CV59: 153 | CW59: 8.05 | CX59: 2181.1 | CY59: 752.25 | CZ59: 36.75 | DA59: 1.85 | DB59: 208.55 | DC59: 237.45 | DD59: 0 | DE59: 2242.7 | DF59: 26.1 | DG59: 37.45 | DH59: 94.5 | DI59: 466.1 | DJ59: 138.1 | DK59: 308.15 | DL59: 64.95 | DM59: 422.35 | DN59: 143.05 | DO59: 176.7 | DP59: 505.4 | DQ59: 1576.5 | DR59: 141.8 | DS59: 52.75 | DT59: 244.05 | DU59: 60.45 | DV59: 0 | DW59: 159.65 | DX59: 158.1 | DY59: 340.3 | DZ59: 385.6 | EA59: 265.35 | EB59: 209.7 | EC59: 694.3 | ED59: 402.58446 | EE59: 1518.0742 | EF59: 1870.0815 | EG59: 192.36828 | EH59: 43.120915 | EI59: 211.065 | EJ59: 326.65 | EK59: 97.4 | EL59: 199.95 | EM59: 489.6 | EN59: 489.6 | EO59: 480 | EP59: 39.965 | EQ59: 2699.45 | ER59: 136.1 | ES59: 1510.1 | ET59: 13.65 | EU59: 1661.25 | EV59: 1696.5 | EW59: 1180.05 | EX59: 69.6 | EY59: 50.2 | EZ59: 28.8 | FA59: 28.8 | FB59: 133.5 | FC59: 98.4 | FD59: 470.6 | FE59: 214.6 | FF59: 657.65 | FG59: 825.25 | FH59: 419.65 | FI59: 479.3 | FJ59: 198.6195 | FK59: 265.65 | FL59: 483.75 | FM59: 178977.8 | FO59: 420.37673 | FP59: 68.1815 | FQ59: 272.23575 | FR59: 221.6 | FS59: 635.19808 | FT59: 397.31367 | FU59: 4.9 | FV59: 171.85 | FW59: 2191.6557

Sheet REACTIVA
B3: martes, 16 de Diciembre del 2025
A5: POTENCIA REACTIVA EJECUTADA DE LAS UNIDADES DE GENERACIÓN DEL COES (MVAR) | FO5: CENTRALES NO INTEGRANTES COES
A6: FECHA | B6: HORA | C6: 65333 | D6: 101 | E6: 102 | F6: 42667 | G6: 42668 | H6: 126 | I6: 127 | J6: 138 | K6: 139 | L6: 197 | M6: 203 | N6: 204 | O6: 230 | P6: 209 | Q6: 56677 | R6: 796 | S6: 2146 | T6: 142 | U6: 143 | V6: 125 | W6: 187 | X6: 163 | Y6: 298 | Z6: 299 | AA6: 219 | AB6: 151 | AC6: 152 | AD6: 153 | AE6: 154 | AF6: 756 | AG6: 156 | AH6: 155 | AI6: 182 | AJ6: 212 | AK6: 758 | AL6: 263 | AM6: 265 | AN6: 775 | AO6: 777 | AP6: 2154 | AQ6: 150 | AR6: 149 | AS6: 188 | AT6: 2131 | AU6: 755 | AV6: 252 | AW6: 249 | AX6: 250 | AY6: 117 | AZ6: 119 | BA6: 120 | BB6: 189 | BC6: 122 | BD6: 266 | BE6: 337 | BF6: 338 | BG6: 251 | BH6: 115 | BI6: 239 | BJ6: 288 | BK6: 240 | BL6: 241 | BM6: 242 | BN6: 191 | BO6: 194 | BP6: 196 | BQ6: 207 | BR6: 236 | BS6: 795 | BT6: 285 | BU6: 995 | BV6: 996 | BW6: 997 | BX6: 766 | BY6: 926 | BZ6: 924 | CA6: 121 | CB6: 103 | CC6: 104 | CD6: 106 | CE6: 105 | CF6: 107 | CG6: 110 | CH6: 109 | CI6: 144 | CJ6: 113 | CK6: 114 | CL6: 193 | CM6: 208 | CN6: 786 | CO6: 787 | CP6: 788 | CQ6: 789 | CR6: 248 | CS6: 2159 | CT6: 267 | CU6: 268 | CV6: 2194 | CW6: 303 | CX6: 59715 | CY6: 62255 | CZ6: 1263 | DA6: 61800 | DB6: 69125 | DC6: 216 | DD6: 198 | DE6: 70400 | DF6: 49607 | DG6: 214 | DH6: 260 | DI6: 2152 | DJ6: 2128 | DK6: 247 | DL6: 228 | DM6: 2135 | DN6: 261 | DO6: 237 | DP6: 253 | DQ6: 770 | DR6: 235 | DS6: 238 | DT6: 2184 | DU6: 61855 | DV6: 223 | DW6: 226 | DX6: 201 | DY6: 258 | DZ6: 259 | EA6: 920 | EB6: 257 | EC6: 256 | ED6: 2148 | EE6: 58288 | EF6: 58289 | EG6: 58839 | EH6: 58840 | EI6: 75260 | EJ6: 296 | EK6: 297 | EL6: 211 | EM6: 2175 | EN6: 2178 | EO6: 2181 | EP6: 1262 | EQ6: 63425 | ER6: 233 | ES6: 2150 | ET6: 2165 | EU6: 2161 | EV6: 61197 | EW6: 58851 | EX6: 225 | EY6: 2201 | EZ6: 2171 | FA6: 760 | FB6: 234 | FC6: 215 | FD6: 917 | FE6: 289 | FF6: 58333 | FG6: 58336 | FH6: 213 | FI6: 232 | FJ6: 2190 | FK6: 69867 | FL6: 75066 | FM6: TOTAL COES | FO6: 221 | FP6: 222 | FQ6: 224 | FR6: 2187 | FS6: 227 | FT6: 49400 | FU6: 199 | FV6: 200 | FW6: TOTAL NO COES
C7: SUR | D7: CENTRO | E7: CENTRO | F7: NORTE | G7: NORTE | H7: NORTE | I7: NORTE | J7: CENTRO | K7: CENTRO | L7: CENTRO | M7: CENTRO | N7: CENTRO | O7: CENTRO | P7: CENTRO | Q7: CENTRO | R7: CENTRO | S7: CENTRO | T7: CENTRO | U7: CENTRO | V7: CENTRO | W7: CENTRO | X7: SUR | Y7: SUR | Z7: SUR | AA7: CENTRO | AB7: SUR | AC7: SUR | AD7: SUR | AE7: SUR | AF7: SUR | AG7: SUR | AH7: SUR | AI7: SUR | AJ7: CENTRO | AK7: NORTE | AL7: NORTE | AM7: NORTE | AN7: CENTRO | AO7: CENTRO | AP7: CENTRO | AQ7: CENTRO | AR7: CENTRO | AS7: CENTRO | AT7: CENTRO | AU7: SUR | AV7: CENTRO | AW7: CENTRO | AX7: CENTRO | AY7: CENTRO | AZ7: CENTRO | BA7: CENTRO | BB7: SUR | BC7: NORTE | BD7: CENTRO | BE7: CENTRO | BF7: CENTRO | BG7: CENTRO | BH7: NORTE | BI7: NORTE | BJ7: NORTE | BK7: SUR | BL7: SUR | BM7: SUR | BN7: CENTRO | BO7: CENTRO | BP7: CENTRO | BQ7: CENTRO | BR7: CENTRO | BS7: CENTRO | BT7: CENTRO | BU7: SUR | BV7: SUR | BW7: SUR | BX7: NORTE | BY7: SUR | BZ7: CENTRO | CA7: NORTE | CB7: CENTRO | CC7: CENTRO | CD7: CENTRO | CE7: CENTRO | CF7: CENTRO | CG7: CENTRO | CH7: CENTRO | CI7: CENTRO | CJ7: CENTRO | CK7: CENTRO | CL7: CENTRO | CM7: CENTRO | CN7: SUR | CO7: SUR | CP7: SUR | CQ7: SUR | CR7: CENTRO | CS7: CENTRO | CT7: CENTRO | CU7: CENTRO | CV7: NORTE | CW7: CENTRO | CX7: CENTRO | CY7: SUR | CZ7: NORTE | DA7: NORTE | DB7: CENTRO | DC7: NORTE | DD7: NORTE | DE7: SUR | DF7: SUR | DG7: CENTRO | DH7: CENTRO | DI7: CENTRO | DJ7: NORTE | DK7: NORTE | DL7: CENTRO | DM7: CENTRO | DN7: SUR | DO7: SUR | DP7: CENTRO | DQ7: CENTRO | DR7: SUR | DS7: CENTRO | DT7: CENTRO | DU7: NORTE | DV7: CENTRO | DW7: CENTRO | DX7: NORTE | DY7: CENTRO | DZ7: CENTRO | EA7: CENTRO | EB7: NORTE | EC7: NORTE | ED7: SUR | EE7: CENTRO | EF7: CENTRO | EG7: CENTRO | EH7: CENTRO | EJ7: CENTRO | EK7: CENTRO | EL7: SUR | EM7: SUR | EN7: SUR | EO7: SUR | EP7: NORTE | EQ7: SUR | ER7: SUR | ES7: SUR | ET7: CENTRO | EU7: CENTRO | EV7: CENTRO | EW7: SUR | EX7: CENTRO | EY7: CENTRO | EZ7: CENTRO | FA7: CENTRO | FB7: SUR | FC7: NORTE | FD7: CENTRO | FE7: NORTE | FF7: NORTE | FG7: NORTE | FH7: CENTRO | FI7: NORTE | FJ7: NORTE | FK7: NORTE | FO7: NORTE | FP7: CENTRO | FQ7: NORTE | FR7: NORTE | FS7: NORTE | FT7: NORTE | FU7: NORTE | FV7: NORTE
C8: HIDROELÉCTRICA | D8: HIDROELÉCTRICA | E8: HIDROELÉCTRICA | F8: TERMOELÉCTRICA | G8: TERMOELÉCTRICA | H8: HIDROELÉCTRICA | I8: HIDROELÉCTRICA | J8: TERMOELÉCTRICA | K8: TERMOELÉCTRICA | L8: TERMOELÉCTRICA | M8: TERMOELÉCTRICA | N8: TERMOELÉCTRICA | O8: TERMOELÉCTRICA | P8: TERMOELÉCTRICA | Q8: TERMOELÉCTRICA | R8: HIDROELÉCTRICA | S8: HIDROELÉCTRICA | T8: TERMOELÉCTRICA | U8: TERMOELÉCTRICA | V8: TERMOELÉCTRICA | W8: TERMOELÉCTRICA | X8: HIDROELÉCTRICA | Y8: HIDROELÉCTRICA | Z8: HIDROELÉCTRICA | AA8: TERMOELÉCTRICA | AB8: HIDROELÉCTRICA | AC8: HIDROELÉCTRICA | AD8: HIDROELÉCTRICA | AE8: HIDROELÉCTRICA | AF8: TERMOELÉCTRICA | AG8: TERMOELÉCTRICA | AH8: TERMOELÉCTRICA | AI8: HIDROELÉCTRICA | AJ8: HIDROELÉCTRICA | AK8: TERMOELÉCTRICA | AL8: TERMOELÉCTRICA | AM8: TERMOELÉCTRICA | AN8: HIDROELÉCTRICA | AO8: HIDROELÉCTRICA | AP8: HIDROELÉCTRICA | AQ8: HIDROELÉCTRICA | AR8: HIDROELÉCTRICA | AS8: HIDROELÉCTRICA | AT8: HIDROELÉCTRICA | AU8: HIDROELÉCTRICA | AV8: TERMOELÉCTRICA | AW8: TERMOELÉCTRICA | AX8: TERMOELÉCTRICA | AY8: HIDROELÉCTRICA | AZ8: HIDROELÉCTRICA | BA8: HIDROELÉCTRICA | BB8: HIDROELÉCTRICA | BC8: HIDROELÉCTRICA | BD8: HIDROELÉCTRICA | BE8: HIDROELÉCTRICA | BF8: HIDROELÉCTRICA | BG8: HIDROELÉCTRICA | BH8: TERMOELÉCTRICA | BI8: TERMOELÉCTRICA | BJ8: TERMOELÉCTRICA | BK8: TERMOELÉCTRICA | BL8: TERMOELÉCTRICA | BM8: TERMOELÉCTRICA | BN8: HIDROELÉCTRICA | BO8: TERMOELÉCTRICA | BP8: TERMOELÉCTRICA | BQ8: TERMOELÉCTRICA | BR8: TERMOELÉCTRICA | BS8: TERMOELÉCTRICA | BT8: TERMOELÉCTRICA | BU8: TERMOELÉCTRICA | BV8: TERMOELÉCTRICA | BW8: TERMOELÉCTRICA | BX8: HIDROELÉCTRICA | BY8: TERMOELÉCTRICA | BZ8: TERMOELÉCTRICA | CA8: HIDROELÉCTRICA | CB8: HIDROELÉCTRICA | CC8: HIDROELÉCTRICA | CD8: HIDROELÉCTRICA | CE8: HIDROELÉCTRICA | CF8: HIDROELÉCTRICA | CG8: TERMOELÉCTRICA | CH8: TERMOELÉCTRICA | CI8: TERMOELÉCTRICA | CJ8: TERMOELÉCTRICA | CK8: TERMOELÉCTRICA | CL8: TERMOELÉCTRICA | CM8: TERMOELÉCTRICA | CN8: TERMOELÉCTRICA | CO8: TERMOELÉCTRICA | CP8: TERMOELÉCTRICA | CQ8: TERMOELÉCTRICA | CR8: TERMOELÉCTRICA | CS8: TERMOELÉCTRICA | CT8: HIDROELÉCTRICA | CU8: HIDROELÉCTRICA | CV8: HIDROELÉCTRICA | CW8: SOLAR | CX8: EÓLICA | CY8: SOLAR | CZ8: EÓLICA | DA8: SOLAR | DB8: HIDROELÉCTRICA | DC8: HIDROELÉCTRICA | DD8: HIDROELÉCTRICA | DE8: SOLAR | DF8: HIDROELÉCTRICA | DG8: HIDROELÉCTRICA | DH8: HIDROELÉCTRICA | DI8: HIDROELÉCTRICA | DJ8: HIDROELÉCTRICA | DK8: HIDROELÉCTRICA | DL8: HIDROELÉCTRICA | DM8: HIDROELÉCTRICA | DN8: SOLAR | DO8: SOLAR | DP8: EÓLICA | DQ8: EÓLICA | DR8: SOLAR | DS8: HIDROELÉCTRICA | DT8: HIDROELÉCTRICA | DU8: HIDROELÉCTRICA | DV8: HIDROELÉCTRICA | DW8: HIDROELÉCTRICA | DX8: HIDROELÉCTRICA | DY8: HIDROELÉCTRICA | DZ8: HIDROELÉCTRICA | EA8: HIDROELÉCTRICA | EB8: EÓLICA | EC8: EÓLICA | ED8: SOLAR | EE8: EÓLICA | EF8: EÓLICA | EG8: EÓLICA | EH8: EÓLICA | EI8: SOLAR | EJ8: HIDROELÉCTRICA | EK8: HIDROELÉCTRICA | EL8: HIDROELÉCTRICA | EM8: HIDROELÉCTRICA | EN8: HIDROELÉCTRICA | EO8: HIDROELÉCTRICA | EP8: EÓLICA | EQ8: SOLAR | ER8: SOLAR | ES8: SOLAR | ET8: HIDROELÉCTRICA | EU8: EÓLICA | EV8: EÓLICA | EW8: SOLAR | EX8: TERMOELÉCTRICA | EY8: TERMOELÉCTRICA | EZ8: TERMOELÉCTRICA | FA8: TERMOELÉCTRICA | FB8: SOLAR | FC8: HIDROELÉCTRICA | FD8: HIDROELÉCTRICA | FE8: TERMOELÉCTRICA | FF8: TERMOELÉCTRICA | FG8: TERMOELÉCTRICA | FH8: TERMOELÉCTRICA | FI8: TERMOELÉCTRICA | FJ8: TERMOELÉCTRICA | FK8: TERMOELÉCTRICA | FL8: TERMOELÉCTRICA | FO8: HIDROELÉCTRICA | FP8: HIDROELÉCTRICA | FQ8: HIDROELÉCTRICA | FR8: HIDROELÉCTRICA | FS8: TERMOELÉCTRICA | FT8: TERMOELÉCTRICA | FU8: HIDROELÉCTRICA | FV8: HIDROELÉCTRICA
