Workbook

Sheet EVENTOS
B3: lunes, 27 de Enero del 2025
B5: INFORMACIÓN DE EVENTOS PRINCIPALES EN SUS INSTALACIONES
B6: TIPO DE EVENTO | C6: EMPRESA | D6: UBICACIÓN | E6: TIPO DE EQUIPO | F6: EQUIPO | G6: INICIO | H6: FINAL | I6: DESCRIPCIÓN | J6: MW INDISP. | K6: INTERRUPCIÓN (SI/NO) | L6: TENSIÓN DE FALLA (kV)
B7: FALLA | C7: AGROAURORA S.A.C. | D7: MAPLE ETANOL | E7: CENTRAL TERMOELÉCTRICA | F7: CENTRAL | G7: 27/01/2025 04:38:00 | H7: 27/01/2025 22:08:00 | I7: DESCONEXIÓN DE LA TV DE LA C.T. MAPLE | K7: NO | L7: 0
B8: EVENTO | C8: CONELSUR LT SAC | D8: PORTILLO | E8: SUBESTACION | F8: SS.EE. | G8: 27/01/2025 00:00:00 | H8: 28/01/2025 00:00:00 | I8: DECLARACIÓN DE SITUACIÓN EXCEPCIONAL EN LA S.E. PORTILLO DE 60 kV | K8: NO
B9: EVENTO | C9: CONELSUR LT SAC | D9: PORTILLO | E9: SUBESTACION | F9: SS.EE. | G9: 28/01/2025 00:00:00 | H9: 28/01/2025 00:00:00 | I9: DECLARACIÓN DE SITUACIÓN EXCEPCIONAL EN LA S.E. PORTILLO DE 60 kV | K9: NO
B10: FALLA | C10: EGESUR | D10: INDEPENDENCIA | E10: GENERADOR TERMOELÉCTRICO | F10: INDEP_G1 | G10: 27/01/2025 14:43:00 | H10: 27/01/2025 15:49:00 | I10: DESCONEXIÓN DEL GENERADOR G1 DE LA C.T. INDEPENDENCIA | K10: NO | L10: 0
B11: FALLA | C11: HIDROCAÑETE S.A. | D11: NUEVA IMPERIAL | E11: CENTRAL HIDROELÉCTRICA | F11: CENTRAL | G11: 27/01/2025 01:47:26 | H11: 27/01/2025 05:42:00 | I11: DESCONEXIÓN DE LA C.H. NUEVA IMPERIAL POR FALLA EXTERNA | K11: NO | L11: 20
B12: FALLA | C12: HIDROCAÑETE S.A. | D12: NUEVA IMPERIAL | E12: CENTRAL HIDROELÉCTRICA | F12: CENTRAL | G12: 27/01/2025 19:57:36 | H12: 28/01/2025 00:00:00 | I12: DESCONEXIÓN DE LA C.H. NUEVA IMPERIAL POR FALLA EXTERNA | K12: NO | L12: 20
B13: FALLA | C13: ORYGEN PERU S.A.A. | D13: MOYOPAMPA | E13: GENERADOR HIDROELÉCTRICO | F13: G3 | G13: 27/01/2025 01:52:00 | H13: 27/01/2025 06:58:00 | I13: DESCONEXIÓN DEL GRUPO G3 DE LA C.H. MOYOPAMPA | K13: NO | L13: 9.5

Sheet RESTRIC_OPE
B3: lunes, 27 de Enero del 2025
B5: RESTRICCIONES OPERATIVAS
B6: FECHA | C6: HORA INICIO | D6: HORA FINAL | E6: EMPRESA | F6: UBICACIÓN | G6: T.Eq. | H6: EQUIPO | I6: DESCRIPCIÓN
B7: 27/01/2025 | C7: 00:00 | D7: 24:00 | E7: CELEPSA | F7: C.H. EL PLATANAL | G7: CH | H7: CENTRAL | I7: Debido al incremento del caudal del rio cañete y establecimiento de la temporada de avenida, se declara la C.H. El Platanal como CENTRAL HIDRÁULICA DE PASADA (correo 03/01/2025).
B8: 27/01/2025 | C8: 00:00 | D8: 24:00 | E8: CELEPSA | F8: C.H. EL PLATANAL | G8: CH | H8: CENTRAL | I8: Debido al incremento del caudal del rio cañete y establecimiento de la temporada de avenida, se declara la C.H. El Platanal como CENTRAL HIDRÁULICA DE PASADA (correo 03/01/2025).
B9: 27/01/2025 | C9: 00:00 | D9: 24:00 | E9: EGASA | F9: S.E. CONVERTIDOR | G9: BARRA | H9: BARRA138KV | I9: EGASA limitó la capacidad del transformador 138 kV/33 kV a 50 MVA por deterioro del aislamiento.
B10: 27/01/2025 | C10: 00:00 | D10: 24:00 | E10: EGASA | F10: S.E. CONVERTIDOR | G10: BARRA | H10: BARRA138KV | I10: EGASA limitó la capacidad del transformador 138 kV/33 kV a 50 MVA por deterioro del aislamiento.
B11: 27/01/2025 | C11: 00:00 | D11: 24:00 | E11: ENEL GENERACION PIURA S.A. | F11: C.T. MALACAS | G11: CT | H11: CENTRAL | I11: De acuerdo con la comunicación vía correo del día 24.10.2024. ENEL GENERACIÓN PIURA informa una restricción de potencia para alcanzar 105 MW en simultaneo (TG6+TGN4).
B12: 27/01/2025 | C12: 00:00 | D12: 24:00 | E12: ENEL GENERACION PIURA S.A. | F12: C.T. MALACAS | G12: CT | H12: CENTRAL | I12: De acuerdo con la comunicación vía correo del día 24.10.2024. ENEL GENERACIÓN PIURA informa una restricción de potencia para alcanzar 105 MW en simultaneo (TG6+TGN4).
B13: 27/01/2025 | C13: 00:00 | D13: 24:00 | E13: ENGIE | F13: C.E. PUNTA LOMITAS | G13: CE | H13: CENTRAL | I13: De acuerdo a la carta ENG/737-2024 (Exp:202400007555). Limitación de cables de media tensión a 100 MW de los transformadores PLT1 y PLT2 de la CE Punta Lomitas. Quedan limitados a 200 MW la generación de CE Punta Lomitas y Punta Lomitas Extensión.
B14: 27/01/2025 | C14: 00:00 | D14: 24:00 | E14: ENGIE | F14: C.E. PUNTA LOMITAS | G14: CE | H14: CENTRAL | I14: De acuerdo a la carta ENG/737-2024 (Exp:202400007555). Limitación de cables de media tensión a 100 MW de los transformadores PLT1 y PLT2 de la CE Punta Lomitas. Quedan limitados a 200 MW la generación de CE Punta Lomitas y Punta Lomitas Extensión.
B15: 27/01/2025 | C15: 00:00 | D15: 24:00 | E15: ENGIE | F15: C.H. QUITARACSA | G15: CH | H15: CENTRAL | I15: De acuerdo con el correo del 23.04 se considera la operación continua de la CH Quitaracsa debido a que el sistema de refrigeración de la CH Cañón del Pato se alimenta desde la descarga del caudal turbinado por la CH Quitaracsa.
B16: 27/01/2025 | C16: 00:00 | D16: 24:00 | E16: ENGIE | F16: C.H. QUITARACSA | G16: CH | H16: CENTRAL | I16: De acuerdo con el correo del 23.04 se considera la operación continua de la CH Quitaracsa debido a que el sistema de refrigeración de la CH Cañón del Pato se alimenta desde la descarga del caudal turbinado por la CH Quitaracsa.
B17: 27/01/2025 | C17: 00:00 | D17: 24:00 | E17: ENGIE | F17: C.H. YUNCÁN | G17: GH | H17: G3 | I17: Según la carta N° ENG/ 198-2024 enviada por su representada, se opera de forma continua el G3 de la CH Yuncán, debido a la ejecución de mantenimientos necesarios para evitar daños en los sellos de seguridad de la válvula esférica del grupo.
... B76: 27/01/2025 | C76: 00:00 | D76: 24:00 | E76: TRANSMANTARO | F76: S.E. SOCABAYA | G76: SSEE | H76: S.E. | I76: Opera en simple barra en 220 kV por indisponibilidad de la protección diferencial de barras por alarma.

Sheet MANTENIMIENTO EJECUTADOS
B3: lunes, 27 de Enero del 2025
B5: Mantenimiento Ejecutado
B6: Empresa | C6: Ubicación | D6: Equipo | E6: Inicio | F6: Final | G6: Descripción | H6: MW Indisp. | I6: Prog. | J6: Dispon | K6: Interrupc. | L6: Tipo | M6: CodEq | N6: TipoEq_Osinerg
B7: ATLANTICA TRANSMISION SUR S.A. | C7: CHILCA CTM - POROMA | D7: L-5032 | E7: 27/01/2025 08:00 | F7: 27/01/2025 16:00 | G7: INSPECCION ANUAL EN LLTT | H7: 0 | I7: P | J7: E/S | K7: N | L7: PREV. | M7: 13652 | N7: T
B8: ATLANTICA TRANSMISION SUR S.A. | C8: CHILCA-CTM | D8: INT-5261 | E8: 27/01/2025 00:00 | F8: 28/01/2025 00:00 | G8: Seccionador SBB-5261 fase S indisponible para maniobras de apertura y cierre por anomalia en tapa de tanque de compresion, el seccionador permanece cerrado y bloqueado. | H8: 0 | I8: P | J8: E/S | K8: N | L8: OTROS | M8: 13854 | N8: T
B9: ATLANTICA TRANSMISION SUR S.A. | C9: OCONA | D9: INT-5450 | E9: 27/01/2025 00:00 | F9: 28/01/2025 00:00 | G9: RESTRICCION OPERATIVA EN INTERRUPTOR INT-5450, POSICION CERRADA, REB-5450 EN SERVICIO SUMINISTRANDO LOS SS.AA. DE S.E. OCO?A | H9: 0 | I9: P | J9: E/S | K9: N | L9: OTROS | M9: 13761 | N9: T
B10: ATLANTICA TRANSMISION SUR S.A. | C10: OCONA | D10: INT-5462 | E10: 27/01/2025 00:00 | F10: 28/01/2025 00:00 | G10: Seccionador SBA-5462 fase T indisponible por problemas mecanicos, el seccionador permanece cerrado y bloqueado | H10: 0 | I10: P | J10: E/S | K10: N | L10: OTROS | M10: 13758 | N10: T
B11: ATLANTICA TRANSMISION SUR S.A. | C11: OCONA - SAN JOSE | D11: L-5036 | E11: 27/01/2025 08:00 | F11: 27/01/2025 16:00 | G11: INSPECCION ANUAL EN LLTT | H11: 0 | I11: P | J11: E/S | K11: N | L11: PREV. | M11: 14961 | N11: T
B12: ATLANTICA TRANSMISION SUR S.A. | C12: POROMA | D12: INT-5361 | E12: 27/01/2025 00:00 | F12: 28/01/2025 00:00 | G12: Seccionador SBA-5361 fase R indisponible por problemas mecanicos, el seccionador permanece cerrado y bloqueado | H12: 0 | I12: P | J12: E/S | K12: N | L12: OTROS | M12: 13746 | N12: T
B13: ATLANTICA TRANSMISION SUR S.A. | C13: POROMA | D13: REB-5350 | E13: 27/01/2025 00:00 | F13: 28/01/2025 00:00 | G13: FUERA DE SERVICIO POR FALLA EN EL EQUIPO. | H13: 0 | I13: P | J13: F/S | K13: N | L13: OTROS | M13: 13771 | N13: T
B14: ATLANTICA TRANSMISION SUR S.A. | C14: POROMA - OCONA | D14: L-5034 | E14: 27/01/2025 08:00 | F14: 27/01/2025 16:00 | G14: INSPECCION ANUAL EN LLTT | H14: 0 | I14: P | J14: E/S | K14: N | L14: PREV. | M14: 13743 | N14: T
B15: ATRIA ENERGIA S.A.C. | C15: PURMACANA | D15: G1 | E15: 27/01/2025 00:00 | F15: 28/01/2025 00:00 | G15: OVERHAUL DE TURBINA | H15: 0.7 | I15: P | J15: F/S | K15: N | L15: PREV. | M15: 13133 | N15: G
B16: CONELSUR LT SAC | C16: LOMERA | D16: BARRA A 220 kV | E16: 27/01/2025 00:00 | F16: 27/01/2025 14:45 | G16: POR REEMPLAZO DE COMPONENTES Y GAS SF6 EN CL2117. LOMERA OPERA EN BARRA SIMPLE | H16: 0 | I16: P | J16: F/S | K16: N | L16: OTROS | M16: 16951 | N16: T
B17: CONELSUR LT SAC | C17: LOMERA | D17: CL-2117 | E17: 27/01/2025 00:00 | F17: 27/01/2025 17:00 | G17: REEMPLAZO DE COMPONENTES Y GAS SF6 | H17: 0 | I17: P | J17: F/S | K17: N | L17: OTROS | M17: 14198 | N17: T
B18: CONELSUR LT SAC | C18: LOMERA | D18: BARRA A 220 kV | E18: 27/01/2025 08:00 | F18: 27/01/2025 14:45 | G18: POR REEMPLAZO DE COMPONENTES Y GAS SF6 EN CL-2117. CONEXION DE ACOMETIDA REFERENTE A LA BARRA A | H18: 0 | I18: P | J18: F/S | K18: N | L18: OTROS | M18: 16951 | N18: T
... B96: TRANSMANTARO | C96: YARABAMBA | D96: AT-104 523 | E96: 27/01/2025 00:00 | F96: 28/01/2025 00:00 | G96: NO SE TIENE MANDO REMOTO PARA CONTROLAR LOS TAPS DEL AUTOTRANSFORMADOR POR PROBLEMAS EN EL TRANSDUCTOR. LA MANIOBRA ES LOCAL Y REQUIERE AL ASISTENTE EN LA SUBESTACION PARA LAS MANIOBRAS. | H96: 0 | I96: P | J96: E/S | K96: N | L96: OTROS | M96: 17433 | N96: T

Sheet INGRESO OC
A3: lunes, 27 de Enero del 2025
A5: INGRESO A OPERACIÓN COMERCIAL
A6: EMPRESA | B6: TIPO DE EQUIPO | C6: UBICACIÓN | D6: EQUIPO | E6: Fecha y hora de Ingreso a Operación Comercial

Sheet DESPACHO_EJECUTADO
B3: lunes, 27 de Enero del 2025
A5: POTENCIA ACTIVA EJECUTADA DE LAS UNIDADES DE GENERACIÓN DEL SEIN (MW) | FI5: CENTRALES NO INTEGRANTES COES
A6: FECHA | B6: HORA | C6: 337 | D6: 338 | E6: 121 | F6: 101 | G6: 102 | H6: 42667 | I6: 42668 | J6: 126 | K6: 127 | L6: 138 | M6: 139 | N6: 197 | O6: 203 | P6: 204 | Q6: 230 | R6: 209 | S6: 56677 | T6: 796 | U6: 2146 | V6: 142 | W6: 143 | X6: 125 | Y6: 187 | Z6: 163 | AA6: 298 | AB6: 299 | AC6: 219 | AD6: 151 | AE6: 152 | AF6: 153 | AG6: 154 | AH6: 756 | AI6: 156 | AJ6: 155 | AK6: 182 | AL6: 212 | AM6: 758 | AN6: 263 | AO6: 265 | AP6: 775 | AQ6: 777 | AR6: 2154 | AS6: 150 | AT6: 149 | AU6: 188 | AV6: 2131 | AW6: 755 | AX6: 252 | AY6: 249 | AZ6: 250 | BA6: 117 | BB6: 267 | BC6: 268 | BD6: 119 | BE6: 120 | BF6: 189 | BG6: 122 | BH6: 266 | BI6: 251 | BJ6: 115 | BK6: 239 | BL6: 288 | BM6: 240 | BN6: 241 | BO6: 242 | BP6: 191 | BQ6: 194 | BR6: 196 | BS6: 207 | BT6: 236 | BU6: 795 | BV6: 285 | BW6: 995 | BX6: 996 | BY6: 997 | BZ6: 766 | CA6: 926 | CB6: 924 | CC6: 103 | CD6: 104 | CE6: 106 | CF6: 105 | CG6: 107 | CH6: 110 | CI6: 109 | CJ6: 144 | CK6: 113 | CL6: 114 | CM6: 193 | CN6: 208 | CO6: 786 | CP6: 787 | CQ6: 788 | CR6: 789 | CS6: 248 | CT6: 2159 | CU6: 303 | CV6: 59715 | CW6: 62255 | CX6: 1263 | CY6: 61800 | CZ6: 2194 | DA6: 216 | DB6: 198 | DC6: 214 | DD6: 260 | DE6: 2152 | DF6: 2128 | DG6: 247 | DH6: 228 | DI6: 2135 | DJ6: 261 | DK6: 237 | DL6: 253 | DM6: 770 | DN6: 225 | DO6: 2201 | DP6: 2171 | DQ6: 760 | DR6: 235 | DS6: 238 | DT6: 2184 | DU6: 61855 | DV6: 223 | DW6: 226 | DX6: 201 | DY6: 258 | DZ6: 259 | EA6: 920 | EB6: 257 | EC6: 256 | ED6: 2148 | EE6: 58288 | EF6: 58289 | EG6: 58839 | EH6: 58840 | EI6: 296 | EJ6: 297 | EK6: 211 | EL6: 2175 | EM6: 2178 | EN6: 2181 | EO6: 1262 | EP6: 233 | EQ6: 2150 | ER6: 2165 | ES6: 2161 | ET6: 61197 | EU6: 58851 | EV6: 234 | EW6: 215 | EX6: 917 | EY6: 289 | EZ6: 58333 | FA6: 58336 | FB6: 202 | FC6: 58487 | FD6: 213 | FE6: 232 | FF6: 2190 | FG6: TOTAL COES | FI6: 221 | FJ6: 49607 | FK6: 222 | FL6: 224 | FM6: 2187 | FN6: 227 | FO6: 49400 | FP6: 199 | FQ6: 200 | FR6: TOTAL NO COES
C7: CENTRO | D7: CENTRO | E7: NORTE | F7: CENTRO | G7: CENTRO | H7: NORTE | I7: NORTE | J7: NORTE | K7: NORTE | L7: CENTRO | M7: CENTRO | N7: CENTRO | O7: CENTRO | P7: CENTRO | Q7: CENTRO | R7: CENTRO | S7: CENTRO | T7: CENTRO | U7: CENTRO | V7: CENTRO | W7: CENTRO | X7: CENTRO | Y7: CENTRO | Z7: SUR | AA7: SUR | AB7: SUR | AC7: CENTRO | AD7: SUR | AE7: SUR | AF7: SUR | AG7: SUR | AH7: SUR | AI7: SUR | AJ7: SUR | AK7: SUR | AL7: CENTRO | AM7: NORTE | AN7: NORTE | AO7: NORTE | AP7: CENTRO | AQ7: CENTRO | AR7: CENTRO | AS7: CENTRO | AT7: CENTRO | AU7: CENTRO | AV7: CENTRO | AW7: SUR | AX7: CENTRO | AY7: CENTRO | AZ7: CENTRO | BA7: CENTRO | BB7: CENTRO | BC7: CENTRO | BD7: CENTRO | BE7: CENTRO | BF7: SUR | BG7: NORTE | BH7: CENTRO | BI7: CENTRO | BJ7: NORTE | BK7: NORTE | BL7: NORTE | BM7: SUR | BN7: SUR | BO7: SUR | BP7: CENTRO | BQ7: CENTRO | BR7: CENTRO | BS7: CENTRO | BT7: CENTRO | BU7: CENTRO | BV7: CENTRO | BW7: SUR | BX7: SUR | BY7: SUR | BZ7: NORTE | CA7: SUR | CB7: CENTRO | CC7: CENTRO | CD7: CENTRO | CE7: CENTRO | CF7: CENTRO | CG7: CENTRO | CH7: CENTRO | CI7: CENTRO | CJ7: CENTRO | CK7: CENTRO | CL7: CENTRO | CM7: CENTRO | CN7: CENTRO | CO7: SUR | CP7: SUR | CQ7: SUR | CR7: SUR | CS7: CENTRO | CT7: CENTRO | CU7: CENTRO | CV7: CENTRO | CW7: SUR | CX7: NORTE | CY7: NORTE | CZ7: NORTE | DA7: NORTE | DB7: NORTE | DC7: CENTRO | DD7: CENTRO | DE7: CENTRO | DF7: NORTE | DG7: NORTE | DH7: CENTRO | DI7: CENTRO | DJ7: SUR | DK7: SUR | DL7: CENTRO | DM7: CENTRO | DN7: CENTRO | DO7: CENTRO | DP7: CENTRO | DQ7: CENTRO | DR7: SUR | DS7: CENTRO | DT7: CENTRO | DU7: NORTE | DV7: CENTRO | DW7: CENTRO | DX7: NORTE | DY7: CENTRO | DZ7: CENTRO | EA7: CENTRO | EB7: NORTE | EC7: NORTE | ED7: SUR | EE7: CENTRO | EF7: CENTRO | EG7: CENTRO | EH7: CENTRO | EI7: CENTRO | EJ7: CENTRO | EK7: SUR | EL7: SUR | EM7: SUR | EN7: SUR | EO7: NORTE | EP7: SUR | EQ7: SUR | ER7: CENTRO | ES7: CENTRO | ET7: CENTRO | EU7: SUR | EV7: SUR | EW7: NORTE | EX7: CENTRO | EY7: NORTE | EZ7: NORTE | FA7: NORTE | FB7: CENTRO | FC7: CENTRO | FD7: CENTRO | FE7: NORTE | FF7: NORTE | FI7: NORTE | FJ7: SUR | FK7: CENTRO | FL7: NORTE | FM7: NORTE | FN7: NORTE | FO7: NORTE | FP7: NORTE | FQ7: NORTE
C8: HIDROELÉCTRICA | D8: HIDROELÉCTRICA | E8: HIDROELÉCTRICA | F8: HIDROELÉCTRICA | G8: HIDROELÉCTRICA | H8: TERMOELÉCTRICA | I8: TERMOELÉCTRICA | J8: HIDROELÉCTRICA | K8: HIDROELÉCTRICA | L8: TERMOELÉCTRICA | M8: TERMOELÉCTRICA | N8: TERMOELÉCTRICA | O8: TERMOELÉCTRICA | P8: TERMOELÉCTRICA | Q8: TERMOELÉCTRICA | R8: TERMOELÉCTRICA | S8: TERMOELÉCTRICA | T8: HIDROELÉCTRICA | U8: HIDROELÉCTRICA | V8: TERMOELÉCTRICA | W8: TERMOELÉCTRICA | X8: TERMOELÉCTRICA | Y8: TERMOELÉCTRICA | Z8: HIDROELÉCTRICA | AA8: HIDROELÉCTRICA | AB8: HIDROELÉCTRICA | AC8: TERMOELÉCTRICA | AD8: HIDROELÉCTRICA | AE8: HIDROELÉCTRICA | AF8: HIDROELÉCTRICA | AG8: HIDROELÉCTRICA | AH8: TERMOELÉCTRICA | AI8: TERMOELÉCTRICA | AJ8: TERMOELÉCTRICA | AK8: HIDROELÉCTRICA | AL8: HIDROELÉCTRICA | AM8: TERMOELÉCTRICA | AN8: TERMOELÉCTRICA | AO8: TERMOELÉCTRICA | AP8: HIDROELÉCTRICA | AQ8: HIDROELÉCTRICA | AR8: HIDROELÉCTRICA | AS8: HIDROELÉCTRICA | AT8: HIDROELÉCTRICA | AU8: HIDROELÉCTRICA | AV8: HIDROELÉCTRICA | AW8: HIDROELÉCTRICA | AX8: TERMOELÉCTRICA | AY8: TERMOELÉCTRICA | AZ8: TERMOELÉCTRICA | BA8: HIDROELÉCTRICA | BB8: HIDROELÉCTRICA | BC8: HIDROELÉCTRICA | BD8: HIDROELÉCTRICA | BE8: HIDROELÉCTRICA | BF8: HIDROELÉCTRICA | BG8: HIDROELÉCTRICA | BH8: HIDROELÉCTRICA | BI8: HIDROELÉCTRICA | BJ8: TERMOELÉCTRICA | BK8: TERMOELÉCTRICA | BL8: TERMOELÉCTRICA | BM8: TERMOELÉCTRICA | BN8: TERMOELÉCTRICA | BO8: TERMOELÉCTRICA | BP8: HIDROELÉCTRICA | BQ8: TERMOELÉCTRICA | BR8: TERMOELÉCTRICA | BS8: TERMOELÉCTRICA | BT8: TERMOELÉCTRICA | BU8: TERMOELÉCTRICA | BV8: TERMOELÉCTRICA | BW8: TERMOELÉCTRICA | BX8: TERMOELÉCTRICA | BY8: TERMOELÉCTRICA | BZ8: HIDROELÉCTRICA | CA8: TERMOELÉCTRICA | CB8: TERMOELÉCTRICA | CC8: HIDROELÉCTRICA | CD8: HIDROELÉCTRICA | CE8: HIDROELÉCTRICA | CF8: HIDROELÉCTRICA | CG8: HIDROELÉCTRICA | CH8: TERMOELÉCTRICA | CI8: TERMOELÉCTRICA | CJ8: TERMOELÉCTRICA | CK8: TERMOELÉCTRICA | CL8: TERMOELÉCTRICA | CM8: TERMOELÉCTRICA | CN8: TERMOELÉCTRICA | CO8: TERMOELÉCTRICA | CP8: TERMOELÉCTRICA | CQ8: TERMOELÉCTRICA | CR8: TERMOELÉCTRICA | CS8: TERMOELÉCTRICA | CT8: TERMOELÉCTRICA | CU8: SOLAR | CV8: EÓLICA | CW8: SOLAR | CX8: EÓLICA | CY8: SOLAR | CZ8: HIDROELÉCTRICA | DA8: HIDROELÉCTRICA | DB8: HIDROELÉCTRICA | DC8: HIDROELÉCTRICA | DD8: HIDROELÉCTRICA | DE8: HIDROELÉCTRICA | DF8: HIDROELÉCTRICA | DG8: HIDROELÉCTRICA | DH8: HIDROELÉCTRICA | DI8: HIDROELÉCTRICA | DJ8: SOLAR | DK8: SOLAR | DL8: EÓLICA | DM8: EÓLICA | DN8: TERMOELÉCTRICA | DO8: TERMOELÉCTRICA | DP8: TERMOELÉCTRICA | DQ8: TERMOELÉCTRICA | DR8: SOLAR | DS8: HIDROELÉCTRICA | DT8: HIDROELÉCTRICA | DU8: HIDROELÉCTRICA | DV8: HIDROELÉCTRICA | DW8: HIDROELÉCTRICA | DX8: HIDROELÉCTRICA | DY8: HIDROELÉCTRICA | DZ8: HIDROELÉCTRICA | EA8: HIDROELÉCTRICA | EB8: EÓLICA | EC8: EÓLICA | ED8: SOLAR | EE8: EÓLICA | EF8: EÓLICA | EG8: EÓLICA | EH8: EÓLICA | EI8: HIDROELÉCTRICA | EJ8: HIDROELÉCTRICA | EK8: HIDROELÉCTRICA | EL8: HIDROELÉCTRICA | EM8: HIDROELÉCTRICA | EN8: HIDROELÉCTRICA | EO8: EÓLICA | EP8: SOLAR | EQ8: SOLAR | ER8: HIDROELÉCTRICA | ES8: EÓLICA | ET8: EÓLICA | EU8: SOLAR | EV8: SOLAR | EW8: HIDROELÉCTRICA | EX8: HIDROELÉCTRICA | EY8: TERMOELÉCTRICA | EZ8: TERMOELÉCTRICA | FA8: TERMOELÉCTRICA | FB8: TERMOELÉCTRICA | FC8: TERMOELÉCTRICA | FD8: TERMOELÉCTRICA | FE8: TERMOELÉCTRICA | FF8: TERMOELÉCTRICA | FI8: HIDROELÉCTRICA | FJ8: HIDROELÉCTRICA | FK8: HIDROELÉCTRICA | FL8: HIDROELÉCTRICA | FM8: HIDROELÉCTRICA | FN8: TERMOELÉCTRICA | FO8: TERMOELÉCTRICA | FP8: HIDROELÉCTRICA | FQ8: HIDROELÉCTRICA
C9: CENTRALES SANTA ROSA S.A.C. | D9: CENTRALES SANTA ROSA S.A.C. | E9: INVERSIONES SHAQSHA S.A.C. | F9: ELECTROPERU | G9: ELECTROPERU | H9: ELECTROPERU | I9: ELECTROPERU | J9: ORAZUL ENERGY PERÚ | K9: ORAZUL ENERGY PERÚ | L9: TERMOSELVA | M9: TERMOSELVA | N9: KALLPA GENERACION S.A. | O9: KALLPA GENERACION S.A. | P9: KALLPA GENERACION S.A. | Q9: KALLPA GENERACION S.A. | R9: KALLPA GENERACION S.A. | S9: KALLPA GENERACION S.A. | T9: KALLPA GENERACION S.A. | U9: KALLPA GENERACION S.A. | V9: SHOUGESA | W9: SHOUGESA | X9: SHOUGESA | Y9: SHOUGESA | Z9: EGEMSA | AA9: EGESUR | AB9: EGESUR | AC9: EGESUR | AD9: EGASA | AE9: EGASA | AF9: EGASA | AG9: EGASA | AH9: EGASA | AI9: EGASA | AJ9: EGASA | AK9: SAN GABAN | AL9: CELEPSA | AM9: MINERA CERRO VERDE | AN9: PLANTA DE RESERVA FRIA DE GENERACION DE ETEN S.A. | AO9: PLANTA DE RESERVA FRIA DE GENERACION DE ETEN S.A. | AP9: EMPRESA DE GENERACION HUALLAGA | AQ9: EMPRESA DE GENERACION HUALLAGA | AR9: LA VIRGEN | AS9: CHINANGO S.A.C. | AT9: CHINANGO S.A.C. | AU9: HIDROELECTRICA HUANCHOR S.A.C. | AV9: CELEPSA RENOVABLES S.R.L. | AW9: INLAND ENERGY SAC | AX9: FENIX POWER PERÚ | AY9: FENIX POWER PERÚ | AZ9: FENIX POWER PERÚ | BA9: STATKRAFT S.A | BB9: STATKRAFT S.A | BC9: STATKRAFT S.A | BD9: STATKRAFT S.A | BE9: STATKRAFT S.A | BF9: STATKRAFT S.A | BG9: STATKRAFT S.A | BH9: STATKRAFT S.A | BI9: EMPRESA DE GENERACION HUANZA | BJ9: ENEL GENERACION PIURA S.A. | BK9: ENEL GENERACION PIURA S.A. | BL9: ENEL GENERACION PIURA S.A. | BM9: ENGIE | BN9: ENGIE | BO9: ENGIE | BP9: ENGIE | BQ9: ENGIE | BR9: ENGIE | BS9: ENGIE | BT9: ENGIE | BU9: ENGIE | BV9: ENGIE | BW9: ENGIE | BX9: ENGIE | BY9: ENGIE | BZ9: ENGIE | CA9: INFRAESTRUCTURAS Y ENERGIAS DEL PERU S.A.C. | CB9: INFRAESTRUCTURAS Y ENERGIAS DEL PERU S.A.C. | CC9: ORYGEN PERU S.A.A. | CD9: ORYGEN PERU S.A.A. | CE9: ORYGEN PERU S.A.A. | CF9: ORYGEN PERU S.A.A. | CG9: ORYGEN PERU S.A.A. | CH9: ORYGEN PERU S.A.A. | CI9: ORYGEN PERU S.A.A. | CJ9: ORYGEN PERU S.A.A. | CK9: ORYGEN PERU S.A.A. | CL9: ORYGEN PERU S.A.A. | CM9: ORYGEN PERU S.A.A. | CN9: ORYGEN PERU S.A.A. | CO9: SAMAY I S.A.C | CP9: SAMAY I S.A.C | CQ9: SAMAY I S.A.C | CR9: SAMAY I S.A.C | CS9: TERMOCHILCA S.A.C. | CT9: TERMOCHILCA S.A.C. | CU9: COLCA SOLAR S.A.C. | CV9: ENERGIA RENOVABLE DEL SUR S.A. | CW9: GR CORTARRAMA SOCIEDAD ANONIMA CERRADA | CX9: GR TARUCA SOCIEDAD ANONIMA CERRADA | CY9: KONDU SAC | CZ9: PERUANA DE INVERSIONES EN ENERGIAS RENOVABLES S.A. | DA9: ORAZUL ENERGY PERÚ | DB9: ORAZUL ENERGY PERÚ | DC9: MAJA ENERGIA S.A.C. | DD9: EMPRESA DE GENERACION ELECTRICA CANCHAYLLO SAC | DE9: EMPRESA DE GENERACION ELECTRICA SANTA ANA S.A.C. | DF9: EMPRESA ELECTRICA AGUA AZUL | DG9: EMPRESA ELECTRICA RIO DOBLE | DH9: HIDROCAÑETE S.A. | DI9: HUAURA POWER GROUP S.A. | DJ9: MOQUEGUA FV S.A.C. | DK9: PANAMERICANA SOLAR SAC. | DL9: PARQUE EOLICO MARCONA S.A.C. | DM9: PARQUE EOLICO TRES HERMANAS S.A.C. | DN9: PETRAMAS | DO9: PETRAMAS | DP9: PETRAMAS | DQ9: PETRAMAS | DR9: TACNA SOLAR SAC. | DS9: ELECTRICA YANAPAMPA SAC | DT9: ANDEAN POWER S.A.C. | DU9: ASOCIACIÓN SANTA LUCIA DE CHACAS | DV9: ATRIA ENERGIA S.A.C. | DW9: EGEJUNIN | DX9: EGEJUNIN | DY9: EGEJUNIN | DZ9: EGEJUNIN | EA9: EMPRESA DE GENERACION ELECTRICA RIO BAÑOS S.A.C. | EB9: ENERGÍA EÓLICA S.A. | EC9: ENERGÍA EÓLICA S.A. | ED9: ENGIE | EE9: ENGIE | EF9: ENGIE | EG9: ENGIE | EH9: ENGIE | EI9: GENERACIÓN ANDINA S.A.C. | EJ9: GENERACIÓN ANDINA S.A.C. | EK9: GENERADORA DE ENERGÍA DEL PERÚ | EL9: GENERADORA DE ENERGÍA DEL PERÚ | EM9: GENERADORA DE ENERGÍA DEL PERÚ | EN9: GENERADORA DE ENERGÍA DEL PERÚ | EO9: GR PAINO SOCIEDAD ANONIMA CERRADA | EP9: MAJES ARCUS S.A.C. | EQ9: ORYGEN PERU S.A.A. | ER9: ORYGEN PERU S.A.A. | ES9: ORYGEN PERU S.A.A. | ET9: ORYGEN PERU S.A.A. | EU9: ORYGEN PERU S.A.A. | EV9: REPARTICIÓN ARCUS S.A.C. | EW9: SINERSA | EX9: SINERSA | EY9: BIOENERGIA DEL CHIRA S.A. | EZ9: GM OPERACIONES S.A.C. | FA9: GM OPERACIONES S.A.C. | FB9: SDF ENERGIA SAC | FC9: SDF ENERGIA SAC | FD9: AGRO INDUSTRIAL PARAMONGA S.A. | FE9: AGROAURORA S.A.C. | FF9: AGROINDUSTRIAS SAN JACINTO S.A.A. | FI9: UNACEM PERU S.A. | FJ9: SAN GABAN | FK9: ELECTRO ORIENTE | FL9: AGUAS Y ENERGIA PERU | FM9: ELECTRO ZAÑA S.A.C. | FN9: ELECTRONOROESTE S.A. | FO9: SDE PIURA | FP9: SINERSA | FQ9: SINERSA
C10: SANTA ROSA 1 | D10: SANTA ROSA 2 | E10: PARIAC | F10: MANTARO | G10: RESTITUCION | H10: TUMBES MAK 1 | I10: TUMBES MAK 2 | J10: CARHUAQUERO | K10: CAÑON DEL PATO | L10: AGUAYTIA TG1 | M10: AGUAYTIA TG2 | N10: KALLPA TG1 | O10: KALLPA TG2 | P10: KALLPA TG3 | Q10: KALLPA TV | R10: LFLORES TG1 | S10: LFLORES TV | T10: CERRO DEL AGUILA | U10: CERRODELAGUILAG4 | V10: SHOUGESA TV1 | W10: SHOUGESA TV2 | X10: SHOUGESA TV3 | Y10: SHOUGESA CUMMINS | Z10: MACHUPICCHU | AA10: ARICOTA 1 | AB10: ARICOTA 2 | AC10: INDEPENDENCIA | AD10: CHARCANI I,II,III | AE10: CHARCANI IV | AF10: CHARCANI V | AG10: CHARCANI VI | AH10: CHILINA TG | AI10: MOLLENDO 1, 2, 3 | AJ10: CHILINA (SULZ 1,2) | AK10: SAN GABAN II | AL10: PLATANAL | AM10: RECKA | AN10: RF ETEN TG1 | AO10: RF ETEN TG2 | AP10: CHAGLLA GP1 | AQ10: CHAGLLA | AR10: LA VIRGEN | AS10: CHIMAY | AT10: YANANGO | AU10: HUANCHOR | AV10: MARAÑON | AW10: STA TERESA | AX10: FENIX GT11 | AY10: FENIX GT12 | AZ10: FENIX TV10 | BA10: YAUPI | BB10: OROYA | BC10: PACHACHACA | BD10: MALPASO | BE10: CAHUA | BF10: ARCATA | BG10: GALLITO CIEGO | BH10: CHEVES | BI10: HUANZA | BJ10: MALACAS2 TG4 | BK10: MALACAS3 TG 5 | BL10: MALACAS1 TG6 | BM10: RF ILO2 TG1 | BN10: RF ILO2 TG2 | BO10: RF ILO2 TG3 | BP10: YUNCAN | BQ10: CHILCA1 TG1 | BR10: CHILCA1 TG2 | BS10: CHILCA1 TG3 | BT10: CHILCA-TV | BU10: CHILCA2 TG41 | BV10: CHILCA2-TV | BW10: CTNEPI_TG41 | BX10: CTNEPI_TG42 | BY10: CTNEPI_TG43 | BZ10: QUITARACSA | CA10: RF PTO MALDONADO | CB10: RF PUCALLPA | CC10: HUINCO | CD10: MATUCANA | CE10: MOYOPAMPA | CF10: CALLAHUANCA | CG10: HUAMPANI | CH10: STA ROSA WEST TG7 | CI10: UTI_5 | CJ10: UTI_6 | CK10: VENTANILLA 3 | CL10: VENTANILLA 4 | CM10: VENTANILLA TV | CN10: STAROSA TG8 | CO10: PTO_BRVO TG1 | CP10: PTO_BRVO TG2 | CQ10: PTO_BRVO TG3 | CR10: PTO_BRVO TG4 | CS10: OLLEROS TG1 | CT10: OLLEROS TV | CU10: CS YARUCAYA | CV10: SAN JUAN | CW10: MATARANI | CX10: DUNA | CY10: CARHUAQUERO (CS) | CZ10: MANTA I | DA10: CARHUAQUERO4 | DB10: CAÑA BRAVA | DC10: RONCADOR | DD10: CANCHAYLLO | DE10: RENOVANDESH1 | DF10: POTRERO | DG10: PIZARRAS | DH10: NIMPERIAL | DI10: YARUCAYA | DJ10: MOQUEGUA-SOLAR | DK10: PANAMERICANA-SOLAR | DL10: PQE-EOLICO-MARCONA | DM10: PQE-EOLICO-3-HERMANAS | DN10: HUAYCOLORO | DO10: CALLAO | DP10: DONA_CATALINA | DQ10: LAGRINGAV | DR10: TACNA-SOLAR | DS10: YANAPAMPA | DT10: CARHUAC | DU10: HUALLIN | DV10: PURMACANA | DW10: HUASAHUASI | DX10: STACRUZ_1_2 | DY10: RUNATULLO_II | DZ10: RUNATULLO_III | EA10: RUCUY | EB10: PQE-EOLICO-TALARA | EC10: PQE-EOLICO-CUPISNIQUE | ED10: INTIPAMPA | EE10: PUNTA LOMITAS-BL1 | EF10: PUNTA LOMITAS-BL2 | EG10: PUN LOMITAS_EXP-BL1 | EH10: PUN LOMITAS_EXP-BL2 | EI10: 8AGOSTO | EJ10: EL CARMEN | EK10: LA JOYA | EL10: ANGEL_I | EM10: ANGEL_II | EN10: ANGEL_III | EO10: HUAMBOS | EP10: MAJES | EQ10: RUBI | ER10: CH_HER1 | ES10: WAYRA-I | ET10: WAYRA EXTENSION | EU10: CLEMESI | EV10: REPARTICION | EW10: POECHOS2 | EX10: CHANCAY | EY10: CANA BRAVA | EZ10: REFINERIA TALARA TV1 | FA10: REFINERÍA TALARA TV2 | FB10: OQUENDO TG1 | FC10: OQUENDO TV1 | FD10: PARAMONGA | FE10: MAPLE | FF10: SAN_JACINTO | FG10: MW | FI10: CARPAPATA | FJ10: TUPURI | FK10: CENTRALES ELOR | FL10: PIAS1 | FM10: ZANA | FN10: TABLAZO | FO10: TALLANCA | FP10: CURUMUY | FQ10: POECHOS1 | FR10: MW
A11: 27/01/2025 | B11: 00:30 | C11: 1.1 | D11: 1.6 | E11: 4.3 | F11: 651 | G11: 218.3 | J11: 90.1 | K11: 238.7 | N11: 108.9 | O11: 107.9 | P11: 108 | Q11: 207.5 | R11: 123 | S11: 74.4 | T11: 558.2 | U11: 10.6 | Z11: 166.2 | AA11: 8 | AB11: 2.7 | AC11: 0 | AD11: 6.5 | AF11: 66.2 | AG11: 5.3 | AK11: 111.3 | AL11: 171.9 | AP11: 6.5 | AQ11: 459.9 | AR11: 63 | AS11: 136.1 | AT11: 40.4 | AU11: 18.4 | AV11: 19.7 | AW11: 90.4 | AX11: 0 | AY11: 123 | AZ11: 73.4 | BA11: 108.9 | BB11: 7.9 | BC11: 2.5 | BD11: 39.8 | BE11: 47.5 | BF11: 3.7 | BG11: 30.5 | BH11: 127.4 | BI11: 0 | BL11: 46.8 | BP11: 131.2 | BQ11: 0 | BR11: 0 | BT11: 0 | BZ11: 86.6 | CC11: 222.3 | CD11: 123.1 | CE11: 64.8 | CF11: 81.8 | CG11: 30.3 | CH11: 0 | CK11: 103.5 | CL11: 102.5 | CM11: 120.1 | CU11: 0 | CV11: 97 | CW11: 0 | CX11: 15.1 | CY11: 0 | CZ11: 20 | DA11: 10 | DB11: 5.5 | DC11: 3.6 | DD11: 5.2 | DE11: 20.3 | DF11: 20 | DG11: 13.6 | DH11: 3.7 | DI11: 18.8 | DJ11: 0 | DK11: 0 | DL11: 29.3 | DM11: 69.2 | DN11: 4.8 | DO11: 2.3 | DP11: 2.4 | DQ11: 2.9 | DR11: 0 | DS11: 3.5 | DT11: 9.4 | DU11: 2 | DW11: 14.2 | DX11: 8.8 | DY11: 19.6 | DZ11: 20.4 | EA11: 19.9 | EB11: 18.1 | EC11: 30.4 | ED11: 0 | EE11: 19 | EF11: 49.2 | EG11: 1.4 | EH11: 1 | EI11: 21 | EJ11: 6.9 | EK11: 7.6 | EL11: 20 | EM11: 20 | EN11: 19.8 | EO11: 13.2 | EP11: 0 | EQ11: 0 | ER11: 0.6 | ES11: 14.9 | ET11: 14.5 | EU11: 0 | EV11: 0 | EW11: 7.5 | EX11: 19.9 | EY11: 10 | EZ11: 18 | FA11: 36.6 | FB11: 28.8 | FC11: 3.4 | FD11: 14 | FE11: 15.1 | FF11: 6.9 | FG11: 6413 | FI11: 24.2739 | FJ11: 1.3 | FK11: 0 | FL11: 6.11 | FM11: 8.3 | FO11: 18.9213 | FP11: 5.6 | FQ11: 4.3 | FR11: 68.8052
A12: 27/01/2025 | B12: 01:00 | C12: 1.1 | D12: 1.6 | E12: 4.3 | F12: 648.5 | G12: 218.6 | J12: 70.3 | K12: 238.8 | N12: 107.9 | O12: 108.6 | P12: 108.6 | Q12: 207.9 | R12: 120.7 | S12: 74 | T12: 558 | U12: 10.5 | Z12: 166.1 | AA12: 7.9 | AB12: 2.8 | AC12: 0 | AD12: 6.5 | AF12: 66.2 | AG12: 5.3 | AK12: 111.4 | AL12: 148.6 | AP12: 6.5 | AQ12: 459.9 | AR12: 61.8 | AS12: 133.2 | AT12: 40.2 | AU12: 18.3 | AV12: 19.7 | AW12: 94.4 | AX12: 0 | AY12: 124.5 | AZ12: 73.7 | BA12: 109.2 | BB12: 7.7 | BC12: 2.7 | BD12: 39.8 | BE12: 47.3 | BF12: 3.7 | BG12: 30.7 | BH12: 127.1 | BI12: 0 | BL12: 47 | BP12: 131.1 | BQ12: 0 | BR12: 0 | BT12: 0 | BZ12: 33.1 | CC12: 193.8 | CD12: 118 | CE12: 64.5 | CF12: 81.6 | CG12: 30.4 | CH12: 0 | CK12: 103.6 | CL12: 103.7 | CM12: 120 | CU12: 0 | CV12: 84.2 | CW12: 0 | CX12: 16 | CY12: 0 | CZ12: 20 | DA12: 9.9 | DB12: 5.4 | DC12: 3.7 | DD12: 5.2 | DE12: 20.5 | DF12: 20 | DG12: 14 | DH12: 3.7 | DI12: 18.8 | DJ12: 0 | DK12: 0 | DL12: 28.8 | DM12: 67.9 | DN12: 4.8 | DO12: 2.3 | DP12: 2.4 | DQ12: 2.9 | DR12: 0 | DS12: 3.7 | DT12: 6.3 | DU12: 2 | DW12: 16.1 | DX12: 8.8 | DY12: 19.1 | DZ12: 20.4 | EA12: 19.8 | EB12: 20.7 | EC12: 27.4 | ED12: 0 | EE12: 14.8 | EF12: 51 | EG12: 1.2 | EH12: 0.7 | EI12: 21 | EJ12: 7.1 | EK12: 7.6 | EL12: 20 | EM12: 20 | EN12: 19.8 | EO12: 13.1 | EP12: 0 | EQ12: 0 | ER12: 0.6 | ES12: 12.9 | ET12: 16 | EU12: 0 | EV12: 0 | EW12: 7.5 | EX12: 19.8 | EY12: 10.1 | EZ12: 18 | FA12: 36.3 | FB12: 28.8 | FC12: 3.4 | FD12: 14 | FE12: 15.1 | FF12: 7 | FG12: 6262 | FI12: 24.27621 | FJ12: 1.3 | FK12: 0 | FL12: 6.1115 | FM12: 8.2 | FO12: 18.92166 | FP12: 5.9 | FQ12: 4.2 | FR12: 68.90937
A13: 27/01/2025 | B13: 01:30 | C13: 1.1 | D13: 1.6 | E13: 4.3 | F13: 651.7 | G13: 219.1 | J13: 60.2 | K13: 239.9 | N13: 108 | O13: 108.1 | P13: 108.6 | Q13: 207.9 | R13: 122.2 | S13: 74.3 | T13: 561.2 | U13: 10.6 | Z13: 168.3 | AA13: 7.9 | AB13: 2.8 | AC13: 0 | AD13: 6.5 | AF13: 66.2 | AG13: 5.3 | AK13: 111.3 | AL13: 203.6 | AP13: 6.5 | AQ13: 459.7 | AR13: 61.1 | AS13: 137.8 | AT13: 40.5 | AU13: 18.3 | AV13: 19.7 | AW13: 93.2 | AX13: 0 | AY13: 123 | AZ13: 73.7 | BA13: 108.9 | BB13: 7.7 | BC13: 2.8 | BD13: 39.8 | BE13: 47.5 | BF13: 3.7 | BG13: 30.8 | BH13: 126.8 | BI13: 0 | BL13: 46.8 | BP13: 131.4 | BQ13: 0 | BR13: 0 | BT13: 0 | BZ13: 16.2 | CC13: 153.7 | CD13: 120.9 | CE13: 64.8 | CF13: 81.7 | CG13: 30.4 | CH13: 0 | CK13: 104.3 | CL13: 104.1 | CM13: 120.4 | CU13: 0 | CV13: 70.1 | CW13: 0 | CX13: 14.1 | CY13: 0 | CZ13: 20 | DA13: 9.9 | DB13: 4.7 | DC13: 3.6 | DD13: 5.1 | DE13: 20.4 | DF13: 20 | DG13: 14.1 | DH13: 3.7 | DI13: 18.8 | DJ13: 0 | DK13: 0 | DL13: 24.4 | DM13: 58.6 | DN13: 4.8 | DO13: 2.3 | DP13: 2.4 | DQ13: 2.9 | DR13: 0 | DS13: 3.7 | DT13: 6.5 | DU13: 2 | DW13: 16.1 | DX13: 8.8 | DY13: 19.3 | DZ13: 20.3 | EA13: 20 | EB13: 25.7 | EC13: 18.6 | ED13: 0 | EE13: 17.8 | EF13: 47.1 | EG13: 1.1 | EH13: 0.7 | EI13: 21 | EJ13: 7.3 | EK13: 7.6 | EL13: 20 | EM13: 20 | EN13: 19.8 | EO13: 10.6 | EP13: 0 | EQ13: 0 | ER13: 0.6 | ES13: 10.4 | ET13: 17.3 | EU13: 0 | EV13: 0 | EW13: 7.5 | EX13: 20 | EY13: 9.4 | EZ13: 17.9 | FA13: 36.5 | FB13: 28.8 | FC13: 3.4 | FD13: 13.9 | FE13: 15.1 | FF13: 7.2 | FG13: 6228.8 | FI13: 24.27525 | FJ13: 1.2 | FK13: 0 | FL13: 6.111 | FM13: 8.2 | FO13: 18.92229 | FP13: 6.5 | FQ13: 4.3 | FR13: 69.50854
A14: 27/01/2025 | B14: 02:00 | C14: 1.1 | D14: 1.6 | E14: 4.3 | F14: 650.2 | G14: 218.6 | J14: 60.3 | K14: 239.4 | N14: 108.1 | O14: 108.2 | P14: 108.9 | Q14: 208.5 | R14: 123.5 | S14: 73.7 | T14: 561.8 | U14: 10.5 | Z14: 168.2 | AA14: 7.9 | AB14: 2.7 | AC14: 0 | AD14: 6.5 | AF14: 29.6 | AG14: 5.5 | AK14: 111.1 | AL14: 193.8 | AP14: 6.5 | AQ14: 459.3 | AR14: 61.2 | AS14: 143.9 | AT14: 40.2 | AU14: 18.4 | AV14: 19.7 | AW14: 93 | AX14: 0 | AY14: 124.6 | AZ14: 74 | BA14: 108.7 | BB14: 7.7 | BC14: 2.7 | BD14: 40.1 | BE14: 47 | BF14: 3.7 | BG14: 30.3 | BH14: 126.3 | BI14: 0 | BL14: 46.9 | BP14: 131.1 | BQ14: 0 | BR14: 0 | BT14: 0 | BZ14: 16.4 | CC14: 160.5 | CD14: 126.1 | CE14: 44.4 | CF14: 82 | CG14: 30.2 | CH14: 0 | CK14: 103.8 | CL14: 103.6 | CM14: 120.7 | CU14: 0 | CV14: 72.5 | CW14: 0 | CX14: 14.1 | CY14: 0 | CZ14: 20 | DA14: 9.9 | DB14: 4.7 | DC14: 3.7 | DD14: 5.2 | DE14: 20.3 | DF14: 20 | DG14: 14 | DH14: 0 | DI14: 18.8 | DJ14: 0 | DK14: 0 | DL14: 21.3 | DM14: 52.6 | DN14: 4.8 | DO14: 2.3 | DP14: 2.4 | DQ14: 3 | DR14: 0 | DS14: 3.7 | DT14: 6.5 | DU14: 2 | DW14: 16.1 | DX14: 8.9 | DY14: 19.1 | DZ14: 20.4 | EA14: 20 | EB14: 22.7 | EC14: 16 | ED14: 0 | EE14: 27.4 | EF14: 65.1 | EG14: 2 | EH14: 1.1 | EI14: 21 | EJ14: 8.4 | EK14: 7.9 | EL14: 20 | EM14: 20 | EN14: 19.9 | EO14: 11.1 | EP14: 0 | EQ14: 0 | ER14: 0.6 | ES14: 10.5 | ET14: 16 | EU14: 0 | EV14: 0 | EW14: 7.6 | EX14: 20 | EY14: 9.4 | EZ14: 18 | FA14: 36.4 | FB14: 28.8 | FC14: 3.4 | FD14: 13 | FE14: 15.1 | FF14: 7.5 | FG14: 6192.2 | FI14: 24.27391 | FJ14: 1.2 | FK14: 0 | FL14: 6.1105 | FM14: 8 | FO14: 18.92225 | FP14: 6.9 | FQ14: 4.3 | FR14: 69.70666
A15: 27/01/2025 | B15: 02:30 | C15: 1.1 | D15: 1.6 | E15: 4.3 | F15: 647 | G15: 218.5 | J15: 60.6 | K15: 238.4 | N15: 108 | O15: 109 | P15: 108.1 | Q15: 208.4 | R15: 123 | S15: 73.7 | T15: 552.6 | U15: 10.5 | Z15: 168.8 | AA15: 8 | AB15: 2.6 | AC15: 0 | AD15: 6.7 | AF15: 30.5 | AG15: 5.9 | AK15: 111.3 | AL15: 193.7 | AP15: 6.5 | AQ15: 377.4 | AR15: 59.9 | AS15: 148 | AT15: 40.1 | AU15: 18.3 | AV15: 19.7 | AW15: 95.8 | AX15: 0 | AY15: 125.7 | AZ15: 73.3 | BA15: 108.8 | BB15: 7.7 | BC15: 2.7 | BD15: 44.3 | BE15: 47.2 | BF15: 3.7 | BG15: 30.9 | BH15: 126.8 | BI15: 0 | BL15: 46.7 | BP15: 131.3 | BQ15: 0 | BR15: 0 | BT15: 0 | BZ15: 16.5 | CC15: 112.5 | CD15: 130.2 | CE15: 44.5 | CF15: 81.5 | CG15: 30.3 | CH15: 0 | CK15: 103.7 | CL15: 103.3 | CM15: 120.1 | CU15: 0 | CV15: 85.2 | CW15: 0 | CX15: 15.2 | CY15: 0 | CZ15: 20 | DA15: 9.9 | DB15: 4.6 | DC15: 3.7 | DD15: 5.2 | DE15: 20.4 | DF15: 20 | DG15: 14.1 | DH15: 0 | DI15: 18.8 | DJ15: 0 | DK15: 0 | DL15: 26.1 | DM15: 64 | DN15: 4.8 | DO15: 2.3 | DP15: 2.4 | DQ15: 3 | DR15: 0 | DS15: 3.6 | DT15: 6.5 | DU15: 2 | DW15: 16.1 | DX15: 8.9 | DY15: 18.9 | DZ15: 20.4 | EA15: 19.9 | EB15: 22.1 | EC15: 16.1 | ED15: 0 | EE15: 22.5 | EF15: 66.5 | EG15: 1.3 | EH15: 1.1 | EI15: 21 | EJ15: 8.4 | EK15: 7.8 | EL15: 20 | EM15: 20 | EN15: 20 | EO15: 12.1 | EP15: 0 | EQ15: 0 | ER15: 0.6 | ES15: 19 | ET15: 21.5 | EU15: 0 | EV15: 0 | EW15: 7.6 | EX15: 20 | EY15: 9.3 | EZ15: 17.9 | FA15: 36.5 | FB15: 28.9 | FC15: 3.1 | FD15: 13.9 | FE15: 15.1 | FF15: 7.2 | FG15: 6105.2 | FI15: 24.27089 | FJ15: 1.2 | FK15: 0 | FL15: 6.109 | FM15: 8 | FO15: 18.9225 | FP15: 7.1 | FQ15: 4.3 | FR15: 69.90239
A16: 27/01/2025 | B16: 03:00 | C16: 1.1 | D16: 1.6 | E16: 4.3 | F16: 648 | G16: 218.5 | J16: 59.2 | K16: 239 | N16: 108.9 | O16: 109 | P16: 109.5 | Q16: 209.2 | R16: 123.2 | S16: 73.6 | T16: 561.3 | U16: 10.4 | Z16: 162.4 | AA16: 7.7 | AB16: 2.6 | AC16: 0 | AD16: 6.5 | AF16: 29.9 | AG16: 5.4 | AK16: 111.1 | AL16: 191.8 | AP16: 6.5 | AQ16: 441.8 | AR16: 61.4 | AS16: 148 | AT16: 40 | AU16: 18.3 | AV16: 19.7 | AW16: 92.5 | AX16: 0 | AY16: 122.8 | AZ16: 74.5 | BA16: 109.4 | BB16: 7.7 | BC16: 2.8 | BD16: 43.2 | BE16: 47.3 | BF16: 3.7 | BG16: 30.3 | BH16: 125.9 | BI16: 0 | BL16: 47.3 | BP16: 130.8 | BQ16: 0 | BR16: 0 | BT16: 0 | BZ16: 16 | CC16: 55.6 | CD16: 129.6 | CE16: 44.6 | CF16: 81.9 | CG16: 30.2 | CH16: 0 | CK16: 105.1 | CL16: 104.9 | CM16: 121.2 | CU16: 0 | CV16: 85.2 | CW16: 0 | CX16: 17.1 | CY16: 0 | CZ16: 20 | DA16: 9.9 | DB16: 4.7 | DC16: 3.7 | DD16: 5.2 | DE16: 20.4 | DF16: 20 | DG16: 14 | DH16: 0 | DI16: 18.8 | DJ16: 0 | DK16: 0 | DL16: 24.4 | DM16: 64.1 | DN16: 4.8 | DO16: 2.3 | DP16: 2.4 | DQ16: 3 | DR16: 0 | DS16: 3.7 | DT16: 6.5 | DU16: 2 | DW16: 16.1 | DX16: 8.9 | DY16: 18.9 | DZ16: 20.4 | EA16: 19.9 | EB16: 25.6 | EC16: 13.2 | ED16: 0 | EE16: 25.3 | EF16: 61.2 | EG16: 0.9 | EH16: 1.8 | EI16: 21 | EJ16: 8.4 | EK16: 7.7 | EL16: 20 | EM16: 20 | EN16: 20 | EO16: 13.1 | EP16: 0 | EQ16: 0 | ER16: 0.6 | ES16: 20.4 | ET16: 16.6 | EU16: 0 | EV16: 0 | EW16: 7.6 | EX16: 19.9 | EY16: 9.5 | EZ16: 18 | FA16: 36.3 | FB16: 28.9 | FC16: 3.1 | FD16: 13.7 | FE16: 15.1 | FF16: 8.1 | FG16: 6109.6 | FI16: 24.27044 | FJ16: 1.2 | FK16: 0 | FL16: 6.1105 | FM16: 8 | FO16: 18.53416 | FP16: 7.3 | FQ16: 4.2 | FR16: 69.6151
A17: 27/01/2025 | B17: 03:30 | C17: 1.1 | D17: 1.6 | E17: 4.3 | F17: 651.9 | G17: 218.9 | J17: 60.3 | K17: 240.9 | N17: 109.7 | O17: 108.8 | P17: 108.2 | Q17: 211 | R17: 123.6 | S17: 73.7 | T17: 561.8 | U17: 10.6 | Z17: 170.8 | AA17: 8.1 | AB17: 2.7 | AC17: 0 | AD17: 6.6 | AF17: 30.8 | AG17: 5.4 | AK17: 111.4 | AL17: 176.2 | AP17: 6.5 | AQ17: 466.5 | AR17: 62.5 | AS17: 136.2 | AT17: 40.5 | AU17: 18.3 | AV17: 19.7 | AW17: 94 | AX17: 0 | AY17: 124.7 | AZ17: 74.1 | BA17: 109 | BB17: 7.7 | BC17: 2.8 | BD17: 43.8 | BE17: 47.3 | BF17: 3.7 | BG17: 30.7 | BH17: 127.1 | BI17: 0 | BL17: 36.5 | BP17: 131.5 | BQ17: 0 | BR17: 0 | BT17: 0 | BZ17: 16.5 | CC17: 80.4 | CD17: 120.1 | CE17: 44.9 | CF17: 82 | CG17: 30.5 | CH17: 0 | CK17: 104.2 | CL17: 103.9 | CM17: 121.3 | CU17: 0 | CV17: 80.7 | CW17: 0 | CX17: 17 | CY17: 0 | CZ17: 20 | DA17: 9.9 | DB17: 4.7 | DC17: 3.7 | DD17: 5.2 | DE17: 20.5 | DF17: 20 | DG17: 14 | DH17: 0 | DI17: 18.8 | DJ17: 0 | DK17: 0 | DL17: 24.5 | DM17: 64.7 | DN17: 4.8 | DO17: 2.3 | DP17: 2.4 | DQ17: 3 | DR17: 0 | DS17: 3.6 | DT17: 6.5 | DU17: 2 | DW17: 16.2 | DX17: 8.9 | DY17: 18.8 | DZ17: 20.3 | EA17: 20 | EB17: 17.5 | EC17: 17.3 | ED17: 0 | EE17: 26.6 | EF17: 65.9 | EG17: 1.1 | EH17: 0.7 | EI17: 21 | EJ17: 8.4 | EK17: 7.6 | EL17: 20 | EM17: 20 | EN17: 20 | EO17: 12.4 | EP17: 0 | EQ17: 0 | ER17: 0.6 | ES17: 20.5 | ET17: 18.4 | EU17: 0 | EV17: 0 | EW17: 7.5 | EX17: 20 | EY17: 10.1 | EZ17: 17.8 | FA17: 36 | FB17: 28.9 | FC17: 3.2 | FD17: 12 | FE17: 15.1 | FF17: 7.6 | FG17: 6134 | FI17: 24.27101 | FJ17: 1.2 | FK17: 1.665 | FL17: 6.1105 | FM17: 8 | FO17: 18.75004 | FP17: 7.4 | FQ17: 4.3 | FR17: 71.69655
A18: 27/01/2025 | B18: 04:00 | C18: 1.1 | D18: 1.6 | E18: 4.3 | F18: 641.3 | G18: 218.9 | J18: 58.7 | K18: 233.3 | N18: 108.2 | O18: 107.9 | P18: 107.6 | Q18: 207 | R18: 122.1 | S18: 74.2 | T18: 553.5 | U18: 10.3 | Z18: 161.8 | AA18: 7.2 | AB18: 2.5 | AC18: 0 | AD18: 6.7 | AF18: 29.2 | AG18: 5.1 | AK18: 109.3 | AL18: 175.7 | AP18: 6.5 | AQ18: 459.1 | AR18: 63 | AS18: 119.1 | AT18: 39.1 | AU18: 18.3 | AV18: 19.7 | AW18: 90.5 | AX18: 0 | AY18: 119.2 | AZ18: 73.2 | BA18: 106.3 | BB18: 7.8 | BC18: 2.8 | BD18: 41.8 | BE18: 46.4 | BF18: 3.7 | BG18: 29.5 | BH18: 123.4 | BI18: 0 | BL18: 24.1 | BP18: 129.3 | BQ18: 0 | BR18: 0 | BT18: 0 | BZ18: 92.8 | CC18: 41.6 | CD18: 107.2 | CE18: 43.8 | CF18: 81 | CG18: 29.5 | CH18: 0 | CK18: 103.3 | CL18: 102.4 | CM18: 119.7 | CU18: 0 | CV18: 92.6 | CW18: 0 | CX18: 17 | CY18: 0 | CZ18: 20 | DA18: 10 | DB18: 4.7 | DC18: 3.7 | DD18: 5.2 | DE18: 19.8 | DF18: 20 | DG18: 14 | DH18: 0 | DI18: 18.8 | DJ18: 0 | DK18: 0 | DL18: 23.1 | DM18: 65.2 | DN18: 4.8 | DO18: 2.3 | DP18: 2.4 | DQ18: 3 | DR18: 0 | DS18: 3.6 | DT18: 6.5 | DU18: 2 | DW18: 16.2 | DX18: 8.9 | DY18: 18.6 | DZ18: 20.2 | EA18: 19.8 | EB18: 12.6 | EC18: 21.1 | ED18: 0 | EE18: 28.9 | EF18: 67.5 | EG18: 0.8 | EH18: 0.5 | EI18: 21 | EJ18: 8.4 | EK18: 7.5 | EL18: 20 | EM18: 20 | EN18: 20 | EO18: 13.8 | EP18: 0 | EQ18: 0 | ER18: 0.6 | ES18: 28.9 | ET18: 26.3 | EU18: 0 | EV18: 0 | EW18: 7.5 | EX18: 19.8 | EY18: 9.7 | EZ18: 17.9 | FA18: 35.8 | FB18: 28.9 | FC18: 3.2 | FD18: 13.8 | FE18: 14.8 | FF18: 8.8 | FG18: 6072.1 | FI18: 24.27359 | FJ18: 1.2 | FK18: 7.887 | FL18: 6.1105 | FM18: 8 | FO18: 18.9235 | FP18: 7.4 | FQ18: 4.2 | FR18: 77.99459
A19: 27/01/2025 | B19: 04:30 | C19: 1.1 | D19: 1.6 | E19: 4.3 | F19: 641.9 | G19: 217 | J19: 61.1 | K19: 236.9 | N19: 106.9 | O19: 106.6 | P19: 106.1 | Q19: 207.5 | R19: 122 | S19: 73.5 | T19: 552 | U19: 10.6 | Z19: 167.1 | AA19: 7.6 | AB19: 2.6 | AC19: 0 | AD19: 6.7 | AF19: 29.3 | AG19: 2.7 | AK19: 110.3 | AL19: 222.6 | AP19: 6.5 | AQ19: 374.1 | AR19: 63.8 | AS19: 136.4 | AT19: 40.5 | AU19: 18.3 | AV19: 19.7 | AW19: 93.8 | AX19: 0 | AY19: 121.5 | AZ19: 72 | BA19: 107.9 | BB19: 7.5 | BC19: 2.8 | BD19: 42.5 | BE19: 46.7 | BF19: 3.7 | BG19: 30 | BH19: 148.9 | BI19: 0 | BL19: 24.2 | BP19: 130.5 | BQ19: 0 | BR19: 0 | BT19: 0 | BZ19: 93.7 | CC19: 42.1 | CD19: 123 | CE19: 44.1 | CF19: 80.7 | CG19: 29.9 | CH19: 0 | CK19: 101.4 | CL19: 102.1 | CM19: 118 | CU19: 0 | CV19: 101.5 | CW19: 0 | CX19: 16.1 | CY19: 0 | CZ19: 19.9 | DA19: 9.9 | DB19: 4.7 | DC19: 3.7 | DD19: 5.2 | DE19: 19.9 | DF19: 20 | DG19: 14 | DH19: 0 | DI19: 18.8 | DJ19: 0 | DK19: 0 | DL19: 26.8 | DM19: 67.7 | DN19: 4.8 | DO19: 2.3 | DP19: 2.4 | DQ19: 3 | DR19: 0 | DS19: 3.6 | DT19: 6.5 | DU19: 2 | DW19: 16.2 | DX19: 9 | DY19: 18.6 | DZ19: 20.2 | EA19: 20 | EB19: 23.5 | EC19: 20.6 | ED19: 0 | EE19: 33.8 | EF19: 66.2 | EG19: 1.2 | EH19: 1 | EI19: 21 | EJ19: 8.4 | EK19: 7.5 | EL19: 20 | EM19: 20 | EN19: 20 | EO19: 13.2 | EP19: 0 | EQ19: 0 | ER19: 0.6 | ES19: 44.5 | ET19: 33.6 | EU19: 0 | EV19: 0 | EW19: 7.5 | EX19: 20 | EY19: 10.1 | EZ19: 17.9 | FA19: 35.9 | FB19: 28.9 | FC19: 3.1 | FD19: 13.9 | FE19: 15.1 | FF19: 8.3 | FG19: 6156.9 | FI19: 24.27018 | FJ19: 1.2 | FK19: 7.929 | FL19: 6.11 | FM19: 8 | FO19: 18.92347 | FP19: 7.6 | FQ19: 4.2 | FR19: 78.23265
A20: 27/01/2025 | B20: 05:00 | C20: 1.1 | D20: 1.6 | E20: 4.3 | F20: 644.2 | G20: 217.4 | J20: 61.6 | K20: 237.3 | N20: 107.7 | O20: 106.9 | P20: 107.7 | Q20: 206.7 | R20: 122.3 | S20: 74.8 | T20: 558.3 | U20: 10.7 | Z20: 169.7 | AA20: 7.7 | AB20: 2.7 | AC20: 0 | AD20: 6.7 | AF20: 29.7 | AG20: 4.7 | AK20: 110.8 | AL20: 223 | AP20: 6.5 | AQ20: 384.5 | AR20: 65 | AS20: 138.4 | AT20: 40.8 | AU20: 18.4 | AV20: 19.7 | AW20: 90.6 | AX20: 0 | AY20: 123.8 | AZ20: 72.9 | BA20: 109.3 | BB20: 7.5 | BC20: 2.8 | BD20: 44.8 | BE20: 47 | BF20: 3.7 | BG20: 31 | BH20: 153.9 | BI20: 0 | BL20: 24.7 | BP20: 131.1 | BQ20: 0 | BR20: 0 | BT20: 0 | BZ20: 95.4 | CC20: 53.5 | CD20: 124.7 | CE20: 44.5 | CF20: 78.4 | CG20: 30.3 | CH20: 0 | CK20: 103.1 | CL20: 103.7 | CM20: 119.3 | CU20: 0 | CV20: 97.5 | CW20: 0 | CX20: 15.9 | CY20: 0 | CZ20: 20 | DA20: 10 | DB20: 4.7 | DC20: 3.7 | DD20: 5.2 | DE20: 20.1 | DF20: 20 | DG20: 14 | DH20: 0 | DI20: 18.8 | DJ20: 0 | DK20: 0 | DL20: 29.8 | DM20: 71.1 | DN20: 4.8 | DO20: 2.3 | DP20: 2.4 | DQ20: 3 | DR20: 0 | DS20: 3.6 | DT20: 6.5 | DU20: 2 | DW20: 16.2 | DX20: 9.1 | DY20: 18.8 | DZ20: 20.3 | EA20: 19.8 | EB20: 23.1 | EC20: 16.4 | ED20: 0 | EE20: 29.9 | EF20: 68.5 | EG20: 1.9 | EH20: 1 | EI20: 21 | EJ20: 8.4 | EK20: 7.5 | EL20: 20 | EM20: 20 | EN20: 20 | EO20: 12.5 | EP20: 0 | EQ20: 0 | ER20: 0.6 | ES20: 45.2 | ET20: 35.2 | EU20: 0 | EV20: 0 | EW20: 7.5 | EX20: 19.8 | EY20: 9.8 | EZ20: 18 | FA20: 36 | FB20: 28.9 | FC20: 3.4 | FD20: 13.9 | FE20: 0 | FF20: 7.8 | FG20: 6202.8 | FI20: 24.2711 | FJ20: 1.2 | FK20: 7.937 | FL20: 6.113 | FM20: 8 | FO20: 18.92369 | FP20: 7.6 | FQ20: 4.3 | FR20: 78.34479
A21: 27/01/2025 | B21: 05:30 | C21: 1.1 | D21: 1.6 | E21: 4.3 | F21: 646.9 | G21: 218.2 | J21: 59.2 | K21: 238.2 | N21: 107.5 | O21: 107.9 | P21: 108.3 | Q21: 208.4 | R21: 121.4 | S21: 74.9 | T21: 558.6 | U21: 10.5 | Z21: 160.6 | AA21: 7.7 | AB21: 2.6 | AC21: 0 | AD21: 6.7 | AF21: 29.5 | AG21: 4.5 | AK21: 110.7 | AL21: 164.1 | AP21: 6.5 | AQ21: 465.3 | AR21: 63.2 | AS21: 137.1 | AT21: 40.9 | AU21: 18.4 | AV21: 19.7 | AW21: 88.2 | AX21: 0 | AY21: 122.5 | AZ21: 73.3 | BA21: 108.6 | BB21: 7.6 | BC21: 2.8 | BD21: 43.5 | BE21: 46.8 | BF21: 3.7 | BG21: 30.2 | BH21: 153.8 | BI21: 0 | BL21: 24.9 | BP21: 130.6 | BQ21: 0 | BR21: 0 | BT21: 0 | BZ21: 113.5 | CC21: 82.7 | CD21: 132 | CE21: 64.3 | CF21: 80 | CG21: 30.1 | CH21: 0 | CK21: 104 | CL21: 104.8 | CM21: 120.1 | CU21: 0 | CV21: 87.9 | CW21: 0 | CX21: 17 | CY21: 0 | CZ21: 20 | DA21: 9.9 | DB21: 4.7 | DC21: 3.6 | DD21: 5.1 | DE21: 20.2 | DF21: 20 | DG21: 14 | DH21: 0 | DI21: 18.8 | DJ21: 0.1 | DK21: 0 | DL21: 27.6 | DM21: 68.5 | DN21: 4.8 | DO21: 2.3 | DP21: 2.4 | DQ21: 3 | DR21: 0 | DS21: 3.6 | DT21: 6.5 | DU21: 2 | DW21: 16.3 | DX21: 9.1 | DY21: 19 | DZ21: 20.4 | EA21: 19.8 | EB21: 23.6 | EC21: 14.4 | ED21: 0 | EE21: 37.2 | EF21: 61.5 | EG21: 1.1 | EH21: 1.4 | EI21: 21 | EJ21: 8.4 | EK21: 7.9 | EL21: 20 | EM21: 20 | EN21: 20 | EO21: 13.9 | EP21: 0 | EQ21: 0 | ER21: 0.6 | ES21: 41.9 | ET21: 38.3 | EU21: 0.1 | EV21: 0 | EW21: 7.5 | EX21: 19.8 | EY21: 9.3 | EZ21: 17.8 | FA21: 35.7 | FB21: 28.9 | FC21: 3.4 | FD21: 13.9 | FE21: 0 | FF21: 8.5 | FG21: 6275.2 | FI21: 24.27324 | FJ21: 1.2 | FK21: 8.039 | FL21: 6.1145 | FM21: 8 | FO21: 18.92311 | FP21: 7.7 | FQ21: 4.3 | FR21: 78.54985
A22: 27/01/2025 | B22: 06:00 | C22: 1.1 | D22: 1.6 | E22: 4.3 | F22: 649.2 | G22: 218.7 | J22: 60.2 | K22: 239.6 | N22: 108.4 | O22: 108.8 | P22: 108.5 | Q22: 208.2 | R22: 122.7 | S22: 74.6 | T22: 560.5 | U22: 10.6 | Z22: 169.1 | AA22: 7.9 | AB22: 2.7 | AC22: 0 | AD22: 6.7 | AF22: 30.4 | AG22: 4.6 | AK22: 111.2 | AL22: 190.4 | AP22: 6.5 | AQ22: 465.9 | AR22: 63 | AS22: 133.2 | AT22: 41.2 | AU22: 18.3 | AV22: 19.7 | AW22: 91.1 | AX22: 0 | AY22: 125 | AZ22: 73.5 | BA22: 109.1 | BB22: 7.7 | BC22: 2.8 | BD22: 44.4 | BE22: 47 | BF22: 3.7 | BG22: 30.7 | BH22: 150.5 | BI22: 0 | BL22: 24.9 | BP22: 131 | BQ22: 0 | BR22: 0 | BT22: 0 | BZ22: 115.1 | CC22: 72.3 | CD22: 132.7 | CE22: 66.7 | CF22: 80.6 | CG22: 28.1 | CH22: 0 | CK22: 103.9 | CL22: 103.4 | CM22: 120.3 | CU22: 0 | CV22: 87.7 | CW22: 2.7 | CX22: 14.3 | CY22: 0 | CZ22: 20 | DA22: 9.9 | DB22: 4.7 | DC22: 3.7 | DD22: 5.1 | DE22: 20.4 | DF22: 20 | DG22: 14 | DH22: 2.1 | DI22: 18.8 | DJ22: 0.7 | DK22: 0.7 | DL22: 22.7 | DM22: 60.7 | DN22: 4.8 | DO22: 2.3 | DP22: 2.4 | DQ22: 3 | DR22: 0.1 | DS22: 3.6 | DT22: 6.3 | DU22: 2 | DW22: 15.8 | DX22: 9.3 | DY22: 19.3 | DZ22: 20.3 | EA22: 19.8 | EB22: 18 | EC22: 10.9 | ED22: 1.9 | EE22: 31 | EF22: 64.4 | EG22: 2 | EH22: 1.5 | EI22: 21 | EJ22: 8.4 | EK22: 7.9 | EL22: 20 | EM22: 20 | EN22: 20 | EO22: 11.3 | EP22: 0 | EQ22: 11.8 | ER22: 0.6 | ES22: 51.9 | ET22: 39.6 | EU22: 10.3 | EV22: 0 | EW22: 7.5 | EX22: 19.9 | EY22: 10.1 | EZ22: 18.1 | FA22: 36 | FB22: 28.9 | FC22: 3.4 | FD22: 14 | FE22: 0 | FF22: 9.3 | FG22: 6329.2 | FI22: 24.27081 | FJ22: 1.2 | FK22: 8.039 | FL22: 6.114 | FM22: 8 | FO22: 18.92243 | FP22: 7.6 | FQ22: 4.3 | FR22: 78.44624
... A58: 28/01/2025 | B58: 00:00 | C58: 1 | D58: 1.7 | E58: 4.3 | F58: 616.4 | G58: 219.1 | J58: 80 | K58: 240.9 | N58: 107.7 | O58: 107.7 | P58: 107.9 | Q58: 209.8 | R58: 168.3 | S58: 99.9 | T58: 562.1 | U58: 10.6 | Z58: 172.3 | AA58: 8.4 | AB58: 2.6 | AC58: 0 | AD58: 6.5 | AF58: 84.1 | AG58: 4.7 | AK58: 111.4 | AL58: 146.2 | AP58: 6.5 | AQ58: 460.4 | AR58: 57.9 | AS58: 138.8 | AT58: 40.7 | AU58: 18.2 | AV58: 19.7 | AW58: 94.1 | AX58: 125.4 | AY58: 126 | AZ58: 152.1 | BA58: 110 | BB58: 7.9 | BC58: 2 | BD58: 44.9 | BE58: 47.7 | BF58: 3.8 | BG58: 31.2 | BH58: 175.2 | BI58: 46.4 | BL58: 47.2 | BP58: 131.8 | BQ58: 0 | BR58: 162 | BT58: 65.2 | BZ58: 115.4 | CC58: 143.1 | CD58: 124.5 | CE58: 64.4 | CF58: 78.8 | CG58: 30.6 | CH58: 0 | CK58: 103.6 | CL58: 103.4 | CM58: 120.5 | CU58: 0 | CV58: 59.7 | CW58: 0 | CX58: 14.5 | CY58: 0 | CZ58: 20 | DA58: 9.8 | DB58: 5.4 | DC58: 3.6 | DD58: 5.1 | DE58: 20.6 | DF58: 20 | DG58: 13 | DH58: 0 | DI58: 18.8 | DJ58: 0 | DK58: 0 | DL58: 21.5 | DM58: 59.2 | DN58: 3.2 | DO58: 2.3 | DP58: 2.4 | DQ58: 2.9 | DR58: 0 | DS58: 3.5 | DT58: 17.4 | DU58: 2 | DW58: 13.3 | DX58: 9.2 | DY58: 20.4 | DZ58: 20.5 | EA58: 19.7 | EB58: 4 | EC58: 8.5 | ED58: 0 | EE58: 35.4 | EF58: 77.4 | EG58: 1.4 | EH58: 1.8 | EI58: 21 | EJ58: 8.4 | EK58: 1.1 | EL58: 20 | EM58: 20 | EN58: 20 | EO58: 12.5 | EP58: 0 | EQ58: 0 | ER58: 0.6 | ES58: 42.9 | ET58: 31.5 | EU58: 0 | EV58: 0 | EW58: 8.2 | EX58: 19.8 | EY58: 10.4 | EZ58: 0 | FA58: 37 | FB58: 28.7 | FC58: 3.2 | FD58: 12.7 | FE58: 3.4 | FF58: 8.6 | FG58: 6899.5 | FI58: 23.60828 | FJ58: 1.3 | FK58: 8.007 | FL58: 6.112 | FM58: 9 | FO58: 18.93879 | FP58: 9.4 | FQ58: 4.1 | FR58: 80.46607
A59: EJEC | C59: 24.8 | D59: 32 | E59: 102.8 | F59: 15500.3 | G59: 5256.7 | H59: 0 | I59: 0 | J59: 1908.25 | K59: 5712.2 | L59: 0 | M59: 0 | N59: 3143.25 | O59: 3170.7 | P59: 3170.5 | Q59: 5521.05 | R59: 4200.15 | S59: 2295.6 | T59: 13382.55 | U59: 252.2 | V59: 0 | W59: 0 | X59: 0 | Y59: 0 | Z59: 3979.75 | AA59: 183.55 | AB59: 62.7 | AC59: 44.4 | AD59: 158.2 | AE59: 0 | AF59: 1519 | AG59: 135.8 | AH59: 0 | AI59: 0 | AJ59: 0 | AK59: 2657.95 | AL59: 5011.1 | AM59: 0 | AN59: 0 | AO59: 0 | AP59: 155.95 | AQ59: 10889.7 | AR59: 1452.35 | AS59: 3386.1 | AT59: 975.35 | AU59: 440.75 | AV59: 472.8 | AW59: 2177.6 | AX59: 2769.2 | AY59: 3714.35 | AZ59: 3430.15 | BA59: 2610.55 | BB59: 189.95 | BC59: 59.9 | BD59: 1017.1 | BE59: 1121.95 | BF59: 90.55 | BG59: 726.55 | BH59: 3798.5 | BI59: 1219.6 | BJ59: 0 | BK59: 0 | BL59: 1035.2 | BM59: 0 | BN59: 0 | BO59: 0 | BP59: 3137.7 | BQ59: 288.6 | BR59: 631.55 | BS59: 0 | BT59: 129 | BU59: 0 | BV59: 0 | BW59: 0 | BX59: 0 | BY59: 0 | BZ59: 2411.75 | CA59: 0 | CB59: 0 | CC59: 4245.4 | CD59: 3067.4 | CE59: 1462.15 | CF59: 1931.55 | CG59: 722 | CH59: 422 | CI59: 0 | CJ59: 0 | CK59: 2971.2 | CL59: 2959.5 | CM59: 3207.2 | CN59: 0 | CO59: 0 | CP59: 0 | CQ59: 0 | CR59: 0 | CS59: 0 | CT59: 0 | CU59: 7.05 | CV59: 2038.1 | CW59: 626.35 | CX59: 360.75 | CY59: 1.8 | CZ59: 479.7 | DA59: 237.9 | DB59: 123.8 | DC59: 86.9 | DD59: 123.95 | DE59: 485.15 | DF59: 478.9 | DG59: 322.4 | DH59: 55.5 | DI59: 451.2 | DJ59: 114.85 | DK59: 144 | DL59: 560.55 | DM59: 1594.75 | DN59: 81.9 | DO59: 54.4 | DP59: 55.2 | DQ59: 64.15 | DR59: 156.1 | DS59: 86.2 | DT59: 355.5 | DU59: 48 | DV59: 0 | DW59: 356.7 | DX59: 217.45 | DY59: 478.9 | DZ59: 488.6 | EA59: 478.5 | EB59: 272.6 | EC59: 573.1 | ED59: 218.65 | EE59: 1359.35 | EF59: 1845 | EG59: 135.35 | EH59: 130.9 | EI59: 503.85 | EJ59: 197.95 | EK59: 176.95 | EL59: 480 | EM59: 480 | EN59: 479.65 | EO59: 297.7 | EP59: 124.7 | EQ59: 1020.6 | ER59: 14.4 | ES59: 1475.75 | ET59: 1431.2 | EU59: 843.5 | EV59: 106.3 | EW59: 184.9 | EX59: 478.95 | EY59: 239.7 | EZ59: 393.35 | FA59: 864.15 | FB59: 685.8 | FC59: 79.2 | FD59: 309.6 | FE59: 74.55 | FF59: 187.65 | FG59: 173627.2 | FI59: 565.10693 | FJ59: 30.3 | FK59: 144.9615 | FL59: 146.68875 | FM59: 198.1 | FN59: 0 | FO59: 453.97657 | FP59: 181.6 | FQ59: 164.45 | FR59: 1885.1837

Sheet REACTIVA
B3: lunes, 27 de Enero del 2025
A5: POTENCIA REACTIVA EJECUTADA DE LAS UNIDADES DE GENERACIÓN DEL COES (MVAR) | FH5: CENTRALES NO INTEGRANTES COES
A6: FECHA | B6: HORA | C6: 337 | D6: 338 | E6: 121 | F6: 101 | G6: 102 | H6: 42667 | I6: 42668 | J6: 126 | K6: 127 | L6: 138 | M6: 139 | N6: 197 | O6: 203 | P6: 204 | Q6: 230 | R6: 209 | S6: 56677 | T6: 796 | U6: 2146 | V6: 142 | W6: 143 | X6: 125 | Y6: 187 | Z6: 163 | AA6: 298 | AB6: 219 | AC6: 151 | AD6: 152 | AE6: 153 | AF6: 154 | AG6: 756 | AH6: 156 | AI6: 155 | AJ6: 182 | AK6: 212 | AL6: 758 | AM6: 263 | AN6: 265 | AO6: 775 | AP6: 777 | AQ6: 2154 | AR6: 150 | AS6: 149 | AT6: 188 | AU6: 2131 | AV6: 755 | AW6: 252 | AX6: 249 | AY6: 250 | AZ6: 117 | BA6: 267 | BB6: 268 | BC6: 119 | BD6: 120 | BE6: 189 | BF6: 122 | BG6: 266 | BH6: 251 | BI6: 115 | BJ6: 239 | BK6: 288 | BL6: 240 | BM6: 241 | BN6: 242 | BO6: 191 | BP6: 194 | BQ6: 196 | BR6: 207 | BS6: 236 | BT6: 795 | BU6: 285 | BV6: 995 | BW6: 996 | BX6: 997 | BY6: 766 | BZ6: 926 | CA6: 924 | CB6: 103 | CC6: 104 | CD6: 106 | CE6: 105 | CF6: 107 | CG6: 110 | CH6: 109 | CI6: 144 | CJ6: 113 | CK6: 114 | CL6: 193 | CM6: 208 | CN6: 786 | CO6: 787 | CP6: 788 | CQ6: 789 | CR6: 248 | CS6: 2159 | CT6: 303 | CU6: 59715 | CV6: 62255 | CW6: 1263 | CX6: 61800 | CY6: 2194 | CZ6: 216 | DA6: 198 | DB6: 214 | DC6: 260 | DD6: 2152 | DE6: 2128 | DF6: 247 | DG6: 228 | DH6: 2135 | DI6: 261 | DJ6: 237 | DK6: 253 | DL6: 770 | DM6: 225 | DN6: 2201 | DO6: 2171 | DP6: 760 | DQ6: 235 | DR6: 238 | DS6: 2184 | DT6: 61855 | DU6: 223 | DV6: 226 | DW6: 201 | DX6: 258 | DY6: 259 | DZ6: 920 | EA6: 257 | EB6: 256 | EC6: 2148 | ED6: 58288 | EE6: 58289 | EF6: 58839 | EG6: 58840 | EH6: 296 | EI6: 297 | EJ6: 211 | EK6: 2175 | EL6: 2178 | EM6: 2181 | EN6: 1262 | EO6: 233 | EP6: 2150 | EQ6: 2165 | ER6: 2161 | ES6: 61197 | ET6: 58851 | EU6: 234 | EV6: 215 | EW6: 917 | EX6: 289 | EY6: 58333 | EZ6: 58336 | FA6: 202 | FB6: 58487 | FC6: 213 | FD6: 232 | FE6: 2190 | FF6: TOTAL COES | FH6: 221 | FI6: 49607 | FJ6: 222 | FK6: 224 | FL6: 2187 | FM6: 227 | FN6: 49400 | FO6: 199 | FP6: 200 | FQ6: TOTAL NO COES
C7: CENTRO | D7: CENTRO | E7: NORTE | F7: CENTRO | G7: CENTRO | H7: NORTE | I7: NORTE | J7: NORTE | K7: NORTE | L7: CENTRO | M7: CENTRO | N7: CENTRO | O7: CENTRO | P7: CENTRO | Q7: CENTRO | R7: CENTRO | S7: CENTRO | T7: CENTRO | U7: CENTRO | V7: CENTRO | W7: CENTRO | X7: CENTRO | Y7: CENTRO | Z7: SUR | AA7: SUR | AB7: CENTRO | AC7: SUR | AD7: SUR | AE7: SUR | AF7: SUR | AG7: SUR | AH7: SUR | AI7: SUR | AJ7: SUR | AK7: CENTRO | AL7: NORTE | AM7: NORTE | AN7: NORTE | AO7: CENTRO | AP7: CENTRO | AQ7: CENTRO | AR7: CENTRO | AS7: CENTRO | AT7: CENTRO | AU7: CENTRO | AV7: SUR | AW7: CENTRO | AX7: CENTRO | AY7: CENTRO | AZ7: CENTRO | BA7: CENTRO | BB7: CENTRO | BC7: CENTRO | BD7: CENTRO | BE7: SUR | BF7: NORTE | BG7: CENTRO | BH7: CENTRO | BI7: NORTE | BJ7: NORTE | BK7: NORTE | BL7: SUR | BM7: SUR | BN7: SUR | BO7: CENTRO | BP7: CENTRO | BQ7: CENTRO | BR7: CENTRO | BS7: CENTRO | BT7: CENTRO | BU7: CENTRO | BV7: SUR | BW7: SUR | BX7: SUR | BY7: NORTE | BZ7: SUR | CA7: CENTRO | CB7: CENTRO | CC7: CENTRO | CD7: CENTRO | CE7: CENTRO | CF7: CENTRO | CG7: CENTRO | CH7: CENTRO | CI7: CENTRO | CJ7: CENTRO | CK7: CENTRO | CL7: CENTRO | CM7: CENTRO | CN7: SUR | CO7: SUR | CP7: SUR | CQ7: SUR | CR7: CENTRO | CS7: CENTRO | CT7: CENTRO | CU7: CENTRO | CV7: SUR | CW7: NORTE | CX7: NORTE | CY7: NORTE | CZ7: NORTE | DA7: NORTE | DB7: CENTRO | DC7: CENTRO | DD7: CENTRO | DE7: NORTE | DF7: NORTE | DG7: CENTRO | DH7: CENTRO | DI7: SUR | DJ7: SUR | DK7: CENTRO | DL7: CENTRO | DM7: CENTRO | DN7: CENTRO | DO7: CENTRO | DP7: CENTRO | DQ7: SUR | DR7: CENTRO | DS7: CENTRO | DT7: NORTE | DU7: CENTRO | DV7: CENTRO | DW7: NORTE | DX7: CENTRO | DY7: CENTRO | DZ7: CENTRO | EA7: NORTE | EB7: NORTE | EC7: SUR | ED7: CENTRO | EE7: CENTRO | EF7: CENTRO | EG7: CENTRO | EH7: CENTRO | EI7: CENTRO | EJ7: SUR | EK7: SUR | EL7: SUR | EM7: SUR | EN7: NORTE | EO7: SUR | EP7: SUR | EQ7: CENTRO | ER7: CENTRO | ES7: CENTRO | ET7: SUR | EU7: SUR | EV7: NORTE | EW7: CENTRO | EX7: NORTE | EY7: NORTE | EZ7: NORTE | FA7: CENTRO | FB7: CENTRO | FC7: CENTRO | FD7: NORTE | FE7: NORTE | FH7: NORTE | FI7: SUR | FJ7: CENTRO | FK7: NORTE | FL7: NORTE | FM7: NORTE | FN7: NORTE | FO7: NORTE | FP7: NORTE
C8: HIDROELÉCTRICA | D8: HIDROELÉCTRICA | E8: HIDROELÉCTRICA | F8: HIDROELÉCTRICA | G8: HIDROELÉCTRICA | H8: TERMOELÉCTRICA | I8: TERMOELÉCTRICA | J8: HIDROELÉCTRICA | K8: HIDROELÉCTRICA | L8: TERMOELÉCTRICA | M8: TERMOELÉCTRICA | N8: TERMOELÉCTRICA | O8: TERMOELÉCTRICA | P8: TERMOELÉCTRICA | Q8: TERMOELÉCTRICA | R8: TERMOELÉCTRICA | S8: TERMOELÉCTRICA | T8: HIDROELÉCTRICA | U8: HIDROELÉCTRICA | V8: TERMOELÉCTRICA | W8: TERMOELÉCTRICA | X8: TERMOELÉCTRICA | Y8: TERMOELÉCTRICA | Z8: HIDROELÉCTRICA | AA8: HIDROELÉCTRICA | AB8: TERMOELÉCTRICA | AC8: HIDROELÉCTRICA | AD8: HIDROELÉCTRICA | AE8: HIDROELÉCTRICA | AF8: HIDROELÉCTRICA | AG8: TERMOELÉCTRICA | AH8: TERMOELÉCTRICA | AI8: TERMOELÉCTRICA | AJ8: HIDROELÉCTRICA | AK8: HIDROELÉCTRICA | AL8: TERMOELÉCTRICA | AM8: TERMOELÉCTRICA | AN8: TERMOELÉCTRICA | AO8: HIDROELÉCTRICA | AP8: HIDROELÉCTRICA | AQ8: HIDROELÉCTRICA | AR8: HIDROELÉCTRICA | AS8: HIDROELÉCTRICA | AT8: HIDROELÉCTRICA | AU8: HIDROELÉCTRICA | AV8: HIDROELÉCTRICA | AW8: TERMOELÉCTRICA | AX8: TERMOELÉCTRICA | AY8: TERMOELÉCTRICA | AZ8: HIDROELÉCTRICA | BA8: HIDROELÉCTRICA | BB8: HIDROELÉCTRICA | BC8: HIDROELÉCTRICA | BD8: HIDROELÉCTRICA | BE8: HIDROELÉCTRICA | BF8: HIDROELÉCTRICA | BG8: HIDROELÉCTRICA | BH8: HIDROELÉCTRICA | BI8: TERMOELÉCTRICA | BJ8: TERMOELÉCTRICA | BK8: TERMOELÉCTRICA | BL8: TERMOELÉCTRICA | BM8: TERMOELÉCTRICA | BN8: TERMOELÉCTRICA | BO8: HIDROELÉCTRICA | BP8: TERMOELÉCTRICA | BQ8: TERMOELÉCTRICA | BR8: TERMOELÉCTRICA | BS8: TERMOELÉCTRICA | BT8: TERMOELÉCTRICA | BU8: TERMOELÉCTRICA | BV8: TERMOELÉCTRICA | BW8: TERMOELÉCTRICA | BX8: TERMOELÉCTRICA | BY8: HIDROELÉCTRICA | BZ8: TERMOELÉCTRICA | CA8: TERMOELÉCTRICA | CB8: HIDROELÉCTRICA | CC8: HIDROELÉCTRICA | CD8: HIDROELÉCTRICA | CE8: HIDROELÉCTRICA | CF8: HIDROELÉCTRICA | CG8: TERMOELÉCTRICA | CH8: TERMOELÉCTRICA | CI8: TERMOELÉCTRICA | CJ8: TERMOELÉCTRICA | CK8: TERMOELÉCTRICA | CL8: TERMOELÉCTRICA | CM8: TERMOELÉCTRICA | CN8: TERMOELÉCTRICA | CO8: TERMOELÉCTRICA | CP8: TERMOELÉCTRICA | CQ8: TERMOELÉCTRICA | CR8: TERMOELÉCTRICA | CS8: TERMOELÉCTRICA | CT8: SOLAR | CU8: EÓLICA | CV8: SOLAR | CW8: EÓLICA | CX8: SOLAR | CY8: HIDROELÉCTRICA | CZ8: HIDROELÉCTRICA | DA8: HIDROELÉCTRICA | DB8: HIDROELÉCTRICA | DC8: HIDROELÉCTRICA | DD8: HIDROELÉCTRICA | DE8: HIDROELÉCTRICA | DF8: HIDROELÉCTRICA | DG8: HIDROELÉCTRICA | DH8: HIDROELÉCTRICA | DI8: SOLAR | DJ8: SOLAR | DK8: EÓLICA | DL8: EÓLICA | DM8: TERMOELÉCTRICA | DN8: TERMOELÉCTRICA | DO8: TERMOELÉCTRICA | DP8: TERMOELÉCTRICA | DQ8: SOLAR | DR8: HIDROELÉCTRICA | DS8: HIDROELÉCTRICA | DT8: HIDROELÉCTRICA | DU8: HIDROELÉCTRICA | DV8: HIDROELÉCTRICA | DW8: HIDROELÉCTRICA | DX8: HIDROELÉCTRICA | DY8: HIDROELÉCTRICA | DZ8: HIDROELÉCTRICA | EA8: EÓLICA | EB8: EÓLICA | EC8: SOLAR | ED8: EÓLICA | EE8: EÓLICA | EF8: EÓLICA | EG8: EÓLICA | EH8: HIDROELÉCTRICA | EI8: HIDROELÉCTRICA | EJ8: HIDROELÉCTRICA | EK8: HIDROELÉCTRICA | EL8: HIDROELÉCTRICA | EM8: HIDROELÉCTRICA | EN8: EÓLICA | EO8: SOLAR | EP8: SOLAR | EQ8: HIDROELÉCTRICA | ER8: EÓLICA | ES8: EÓLICA | ET8: SOLAR | EU8: SOLAR | EV8: HIDROELÉCTRICA | EW8: HIDROELÉCTRICA | EX8: TERMOELÉCTRICA | EY8: TERMOELÉCTRICA | EZ8: TERMOELÉCTRICA | FA8: TERMOELÉCTRICA | FB8: TERMOELÉCTRICA | FC8: TERMOELÉCTRICA | FD8: TERMOELÉCTRICA | FE8: TERMOELÉCTRICA | FH8: HIDROELÉCTRICA | FI8: HIDROELÉCTRICA | FJ8: HIDROELÉCTRICA | FK8: HIDROELÉCTRICA | FL8: HIDROELÉCTRICA | FM8: TERMOELÉCTRICA | FN8: TERMOELÉCTRICA | FO8: HIDROELÉCTRICA | FP8: HIDROELÉCTRICA
