Workbook

Sheet EVENTOS
B3: miércoles, 4 de Marzo del 2026
B5: INFORMACIÓN DE EVENTOS PRINCIPALES EN SUS INSTALACIONES
B6: TIPO DE EVENTO | C6: EMPRESA | D6: UBICACIÓN | E6: TIPO DE EQUIPO | F6: EQUIPO | G6: INICIO | H6: FINAL | I6: DESCRIPCIÓN | J6: MW INDISP. | K6: INTERRUPCIÓN (SI/NO) | L6: TENSIÓN DE FALLA (kV)
B7: EVENTO | C7: ATLANTICA TRANSMISION SUR S.A. | D7: CHILCA CTM - POROMA | E7: LINEA DE TRANSMISION | F7: L-5032 | G7: 04/03/2026 09:31:00 | H7: 04/03/2026 09:31:00 | I7: RECIERRE EXITOSO DE LA LÍNEA L-5032 (CHILCA - POROMA) DE 500 KV, | K7: NO
B8: FALLA | C8: COMPAÑIA TRANSMISORA ANDINA S.A. | D8: HUALLANCA - HUARAZ OESTE | E8: LINEA DE TRANSMISION | F8: L-1127 | G8: 04/03/2026 15:55:04 | H8: 05/03/2026 16:02:34 | I8: DESCONEXIÓN DE LA LINEA L-1127 (HUALLANCA - HUARAZ OESTE) DE 138 KV | K8: NO | L8: 138
B9: FALLA | C9: ELECTRO DUNAS | D9: CHINCHA-INDEPENDENCIA_60 | E9: LINEA DE TRANSMISION | F9: L-6120 | G9: 04/03/2026 08:02:57 | H9: 04/03/2026 08:06:28 | I9: DESCONEXIÓN DE LA LÍNEA L-6120 (INDEPENDENCIA – CHINCHA) DE 60 KV | K9: NO | L9: 60
B10: EVENTO | C10: ELECTRO ORIENTE | D10: BELAUNDE TERRY - TARAPOTO | E10: LINEA DE TRANSMISION | F10: L-1018 | G10: 04/03/2026 18:15:00 | H10: 04/03/2026 21:08:00 | I10: DECLARACIÓN DE SITUACIÓN EXCEPCIONAL EN LA LÍNEA L-1018 (BELAUNDE TERRY - TARAPOTO) DE 138 kV | K10: NO
B11: FALLA | C11: RED DE ENERGIA DEL PERU S.A. | D11: ABANCAY NUEVA - CACHIMAYO | E11: LINEA DE TRANSMISION | F11: L-1007 | G11: 04/03/2026 22:46:00 | H11: 04/03/2026 22:46:00 | I11: RECIERRE EXITOSO DE LA LÍNEA L-1007 (ABANCAY NUEVA – CACHIMAYO) DE 138 KV | K11: NO | L11: 138
B12: EVENTO | C12: RED DE ENERGIA DEL PERU S.A. | D12: QUENCORO | E12: TRANSFORMADOR 3D | F12: T47-131 | G12: 04/03/2026 11:35:00 | H12: 04/03/2026 22:36:00 | I12: RECHAZO MANUAL DE CARGA POR SOBRECARGA DEL TRANSFORMADOR T47-131 DE 138/34,5/10,5 kV DE LA S.E. QUENCORO | J12: 0.59 | K12: SI
B13: FALLA | C13: SAN GABAN | D13: PCH TUPURI | E13: CENTRAL HIDROELÉCTRICA | F13: CENTRAL | G13: 04/03/2026 07:44:00 | H13: 04/03/2026 08:27:00 | I13: DESCONEXIÓN DEL GENERADOR G1 DE LA P.C.H. TUPURI | K13: NO | L13: 2.4
B14: FALLA | C14: STATKRAFT S.A | D14: CAHUA | E14: GENERADOR HIDROELÉCTRICO | F14: G1 | G14: 04/03/2026 19:14:33 | H14: 04/03/2026 20:41:00 | I14: DESCONEXIÓN DEL GENERADOR G1 DE LA C.H. CAHUA | K14: NO | L14: 10
B15: FALLA | C15: STATKRAFT S.A | D15: YAUPI | E15: GENERADOR HIDROELÉCTRICO | F15: G1 | G15: 04/03/2026 05:47:56 | H15: 04/03/2026 09:58:00 | I15: DESCONEXIÓN DEL GENERADOR G1 DE LA C.H. YAUPI | K15: NO | L15: 13.8

Sheet RESTRIC_OPE
B3: miércoles, 4 de Marzo del 2026
B5: RESTRICCIONES OPERATIVAS
B6: FECHA | C6: HORA INICIO | D6: HORA FINAL | E6: EMPRESA | F6: UBICACIÓN | G6: T.Eq. | H6: EQUIPO | I6: DESCRIPCIÓN
B7: 04/03/2026 | C7: 00:00 | D7: 24:00 | E7: CELEPSA | F7: C.H. EL PLATANAL | G7: CH | H7: CENTRAL | I7: De acuerdo con lo informado por CELEPSA mediante correo el dia 17.01, declaran que la CH Platanal se encontrará de pasada.
B8: 04/03/2026 | C8: 00:00 | D8: 24:00 | E8: EGASA | F8: S.E. CONVERTIDOR | G8: BARRA | H8: BARRA138KV | I8: EGASA limitó la capacidad del transformador 138 kV/33 kV a 50 MVA por deterioro del aislamiento.
B9: 04/03/2026 | C9: 00:00 | D9: 24:00 | E9: ELECTROPERU | F9: C.H. MANTARO | G9: CH | H9: CENTRAL | I9: De acuerdo con el correo del día 25.08.2025, la central tiene una limitación de potencia máxima de 650 MW por seguridad de la central.
B10: 04/03/2026 | C10: 00:00 | D10: 24:00 | E10: EMPRESA DE GENERACION HUALLAGA | F10: C.H. CHAGLLA | G10: CH | H10: CENTRAL | I10: Según lo informado el día 19/02/2026 vía correo electrónico. Se reduce la banda de regulación (RSF) para las unidades G1 y G2 a [180 - 233]. Esto debido a un incremento de vibraciones mecánicas.
B11: 04/03/2026 | C11: 00:00 | D11: 24:00 | E11: ENEL GENERACION PIURA S.A. | F11: C.T. MALACAS | G11: CT | H11: CENTRAL | I11: De acuerdo con la comunicación vía correo del día 24.10.2024. ENEL GENERACIÓN PIURA informa una restricción de potencia para alcanzar 105 MW en simultaneo (TG6+TGN4).
B12: 04/03/2026 | C12: 00:00 | D12: 24:00 | E12: ENEL GENERACION PIURA S.A. | F12: C.T. MALACAS | G12: GT | H12: TG4 | I12: De acuerdo a lo informado por correo electrónico el día 16.01, con la disponibilidad de aproximadamente 12 MMPCD (339.8Mm³) la unidad TG4 puede con una generación de 80 MW durante 4 horas, y a potencia mínima durante el resto de los periodos
B13: 04/03/2026 | C13: 00:00 | D13: 24:00 | E13: ENGIE ENERGIA PERU S.A.A. | F13: C.H. YUNCÁN | G13: GH | H13: G3 | I13: Según la carta N° ENG/ 198-2024 enviada por su representada, se opera de forma continua el G3 de la CH Yuncán, debido a la ejecución de mantenimientos necesarios para evitar daños en los sellos de seguridad de la válvula esférica del grupo.
B14: 04/03/2026 | C14: 00:00 | D14: 24:00 | E14: ENGIE ENERGIA PERU S.A.A. | F14: C.T. CHILCA 1 | G14: CT | H14: CENTRAL | I14: Restricción de temperatura de la C.T Chilca, ver valor en el modelo de despacho.
B15: 04/03/2026 | C15: 00:00 | D15: 24:00 | E15: ENGIE ENERGIA PERU S.A.A. | F15: C.T. CHILCA 1 | G15: CT | H15: CENTRAL | I15: Con carta ENG/971-2023, indica que no puede cumplir con las IO considerada en el PDO_17122023 dado que vulneran la seguridad de sus activos. Indican que se debe tomar TMO=168h.
B16: 04/03/2026 | C16: 00:00 | D16: 24:00 | E16: ENGIE ENERGIA PERU S.A.A. | F16: C.T. CHILCA 2 | G16: CT | H16: CENTRAL | I16: Con carta ENG/971-2023, indica que no puede cumplir con las IO considerada en el PDO_17122023 dado que vulneran la seguridad de sus activos. Indican que se debe tomar TMO=168h.
B17: 04/03/2026 | C17: 00:00 | D17: 24:00 | E17: FENIX POWER PERÚ | F17: C.T. FENIX | G17: CT | H17: CENTRAL | I17: De acuerdo con lo comunicado en el correo del día 06.05.2025, la CT Fenix cuenta con TMO de 168 hrs en todos sus modos de operación.
... B58: 04/03/2026 | C58: 00:00 | D58: 24:00 | E58: TERMOSELVA | F58: C.T. AGUAYTÍA | G58: CT | H58: CENTRAL | I58: Disponibilidad de 16 MMSCF para la CT Aguaytía.

Sheet MANTENIMIENTO EJECUTADOS
B3: miércoles, 4 de Marzo del 2026
B5: Mantenimiento Ejecutado
B6: Empresa | C6: Ubicación | D6: Equipo | E6: Inicio | F6: Final | G6: Descripción | H6: MW Indisp. | I6: Prog. | J6: Dispon | K6: Interrupc. | L6: Tipo | M6: CodEq | N6: TipoEq_Osinerg
B7: AGRO INDUSTRIAL PARAMONGA S.A. | C7: PARAMONGA | D7: TV-01 | E7: 04/03/2026 00:00 | F7: 04/03/2026 07:59 | G7: LIMPIEZA E INSPECCION DE LA CALDERA CBS Y MANTENIMIENTO A SUS PERIFERICOS (CONDUCTORES, VENTILADORES, BOMBAS, MOTORES, ETC) | H7: 14 | I7: P | J7: F/S | K7: N | L7: PREV. | M7: 12664 | N7: G
B8: ATLANTICA TRANSMISION SUR S.A. | C8: OCONA | D8: INT-5450 | E8: 04/03/2026 00:00 | F8: 05/03/2026 00:00 | G8: Interruptor INT-5450 cerrado con restriccion operativa, REB-5450 en servicio y suministrando los SS.AA. de la S.E. Oco?a. | H8: 0 | I8: P | J8: E/S | K8: N | L8: OTROS | M8: 13761 | N8: T
B9: ATLANTICA TRANSMISION SUR S.A. | C9: POROMA | D9: REB-5350 | E9: 04/03/2026 00:00 | F9: 05/03/2026 00:00 | G9: Fuera de servicio por falla en el equipo. | H9: 0 | I9: P | J9: F/S | K9: N | L9: OTROS | M9: 13771 | N9: T
B10: ATN S.A. | C10: KIMAN AYLLU | D10: AUT-501 | E10: 04/03/2026 00:00 | F10: 05/03/2026 00:00 | G10: Restriccion Operativa en el circuito de control de cambiador de tap s del AUT-501 | H10: 0 | I10: P | J10: E/S | K10: N | L10: OTROS | M10: 13099 | N10: T
B11: BIOENERGIA DEL CHIRA S.A. | C11: CA?A BRAVA | D11: CENTRAL | E11: 04/03/2026 00:00 | F11: 05/03/2026 00:00 | G11: La C.T. Ca?a Brava para para mentenimiento anual programado. | H11: 11.9 | I11: P | J11: F/S | K11: N | L11: PREV. | M11: 20510 | N11: G
B12: CONELSUR LT SAC | C12: CAJAMARQUILLA | D12: BARRA A 220kV | E12: 04/03/2026 00:00 | F12: 05/03/2026 00:00 | G12: NO SE PUEDE INDISPONER LA BARRA A POR RESTRICCION OPERATIVA DEL SECCIONADOR DE BARRA B DE LA CL-TR1 | H12: 0 | I12: F | J12: E/S | K12: N | L12: OTROS | M12: 1103 | N12: T
B13: CONELSUR LT SAC | C13: CAJAMARQUILLA | D13: CL-TRAFO | E13: 04/03/2026 00:00 | F13: 05/03/2026 00:00 | G13: INDISPONIBLE SECCIONADOR DE BARRA B SB-20011 DE CL-TR1 | H13: 0 | I13: F | J13: E/S | K13: N | L13: OTROS | M13: 1906 | N13: T
B14: CONELSUR LT SAC | C14: CALLAHUANCA (CNS) | D14: CL-2008 | E14: 04/03/2026 00:00 | F14: 05/03/2026 00:00 | G14: RELE DE RESPALDO INOPERATIVO | H14: 0 | I14: F | J14: E/S | K14: N | L14: OTROS | M14: 1337 | N14: T
B15: CONELSUR LT SAC | C15: CALLAHUANCA (CNS) | D15: S.E. | E15: 04/03/2026 00:00 | F15: 05/03/2026 00:00 | G15: RELE DIFERENCIAL DE BARRAS DE CALLAHUANCA 220KV INOPERATIVO | H15: 0 | I15: P | J15: E/S | K15: N | L15: OTROS | M15: 316 | N15: T
B16: CVC ENERGIA | C16: FELAM | D16: BARRA A | E16: 04/03/2026 10:00 | F16: 04/03/2026 17:00 | G16: Se realizaran pruebas de funcionamiento de la operacion en manivela; para ello, se efectuara la transferencia de carga de la barra A hacia la barra B y viceversa. El mismo dia 04/03 a las 17:00 horas, se gestionara el retorno a la topologia inicial, restableciendo la operacion en la barra A. | H16: 0 | I16: P | J16: F/S | K16: N | L16: OTROS | M16: 14754 | N16: T
B17: EGASA | C17: CHARCANI IV | D17: CENTRAL | E17: 04/03/2026 00:00 | F17: 05/03/2026 00:00 | G17: FS Fuerza Mayor, Ingreso de huayco a la central. | H17: 15 | I17: F | J17: F/S | K17: N | L17: OTROS | M17: 1198 | N17: G
B18: EGASA | C18: CHARCANI V | D18: CAMPANARIO | E18: 04/03/2026 00:00 | F18: 05/03/2026 00:00 | G18: FS por prevencion temporada de lluvias | H18: 0 | I18: P | J18: F/S | K18: N | L18: PREV. | M18: 11422 | N18: T
... B116: TRANSMANTARO | C116: YARABAMBA | D116: SS.EE. | E116: 04/03/2026 00:00 | F116: 05/03/2026 00:00 | G116: PROTECCION DIFERENCIAL DE BARRAS 87B 220 KV SE ENCUENTRA BLOQUEADO, LUEGO DE TENER UNA ACTUACION INDESEADA DURANTE EL EVENTO DEL 11.01.2026. | H116: 0 | I116: P | J116: E/S | K116: N | L116: OTROS | M116: 17419 | N116: T

Sheet INGRESO OC
A3: miércoles, 4 de Marzo del 2026
A5: INGRESO A OPERACIÓN COMERCIAL
A6: EMPRESA | B6: TIPO DE EQUIPO | C6: UBICACIÓN | D6: EQUIPO | E6: Fecha y hora de Ingreso a Operación Comercial

Sheet DESPACHO_EJECUTADO
B3: miércoles, 4 de Marzo del 2026
A5: POTENCIA ACTIVA EJECUTADA DE LAS UNIDADES DE GENERACIÓN DEL SEIN (MW) | FQ5: CENTRALES NO INTEGRANTES COES
A6: FECHA | B6: HORA | C6: 65333 | D6: 101 | E6: 102 | F6: 42667 | G6: 42668 | H6: 126 | I6: 127 | J6: 138 | K6: 139 | L6: 197 | M6: 203 | N6: 204 | O6: 230 | P6: 209 | Q6: 56677 | R6: 796 | S6: 2146 | T6: 142 | U6: 143 | V6: 125 | W6: 187 | X6: 163 | Y6: 298 | Z6: 299 | AA6: 219 | AB6: 151 | AC6: 152 | AD6: 153 | AE6: 154 | AF6: 756 | AG6: 156 | AH6: 155 | AI6: 182 | AJ6: 212 | AK6: 758 | AL6: 263 | AM6: 265 | AN6: 775 | AO6: 777 | AP6: 2154 | AQ6: 150 | AR6: 149 | AS6: 188 | AT6: 2131 | AU6: 755 | AV6: 252 | AW6: 249 | AX6: 250 | AY6: 117 | AZ6: 119 | BA6: 120 | BB6: 189 | BC6: 122 | BD6: 266 | BE6: 337 | BF6: 338 | BG6: 251 | BH6: 115 | BI6: 239 | BJ6: 288 | BK6: 240 | BL6: 241 | BM6: 242 | BN6: 191 | BO6: 194 | BP6: 196 | BQ6: 207 | BR6: 236 | BS6: 795 | BT6: 285 | BU6: 995 | BV6: 996 | BW6: 997 | BX6: 766 | BY6: 926 | BZ6: 924 | CA6: 121 | CB6: 103 | CC6: 104 | CD6: 106 | CE6: 105 | CF6: 107 | CG6: 110 | CH6: 109 | CI6: 144 | CJ6: 113 | CK6: 114 | CL6: 193 | CM6: 208 | CN6: 786 | CO6: 787 | CP6: 788 | CQ6: 789 | CR6: 248 | CS6: 2159 | CT6: 267 | CU6: 268 | CV6: 2194 | CW6: 303 | CX6: 59715 | CY6: 62255 | CZ6: 1263 | DA6: 61800 | DB6: 69125 | DC6: 216 | DD6: 198 | DE6: 70400 | DF6: 76068 | DG6: 49607 | DH6: 214 | DI6: 260 | DJ6: 2152 | DK6: 2128 | DL6: 247 | DM6: 228 | DN6: 2135 | DO6: 261 | DP6: 237 | DQ6: 253 | DR6: 770 | DS6: 235 | DT6: 238 | DU6: 2184 | DV6: 61855 | DW6: 223 | DX6: 75566 | DY6: 226 | DZ6: 201 | EA6: 258 | EB6: 259 | EC6: 257 | ED6: 256 | EE6: 2148 | EF6: 58288 | EG6: 58289 | EH6: 58839 | EI6: 58840 | EJ6: 75260 | EK6: 296 | EL6: 297 | EM6: 211 | EN6: 2175 | EO6: 2178 | EP6: 2181 | EQ6: 1262 | ER6: 63425 | ES6: 233 | ET6: 2150 | EU6: 2165 | EV6: 2161 | EW6: 61197 | EX6: 58851 | EY6: 225 | EZ6: 2201 | FA6: 2171 | FB6: 760 | FC6: 234 | FD6: 215 | FE6: 917 | FF6: 920 | FG6: 289 | FH6: 58333 | FI6: 58336 | FJ6: 213 | FK6: 232 | FL6: 2190 | FM6: 69867 | FN6: 75066 | FO6: TOTAL COES | FQ6: 221 | FR6: 222 | FS6: 224 | FT6: 2187 | FU6: 227 | FV6: 49400 | FW6: 199 | FX6: 200 | FY6: TOTAL NO COES
C7: SUR | D7: CENTRO | E7: CENTRO | F7: NORTE | G7: NORTE | H7: NORTE | I7: NORTE | J7: CENTRO | K7: CENTRO | L7: CENTRO | M7: CENTRO | N7: CENTRO | O7: CENTRO | P7: CENTRO | Q7: CENTRO | R7: CENTRO | S7: CENTRO | T7: CENTRO | U7: CENTRO | V7: CENTRO | W7: CENTRO | X7: SUR | Y7: SUR | Z7: SUR | AA7: CENTRO | AB7: SUR | AC7: SUR | AD7: SUR | AE7: SUR | AF7: SUR | AG7: SUR | AH7: SUR | AI7: SUR | AJ7: CENTRO | AK7: NORTE | AL7: NORTE | AM7: NORTE | AN7: CENTRO | AO7: CENTRO | AP7: CENTRO | AQ7: CENTRO | AR7: CENTRO | AS7: CENTRO | AT7: CENTRO | AU7: SUR | AV7: CENTRO | AW7: CENTRO | AX7: CENTRO | AY7: CENTRO | AZ7: CENTRO | BA7: CENTRO | BB7: SUR | BC7: NORTE | BD7: CENTRO | BE7: CENTRO | BF7: CENTRO | BG7: CENTRO | BH7: NORTE | BI7: NORTE | BJ7: NORTE | BK7: SUR | BL7: SUR | BM7: SUR | BN7: CENTRO | BO7: CENTRO | BP7: CENTRO | BQ7: CENTRO | BR7: CENTRO | BS7: CENTRO | BT7: CENTRO | BU7: SUR | BV7: SUR | BW7: SUR | BX7: NORTE | BY7: SUR | BZ7: CENTRO | CA7: NORTE | CB7: CENTRO | CC7: CENTRO | CD7: CENTRO | CE7: CENTRO | CF7: CENTRO | CG7: CENTRO | CH7: CENTRO | CI7: CENTRO | CJ7: CENTRO | CK7: CENTRO | CL7: CENTRO | CM7: CENTRO | CN7: SUR | CO7: SUR | CP7: SUR | CQ7: SUR | CR7: CENTRO | CS7: CENTRO | CT7: CENTRO | CU7: CENTRO | CV7: NORTE | CW7: CENTRO | CX7: CENTRO | CY7: SUR | CZ7: NORTE | DA7: NORTE | DB7: CENTRO | DC7: NORTE | DD7: NORTE | DE7: SUR | DF7: SUR | DG7: SUR | DH7: CENTRO | DI7: CENTRO | DJ7: CENTRO | DK7: NORTE | DL7: NORTE | DM7: CENTRO | DN7: CENTRO | DO7: SUR | DP7: SUR | DQ7: CENTRO | DR7: CENTRO | DS7: SUR | DT7: CENTRO | DU7: CENTRO | DV7: NORTE | DW7: CENTRO | DX7: CENTRO | DY7: CENTRO | DZ7: NORTE | EA7: CENTRO | EB7: CENTRO | EC7: NORTE | ED7: NORTE | EE7: SUR | EF7: CENTRO | EG7: CENTRO | EH7: CENTRO | EI7: CENTRO | EJ7: SUR | EK7: CENTRO | EL7: CENTRO | EM7: SUR | EN7: SUR | EO7: SUR | EP7: SUR | EQ7: NORTE | ER7: SUR | ES7: SUR | ET7: SUR | EU7: CENTRO | EV7: CENTRO | EW7: CENTRO | EX7: SUR | EY7: CENTRO | EZ7: CENTRO | FA7: CENTRO | FB7: CENTRO | FC7: SUR | FD7: NORTE | FE7: CENTRO | FF7: CENTRO | FG7: NORTE | FH7: NORTE | FI7: NORTE | FJ7: CENTRO | FK7: NORTE | FL7: NORTE | FM7: NORTE | FN7: NORTE | FQ7: NORTE | FR7: CENTRO | FS7: NORTE | FT7: NORTE | FU7: NORTE | FV7: NORTE | FW7: NORTE | FX7: NORTE
C8: HIDROELÉCTRICA | D8: HIDROELÉCTRICA | E8: HIDROELÉCTRICA | F8: TERMOELÉCTRICA | G8: TERMOELÉCTRICA | H8: HIDROELÉCTRICA | I8: HIDROELÉCTRICA | J8: TERMOELÉCTRICA | K8: TERMOELÉCTRICA | L8: TERMOELÉCTRICA | M8: TERMOELÉCTRICA | N8: TERMOELÉCTRICA | O8: TERMOELÉCTRICA | P8: TERMOELÉCTRICA | Q8: TERMOELÉCTRICA | R8: HIDROELÉCTRICA | S8: HIDROELÉCTRICA | T8: TERMOELÉCTRICA | U8: TERMOELÉCTRICA | V8: TERMOELÉCTRICA | W8: TERMOELÉCTRICA | X8: HIDROELÉCTRICA | Y8: HIDROELÉCTRICA | Z8: HIDROELÉCTRICA | AA8: TERMOELÉCTRICA | AB8: HIDROELÉCTRICA | AC8: HIDROELÉCTRICA | AD8: HIDROELÉCTRICA | AE8: HIDROELÉCTRICA | AF8: TERMOELÉCTRICA | AG8: TERMOELÉCTRICA | AH8: TERMOELÉCTRICA | AI8: HIDROELÉCTRICA | AJ8: HIDROELÉCTRICA | AK8: TERMOELÉCTRICA | AL8: TERMOELÉCTRICA | AM8: TERMOELÉCTRICA | AN8: HIDROELÉCTRICA | AO8: HIDROELÉCTRICA | AP8: HIDROELÉCTRICA | AQ8: HIDROELÉCTRICA | AR8: HIDROELÉCTRICA | AS8: HIDROELÉCTRICA | AT8: HIDROELÉCTRICA | AU8: HIDROELÉCTRICA | AV8: TERMOELÉCTRICA | AW8: TERMOELÉCTRICA | AX8: TERMOELÉCTRICA | AY8: HIDROELÉCTRICA | AZ8: HIDROELÉCTRICA | BA8: HIDROELÉCTRICA | BB8: HIDROELÉCTRICA | BC8: HIDROELÉCTRICA | BD8: HIDROELÉCTRICA | BE8: HIDROELÉCTRICA | BF8: HIDROELÉCTRICA | BG8: HIDROELÉCTRICA | BH8: TERMOELÉCTRICA | BI8: TERMOELÉCTRICA | BJ8: TERMOELÉCTRICA | BK8: TERMOELÉCTRICA | BL8: TERMOELÉCTRICA | BM8: TERMOELÉCTRICA | BN8: HIDROELÉCTRICA | BO8: TERMOELÉCTRICA | BP8: TERMOELÉCTRICA | BQ8: TERMOELÉCTRICA | BR8: TERMOELÉCTRICA | BS8: TERMOELÉCTRICA | BT8: TERMOELÉCTRICA | BU8: TERMOELÉCTRICA | BV8: TERMOELÉCTRICA | BW8: TERMOELÉCTRICA | BX8: HIDROELÉCTRICA | BY8: TERMOELÉCTRICA | BZ8: TERMOELÉCTRICA | CA8: HIDROELÉCTRICA | CB8: HIDROELÉCTRICA | CC8: HIDROELÉCTRICA | CD8: HIDROELÉCTRICA | CE8: HIDROELÉCTRICA | CF8: HIDROELÉCTRICA | CG8: TERMOELÉCTRICA | CH8: TERMOELÉCTRICA | CI8: TERMOELÉCTRICA | CJ8: TERMOELÉCTRICA | CK8: TERMOELÉCTRICA | CL8: TERMOELÉCTRICA | CM8: TERMOELÉCTRICA | CN8: TERMOELÉCTRICA | CO8: TERMOELÉCTRICA | CP8: TERMOELÉCTRICA | CQ8: TERMOELÉCTRICA | CR8: TERMOELÉCTRICA | CS8: TERMOELÉCTRICA | CT8: HIDROELÉCTRICA | CU8: HIDROELÉCTRICA | CV8: HIDROELÉCTRICA | CW8: SOLAR | CX8: EÓLICA | CY8: SOLAR | CZ8: EÓLICA | DA8: SOLAR | DB8: HIDROELÉCTRICA | DC8: HIDROELÉCTRICA | DD8: HIDROELÉCTRICA | DE8: SOLAR | DF8: SOLAR | DG8: HIDROELÉCTRICA | DH8: HIDROELÉCTRICA | DI8: HIDROELÉCTRICA | DJ8: HIDROELÉCTRICA | DK8: HIDROELÉCTRICA | DL8: HIDROELÉCTRICA | DM8: HIDROELÉCTRICA | DN8: HIDROELÉCTRICA | DO8: SOLAR | DP8: SOLAR | DQ8: EÓLICA | DR8: EÓLICA | DS8: SOLAR | DT8: HIDROELÉCTRICA | DU8: HIDROELÉCTRICA | DV8: HIDROELÉCTRICA | DW8: HIDROELÉCTRICA | DX8: SOLAR | DY8: HIDROELÉCTRICA | DZ8: HIDROELÉCTRICA | EA8: HIDROELÉCTRICA | EB8: HIDROELÉCTRICA | EC8: EÓLICA | ED8: EÓLICA | EE8: SOLAR | EF8: EÓLICA | EG8: EÓLICA | EH8: EÓLICA | EI8: EÓLICA | EJ8: SOLAR | EK8: HIDROELÉCTRICA | EL8: HIDROELÉCTRICA | EM8: HIDROELÉCTRICA | EN8: HIDROELÉCTRICA | EO8: HIDROELÉCTRICA | EP8: HIDROELÉCTRICA | EQ8: EÓLICA | ER8: SOLAR | ES8: SOLAR | ET8: SOLAR | EU8: HIDROELÉCTRICA | EV8: EÓLICA | EW8: EÓLICA | EX8: SOLAR | EY8: TERMOELÉCTRICA | EZ8: TERMOELÉCTRICA | FA8: TERMOELÉCTRICA | FB8: TERMOELÉCTRICA | FC8: SOLAR | FD8: HIDROELÉCTRICA | FE8: HIDROELÉCTRICA | FF8: HIDROELÉCTRICA | FG8: TERMOELÉCTRICA | FH8: TERMOELÉCTRICA | FI8: TERMOELÉCTRICA | FJ8: TERMOELÉCTRICA | FK8: TERMOELÉCTRICA | FL8: TERMOELÉCTRICA | FM8: TERMOELÉCTRICA | FN8: TERMOELÉCTRICA | FQ8: HIDROELÉCTRICA | FR8: HIDROELÉCTRICA | FS8: HIDROELÉCTRICA | FT8: HIDROELÉCTRICA | FU8: TERMOELÉCTRICA | FV8: TERMOELÉCTRICA | FW8: HIDROELÉCTRICA | FX8: HIDROELÉCTRICA
C9: HYDRO GLOBAL PERÚ S.A.C. | D9: ELECTROPERU | E9: ELECTROPERU | F9: ELECTROPERU | G9: ELECTROPERU | H9: ORAZUL ENERGY PERÚ | I9: ORAZUL ENERGY PERÚ | J9: TERMOSELVA | K9: TERMOSELVA | L9: KALLPA GENERACION S.A. | M9: KALLPA GENERACION S.A. | N9: KALLPA GENERACION S.A. | O9: KALLPA GENERACION S.A. | P9: KALLPA GENERACION S.A. | Q9: KALLPA GENERACION S.A. | R9: KALLPA GENERACION S.A. | S9: KALLPA GENERACION S.A. | T9: SHOUGESA | U9: SHOUGESA | V9: SHOUGESA | W9: SHOUGESA | X9: EGEMSA | Y9: EGESUR | Z9: EGESUR | AA9: EGESUR | AB9: EGASA | AC9: EGASA | AD9: EGASA | AE9: EGASA | AF9: EGASA | AG9: EGASA | AH9: EGASA | AI9: SAN GABAN | AJ9: CELEPSA | AK9: MINERA CERRO VERDE | AL9: PLANTA DE RESERVA FRIA DE GENERACION DE ETEN S.A. | AM9: PLANTA DE RESERVA FRIA DE GENERACION DE ETEN S.A. | AN9: EMPRESA DE GENERACION HUALLAGA | AO9: EMPRESA DE GENERACION HUALLAGA | AP9: LA VIRGEN | AQ9: CHINANGO S.A.C. | AR9: CHINANGO S.A.C. | AS9: HIDROELECTRICA HUANCHOR S.A.C. | AT9: CELEPSA RENOVABLES S.R.L. | AU9: INLAND ENERGY SAC | AV9: FENIX POWER PERÚ | AW9: FENIX POWER PERÚ | AX9: FENIX POWER PERÚ | AY9: STATKRAFT S.A | AZ9: STATKRAFT S.A | BA9: STATKRAFT S.A | BB9: STATKRAFT S.A | BC9: STATKRAFT S.A | BD9: STATKRAFT S.A | BE9: CENTRALES SANTA ROSA S.A.C. | BF9: CENTRALES SANTA ROSA S.A.C. | BG9: EMPRESA DE GENERACION HUANZA | BH9: ENEL GENERACION PIURA S.A. | BI9: ENEL GENERACION PIURA S.A. | BJ9: ENEL GENERACION PIURA S.A. | BK9: ENGIE ENERGIA PERU S.A.A. | BL9: ENGIE ENERGIA PERU S.A.A. | BM9: ENGIE ENERGIA PERU S.A.A. | BN9: ENGIE ENERGIA PERU S.A.A. | BO9: ENGIE ENERGIA PERU S.A.A. | BP9: ENGIE ENERGIA PERU S.A.A. | BQ9: ENGIE ENERGIA PERU S.A.A. | BR9: ENGIE ENERGIA PERU S.A.A. | BS9: ENGIE ENERGIA PERU S.A.A. | BT9: ENGIE ENERGIA PERU S.A.A. | BU9: ENGIE ENERGIA PERU S.A.A. | BV9: ENGIE ENERGIA PERU S.A.A. | BW9: ENGIE ENERGIA PERU S.A.A. | BX9: ENGIE ENERGIA PERU S.A.A. | BY9: INFRAESTRUCTURAS Y ENERGIAS DEL PERU S.A.C. | BZ9: INFRAESTRUCTURAS Y ENERGIAS DEL PERU S.A.C. | CA9: INVERSIONES SHAQSHA S.A.C. | CB9: ORYGEN PERU S.A.A. | CC9: ORYGEN PERU S.A.A. | CD9: ORYGEN PERU S.A.A. | CE9: ORYGEN PERU S.A.A. | CF9: ORYGEN PERU S.A.A. | CG9: ORYGEN PERU S.A.A. | CH9: ORYGEN PERU S.A.A. | CI9: ORYGEN PERU S.A.A. | CJ9: ORYGEN PERU S.A.A. | CK9: ORYGEN PERU S.A.A. | CL9: ORYGEN PERU S.A.A. | CM9: ORYGEN PERU S.A.A. | CN9: SAMAY I S.A.C | CO9: SAMAY I S.A.C | CP9: SAMAY I S.A.C | CQ9: SAMAY I S.A.C | CR9: TERMOCHILCA S.A.C. | CS9: TERMOCHILCA S.A.C. | CT9: TRANSMISION ANDINA DE GENERACION S.A.C. | CU9: TRANSMISION ANDINA DE GENERACION S.A.C. | CV9: CELARIS ENERGY S.A. | CW9: COLCA SOLAR S.A.C. | CX9: ENERGIA RENOVABLE DEL SUR S.A. | CY9: GR CORTARRAMA SOCIEDAD ANONIMA CERRADA | CZ9: GR TARUCA SOCIEDAD ANONIMA CERRADA | DA9: KONDU SAC | DB9: VARI ENERGIA S.A.C. | DC9: ORAZUL ENERGY PERÚ | DD9: ORAZUL ENERGY PERÚ | DE9: KALLPA GENERACION S.A. | DF9: KALLPA GENERACION S.A. | DG9: SAN GABAN | DH9: MAJA ENERGIA S.A.C. | DI9: EMPRESA DE GENERACION ELECTRICA CANCHAYLLO SAC | DJ9: EMPRESA DE GENERACION ELECTRICA SANTA ANA S.A.C. | DK9: EMPRESA ELECTRICA AGUA AZUL | DL9: EMPRESA ELECTRICA RIO DOBLE | DM9: HIDROCAÑETE S.A. | DN9: HUAURA POWER GROUP S.A. | DO9: MOQUEGUA FV S.A.C. | DP9: PANAMERICANA SOLAR SAC. | DQ9: PARQUE EOLICO MARCONA S.A.C. | DR9: PARQUE EOLICO TRES HERMANAS S.A.C. | DS9: TACNA SOLAR SAC. | DT9: ELECTRICA YANAPAMPA SAC | DU9: ANDEAN POWER S.A.C. | DV9: ASOCIACIÓN SANTA LUCIA DE CHACAS | DW9: ATRIA ENERGIA S.A.C. | DX9: COENERGY S.A.C. | DY9: EGEJUNIN | DZ9: EGEJUNIN | EA9: EGEJUNIN | EB9: EGEJUNIN | EC9: ENERGÍA EÓLICA S.A. | ED9: ENERGÍA EÓLICA S.A. | EE9: ENGIE ENERGIA PERU S.A.A. | EF9: ENGIE ENERGIA PERU S.A.A. | EG9: ENGIE ENERGIA PERU S.A.A. | EH9: ENGIE ENERGIA PERU S.A.A. | EI9: ENGIE ENERGIA PERU S.A.A. | EJ9: ENGIE ENERGIA PERU S.A.A. | EK9: GENERACIÓN ANDINA S.A.C. | EL9: GENERACIÓN ANDINA S.A.C. | EM9: GENERADORA DE ENERGÍA DEL PERÚ | EN9: GENERADORA DE ENERGÍA DEL PERÚ | EO9: GENERADORA DE ENERGÍA DEL PERÚ | EP9: GENERADORA DE ENERGÍA DEL PERÚ | EQ9: GR PAINO SOCIEDAD ANONIMA CERRADA | ER9: JOYA SOLAR S.A.C. | ES9: MAJES ARCUS S.A.C. | ET9: ORYGEN PERU S.A.A. | EU9: ORYGEN PERU S.A.A. | EV9: ORYGEN PERU S.A.A. | EW9: ORYGEN PERU S.A.A. | EX9: ORYGEN PERU S.A.A. | EY9: PETRAMAS | EZ9: PETRAMAS | FA9: PETRAMAS | FB9: PETRAMAS | FC9: REPARTICIÓN ARCUS S.A.C. | FD9: SINERSA | FE9: SINERSA | FF9: SINERSA | FG9: BIOENERGIA DEL CHIRA S.A. | FH9: GM OPERACIONES S.A.C. | FI9: GM OPERACIONES S.A.C. | FJ9: AGRO INDUSTRIAL PARAMONGA S.A. | FK9: AGROAURORA S.A.C. | FL9: AGROINDUSTRIAS SAN JACINTO S.A.A. | FM9: AGROLMOS SOCIEDAD ANONIMA - AGROLMOS S.A. | FN9: CASA GRANDE S.A.A. | FQ9: UNACEM PERU S.A. | FR9: ELECTRO ORIENTE | FS9: AGUAS Y ENERGIA PERU | FT9: ELECTRO ZAÑA S.A.C. | FU9: ELECTRONOROESTE S.A. | FV9: SDE PIURA | FW9: SINERSA | FX9: SINERSA
C10: SAN GABAN III | D10: MANTARO | E10: RESTITUCION | F10: TUMBES MAK 1 | G10: TUMBES MAK 2 | H10: CARHUAQUERO | I10: CAÑON DEL PATO | J10: AGUAYTIA TG1 | K10: AGUAYTIA TG2 | L10: KALLPA TG1 | M10: KALLPA TG2 | N10: KALLPA TG3 | O10: KALLPA TV | P10: LFLORES TG1 | Q10: LFLORES TV | R10: CERRO DEL AGUILA | S10: CERRODELAGUILAG4 | T10: SHOUGESA TV1 | U10: SHOUGESA TV2 | V10: SHOUGESA TV3 | W10: SHOUGESA CUMMINS | X10: MACHUPICCHU | Y10: ARICOTA 1 | Z10: ARICOTA 2 | AA10: INDEPENDENCIA | AB10: CHARCANI I,II,III | AC10: CHARCANI IV | AD10: CHARCANI V | AE10: CHARCANI VI | AF10: CHILINA TG | AG10: MOLLENDO 1, 2, 3 | AH10: CHILINA (SULZ 1,2) | AI10: SAN GABAN II | AJ10: PLATANAL | AK10: RECKA | AL10: RF ETEN TG1 | AM10: RF ETEN TG2 | AN10: CHAGLLA GP1 | AO10: CHAGLLA | AP10: LA VIRGEN | AQ10: CHIMAY | AR10: YANANGO | AS10: HUANCHOR | AT10: MARAÑON | AU10: STA TERESA | AV10: FENIX GT11 | AW10: FENIX GT12 | AX10: FENIX TV10 | AY10: YAUPI | AZ10: MALPASO | BA10: CAHUA | BB10: ARCATA | BC10: GALLITO CIEGO | BD10: CHEVES | BE10: SANTA ROSA 1 | BF10: SANTA ROSA 2 | BG10: HUANZA | BH10: MALACAS2 TG4 | BI10: MALACAS3 TG 5 | BJ10: MALACAS1 TG6 | BK10: RF ILO2 TG1 | BL10: RF ILO2 TG2 | BM10: RF ILO2 TG3 | BN10: YUNCAN | BO10: CHILCA1 TG1 | BP10: CHILCA1 TG2 | BQ10: CHILCA1 TG3 | BR10: CHILCA-TV | BS10: CHILCA2 TG41 | BT10: CHILCA2-TV | BU10: CTNEPI_TG41 | BV10: CTNEPI_TG42 | BW10: CTNEPI_TG43 | BX10: QUITARACSA | BY10: RF PTO MALDONADO | BZ10: RF PUCALLPA | CA10: PARIAC | CB10: HUINCO | CC10: MATUCANA | CD10: MOYOPAMPA | CE10: CALLAHUANCA | CF10: HUAMPANI | CG10: STA ROSA WEST TG7 | CH10: UTI_5 | CI10: UTI_6 | CJ10: VENTANILLA 3 | CK10: VENTANILLA 4 | CL10: VENTANILLA TV | CM10: STAROSA TG8 | CN10: PTO_BRVO TG1 | CO10: PTO_BRVO TG2 | CP10: PTO_BRVO TG3 | CQ10: PTO_BRVO TG4 | CR10: OLLEROS TG1 | CS10: OLLEROS TV | CT10: OROYA | CU10: PACHACHACA | CV10: MANTA I | CW10: CS YARUCAYA | CX10: SAN JUAN | CY10: MATARANI | CZ10: DUNA | DA10: CARHUAQUERO (CS) | DB10: ANASHIRONI | DC10: CARHUAQUERO4 | DD10: CAÑA BRAVA | DE10: SUNNY | DF10: SUNNY EXPANSION | DG10: TUPURI | DH10: RONCADOR | DI10: CANCHAYLLO | DJ10: RENOVANDESH1 | DK10: POTRERO | DL10: PIZARRAS | DM10: NIMPERIAL | DN10: YARUCAYA | DO10: MOQUEGUA-SOLAR | DP10: PANAMERICANA-SOLAR | DQ10: PQE-EOLICO-MARCONA | DR10: PQE-EOLICO-3-HERMANAS | DS10: TACNA-SOLAR | DT10: YANAPAMPA | DU10: CARHUAC | DV10: HUALLIN | DW10: PURMACANA | DX10: COENERGY | DY10: HUASAHUASI | DZ10: STACRUZ_1_2 | EA10: RUNATULLO_II | EB10: RUNATULLO_III | EC10: PQE-EOLICO-TALARA | ED10: PQE-EOLICO-CUPISNIQUE | EE10: INTIPAMPA | EF10: PUNTA LOMITAS-BL1 | EG10: PUNTA LOMITAS-BL2 | EH10: PUN LOMITAS_EXP-BL1 | EI10: PUN LOMITAS_EXP-BL2 | EJ10: EXPANSIÓN INTIPAMPA | EK10: 8AGOSTO | EL10: EL CARMEN | EM10: LA JOYA | EN10: ANGEL_I | EO10: ANGEL_II | EP10: ANGEL_III | EQ10: HUAMBOS | ER10: SAN MARTIN SOLAR | ES10: MAJES | ET10: RUBI | EU10: CH_HER1 | EV10: WAYRA-I | EW10: WAYRA EXTENSION | EX10: CLEMESI | EY10: HUAYCOLORO | EZ10: CALLAO | FA10: DONA_CATALINA | FB10: LAGRINGAV | FC10: REPARTICION | FD10: POECHOS2 | FE10: CHANCAY | FF10: RUCUY | FG10: CANA BRAVA | FH10: REFINERIA TALARA TV1 | FI10: REFINERÍA TALARA TV2 | FJ10: PARAMONGA | FK10: MAPLE | FL10: SAN_JACINTO | FM10: AGROLMOS | FN10: CASA GRANDE | FO10: MW | FQ10: CARPAPATA | FR10: CENTRALES ELOR | FS10: PIAS1 | FT10: ZANA | FU10: TABLAZO | FV10: TALLANCA | FW10: CURUMUY | FX10: POECHOS1 | FY10: MW
A11: 04/03/2026 | B11: 00:30 | C11: 201.4 | D11: 652.2 | E11: 213.4 | F11: 7.5 | G11: 7.7 | H11: 92.1 | I11: 235.5 | J11: 0 | K11: 80.3 | R11: 532.4 | S11: 10.2 | T11: 13.6 | U11: 5.6 | X11: 166.4 | Y11: 9.9 | Z11: 6.6 | AB11: 6.4 | AD11: 79.5 | AI11: 110.2 | AJ11: 202.4 | AK11: 0 | AN11: 6.5 | AO11: 394.5 | AP11: 82.5 | AQ11: 150.5 | AR11: 42.1 | AS11: 18.6 | AT11: 18.9 | AU11: 91.8 | AV11: 0 | AW11: 91.6 | AX11: 61 | AY11: 109.7 | AZ11: 45.9 | BA11: 0 | BB11: 3.8 | BC11: 28.8 | BD11: 173.5 | BG11: 92.6 | BH11: 34.8 | BJ11: 0 | BN11: 131.6 | BU11: 194.5 | BV11: 195.4 | BW11: 195.8 | BX11: 0 | CA11: 4.4 | CB11: 257.1 | CC11: 132.6 | CD11: 62.2 | CE11: 77.8 | CF11: 26.4 | CG11: 0 | CJ11: 138.3 | CN11: 0 | CO11: 174.4 | CP11: 175 | CQ11: 174.6 | CT11: 0 | CU11: 8.5 | CV11: 20 | CW11: 0 | CX11: 62.1 | CY11: 0 | CZ11: 0 | DA11: 0 | DB11: 20.3 | DC11: 9.9 | DD11: 5.5 | DE11: 0 | DF11: 0 | DG11: 2.2 | DH11: 3.2 | DI11: 5.1 | DJ11: 20.1 | DK11: 15.1 | DL11: 18.7 | DM11: 3.5 | DN11: 18.4 | DO11: 0 | DP11: 0 | DQ11: 18.8 | DR11: 36.3 | DS11: 0 | DT11: 2.8 | DU11: 20.4 | DV11: 3.2 | DX11: 0 | DY11: 19.8 | DZ11: 13.2 | EA11: 20.3 | EB11: 20.2 | EC11: 1.1 | ED11: 0 | EE11: 0 | EF11: 17.9 | EG11: 29 | EH11: 0.6 | EI11: 0 | EJ11: 0 | EK11: 21 | EL11: 7.7 | EM11: 7.3 | EN11: 20.4 | EO11: 20.4 | EP11: 20 | EQ11: 0 | ER11: 0 | ES11: 0 | ET11: 0 | EU11: 0.3 | EV11: 0 | EW11: 0 | EX11: 0 | EY11: 4.8 | EZ11: 2.4 | FA11: 1.2 | FB11: 2.6 | FC11: 0 | FD11: 6.1 | FE11: 20 | FF11: 20 | FH11: 0 | FI11: 0 | FJ11: 0 | FK11: 13.4 | FL11: 7.3 | FM11: 12 | FN11: 14.6 | FO11: 6638.2 | FQ11: 24.5338 | FR11: 7.92 | FS11: 9.6 | FT11: 13.2 | FU11: 25.8 | FV11: 19 | FW11: 9.7 | FX11: 13.4 | FY11: 123.1538
A12: 04/03/2026 | B12: 01:00 | C12: 201.8 | D12: 652.9 | E12: 214.3 | F12: 7.6 | G12: 7.6 | H12: 92.6 | I12: 234.4 | J12: 0 | K12: 59.9 | R12: 562.8 | S12: 10.2 | T12: 13.5 | U12: 0 | X12: 166.4 | Y12: 9.9 | Z12: 6.5 | AB12: 6.4 | AD12: 90.4 | AI12: 110.1 | AJ12: 199 | AK12: 0 | AN12: 6.5 | AO12: 364.4 | AP12: 82.5 | AQ12: 150.4 | AR12: 42.1 | AS12: 18.6 | AT12: 18.9 | AU12: 90.9 | AV12: 0 | AW12: 89.8 | AX12: 61 | AY12: 109.8 | AZ12: 37.9 | BA12: 0 | BB12: 3.8 | BC12: 28.1 | BD12: 171.3 | BG12: 76.6 | BH12: 30.7 | BJ12: 0 | BN12: 131.8 | BU12: 196.2 | BV12: 196.3 | BW12: 196.4 | BX12: 0 | CA12: 4.5 | CB12: 252.2 | CC12: 126.6 | CD12: 62.4 | CE12: 78.7 | CF12: 29.8 | CG12: 0 | CJ12: 138.7 | CN12: 0 | CO12: 174.3 | CP12: 174.9 | CQ12: 174.7 | CT12: 3.6 | CU12: 8.4 | CV12: 19.9 | CW12: 0 | CX12: 63 | CY12: 0 | CZ12: 0 | DA12: 0 | DB12: 20.4 | DC12: 10 | DD12: 5.6 | DE12: 0 | DF12: 0 | DG12: 2.2 | DH12: 3.2 | DI12: 5.1 | DJ12: 20.3 | DK12: 15.1 | DL12: 18.7 | DM12: 3.5 | DN12: 18.4 | DO12: 0 | DP12: 0 | DQ12: 17.7 | DR12: 30 | DS12: 0 | DT12: 2.8 | DU12: 20.4 | DV12: 3.2 | DX12: 0 | DY12: 19.8 | DZ12: 13.2 | EA12: 20.3 | EB12: 20.2 | EC12: 1.4 | ED12: 0 | EE12: 0 | EF12: 10.6 | EG12: 21.2 | EH12: 0 | EI12: 0 | EJ12: 0 | EK12: 21 | EL12: 7.7 | EM12: 7.3 | EN12: 20.4 | EO12: 20.4 | EP12: 20 | EQ12: 0 | ER12: 0 | ES12: 0 | ET12: 0 | EU12: 0.3 | EV12: 0 | EW12: 0 | EX12: 0 | EY12: 4.8 | EZ12: 2.4 | FA12: 1.2 | FB12: 2.6 | FC12: 0 | FD12: 6.2 | FE12: 20 | FF12: 20 | FH12: 0 | FI12: 0 | FJ12: 0 | FK12: 13.2 | FL12: 7 | FM12: 11.7 | FN12: 15 | FO12: 6566.5 | FQ12: 24.48813 | FR12: 7.92 | FS12: 9.5 | FT12: 13.2 | FU12: 25.7 | FV12: 19 | FW12: 9.8 | FX12: 13.5 | FY12: 123.10813
A13: 04/03/2026 | B13: 01:30 | C13: 202 | D13: 652.7 | E13: 214.1 | F13: 7.6 | G13: 7.7 | H13: 91.4 | I13: 234.9 | J13: 0 | K13: 60.7 | R13: 482.9 | S13: 10.3 | T13: 13.3 | U13: 0 | X13: 165.6 | Y13: 9.9 | Z13: 6.5 | AB13: 6.4 | AD13: 90.6 | AI13: 110.5 | AJ13: 188.6 | AK13: 0 | AN13: 6.5 | AO13: 367.1 | AP13: 80.9 | AQ13: 150.4 | AR13: 42.2 | AS13: 18.6 | AT13: 18.9 | AU13: 90.5 | AV13: 0 | AW13: 90.8 | AX13: 61.3 | AY13: 109.6 | AZ13: 45.7 | BA13: 0 | BB13: 3.8 | BC13: 28.5 | BD13: 174.3 | BG13: 76.1 | BH13: 30.5 | BJ13: 0 | BN13: 131.6 | BU13: 195.9 | BV13: 196.8 | BW13: 196.1 | BX13: 0 | CA13: 4.4 | CB13: 233 | CC13: 124.4 | CD13: 62.3 | CE13: 78.5 | CF13: 29.7 | CG13: 0 | CJ13: 138.5 | CN13: 0 | CO13: 175.9 | CP13: 176.5 | CQ13: 176.3 | CT13: 7.9 | CU13: 8.6 | CV13: 19.8 | CW13: 0 | CX13: 57.9 | CY13: 0 | CZ13: 0 | DA13: 0 | DB13: 20.3 | DC13: 9.8 | DD13: 5.5 | DE13: 0 | DF13: 0 | DG13: 2.2 | DH13: 3.2 | DI13: 5.1 | DJ13: 20.4 | DK13: 15.1 | DL13: 18.7 | DM13: 3.6 | DN13: 18.4 | DO13: 0 | DP13: 0 | DQ13: 15.4 | DR13: 35.1 | DS13: 0 | DT13: 2.7 | DU13: 20.4 | DV13: 3.2 | DX13: 0 | DY13: 19.8 | DZ13: 13.2 | EA13: 20.3 | EB13: 20.2 | EC13: 0.1 | ED13: 0 | EE13: 0 | EF13: 14.4 | EG13: 31.9 | EH13: 0.6 | EI13: 0.1 | EJ13: 0 | EK13: 21 | EL13: 7.6 | EM13: 7.3 | EN13: 20.4 | EO13: 20.4 | EP13: 20 | EQ13: 0 | ER13: 0 | ES13: 0 | ET13: 0 | EU13: 0.3 | EV13: 0 | EW13: 0 | EX13: 0 | EY13: 4.8 | EZ13: 2.4 | FA13: 1.2 | FB13: 2.6 | FC13: 0 | FD13: 6.2 | FE13: 20 | FF13: 20 | FH13: 0 | FI13: 0 | FJ13: 0 | FK13: 15 | FL13: 7.2 | FM13: 12 | FN13: 14.7 | FO13: 6488.3 | FQ13: 24.5196 | FR13: 7.93 | FS13: 9.1 | FT13: 13.2 | FU13: 25.5 | FV13: 19 | FW13: 9.9 | FX13: 13.5 | FY13: 122.6496
A14: 04/03/2026 | B14: 02:00 | C14: 203 | D14: 653 | E14: 214.7 | F14: 7.6 | G14: 7.8 | H14: 92.3 | I14: 234.7 | J14: 0 | K14: 59 | R14: 535.2 | S14: 10.2 | T14: 13.4 | U14: 0 | X14: 166.4 | Y14: 9.5 | Z14: 6.6 | AB14: 6.4 | AD14: 90.6 | AI14: 110.2 | AJ14: 154.8 | AK14: 0 | AN14: 6.5 | AO14: 364.2 | AP14: 81.6 | AQ14: 150.4 | AR14: 42.2 | AS14: 18.6 | AT14: 18.9 | AU14: 91 | AV14: 0 | AW14: 91 | AX14: 60.4 | AY14: 110.1 | AZ14: 46.4 | BA14: 0 | BB14: 3.8 | BC14: 28.5 | BD14: 146.8 | BG14: 76.7 | BH14: 27.7 | BJ14: 0 | BN14: 132 | BU14: 195.1 | BV14: 196.2 | BW14: 196 | BX14: 0 | CA14: 4.4 | CB14: 239.3 | CC14: 128.1 | CD14: 62.4 | CE14: 78.6 | CF14: 30.9 | CG14: 0 | CJ14: 138.8 | CN14: 0 | CO14: 175.8 | CP14: 176.7 | CQ14: 29.8 | CT14: 7.8 | CU14: 8.4 | CV14: 19.8 | CW14: 0 | CX14: 63.4 | CY14: 0 | CZ14: 0 | DA14: 0 | DB14: 20.3 | DC14: 9.8 | DD14: 5.6 | DE14: 0 | DF14: 0 | DG14: 2.2 | DH14: 3.2 | DI14: 5.1 | DJ14: 20.5 | DK14: 15.1 | DL14: 18.8 | DM14: 3.6 | DN14: 17.4 | DO14: 0 | DP14: 0 | DQ14: 14.8 | DR14: 41.3 | DS14: 0 | DT14: 2.7 | DU14: 20.4 | DV14: 3.2 | DX14: 0 | DY14: 19.8 | DZ14: 13.2 | EA14: 20.2 | EB14: 20.2 | EC14: 0.2 | ED14: 0 | EE14: 0 | EF14: 14.5 | EG14: 27.3 | EH14: 0.7 | EI14: 0 | EJ14: 0 | EK14: 21 | EL14: 7.5 | EM14: 7.3 | EN14: 20.4 | EO14: 20.4 | EP14: 20 | EQ14: 0 | ER14: 0 | ES14: 0 | ET14: 0 | EU14: 0.6 | EV14: 0 | EW14: 0 | EX14: 0 | EY14: 4.8 | EZ14: 2.4 | FA14: 1.2 | FB14: 2.6 | FC14: 0 | FD14: 6.2 | FE14: 20 | FF14: 20 | FH14: 0 | FI14: 0 | FJ14: 0 | FK14: 13.1 | FL14: 6.5 | FM14: 11.7 | FN14: 14 | FO14: 6343.5 | FQ14: 24.54509 | FR14: 7.93 | FS14: 8.8 | FT14: 13.2 | FU14: 25.5 | FV14: 19 | FW14: 9.9 | FX14: 13.5 | FY14: 122.37509
A15: 04/03/2026 | B15: 02:30 | C15: 203.4 | D15: 651.6 | E15: 213 | F15: 7.7 | G15: 7.8 | H15: 92.2 | I15: 235 | J15: 0 | K15: 60.1 | R15: 532.6 | S15: 10.2 | T15: 13.2 | U15: 0 | X15: 164.7 | Y15: 9.8 | Z15: 6.6 | AB15: 6.4 | AD15: 90.3 | AI15: 110.3 | AJ15: 179 | AK15: 0 | AN15: 6.5 | AO15: 364.7 | AP15: 82.4 | AQ15: 150.2 | AR15: 42.2 | AS15: 18.6 | AT15: 18.9 | AU15: 89.7 | AV15: 0 | AW15: 91.3 | AX15: 61.1 | AY15: 109.9 | AZ15: 46.5 | BA15: 0 | BB15: 3.8 | BC15: 28.2 | BD15: 141.4 | BG15: 76.5 | BH15: 30.4 | BJ15: 0 | BN15: 131.2 | BU15: 194.6 | BV15: 195.2 | BW15: 195.3 | BX15: 0 | CA15: 4.3 | CB15: 233.6 | CC15: 125.4 | CD15: 62.7 | CE15: 78.5 | CF15: 30.8 | CG15: 0 | CJ15: 138.6 | CN15: 0 | CO15: 175.7 | CP15: 176.2 | CQ15: 0 | CT15: 5.4 | CU15: 8.5 | CV15: 19.6 | CW15: 0 | CX15: 46 | CY15: 0 | CZ15: 0 | DA15: 0 | DB15: 20.3 | DC15: 10 | DD15: 5.6 | DE15: 0 | DF15: 0 | DG15: 2.2 | DH15: 3.2 | DI15: 5.1 | DJ15: 20.3 | DK15: 15.1 | DL15: 18.8 | DM15: 3.6 | DN15: 8.5 | DO15: 0 | DP15: 0 | DQ15: 12.2 | DR15: 37.7 | DS15: 0 | DT15: 2.9 | DU15: 20.4 | DV15: 3.2 | DX15: 0 | DY15: 19.8 | DZ15: 13.2 | EA15: 20.2 | EB15: 20.2 | EC15: 0.8 | ED15: 0 | EE15: 0 | EF15: 14.8 | EG15: 29.2 | EH15: 0.4 | EI15: 0 | EJ15: 0 | EK15: 21 | EL15: 7.5 | EM15: 7.3 | EN15: 20.4 | EO15: 20.4 | EP15: 20 | EQ15: 0 | ER15: 0 | ES15: 0 | ET15: 0 | EU15: 0.6 | EV15: 0 | EW15: 0 | EX15: 0 | EY15: 4.6 | EZ15: 2.4 | FA15: 1.2 | FB15: 1.6 | FC15: 0 | FD15: 6.2 | FE15: 20 | FF15: 20 | FH15: 0 | FI15: 0 | FJ15: 0 | FK15: 13.4 | FL15: 6.5 | FM15: 12 | FN15: 13.6 | FO15: 6284.2 | FQ15: 24.52832 | FR15: 7.93 | FS15: 9.3 | FT15: 13.2 | FU15: 25.5 | FV15: 19 | FW15: 10 | FX15: 13.4 | FY15: 122.85832
A16: 04/03/2026 | B16: 03:00 | C16: 205.8 | D16: 651.7 | E16: 213.8 | F16: 7.8 | G16: 7.8 | H16: 92.1 | I16: 235.6 | J16: 0 | K16: 61.1 | R16: 525.9 | S16: 10.3 | T16: 13.2 | U16: 0 | X16: 166.8 | Y16: 9.9 | Z16: 6.5 | AB16: 6.4 | AD16: 91 | AI16: 110.4 | AJ16: 172.6 | AK16: 0 | AN16: 6.5 | AO16: 363.8 | AP16: 81.4 | AQ16: 150.3 | AR16: 42.1 | AS16: 16.9 | AT16: 18.9 | AU16: 90.2 | AV16: 0 | AW16: 93.1 | AX16: 61.5 | AY16: 110.3 | AZ16: 46.4 | BA16: 0 | BB16: 3.8 | BC16: 28.5 | BD16: 140.6 | BG16: 76.8 | BH16: 28.9 | BJ16: 0 | BN16: 131.4 | BU16: 193.9 | BV16: 195.4 | BW16: 195.3 | BX16: 0 | CA16: 4.3 | CB16: 233.3 | CC16: 125.4 | CD16: 63.2 | CE16: 78.4 | CF16: 30.9 | CG16: 0 | CJ16: 138.3 | CN16: 0 | CO16: 177.7 | CP16: 177.6 | CQ16: 0 | CT16: 0 | CU16: 8.5 | CV16: 19.6 | CW16: 0 | CX16: 44.2 | CY16: 0 | CZ16: 0 | DA16: 0 | DB16: 20.3 | DC16: 9.9 | DD16: 5.6 | DE16: 0 | DF16: 0 | DG16: 2.2 | DH16: 3.2 | DI16: 5.1 | DJ16: 20.3 | DK16: 15.1 | DL16: 18.8 | DM16: 3.6 | DN16: 6 | DO16: 0 | DP16: 0 | DQ16: 11.9 | DR16: 31.3 | DS16: 0 | DT16: 2.8 | DU16: 20.4 | DV16: 3.2 | DX16: 0 | DY16: 19.8 | DZ16: 13.2 | EA16: 20 | EB16: 20.2 | EC16: 0.4 | ED16: 0 | EE16: 0 | EF16: 13.8 | EG16: 28.9 | EH16: 1.1 | EI16: 0.1 | EJ16: 0 | EK16: 21 | EL16: 7.5 | EM16: 7.3 | EN16: 20.4 | EO16: 20.4 | EP16: 20 | EQ16: 0 | ER16: 0 | ES16: 0 | ET16: 0 | EU16: 0.6 | EV16: 0 | EW16: 1.4 | EX16: 0 | EY16: 4.8 | EZ16: 2.4 | FA16: 1.2 | FB16: 2.6 | FC16: 0 | FD16: 6.2 | FE16: 20 | FF16: 20 | FH16: 0 | FI16: 0 | FJ16: 0 | FK16: 14.3 | FL16: 6.3 | FM16: 12 | FN16: 13.7 | FO16: 6265.4 | FQ16: 24.52763 | FR16: 7.94 | FS16: 9.5 | FT16: 13.2 | FU16: 25.5 | FV16: 19 | FW16: 10 | FX16: 13.5 | FY16: 123.16763
A17: 04/03/2026 | B17: 03:30 | C17: 203.9 | D17: 652.5 | E17: 214.3 | F17: 7.7 | G17: 7.7 | H17: 92.6 | I17: 235.7 | J17: 0 | K17: 59.9 | R17: 542.8 | S17: 10.3 | T17: 13.1 | U17: 0 | X17: 164.3 | Y17: 10.2 | Z17: 6.6 | AB17: 6.3 | AD17: 90.9 | AI17: 110.2 | AJ17: 176.8 | AK17: 0 | AN17: 6.5 | AO17: 365.2 | AP17: 82.6 | AQ17: 150.7 | AR17: 42.1 | AS17: 18.6 | AT17: 18.9 | AU17: 92.1 | AV17: 0 | AW17: 91.8 | AX17: 60.6 | AY17: 109.9 | AZ17: 46.5 | BA17: 0 | BB17: 3.8 | BC17: 28.5 | BD17: 148.1 | BG17: 76.9 | BH17: 27.9 | BJ17: 0 | BN17: 131.9 | BU17: 195.3 | BV17: 196 | BW17: 196.1 | BX17: 0 | CA17: 4.3 | CB17: 242.4 | CC17: 129.2 | CD17: 63 | CE17: 78.6 | CF17: 30.9 | CG17: 0 | CJ17: 139.1 | CN17: 0 | CO17: 96.5 | CP17: 176.8 | CQ17: 0 | CT17: 0 | CU17: 8.6 | CV17: 19.5 | CW17: 0 | CX17: 49.5 | CY17: 0 | CZ17: 0 | DA17: 0 | DB17: 20.3 | DC17: 9.9 | DD17: 5.6 | DE17: 0 | DF17: 0 | DG17: 2.2 | DH17: 3.2 | DI17: 5.1 | DJ17: 20.4 | DK17: 15.1 | DL17: 18.7 | DM17: 3.6 | DN17: 6 | DO17: 0 | DP17: 0 | DQ17: 11.4 | DR17: 30.6 | DS17: 0 | DT17: 2.7 | DU17: 20.4 | DV17: 3.2 | DX17: 0 | DY17: 19.8 | DZ17: 13.2 | EA17: 20.1 | EB17: 20.2 | EC17: 1.3 | ED17: 0 | EE17: 0 | EF17: 14 | EG17: 26.7 | EH17: 0.5 | EI17: 0 | EJ17: 0 | EK17: 21 | EL17: 7.4 | EM17: 7.3 | EN17: 20.4 | EO17: 20.4 | EP17: 20 | EQ17: 0 | ER17: 0 | ES17: 0 | ET17: 0 | EU17: 0.6 | EV17: 15.4 | EW17: 5.8 | EX17: 0 | EY17: 4.8 | EZ17: 2.4 | FA17: 1.2 | FB17: 2.5 | FC17: 0 | FD17: 6.2 | FE17: 20 | FF17: 20 | FH17: 0 | FI17: 0 | FJ17: 0 | FK17: 14.7 | FL17: 7.6 | FM17: 11.9 | FN17: 16 | FO17: 6254 | FQ17: 24.55642 | FR17: 7.94 | FS17: 10.2 | FT17: 13.2 | FU17: 25.4 | FV17: 19 | FW17: 10.1 | FX17: 13.4 | FY17: 123.79642
A18: 04/03/2026 | B18: 04:00 | C18: 199.8 | D18: 649.5 | E18: 213.8 | F18: 7.5 | G18: 7.5 | H18: 91.2 | I18: 234 | J18: 0 | K18: 58.4 | R18: 541 | S18: 10.2 | T18: 13.4 | U18: 0 | X18: 159.5 | Y18: 10.1 | Z18: 6.5 | AB18: 6.3 | AD18: 90.3 | AI18: 110 | AJ18: 170.9 | AK18: 0 | AN18: 6.5 | AO18: 366.5 | AP18: 81.9 | AQ18: 150 | AR18: 42.1 | AS18: 18.6 | AT18: 18.9 | AU18: 89.8 | AV18: 0 | AW18: 87.9 | AX18: 61 | AY18: 108.9 | AZ18: 45.6 | BA18: 0 | BB18: 3.8 | BC18: 28.3 | BD18: 146.7 | BG18: 75.4 | BH18: 29 | BJ18: 0 | BN18: 131.2 | BU18: 193.9 | BV18: 195.1 | BW18: 195.3 | BX18: 0 | CA18: 4.4 | CB18: 239.9 | CC18: 126.6 | CD18: 62.2 | CE18: 78.3 | CF18: 30.4 | CG18: 0 | CJ18: 138.7 | CN18: 0 | CO18: 92.9 | CP18: 172.9 | CQ18: 0 | CT18: 0 | CU18: 8.4 | CV18: 20 | CW18: 0 | CX18: 53 | CY18: 0 | CZ18: 0 | DA18: 0 | DB18: 20.2 | DC18: 10.1 | DD18: 5.7 | DE18: 0 | DF18: 0 | DG18: 2.2 | DH18: 3.2 | DI18: 5 | DJ18: 20.1 | DK18: 15.1 | DL18: 18.8 | DM18: 3.6 | DN18: 7.7 | DO18: 0 | DP18: 0 | DQ18: 12.8 | DR18: 31 | DS18: 0 | DT18: 3 | DU18: 20.4 | DV18: 3.2 | DX18: 0 | DY18: 19.8 | DZ18: 13.2 | EA18: 20.1 | EB18: 20.2 | EC18: 1.6 | ED18: 0 | EE18: 0 | EF18: 16.7 | EG18: 31.1 | EH18: 0 | EI18: 0 | EJ18: 0 | EK18: 21 | EL18: 7.4 | EM18: 7.3 | EN18: 20.4 | EO18: 20.4 | EP18: 20 | EQ18: 0 | ER18: 0 | ES18: 0 | ET18: 0 | EU18: 0.6 | EV18: 30.5 | EW18: 12.5 | EX18: 0 | EY18: 4.8 | EZ18: 2.4 | FA18: 1.2 | FB18: 2.5 | FC18: 0 | FD18: 6.1 | FE18: 20 | FF18: 20 | FH18: 0 | FI18: 0 | FJ18: 0 | FK18: 14.7 | FL18: 6.5 | FM18: 11.5 | FN18: 15.5 | FO18: 6234.1 | FQ18: 24.53289 | FR18: 7.94 | FS18: 9.7 | FT18: 13.2 | FU18: 25.4 | FV18: 19 | FW18: 10.1 | FX18: 13.4 | FY18: 123.27289
A19: 04/03/2026 | B19: 04:30 | C19: 202.8 | D19: 651.9 | E19: 214.5 | F19: 7.7 | G19: 7.6 | H19: 92.1 | I19: 235.7 | J19: 0 | K19: 0 | R19: 546.7 | S19: 10.2 | T19: 14.1 | U19: 0 | X19: 167.4 | Y19: 10.1 | Z19: 6.6 | AB19: 6.4 | AD19: 90.6 | AI19: 110.3 | AJ19: 182 | AK19: 0 | AN19: 6.5 | AO19: 364.7 | AP19: 75.3 | AQ19: 150.7 | AR19: 42.1 | AS19: 18.6 | AT19: 18.9 | AU19: 91.1 | AV19: 0 | AW19: 90.9 | AX19: 61.8 | AY19: 110.1 | AZ19: 46.2 | BA19: 0 | BB19: 3.8 | BC19: 28.5 | BD19: 150.2 | BG19: 82.1 | BH19: 28.3 | BJ19: 0 | BN19: 131.6 | BU19: 194.9 | BV19: 195.9 | BW19: 196.1 | BX19: 0 | CA19: 4.4 | CB19: 243.5 | CC19: 130.3 | CD19: 62.9 | CE19: 78.6 | CF19: 30.9 | CG19: 0 | CJ19: 139.2 | CN19: 0 | CO19: 96.4 | CP19: 176.4 | CQ19: 0 | CT19: 0 | CU19: 8.4 | CV19: 20 | CW19: 0 | CX19: 56.6 | CY19: 0 | CZ19: 0 | DA19: 0 | DB19: 20.4 | DC19: 9.8 | DD19: 5.6 | DE19: 0 | DF19: 0 | DG19: 2.2 | DH19: 3.2 | DI19: 5 | DJ19: 20.5 | DK19: 15.1 | DL19: 18.7 | DM19: 3.6 | DN19: 10 | DO19: 0 | DP19: 0 | DQ19: 12.3 | DR19: 30.3 | DS19: 0 | DT19: 3.1 | DU19: 20.4 | DV19: 3.2 | DX19: 0 | DY19: 19.8 | DZ19: 13.2 | EA19: 20 | EB19: 20.2 | EC19: 0.9 | ED19: 0 | EE19: 0 | EF19: 18.8 | EG19: 36.7 | EH19: 0.5 | EI19: 0 | EJ19: 0 | EK19: 21 | EL19: 7.4 | EM19: 7.3 | EN19: 20.4 | EO19: 20.4 | EP19: 20 | EQ19: 0 | ER19: 0 | ES19: 0 | ET19: 0 | EU19: 0.6 | EV19: 33.4 | EW19: 30.4 | EX19: 0 | EY19: 4.8 | EZ19: 2.4 | FA19: 1.2 | FB19: 2.5 | FC19: 0 | FD19: 6.2 | FE19: 20 | FF19: 20 | FH19: 0 | FI19: 0 | FJ19: 0 | FK19: 14.7 | FL19: 7.2 | FM19: 11.1 | FN19: 15.9 | FO19: 6273 | FQ19: 24.55378 | FR19: 7.94 | FS19: 9.5 | FT19: 13.2 | FU19: 25.5 | FV19: 19 | FW19: 10.2 | FX19: 13.3 | FY19: 123.19378
A20: 04/03/2026 | B20: 05:00 | C20: 202.7 | D20: 651.4 | E20: 214.1 | F20: 7.7 | G20: 7.7 | H20: 91.9 | I20: 236 | J20: 0 | K20: 0 | R20: 538.7 | S20: 10.2 | T20: 14.7 | U20: 0 | X20: 167.6 | Y20: 10.1 | Z20: 6.6 | AB20: 6.4 | AD20: 90.4 | AI20: 110.2 | AJ20: 181.8 | AK20: 0 | AN20: 6.5 | AO20: 368.2 | AP20: 80.5 | AQ20: 150.7 | AR20: 42.1 | AS20: 18.6 | AT20: 18.9 | AU20: 92.9 | AV20: 0 | AW20: 90.8 | AX20: 60.2 | AY20: 110 | AZ20: 46.2 | BA20: 0 | BB20: 3.8 | BC20: 27.9 | BD20: 145 | BG20: 82 | BH20: 27.8 | BJ20: 0 | BN20: 131.7 | BU20: 195.2 | BV20: 196 | BW20: 195.6 | BX20: 0 | CA20: 4.3 | CB20: 239.1 | CC20: 127.9 | CD20: 62.8 | CE20: 79 | CF20: 30.8 | CG20: 0 | CJ20: 139.1 | CN20: 0 | CO20: 96 | CP20: 176.2 | CQ20: 0 | CT20: 0 | CU20: 8.4 | CV20: 20 | CW20: 0 | CX20: 53.5 | CY20: 0 | CZ20: 0 | DA20: 0 | DB20: 20.3 | DC20: 10 | DD20: 5.5 | DE20: 0 | DF20: 0 | DG20: 2.2 | DH20: 3.2 | DI20: 5.2 | DJ20: 20.3 | DK20: 15.1 | DL20: 18.7 | DM20: 3.6 | DN20: 18.4 | DO20: 0 | DP20: 0 | DQ20: 12 | DR20: 31.5 | DS20: 0 | DT20: 3 | DU20: 20.4 | DV20: 3.2 | DX20: 0 | DY20: 19.8 | DZ20: 13.2 | EA20: 20.1 | EB20: 20.2 | EC20: 0.1 | ED20: 0 | EE20: 0 | EF20: 22.4 | EG20: 42.9 | EH20: 1 | EI20: 0 | EJ20: 0 | EK20: 21 | EL20: 7.4 | EM20: 7.3 | EN20: 20.4 | EO20: 20.4 | EP20: 20 | EQ20: 0 | ER20: 0 | ES20: 0 | ET20: 0 | EU20: 0.6 | EV20: 37.6 | EW20: 29.4 | EX20: 0 | EY20: 4.8 | EZ20: 2.4 | FA20: 1.2 | FB20: 2.5 | FC20: 0 | FD20: 6.2 | FE20: 20 | FF20: 20 | FH20: 0 | FI20: 0 | FJ20: 0 | FK20: 14.7 | FL20: 7.7 | FM20: 11 | FN20: 15.9 | FO20: 6278.7 | FQ20: 24.5394 | FR20: 7.94 | FS20: 9.1 | FT20: 13.2 | FU20: 25.6 | FV20: 19 | FW20: 10.1 | FX20: 13.4 | FY20: 122.8794
A21: 04/03/2026 | B21: 05:30 | C21: 202.7 | D21: 651.5 | E21: 214.5 | F21: 7.6 | G21: 7.7 | H21: 92 | I21: 234.6 | J21: 0 | K21: 0 | R21: 564.4 | S21: 10.2 | T21: 14.2 | U21: 0 | X21: 166.9 | Y21: 10 | Z21: 6.6 | AB21: 6.4 | AD21: 90.2 | AI21: 110.3 | AJ21: 208.8 | AK21: 0 | AN21: 6.5 | AO21: 397.1 | AP21: 82.2 | AQ21: 150.9 | AR21: 42.1 | AS21: 18.6 | AT21: 18.9 | AU21: 91 | AV21: 0 | AW21: 90.9 | AX21: 60.4 | AY21: 110 | AZ21: 45.9 | BA21: 0 | BB21: 3.8 | BC21: 27.8 | BD21: 159.4 | BG21: 81.9 | BH21: 0 | BJ21: 0 | BN21: 131.3 | BU21: 194.1 | BV21: 195 | BW21: 194.9 | BX21: 0 | CA21: 4.4 | CB21: 256.8 | CC21: 133.3 | CD21: 62.8 | CE21: 79.1 | CF21: 30.8 | CG21: 0 | CJ21: 139 | CN21: 0 | CO21: 175.6 | CP21: 176.3 | CQ21: 0 | CT21: 0 | CU21: 8.4 | CV21: 20 | CW21: 0 | CX21: 64.2 | CY21: 0 | CZ21: 0 | DA21: 0 | DB21: 20.4 | DC21: 9.8 | DD21: 5.7 | DE21: 0 | DF21: 0 | DG21: 2.2 | DH21: 3.2 | DI21: 5.2 | DJ21: 20.3 | DK21: 5.1 | DL21: 18.8 | DM21: 3.5 | DN21: 18.4 | DO21: 0 | DP21: 0 | DQ21: 14.7 | DR21: 36.5 | DS21: 0 | DT21: 3 | DU21: 20.4 | DV21: 3.2 | DX21: 0 | DY21: 19.8 | DZ21: 13.2 | EA21: 20 | EB21: 20.2 | EC21: 0 | ED21: 0 | EE21: 0 | EF21: 21.2 | EG21: 51.8 | EH21: 1 | EI21: 0 | EJ21: 0 | EK21: 21 | EL21: 7.2 | EM21: 7.3 | EN21: 20.4 | EO21: 20.4 | EP21: 20 | EQ21: 0 | ER21: 0 | ES21: 0 | ET21: 0 | EU21: 0.6 | EV21: 28.1 | EW21: 23.6 | EX21: 0 | EY21: 4.8 | EZ21: 2.4 | FA21: 0.6 | FB21: 2.6 | FC21: 0 | FD21: 6.2 | FE21: 20 | FF21: 20 | FH21: 0 | FI21: 0 | FJ21: 0 | FK21: 14.7 | FL21: 6.5 | FM21: 11.1 | FN21: 16.6 | FO21: 6443.7 | FQ21: 24.54725 | FR21: 7.94 | FS21: 8.5 | FT21: 13.2 | FU21: 25.8 | FV21: 19 | FW21: 10.3 | FX21: 13.3 | FY21: 122.58725
A22: 04/03/2026 | B22: 06:00 | C22: 204.2 | D22: 652.5 | E22: 214.3 | F22: 7.7 | G22: 7.7 | H22: 92.5 | I22: 234.8 | J22: 0 | K22: 0 | R22: 562.5 | S22: 10.2 | T22: 14.2 | U22: 0 | X22: 163.6 | Y22: 10 | Z22: 6.8 | AB22: 6.5 | AD22: 90.5 | AI22: 110.2 | AJ22: 202 | AK22: 0 | AN22: 6.5 | AO22: 377.8 | AP22: 82.2 | AQ22: 150.8 | AR22: 42.1 | AS22: 18.6 | AT22: 18.9 | AU22: 91.5 | AV22: 0 | AW22: 91.7 | AX22: 60 | AY22: 87.5 | AZ22: 46.3 | BA22: 0 | BB22: 3.8 | BC22: 28.6 | BD22: 157.6 | BG22: 82.1 | BH22: 0 | BJ22: 20.2 | BN22: 131.4 | BU22: 194.3 | BV22: 194.7 | BW22: 195.2 | BX22: 0 | CA22: 4.4 | CB22: 255.6 | CC22: 134.3 | CD22: 66.1 | CE22: 78.3 | CF22: 30.9 | CG22: 0 | CJ22: 139.4 | CN22: 0 | CO22: 176.3 | CP22: 177.2 | CQ22: 0 | CT22: 0 | CU22: 8.4 | CV22: 20 | CW22: 0 | CX22: 72.3 | CY22: 0.8 | CZ22: 0 | DA22: 0 | DB22: 20.4 | DC22: 9.9 | DD22: 5.7 | DE22: 3 | DF22: 1.83 | DG22: 2.2 | DH22: 3.2 | DI22: 5.1 | DJ22: 20.6 | DK22: 5.1 | DL22: 18.7 | DM22: 3.5 | DN22: 18.4 | DO22: 0.1 | DP22: 0 | DQ22: 16.4 | DR22: 40.8 | DS22: 0.1 | DT22: 3 | DU22: 20.4 | DV22: 3.2 | DX22: 0 | DY22: 19.8 | DZ22: 13.2 | EA22: 20.3 | EB22: 20.2 | EC22: 0 | ED22: 0 | EE22: 0.4 | EF22: 24.6 | EG22: 60.8 | EH22: 1 | EI22: 0 | EJ22: 0.6 | EK22: 21 | EL22: 7.2 | EM22: 7.3 | EN22: 20.4 | EO22: 20.4 | EP22: 20 | EQ22: 0 | ER22: 4.1 | ES22: 0.1 | ET22: 2.8 | EU22: 0.6 | EV22: 20.5 | EW22: 15.1 | EX22: 1.9 | EY22: 4.8 | EZ22: 2.4 | FA22: 0.6 | FB22: 2.6 | FC22: 0 | FD22: 6.2 | FE22: 20 | FF22: 20 | FH22: 0 | FI22: 0 | FJ22: 0 | FK22: 14.6 | FL22: 7.2 | FM22: 11 | FN22: 16.3 | FO22: 6445.63 | FQ22: 24.54225 | FR22: 7.95 | FS22: 8 | FT22: 13.2 | FU22: 25.9 | FV22: 19 | FW22: 10.3 | FX22: 13.6 | FY22: 122.49225
... A58: 05/03/2026 | B58: 00:00 | C58: 204.7 | D58: 656.3 | E58: 214.6 | F58: 7.8 | G58: 7.6 | H58: 93.5 | I58: 236.5 | J58: 81.8 | K58: 0 | R58: 569.1 | S58: 10.3 | T58: 14.7 | U58: 0 | X58: 167.3 | Y58: 10.2 | Z58: 6.7 | AB58: 6.3 | AD58: 141.6 | AI58: 110.3 | AJ58: 169.3 | AK58: 0 | AN58: 6.5 | AO58: 367.4 | AP58: 83 | AQ58: 150.6 | AR58: 42.1 | AS58: 18.6 | AT58: 18.9 | AU58: 91.3 | AV58: 154.2 | AW58: 154.7 | AX58: 170.8 | AY58: 109.8 | AZ58: 47.1 | BA58: 0 | BB58: 3.8 | BC58: 28 | BD58: 148.1 | BG58: 94.2 | BH58: 34.8 | BJ58: 14.6 | BN58: 130.19 | BU58: 195.37 | BV58: 193.23 | BW58: 119.48 | BX58: 0 | CA58: 4.6 | CB58: 195.8 | CC58: 119 | CD58: 60.1 | CE58: 71.1 | CF58: 0 | CG58: 0 | CJ58: 138.4 | CN58: 96.3 | CO58: 0 | CP58: 0 | CQ58: 0 | CT58: 7.8 | CU58: 9.1 | CV58: 20.2 | CW58: 0 | CX58: 65 | CY58: 0 | CZ58: 0 | DA58: 0 | DB58: 20.3 | DC58: 10.5 | DD58: 5.7 | DE58: 0 | DF58: 0 | DG58: 2.2 | DH58: 3 | DI58: 5 | DJ58: 20.4 | DK58: 16 | DL58: 18.5 | DM58: 3.5 | DN58: 18.4 | DO58: 0 | DP58: 0 | DQ58: 14.4 | DR58: 38.9 | DS58: 0 | DT58: 1.5 | DU58: 20.4 | DV58: 3.2 | DX58: 0 | DY58: 19.9 | DZ58: 13.2 | EA58: 20.3 | EB58: 20.2 | EC58: 2.2 | ED58: 0 | EE58: 0 | EF58: 55.21 | EG58: 80.72 | EH58: 3.5023 | EI58: 4.126 | EJ58: 0 | EK58: 21 | EL58: 7.5 | EM58: 7.2 | EN58: 20.4 | EO58: 20.4 | EP58: 20 | EQ58: 0 | ER58: 0 | ES58: 0 | ET58: 0 | EU58: 0 | EV58: 18 | EW58: 15.4 | EX58: 0 | EY58: 4.8 | EZ58: 2.3 | FA58: 0.7 | FB58: 1.6 | FC58: 0 | FD58: 6.4 | FE58: 20 | FF58: 20 | FH58: 44.2 | FI58: 29.9 | FJ58: 16.8 | FK58: 14.1 | FL58: 6 | FM58: 12.3 | FN58: 18.6 | FO58: 6621.6283 | FQ58: 24.56726 | FR58: 8 | FS58: 10.6 | FT58: 13.2 | FU58: 25.1 | FV58: 19 | FW58: 10.8 | FX58: 13.4 | FY58: 124.66726
A59: EJEC | C59: 4860.25 | D59: 15726.2 | E59: 5135.55 | F59: 183.55 | G59: 183.8 | H59: 2224.05 | I59: 5644.15 | J59: 974.65 | K59: 249.7 | L59: 0 | M59: 0 | N59: 0 | O59: 0 | P59: 0 | Q59: 0 | R59: 12195.25 | S59: 245.3 | T59: 322.35 | U59: 2.8 | V59: 0 | W59: 0 | X59: 3979.55 | Y59: 240.15 | Z59: 159.65 | AA59: 0 | AB59: 152.1 | AC59: 0 | AD59: 2742.85 | AE59: 0 | AF59: 0 | AG59: 0 | AH59: 0 | AI59: 2645.75 | AJ59: 4657 | AK59: 961.9 | AL59: 0 | AM59: 0 | AN59: 156 | AO59: 9256.2 | AP59: 1974 | AQ59: 3607.9 | AR59: 1010.75 | AS59: 445.35 | AT59: 453.6 | AU59: 2180.85 | AV59: 1734 | AW59: 2500.5 | AX59: 2589.7 | AY59: 2539.2 | AZ59: 1034.9 | BA59: 299.05 | BB59: 91.2 | BC59: 694.25 | BD59: 3636.65 | BE59: 0 | BF59: 0 | BG59: 1803.65 | BH59: 719.35 | BI59: 0 | BJ59: 282.85 | BK59: 0 | BL59: 0 | BM59: 0 | BN59: 3150.775 | BO59: 0 | BP59: 0 | BQ59: 0 | BR59: 0 | BS59: 0 | BT59: 0 | BU59: 4676.27 | BV59: 4653.16 | BW59: 3865.67 | BX59: 458.315 | BY59: 0 | BZ59: 0 | CA59: 104.05 | CB59: 5313.9 | CC59: 2893.7 | CD59: 1521.25 | CE59: 1871.9 | CF59: 677.75 | CG59: 618.55 | CH59: 0 | CI59: 0 | CJ59: 3318.65 | CK59: 0 | CL59: 0 | CM59: 0 | CN59: 1371.65 | CO59: 2597.75 | CP59: 3789.1 | CQ59: 1207.8 | CR59: 0 | CS59: 0 | CT59: 124.8 | CU59: 214.65 | CV59: 474.35 | CW59: 2.65 | CX59: 1894.25 | CY59: 723.25 | CZ59: 54.15 | DA59: 1.25 | DB59: 487.8 | DC59: 243.7 | DD59: 134.75 | DE59: 2062.05 | DF59: 1033.065 | DG59: 50.55 | DH59: 68.1 | DI59: 120.95 | DJ59: 489.35 | DK59: 296.4 | DL59: 448.4 | DM59: 84.6 | DN59: 414.4 | DO59: 149.9 | DP59: 188.95 | DQ59: 405.4 | DR59: 1179.9 | DS59: 162.8 | DT59: 67.6 | DU59: 435.45 | DV59: 76.8 | DW59: 0 | DX59: 3.1 | DY59: 475.3 | DZ59: 316.85 | EA59: 485.15 | EB59: 484.65 | EC59: 23.45 | ED59: 62.05 | EE59: 353.5 | EF59: 1254.365 | EG59: 1788.83 | EH59: 109.6793 | EI59: 89.2728 | EJ59: 258.55 | EK59: 504 | EL59: 177.3 | EM59: 176.65 | EN59: 489.6 | EO59: 489.6 | EP59: 480 | EQ59: 51.15 | ER59: 2555.1 | ES59: 140.65 | ET59: 1420.7 | EU59: 12.75 | EV59: 1095.8 | EW59: 1242.05 | EX59: 1070.2 | EY59: 89.4 | EZ59: 56.05 | FA59: 23.75 | FB59: 52.75 | FC59: 141 | FD59: 152 | FE59: 479.75 | FF59: 479.75 | FG59: 0 | FH59: 629.25 | FI59: 475.05 | FJ59: 252.75 | FK59: 334.05 | FL59: 162.6 | FM59: 276.8 | FN59: 360.45 | FO59: 174252.7 | FQ59: 589.0389 | FR59: 185.45 | FS59: 221.65 | FT59: 211.2 | FU59: 610.4 | FV59: 456 | FW59: 248.6 | FX59: 321.75 | FY59: 2844.0889

Sheet REACTIVA
B3: miércoles, 4 de Marzo del 2026
A5: POTENCIA REACTIVA EJECUTADA DE LAS UNIDADES DE GENERACIÓN DEL COES (MVAR) | FQ5: CENTRALES NO INTEGRANTES COES
A6: FECHA | B6: HORA | C6: 65333 | D6: 101 | E6: 102 | F6: 42667 | G6: 42668 | H6: 126 | I6: 127 | J6: 138 | K6: 139 | L6: 197 | M6: 203 | N6: 204 | O6: 230 | P6: 209 | Q6: 56677 | R6: 796 | S6: 2146 | T6: 142 | U6: 143 | V6: 125 | W6: 187 | X6: 163 | Y6: 298 | Z6: 299 | AA6: 219 | AB6: 151 | AC6: 152 | AD6: 153 | AE6: 154 | AF6: 756 | AG6: 156 | AH6: 155 | AI6: 182 | AJ6: 212 | AK6: 758 | AL6: 263 | AM6: 265 | AN6: 775 | AO6: 777 | AP6: 2154 | AQ6: 150 | AR6: 149 | AS6: 188 | AT6: 2131 | AU6: 755 | AV6: 252 | AW6: 249 | AX6: 250 | AY6: 117 | AZ6: 119 | BA6: 120 | BB6: 189 | BC6: 122 | BD6: 266 | BE6: 337 | BF6: 338 | BG6: 251 | BH6: 115 | BI6: 239 | BJ6: 288 | BK6: 240 | BL6: 241 | BM6: 242 | BN6: 191 | BO6: 194 | BP6: 196 | BQ6: 207 | BR6: 236 | BS6: 795 | BT6: 285 | BU6: 995 | BV6: 996 | BW6: 997 | BX6: 766 | BY6: 926 | BZ6: 924 | CA6: 121 | CB6: 103 | CC6: 104 | CD6: 106 | CE6: 105 | CF6: 107 | CG6: 110 | CH6: 109 | CI6: 144 | CJ6: 113 | CK6: 114 | CL6: 193 | CM6: 208 | CN6: 786 | CO6: 787 | CP6: 788 | CQ6: 789 | CR6: 248 | CS6: 2159 | CT6: 267 | CU6: 268 | CV6: 2194 | CW6: 303 | CX6: 59715 | CY6: 62255 | CZ6: 1263 | DA6: 61800 | DB6: 69125 | DC6: 216 | DD6: 198 | DE6: 70400 | DF6: 76068 | DG6: 49607 | DH6: 214 | DI6: 260 | DJ6: 2152 | DK6: 2128 | DL6: 247 | DM6: 228 | DN6: 2135 | DO6: 261 | DP6: 237 | DQ6: 253 | DR6: 770 | DS6: 235 | DT6: 238 | DU6: 2184 | DV6: 61855 | DW6: 223 | DX6: 75566 | DY6: 226 | DZ6: 201 | EA6: 258 | EB6: 259 | EC6: 257 | ED6: 256 | EE6: 2148 | EF6: 58288 | EG6: 58289 | EH6: 58839 | EI6: 58840 | EJ6: 75260 | EK6: 296 | EL6: 297 | EM6: 211 | EN6: 2175 | EO6: 2178 | EP6: 2181 | EQ6: 1262 | ER6: 63425 | ES6: 233 | ET6: 2150 | EU6: 2165 | EV6: 2161 | EW6: 61197 | EX6: 58851 | EY6: 225 | EZ6: 2201 | FA6: 2171 | FB6: 760 | FC6: 234 | FD6: 215 | FE6: 917 | FF6: 920 | FG6: 289 | FH6: 58333 | FI6: 58336 | FJ6: 213 | FK6: 232 | FL6: 2190 | FM6: 69867 | FN6: 75066 | FO6: TOTAL COES | FQ6: 221 | FR6: 222 | FS6: 224 | FT6: 2187 | FU6: 227 | FV6: 49400 | FW6: 199 | FX6: 200 | FY6: TOTAL NO COES
C7: SUR | D7: CENTRO | E7: CENTRO | F7: NORTE | G7: NORTE | H7: NORTE | I7: NORTE | J7: CENTRO | K7: CENTRO | L7: CENTRO | M7: CENTRO | N7: CENTRO | O7: CENTRO | P7: CENTRO | Q7: CENTRO | R7: CENTRO | S7: CENTRO | T7: CENTRO | U7: CENTRO | V7: CENTRO | W7: CENTRO | X7: SUR | Y7: SUR | Z7: SUR | AA7: CENTRO | AB7: SUR | AC7: SUR | AD7: SUR | AE7: SUR | AF7: SUR | AG7: SUR | AH7: SUR | AI7: SUR | AJ7: CENTRO | AK7: NORTE | AL7: NORTE | AM7: NORTE | AN7: CENTRO | AO7: CENTRO | AP7: CENTRO | AQ7: CENTRO | AR7: CENTRO | AS7: CENTRO | AT7: CENTRO | AU7: SUR | AV7: CENTRO | AW7: CENTRO | AX7: CENTRO | AY7: CENTRO | AZ7: CENTRO | BA7: CENTRO | BB7: SUR | BC7: NORTE | BD7: CENTRO | BE7: CENTRO | BF7: CENTRO | BG7: CENTRO | BH7: NORTE | BI7: NORTE | BJ7: NORTE | BK7: SUR | BL7: SUR | BM7: SUR | BN7: CENTRO | BO7: CENTRO | BP7: CENTRO | BQ7: CENTRO | BR7: CENTRO | BS7: CENTRO | BT7: CENTRO | BU7: SUR | BV7: SUR | BW7: SUR | BX7: NORTE | BY7: SUR | BZ7: CENTRO | CA7: NORTE | CB7: CENTRO | CC7: CENTRO | CD7: CENTRO | CE7: CENTRO | CF7: CENTRO | CG7: CENTRO | CH7: CENTRO | CI7: CENTRO | CJ7: CENTRO | CK7: CENTRO | CL7: CENTRO | CM7: CENTRO | CN7: SUR | CO7: SUR | CP7: SUR | CQ7: SUR | CR7: CENTRO | CS7: CENTRO | CT7: CENTRO | CU7: CENTRO | CV7: NORTE | CW7: CENTRO | CX7: CENTRO | CY7: SUR | CZ7: NORTE | DA7: NORTE | DB7: CENTRO | DC7: NORTE | DD7: NORTE | DE7: SUR | DF7: SUR | DG7: SUR | DH7: CENTRO | DI7: CENTRO | DJ7: CENTRO | DK7: NORTE | DL7: NORTE | DM7: CENTRO | DN7: CENTRO | DO7: SUR | DP7: SUR | DQ7: CENTRO | DR7: CENTRO | DS7: SUR | DT7: CENTRO | DU7: CENTRO | DV7: NORTE | DW7: CENTRO | DX7: CENTRO | DY7: CENTRO | DZ7: NORTE | EA7: CENTRO | EB7: CENTRO | EC7: NORTE | ED7: NORTE | EE7: SUR | EF7: CENTRO | EG7: CENTRO | EH7: CENTRO | EI7: CENTRO | EJ7: SUR | EK7: CENTRO | EL7: CENTRO | EM7: SUR | EN7: SUR | EO7: SUR | EP7: SUR | EQ7: NORTE | ER7: SUR | ES7: SUR | ET7: SUR | EU7: CENTRO | EV7: CENTRO | EW7: CENTRO | EX7: SUR | EY7: CENTRO | EZ7: CENTRO | FA7: CENTRO | FB7: CENTRO | FC7: SUR | FD7: NORTE | FE7: CENTRO | FF7: CENTRO | FG7: NORTE | FH7: NORTE | FI7: NORTE | FJ7: CENTRO | FK7: NORTE | FL7: NORTE | FM7: NORTE | FN7: NORTE | FQ7: NORTE | FR7: CENTRO | FS7: NORTE | FT7: NORTE | FU7: NORTE | FV7: NORTE | FW7: NORTE | FX7: NORTE
C8: HIDROELÉCTRICA | D8: HIDROELÉCTRICA | E8: HIDROELÉCTRICA | F8: TERMOELÉCTRICA | G8: TERMOELÉCTRICA | H8: HIDROELÉCTRICA | I8: HIDROELÉCTRICA | J8: TERMOELÉCTRICA | K8: TERMOELÉCTRICA | L8: TERMOELÉCTRICA | M8: TERMOELÉCTRICA | N8: TERMOELÉCTRICA | O8: TERMOELÉCTRICA | P8: TERMOELÉCTRICA | Q8: TERMOELÉCTRICA | R8: HIDROELÉCTRICA | S8: HIDROELÉCTRICA | T8: TERMOELÉCTRICA | U8: TERMOELÉCTRICA | V8: TERMOELÉCTRICA | W8: TERMOELÉCTRICA | X8: HIDROELÉCTRICA | Y8: HIDROELÉCTRICA | Z8: HIDROELÉCTRICA | AA8: TERMOELÉCTRICA | AB8: HIDROELÉCTRICA | AC8: HIDROELÉCTRICA | AD8: HIDROELÉCTRICA | AE8: HIDROELÉCTRICA | AF8: TERMOELÉCTRICA | AG8: TERMOELÉCTRICA | AH8: TERMOELÉCTRICA | AI8: HIDROELÉCTRICA | AJ8: HIDROELÉCTRICA | AK8: TERMOELÉCTRICA | AL8: TERMOELÉCTRICA | AM8: TERMOELÉCTRICA | AN8: HIDROELÉCTRICA | AO8: HIDROELÉCTRICA | AP8: HIDROELÉCTRICA | AQ8: HIDROELÉCTRICA | AR8: HIDROELÉCTRICA | AS8: HIDROELÉCTRICA | AT8: HIDROELÉCTRICA | AU8: HIDROELÉCTRICA | AV8: TERMOELÉCTRICA | AW8: TERMOELÉCTRICA | AX8: TERMOELÉCTRICA | AY8: HIDROELÉCTRICA | AZ8: HIDROELÉCTRICA | BA8: HIDROELÉCTRICA | BB8: HIDROELÉCTRICA | BC8: HIDROELÉCTRICA | BD8: HIDROELÉCTRICA | BE8: HIDROELÉCTRICA | BF8: HIDROELÉCTRICA | BG8: HIDROELÉCTRICA | BH8: TERMOELÉCTRICA | BI8: TERMOELÉCTRICA | BJ8: TERMOELÉCTRICA | BK8: TERMOELÉCTRICA | BL8: TERMOELÉCTRICA | BM8: TERMOELÉCTRICA | BN8: HIDROELÉCTRICA | BO8: TERMOELÉCTRICA | BP8: TERMOELÉCTRICA | BQ8: TERMOELÉCTRICA | BR8: TERMOELÉCTRICA | BS8: TERMOELÉCTRICA | BT8: TERMOELÉCTRICA | BU8: TERMOELÉCTRICA | BV8: TERMOELÉCTRICA | BW8: TERMOELÉCTRICA | BX8: HIDROELÉCTRICA | BY8: TERMOELÉCTRICA | BZ8: TERMOELÉCTRICA | CA8: HIDROELÉCTRICA | CB8: HIDROELÉCTRICA | CC8: HIDROELÉCTRICA | CD8: HIDROELÉCTRICA | CE8: HIDROELÉCTRICA | CF8: HIDROELÉCTRICA | CG8: TERMOELÉCTRICA | CH8: TERMOELÉCTRICA | CI8: TERMOELÉCTRICA | CJ8: TERMOELÉCTRICA | CK8: TERMOELÉCTRICA | CL8: TERMOELÉCTRICA | CM8: TERMOELÉCTRICA | CN8: TERMOELÉCTRICA | CO8: TERMOELÉCTRICA | CP8: TERMOELÉCTRICA | CQ8: TERMOELÉCTRICA | CR8: TERMOELÉCTRICA | CS8: TERMOELÉCTRICA | CT8: HIDROELÉCTRICA | CU8: HIDROELÉCTRICA | CV8: HIDROELÉCTRICA | CW8: SOLAR | CX8: EÓLICA | CY8: SOLAR | CZ8: EÓLICA | DA8: SOLAR | DB8: HIDROELÉCTRICA | DC8: HIDROELÉCTRICA | DD8: HIDROELÉCTRICA | DE8: SOLAR | DF8: SOLAR | DG8: HIDROELÉCTRICA | DH8: HIDROELÉCTRICA | DI8: HIDROELÉCTRICA | DJ8: HIDROELÉCTRICA | DK8: HIDROELÉCTRICA | DL8: HIDROELÉCTRICA | DM8: HIDROELÉCTRICA | DN8: HIDROELÉCTRICA | DO8: SOLAR | DP8: SOLAR | DQ8: EÓLICA | DR8: EÓLICA | DS8: SOLAR | DT8: HIDROELÉCTRICA | DU8: HIDROELÉCTRICA | DV8: HIDROELÉCTRICA | DW8: HIDROELÉCTRICA | DX8: SOLAR | DY8: HIDROELÉCTRICA | DZ8: HIDROELÉCTRICA | EA8: HIDROELÉCTRICA | EB8: HIDROELÉCTRICA | EC8: EÓLICA | ED8: EÓLICA | EE8: SOLAR | EF8: EÓLICA | EG8: EÓLICA | EH8: EÓLICA | EI8: EÓLICA | EJ8: SOLAR | EK8: HIDROELÉCTRICA | EL8: HIDROELÉCTRICA | EM8: HIDROELÉCTRICA | EN8: HIDROELÉCTRICA | EO8: HIDROELÉCTRICA | EP8: HIDROELÉCTRICA | EQ8: EÓLICA | ER8: SOLAR | ES8: SOLAR | ET8: SOLAR | EU8: HIDROELÉCTRICA | EV8: EÓLICA | EW8: EÓLICA | EX8: SOLAR | EY8: TERMOELÉCTRICA | EZ8: TERMOELÉCTRICA | FA8: TERMOELÉCTRICA | FB8: TERMOELÉCTRICA | FC8: SOLAR | FD8: HIDROELÉCTRICA | FE8: HIDROELÉCTRICA | FF8: HIDROELÉCTRICA | FG8: TERMOELÉCTRICA | FH8: TERMOELÉCTRICA | FI8: TERMOELÉCTRICA | FJ8: TERMOELÉCTRICA | FK8: TERMOELÉCTRICA | FL8: TERMOELÉCTRICA | FM8: TERMOELÉCTRICA | FN8: TERMOELÉCTRICA | FQ8: HIDROELÉCTRICA | FR8: HIDROELÉCTRICA | FS8: HIDROELÉCTRICA | FT8: HIDROELÉCTRICA | FU8: TERMOELÉCTRICA | FV8: TERMOELÉCTRICA | FW8: HIDROELÉCTRICA | FX8: HIDROELÉCTRICA
