Workbook

Sheet EVENTOS
B3: lunes, 27 de Octubre del 2025
B5: INFORMACIÓN DE EVENTOS PRINCIPALES EN SUS INSTALACIONES
B6: TIPO DE EVENTO | C6: EMPRESA | D6: UBICACIÓN | E6: TIPO DE EQUIPO | F6: EQUIPO | G6: INICIO | H6: FINAL | I6: DESCRIPCIÓN | J6: MW INDISP. | K6: INTERRUPCIÓN (SI/NO) | L6: TENSIÓN DE FALLA (kV)
B7: FALLA | C7: CONCESIONARIA LINEA DE TRANSMISION CCNCM S.A.C. | D7: CACLIC - BELAUNDE TERRY | E7: LINEA DE TRANSMISION | F7: L-2194 | G7: 27/10/2025 18:27:50 | H7: 27/10/2025 18:32:24 | I7: DESCONEXIÓN DE LA LÍNEA L-2194 (CÁCLIC - BELAUNDE TERRY) DE 220 KV | J7: 57.81 | K7: SI | L7: 220
B8: EVENTO | C8: CONELSUR LT SAC | D8: PORTILLO | E8: SUBESTACION | F8: SS.EE. | G8: 27/10/2025 08:34:00 | H8: 28/10/2025 00:00:00 | I8: DECLARACIÓN DE SITUACIÓN EXCEPCIONAL EN LA S.E. PORTILLO 60 kV | K8: NO
B9: EVENTO | C9: ELECTRO ORIENTE | D9: BELAUNDE TERRY - TARAPOTO | E9: LINEA DE TRANSMISION | F9: L-1018 | G9: 27/10/2025 18:00:00 | H9: 27/10/2025 18:27:00 | I9: DECLARACIÓN DE SITUACIÓN EXCEPCIONAL EN LA LÍNEA L-1018 (BELAUNDE TERRY - TARAPOTO) DE 138 kV | K9: NO
B10: FALLA | C10: GENERACIÓN ANDINA S.A.C. | D10: TINGO MARÍA - 8 DE AGOSTO | E10: LINEA DE TRANSMISION | F10: L-1145 | G10: 27/10/2025 01:32:32 | H10: 27/10/2025 01:32:32 | I10: RECIERRE EXITOSO EN LA LÍNEA L-1145 (TINGO MARÍA - 8 DE AGOSTO) DE 138 KV | K10: NO | L10: 138
B11: FALLA | C11: INVERSIONES SHAQSHA S.A.C. | D11: COBRIZA I - COBRIZA II | E11: LINEA DE TRANSMISION | F11: L-6602 | G11: 27/10/2025 17:41:39 | H11: 27/10/2025 17:42:45 | I11: DESCONEXIÓN DE LA LÍNEA L-6602 (COBRIZA I – COBRIZA II) DE 69 KV | J11: 6.5 | K11: SI | L11: 0
B12: FALLA | C12: KALLPA GENERACION S.A. | D12: SAN JOSE - SUNNY | E12: LINEA DE TRANSMISION | F12: L-2070 | G12: 27/10/2025 08:21:00 | H12: 27/10/2025 10:40:00 | I12: DESCONEXIÓN DE LA LÍNEA L-2070 (SAN JOSÉ - SUNNY) DE 220 KV | K12: SI | L12: 220
B13: FALLA | C13: LINEAS ANDINAS SECUNDARIAS S.A.C. | D13: CARHUAMAYO - HUARÓN | E13: LINEA DE TRANSMISION | F13: L-6514 | G13: 27/10/2025 12:49:02 | H13: 27/10/2025 12:50:14 | I13: DESCONEXIÓN DE LAS LÍNEAS L-6514/L-6516 (CARHUAMAYO - HUARÓN - EXCELSIOR) DE 50 KV | J13: 8.49 | K13: SI | L13: 50
B14: EVENTO | C14: RED DE ENERGIA DEL PERU S.A. | D14: TINGO MARÍA - AUCAYACU | E14: LINEA DE TRANSMISION | F14: L-1122 | G14: 27/10/2025 18:48:00 | H14: 27/10/2025 21:20:00 | I14: DECLARACIÓN DE SITUACIÓN EXCEPCIONAL EN LA LÍNEA L-1122 (TINGO MARÍA - AUCAYACU) DE 138 kV | K14: NO
B15: FALLA | C15: RED DE ENERGIA DEL PERU S.A. | D15: PIURA OESTE | E15: REACTOR | F15: R-7 | G15: 27/10/2025 01:47:49 | H15: 27/10/2025 12:08:00 | I15: DESCONEXIÓN DEL REACTOR R-7 DE LA S.E. PIURA OESTE | K15: NO | L15: 220

Sheet RESTRIC_OPE
B3: lunes, 27 de Octubre del 2025
B5: RESTRICCIONES OPERATIVAS
B6: FECHA | C6: HORA INICIO | D6: HORA FINAL | E6: EMPRESA | F6: UBICACIÓN | G6: T.Eq. | H6: EQUIPO | I6: DESCRIPCIÓN
B7: 27/10/2025 | C7: 00:00 | D7: 24:00 | E7: EGASA | F7: S.E. CONVERTIDOR | G7: BARRA | H7: BARRA138KV | I7: EGASA limitó la capacidad del transformador 138 kV/33 kV a 50 MVA por deterioro del aislamiento.
B8: 27/10/2025 | C8: 00:00 | D8: 24:00 | E8: ELECTROPERU | F8: C.H. MANTARO | G8: CH | H8: CENTRAL | I8: De acuerdo con el correo del día 25.08.2025, la central tiene una limitación de potencia máxima de 650 MW por seguridad de la central.
B9: 27/10/2025 | C9: 00:00 | D9: 24:00 | E9: ENEL GENERACION PIURA S.A. | F9: C.T. MALACAS | G9: CT | H9: CENTRAL | I9: De acuerdo con la comunicación vía correo del día 24.10.2024. ENEL GENERACIÓN PIURA informa una restricción de potencia para alcanzar 105 MW en simultaneo (TG6+TGN4).
B10: 27/10/2025 | C10: 00:00 | D10: 24:00 | E10: ENEL GENERACION PIURA S.A. | F10: C.T. MALACAS | G10: GT | H10: TG4 | I10: De acuerdo a lo informado mediante correo electronico el día 04.07, la uniadTG4 puede operar a potencia efectiva durante 3 horas o con 80MW durante 4 horas, y el resto de los periodos a mínima generación.
B11: 27/10/2025 | C11: 00:00 | D11: 24:00 | E11: ENGIE ENERGIA PERU S.A.A. | F11: C.H. YUNCÁN | G11: GH | H11: G3 | I11: Según la carta N° ENG/ 198-2024 enviada por su representada, se opera de forma continua el G3 de la CH Yuncán, debido a la ejecución de mantenimientos necesarios para evitar daños en los sellos de seguridad de la válvula esférica del grupo.
B12: 27/10/2025 | C12: 00:00 | D12: 24:00 | E12: ENGIE ENERGIA PERU S.A.A. | F12: C.T. CHILCA 1 | G12: CT | H12: CENTRAL | I12: Restricción de temperatura de la C.T Chilca, ver valor en el modelo de despacho.
B13: 27/10/2025 | C13: 00:00 | D13: 24:00 | E13: ENGIE ENERGIA PERU S.A.A. | F13: C.T. CHILCA 1 | G13: CT | H13: CENTRAL | I13: Con carta ENG/971-2023, indica que no puede cumplir con las IO considerada en el PDO_17122023 dado que vulneran la seguridad de sus activos. Indican que se debe tomar TMO=168h.
B14: 27/10/2025 | C14: 00:00 | D14: 24:00 | E14: ENGIE ENERGIA PERU S.A.A. | F14: C.T. CHILCA 2 | G14: CT | H14: CENTRAL | I14: Con carta ENG/971-2023, indica que no puede cumplir con las IO considerada en el PDO_17122023 dado que vulneran la seguridad de sus activos. Indican que se debe tomar TMO=168h.
B15: 27/10/2025 | C15: 00:00 | D15: 24:00 | E15: FENIX POWER PERÚ | F15: C.T. FENIX | G15: CT | H15: CENTRAL | I15: De acuerdo con lo comunicado en el correo del día 06.05.2024, la CT Fenix cuenta con TMO de 168 hrs en todos su modos de operación.
B16: 27/10/2025 | C16: 00:00 | D16: 24:00 | E16: KALLPA GENERACION S.A. | F16: C.H. MINI CENTRAL CERRO DEL AGUILA | G16: CH | H16: CENTRAL | I16: Caudal ecológico de la Mini CH Cerro del Águila es de 6.1 m3/s correspondiente al mes de setiembre.
B17: 27/10/2025 | C17: 00:00 | D17: 24:00 | E17: KALLPA GENERACION S.A. | F17: C.H. MINI CENTRAL CERRO DEL AGUILA | G17: CH | H17: CENTRAL | I17: De acuerdo con lo informado por Kallpa el día 20.08.2025, la MCH Cerro del Águila tiene TA=0.07h, TMO=0.08h, TMA=0.16h.
... B47: 27/10/2025 | C47: 00:00 | D47: 24:00 | E47: UNACEM PERU S.A. | F47: S.E. CONDORCOCHA | G47: TRAFO3D | H47: T-3 138/44 kV | I47: De acuerdo con lo comunicado UNACEM mediante el informe INF_00142-2025, la transformador T3 de la SE Condorcocha esta limitado al 50% de su capacidad.

Sheet MANTENIMIENTO EJECUTADOS
B3: lunes, 27 de Octubre del 2025
B5: Mantenimiento Ejecutado
B6: Empresa | C6: Ubicación | D6: Equipo | E6: Inicio | F6: Final | G6: Descripción | H6: MW Indisp. | I6: Prog. | J6: Dispon | K6: Interrupc. | L6: Tipo | M6: CodEq | N6: TipoEq_Osinerg
B7: ATLANTICA TRANSMISION SUR S.A. | C7: CHILCA CTM - POROMA | D7: L-5032 | E7: 27/10/2025 07:33 | F7: 27/10/2025 17:20 | G7: Mejoramiento de PAT | H7: 0 | I7: P | J7: E/S | K7: N | L7: PREV. | M7: 13652 | N7: T
B8: ATLANTICA TRANSMISION SUR S.A. | C8: CHILCA CTM - POROMA | D8: L-5032 | E8: 27/10/2025 08:00 | F8: 27/10/2025 16:47 | G8: Mantenimiento de pedestales. | H8: 0 | I8: P | J8: E/S | K8: N | L8: PREV. | M8: 13652 | N8: T
B9: ATLANTICA TRANSMISION SUR S.A. | C9: OCONA | D9: INT-5450 | E9: 27/10/2025 00:00 | F9: 28/10/2025 00:00 | G9: Interruptor INT-5450 cerrado con restriccion operativa, REB-5450 en servicio y suministrando los SS.AA. de la S.E. Oco?a. | H9: 0 | I9: P | J9: E/S | K9: N | L9: OTROS | M9: 13761 | N9: T
B10: ATLANTICA TRANSMISION SUR S.A. | C10: POROMA | D10: INT-5371 | E10: 27/10/2025 00:00 | F10: 28/10/2025 00:00 | G10: Seccionador SBB-5371 fase T indisponible por problemas mecanicos, el seccionador permanece cerrado y bloqueado | H10: 0 | I10: P | J10: E/S | K10: N | L10: OTROS | M10: 13751 | N10: T
B11: ATLANTICA TRANSMISION SUR S.A. | C11: POROMA | D11: REB-5350 | E11: 27/10/2025 00:00 | F11: 28/10/2025 00:00 | G11: Fuera de servicio po falla en el equipo. | H11: 0 | I11: P | J11: F/S | K11: N | L11: OTROS | M11: 13771 | N11: T
B12: ATLANTICA TRANSMISION SUR S.A. | C12: POROMA | D12: AUT-5371 | E12: 27/10/2025 08:46 | F12: 27/10/2025 15:35 | G12: MANTENIMIENTO PREVENTIVO EN AUTOTRANSFORMADOR Y EQUIPOS DE CELDA | H12: 0 | I12: P | J12: F/S | K12: N | L12: PRUEBA | M12: 13783 | N12: T
B13: ATLANTICA TRANSMISION SUR S.A. | C13: POROMA | D13: BARRA A_220KV | E13: 27/10/2025 08:49 | F13: 27/10/2025 15:18 | G13: Mantenimiento en equipos del AUT5371 asociados a la barra A | H13: 0 | I13: P | J13: F/S | K13: N | L13: PREV. | M13: 13860 | N13: T
B14: ATLANTICA TRANSMISION SUR S.A. | C14: POROMA | D14: REL-5381 | E14: 27/10/2025 10:56 | F14: 27/10/2025 16:50 | G14: Extraccion de muestras de aceite. | H14: 0 | I14: P | J14: E/S | K14: N | L14: PREV. | M14: 13772 | N14: T
B15: ATN S.A. | C15: KIMAN AYLLU | D15: AUT-501 | E15: 27/10/2025 00:00 | F15: 28/10/2025 00:00 | G15: Restriccion Operativa en el circuito de control de cambiador de tap s del AUT-501 | H15: 0 | I15: P | J15: E/S | K15: N | L15: OTROS | M15: 13099 | N15: T
B16: CONCESIONARIA LINEA DE TRANSMISION LA NI?A S.A.C. | C16: ALIPIO ROSALES | D16: SS.EE. | E16: 27/10/2025 00:00 | F16: 28/10/2025 00:00 | G16: DIFERENCIAL DE BARRAS DESHABILITADO 220KV A SOLICITUD DE LA EMPRESA ACCIONA HASTA EL INICIO DE SU OPERACION EXPERIMENTAL POR LA INCORPORACION DE SU NUEVA BAHIA | H16: 0 | I16: P | J16: E/S | K16: N | L16: OTROS | M16: 24127 | N16: T
B17: CONCESIONARIA TRANSMISORA REQUE TUMBES S.A.C. | C17: ALIPIO ROSALES | D17: TR-2306 | E17: 27/10/2025 00:00 | F17: 28/10/2025 00:00 | G17: Pruebas previas a su integracion. | H17: 0 | I17: P | J17: E/S | K17: N | L17: P.ENERG | M17: 26657 | N17: T
B18: CONELSUR LT SAC | C18: CALLAHUANCA (CNS) | D18: S.E. | E18: 27/10/2025 00:00 | F18: 28/10/2025 00:00 | G18: RELE DIFERENCIAL DE BARRAS DE CALLAHUANCA 220KV INOPERATIVO | H18: 0 | I18: F | J18: E/S | K18: N | L18: OTROS | M18: 316 | N18: T
... B116: TRANSMANTARO | C116: YARABAMBA | D116: IN-5120 | E116: 27/10/2025 00:00 | F116: 28/10/2025 00:00 | G116: INTERRUPTOR INDISPONIBLE POR FALLA EN LOS MANDOS DE CONTROL DE N1, N2 Y N3. | H116: 0 | I116: P | J116: F/S | K116: N | L116: OTROS | M116: 17437 | N116: T

Sheet INGRESO OC
A3: lunes, 27 de Octubre del 2025
A5: INGRESO A OPERACIÓN COMERCIAL
A6: EMPRESA | B6: TIPO DE EQUIPO | C6: UBICACIÓN | D6: EQUIPO | E6: Fecha y hora de Ingreso a Operación Comercial

Sheet DESPACHO_EJECUTADO
B3: lunes, 27 de Octubre del 2025
A5: POTENCIA ACTIVA EJECUTADA DE LAS UNIDADES DE GENERACIÓN DEL SEIN (MW) | FM5: CENTRALES NO INTEGRANTES COES
A6: FECHA | B6: HORA | C6: 65333 | D6: 101 | E6: 102 | F6: 42667 | G6: 42668 | H6: 126 | I6: 127 | J6: 138 | K6: 139 | L6: 197 | M6: 203 | N6: 204 | O6: 230 | P6: 209 | Q6: 56677 | R6: 796 | S6: 2146 | T6: 142 | U6: 143 | V6: 125 | W6: 187 | X6: 163 | Y6: 298 | Z6: 299 | AA6: 219 | AB6: 151 | AC6: 152 | AD6: 153 | AE6: 154 | AF6: 756 | AG6: 156 | AH6: 155 | AI6: 182 | AJ6: 212 | AK6: 758 | AL6: 263 | AM6: 265 | AN6: 775 | AO6: 777 | AP6: 2154 | AQ6: 150 | AR6: 149 | AS6: 188 | AT6: 2131 | AU6: 755 | AV6: 252 | AW6: 249 | AX6: 250 | AY6: 117 | AZ6: 267 | BA6: 268 | BB6: 119 | BC6: 120 | BD6: 189 | BE6: 122 | BF6: 266 | BG6: 337 | BH6: 338 | BI6: 251 | BJ6: 115 | BK6: 239 | BL6: 288 | BM6: 240 | BN6: 241 | BO6: 242 | BP6: 191 | BQ6: 194 | BR6: 196 | BS6: 207 | BT6: 236 | BU6: 795 | BV6: 285 | BW6: 995 | BX6: 996 | BY6: 997 | BZ6: 766 | CA6: 926 | CB6: 924 | CC6: 121 | CD6: 103 | CE6: 104 | CF6: 106 | CG6: 105 | CH6: 107 | CI6: 110 | CJ6: 109 | CK6: 144 | CL6: 113 | CM6: 114 | CN6: 193 | CO6: 208 | CP6: 786 | CQ6: 787 | CR6: 788 | CS6: 789 | CT6: 248 | CU6: 2159 | CV6: 303 | CW6: 59715 | CX6: 62255 | CY6: 1263 | CZ6: 61800 | DA6: 2194 | DB6: 69125 | DC6: 216 | DD6: 198 | DE6: 70400 | DF6: 49607 | DG6: 214 | DH6: 260 | DI6: 2152 | DJ6: 2128 | DK6: 247 | DL6: 228 | DM6: 2135 | DN6: 261 | DO6: 237 | DP6: 253 | DQ6: 770 | DR6: 235 | DS6: 238 | DT6: 2184 | DU6: 61855 | DV6: 223 | DW6: 226 | DX6: 201 | DY6: 258 | DZ6: 259 | EA6: 920 | EB6: 257 | EC6: 256 | ED6: 2148 | EE6: 58288 | EF6: 58289 | EG6: 58839 | EH6: 58840 | EI6: 296 | EJ6: 297 | EK6: 211 | EL6: 2175 | EM6: 2178 | EN6: 2181 | EO6: 1262 | EP6: 63425 | EQ6: 233 | ER6: 2150 | ES6: 2165 | ET6: 2161 | EU6: 61197 | EV6: 58851 | EW6: 225 | EX6: 2201 | EY6: 2171 | EZ6: 760 | FA6: 234 | FB6: 215 | FC6: 917 | FD6: 289 | FE6: 58333 | FF6: 58336 | FG6: 213 | FH6: 232 | FI6: 2190 | FJ6: 69867 | FK6: TOTAL COES | FM6: 221 | FN6: 222 | FO6: 224 | FP6: 2187 | FQ6: 227 | FR6: 49400 | FS6: 199 | FT6: 200 | FU6: TOTAL NO COES
C7: SUR | D7: CENTRO | E7: CENTRO | F7: NORTE | G7: NORTE | H7: NORTE | I7: NORTE | J7: CENTRO | K7: CENTRO | L7: CENTRO | M7: CENTRO | N7: CENTRO | O7: CENTRO | P7: CENTRO | Q7: CENTRO | R7: CENTRO | S7: CENTRO | T7: CENTRO | U7: CENTRO | V7: CENTRO | W7: CENTRO | X7: SUR | Y7: SUR | Z7: SUR | AA7: CENTRO | AB7: SUR | AC7: SUR | AD7: SUR | AE7: SUR | AF7: SUR | AG7: SUR | AH7: SUR | AI7: SUR | AJ7: CENTRO | AK7: NORTE | AL7: NORTE | AM7: NORTE | AN7: CENTRO | AO7: CENTRO | AP7: CENTRO | AQ7: CENTRO | AR7: CENTRO | AS7: CENTRO | AT7: CENTRO | AU7: SUR | AV7: CENTRO | AW7: CENTRO | AX7: CENTRO | AY7: CENTRO | AZ7: CENTRO | BA7: CENTRO | BB7: CENTRO | BC7: CENTRO | BD7: SUR | BE7: NORTE | BF7: CENTRO | BG7: CENTRO | BH7: CENTRO | BI7: CENTRO | BJ7: NORTE | BK7: NORTE | BL7: NORTE | BM7: SUR | BN7: SUR | BO7: SUR | BP7: CENTRO | BQ7: CENTRO | BR7: CENTRO | BS7: CENTRO | BT7: CENTRO | BU7: CENTRO | BV7: CENTRO | BW7: SUR | BX7: SUR | BY7: SUR | BZ7: NORTE | CA7: SUR | CB7: CENTRO | CC7: NORTE | CD7: CENTRO | CE7: CENTRO | CF7: CENTRO | CG7: CENTRO | CH7: CENTRO | CI7: CENTRO | CJ7: CENTRO | CK7: CENTRO | CL7: CENTRO | CM7: CENTRO | CN7: CENTRO | CO7: CENTRO | CP7: SUR | CQ7: SUR | CR7: SUR | CS7: SUR | CT7: CENTRO | CU7: CENTRO | CV7: CENTRO | CW7: CENTRO | CX7: SUR | CY7: NORTE | CZ7: NORTE | DA7: NORTE | DB7: CENTRO | DC7: NORTE | DD7: NORTE | DE7: SUR | DF7: SUR | DG7: CENTRO | DH7: CENTRO | DI7: CENTRO | DJ7: NORTE | DK7: NORTE | DL7: CENTRO | DM7: CENTRO | DN7: SUR | DO7: SUR | DP7: CENTRO | DQ7: CENTRO | DR7: SUR | DS7: CENTRO | DT7: CENTRO | DU7: NORTE | DV7: CENTRO | DW7: CENTRO | DX7: NORTE | DY7: CENTRO | DZ7: CENTRO | EA7: CENTRO | EB7: NORTE | EC7: NORTE | ED7: SUR | EE7: CENTRO | EF7: CENTRO | EG7: CENTRO | EH7: CENTRO | EI7: CENTRO | EJ7: CENTRO | EK7: SUR | EL7: SUR | EM7: SUR | EN7: SUR | EO7: NORTE | EP7: SUR | EQ7: SUR | ER7: SUR | ES7: CENTRO | ET7: CENTRO | EU7: CENTRO | EV7: SUR | EW7: CENTRO | EX7: CENTRO | EY7: CENTRO | EZ7: CENTRO | FA7: SUR | FB7: NORTE | FC7: CENTRO | FD7: NORTE | FE7: NORTE | FF7: NORTE | FG7: CENTRO | FH7: NORTE | FI7: NORTE | FJ7: NORTE | FM7: NORTE | FN7: CENTRO | FO7: NORTE | FP7: NORTE | FQ7: NORTE | FR7: NORTE | FS7: NORTE | FT7: NORTE
C8: HIDROELÉCTRICA | D8: HIDROELÉCTRICA | E8: HIDROELÉCTRICA | F8: TERMOELÉCTRICA | G8: TERMOELÉCTRICA | H8: HIDROELÉCTRICA | I8: HIDROELÉCTRICA | J8: TERMOELÉCTRICA | K8: TERMOELÉCTRICA | L8: TERMOELÉCTRICA | M8: TERMOELÉCTRICA | N8: TERMOELÉCTRICA | O8: TERMOELÉCTRICA | P8: TERMOELÉCTRICA | Q8: TERMOELÉCTRICA | R8: HIDROELÉCTRICA | S8: HIDROELÉCTRICA | T8: TERMOELÉCTRICA | U8: TERMOELÉCTRICA | V8: TERMOELÉCTRICA | W8: TERMOELÉCTRICA | X8: HIDROELÉCTRICA | Y8: HIDROELÉCTRICA | Z8: HIDROELÉCTRICA | AA8: TERMOELÉCTRICA | AB8: HIDROELÉCTRICA | AC8: HIDROELÉCTRICA | AD8: HIDROELÉCTRICA | AE8: HIDROELÉCTRICA | AF8: TERMOELÉCTRICA | AG8: TERMOELÉCTRICA | AH8: TERMOELÉCTRICA | AI8: HIDROELÉCTRICA | AJ8: HIDROELÉCTRICA | AK8: TERMOELÉCTRICA | AL8: TERMOELÉCTRICA | AM8: TERMOELÉCTRICA | AN8: HIDROELÉCTRICA | AO8: HIDROELÉCTRICA | AP8: HIDROELÉCTRICA | AQ8: HIDROELÉCTRICA | AR8: HIDROELÉCTRICA | AS8: HIDROELÉCTRICA | AT8: HIDROELÉCTRICA | AU8: HIDROELÉCTRICA | AV8: TERMOELÉCTRICA | AW8: TERMOELÉCTRICA | AX8: TERMOELÉCTRICA | AY8: HIDROELÉCTRICA | AZ8: HIDROELÉCTRICA | BA8: HIDROELÉCTRICA | BB8: HIDROELÉCTRICA | BC8: HIDROELÉCTRICA | BD8: HIDROELÉCTRICA | BE8: HIDROELÉCTRICA | BF8: HIDROELÉCTRICA | BG8: HIDROELÉCTRICA | BH8: HIDROELÉCTRICA | BI8: HIDROELÉCTRICA | BJ8: TERMOELÉCTRICA | BK8: TERMOELÉCTRICA | BL8: TERMOELÉCTRICA | BM8: TERMOELÉCTRICA | BN8: TERMOELÉCTRICA | BO8: TERMOELÉCTRICA | BP8: HIDROELÉCTRICA | BQ8: TERMOELÉCTRICA | BR8: TERMOELÉCTRICA | BS8: TERMOELÉCTRICA | BT8: TERMOELÉCTRICA | BU8: TERMOELÉCTRICA | BV8: TERMOELÉCTRICA | BW8: TERMOELÉCTRICA | BX8: TERMOELÉCTRICA | BY8: TERMOELÉCTRICA | BZ8: HIDROELÉCTRICA | CA8: TERMOELÉCTRICA | CB8: TERMOELÉCTRICA | CC8: HIDROELÉCTRICA | CD8: HIDROELÉCTRICA | CE8: HIDROELÉCTRICA | CF8: HIDROELÉCTRICA | CG8: HIDROELÉCTRICA | CH8: HIDROELÉCTRICA | CI8: TERMOELÉCTRICA | CJ8: TERMOELÉCTRICA | CK8: TERMOELÉCTRICA | CL8: TERMOELÉCTRICA | CM8: TERMOELÉCTRICA | CN8: TERMOELÉCTRICA | CO8: TERMOELÉCTRICA | CP8: TERMOELÉCTRICA | CQ8: TERMOELÉCTRICA | CR8: TERMOELÉCTRICA | CS8: TERMOELÉCTRICA | CT8: TERMOELÉCTRICA | CU8: TERMOELÉCTRICA | CV8: SOLAR | CW8: EÓLICA | CX8: SOLAR | CY8: EÓLICA | CZ8: SOLAR | DA8: HIDROELÉCTRICA | DB8: HIDROELÉCTRICA | DC8: HIDROELÉCTRICA | DD8: HIDROELÉCTRICA | DE8: SOLAR | DF8: HIDROELÉCTRICA | DG8: HIDROELÉCTRICA | DH8: HIDROELÉCTRICA | DI8: HIDROELÉCTRICA | DJ8: HIDROELÉCTRICA | DK8: HIDROELÉCTRICA | DL8: HIDROELÉCTRICA | DM8: HIDROELÉCTRICA | DN8: SOLAR | DO8: SOLAR | DP8: EÓLICA | DQ8: EÓLICA | DR8: SOLAR | DS8: HIDROELÉCTRICA | DT8: HIDROELÉCTRICA | DU8: HIDROELÉCTRICA | DV8: HIDROELÉCTRICA | DW8: HIDROELÉCTRICA | DX8: HIDROELÉCTRICA | DY8: HIDROELÉCTRICA | DZ8: HIDROELÉCTRICA | EA8: HIDROELÉCTRICA | EB8: EÓLICA | EC8: EÓLICA | ED8: SOLAR | EE8: EÓLICA | EF8: EÓLICA | EG8: EÓLICA | EH8: EÓLICA | EI8: HIDROELÉCTRICA | EJ8: HIDROELÉCTRICA | EK8: HIDROELÉCTRICA | EL8: HIDROELÉCTRICA | EM8: HIDROELÉCTRICA | EN8: HIDROELÉCTRICA | EO8: EÓLICA | EP8: SOLAR | EQ8: SOLAR | ER8: SOLAR | ES8: HIDROELÉCTRICA | ET8: EÓLICA | EU8: EÓLICA | EV8: SOLAR | EW8: TERMOELÉCTRICA | EX8: TERMOELÉCTRICA | EY8: TERMOELÉCTRICA | EZ8: TERMOELÉCTRICA | FA8: SOLAR | FB8: HIDROELÉCTRICA | FC8: HIDROELÉCTRICA | FD8: TERMOELÉCTRICA | FE8: TERMOELÉCTRICA | FF8: TERMOELÉCTRICA | FG8: TERMOELÉCTRICA | FH8: TERMOELÉCTRICA | FI8: TERMOELÉCTRICA | FJ8: TERMOELÉCTRICA | FM8: HIDROELÉCTRICA | FN8: HIDROELÉCTRICA | FO8: HIDROELÉCTRICA | FP8: HIDROELÉCTRICA | FQ8: TERMOELÉCTRICA | FR8: TERMOELÉCTRICA | FS8: HIDROELÉCTRICA | FT8: HIDROELÉCTRICA
C9: HYDRO GLOBAL PERÚ S.A.C. | D9: ELECTROPERU | E9: ELECTROPERU | F9: ELECTROPERU | G9: ELECTROPERU | H9: ORAZUL ENERGY PERÚ | I9: ORAZUL ENERGY PERÚ | J9: TERMOSELVA | K9: TERMOSELVA | L9: KALLPA GENERACION S.A. | M9: KALLPA GENERACION S.A. | N9: KALLPA GENERACION S.A. | O9: KALLPA GENERACION S.A. | P9: KALLPA GENERACION S.A. | Q9: KALLPA GENERACION S.A. | R9: KALLPA GENERACION S.A. | S9: KALLPA GENERACION S.A. | T9: SHOUGESA | U9: SHOUGESA | V9: SHOUGESA | W9: SHOUGESA | X9: EGEMSA | Y9: EGESUR | Z9: EGESUR | AA9: EGESUR | AB9: EGASA | AC9: EGASA | AD9: EGASA | AE9: EGASA | AF9: EGASA | AG9: EGASA | AH9: EGASA | AI9: SAN GABAN | AJ9: CELEPSA | AK9: MINERA CERRO VERDE | AL9: PLANTA DE RESERVA FRIA DE GENERACION DE ETEN S.A. | AM9: PLANTA DE RESERVA FRIA DE GENERACION DE ETEN S.A. | AN9: EMPRESA DE GENERACION HUALLAGA | AO9: EMPRESA DE GENERACION HUALLAGA | AP9: LA VIRGEN | AQ9: CHINANGO S.A.C. | AR9: CHINANGO S.A.C. | AS9: HIDROELECTRICA HUANCHOR S.A.C. | AT9: CELEPSA RENOVABLES S.R.L. | AU9: INLAND ENERGY SAC | AV9: FENIX POWER PERÚ | AW9: FENIX POWER PERÚ | AX9: FENIX POWER PERÚ | AY9: STATKRAFT S.A | AZ9: STATKRAFT S.A | BA9: STATKRAFT S.A | BB9: STATKRAFT S.A | BC9: STATKRAFT S.A | BD9: STATKRAFT S.A | BE9: STATKRAFT S.A | BF9: STATKRAFT S.A | BG9: CENTRALES SANTA ROSA S.A.C. | BH9: CENTRALES SANTA ROSA S.A.C. | BI9: EMPRESA DE GENERACION HUANZA | BJ9: ENEL GENERACION PIURA S.A. | BK9: ENEL GENERACION PIURA S.A. | BL9: ENEL GENERACION PIURA S.A. | BM9: ENGIE ENERGIA PERU S.A.A. | BN9: ENGIE ENERGIA PERU S.A.A. | BO9: ENGIE ENERGIA PERU S.A.A. | BP9: ENGIE ENERGIA PERU S.A.A. | BQ9: ENGIE ENERGIA PERU S.A.A. | BR9: ENGIE ENERGIA PERU S.A.A. | BS9: ENGIE ENERGIA PERU S.A.A. | BT9: ENGIE ENERGIA PERU S.A.A. | BU9: ENGIE ENERGIA PERU S.A.A. | BV9: ENGIE ENERGIA PERU S.A.A. | BW9: ENGIE ENERGIA PERU S.A.A. | BX9: ENGIE ENERGIA PERU S.A.A. | BY9: ENGIE ENERGIA PERU S.A.A. | BZ9: ENGIE ENERGIA PERU S.A.A. | CA9: INFRAESTRUCTURAS Y ENERGIAS DEL PERU S.A.C. | CB9: INFRAESTRUCTURAS Y ENERGIAS DEL PERU S.A.C. | CC9: INVERSIONES SHAQSHA S.A.C. | CD9: ORYGEN PERU S.A.A. | CE9: ORYGEN PERU S.A.A. | CF9: ORYGEN PERU S.A.A. | CG9: ORYGEN PERU S.A.A. | CH9: ORYGEN PERU S.A.A. | CI9: ORYGEN PERU S.A.A. | CJ9: ORYGEN PERU S.A.A. | CK9: ORYGEN PERU S.A.A. | CL9: ORYGEN PERU S.A.A. | CM9: ORYGEN PERU S.A.A. | CN9: ORYGEN PERU S.A.A. | CO9: ORYGEN PERU S.A.A. | CP9: SAMAY I S.A.C | CQ9: SAMAY I S.A.C | CR9: SAMAY I S.A.C | CS9: SAMAY I S.A.C | CT9: TERMOCHILCA S.A.C. | CU9: TERMOCHILCA S.A.C. | CV9: COLCA SOLAR S.A.C. | CW9: ENERGIA RENOVABLE DEL SUR S.A. | CX9: GR CORTARRAMA SOCIEDAD ANONIMA CERRADA | CY9: GR TARUCA SOCIEDAD ANONIMA CERRADA | CZ9: KONDU SAC | DA9: PERUANA DE INVERSIONES EN ENERGIAS RENOVABLES S.A. | DB9: VARI ENERGIA S.A.C. | DC9: ORAZUL ENERGY PERÚ | DD9: ORAZUL ENERGY PERÚ | DE9: KALLPA GENERACION S.A. | DF9: SAN GABAN | DG9: MAJA ENERGIA S.A.C. | DH9: EMPRESA DE GENERACION ELECTRICA CANCHAYLLO SAC | DI9: EMPRESA DE GENERACION ELECTRICA SANTA ANA S.A.C. | DJ9: EMPRESA ELECTRICA AGUA AZUL | DK9: EMPRESA ELECTRICA RIO DOBLE | DL9: HIDROCAÑETE S.A. | DM9: HUAURA POWER GROUP S.A. | DN9: MOQUEGUA FV S.A.C. | DO9: PANAMERICANA SOLAR SAC. | DP9: PARQUE EOLICO MARCONA S.A.C. | DQ9: PARQUE EOLICO TRES HERMANAS S.A.C. | DR9: TACNA SOLAR SAC. | DS9: ELECTRICA YANAPAMPA SAC | DT9: ANDEAN POWER S.A.C. | DU9: ASOCIACIÓN SANTA LUCIA DE CHACAS | DV9: ATRIA ENERGIA S.A.C. | DW9: EGEJUNIN | DX9: EGEJUNIN | DY9: EGEJUNIN | DZ9: EGEJUNIN | EA9: EMPRESA DE GENERACION ELECTRICA RIO BAÑOS S.A.C. | EB9: ENERGÍA EÓLICA S.A. | EC9: ENERGÍA EÓLICA S.A. | ED9: ENGIE ENERGIA PERU S.A.A. | EE9: ENGIE ENERGIA PERU S.A.A. | EF9: ENGIE ENERGIA PERU S.A.A. | EG9: ENGIE ENERGIA PERU S.A.A. | EH9: ENGIE ENERGIA PERU S.A.A. | EI9: GENERACIÓN ANDINA S.A.C. | EJ9: GENERACIÓN ANDINA S.A.C. | EK9: GENERADORA DE ENERGÍA DEL PERÚ | EL9: GENERADORA DE ENERGÍA DEL PERÚ | EM9: GENERADORA DE ENERGÍA DEL PERÚ | EN9: GENERADORA DE ENERGÍA DEL PERÚ | EO9: GR PAINO SOCIEDAD ANONIMA CERRADA | EP9: JOYA SOLAR S.A.C. | EQ9: MAJES ARCUS S.A.C. | ER9: ORYGEN PERU S.A.A. | ES9: ORYGEN PERU S.A.A. | ET9: ORYGEN PERU S.A.A. | EU9: ORYGEN PERU S.A.A. | EV9: ORYGEN PERU S.A.A. | EW9: PETRAMAS | EX9: PETRAMAS | EY9: PETRAMAS | EZ9: PETRAMAS | FA9: REPARTICIÓN ARCUS S.A.C. | FB9: SINERSA | FC9: SINERSA | FD9: BIOENERGIA DEL CHIRA S.A. | FE9: GM OPERACIONES S.A.C. | FF9: GM OPERACIONES S.A.C. | FG9: AGRO INDUSTRIAL PARAMONGA S.A. | FH9: AGROAURORA S.A.C. | FI9: AGROINDUSTRIAS SAN JACINTO S.A.A. | FJ9: AGROLMOS SOCIEDAD ANONIMA - AGROLMOS S.A. | FM9: UNACEM PERU S.A. | FN9: ELECTRO ORIENTE | FO9: AGUAS Y ENERGIA PERU | FP9: ELECTRO ZAÑA S.A.C. | FQ9: ELECTRONOROESTE S.A. | FR9: SDE PIURA | FS9: SINERSA | FT9: SINERSA
C10: SAN GABAN III | D10: MANTARO | E10: RESTITUCION | F10: TUMBES MAK 1 | G10: TUMBES MAK 2 | H10: CARHUAQUERO | I10: CAÑON DEL PATO | J10: AGUAYTIA TG1 | K10: AGUAYTIA TG2 | L10: KALLPA TG1 | M10: KALLPA TG2 | N10: KALLPA TG3 | O10: KALLPA TV | P10: LFLORES TG1 | Q10: LFLORES TV | R10: CERRO DEL AGUILA | S10: CERRODELAGUILAG4 | T10: SHOUGESA TV1 | U10: SHOUGESA TV2 | V10: SHOUGESA TV3 | W10: SHOUGESA CUMMINS | X10: MACHUPICCHU | Y10: ARICOTA 1 | Z10: ARICOTA 2 | AA10: INDEPENDENCIA | AB10: CHARCANI I,II,III | AC10: CHARCANI IV | AD10: CHARCANI V | AE10: CHARCANI VI | AF10: CHILINA TG | AG10: MOLLENDO 1, 2, 3 | AH10: CHILINA (SULZ 1,2) | AI10: SAN GABAN II | AJ10: PLATANAL | AK10: RECKA | AL10: RF ETEN TG1 | AM10: RF ETEN TG2 | AN10: CHAGLLA GP1 | AO10: CHAGLLA | AP10: LA VIRGEN | AQ10: CHIMAY | AR10: YANANGO | AS10: HUANCHOR | AT10: MARAÑON | AU10: STA TERESA | AV10: FENIX GT11 | AW10: FENIX GT12 | AX10: FENIX TV10 | AY10: YAUPI | AZ10: OROYA | BA10: PACHACHACA | BB10: MALPASO | BC10: CAHUA | BD10: ARCATA | BE10: GALLITO CIEGO | BF10: CHEVES | BG10: SANTA ROSA 1 | BH10: SANTA ROSA 2 | BI10: HUANZA | BJ10: MALACAS2 TG4 | BK10: MALACAS3 TG 5 | BL10: MALACAS1 TG6 | BM10: RF ILO2 TG1 | BN10: RF ILO2 TG2 | BO10: RF ILO2 TG3 | BP10: YUNCAN | BQ10: CHILCA1 TG1 | BR10: CHILCA1 TG2 | BS10: CHILCA1 TG3 | BT10: CHILCA-TV | BU10: CHILCA2 TG41 | BV10: CHILCA2-TV | BW10: CTNEPI_TG41 | BX10: CTNEPI_TG42 | BY10: CTNEPI_TG43 | BZ10: QUITARACSA | CA10: RF PTO MALDONADO | CB10: RF PUCALLPA | CC10: PARIAC | CD10: HUINCO | CE10: MATUCANA | CF10: MOYOPAMPA | CG10: CALLAHUANCA | CH10: HUAMPANI | CI10: STA ROSA WEST TG7 | CJ10: UTI_5 | CK10: UTI_6 | CL10: VENTANILLA 3 | CM10: VENTANILLA 4 | CN10: VENTANILLA TV | CO10: STAROSA TG8 | CP10: PTO_BRVO TG1 | CQ10: PTO_BRVO TG2 | CR10: PTO_BRVO TG3 | CS10: PTO_BRVO TG4 | CT10: OLLEROS TG1 | CU10: OLLEROS TV | CV10: CS YARUCAYA | CW10: SAN JUAN | CX10: MATARANI | CY10: DUNA | CZ10: CARHUAQUERO (CS) | DA10: MANTA I | DB10: ANASHIRONI | DC10: CARHUAQUERO4 | DD10: CAÑA BRAVA | DE10: SUNNY | DF10: TUPURI | DG10: RONCADOR | DH10: CANCHAYLLO | DI10: RENOVANDESH1 | DJ10: POTRERO | DK10: PIZARRAS | DL10: NIMPERIAL | DM10: YARUCAYA | DN10: MOQUEGUA-SOLAR | DO10: PANAMERICANA-SOLAR | DP10: PQE-EOLICO-MARCONA | DQ10: PQE-EOLICO-3-HERMANAS | DR10: TACNA-SOLAR | DS10: YANAPAMPA | DT10: CARHUAC | DU10: HUALLIN | DV10: PURMACANA | DW10: HUASAHUASI | DX10: STACRUZ_1_2 | DY10: RUNATULLO_II | DZ10: RUNATULLO_III | EA10: RUCUY | EB10: PQE-EOLICO-TALARA | EC10: PQE-EOLICO-CUPISNIQUE | ED10: INTIPAMPA | EE10: PUNTA LOMITAS-BL1 | EF10: PUNTA LOMITAS-BL2 | EG10: PUN LOMITAS_EXP-BL1 | EH10: PUN LOMITAS_EXP-BL2 | EI10: 8AGOSTO | EJ10: EL CARMEN | EK10: LA JOYA | EL10: ANGEL_I | EM10: ANGEL_II | EN10: ANGEL_III | EO10: HUAMBOS | EP10: SAN MARTIN SOLAR | EQ10: MAJES | ER10: RUBI | ES10: CH_HER1 | ET10: WAYRA-I | EU10: WAYRA EXTENSION | EV10: CLEMESI | EW10: HUAYCOLORO | EX10: CALLAO | EY10: DONA_CATALINA | EZ10: LAGRINGAV | FA10: REPARTICION | FB10: POECHOS2 | FC10: CHANCAY | FD10: CANA BRAVA | FE10: REFINERIA TALARA TV1 | FF10: REFINERÍA TALARA TV2 | FG10: PARAMONGA | FH10: MAPLE | FI10: SAN_JACINTO | FJ10: AGROLMOS | FK10: MW | FM10: CARPAPATA | FN10: CENTRALES ELOR | FO10: PIAS1 | FP10: ZANA | FQ10: TABLAZO | FR10: TALLANCA | FS10: CURUMUY | FT10: POECHOS1 | FU10: MW
A11: 27/10/2025 | B11: 00:30 | C11: 144.8 | D11: 628.9 | E11: 213 | H11: 89.6 | I11: 207.1 | L11: 185.8 | M11: 192.8 | N11: 192.6 | O11: 284.4 | P11: 214.4 | Q11: 110.4 | R11: 366.4 | S11: 5.2 | X11: 165.4 | Y11: 7.2 | Z11: 5.7 | AB11: 6.9 | AC11: 11.6 | AD11: 71.9 | AI11: 79.7 | AJ11: 114.7 | AN11: 6.5 | AO11: 304.8 | AP11: 53.3 | AQ11: 76.5 | AR11: 27.5 | AS11: 18.2 | AT11: 18.8 | AU11: 91.4 | AY11: 105.8 | AZ11: 5.5 | BA11: 9.1 | BB11: 18.6 | BC11: 40.7 | BD11: 2 | BE11: 29.3 | BF11: 76.2 | BI11: 72.6 | BL11: 48 | BP11: 110.9 | BQ11: 62 | BR11: 11 | BS11: 200 | BT11: 87.4 | CC11: 4 | CD11: 128.5 | CE11: 83.4 | CF11: 64.2 | CG11: 48 | CH11: 29.9 | CL11: 145.9 | CM11: 147.1 | CN11: 149.5 | CT11: 0 | CU11: 0 | CV11: 0 | CW11: 34.7 | CX11: 0 | CY11: 0.8 | CZ11: 0 | DA11: 17.3 | DB11: 20.7 | DC11: 9.8 | DD11: 5.4 | DE11: 0 | DF11: 0.9 | DG11: 3.5 | DH11: 4.4 | DJ11: 16.5 | DK11: 18.9 | DL11: 3.6 | DM11: 18.6 | DN11: 0 | DO11: 0 | DP11: 9.2 | DQ11: 28.1 | DR11: 0 | DS11: 3.4 | DT11: 16.6 | DU11: 2.3 | DW11: 10.1 | DX11: 7.2 | DY11: 14.8 | DZ11: 20.2 | EA11: 20 | EB11: 11.9 | EC11: 22.1 | ED11: 0 | EE11: 85.3 | EF11: 81 | EG11: 7.3 | EH11: 4.6 | EI11: 20.9 | EJ11: 6.4 | EK11: 7.1 | EL11: 18 | EM11: 18.6 | EN11: 18.3 | EO11: 1.4 | EP11: 0 | EQ11: 0 | ER11: 0 | ES11: 0.6 | ET11: 30.7 | EU11: 18.7 | EV11: 0 | EW11: 2.9 | EX11: 1.1 | EY11: 2.4 | EZ11: 1.1 | FA11: 0 | FB11: 6.346 | FC11: 20.008 | FD11: 8.8 | FF11: 0 | FG11: 15.7 | FH11: 17.5 | FI11: 9.1 | FK11: 6299.954 | FM11: 21.4 | FN11: 0 | FO11: 5.9 | FP11: 13.2 | FQ11: 27.2 | FR11: 18 | FS11: 5.29 | FT11: 4.303 | FU11: 95.293
A12: 27/10/2025 | B12: 01:00 | C12: 91.5 | D12: 630.6 | E12: 214 | H12: 90.4 | I12: 207.3 | L12: 185.6 | M12: 189.4 | N12: 189.6 | O12: 280.3 | P12: 213.1 | Q12: 110.1 | R12: 369.6 | S12: 5.2 | X12: 168.1 | Y12: 8 | Z12: 5.8 | AB12: 6.9 | AC12: 11.6 | AD12: 72.4 | AI12: 80.4 | AJ12: 117.8 | AN12: 6.4 | AO12: 305 | AP12: 52.2 | AQ12: 76.5 | AR12: 28.1 | AS12: 18.2 | AT12: 18.8 | AU12: 91 | AY12: 106.1 | AZ12: 5.5 | BA12: 9.1 | BB12: 21.4 | BC12: 41 | BD12: 2 | BE12: 30.4 | BF12: 77.2 | BI12: 73.2 | BL12: 47.8 | BP12: 70.2 | BQ12: 61.6 | BR12: 10.4 | BS12: 200 | BT12: 86.7 | CC12: 4 | CD12: 164 | CE12: 84.4 | CF12: 64.5 | CG12: 47.7 | CH12: 30.1 | CL12: 145.5 | CM12: 146.5 | CN12: 148.7 | CT12: 0 | CU12: 0 | CV12: 0 | CW12: 39.5 | CX12: 0 | CY12: 0.8 | CZ12: 0 | DA12: 17.4 | DB12: 20.7 | DC12: 9.9 | DD12: 5.4 | DE12: 0 | DF12: 0.9 | DG12: 3.5 | DH12: 4.3 | DJ12: 16.5 | DK12: 18.9 | DL12: 3.6 | DM12: 18.6 | DN12: 0 | DO12: 0 | DP12: 12 | DQ12: 38.1 | DR12: 0 | DS12: 3.4 | DT12: 17.7 | DU12: 2.3 | DW12: 10.1 | DX12: 7.3 | DY12: 14.9 | DZ12: 20.2 | EA12: 20 | EB12: 10.3 | EC12: 14.1 | ED12: 0 | EE12: 76.9 | EF12: 71.7 | EG12: 6.8 | EH12: 3.5 | EI12: 20.9 | EJ12: 6.3 | EK12: 7.1 | EL12: 18 | EM12: 18 | EN12: 18.3 | EO12: 1.3 | EP12: 0 | EQ12: 0 | ER12: 0 | ES12: 0.6 | ET12: 25.7 | EU12: 19.9 | EV12: 0 | EW12: 2.9 | EX12: 1.1 | EY12: 2.4 | EZ12: 1.1 | FA12: 0 | FB12: 6.345 | FC12: 20.013 | FD12: 8.2 | FF12: 0 | FG12: 15.1 | FH12: 17.5 | FI12: 8.2 | FK12: 6230.158 | FM12: 21.4 | FN12: 0 | FO12: 5.9 | FP12: 13.2 | FQ12: 27.1 | FR12: 18.6 | FS12: 5.286 | FT12: 4.264 | FU12: 95.75
A13: 27/10/2025 | B13: 01:30 | C13: 150.7 | D13: 630.8 | E13: 214 | H13: 90.3 | I13: 210.6 | L13: 177.6 | M13: 178 | N13: 178.6 | O13: 269.5 | P13: 213.5 | Q13: 110.2 | R13: 369.5 | S13: 5.2 | X13: 164.5 | Y13: 7.7 | Z13: 6.2 | AB13: 7.1 | AC13: 11.6 | AD13: 72.4 | AI13: 79.8 | AJ13: 117.9 | AN13: 6.4 | AO13: 304.4 | AP13: 52.2 | AQ13: 76.6 | AR13: 26.7 | AS13: 18.2 | AT13: 18.8 | AU13: 89.8 | AY13: 106.7 | AZ13: 5.6 | BA13: 9.1 | BB13: 34.1 | BC13: 41 | BD13: 2 | BE13: 30.1 | BF13: 77 | BI13: 72.9 | BL13: 47.8 | BP13: 70.1 | BQ13: 62.1 | BR13: 45.2 | BS13: 200 | BT13: 86.5 | CC13: 4 | CD13: 134.8 | CE13: 84 | CF13: 64.3 | CG13: 47.9 | CH13: 30 | CL13: 145.8 | CM13: 146.9 | CN13: 149 | CT13: 0 | CU13: 0 | CV13: 0 | CW13: 39.1 | CX13: 0 | CY13: 0.5 | CZ13: 0 | DA13: 17.5 | DB13: 20.7 | DC13: 9.9 | DD13: 5.5 | DE13: 0 | DF13: 0.9 | DG13: 3.5 | DH13: 4.3 | DJ13: 16.5 | DK13: 18.9 | DL13: 3.6 | DM13: 18.6 | DN13: 0 | DO13: 0 | DP13: 9.8 | DQ13: 28.5 | DR13: 0 | DS13: 3.5 | DT13: 17.8 | DU13: 2.3 | DW13: 10.1 | DX13: 7.3 | DY13: 15 | DZ13: 20.2 | EA13: 20 | EB13: 10.1 | EC13: 15.3 | ED13: 0 | EE13: 64.3 | EF13: 55.7 | EG13: 5.1 | EH13: 3.6 | EI13: 20.9 | EJ13: 6.1 | EK13: 7.1 | EL13: 18 | EM13: 18.4 | EN13: 18.6 | EO13: 0.7 | EP13: 0 | EQ13: 0 | ER13: 0 | ES13: 0.6 | ET13: 26.1 | EU13: 19.4 | EV13: 0 | EW13: 2.9 | EX13: 1.1 | EY13: 2.4 | EZ13: 1.1 | FA13: 0 | FB13: 6.333 | FC13: 20.005 | FD13: 8.1 | FF13: 0 | FG13: 15.8 | FH13: 17.5 | FI13: 8.9 | FK13: 6223.838 | FM13: 21.5 | FN13: 0 | FO13: 5.9 | FP13: 13.2 | FQ13: 27.1 | FR13: 18.6 | FS13: 5.287 | FT13: 4.266 | FU13: 95.853
A14: 27/10/2025 | B14: 02:00 | C14: 153 | D14: 633.2 | E14: 215.5 | H14: 91.4 | I14: 213.1 | L14: 177.3 | M14: 176.9 | N14: 176.7 | O14: 260.4 | P14: 211.3 | Q14: 110.1 | R14: 370.9 | S14: 5.2 | X14: 159.6 | Y14: 8 | Z14: 6.3 | AB14: 6.9 | AC14: 11.6 | AD14: 51.5 | AI14: 80.6 | AJ14: 102.7 | AN14: 6.4 | AO14: 300.1 | AP14: 51.9 | AQ14: 77 | AR14: 27.8 | AS14: 18.3 | AT14: 18.8 | AU14: 94.2 | AY14: 106.8 | AZ14: 5.5 | BA14: 9.1 | BB14: 18.8 | BC14: 42.1 | BD14: 2 | BE14: 14.2 | BF14: 79.2 | BI14: 56.2 | BL14: 47.9 | BP14: 70.4 | BQ14: 61.5 | BR14: 79.4 | BS14: 200 | BT14: 86.8 | CC14: 4 | CD14: 112.6 | CE14: 85.3 | CF14: 64.7 | CG14: 47.8 | CH14: 30.1 | CL14: 145.3 | CM14: 146.1 | CN14: 148.7 | CT14: 0 | CU14: 0 | CV14: 0 | CW14: 37.5 | CX14: 0 | CY14: 0.1 | CZ14: 0 | DA14: 17.3 | DB14: 20.8 | DC14: 9.9 | DD14: 5.5 | DE14: 0 | DF14: 0.9 | DG14: 3.5 | DH14: 4.3 | DJ14: 16.5 | DK14: 18.8 | DL14: 3.6 | DM14: 18.6 | DN14: 0 | DO14: 0 | DP14: 9.8 | DQ14: 27.4 | DR14: 0 | DS14: 3.5 | DT14: 18.2 | DU14: 2.3 | DW14: 10.1 | DX14: 7.4 | DY14: 15.2 | DZ14: 20.2 | EA14: 20 | EB14: 10.4 | EC14: 30 | ED14: 0 | EE14: 57.9 | EF14: 55.7 | EG14: 5.4 | EH14: 3.6 | EI14: 20.9 | EJ14: 6 | EK14: 7.1 | EL14: 18.2 | EM14: 18.4 | EN14: 18.6 | EO14: 0.5 | EP14: 0 | EQ14: 0 | ER14: 0 | ES14: 0.6 | ET14: 27.2 | EU14: 19.2 | EV14: 0 | EW14: 2.9 | EX14: 1.1 | EY14: 2.4 | EZ14: 1.1 | FA14: 0 | FB14: 6.313 | FC14: 20.046 | FD14: 9.2 | FF14: 0 | FG14: 15.8 | FH14: 17.5 | FI14: 6.5 | FK14: 6155.159 | FM14: 21.5 | FN14: 0 | FO14: 5.9 | FP14: 13.2 | FQ14: 27.3 | FR14: 18.6 | FS14: 5.329 | FT14: 4.272 | FU14: 96.101
A15: 27/10/2025 | B15: 02:30 | C15: 149.9 | D15: 635.3 | E15: 216.5 | H15: 90.3 | I15: 212.5 | L15: 177.2 | M15: 176 | N15: 177.3 | O15: 272 | P15: 212.1 | Q15: 110.6 | R15: 377.1 | S15: 5.2 | X15: 170.3 | Y15: 8.1 | Z15: 6.2 | AB15: 6.9 | AC15: 11.6 | AD15: 51.5 | AI15: 100.6 | AJ15: 89.8 | AN15: 6.4 | AO15: 147.8 | AP15: 51.8 | AQ15: 76.8 | AR15: 29 | AS15: 18.3 | AT15: 18.8 | AU15: 91.7 | AY15: 106.2 | AZ15: 5.5 | BA15: 9.3 | BB15: 18.5 | BC15: 41.8 | BD15: 2 | BE15: 12 | BF15: 80.2 | BI15: 56.3 | BL15: 47.9 | BP15: 70.5 | BQ15: 10 | BR15: 115.9 | BS15: 200 | BT15: 149.5 | CC15: 4 | CD15: 98.7 | CE15: 85.1 | CF15: 64.8 | CG15: 47.9 | CH15: 30.1 | CL15: 145.9 | CM15: 147 | CN15: 149.1 | CT15: 0 | CU15: 0 | CV15: 0 | CW15: 41.8 | CX15: 0 | CY15: 0 | CZ15: 0 | DA15: 17.4 | DB15: 20.8 | DC15: 9.9 | DD15: 5.4 | DE15: 0 | DF15: 0.9 | DG15: 3.5 | DH15: 4.5 | DJ15: 16.8 | DK15: 18.9 | DL15: 3.6 | DM15: 18.6 | DN15: 0 | DO15: 0 | DP15: 11.2 | DQ15: 27 | DR15: 0 | DS15: 3.5 | DT15: 14.8 | DU15: 2.5 | DW15: 10.1 | DX15: 7.4 | DY15: 15 | DZ15: 20.2 | EA15: 20 | EB15: 10.1 | EC15: 28.9 | ED15: 0 | EE15: 55 | EF15: 51.3 | EG15: 4.2 | EH15: 3.3 | EI15: 20.7 | EJ15: 6 | EK15: 7.1 | EL15: 18.2 | EM15: 18.6 | EN15: 18.9 | EO15: 0 | EP15: 0 | EQ15: 0 | ER15: 0 | ES15: 0.6 | ET15: 34.5 | EU15: 24.5 | EV15: 0 | EW15: 2.9 | EX15: 1.1 | EY15: 2.4 | EZ15: 1.1 | FA15: 0 | FB15: 6.354 | FC15: 20.046 | FD15: 9.2 | FF15: 0 | FG15: 15.8 | FH15: 17.5 | FI15: 8.2 | FK15: 6076.1 | FM15: 21.6 | FN15: 0 | FO15: 5.9 | FP15: 13.2 | FQ15: 27.3 | FR15: 18.6 | FS15: 5.292 | FT15: 4.314 | FU15: 96.206
A16: 27/10/2025 | B16: 03:00 | C16: 143.8 | D16: 626 | E16: 212.2 | H16: 89.2 | I16: 73.2 | L16: 183.6 | M16: 185.2 | N16: 185.1 | O16: 277.9 | P16: 214 | Q16: 110.2 | R16: 364.5 | S16: 5.1 | X16: 161 | Y16: 7.2 | Z16: 6 | AB16: 6.9 | AC16: 11.6 | AD16: 49.6 | AI16: 99.1 | AJ16: 89.8 | AN16: 6.4 | AO16: 146.4 | AP16: 51.7 | AQ16: 75.9 | AR16: 27 | AS16: 18.2 | AT16: 18.8 | AU16: 86.9 | AY16: 105.3 | AZ16: 5.5 | BA16: 9.1 | BB16: 17.3 | BC16: 40.4 | BD16: 2 | BE16: 11.7 | BF16: 74.6 | BI16: 54 | BL16: 47.9 | BP16: 69.3 | BQ16: 10.1 | BR16: 172.6 | BS16: 200 | BT16: 180.5 | CC16: 4 | CD16: 100.9 | CE16: 81.9 | CF16: 63.5 | CG16: 43.4 | CH16: 29.8 | CL16: 146.4 | CM16: 147.2 | CN16: 149.5 | CT16: 0 | CU16: 0 | CV16: 0 | CW16: 46.7 | CX16: 0 | CY16: 0.9 | CZ16: 0 | DA16: 17.5 | DB16: 20.7 | DC16: 9.9 | DD16: 5.4 | DE16: 0 | DF16: 0.9 | DG16: 3.5 | DH16: 4.5 | DJ16: 17.2 | DK16: 18.9 | DL16: 3.6 | DM16: 18.6 | DN16: 0 | DO16: 0 | DP16: 10.7 | DQ16: 30.6 | DR16: 0 | DS16: 3.5 | DT16: 14.5 | DU16: 2.6 | DW16: 10 | DX16: 7.4 | DY16: 14.4 | DZ16: 20.1 | EA16: 20 | EB16: 7.9 | EC16: 15 | ED16: 0 | EE16: 48.8 | EF16: 47.6 | EG16: 3 | EH16: 4.6 | EI16: 20.5 | EJ16: 6 | EK16: 7.1 | EL16: 18.2 | EM16: 18.6 | EN16: 18.9 | EO16: 1.2 | EP16: 0 | EQ16: 0 | ER16: 0 | ES16: 0.6 | ET16: 38.7 | EU16: 27.5 | EV16: 0 | EW16: 2.9 | EX16: 1.1 | EY16: 2.4 | EZ16: 1.1 | FA16: 0 | FB16: 6.348 | FC16: 20.029 | FD16: 9.5 | FF16: 0 | FG16: 15 | FH16: 17.5 | FI16: 8.9 | FK16: 5970.477 | FM16: 21.8 | FN16: 0 | FO16: 5.9 | FP16: 13.2 | FQ16: 27.3 | FR16: 17.8 | FS16: 5.361 | FT16: 4.274 | FU16: 95.635
A17: 27/10/2025 | B17: 03:30 | C17: 152.8 | D17: 638 | E17: 215.9 | H17: 91.8 | I17: 160 | L17: 175.5 | M17: 175.5 | N17: 175.9 | O17: 261.5 | P17: 212.7 | Q17: 110 | R17: 384.4 | S17: 5.3 | X17: 170.9 | Y17: 8.4 | Z17: 6.3 | AB17: 6.9 | AC17: 10.8 | AD17: 51.5 | AI17: 103.7 | AJ17: 89.6 | AN17: 6.5 | AO17: 11.8 | AP17: 52 | AQ17: 105 | AR17: 29.3 | AS17: 18.2 | AT17: 18.8 | AU17: 89.6 | AY17: 109 | AZ17: 5.5 | BA17: 9.1 | BB17: 22.1 | BC17: 42.5 | BD17: 2 | BE17: 12.2 | BF17: 81.3 | BI17: 57.3 | BL17: 47.9 | BP17: 70.6 | BQ17: 9.8 | BR17: 172.9 | BS17: 200 | BT17: 181 | CC17: 4 | CD17: 154.9 | CE17: 91.1 | CF17: 65.5 | CG17: 42.2 | CH17: 30.7 | CL17: 145.7 | CM17: 146.7 | CN17: 148.4 | CT17: 0 | CU17: 0 | CV17: 0 | CW17: 45.9 | CX17: 0 | CY17: 0.8 | CZ17: 0 | DA17: 17.5 | DB17: 20.9 | DC17: 9.9 | DD17: 5.5 | DE17: 0 | DF17: 0.8 | DG17: 3.5 | DH17: 4.4 | DJ17: 17.9 | DK17: 18.9 | DL17: 3.6 | DM17: 18.6 | DN17: 0 | DO17: 0 | DP17: 9.5 | DQ17: 27 | DR17: 0 | DS17: 3.5 | DT17: 14.5 | DU17: 2.6 | DW17: 10.1 | DX17: 7.4 | DY17: 14.7 | DZ17: 20.2 | EA17: 20 | EB17: 9.3 | EC17: 11 | ED17: 0 | EE17: 52.2 | EF17: 52.7 | EG17: 5.7 | EH17: 2.6 | EI17: 20.5 | EJ17: 6 | EK17: 7.2 | EL17: 18.2 | EM17: 18.4 | EN17: 18.7 | EO17: 1.4 | EP17: 0 | EQ17: 0 | ER17: 0 | ES17: 0.6 | ET17: 35.2 | EU17: 23.9 | EV17: 0 | EW17: 2.9 | EX17: 1.1 | EY17: 2.4 | EZ17: 1.1 | FA17: 0 | FB17: 6.313 | FC17: 20.022 | FD17: 8.9 | FF17: 0 | FG17: 15 | FH17: 17.5 | FI17: 8.6 | FK17: 6056.135 | FM17: 21.9 | FN17: 0 | FO17: 5.9 | FP17: 13.2 | FQ17: 27.3 | FR17: 18.6 | FS17: 5.365 | FT17: 4.305 | FU17: 96.57
A18: 27/10/2025 | B18: 04:00 | C18: 145.2 | D18: 635.3 | E18: 215.7 | H18: 89.7 | I18: 218 | L18: 176.8 | M18: 176.8 | N18: 177.2 | O18: 264.5 | P18: 214.3 | Q18: 110.4 | R18: 379.3 | S18: 5.2 | X18: 168 | Y18: 7.8 | Z18: 6.2 | AB18: 6.9 | AC18: 11 | AD18: 51 | AI18: 102.5 | AJ18: 89.5 | AN18: 6.4 | AO18: 0 | AP18: 52.4 | AQ18: 134.7 | AR18: 29.3 | AS18: 18.2 | AT18: 18.8 | AU18: 90.8 | AY18: 106.2 | AZ18: 5.5 | BA18: 9.1 | BB18: 18.2 | BC18: 41.3 | BD18: 2 | BE18: 12 | BF18: 77 | BI18: 56 | BL18: 48.2 | BP18: 70.4 | BQ18: 10.7 | BR18: 174.7 | BS18: 200 | BT18: 180.9 | CC18: 4 | CD18: 118.1 | CE18: 88.9 | CF18: 64.7 | CG18: 42 | CH18: 30.4 | CL18: 147 | CM18: 147.7 | CN18: 150.2 | CT18: 0 | CU18: 0 | CV18: 0 | CW18: 43.3 | CX18: 0 | CY18: 0.3 | CZ18: 0 | DA18: 17.6 | DB18: 20.7 | DC18: 9.9 | DD18: 5.4 | DE18: 0 | DF18: 0.8 | DG18: 3.5 | DH18: 4.4 | DJ18: 18.3 | DK18: 18.9 | DL18: 3.6 | DM18: 18.6 | DN18: 0 | DO18: 0 | DP18: 10.7 | DQ18: 33.6 | DR18: 0 | DS18: 3.5 | DT18: 14.7 | DU18: 2.6 | DW18: 10.1 | DX18: 7.4 | DY18: 14.4 | DZ18: 20.2 | EA18: 20 | EB18: 11.9 | EC18: 12.6 | ED18: 0 | EE18: 59.2 | EF18: 52.6 | EG18: 7.1 | EH18: 3.4 | EI18: 20.5 | EJ18: 6 | EK18: 7.2 | EL18: 18.2 | EM18: 18.4 | EN18: 18.7 | EO18: 0.7 | EP18: 0 | EQ18: 0 | ER18: 0 | ES18: 0.6 | ET18: 27.3 | EU18: 24.3 | EV18: 0 | EW18: 2.9 | EX18: 1.1 | EY18: 2.4 | EZ18: 1.1 | FA18: 0 | FB18: 6.354 | FC18: 20.012 | FD18: 8.8 | FF18: 0 | FG18: 15 | FH18: 17.5 | FI18: 8.2 | FK18: 6081.666 | FM18: 22.1 | FN18: 0 | FO18: 5.9 | FP18: 13.2 | FQ18: 27.4 | FR18: 18.6 | FS18: 5.373 | FT18: 4.294 | FU18: 96.867
A19: 27/10/2025 | B19: 04:30 | C19: 148.7 | D19: 633.1 | E19: 215.3 | H19: 90.2 | I19: 214.5 | L19: 175.8 | M19: 175.2 | N19: 175.1 | O19: 266.5 | P19: 213.8 | Q19: 110.4 | R19: 378.1 | S19: 5.2 | X19: 167.7 | Y19: 7.8 | Z19: 6.1 | AB19: 6.9 | AC19: 11 | AD19: 51 | AI19: 102.3 | AJ19: 89.2 | AN19: 6.4 | AO19: 0 | AP19: 52.5 | AQ19: 142.3 | AR19: 29.6 | AS19: 18.2 | AT19: 18.8 | AU19: 92.3 | AY19: 106 | AZ19: 5.5 | BA19: 9.1 | BB19: 24.5 | BC19: 40.1 | BD19: 2 | BE19: 12 | BF19: 76.6 | BI19: 55.8 | BL19: 47.9 | BP19: 70.2 | BQ19: 10.1 | BR19: 174.2 | BS19: 200 | BT19: 181.5 | CC19: 4 | CD19: 119.8 | CE19: 88.9 | CF19: 62.5 | CG19: 46.7 | CH19: 30.3 | CL19: 146.4 | CM19: 147.5 | CN19: 149.2 | CT19: 0 | CU19: 0 | CV19: 0 | CW19: 30.1 | CX19: 0 | CY19: 0 | CZ19: 0 | DA19: 17.7 | DB19: 20.7 | DC19: 9.9 | DD19: 5.6 | DE19: 0 | DF19: 0.8 | DG19: 3.5 | DH19: 4.4 | DJ19: 18.5 | DK19: 18.9 | DL19: 3.6 | DM19: 18.6 | DN19: 0 | DO19: 0 | DP19: 12.6 | DQ19: 24.1 | DR19: 0 | DS19: 3.5 | DT19: 14.5 | DU19: 2.6 | DW19: 9.9 | DX19: 7.6 | DY19: 14.4 | DZ19: 19.8 | EA19: 20 | EB19: 12.7 | EC19: 9 | ED19: 0 | EE19: 53.8 | EF19: 49.1 | EG19: 5.2 | EH19: 2.6 | EI19: 20.4 | EJ19: 6 | EK19: 7.2 | EL19: 18.2 | EM19: 18.8 | EN19: 18.8 | EO19: 0 | EP19: 0 | EQ19: 0 | ER19: 0 | ES19: 0.6 | ET19: 19.3 | EU19: 16.1 | EV19: 0 | EW19: 2.9 | EX19: 1.1 | EY19: 2.4 | EZ19: 1.1 | FA19: 0 | FB19: 6.348 | FC19: 19.987 | FD19: 9.2 | FF19: 0 | FG19: 15.9 | FH19: 17.5 | FI19: 9 | FK19: 6039.335 | FM19: 22.1 | FN19: 0 | FO19: 5.9 | FP19: 13.2 | FQ19: 27.3 | FR19: 18.6 | FS19: 5.323 | FT19: 4.266 | FU19: 96.689
A20: 27/10/2025 | B20: 05:00 | C20: 201.8 | D20: 632.8 | E20: 215 | H20: 90.2 | I20: 215.2 | L20: 185.7 | M20: 192.4 | N20: 192.8 | O20: 280 | P20: 213 | Q20: 110.7 | R20: 378.2 | S20: 5.2 | X20: 166.5 | Y20: 7.8 | Z20: 6.1 | AB20: 7 | AC20: 11.1 | AD20: 59.4 | AI20: 102.3 | AJ20: 120.4 | AN20: 6.4 | AO20: 0 | AP20: 53.8 | AQ20: 145.6 | AR20: 29.3 | AS20: 18.2 | AT20: 18.8 | AU20: 92.2 | AY20: 106.5 | AZ20: 5.5 | BA20: 9.1 | BB20: 35.3 | BC20: 40.1 | BD20: 2 | BE20: 12 | BF20: 76.7 | BI20: 82.8 | BL20: 48 | BP20: 70.1 | BQ20: 10.4 | BR20: 174.3 | BS20: 200 | BT20: 182 | CC20: 4 | CD20: 197 | CE20: 88.9 | CF20: 62.5 | CG20: 47.2 | CH20: 30.2 | CL20: 146.7 | CM20: 147.6 | CN20: 149.6 | CT20: 0 | CU20: 0 | CV20: 0 | CW20: 30.8 | CX20: 0 | CY20: 0 | CZ20: 0 | DA20: 17.7 | DB20: 20.7 | DC20: 9.9 | DD20: 5.3 | DE20: 0 | DF20: 1 | DG20: 3.5 | DH20: 4.3 | DJ20: 18.5 | DK20: 18.9 | DL20: 3.6 | DM20: 18.6 | DN20: 0 | DO20: 0 | DP20: 10.9 | DQ20: 23.4 | DR20: 0 | DS20: 3.5 | DT20: 14.9 | DU20: 2.6 | DW20: 9.9 | DX20: 7.8 | DY20: 14.4 | DZ20: 19.4 | EA20: 20 | EB20: 13.5 | EC20: 9.5 | ED20: 0 | EE20: 23.4 | EF20: 30.8 | EG20: 2.7 | EH20: 1.3 | EI20: 20 | EJ20: 5.6 | EK20: 7.2 | EL20: 18.2 | EM20: 18.9 | EN20: 18.8 | EO20: 0 | EP20: 0 | EQ20: 0 | ER20: 0 | ES20: 0.6 | ET20: 12.7 | EU20: 11.9 | EV20: 0 | EW20: 2.9 | EX20: 1.1 | EY20: 2.4 | EZ20: 1.1 | FA20: 0 | FB20: 6.346 | FC20: 20.026 | FD20: 8.9 | FF20: 0 | FG20: 15.5 | FH20: 17.5 | FI20: 9.1 | FK20: 6245.972 | FM20: 22.1 | FN20: 0 | FO20: 5.8 | FP20: 13.2 | FQ20: 27.3 | FR20: 14.5 | FS20: 5.319 | FT20: 4.313 | FU20: 92.532
A21: 27/10/2025 | B21: 05:30 | C21: 202.5 | D21: 632.9 | E21: 215.4 | H21: 90.1 | I21: 216.1 | L21: 185.5 | M21: 201.5 | N21: 201.3 | O21: 284.9 | P21: 213.7 | Q21: 110.1 | R21: 378.7 | S21: 5.2 | X21: 166.1 | Y21: 7.9 | Z21: 5.9 | AB21: 6.9 | AC21: 11.2 | AD21: 90.6 | AI21: 102.5 | AJ21: 136.2 | AN21: 6.4 | AO21: 0 | AP21: 53.8 | AQ21: 147.4 | AR21: 29.4 | AS21: 18.2 | AT21: 18.8 | AU21: 91.3 | AY21: 106.1 | AZ21: 5.5 | BA21: 9.1 | BB21: 35.2 | BC21: 40.3 | BD21: 2 | BE21: 12 | BF21: 76.9 | BI21: 82.8 | BL21: 48 | BP21: 70.1 | BQ21: 30.3 | BR21: 174.5 | BS21: 200 | BT21: 182.6 | CC21: 4 | CD21: 231.2 | CE21: 88.8 | CF21: 62.5 | CG21: 47.2 | CH21: 30.2 | CL21: 146.7 | CM21: 147.6 | CN21: 149.5 | CT21: 10.303 | CU21: 0 | CV21: 0 | CW21: 26.1 | CX21: 1.4 | CY21: 0.2 | CZ21: 0 | DA21: 17.7 | DB21: 20.8 | DC21: 9.9 | DD21: 5.5 | DE21: 5.4 | DF21: 1.1 | DG21: 3.5 | DH21: 4.3 | DJ21: 18.6 | DK21: 18.8 | DL21: 3.6 | DM21: 18.6 | DN21: 0.5 | DO21: 0.4 | DP21: 9 | DQ21: 24.4 | DR21: 0.1 | DS21: 3.4 | DT21: 20.2 | DU21: 2.6 | DW21: 10.2 | DX21: 7.8 | DY21: 14.4 | DZ21: 19.4 | EA21: 20 | EB21: 17.5 | EC21: 9.3 | ED21: 1.1 | EE21: 18.3 | EF21: 18 | EG21: 2.1 | EH21: 0.9 | EI21: 20 | EJ21: 5.8 | EK21: 7.2 | EL21: 18.2 | EM21: 18.9 | EN21: 18.8 | EO21: 0.7 | EP21: 8 | EQ21: 0 | ER21: 5.9 | ES21: 0.6 | ET21: 6.2 | EU21: 3.5 | EV21: 5.4 | EW21: 2.9 | EX21: 1.1 | EY21: 2.4 | EZ21: 1.1 | FA21: 0 | FB21: 6.345 | FC21: 20.06 | FD21: 9.3 | FF21: 0 | FG21: 16 | FH21: 17.5 | FI21: 7.3 | FK21: 6382.208 | FM21: 22.1 | FN21: 0 | FO21: 5.8 | FP21: 13.2 | FQ21: 27.3 | FR21: 9.4 | FS21: 5.293 | FT21: 4.292 | FU21: 87.385
A22: 27/10/2025 | B22: 06:00 | C22: 199.2 | D22: 632.4 | E22: 215 | H22: 88.7 | I22: 217.6 | L22: 186.8 | M22: 190.4 | N22: 189.6 | O22: 280.9 | P22: 215 | Q22: 110.5 | R22: 377.2 | S22: 5.1 | X22: 164 | Y22: 7.6 | Z22: 5.8 | AB22: 6.9 | AC22: 11.8 | AD22: 90.3 | AI22: 109.9 | AJ22: 136.2 | AN22: 6.4 | AO22: 0 | AP22: 53.4 | AQ22: 136.1 | AR22: 30 | AS22: 18.3 | AT22: 18.8 | AU22: 90.2 | AY22: 105.5 | AZ22: 5.5 | BA22: 9.1 | BB22: 20.4 | BC22: 38.5 | BD22: 2 | BE22: 11.8 | BF22: 75.7 | BI22: 82.2 | BL22: 47.9 | BP22: 69.5 | BQ22: 53.7 | BR22: 175 | BS22: 200 | BT22: 181.4 | CC22: 4 | CD22: 152.3 | CE22: 87 | CF22: 61.5 | CG22: 47.3 | CH22: 30 | CL22: 147.1 | CM22: 148 | CN22: 149.9 | CT22: 10.268 | CU22: 0 | CV22: 0 | CW22: 33.9 | CX22: 6.6 | CY22: 0.5 | CZ22: 0 | DA22: 17.7 | DB22: 20.7 | DC22: 9.9 | DD22: 5.4 | DE22: 44.5 | DF22: 1.1 | DG22: 3.5 | DH22: 4.2 | DJ22: 19 | DK22: 18.9 | DL22: 3.6 | DM22: 18.6 | DN22: 1.4 | DO22: 1.4 | DP22: 9.2 | DQ22: 23 | DR22: 0.4 | DS22: 3.4 | DT22: 20.2 | DU22: 2.6 | DW22: 10.4 | DX22: 7.8 | DY22: 14.3 | DZ22: 19 | EA22: 20 | EB22: 18.6 | EC22: 10.7 | ED22: 9.9 | EE22: 15.3 | EF22: 17.8 | EG22: 1.7 | EH22: 0.6 | EI22: 19.9 | EJ22: 5.4 | EK22: 7.2 | EL22: 18.4 | EM22: 18.9 | EN22: 18.9 | EO22: 0.8 | EP22: 79 | EQ22: 0.8 | ER22: 44.4 | ES22: 0.6 | ET22: 5.2 | EU22: 5.1 | EV22: 38.4 | EW22: 2.9 | EX22: 1.1 | EY22: 2.4 | EZ22: 1.1 | FA22: 0.7 | FB22: 6.333 | FC22: 20.033 | FD22: 9.3 | FF22: 0 | FG22: 15.6 | FH22: 17.5 | FI22: 9.3 | FK22: 6474.734 | FM22: 22.1 | FN22: 0 | FO22: 5.8 | FP22: 13.2 | FQ22: 27.2 | FR22: 9.4 | FS22: 5.283 | FT22: 4.294 | FU22: 87.277
... A58: 28/10/2025 | B58: 00:00 | C58: 203.9 | D58: 625.7 | E58: 213.6 | H58: 89.9 | I58: 220.3 | L58: 131.7 | M58: 131.8 | N58: 131.7 | O58: 229.8 | P58: 215.3 | Q58: 110.3 | R58: 375.9 | S58: 10.4 | X58: 167.1 | Y58: 7.3 | Z58: 6 | AB58: 6.9 | AC58: 12.6 | AD58: 69.8 | AI58: 110.6 | AJ58: 153.8 | AN58: 6.5 | AO58: 150.7 | AP58: 50.5 | AQ58: 151.8 | AR58: 26.9 | AS58: 18.3 | AT58: 18.8 | AU58: 90.6 | AY58: 105.9 | AZ58: 5.7 | BA58: 8.4 | BB58: 17.6 | BC58: 41.3 | BD58: 2 | BE58: 25.6 | BF58: 80.8 | BI58: 59.5 | BL58: 0 | BP58: 127.1 | BQ58: 131.4 | BR58: 131.2 | BS58: 131 | BT58: 216.8 | CC58: 4 | CD58: 95 | CE58: 93 | CF58: 65.5 | CG58: 45.2 | CH58: 29.9 | CL58: 147.2 | CM58: 148.2 | CN58: 149.9 | CT58: 214.783 | CU58: 103.777 | CV58: 0 | CW58: 50.2 | CX58: 0 | CY58: 0 | CZ58: 0 | DA58: 20 | DB58: 20.7 | DC58: 9.9 | DD58: 5.3 | DE58: 0 | DF58: 1.1 | DG58: 3.5 | DH58: 4.2 | DJ58: 20 | DK58: 18.7 | DL58: 3.5 | DM58: 18.6 | DN58: 0 | DO58: 0 | DP58: 10 | DQ58: 26.2 | DR58: 0 | DS58: 2.9 | DT58: 17.2 | DU58: 2.8 | DW58: 11.8 | DX58: 8.8 | DY58: 13.4 | DZ58: 18.9 | EA58: 20 | EB58: 13 | EC58: 34.8 | ED58: 0 | EE58: 65.8 | EF58: 73.4 | EG58: 5.4 | EH58: 3.8 | EI58: 21 | EJ58: 7.2 | EK58: 7.3 | EL58: 20.4 | EM58: 20.4 | EN58: 20 | EO58: 0 | EP58: 0 | EQ58: 0 | ER58: 0 | ES58: 0.6 | ET58: 31.1 | EU58: 23 | EV58: 0 | EW58: 2.8 | EX58: 1.1 | EY58: 2.4 | EZ58: 1.1 | FA58: 0 | FB58: 6.315 | FC58: 20.012 | FD58: 8.9 | FF58: 34.4 | FG58: 14.8 | FH58: 13.1 | FI58: 8.1 | FK58: 6687.187 | FM58: 21.2 | FN58: 3.86 | FO58: 6 | FP58: 13.2 | FQ58: 27.2 | FR58: 9.4 | FS58: 4.635 | FT58: 7.207 | FU58: 92.702
A59: EJEC | C59: 4256.3 | D59: 15143.3 | E59: 5143 | F59: 0 | G59: 0 | H59: 2162.4 | I59: 4977.15 | J59: 0 | K59: 0 | L59: 3885.7 | M59: 3912.95 | N59: 3912.5 | O59: 6174.25 | P59: 5089 | Q59: 2639.05 | R59: 9016.85 | S59: 161 | T59: 0 | U59: 0 | V59: 0 | W59: 0 | X59: 3980.35 | Y59: 186.6 | Z59: 144.45 | AA59: 0 | AB59: 165.85 | AC59: 287.95 | AD59: 1898.05 | AE59: 0 | AF59: 0 | AG59: 0 | AH59: 0 | AI59: 2552.55 | AJ59: 3315.8 | AK59: 0 | AL59: 0 | AM59: 0 | AN59: 154.7 | AO59: 3015.35 | AP59: 1253.25 | AQ59: 3330.55 | AR59: 686.7 | AS59: 436.15 | AT59: 451.2 | AU59: 2163.1 | AV59: 0 | AW59: 0 | AX59: 0 | AY59: 2548.9 | AZ59: 133.1 | BA59: 216.7 | BB59: 508.55 | BC59: 992.7 | BD59: 48 | BE59: 392 | BF59: 1826.75 | BG59: 0 | BH59: 0 | BI59: 1595.1 | BJ59: 0 | BK59: 0 | BL59: 1067.75 | BM59: 0 | BN59: 0 | BO59: 0 | BP59: 2600.15 | BQ59: 2946.75 | BR59: 3547.25 | BS59: 4414.15 | BT59: 5333.4 | BU59: 0 | BV59: 0 | BW59: 0 | BX59: 0 | BY59: 0 | BZ59: 0 | CA59: 0 | CB59: 0 | CC59: 96 | CD59: 3666.05 | CE59: 2136.7 | CF59: 1535.85 | CG59: 1109.7 | CH59: 721.55 | CI59: 0 | CJ59: 0 | CK59: 0 | CL59: 3479.45 | CM59: 3496.95 | CN59: 3570.4 | CO59: 0 | CP59: 0 | CQ59: 0 | CR59: 0 | CS59: 0 | CT59: 3175.454 | CU59: 1423.6025 | CV59: 8.2 | CW59: 1277.1 | CX59: 814.75 | CY59: 20.65 | CZ59: 2.55 | DA59: 430.55 | DB59: 497.9 | DC59: 237.8 | DD59: 130.6 | DE59: 1348.95 | DF59: 26.45 | DG59: 84 | DH59: 105.15 | DI59: 0 | DJ59: 463.55 | DK59: 449.9 | DL59: 85.2 | DM59: 445.8 | DN59: 143.05 | DO59: 170.7 | DP59: 302.75 | DQ59: 915.7 | DR59: 147 | DS59: 79.25 | DT59: 385.55 | DU59: 62.7 | DV59: 0 | DW59: 285.15 | DX59: 190.25 | DY59: 336.75 | DZ59: 459.3 | EA59: 480.2 | EB59: 372.45 | EC59: 941.15 | ED59: 388.4 | EE59: 1395.7 | EF59: 1519.85 | EG59: 161.95 | EH59: 91.65 | EI59: 490.05 | EJ59: 163.8 | EK59: 172.6 | EL59: 475.4 | EM59: 477.95 | EN59: 470.9 | EO59: 35.25 | EP59: 2660.1 | EQ59: 142.2 | ER59: 1535.55 | ES59: 14.4 | ET59: 1134.15 | EU59: 1091.85 | EV59: 1145.5 | EW59: 66.05 | EX59: 14.45 | EY59: 55.75 | EZ59: 26.4 | FA59: 135.95 | FB59: 152.099 | FC59: 480.774 | FD59: 213.3 | FE59: 0 | FF59: 317.595 | FG59: 367.05 | FH59: 351.5 | FI59: 200 | FJ59: 0 | FK59: 170728.22 | FM59: 514.65 | FN59: 55.12 | FO59: 143.05 | FP59: 244.2 | FQ59: 644.3 | FR59: 268.85 | FS59: 113.7725 | FT59: 169.561 | FU59: 2153.5035

Sheet REACTIVA
B3: lunes, 27 de Octubre del 2025
A5: POTENCIA REACTIVA EJECUTADA DE LAS UNIDADES DE GENERACIÓN DEL COES (MVAR) | FM5: CENTRALES NO INTEGRANTES COES
A6: FECHA | B6: HORA | C6: 65333 | D6: 101 | E6: 102 | F6: 42667 | G6: 42668 | H6: 126 | I6: 127 | J6: 138 | K6: 139 | L6: 197 | M6: 203 | N6: 204 | O6: 230 | P6: 209 | Q6: 56677 | R6: 796 | S6: 2146 | T6: 142 | U6: 143 | V6: 125 | W6: 187 | X6: 163 | Y6: 298 | Z6: 299 | AA6: 219 | AB6: 151 | AC6: 152 | AD6: 153 | AE6: 154 | AF6: 756 | AG6: 156 | AH6: 155 | AI6: 182 | AJ6: 212 | AK6: 758 | AL6: 263 | AM6: 265 | AN6: 775 | AO6: 777 | AP6: 2154 | AQ6: 150 | AR6: 149 | AS6: 188 | AT6: 2131 | AU6: 755 | AV6: 252 | AW6: 249 | AX6: 250 | AY6: 117 | AZ6: 267 | BA6: 268 | BB6: 119 | BC6: 120 | BD6: 189 | BE6: 122 | BF6: 266 | BG6: 337 | BH6: 338 | BI6: 251 | BJ6: 115 | BK6: 239 | BL6: 288 | BM6: 240 | BN6: 241 | BO6: 242 | BP6: 191 | BQ6: 194 | BR6: 196 | BS6: 207 | BT6: 236 | BU6: 795 | BV6: 285 | BW6: 995 | BX6: 996 | BY6: 997 | BZ6: 766 | CA6: 926 | CB6: 924 | CC6: 121 | CD6: 103 | CE6: 104 | CF6: 106 | CG6: 105 | CH6: 107 | CI6: 110 | CJ6: 109 | CK6: 144 | CL6: 113 | CM6: 114 | CN6: 193 | CO6: 208 | CP6: 786 | CQ6: 787 | CR6: 788 | CS6: 789 | CT6: 248 | CU6: 2159 | CV6: 303 | CW6: 59715 | CX6: 62255 | CY6: 1263 | CZ6: 61800 | DA6: 2194 | DB6: 69125 | DC6: 216 | DD6: 198 | DE6: 70400 | DF6: 49607 | DG6: 214 | DH6: 260 | DI6: 2152 | DJ6: 2128 | DK6: 247 | DL6: 228 | DM6: 2135 | DN6: 261 | DO6: 237 | DP6: 253 | DQ6: 770 | DR6: 235 | DS6: 238 | DT6: 2184 | DU6: 61855 | DV6: 223 | DW6: 226 | DX6: 201 | DY6: 258 | DZ6: 259 | EA6: 920 | EB6: 257 | EC6: 256 | ED6: 2148 | EE6: 58288 | EF6: 58289 | EG6: 58839 | EH6: 58840 | EI6: 296 | EJ6: 297 | EK6: 211 | EL6: 2175 | EM6: 2178 | EN6: 2181 | EO6: 1262 | EP6: 63425 | EQ6: 233 | ER6: 2150 | ES6: 2165 | ET6: 2161 | EU6: 61197 | EV6: 58851 | EW6: 225 | EX6: 2201 | EY6: 2171 | EZ6: 760 | FA6: 234 | FB6: 215 | FC6: 917 | FD6: 289 | FE6: 58333 | FF6: 58336 | FG6: 213 | FH6: 232 | FI6: 2190 | FJ6: 69867 | FK6: TOTAL COES | FM6: 221 | FN6: 222 | FO6: 224 | FP6: 2187 | FQ6: 227 | FR6: 49400 | FS6: 199 | FT6: 200 | FU6: TOTAL NO COES
C7: SUR | D7: CENTRO | E7: CENTRO | F7: NORTE | G7: NORTE | H7: NORTE | I7: NORTE | J7: CENTRO | K7: CENTRO | L7: CENTRO | M7: CENTRO | N7: CENTRO | O7: CENTRO | P7: CENTRO | Q7: CENTRO | R7: CENTRO | S7: CENTRO | T7: CENTRO | U7: CENTRO | V7: CENTRO | W7: CENTRO | X7: SUR | Y7: SUR | Z7: SUR | AA7: CENTRO | AB7: SUR | AC7: SUR | AD7: SUR | AE7: SUR | AF7: SUR | AG7: SUR | AH7: SUR | AI7: SUR | AJ7: CENTRO | AK7: NORTE | AL7: NORTE | AM7: NORTE | AN7: CENTRO | AO7: CENTRO | AP7: CENTRO | AQ7: CENTRO | AR7: CENTRO | AS7: CENTRO | AT7: CENTRO | AU7: SUR | AV7: CENTRO | AW7: CENTRO | AX7: CENTRO | AY7: CENTRO | AZ7: CENTRO | BA7: CENTRO | BB7: CENTRO | BC7: CENTRO | BD7: SUR | BE7: NORTE | BF7: CENTRO | BG7: CENTRO | BH7: CENTRO | BI7: CENTRO | BJ7: NORTE | BK7: NORTE | BL7: NORTE | BM7: SUR | BN7: SUR | BO7: SUR | BP7: CENTRO | BQ7: CENTRO | BR7: CENTRO | BS7: CENTRO | BT7: CENTRO | BU7: CENTRO | BV7: CENTRO | BW7: SUR | BX7: SUR | BY7: SUR | BZ7: NORTE | CA7: SUR | CB7: CENTRO | CC7: NORTE | CD7: CENTRO | CE7: CENTRO | CF7: CENTRO | CG7: CENTRO | CH7: CENTRO | CI7: CENTRO | CJ7: CENTRO | CK7: CENTRO | CL7: CENTRO | CM7: CENTRO | CN7: CENTRO | CO7: CENTRO | CP7: SUR | CQ7: SUR | CR7: SUR | CS7: SUR | CT7: CENTRO | CU7: CENTRO | CV7: CENTRO | CW7: CENTRO | CX7: SUR | CY7: NORTE | CZ7: NORTE | DA7: NORTE | DB7: CENTRO | DC7: NORTE | DD7: NORTE | DE7: SUR | DF7: SUR | DG7: CENTRO | DH7: CENTRO | DI7: CENTRO | DJ7: NORTE | DK7: NORTE | DL7: CENTRO | DM7: CENTRO | DN7: SUR | DO7: SUR | DP7: CENTRO | DQ7: CENTRO | DR7: SUR | DS7: CENTRO | DT7: CENTRO | DU7: NORTE | DV7: CENTRO | DW7: CENTRO | DX7: NORTE | DY7: CENTRO | DZ7: CENTRO | EA7: CENTRO | EB7: NORTE | EC7: NORTE | ED7: SUR | EE7: CENTRO | EF7: CENTRO | EG7: CENTRO | EH7: CENTRO | EI7: CENTRO | EJ7: CENTRO | EK7: SUR | EL7: SUR | EM7: SUR | EN7: SUR | EO7: NORTE | EP7: SUR | EQ7: SUR | ER7: SUR | ES7: CENTRO | ET7: CENTRO | EU7: CENTRO | EV7: SUR | EW7: CENTRO | EX7: CENTRO | EY7: CENTRO | EZ7: CENTRO | FA7: SUR | FB7: NORTE | FC7: CENTRO | FD7: NORTE | FE7: NORTE | FF7: NORTE | FG7: CENTRO | FH7: NORTE | FI7: NORTE | FJ7: NORTE | FM7: NORTE | FN7: CENTRO | FO7: NORTE | FP7: NORTE | FQ7: NORTE | FR7: NORTE | FS7: NORTE | FT7: NORTE
C8: HIDROELÉCTRICA | D8: HIDROELÉCTRICA | E8: HIDROELÉCTRICA | F8: TERMOELÉCTRICA | G8: TERMOELÉCTRICA | H8: HIDROELÉCTRICA | I8: HIDROELÉCTRICA | J8: TERMOELÉCTRICA | K8: TERMOELÉCTRICA | L8: TERMOELÉCTRICA | M8: TERMOELÉCTRICA | N8: TERMOELÉCTRICA | O8: TERMOELÉCTRICA | P8: TERMOELÉCTRICA | Q8: TERMOELÉCTRICA | R8: HIDROELÉCTRICA | S8: HIDROELÉCTRICA | T8: TERMOELÉCTRICA | U8: TERMOELÉCTRICA | V8: TERMOELÉCTRICA | W8: TERMOELÉCTRICA | X8: HIDROELÉCTRICA | Y8: HIDROELÉCTRICA | Z8: HIDROELÉCTRICA | AA8: TERMOELÉCTRICA | AB8: HIDROELÉCTRICA | AC8: HIDROELÉCTRICA | AD8: HIDROELÉCTRICA | AE8: HIDROELÉCTRICA | AF8: TERMOELÉCTRICA | AG8: TERMOELÉCTRICA | AH8: TERMOELÉCTRICA | AI8: HIDROELÉCTRICA | AJ8: HIDROELÉCTRICA | AK8: TERMOELÉCTRICA | AL8: TERMOELÉCTRICA | AM8: TERMOELÉCTRICA | AN8: HIDROELÉCTRICA | AO8: HIDROELÉCTRICA | AP8: HIDROELÉCTRICA | AQ8: HIDROELÉCTRICA | AR8: HIDROELÉCTRICA | AS8: HIDROELÉCTRICA | AT8: HIDROELÉCTRICA | AU8: HIDROELÉCTRICA | AV8: TERMOELÉCTRICA | AW8: TERMOELÉCTRICA | AX8: TERMOELÉCTRICA | AY8: HIDROELÉCTRICA | AZ8: HIDROELÉCTRICA | BA8: HIDROELÉCTRICA | BB8: HIDROELÉCTRICA | BC8: HIDROELÉCTRICA | BD8: HIDROELÉCTRICA | BE8: HIDROELÉCTRICA | BF8: HIDROELÉCTRICA | BG8: HIDROELÉCTRICA | BH8: HIDROELÉCTRICA | BI8: HIDROELÉCTRICA | BJ8: TERMOELÉCTRICA | BK8: TERMOELÉCTRICA | BL8: TERMOELÉCTRICA | BM8: TERMOELÉCTRICA | BN8: TERMOELÉCTRICA | BO8: TERMOELÉCTRICA | BP8: HIDROELÉCTRICA | BQ8: TERMOELÉCTRICA | BR8: TERMOELÉCTRICA | BS8: TERMOELÉCTRICA | BT8: TERMOELÉCTRICA | BU8: TERMOELÉCTRICA | BV8: TERMOELÉCTRICA | BW8: TERMOELÉCTRICA | BX8: TERMOELÉCTRICA | BY8: TERMOELÉCTRICA | BZ8: HIDROELÉCTRICA | CA8: TERMOELÉCTRICA | CB8: TERMOELÉCTRICA | CC8: HIDROELÉCTRICA | CD8: HIDROELÉCTRICA | CE8: HIDROELÉCTRICA | CF8: HIDROELÉCTRICA | CG8: HIDROELÉCTRICA | CH8: HIDROELÉCTRICA | CI8: TERMOELÉCTRICA | CJ8: TERMOELÉCTRICA | CK8: TERMOELÉCTRICA | CL8: TERMOELÉCTRICA | CM8: TERMOELÉCTRICA | CN8: TERMOELÉCTRICA | CO8: TERMOELÉCTRICA | CP8: TERMOELÉCTRICA | CQ8: TERMOELÉCTRICA | CR8: TERMOELÉCTRICA | CS8: TERMOELÉCTRICA | CT8: TERMOELÉCTRICA | CU8: TERMOELÉCTRICA | CV8: SOLAR | CW8: EÓLICA | CX8: SOLAR | CY8: EÓLICA | CZ8: SOLAR | DA8: HIDROELÉCTRICA | DB8: HIDROELÉCTRICA | DC8: HIDROELÉCTRICA | DD8: HIDROELÉCTRICA | DE8: SOLAR | DF8: HIDROELÉCTRICA | DG8: HIDROELÉCTRICA | DH8: HIDROELÉCTRICA | DI8: HIDROELÉCTRICA | DJ8: HIDROELÉCTRICA | DK8: HIDROELÉCTRICA | DL8: HIDROELÉCTRICA | DM8: HIDROELÉCTRICA | DN8: SOLAR | DO8: SOLAR | DP8: EÓLICA | DQ8: EÓLICA | DR8: SOLAR | DS8: HIDROELÉCTRICA | DT8: HIDROELÉCTRICA | DU8: HIDROELÉCTRICA | DV8: HIDROELÉCTRICA | DW8: HIDROELÉCTRICA | DX8: HIDROELÉCTRICA | DY8: HIDROELÉCTRICA | DZ8: HIDROELÉCTRICA | EA8: HIDROELÉCTRICA | EB8: EÓLICA | EC8: EÓLICA | ED8: SOLAR | EE8: EÓLICA | EF8: EÓLICA | EG8: EÓLICA | EH8: EÓLICA | EI8: HIDROELÉCTRICA | EJ8: HIDROELÉCTRICA | EK8: HIDROELÉCTRICA | EL8: HIDROELÉCTRICA | EM8: HIDROELÉCTRICA | EN8: HIDROELÉCTRICA | EO8: EÓLICA | EP8: SOLAR | EQ8: SOLAR | ER8: SOLAR | ES8: HIDROELÉCTRICA | ET8: EÓLICA | EU8: EÓLICA | EV8: SOLAR | EW8: TERMOELÉCTRICA | EX8: TERMOELÉCTRICA | EY8: TERMOELÉCTRICA | EZ8: TERMOELÉCTRICA | FA8: SOLAR | FB8: HIDROELÉCTRICA | FC8: HIDROELÉCTRICA | FD8: TERMOELÉCTRICA | FE8: TERMOELÉCTRICA | FF8: TERMOELÉCTRICA | FG8: TERMOELÉCTRICA | FH8: TERMOELÉCTRICA | FI8: TERMOELÉCTRICA | FJ8: TERMOELÉCTRICA | FM8: HIDROELÉCTRICA | FN8: HIDROELÉCTRICA | FO8: HIDROELÉCTRICA | FP8: HIDROELÉCTRICA | FQ8: TERMOELÉCTRICA | FR8: TERMOELÉCTRICA | FS8: HIDROELÉCTRICA | FT8: HIDROELÉCTRICA
