Workbook

Sheet EVENTOS
B3: sábado, 26 de Abril del 2025
B5: INFORMACIÓN DE EVENTOS PRINCIPALES EN SUS INSTALACIONES
B6: TIPO DE EVENTO | C6: EMPRESA | D6: UBICACIÓN | E6: TIPO DE EQUIPO | F6: EQUIPO | G6: INICIO | H6: FINAL | I6: DESCRIPCIÓN | J6: MW INDISP. | K6: INTERRUPCIÓN (SI/NO) | L6: TENSIÓN DE FALLA (kV)
B7: EVENTO | C7: CONELSUR LT SAC | D7: PORTILLO | E7: SUBESTACION | F7: SS.EE. | G7: 26/04/2025 00:00:00 | H7: 27/04/2025 00:00:00 | I7: DECLARACIÓN DE SITUACIÓN EXCEPCIONAL EN LA S.E. PORTILLO DE 60 kV | K7: NO
B8: EVENTO | C8: ELECTRONOROESTE S.A. | D8: PIURA OESTE - SULLANA | E8: LINEA DE TRANSMISION | F8: L-6698 | G8: 26/04/2025 02:36:00 | H8: 26/04/2025 06:22:00 | I8: DESCONECTÓ LA LÍNEA L-6698 (PIURA OESTE - SULLANA) DE 60 KV | K8: NO
B9: FALLA | C9: KALLPA GENERACION S.A. | D9: MINI CENTRAL CERRO DEL AGUILA | E9: CENTRAL HIDROELÉCTRICA | F9: CENTRAL | G9: 26/04/2025 02:06:00 | H9: 26/04/2025 13:37:00 | I9: DESCONEXIÓN DE LA C.H. MINI CENTRAL CERRO DEL AGUILA POR FALLA | K9: NO | L9: 13.8
B10: EVENTO | C10: RED DE ENERGIA DEL PERU S.A. | D10: TINGO MARÍA - AUCAYACU | E10: LINEA DE TRANSMISION | F10: L-1122 | G10: 26/04/2025 08:40:00 | H10: 26/04/2025 15:45:00 | I10: DECLARACIÓN DE SITUACIÓN EXCEPCIONAL EN LA LÍNEA L-1122 (TINGO MARÍA - AUCAYACU) DE 138 kV | K10: NO
B11: EVENTO | C11: RED DE ENERGIA DEL PERU S.A. | D11: TINGO MARÍA - AUCAYACU | E11: LINEA DE TRANSMISION | F11: L-1122 | G11: 26/04/2025 18:20:00 | H11: 26/04/2025 20:57:00 | I11: DECLARACIÓN DE SITUACIÓN EXCEPCIONAL EN LA LÍNEA L-1122 (TINGO MARÍA - AUCAYACU) DE 138 kV | K11: NO
B12: FALLA | C12: STATKRAFT S.A | D12: MOROCOCHA - CARLOS FRANCISCO | E12: LINEA DE TRANSMISION | F12: L-6532 | G12: 26/04/2025 15:07:00 | H12: 26/04/2025 15:37:00 | I12: DESCONEXIÓN DE LAS LÍNEAS L-6532 Y L-6533 (NUEVA MOROCOCHA - CASAPALCA) DE 50 kV POR FALLA | K12: SI | L12: 50
B13: EVENTO | C13: ATLANTICA TRANSMISION SUR S.A. | D13: POROMA - OCONA | E13: LINEA DE TRANSMISION | F13: L-5034 | G13: 26/04/2025 11:20:00 | H13: 26/04/2025 16:12:00 | I13: DECLARACIÓN DE SITUACION EXCEPCIONAL EN EL ENLACE CENTRO - SUR | K13: NO

Sheet RESTRIC_OPE
B3: sábado, 26 de Abril del 2025
B5: RESTRICCIONES OPERATIVAS
B6: FECHA | C6: HORA INICIO | D6: HORA FINAL | E6: EMPRESA | F6: UBICACIÓN | G6: T.Eq. | H6: EQUIPO | I6: DESCRIPCIÓN
B7: 26/04/2025 | C7: 00:00 | D7: 24:00 | E7: CELEPSA | F7: C.H. EL PLATANAL | G7: CH | H7: CENTRAL | I7: Debido al incremento del caudal del rio cañete y establecimiento de la temporada de avenida, se declara la C.H. El Platanal como CENTRAL HIDRÁULICA DE PASADA (correo 03/01/2025).
B8: 26/04/2025 | C8: 00:00 | D8: 24:00 | E8: EGASA | F8: C.H. CHARCANI II | G8: GH | H8: G2 | I8: El Grupo N°02 esta operando con una potencia no mayor a 0.07MW en referencia a 0.18MW de su potencia efectiva, con el fin de no generar daños mayores hasta la reparación de su cojinete.
B9: 26/04/2025 | C9: 00:00 | D9: 24:00 | E9: EGASA | F9: S.E. CONVERTIDOR | G9: BARRA | H9: BARRA138KV | I9: EGASA limitó la capacidad del transformador 138 kV/33 kV a 50 MVA por deterioro del aislamiento.
B10: 26/04/2025 | C10: 00:00 | D10: 24:00 | E10: ENEL GENERACION PIURA S.A. | F10: C.T. MALACAS | G10: CT | H10: CENTRAL | I10: De acuerdo con la comunicación vía correo del día 24.10.2024. ENEL GENERACIÓN PIURA informa una restricción de potencia para alcanzar 105 MW en simultaneo (TG6+TGN4).
B11: 26/04/2025 | C11: 00:00 | D11: 24:00 | E11: ENEL GENERACION PIURA S.A. | F11: C.T. MALACAS | G11: CT | H11: CENTRAL | I11: La unidad TGN4 de la CT Malacas está limitada a 35 MW y no puede operar en conjunto con la TG6. Esto debido a que el ducto estará en mantenimiento, así como su compresor de GAS hasta el 05/05/2025.
B12: 26/04/2025 | C12: 00:00 | D12: 24:00 | E12: ENGIE | F12: C.E. PUNTA LOMITAS | G12: CE | H12: CENTRAL | I12: De acuerdo a la carta ENG/737-2024 (Exp:202400007555). Limitación de cables de media tensión a 100 MW de los transformadores PLT1 y PLT2 de la CE Punta Lomitas. Quedan limitados a 200 MW la generación de CE Punta Lomitas y Punta Lomitas Extensión.
B13: 26/04/2025 | C13: 00:00 | D13: 24:00 | E13: ENGIE | F13: C.H. QUITARACSA | G13: CH | H13: CENTRAL | I13: De acuerdo con el correo del 23.04 se considera la operación continua de la CH Quitaracsa debido a que el sistema de refrigeración de la CH Cañón del Pato se alimenta desde la descarga del caudal turbinado por la CH Quitaracsa.
B14: 26/04/2025 | C14: 00:00 | D14: 24:00 | E14: ENGIE | F14: C.H. YUNCÁN | G14: GH | H14: G3 | I14: Según la carta N° ENG/ 198-2024 enviada por su representada, se opera de forma continua el G3 de la CH Yuncán, debido a la ejecución de mantenimientos necesarios para evitar daños en los sellos de seguridad de la válvula esférica del grupo.
B15: 26/04/2025 | C15: 00:00 | D15: 24:00 | E15: ENGIE | F15: C.T. CHILCA 1 | G15: CT | H15: CENTRAL | I15: Con carta ENG/971-2023, indica que no puede cumplir con las IO considerada en el PDO_17122023 dado que vulneran la seguridad de sus activos. Indican que se debe tomar TMO=168h.
B16: 26/04/2025 | C16: 00:00 | D16: 24:00 | E16: ENGIE | F16: C.T. CHILCA 1 | G16: CT | H16: CENTRAL | I16: Restricción de temperatura de la C.T Chilca, ver valor en el modelo de despacho.
B17: 26/04/2025 | C17: 00:00 | D17: 24:00 | E17: ENGIE | F17: C.T. CHILCA 2 | G17: CT | H17: CENTRAL | I17: Restricción de temperatura de la C.T Chilca2, ver valor en el modelo de despacho.
... B48: 26/04/2025 | C48: 00:00 | D48: 24:00 | E48: TERMOSELVA | F48: C.T. AGUAYTÍA | G48: CT | H48: CENTRAL | I48: Restricción de 19 MMPCD de GN para la CT Aguaytía.

Sheet MANTENIMIENTO EJECUTADOS
B3: sábado, 26 de Abril del 2025
B5: Mantenimiento Ejecutado
B6: Empresa | C6: Ubicación | D6: Equipo | E6: Inicio | F6: Final | G6: Descripción | H6: MW Indisp. | I6: Prog. | J6: Dispon | K6: Interrupc. | L6: Tipo | M6: CodEq | N6: TipoEq_Osinerg
B7: AGROAURORA S.A.C. | C7: MAPLE ETANOL | D7: CENTRAL | E7: 26/04/2025 00:00 | F7: 27/04/2025 00:00 | G7: MANTENIMIENTO PREVENTIVO PROGRAMADO DE LA CENTRAL TERMOELECTRICA Y EQUIPOS AUXILIARES. | H7: 17 | I7: P | J7: F/S | K7: N | L7: OTROS | M7: 13417 | N7: G
B8: AGROAURORA S.A.C. | C8: MAPLE ETANOL | D8: CENTRAL | E8: 26/04/2025 00:00 | F8: 27/04/2025 00:00 | G8: CENTRAL TERMOELECTRICA FUERA DE SERVICIO POR FALTA DE MATERIA PRIMA PARA LOS REQUERIMIENTOS DE CALOR UTIL EN FABRICA | H8: 17 | I8: P | J8: F/S | K8: N | L8: OTROS | M8: 13417 | N8: G
B9: AGROINDUSTRIAS SAN JACINTO S.A.A. | C9: SAN JACINTO | D9: CENTRAL | E9: 26/04/2025 00:00 | F9: 27/04/2025 00:00 | G9: Mantenimiento Anual. | H9: 8.15 | I9: P | J9: F/S | K9: N | L9: PREV. | M9: 19865 | N9: G
B10: ATLANTICA TRANSMISION SUR S.A. | C10: CHILCA-CTM | D10: INT-5261 | E10: 26/04/2025 00:00 | F10: 27/04/2025 00:00 | G10: Seccionador SBB-5261 fase S indisponible para maniobras de apertura y cierre por anomalia en tapa de tanque de compresion, el seccionador permanece cerrado y bloqueado. | H10: 0 | I10: P | J10: E/S | K10: N | L10: OTROS | M10: 13854 | N10: T
B11: ATLANTICA TRANSMISION SUR S.A. | C11: MONTALVO | D11: ACOPLE 220 | E11: 26/04/2025 00:00 | F11: 27/04/2025 00:00 | G11: Proyecto Refuerzos: Reemplazo del HMI existente, Pruebas y Configuracion. No se contara con nivel 1 de operacion. | H11: 0 | I11: P | J11: E/S | K11: N | L11: P.ENERG | M11: 14767 | N11: T
B12: ATLANTICA TRANSMISION SUR S.A. | C12: MONTALVO | D12: BARRA A_220KV | E12: 26/04/2025 00:00 | F12: 27/04/2025 00:00 | G12: Proyecto Refuerzos: Indisponibilidad de la proteccion diferencial de barras 220 kV por Conexion de la nueva UB-87B hacia la UC existente,Configuracion y Pruebas. | H12: 0 | I12: P | J12: E/S | K12: N | L12: P.ENERG | M12: 13869 | N12: T
B13: ATLANTICA TRANSMISION SUR S.A. | C13: MONTALVO | D13: BARRA A_500KV | E13: 26/04/2025 00:00 | F13: 27/04/2025 00:00 | G13: Proyecto Refuerzos: Indisponibilidad de la proteccion diferencial de barras 500kV por conexion de nueva UB-87B hacia la UC existente, Configuracion y Pruebas. | H13: 0 | I13: P | J13: E/S | K13: N | L13: P.ENERG | M13: 13870 | N13: T
B14: ATLANTICA TRANSMISION SUR S.A. | C14: MONTALVO | D14: BARRA B_220kV | E14: 26/04/2025 00:00 | F14: 27/04/2025 00:00 | G14: Proyecto Refuerzos: Indisponibilidad de la proteccion diferencial de barras 220 kV por Conexion de la nueva UB-87B hacia la UC existente,Configuracion y Pruebas. | H14: 0 | I14: P | J14: E/S | K14: N | L14: P.ENERG | M14: 14765 | N14: T
B15: ATLANTICA TRANSMISION SUR S.A. | C15: MONTALVO | D15: BARRA B_500KV | E15: 26/04/2025 00:00 | F15: 27/04/2025 00:00 | G15: Proyecto Refuerzos: Indisponibilidad de la proteccion diferencial de barras 500kV por conexion de nueva UB-87B hacia la UC existente, Configuracion y Pruebas. | H15: 0 | I15: P | J15: E/S | K15: N | L15: P.ENERG | M15: 13871 | N15: T
B16: ATLANTICA TRANSMISION SUR S.A. | C16: MONTALVO | D16: CL-2057 | E16: 26/04/2025 00:00 | F16: 27/04/2025 00:00 | G16: Proyecto Refuerzos: Reemplazo del HMI existente, Pruebas y Configuracion. No se contara con nivel 1 de operacion. | H16: 0 | I16: P | J16: E/S | K16: N | L16: P.ENERG | M16: 13812 | N16: T
B17: ATLANTICA TRANSMISION SUR S.A. | C17: MONTALVO | D17: CL-AUT-5671_500 | E17: 26/04/2025 00:00 | F17: 27/04/2025 00:00 | G17: Proyecto Refuerzos: Reemplazo del HMI existente, Pruebas y Configuracion. No se contara con nivel 1 de operacion en INT-5671, INT-5652 y SAT-5671. | H17: 0 | I17: P | J17: E/S | K17: N | L17: P.ENERG | M17: 13809 | N17: T
B18: ATLANTICA TRANSMISION SUR S.A. | C18: MONTALVO | D18: INT-5652 | E18: 26/04/2025 00:00 | F18: 27/04/2025 00:00 | G18: Proyecto Refuerzos:Indisponible por Implementacion de conexion de corrientes, disparos, posiciones, enclavamientos hacia los equipos del nuevos Autotransformador. AUT-5671 en servicio solo por Barra A 500kV. | H18: 0 | I18: P | J18: F/S | K18: N | L18: P.ENERG | M18: 13765 | N18: T
... B163: TRANSMANTARO | C163: YARABAMBA | D163: IN-5120 | E163: 26/04/2025 00:00 | F163: 27/04/2025 00:00 | G163: INTERRUPTOR INDISPONIBLE POR FALLA EN LOS MANDOS DE CONTROL DE N1, N2 Y N3. | H163: 0 | I163: P | J163: F/S | K163: N | L163: OTROS | M163: 17437 | N163: T

Sheet INGRESO OC
A3: sábado, 26 de Abril del 2025
A5: INGRESO A OPERACIÓN COMERCIAL
A6: EMPRESA | B6: TIPO DE EQUIPO | C6: UBICACIÓN | D6: EQUIPO | E6: Fecha y hora de Ingreso a Operación Comercial

Sheet DESPACHO_EJECUTADO
B3: sábado, 26 de Abril del 2025
A5: POTENCIA ACTIVA EJECUTADA DE LAS UNIDADES DE GENERACIÓN DEL SEIN (MW) | FL5: CENTRALES NO INTEGRANTES COES
A6: FECHA | B6: HORA | C6: 337 | D6: 338 | E6: 65333 | F6: 101 | G6: 102 | H6: 42667 | I6: 42668 | J6: 126 | K6: 127 | L6: 138 | M6: 139 | N6: 197 | O6: 203 | P6: 204 | Q6: 230 | R6: 209 | S6: 56677 | T6: 796 | U6: 2146 | V6: 142 | W6: 143 | X6: 125 | Y6: 187 | Z6: 163 | AA6: 298 | AB6: 299 | AC6: 219 | AD6: 151 | AE6: 152 | AF6: 153 | AG6: 154 | AH6: 756 | AI6: 156 | AJ6: 155 | AK6: 182 | AL6: 212 | AM6: 758 | AN6: 263 | AO6: 265 | AP6: 775 | AQ6: 777 | AR6: 2154 | AS6: 150 | AT6: 149 | AU6: 188 | AV6: 2131 | AW6: 755 | AX6: 252 | AY6: 249 | AZ6: 250 | BA6: 117 | BB6: 267 | BC6: 268 | BD6: 119 | BE6: 120 | BF6: 189 | BG6: 122 | BH6: 266 | BI6: 251 | BJ6: 115 | BK6: 239 | BL6: 288 | BM6: 240 | BN6: 241 | BO6: 242 | BP6: 191 | BQ6: 194 | BR6: 196 | BS6: 207 | BT6: 236 | BU6: 795 | BV6: 285 | BW6: 995 | BX6: 996 | BY6: 997 | BZ6: 766 | CA6: 926 | CB6: 924 | CC6: 121 | CD6: 103 | CE6: 104 | CF6: 106 | CG6: 105 | CH6: 107 | CI6: 110 | CJ6: 109 | CK6: 144 | CL6: 113 | CM6: 114 | CN6: 193 | CO6: 208 | CP6: 786 | CQ6: 787 | CR6: 788 | CS6: 789 | CT6: 248 | CU6: 2159 | CV6: 303 | CW6: 59715 | CX6: 62255 | CY6: 1263 | CZ6: 61800 | DA6: 2194 | DB6: 216 | DC6: 198 | DD6: 49607 | DE6: 214 | DF6: 260 | DG6: 2152 | DH6: 2128 | DI6: 247 | DJ6: 228 | DK6: 2135 | DL6: 261 | DM6: 237 | DN6: 253 | DO6: 770 | DP6: 225 | DQ6: 2201 | DR6: 2171 | DS6: 760 | DT6: 235 | DU6: 238 | DV6: 2184 | DW6: 61855 | DX6: 223 | DY6: 226 | DZ6: 201 | EA6: 258 | EB6: 259 | EC6: 920 | ED6: 257 | EE6: 256 | EF6: 2148 | EG6: 58288 | EH6: 58289 | EI6: 58839 | EJ6: 58840 | EK6: 296 | EL6: 297 | EM6: 211 | EN6: 2175 | EO6: 2178 | EP6: 2181 | EQ6: 1262 | ER6: 63425 | ES6: 233 | ET6: 2150 | EU6: 2165 | EV6: 2161 | EW6: 61197 | EX6: 58851 | EY6: 234 | EZ6: 215 | FA6: 917 | FB6: 289 | FC6: 58333 | FD6: 58336 | FE6: 202 | FF6: 58487 | FG6: 213 | FH6: 232 | FI6: 2190 | FJ6: TOTAL COES | FL6: 221 | FM6: 222 | FN6: 224 | FO6: 2187 | FP6: 227 | FQ6: 49400 | FR6: 199 | FS6: 200 | FT6: TOTAL NO COES
C7: CENTRO | D7: CENTRO | E7: SUR | F7: CENTRO | G7: CENTRO | H7: NORTE | I7: NORTE | J7: NORTE | K7: NORTE | L7: CENTRO | M7: CENTRO | N7: CENTRO | O7: CENTRO | P7: CENTRO | Q7: CENTRO | R7: CENTRO | S7: CENTRO | T7: CENTRO | U7: CENTRO | V7: CENTRO | W7: CENTRO | X7: CENTRO | Y7: CENTRO | Z7: SUR | AA7: SUR | AB7: SUR | AC7: CENTRO | AD7: SUR | AE7: SUR | AF7: SUR | AG7: SUR | AH7: SUR | AI7: SUR | AJ7: SUR | AK7: SUR | AL7: CENTRO | AM7: NORTE | AN7: NORTE | AO7: NORTE | AP7: CENTRO | AQ7: CENTRO | AR7: CENTRO | AS7: CENTRO | AT7: CENTRO | AU7: CENTRO | AV7: CENTRO | AW7: SUR | AX7: CENTRO | AY7: CENTRO | AZ7: CENTRO | BA7: CENTRO | BB7: CENTRO | BC7: CENTRO | BD7: CENTRO | BE7: CENTRO | BF7: SUR | BG7: NORTE | BH7: CENTRO | BI7: CENTRO | BJ7: NORTE | BK7: NORTE | BL7: NORTE | BM7: SUR | BN7: SUR | BO7: SUR | BP7: CENTRO | BQ7: CENTRO | BR7: CENTRO | BS7: CENTRO | BT7: CENTRO | BU7: CENTRO | BV7: CENTRO | BW7: SUR | BX7: SUR | BY7: SUR | BZ7: NORTE | CA7: SUR | CB7: CENTRO | CC7: NORTE | CD7: CENTRO | CE7: CENTRO | CF7: CENTRO | CG7: CENTRO | CH7: CENTRO | CI7: CENTRO | CJ7: CENTRO | CK7: CENTRO | CL7: CENTRO | CM7: CENTRO | CN7: CENTRO | CO7: CENTRO | CP7: SUR | CQ7: SUR | CR7: SUR | CS7: SUR | CT7: CENTRO | CU7: CENTRO | CV7: CENTRO | CW7: CENTRO | CX7: SUR | CY7: NORTE | CZ7: NORTE | DA7: NORTE | DB7: NORTE | DC7: NORTE | DD7: SUR | DE7: CENTRO | DF7: CENTRO | DG7: CENTRO | DH7: NORTE | DI7: NORTE | DJ7: CENTRO | DK7: CENTRO | DL7: SUR | DM7: SUR | DN7: CENTRO | DO7: CENTRO | DP7: CENTRO | DQ7: CENTRO | DR7: CENTRO | DS7: CENTRO | DT7: SUR | DU7: CENTRO | DV7: CENTRO | DW7: NORTE | DX7: CENTRO | DY7: CENTRO | DZ7: NORTE | EA7: CENTRO | EB7: CENTRO | EC7: CENTRO | ED7: NORTE | EE7: NORTE | EF7: SUR | EG7: CENTRO | EH7: CENTRO | EI7: CENTRO | EJ7: CENTRO | EK7: CENTRO | EL7: CENTRO | EM7: SUR | EN7: SUR | EO7: SUR | EP7: SUR | EQ7: NORTE | ER7: SUR | ES7: SUR | ET7: SUR | EU7: CENTRO | EV7: CENTRO | EW7: CENTRO | EX7: SUR | EY7: SUR | EZ7: NORTE | FA7: CENTRO | FB7: NORTE | FC7: NORTE | FD7: NORTE | FE7: CENTRO | FF7: CENTRO | FG7: CENTRO | FH7: NORTE | FI7: NORTE | FL7: NORTE | FM7: CENTRO | FN7: NORTE | FO7: NORTE | FP7: NORTE | FQ7: NORTE | FR7: NORTE | FS7: NORTE
C8: HIDROELÉCTRICA | D8: HIDROELÉCTRICA | E8: HIDROELÉCTRICA | F8: HIDROELÉCTRICA | G8: HIDROELÉCTRICA | H8: TERMOELÉCTRICA | I8: TERMOELÉCTRICA | J8: HIDROELÉCTRICA | K8: HIDROELÉCTRICA | L8: TERMOELÉCTRICA | M8: TERMOELÉCTRICA | N8: TERMOELÉCTRICA | O8: TERMOELÉCTRICA | P8: TERMOELÉCTRICA | Q8: TERMOELÉCTRICA | R8: TERMOELÉCTRICA | S8: TERMOELÉCTRICA | T8: HIDROELÉCTRICA | U8: HIDROELÉCTRICA | V8: TERMOELÉCTRICA | W8: TERMOELÉCTRICA | X8: TERMOELÉCTRICA | Y8: TERMOELÉCTRICA | Z8: HIDROELÉCTRICA | AA8: HIDROELÉCTRICA | AB8: HIDROELÉCTRICA | AC8: TERMOELÉCTRICA | AD8: HIDROELÉCTRICA | AE8: HIDROELÉCTRICA | AF8: HIDROELÉCTRICA | AG8: HIDROELÉCTRICA | AH8: TERMOELÉCTRICA | AI8: TERMOELÉCTRICA | AJ8: TERMOELÉCTRICA | AK8: HIDROELÉCTRICA | AL8: HIDROELÉCTRICA | AM8: TERMOELÉCTRICA | AN8: TERMOELÉCTRICA | AO8: TERMOELÉCTRICA | AP8: HIDROELÉCTRICA | AQ8: HIDROELÉCTRICA | AR8: HIDROELÉCTRICA | AS8: HIDROELÉCTRICA | AT8: HIDROELÉCTRICA | AU8: HIDROELÉCTRICA | AV8: HIDROELÉCTRICA | AW8: HIDROELÉCTRICA | AX8: TERMOELÉCTRICA | AY8: TERMOELÉCTRICA | AZ8: TERMOELÉCTRICA | BA8: HIDROELÉCTRICA | BB8: HIDROELÉCTRICA | BC8: HIDROELÉCTRICA | BD8: HIDROELÉCTRICA | BE8: HIDROELÉCTRICA | BF8: HIDROELÉCTRICA | BG8: HIDROELÉCTRICA | BH8: HIDROELÉCTRICA | BI8: HIDROELÉCTRICA | BJ8: TERMOELÉCTRICA | BK8: TERMOELÉCTRICA | BL8: TERMOELÉCTRICA | BM8: TERMOELÉCTRICA | BN8: TERMOELÉCTRICA | BO8: TERMOELÉCTRICA | BP8: HIDROELÉCTRICA | BQ8: TERMOELÉCTRICA | BR8: TERMOELÉCTRICA | BS8: TERMOELÉCTRICA | BT8: TERMOELÉCTRICA | BU8: TERMOELÉCTRICA | BV8: TERMOELÉCTRICA | BW8: TERMOELÉCTRICA | BX8: TERMOELÉCTRICA | BY8: TERMOELÉCTRICA | BZ8: HIDROELÉCTRICA | CA8: TERMOELÉCTRICA | CB8: TERMOELÉCTRICA | CC8: HIDROELÉCTRICA | CD8: HIDROELÉCTRICA | CE8: HIDROELÉCTRICA | CF8: HIDROELÉCTRICA | CG8: HIDROELÉCTRICA | CH8: HIDROELÉCTRICA | CI8: TERMOELÉCTRICA | CJ8: TERMOELÉCTRICA | CK8: TERMOELÉCTRICA | CL8: TERMOELÉCTRICA | CM8: TERMOELÉCTRICA | CN8: TERMOELÉCTRICA | CO8: TERMOELÉCTRICA | CP8: TERMOELÉCTRICA | CQ8: TERMOELÉCTRICA | CR8: TERMOELÉCTRICA | CS8: TERMOELÉCTRICA | CT8: TERMOELÉCTRICA | CU8: TERMOELÉCTRICA | CV8: SOLAR | CW8: EÓLICA | CX8: SOLAR | CY8: EÓLICA | CZ8: SOLAR | DA8: HIDROELÉCTRICA | DB8: HIDROELÉCTRICA | DC8: HIDROELÉCTRICA | DD8: HIDROELÉCTRICA | DE8: HIDROELÉCTRICA | DF8: HIDROELÉCTRICA | DG8: HIDROELÉCTRICA | DH8: HIDROELÉCTRICA | DI8: HIDROELÉCTRICA | DJ8: HIDROELÉCTRICA | DK8: HIDROELÉCTRICA | DL8: SOLAR | DM8: SOLAR | DN8: EÓLICA | DO8: EÓLICA | DP8: TERMOELÉCTRICA | DQ8: TERMOELÉCTRICA | DR8: TERMOELÉCTRICA | DS8: TERMOELÉCTRICA | DT8: SOLAR | DU8: HIDROELÉCTRICA | DV8: HIDROELÉCTRICA | DW8: HIDROELÉCTRICA | DX8: HIDROELÉCTRICA | DY8: HIDROELÉCTRICA | DZ8: HIDROELÉCTRICA | EA8: HIDROELÉCTRICA | EB8: HIDROELÉCTRICA | EC8: HIDROELÉCTRICA | ED8: EÓLICA | EE8: EÓLICA | EF8: SOLAR | EG8: EÓLICA | EH8: EÓLICA | EI8: EÓLICA | EJ8: EÓLICA | EK8: HIDROELÉCTRICA | EL8: HIDROELÉCTRICA | EM8: HIDROELÉCTRICA | EN8: HIDROELÉCTRICA | EO8: HIDROELÉCTRICA | EP8: HIDROELÉCTRICA | EQ8: EÓLICA | ER8: SOLAR | ES8: SOLAR | ET8: SOLAR | EU8: HIDROELÉCTRICA | EV8: EÓLICA | EW8: EÓLICA | EX8: SOLAR | EY8: SOLAR | EZ8: HIDROELÉCTRICA | FA8: HIDROELÉCTRICA | FB8: TERMOELÉCTRICA | FC8: TERMOELÉCTRICA | FD8: TERMOELÉCTRICA | FE8: TERMOELÉCTRICA | FF8: TERMOELÉCTRICA | FG8: TERMOELÉCTRICA | FH8: TERMOELÉCTRICA | FI8: TERMOELÉCTRICA | FL8: HIDROELÉCTRICA | FM8: HIDROELÉCTRICA | FN8: HIDROELÉCTRICA | FO8: HIDROELÉCTRICA | FP8: TERMOELÉCTRICA | FQ8: TERMOELÉCTRICA | FR8: HIDROELÉCTRICA | FS8: HIDROELÉCTRICA
C9: CENTRALES SANTA ROSA S.A.C. | D9: CENTRALES SANTA ROSA S.A.C. | E9: HYDRO GLOBAL PERÚ S.A.C. | F9: ELECTROPERU | G9: ELECTROPERU | H9: ELECTROPERU | I9: ELECTROPERU | J9: ORAZUL ENERGY PERÚ | K9: ORAZUL ENERGY PERÚ | L9: TERMOSELVA | M9: TERMOSELVA | N9: KALLPA GENERACION S.A. | O9: KALLPA GENERACION S.A. | P9: KALLPA GENERACION S.A. | Q9: KALLPA GENERACION S.A. | R9: KALLPA GENERACION S.A. | S9: KALLPA GENERACION S.A. | T9: KALLPA GENERACION S.A. | U9: KALLPA GENERACION S.A. | V9: SHOUGESA | W9: SHOUGESA | X9: SHOUGESA | Y9: SHOUGESA | Z9: EGEMSA | AA9: EGESUR | AB9: EGESUR | AC9: EGESUR | AD9: EGASA | AE9: EGASA | AF9: EGASA | AG9: EGASA | AH9: EGASA | AI9: EGASA | AJ9: EGASA | AK9: SAN GABAN | AL9: CELEPSA | AM9: MINERA CERRO VERDE | AN9: PLANTA DE RESERVA FRIA DE GENERACION DE ETEN S.A. | AO9: PLANTA DE RESERVA FRIA DE GENERACION DE ETEN S.A. | AP9: EMPRESA DE GENERACION HUALLAGA | AQ9: EMPRESA DE GENERACION HUALLAGA | AR9: LA VIRGEN | AS9: CHINANGO S.A.C. | AT9: CHINANGO S.A.C. | AU9: HIDROELECTRICA HUANCHOR S.A.C. | AV9: CELEPSA RENOVABLES S.R.L. | AW9: INLAND ENERGY SAC | AX9: FENIX POWER PERÚ | AY9: FENIX POWER PERÚ | AZ9: FENIX POWER PERÚ | BA9: STATKRAFT S.A | BB9: STATKRAFT S.A | BC9: STATKRAFT S.A | BD9: STATKRAFT S.A | BE9: STATKRAFT S.A | BF9: STATKRAFT S.A | BG9: STATKRAFT S.A | BH9: STATKRAFT S.A | BI9: EMPRESA DE GENERACION HUANZA | BJ9: ENEL GENERACION PIURA S.A. | BK9: ENEL GENERACION PIURA S.A. | BL9: ENEL GENERACION PIURA S.A. | BM9: ENGIE | BN9: ENGIE | BO9: ENGIE | BP9: ENGIE | BQ9: ENGIE | BR9: ENGIE | BS9: ENGIE | BT9: ENGIE | BU9: ENGIE | BV9: ENGIE | BW9: ENGIE | BX9: ENGIE | BY9: ENGIE | BZ9: ENGIE | CA9: INFRAESTRUCTURAS Y ENERGIAS DEL PERU S.A.C. | CB9: INFRAESTRUCTURAS Y ENERGIAS DEL PERU S.A.C. | CC9: INVERSIONES SHAQSHA S.A.C. | CD9: ORYGEN PERU S.A.A. | CE9: ORYGEN PERU S.A.A. | CF9: ORYGEN PERU S.A.A. | CG9: ORYGEN PERU S.A.A. | CH9: ORYGEN PERU S.A.A. | CI9: ORYGEN PERU S.A.A. | CJ9: ORYGEN PERU S.A.A. | CK9: ORYGEN PERU S.A.A. | CL9: ORYGEN PERU S.A.A. | CM9: ORYGEN PERU S.A.A. | CN9: ORYGEN PERU S.A.A. | CO9: ORYGEN PERU S.A.A. | CP9: SAMAY I S.A.C | CQ9: SAMAY I S.A.C | CR9: SAMAY I S.A.C | CS9: SAMAY I S.A.C | CT9: TERMOCHILCA S.A.C. | CU9: TERMOCHILCA S.A.C. | CV9: COLCA SOLAR S.A.C. | CW9: ENERGIA RENOVABLE DEL SUR S.A. | CX9: GR CORTARRAMA SOCIEDAD ANONIMA CERRADA | CY9: GR TARUCA SOCIEDAD ANONIMA CERRADA | CZ9: KONDU SAC | DA9: PERUANA DE INVERSIONES EN ENERGIAS RENOVABLES S.A. | DB9: ORAZUL ENERGY PERÚ | DC9: ORAZUL ENERGY PERÚ | DD9: SAN GABAN | DE9: MAJA ENERGIA S.A.C. | DF9: EMPRESA DE GENERACION ELECTRICA CANCHAYLLO SAC | DG9: EMPRESA DE GENERACION ELECTRICA SANTA ANA S.A.C. | DH9: EMPRESA ELECTRICA AGUA AZUL | DI9: EMPRESA ELECTRICA RIO DOBLE | DJ9: HIDROCAÑETE S.A. | DK9: HUAURA POWER GROUP S.A. | DL9: MOQUEGUA FV S.A.C. | DM9: PANAMERICANA SOLAR SAC. | DN9: PARQUE EOLICO MARCONA S.A.C. | DO9: PARQUE EOLICO TRES HERMANAS S.A.C. | DP9: PETRAMAS | DQ9: PETRAMAS | DR9: PETRAMAS | DS9: PETRAMAS | DT9: TACNA SOLAR SAC. | DU9: ELECTRICA YANAPAMPA SAC | DV9: ANDEAN POWER S.A.C. | DW9: ASOCIACIÓN SANTA LUCIA DE CHACAS | DX9: ATRIA ENERGIA S.A.C. | DY9: EGEJUNIN | DZ9: EGEJUNIN | EA9: EGEJUNIN | EB9: EGEJUNIN | EC9: EMPRESA DE GENERACION ELECTRICA RIO BAÑOS S.A.C. | ED9: ENERGÍA EÓLICA S.A. | EE9: ENERGÍA EÓLICA S.A. | EF9: ENGIE | EG9: ENGIE | EH9: ENGIE | EI9: ENGIE | EJ9: ENGIE | EK9: GENERACIÓN ANDINA S.A.C. | EL9: GENERACIÓN ANDINA S.A.C. | EM9: GENERADORA DE ENERGÍA DEL PERÚ | EN9: GENERADORA DE ENERGÍA DEL PERÚ | EO9: GENERADORA DE ENERGÍA DEL PERÚ | EP9: GENERADORA DE ENERGÍA DEL PERÚ | EQ9: GR PAINO SOCIEDAD ANONIMA CERRADA | ER9: JOYA SOLAR S.A.C. | ES9: MAJES ARCUS S.A.C. | ET9: ORYGEN PERU S.A.A. | EU9: ORYGEN PERU S.A.A. | EV9: ORYGEN PERU S.A.A. | EW9: ORYGEN PERU S.A.A. | EX9: ORYGEN PERU S.A.A. | EY9: REPARTICIÓN ARCUS S.A.C. | EZ9: SINERSA | FA9: SINERSA | FB9: BIOENERGIA DEL CHIRA S.A. | FC9: GM OPERACIONES S.A.C. | FD9: GM OPERACIONES S.A.C. | FE9: SDF ENERGIA SAC | FF9: SDF ENERGIA SAC | FG9: AGRO INDUSTRIAL PARAMONGA S.A. | FH9: AGROAURORA S.A.C. | FI9: AGROINDUSTRIAS SAN JACINTO S.A.A. | FL9: UNACEM PERU S.A. | FM9: ELECTRO ORIENTE | FN9: AGUAS Y ENERGIA PERU | FO9: ELECTRO ZAÑA S.A.C. | FP9: ELECTRONOROESTE S.A. | FQ9: SDE PIURA | FR9: SINERSA | FS9: SINERSA
C10: SANTA ROSA 1 | D10: SANTA ROSA 2 | E10: SAN GABAN III | F10: MANTARO | G10: RESTITUCION | H10: TUMBES MAK 1 | I10: TUMBES MAK 2 | J10: CARHUAQUERO | K10: CAÑON DEL PATO | L10: AGUAYTIA TG1 | M10: AGUAYTIA TG2 | N10: KALLPA TG1 | O10: KALLPA TG2 | P10: KALLPA TG3 | Q10: KALLPA TV | R10: LFLORES TG1 | S10: LFLORES TV | T10: CERRO DEL AGUILA | U10: CERRODELAGUILAG4 | V10: SHOUGESA TV1 | W10: SHOUGESA TV2 | X10: SHOUGESA TV3 | Y10: SHOUGESA CUMMINS | Z10: MACHUPICCHU | AA10: ARICOTA 1 | AB10: ARICOTA 2 | AC10: INDEPENDENCIA | AD10: CHARCANI I,II,III | AE10: CHARCANI IV | AF10: CHARCANI V | AG10: CHARCANI VI | AH10: CHILINA TG | AI10: MOLLENDO 1, 2, 3 | AJ10: CHILINA (SULZ 1,2) | AK10: SAN GABAN II | AL10: PLATANAL | AM10: RECKA | AN10: RF ETEN TG1 | AO10: RF ETEN TG2 | AP10: CHAGLLA GP1 | AQ10: CHAGLLA | AR10: LA VIRGEN | AS10: CHIMAY | AT10: YANANGO | AU10: HUANCHOR | AV10: MARAÑON | AW10: STA TERESA | AX10: FENIX GT11 | AY10: FENIX GT12 | AZ10: FENIX TV10 | BA10: YAUPI | BB10: OROYA | BC10: PACHACHACA | BD10: MALPASO | BE10: CAHUA | BF10: ARCATA | BG10: GALLITO CIEGO | BH10: CHEVES | BI10: HUANZA | BJ10: MALACAS2 TG4 | BK10: MALACAS3 TG 5 | BL10: MALACAS1 TG6 | BM10: RF ILO2 TG1 | BN10: RF ILO2 TG2 | BO10: RF ILO2 TG3 | BP10: YUNCAN | BQ10: CHILCA1 TG1 | BR10: CHILCA1 TG2 | BS10: CHILCA1 TG3 | BT10: CHILCA-TV | BU10: CHILCA2 TG41 | BV10: CHILCA2-TV | BW10: CTNEPI_TG41 | BX10: CTNEPI_TG42 | BY10: CTNEPI_TG43 | BZ10: QUITARACSA | CA10: RF PTO MALDONADO | CB10: RF PUCALLPA | CC10: PARIAC | CD10: HUINCO | CE10: MATUCANA | CF10: MOYOPAMPA | CG10: CALLAHUANCA | CH10: HUAMPANI | CI10: STA ROSA WEST TG7 | CJ10: UTI_5 | CK10: UTI_6 | CL10: VENTANILLA 3 | CM10: VENTANILLA 4 | CN10: VENTANILLA TV | CO10: STAROSA TG8 | CP10: PTO_BRVO TG1 | CQ10: PTO_BRVO TG2 | CR10: PTO_BRVO TG3 | CS10: PTO_BRVO TG4 | CT10: OLLEROS TG1 | CU10: OLLEROS TV | CV10: CS YARUCAYA | CW10: SAN JUAN | CX10: MATARANI | CY10: DUNA | CZ10: CARHUAQUERO (CS) | DA10: MANTA I | DB10: CARHUAQUERO4 | DC10: CAÑA BRAVA | DD10: TUPURI | DE10: RONCADOR | DF10: CANCHAYLLO | DG10: RENOVANDESH1 | DH10: POTRERO | DI10: PIZARRAS | DJ10: NIMPERIAL | DK10: YARUCAYA | DL10: MOQUEGUA-SOLAR | DM10: PANAMERICANA-SOLAR | DN10: PQE-EOLICO-MARCONA | DO10: PQE-EOLICO-3-HERMANAS | DP10: HUAYCOLORO | DQ10: CALLAO | DR10: DONA_CATALINA | DS10: LAGRINGAV | DT10: TACNA-SOLAR | DU10: YANAPAMPA | DV10: CARHUAC | DW10: HUALLIN | DX10: PURMACANA | DY10: HUASAHUASI | DZ10: STACRUZ_1_2 | EA10: RUNATULLO_II | EB10: RUNATULLO_III | EC10: RUCUY | ED10: PQE-EOLICO-TALARA | EE10: PQE-EOLICO-CUPISNIQUE | EF10: INTIPAMPA | EG10: PUNTA LOMITAS-BL1 | EH10: PUNTA LOMITAS-BL2 | EI10: PUN LOMITAS_EXP-BL1 | EJ10: PUN LOMITAS_EXP-BL2 | EK10: 8AGOSTO | EL10: EL CARMEN | EM10: LA JOYA | EN10: ANGEL_I | EO10: ANGEL_II | EP10: ANGEL_III | EQ10: HUAMBOS | ER10: SAN MARTIN SOLAR | ES10: MAJES | ET10: RUBI | EU10: CH_HER1 | EV10: WAYRA-I | EW10: WAYRA EXTENSION | EX10: CLEMESI | EY10: REPARTICION | EZ10: POECHOS2 | FA10: CHANCAY | FB10: CANA BRAVA | FC10: REFINERIA TALARA TV1 | FD10: REFINERÍA TALARA TV2 | FE10: OQUENDO TG1 | FF10: OQUENDO TV1 | FG10: PARAMONGA | FH10: MAPLE | FI10: SAN_JACINTO | FJ10: MW | FL10: CARPAPATA | FM10: CENTRALES ELOR | FN10: PIAS1 | FO10: ZANA | FP10: TABLAZO | FQ10: TALLANCA | FR10: CURUMUY | FS10: POECHOS1 | FT10: MW
A11: 26/04/2025 | B11: 00:30 | E11: 102.55 | F11: 647.6 | G11: 214.9 | J11: 89.7 | K11: 167.3 | N11: 111.8 | O11: 111.7 | P11: 112.3 | Q11: 210.5 | R11: 110 | S11: 67.7 | T11: 559.5 | U11: 10.5 | Z11: 165.5 | AA11: 7.5 | AB11: 3.7 | AD11: 6.7 | AE11: 10.1 | AF11: 85 | AG11: 6.3 | AK11: 110.9 | AL11: 224.2 | AP11: 6.5 | AQ11: 466.5 | AR11: 76.6 | AS11: 148.6 | AT11: 42.4 | AU11: 18.7 | AV11: 19.7 | AW11: 89.6 | AX11: 0 | AZ11: 0 | BA11: 108.3 | BB11: 7.8 | BC11: 5.8 | BD11: 45.8 | BE11: 22.4 | BF11: 3.8 | BG11: 38.6 | BH11: 174.2 | BI11: 72.7 | BL11: 48.8 | BP11: 86.4 | BQ11: 92.6 | BR11: 0 | BS11: 101.3 | BT11: 125.1 | CC11: 4.6 | CD11: 218 | CE11: 129.5 | CF11: 65 | CG11: 80.4 | CH11: 30.1 | CL11: 103.8 | CM11: 103.9 | CN11: 121.4 | CV11: 0 | CW11: 95.8 | CX11: 0 | CY11: 0.8 | CZ11: 0 | DA11: 0 | DB11: 9.9 | DC11: 5.6 | DD11: 1.2 | DE11: 3.4 | DF11: 4.8 | DG11: 20.2 | DH11: 10.3 | DI11: 10.2 | DJ11: 3.6 | DK11: 9.3 | DL11: 0 | DM11: 0 | DN11: 25.2 | DO11: 68.6 | DP11: 4.4 | DQ11: 1.9 | DR11: 2.4 | DT11: 0 | DU11: 2.4 | DV11: 20.4 | DW11: 0 | DX11: 0 | DY11: 19.8 | DZ11: 9.7 | EA11: 16.1 | EB11: 20.3 | EC11: 20 | ED11: 4.9 | EE11: 36.7 | EF11: 0 | EG11: 66.2 | EH11: 90.5 | EI11: 9.6 | EJ11: 1.6 | EK11: 20.9 | EL11: 8.3 | EM11: 8.3 | EN11: 20.4 | EO11: 20.4 | EP11: 20.2 | EQ11: 1.2 | ER11: 0 | ES11: 0 | ET11: 0 | EU11: 0.6 | EV11: 40.5 | EW11: 29 | EX11: 0 | EY11: 0 | EZ11: 9.2 | FA11: 20 | FC11: 37.2 | FE11: 29.4 | FF11: 3.4 | FG11: 15 | FJ11: 6674.65 | FL11: 23.54426 | FM11: 0.631 | FO11: 13.16234 | FQ11: 18.91596 | FR11: 10.1 | FS11: 16.1 | FT11: 82.45356
A12: 26/04/2025 | B12: 01:00 | E12: 102.91 | F12: 647.3 | G12: 214.9 | J12: 75.4 | K12: 229.5 | N12: 99.8 | O12: 108 | P12: 108.2 | Q12: 207.8 | R12: 110.2 | S12: 67.2 | T12: 558.3 | U12: 10.5 | Z12: 163.7 | AA12: 7.4 | AB12: 3.7 | AD12: 6.7 | AE12: 10.1 | AF12: 85.5 | AG12: 6.3 | AK12: 111 | AL12: 223.5 | AP12: 6.5 | AQ12: 451.6 | AR12: 76 | AS12: 147 | AT12: 42.4 | AU12: 18.7 | AV12: 19.7 | AW12: 90 | AX12: 0 | AZ12: 0 | BA12: 108.6 | BB12: 7.5 | BC12: 5.8 | BD12: 45.8 | BE12: 22.4 | BF12: 3.8 | BG12: 38.4 | BH12: 174.5 | BI12: 22.5 | BL12: 48.7 | BP12: 86.5 | BQ12: 79.9 | BR12: 0 | BS12: 79.4 | BT12: 105.5 | CC12: 4.6 | CD12: 202.3 | CE12: 128.3 | CF12: 65 | CG12: 78.4 | CH12: 30.3 | CL12: 103.7 | CM12: 103.1 | CN12: 120.4 | CV12: 0 | CW12: 101.2 | CX12: 0 | CY12: 1.2 | CZ12: 0 | DA12: 0 | DB12: 9.9 | DC12: 5.4 | DD12: 1.2 | DE12: 3.4 | DF12: 5 | DG12: 20.4 | DH12: 10.9 | DI12: 10 | DJ12: 2.9 | DK12: 9.3 | DL12: 0 | DM12: 0 | DN12: 30.7 | DO12: 73.5 | DP12: 4.4 | DQ12: 1.9 | DR12: 2.4 | DT12: 0 | DU12: 2.4 | DV12: 16.8 | DW12: 0 | DX12: 0 | DY12: 19.8 | DZ12: 9.7 | EA12: 16.1 | EB12: 20.3 | EC12: 20 | ED12: 6.5 | EE12: 38.5 | EF12: 0 | EG12: 62.1 | EH12: 90.1 | EI12: 6.1 | EJ12: 0.2 | EK12: 20.9 | EL12: 8.3 | EM12: 8.3 | EN12: 20.4 | EO12: 20.4 | EP12: 20.2 | EQ12: 1 | ER12: 0 | ES12: 0 | ET12: 0 | EU12: 0.6 | EV12: 38.8 | EW12: 29.8 | EX12: 0 | EY12: 0 | EZ12: 9.2 | FA12: 20 | FC12: 38 | FE12: 29.4 | FF12: 3.4 | FG12: 15.1 | FJ12: 6561.31 | FL12: 23.54689 | FM12: 0 | FO12: 13.1761 | FQ12: 18.91529 | FR12: 10 | FS12: 16 | FT12: 81.63828
A13: 26/04/2025 | B13: 01:30 | E13: 104.04 | F13: 646.9 | G13: 214.5 | J13: 89.8 | K13: 229.6 | N13: 99.9 | O13: 108.8 | P13: 109 | Q13: 207.2 | R13: 109.1 | S13: 67.3 | T13: 558.6 | U13: 10.5 | Z13: 162.6 | AA13: 7.2 | AB13: 3.7 | AD13: 6.7 | AE13: 10.1 | AF13: 85.1 | AG13: 6.3 | AK13: 110.9 | AL13: 223.3 | AP13: 6.4 | AQ13: 368.4 | AR13: 76.5 | AS13: 134.8 | AT13: 42.5 | AU13: 18.7 | AV13: 19.7 | AW13: 89.3 | AX13: 0 | AZ13: 0 | BA13: 108.3 | BB13: 7.6 | BC13: 5.8 | BD13: 45.6 | BE13: 22.5 | BF13: 3.8 | BG13: 37.7 | BH13: 173.4 | BI13: 22.3 | BL13: 32.6 | BP13: 86.5 | BQ13: 85 | BR13: 0 | BS13: 84.4 | BT13: 107.5 | CC13: 4.6 | CD13: 186.4 | CE13: 117.5 | CF13: 65 | CG13: 78.4 | CH13: 30.2 | CL13: 104 | CM13: 104.3 | CN13: 120.8 | CV13: 0 | CW13: 107.7 | CX13: 0 | CY13: 0.5 | CZ13: 0 | DA13: 0 | DB13: 9.9 | DC13: 5.5 | DD13: 1.2 | DE13: 3.4 | DF13: 5 | DG13: 20.2 | DH13: 11.3 | DI13: 9.9 | DJ13: 3 | DK13: 9.3 | DL13: 0 | DM13: 0 | DN13: 30.4 | DO13: 75.5 | DP13: 0 | DQ13: 2 | DR13: 2.3 | DT13: 0 | DU13: 2.4 | DV13: 9.9 | DW13: 0 | DX13: 0 | DY13: 19.8 | DZ13: 9.7 | EA13: 16.1 | EB13: 20.3 | EC13: 20 | ED13: 13.7 | EE13: 48.2 | EF13: 0 | EG13: 58.7 | EH13: 93 | EI13: 6 | EJ13: 0.2 | EK13: 20.9 | EL13: 8.3 | EM13: 8.3 | EN13: 20.4 | EO13: 20.4 | EP13: 20.2 | EQ13: 0.1 | ER13: 0 | ES13: 0 | ET13: 0 | EU13: 0.6 | EV13: 35 | EW13: 24.2 | EX13: 0 | EY13: 0 | EZ13: 9.2 | FA13: 20 | FC13: 38.6 | FE13: 29.4 | FF13: 3.4 | FG13: 15 | FJ13: 6450.74 | FL13: 23.54199 | FM13: 0 | FO13: 13.17016 | FQ13: 18.91479 | FR13: 10.2 | FS13: 16 | FT13: 81.82694
A14: 26/04/2025 | B14: 02:00 | E14: 103.12 | F14: 647.3 | G14: 214.5 | J14: 90.6 | K14: 229.3 | N14: 99.7 | O14: 108.9 | P14: 108.7 | Q14: 207 | R14: 109.8 | S14: 67.6 | T14: 559.2 | U14: 10.5 | Z14: 165.7 | AA14: 7.4 | AB14: 3.7 | AD14: 6.7 | AE14: 10.1 | AF14: 85 | AG14: 6.3 | AK14: 111.1 | AL14: 223.5 | AP14: 6.4 | AQ14: 392.5 | AR14: 77 | AS14: 139.3 | AT14: 42.4 | AU14: 18.7 | AV14: 19.5 | AW14: 89.4 | AX14: 0 | AZ14: 0 | BA14: 109 | BB14: 7.6 | BC14: 5.8 | BD14: 46.3 | BE14: 22.6 | BF14: 3.8 | BG14: 38.1 | BH14: 174.5 | BI14: 22.6 | BL14: 25 | BP14: 86.5 | BQ14: 84.5 | BR14: 0 | BS14: 84.1 | BT14: 108.4 | CC14: 4.6 | CD14: 88.5 | CE14: 121.5 | CF14: 65.2 | CG14: 78.2 | CH14: 30.3 | CL14: 103.7 | CM14: 103.6 | CN14: 120.1 | CV14: 0 | CW14: 110 | CX14: 0 | CY14: 0.4 | CZ14: 0 | DA14: 0 | DB14: 9.9 | DC14: 5.5 | DD14: 1.2 | DE14: 3.4 | DF14: 4.9 | DG14: 20.4 | DH14: 12.8 | DI14: 9.9 | DJ14: 3.4 | DK14: 9.3 | DL14: 0 | DM14: 0 | DN14: 31 | DO14: 77.1 | DP14: 0 | DQ14: 2 | DR14: 2.3 | DT14: 0 | DU14: 2.4 | DV14: 10.2 | DW14: 0 | DX14: 0 | DY14: 19.8 | DZ14: 9.7 | EA14: 16 | EB14: 20.3 | EC14: 20 | ED14: 12.3 | EE14: 39.6 | EF14: 0 | EG14: 56.2 | EH14: 89 | EI14: 4.3 | EJ14: 1.2 | EK14: 20.9 | EL14: 8.3 | EM14: 8.5 | EN14: 20.4 | EO14: 20.4 | EP14: 20.2 | EQ14: 0.3 | ER14: 0 | ES14: 0 | ET14: 0 | EU14: 0.6 | EV14: 35.7 | EW14: 29 | EX14: 0 | EY14: 0 | EZ14: 9.2 | FA14: 20 | FC14: 38.7 | FE14: 29.4 | FF14: 3.4 | FG14: 15 | FJ14: 6379.92 | FL14: 23.54262 | FM14: 0 | FO14: 13.1715 | FQ14: 18.91437 | FR14: 10.2 | FS14: 15.9 | FT14: 81.72849
A15: 26/04/2025 | B15: 02:30 | E15: 103.47 | F15: 647.2 | G15: 214.7 | J15: 90.2 | K15: 229 | N15: 99.8 | O15: 109.3 | P15: 109.5 | Q15: 207 | R15: 109.9 | S15: 66.8 | T15: 560 | U15: 0 | Z15: 165.6 | AA15: 7.3 | AB15: 3.7 | AD15: 6.7 | AE15: 10.1 | AF15: 85.4 | AG15: 6.3 | AK15: 110.9 | AL15: 223.2 | AP15: 6.5 | AQ15: 305.6 | AR15: 77 | AS15: 126 | AT15: 42.5 | AU15: 18.7 | AV15: 19.1 | AW15: 91.4 | AX15: 0 | AZ15: 0 | BA15: 108.4 | BB15: 7.5 | BC15: 5.9 | BD15: 45.6 | BE15: 22.4 | BF15: 3.8 | BG15: 38 | BH15: 173.9 | BI15: 22.4 | BL15: 25.1 | BP15: 86.5 | BQ15: 85.1 | BR15: 0 | BS15: 85 | BT15: 108.6 | CC15: 4.6 | CD15: 120 | CE15: 110.2 | CF15: 65 | CG15: 78.4 | CH15: 30.2 | CL15: 104 | CM15: 104 | CN15: 120.8 | CV15: 0 | CW15: 110.3 | CX15: 0 | CY15: 0.7 | CZ15: 0 | DA15: 0 | DB15: 9.9 | DC15: 5.4 | DD15: 1.2 | DE15: 3.4 | DF15: 4.9 | DG15: 20.2 | DH15: 16.4 | DI15: 9.8 | DJ15: 3.5 | DK15: 9.3 | DL15: 0 | DM15: 0 | DN15: 31.5 | DO15: 78.6 | DP15: 0 | DQ15: 2 | DR15: 2.3 | DT15: 0 | DU15: 2.4 | DV15: 10.1 | DW15: 0 | DX15: 0 | DY15: 19.8 | DZ15: 9.7 | EA15: 16.1 | EB15: 20.3 | EC15: 20 | ED15: 10.5 | EE15: 48.2 | EF15: 0 | EG15: 52.9 | EH15: 82.1 | EI15: 4.6 | EJ15: 1.8 | EK15: 20.9 | EL15: 8.3 | EM15: 8.9 | EN15: 20.4 | EO15: 20.4 | EP15: 20.2 | EQ15: 0.6 | ER15: 0 | ES15: 0 | ET15: 0 | EU15: 0.6 | EV15: 46.1 | EW15: 36.5 | EX15: 0 | EY15: 0 | EZ15: 9.2 | FA15: 20 | FC15: 38.5 | FE15: 29.4 | FF15: 3.3 | FG15: 14.7 | FJ15: 6314.17 | FL15: 23.54305 | FM15: 0 | FO15: 13.1783 | FQ15: 18.91428 | FR15: 10.1 | FS15: 16 | FT15: 81.73563
A16: 26/04/2025 | B16: 03:00 | E16: 103.49 | F16: 647.3 | G16: 214.9 | J16: 88.4 | K16: 228.3 | N16: 110.4 | O16: 111.5 | P16: 110.5 | Q16: 212 | R16: 109.2 | S16: 68.2 | T16: 561.9 | U16: 0 | Z16: 165.4 | AA16: 7.2 | AB16: 3.7 | AD16: 6.7 | AE16: 10.1 | AF16: 85.5 | AG16: 6.3 | AK16: 110.8 | AL16: 223.9 | AP16: 6.4 | AQ16: 370.2 | AR16: 77.5 | AS16: 148.5 | AT16: 42.5 | AU16: 18.7 | AV16: 19 | AW16: 87.3 | AX16: 0 | AZ16: 0 | BA16: 108.5 | BB16: 7.5 | BC16: 5.9 | BD16: 45 | BE16: 45.9 | BF16: 3.8 | BG16: 37.2 | BH16: 173.5 | BI16: 22.2 | BL16: 25.2 | BP16: 86 | BQ16: 85.8 | BR16: 0 | BS16: 85.8 | BT16: 109.6 | CC16: 4.6 | CD16: 47.8 | CE16: 128.5 | CF16: 63.7 | CG16: 78.1 | CH16: 30.1 | CL16: 104.4 | CM16: 103.6 | CN16: 121.9 | CV16: 0 | CW16: 109.6 | CX16: 0 | CY16: 2.4 | CZ16: 0 | DA16: 0 | DB16: 9.9 | DC16: 5.5 | DD16: 1.2 | DE16: 3.4 | DF16: 4.9 | DG16: 20.3 | DH16: 18.3 | DI16: 9.8 | DJ16: 3.5 | DK16: 9.3 | DL16: 0 | DM16: 0 | DN16: 31.4 | DO16: 76 | DP16: 0 | DQ16: 2 | DR16: 2.3 | DT16: 0 | DU16: 2.4 | DV16: 10.1 | DW16: 0 | DX16: 0 | DY16: 19.8 | DZ16: 9.7 | EA16: 16 | EB16: 20.2 | EC16: 19.8 | ED16: 12.6 | EE16: 52 | EF16: 0 | EG16: 54.6 | EH16: 80.5 | EI16: 5 | EJ16: 1.3 | EK16: 20.9 | EL16: 8.3 | EM16: 8.9 | EN16: 20.4 | EO16: 20.4 | EP16: 20.2 | EQ16: 3.6 | ER16: 0 | ES16: 0 | ET16: 0 | EU16: 0.6 | EV16: 43.4 | EW16: 29.4 | EX16: 0 | EY16: 0 | EZ16: 9.2 | FA16: 19.8 | FC16: 38.7 | FE16: 29.4 | FF16: 3.3 | FG16: 14.8 | FJ16: 6385.49 | FL16: 23.54368 | FM16: 0 | FO16: 13.18072 | FQ16: 18.91448 | FR16: 0 | FS16: 16 | FT16: 71.63888
A17: 26/04/2025 | B17: 03:30 | E17: 103.37 | F17: 647.6 | G17: 214.8 | J17: 90.2 | K17: 229.3 | N17: 105.8 | O17: 106.9 | P17: 106.2 | Q17: 208 | R17: 110.4 | S17: 67.1 | T17: 559.6 | U17: 0 | Z17: 163 | AA17: 7.4 | AB17: 3.2 | AD17: 6.7 | AE17: 10.1 | AF17: 84.6 | AG17: 6.3 | AK17: 110.9 | AL17: 223.9 | AP17: 6.4 | AQ17: 397.7 | AR17: 77.4 | AS17: 138.8 | AT17: 42.4 | AU17: 18.7 | AV17: 19.4 | AW17: 91 | AX17: 29.9 | AZ17: 0 | BA17: 109.1 | BB17: 7.5 | BC17: 5.9 | BD17: 45.7 | BE17: 46 | BF17: 3.8 | BG17: 38 | BH17: 174 | BI17: 22.6 | BL17: 24.8 | BP17: 86.4 | BQ17: 85.2 | BR17: 0 | BS17: 84.7 | BT17: 107.9 | CC17: 4.6 | CD17: 37.1 | CE17: 121.6 | CF17: 63 | CG17: 78.2 | CH17: 30.2 | CL17: 104 | CM17: 104.3 | CN17: 121 | CV17: 0 | CW17: 111.2 | CX17: 0 | CY17: 3.7 | CZ17: 0 | DA17: 0 | DB17: 9.9 | DC17: 5.4 | DD17: 1.2 | DE17: 3.4 | DF17: 4.8 | DG17: 20.2 | DH17: 15.4 | DI17: 9.8 | DJ17: 3.4 | DK17: 9.3 | DL17: 0 | DM17: 0 | DN17: 31 | DO17: 75.4 | DP17: 0 | DQ17: 2 | DR17: 2.3 | DT17: 0 | DU17: 2.4 | DV17: 10.1 | DW17: 0 | DX17: 0 | DY17: 19.8 | DZ17: 9.7 | EA17: 16.1 | EB17: 20.3 | EC17: 20 | ED17: 11.7 | EE17: 51.7 | EF17: 0 | EG17: 53.2 | EH17: 79.3 | EI17: 4.7 | EJ17: 1.3 | EK17: 20.9 | EL17: 8.3 | EM17: 8.7 | EN17: 20.4 | EO17: 20.4 | EP17: 20.2 | EQ17: 4.8 | ER17: 0 | ES17: 0 | ET17: 0 | EU17: 0.6 | EV17: 45 | EW17: 35.6 | EX17: 0 | EY17: 0 | EZ17: 9.2 | FA17: 20 | FC17: 38.2 | FE17: 29.4 | FF17: 3.3 | FG17: 14.8 | FJ17: 6401.17 | FL17: 23.5429 | FM17: 0 | FO17: 13.1789 | FQ17: 18.91445 | FR17: 0 | FS17: 16 | FT17: 71.63625
A18: 26/04/2025 | B18: 04:00 | E18: 103.49 | F18: 649.2 | G18: 215 | J18: 92.4 | K18: 229.2 | N18: 105.5 | O18: 104.5 | P18: 104.2 | Q18: 205.6 | R18: 109.5 | S18: 66.2 | T18: 560.6 | U18: 0 | Z18: 165.5 | AA18: 7.6 | AB18: 3.6 | AD18: 6.7 | AE18: 10.1 | AF18: 85.5 | AG18: 6.2 | AK18: 111.1 | AL18: 224.1 | AP18: 6.5 | AQ18: 411.7 | AR18: 77.5 | AS18: 143.8 | AT18: 42.4 | AU18: 18.7 | AV18: 19.4 | AW18: 89 | AX18: 29.5 | AZ18: 0 | BA18: 109.7 | BB18: 7.6 | BC18: 5.9 | BD18: 46.1 | BE18: 46.2 | BF18: 3.8 | BG18: 39.2 | BH18: 174.2 | BI18: 22.9 | BL18: 25.1 | BP18: 86.9 | BQ18: 84.1 | BR18: 0 | BS18: 83.9 | BT18: 107.9 | CC18: 4.6 | CD18: 23.8 | CE18: 124.1 | CF18: 63.4 | CG18: 78.6 | CH18: 30.3 | CL18: 102.9 | CM18: 103.6 | CN18: 119.7 | CV18: 0 | CW18: 111.9 | CX18: 0 | CY18: 2.9 | CZ18: 0 | DA18: 0 | DB18: 10 | DC18: 5.5 | DD18: 1.2 | DE18: 3.4 | DF18: 4.8 | DG18: 20.1 | DH18: 16.8 | DI18: 9.8 | DJ18: 3.4 | DK18: 9.3 | DL18: 0 | DM18: 0 | DN18: 29.9 | DO18: 72.6 | DP18: 0 | DQ18: 2 | DR18: 2.3 | DT18: 0 | DU18: 2.4 | DV18: 10.1 | DW18: 0 | DX18: 0 | DY18: 19.7 | DZ18: 9.7 | EA18: 16 | EB18: 20.3 | EC18: 20 | ED18: 11.6 | EE18: 49.3 | EF18: 0 | EG18: 51.7 | EH18: 74.7 | EI18: 4.2 | EJ18: 0.9 | EK18: 20.9 | EL18: 8.3 | EM18: 8.7 | EN18: 20.4 | EO18: 20.4 | EP18: 20.2 | EQ18: 4.4 | ER18: 0 | ES18: 0 | ET18: 0 | EU18: 0.6 | EV18: 44.8 | EW18: 36.1 | EX18: 0 | EY18: 0 | EZ18: 9.2 | FA18: 20 | FC18: 38.2 | FE18: 29.4 | FF18: 3.3 | FG18: 15 | FJ18: 6395.19 | FL18: 23.54082 | FM18: 0 | FO18: 13.17978 | FQ18: 18.91436 | FR18: 0 | FS18: 16 | FT18: 71.63496
A19: 26/04/2025 | B19: 04:30 | E19: 103.23 | F19: 643.1 | G19: 214.7 | J19: 89.6 | K19: 227.9 | N19: 105.5 | O19: 105.7 | P19: 105.7 | Q19: 209 | R19: 109.9 | S19: 67.4 | T19: 554.1 | U19: 0 | Z19: 162.9 | AA19: 7.1 | AB19: 3.8 | AD19: 6.7 | AE19: 10.1 | AF19: 71 | AG19: 6.2 | AK19: 110.3 | AL19: 222.9 | AP19: 6.4 | AQ19: 389.2 | AR19: 77.5 | AS19: 142 | AT19: 42.4 | AU19: 18.7 | AV19: 19.3 | AW19: 89.7 | AX19: 29.4 | AZ19: 0 | BA19: 108.1 | BB19: 7.6 | BC19: 5.8 | BD19: 45.5 | BE19: 44.1 | BF19: 3.8 | BG19: 37.4 | BH19: 172.5 | BI19: 22.1 | BL19: 25 | BP19: 86.2 | BQ19: 84.9 | BR19: 0 | BS19: 84.6 | BT19: 107.6 | CC19: 4.6 | CD19: 48.9 | CE19: 120.2 | CF19: 62.6 | CG19: 78.2 | CH19: 29.9 | CL19: 104 | CM19: 103.8 | CN19: 120.9 | CV19: 0 | CW19: 111.1 | CX19: 0 | CY19: 2.9 | CZ19: 0 | DA19: 0 | DB19: 10 | DC19: 5.5 | DD19: 1.2 | DE19: 3.4 | DF19: 4.8 | DG19: 20 | DH19: 16.8 | DI19: 9.8 | DJ19: 3.3 | DK19: 9.3 | DL19: 0 | DM19: 0 | DN19: 30.4 | DO19: 71.2 | DP19: 0 | DQ19: 2 | DR19: 2.3 | DT19: 0 | DU19: 2.4 | DV19: 10.1 | DW19: 0 | DX19: 0 | DY19: 19.7 | DZ19: 9.7 | EA19: 15.8 | EB19: 20.2 | EC19: 20 | ED19: 12.5 | EE19: 57.6 | EF19: 0 | EG19: 35.1 | EH19: 63.9 | EI19: 2.7 | EJ19: 0.1 | EK19: 20.9 | EL19: 8.2 | EM19: 8.8 | EN19: 20.4 | EO19: 20.4 | EP19: 20.2 | EQ19: 3.6 | ER19: 0 | ES19: 0 | ET19: 0 | EU19: 0.6 | EV19: 43.5 | EW19: 38.3 | EX19: 0 | EY19: 0 | EZ19: 9.1 | FA19: 20 | FC19: 37.9 | FE19: 29.3 | FF19: 3.2 | FG19: 15 | FJ19: 6332.93 | FL19: 23.53726 | FM19: 0 | FO19: 13.14753 | FQ19: 18.9146 | FR19: 0 | FS19: 16 | FT19: 71.59939
A20: 26/04/2025 | B20: 05:00 | E20: 103.25 | F20: 651.7 | G20: 214.9 | J20: 90.2 | K20: 231.3 | N20: 120.7 | O20: 120.2 | P20: 120.4 | Q20: 209.9 | R20: 110.9 | S20: 66.8 | T20: 564.5 | U20: 0 | Z20: 166.6 | AA20: 7.9 | AB20: 4 | AD20: 6.7 | AE20: 10.1 | AF20: 69 | AG20: 6.3 | AK20: 110.8 | AL20: 224.1 | AP20: 6.4 | AQ20: 464.9 | AR20: 77.5 | AS20: 149.3 | AT20: 42.4 | AU20: 18.7 | AV20: 18.8 | AW20: 90 | AX20: 29.2 | AZ20: 0 | BA20: 109.5 | BB20: 7.5 | BC20: 5.8 | BD20: 46.6 | BE20: 35.4 | BF20: 3.8 | BG20: 38.7 | BH20: 175.5 | BI20: 22.9 | BL20: 0 | BP20: 86.6 | BQ20: 84.9 | BR20: 0 | BS20: 85.2 | BT20: 108.6 | CC20: 4.6 | CD20: 62 | CE20: 130.6 | CF20: 63.3 | CG20: 78.4 | CH20: 30.5 | CL20: 104.1 | CM20: 104.7 | CN20: 120.4 | CV20: 0 | CW20: 108.5 | CX20: 0 | CY20: 1.4 | CZ20: 0 | DA20: 0 | DB20: 9.9 | DC20: 5.5 | DD20: 1.2 | DE20: 3.4 | DF20: 4.9 | DG20: 20.5 | DH20: 16.8 | DI20: 9.9 | DJ20: 3.3 | DK20: 9.3 | DL20: 0 | DM20: 0 | DN20: 30.5 | DO20: 75.1 | DP20: 0 | DQ20: 2 | DR20: 2.3 | DT20: 0 | DU20: 2.4 | DV20: 10.1 | DW20: 0 | DX20: 0 | DY20: 19.7 | DZ20: 9.7 | EA20: 16.2 | EB20: 20.3 | EC20: 20 | ED20: 15.4 | EE20: 68.7 | EF20: 0 | EG20: 30.2 | EH20: 57.8 | EI20: 2 | EJ20: 0.7 | EK20: 20.9 | EL20: 8.1 | EM20: 8.7 | EN20: 20.4 | EO20: 20.4 | EP20: 20.2 | EQ20: 2.9 | ER20: 0 | ES20: 0 | ET20: 0 | EU20: 0.6 | EV20: 52.2 | EW20: 44.3 | EX20: 0 | EY20: 0 | EZ20: 9.2 | FA20: 20 | FC20: 36.9 | FE20: 29.3 | FF20: 3.3 | FG20: 14.5 | FJ20: 6506.65 | FL20: 23.53626 | FM20: 0 | FO20: 13.16941 | FQ20: 18.91436 | FR20: 0 | FS20: 16.1 | FT20: 71.72003
A21: 26/04/2025 | B21: 05:30 | E21: 103.25 | F21: 646.7 | G21: 215.7 | J21: 90.1 | K21: 229.1 | N21: 117.5 | O21: 118.1 | P21: 117.5 | Q21: 229.5 | R21: 110.9 | S21: 66.6 | T21: 549.4 | U21: 0 | Z21: 166 | AA21: 7.5 | AB21: 3.1 | AD21: 6.7 | AE21: 10.1 | AF21: 71 | AG21: 6.1 | AK21: 111 | AL21: 223.4 | AP21: 6.4 | AQ21: 465.6 | AR21: 77.4 | AS21: 148.2 | AT21: 42.7 | AU21: 18.7 | AV21: 18.9 | AW21: 92.7 | AX21: 35.8 | AZ21: 0 | BA21: 108.7 | BB21: 7.7 | BC21: 5.8 | BD21: 45.4 | BE21: 34.9 | BF21: 3.8 | BG21: 37.7 | BH21: 174.3 | BI21: 42 | BL21: 0 | BP21: 86.8 | BQ21: 85 | BR21: 0 | BS21: 84.6 | BT21: 107.1 | CC21: 4.6 | CD21: 46.3 | CE21: 130.2 | CF21: 63.3 | CG21: 78.3 | CH21: 30.3 | CL21: 103.4 | CM21: 104.1 | CN21: 120.8 | CV21: 0 | CW21: 112.1 | CX21: 0 | CY21: 2.4 | CZ21: 0 | DA21: 0 | DB21: 9.8 | DC21: 5.4 | DD21: 1.2 | DE21: 3.4 | DF21: 5 | DG21: 0 | DH21: 16.8 | DI21: 9.9 | DJ21: 3.2 | DK21: 9.3 | DL21: 0 | DM21: 0 | DN21: 31 | DO21: 73.4 | DP21: 0 | DQ21: 2 | DR21: 2.3 | DT21: 0 | DU21: 2.4 | DV21: 11.1 | DW21: 0 | DX21: 0 | DY21: 19.8 | DZ21: 9.7 | EA21: 15.9 | EB21: 20.3 | EC21: 19.9 | ED21: 14 | EE21: 63.3 | EF21: 0 | EG21: 26.2 | EH21: 51.7 | EI21: 1.3 | EJ21: 0.1 | EK21: 20.9 | EL21: 8.1 | EM21: 8.8 | EN21: 20.4 | EO21: 20.4 | EP21: 20.2 | EQ21: 4.1 | ER21: 0 | ES21: 0 | ET21: 0 | EU21: 0.6 | EV21: 53.8 | EW21: 44.5 | EX21: 0 | EY21: 0 | EZ21: 9.2 | FA21: 20 | FC21: 37.7 | FE21: 29.3 | FF21: 3.3 | FG21: 14.6 | FJ21: 6469.55 | FL21: 23.53595 | FM21: 0 | FO21: 13.19982 | FQ21: 18.91408 | FR21: 0 | FS21: 16 | FT21: 71.64985
A22: 26/04/2025 | B22: 06:00 | E22: 103.1 | F22: 651 | G22: 214.6 | J22: 90.9 | K22: 229.1 | N22: 118.6 | O22: 118.7 | P22: 117.9 | Q22: 211.1 | R22: 110 | S22: 66.9 | T22: 565.5 | U22: 0 | Z22: 170.4 | AA22: 7.8 | AB22: 4.1 | AD22: 6.7 | AE22: 10.1 | AF22: 85.6 | AG22: 6.1 | AK22: 111 | AL22: 221.7 | AP22: 6.4 | AQ22: 466.2 | AR22: 77.7 | AS22: 148.6 | AT22: 42.4 | AU22: 18.5 | AV22: 18.8 | AW22: 94 | AX22: 33 | AZ22: 0 | BA22: 109.2 | BB22: 7.6 | BC22: 5.9 | BD22: 46.4 | BE22: 32.3 | BF22: 3.8 | BG22: 38.3 | BH22: 175 | BI22: 42.1 | BL22: 0 | BP22: 86.7 | BQ22: 114.7 | BR22: 0 | BS22: 114.5 | BT22: 129.5 | CC22: 4.6 | CD22: 91 | CE22: 130.6 | CF22: 63.3 | CG22: 78.4 | CH22: 30.3 | CL22: 103.4 | CM22: 104.4 | CN22: 120.3 | CV22: 0 | CW22: 108.1 | CX22: 0 | CY22: 1.9 | CZ22: 0 | DA22: 9.3 | DB22: 9.9 | DC22: 5.4 | DD22: 1.2 | DE22: 3.4 | DF22: 4.9 | DG22: 0 | DH22: 16.8 | DI22: 9.9 | DJ22: 3.3 | DK22: 9.3 | DL22: 0.9 | DM22: 0.8 | DN22: 30.3 | DO22: 66.2 | DP22: 0 | DQ22: 2 | DR22: 2.3 | DT22: 0.1 | DU22: 2.4 | DV22: 13.8 | DW22: 0 | DX22: 0 | DY22: 19.7 | DZ22: 9.7 | EA22: 15.7 | EB22: 20.3 | EC22: 20 | ED22: 9 | EE22: 50.3 | EF22: 0 | EG22: 30.1 | EH22: 47.2 | EI22: 2.1 | EJ22: 0.3 | EK22: 20.9 | EL22: 7.8 | EM22: 8.9 | EN22: 20.4 | EO22: 20.4 | EP22: 20.2 | EQ22: 3 | ER22: 0.33 | ES22: 0 | ET22: 0.8 | EU22: 0.6 | EV22: 40.8 | EW22: 29.1 | EX22: 0.6 | EY22: 0 | EZ22: 9.2 | FA22: 20 | FC22: 38 | FE22: 29.3 | FF22: 3.3 | FG22: 14.6 | FJ22: 6573.63 | FL22: 23.53519 | FM22: 0 | FO22: 13.18044 | FQ22: 16.34249 | FR22: 0 | FS22: 16 | FT22: 69.05812
... A58: 27/04/2025 | B58: 00:00 | E58: 29.05 | F58: 639 | G58: 212.5 | J58: 88.1 | K58: 228.1 | N58: 106.3 | O58: 106.3 | P58: 106.3 | Q58: 208.1 | R58: 110.3 | S58: 67.9 | T58: 545.8 | U58: 10.2 | Z58: 161.5 | AA58: 7 | AB58: 2.9 | AD58: 6.7 | AE58: 10.1 | AF58: 86.2 | AG58: 7.2 | AK58: 109.5 | AL58: 173.6 | AP58: 6.5 | AQ58: 374.9 | AR58: 73.6 | AS58: 121.3 | AT58: 42.3 | AU58: 18.5 | AV58: 19.5 | AW58: 88.2 | AX58: 188.4 | AZ58: 93.1 | BA58: 107 | BB58: 8.3 | BC58: 7.6 | BD58: 44.2 | BE58: 13.8 | BF58: 3.8 | BG58: 37.3 | BH58: 170.9 | BI58: 93 | BL58: 0 | BP58: 85.2 | BQ58: 130.5 | BR58: 0 | BS58: 129.8 | BT58: 141.9 | CC58: 4.6 | CD58: 184.9 | CE58: 107.5 | CF58: 61.6 | CG58: 77.9 | CH58: 29.7 | CL58: 0 | CM58: 147.4 | CN58: 68.1 | CV58: 0 | CW58: 110.6 | CX58: 0 | CY58: 0 | CZ58: 0 | DA58: 20 | DB58: 9.9 | DC58: 5.5 | DD58: 1.2 | DE58: 3.4 | DF58: 4.9 | DG58: 20 | DH58: 20 | DI58: 18.6 | DJ58: 3.6 | DK58: 9.3 | DL58: 0 | DM58: 0 | DN58: 31.8 | DO58: 83.2 | DP58: 0 | DQ58: 2 | DR58: 2.2 | DT58: 0 | DU58: 2.4 | DV58: 20.2 | DW58: 3.1 | DX58: 0.3 | DY58: 19.8 | DZ58: 9.7 | EA58: 17.4 | EB58: 20.2 | EC58: 19.8 | ED58: 16.6 | EE58: 61.3 | EF58: 0 | EG58: 68.3 | EH58: 85.5 | EI58: 5 | EJ58: 0.5 | EK58: 20.9 | EL58: 7 | EM58: 8.6 | EN58: 20.4 | EO58: 20.4 | EP58: 20.2 | EQ58: 0 | ER58: 0 | ES58: 0 | ET58: 0 | EU58: 0.6 | EV58: 40.7 | EW58: 33.6 | EX58: 0 | EY58: 0 | EZ58: 9.4 | FA58: 19.9 | FC58: 37.3 | FE58: 29.3 | FF58: 3.2 | FG58: 14.2 | FJ58: 6685.95 | FL58: 23.11184 | FM58: 7.998 | FO58: 13.1707 | FQ58: 18.91797 | FR58: 10.3 | FS58: 15.9 | FT58: 89.39851
A59: EJEC | C59: 0 | D59: 0 | E59: 1762.195 | F59: 15458.05 | G59: 5129.95 | H59: 0 | I59: 0 | J59: 2149.85 | K59: 5441.8 | L59: 0 | M59: 0 | N59: 2753.4 | O59: 2770.45 | P59: 2767.7 | Q59: 5167.3 | R59: 3065.45 | S59: 1811.2 | T59: 13351.4 | U59: 130.55 | V59: 0 | W59: 0 | X59: 0 | Y59: 0 | Z59: 3945.35 | AA59: 175.85 | AB59: 85.5 | AC59: 0 | AD59: 160.5 | AE59: 242.55 | AF59: 2149.6 | AG59: 149.9 | AH59: 0 | AI59: 0 | AJ59: 0 | AK59: 2173.05 | AL59: 4968.3 | AM59: 0 | AN59: 0 | AO59: 0 | AP59: 153.95 | AQ59: 10595.55 | AR59: 1752.9 | AS59: 3353.1 | AT59: 1016.5 | AU59: 425.5 | AV59: 464.65 | AW59: 2150.85 | AX59: 2751.6 | AY59: 0 | AZ59: 1267.15 | BA59: 2563.55 | BB59: 192.25 | BC59: 140.35 | BD59: 1095.4 | BE59: 571.25 | BF59: 91.2 | BG59: 909.45 | BH59: 4153.7 | BI59: 1476.95 | BJ59: 0 | BK59: 0 | BL59: 140.15 | BM59: 0 | BN59: 0 | BO59: 0 | BP59: 2070.55 | BQ59: 2728.85 | BR59: 625.15 | BS59: 2885.05 | BT59: 3195.25 | BU59: 0 | BV59: 0 | BW59: 0 | BX59: 0 | BY59: 0 | BZ59: 0 | CA59: 0 | CB59: 0 | CC59: 110.25 | CD59: 3931.95 | CE59: 3037.9 | CF59: 1523.3 | CG59: 1892.05 | CH59: 723.7 | CI59: 0 | CJ59: 0 | CK59: 0 | CL59: 1342.3 | CM59: 2871.25 | CN59: 2282.1 | CO59: 0 | CP59: 0 | CQ59: 0 | CR59: 0 | CS59: 0 | CT59: 0 | CU59: 0 | CV59: 9.25 | CW59: 2633.2 | CX59: 658.3 | CY59: 62.45 | CZ59: 3 | DA59: 364.35 | DB59: 237.9 | DC59: 130.55 | DD59: 28.8 | DE59: 79.3 | DF59: 98.4 | DG59: 121.35 | DH59: 422.8 | DI59: 381.6 | DJ59: 81.85 | DK59: 223.2 | DL59: 131.4 | DM59: 155.55 | DN59: 724.5 | DO59: 1888.5 | DP59: 4.4 | DQ59: 47.9 | DR59: 54.85 | DS59: 0 | DT59: 158.75 | DU59: 56.9 | DV59: 390.8 | DW59: 14.15 | DX59: 5.2 | DY59: 471.85 | DZ59: 232.85 | EA59: 389.4 | EB59: 485.9 | EC59: 478.65 | ED59: 358.4 | EE59: 1411.55 | EF59: 298.7 | EG59: 1727.95 | EH59: 1984.4 | EI59: 211.35 | EJ59: 128.5 | EK59: 501.6 | EL59: 179.3 | EM59: 208.95 | EN59: 489.6 | EO59: 489.6 | EP59: 484.8 | EQ59: 82.6 | ER59: 2121.594 | ES59: 127.9 | ET59: 1194.95 | EU59: 14.4 | EV59: 1627.95 | EW59: 1719.2 | EX59: 883.5 | EY59: 122.95 | EZ59: 221.85 | FA59: 479.6 | FB59: 0 | FC59: 901.2 | FD59: 0 | FE59: 698.25 | FF59: 77.95 | FG59: 351.95 | FH59: 0 | FI59: 0 | FJ59: 170623.94 | FL59: 565.14932 | FM59: 93.3055 | FN59: 0 | FO59: 315.99723 | FP59: 0 | FQ59: 324.09025 | FR59: 198.9 | FS59: 384.9 | FT59: 1882.3423

Sheet REACTIVA
B3: sábado, 26 de Abril del 2025
A5: POTENCIA REACTIVA EJECUTADA DE LAS UNIDADES DE GENERACIÓN DEL COES (MVAR) | FK5: CENTRALES NO INTEGRANTES COES
A6: FECHA | B6: HORA | C6: 337 | D6: 338 | E6: 65333 | F6: 101 | G6: 102 | H6: 42667 | I6: 42668 | J6: 126 | K6: 127 | L6: 138 | M6: 139 | N6: 197 | O6: 203 | P6: 204 | Q6: 230 | R6: 209 | S6: 56677 | T6: 796 | U6: 2146 | V6: 142 | W6: 143 | X6: 125 | Y6: 187 | Z6: 163 | AA6: 298 | AB6: 219 | AC6: 151 | AD6: 152 | AE6: 153 | AF6: 154 | AG6: 756 | AH6: 156 | AI6: 155 | AJ6: 182 | AK6: 212 | AL6: 758 | AM6: 263 | AN6: 265 | AO6: 775 | AP6: 777 | AQ6: 2154 | AR6: 150 | AS6: 149 | AT6: 188 | AU6: 2131 | AV6: 755 | AW6: 252 | AX6: 249 | AY6: 250 | AZ6: 117 | BA6: 267 | BB6: 268 | BC6: 119 | BD6: 120 | BE6: 189 | BF6: 122 | BG6: 266 | BH6: 251 | BI6: 115 | BJ6: 239 | BK6: 288 | BL6: 240 | BM6: 241 | BN6: 242 | BO6: 191 | BP6: 194 | BQ6: 196 | BR6: 207 | BS6: 236 | BT6: 795 | BU6: 285 | BV6: 995 | BW6: 996 | BX6: 997 | BY6: 766 | BZ6: 926 | CA6: 924 | CB6: 121 | CC6: 103 | CD6: 104 | CE6: 106 | CF6: 105 | CG6: 107 | CH6: 110 | CI6: 109 | CJ6: 144 | CK6: 113 | CL6: 114 | CM6: 193 | CN6: 208 | CO6: 786 | CP6: 787 | CQ6: 788 | CR6: 789 | CS6: 248 | CT6: 2159 | CU6: 303 | CV6: 59715 | CW6: 62255 | CX6: 1263 | CY6: 61800 | CZ6: 2194 | DA6: 216 | DB6: 198 | DC6: 49607 | DD6: 214 | DE6: 260 | DF6: 2152 | DG6: 2128 | DH6: 247 | DI6: 228 | DJ6: 2135 | DK6: 261 | DL6: 237 | DM6: 253 | DN6: 770 | DO6: 225 | DP6: 2201 | DQ6: 2171 | DR6: 760 | DS6: 235 | DT6: 238 | DU6: 2184 | DV6: 61855 | DW6: 223 | DX6: 226 | DY6: 201 | DZ6: 258 | EA6: 259 | EB6: 920 | EC6: 257 | ED6: 256 | EE6: 2148 | EF6: 58288 | EG6: 58289 | EH6: 58839 | EI6: 58840 | EJ6: 296 | EK6: 297 | EL6: 211 | EM6: 2175 | EN6: 2178 | EO6: 2181 | EP6: 1262 | EQ6: 63425 | ER6: 233 | ES6: 2150 | ET6: 2165 | EU6: 2161 | EV6: 61197 | EW6: 58851 | EX6: 234 | EY6: 215 | EZ6: 917 | FA6: 289 | FB6: 58333 | FC6: 58336 | FD6: 202 | FE6: 58487 | FF6: 213 | FG6: 232 | FH6: 2190 | FI6: TOTAL COES | FK6: 221 | FL6: 222 | FM6: 224 | FN6: 2187 | FO6: 227 | FP6: 49400 | FQ6: 199 | FR6: 200 | FS6: TOTAL NO COES
C7: CENTRO | D7: CENTRO | E7: SUR | F7: CENTRO | G7: CENTRO | H7: NORTE | I7: NORTE | J7: NORTE | K7: NORTE | L7: CENTRO | M7: CENTRO | N7: CENTRO | O7: CENTRO | P7: CENTRO | Q7: CENTRO | R7: CENTRO | S7: CENTRO | T7: CENTRO | U7: CENTRO | V7: CENTRO | W7: CENTRO | X7: CENTRO | Y7: CENTRO | Z7: SUR | AA7: SUR | AB7: CENTRO | AC7: SUR | AD7: SUR | AE7: SUR | AF7: SUR | AG7: SUR | AH7: SUR | AI7: SUR | AJ7: SUR | AK7: CENTRO | AL7: NORTE | AM7: NORTE | AN7: NORTE | AO7: CENTRO | AP7: CENTRO | AQ7: CENTRO | AR7: CENTRO | AS7: CENTRO | AT7: CENTRO | AU7: CENTRO | AV7: SUR | AW7: CENTRO | AX7: CENTRO | AY7: CENTRO | AZ7: CENTRO | BA7: CENTRO | BB7: CENTRO | BC7: CENTRO | BD7: CENTRO | BE7: SUR | BF7: NORTE | BG7: CENTRO | BH7: CENTRO | BI7: NORTE | BJ7: NORTE | BK7: NORTE | BL7: SUR | BM7: SUR | BN7: SUR | BO7: CENTRO | BP7: CENTRO | BQ7: CENTRO | BR7: CENTRO | BS7: CENTRO | BT7: CENTRO | BU7: CENTRO | BV7: SUR | BW7: SUR | BX7: SUR | BY7: NORTE | BZ7: SUR | CA7: CENTRO | CB7: NORTE | CC7: CENTRO | CD7: CENTRO | CE7: CENTRO | CF7: CENTRO | CG7: CENTRO | CH7: CENTRO | CI7: CENTRO | CJ7: CENTRO | CK7: CENTRO | CL7: CENTRO | CM7: CENTRO | CN7: CENTRO | CO7: SUR | CP7: SUR | CQ7: SUR | CR7: SUR | CS7: CENTRO | CT7: CENTRO | CU7: CENTRO | CV7: CENTRO | CW7: SUR | CX7: NORTE | CY7: NORTE | CZ7: NORTE | DA7: NORTE | DB7: NORTE | DC7: SUR | DD7: CENTRO | DE7: CENTRO | DF7: CENTRO | DG7: NORTE | DH7: NORTE | DI7: CENTRO | DJ7: CENTRO | DK7: SUR | DL7: SUR | DM7: CENTRO | DN7: CENTRO | DO7: CENTRO | DP7: CENTRO | DQ7: CENTRO | DR7: CENTRO | DS7: SUR | DT7: CENTRO | DU7: CENTRO | DV7: NORTE | DW7: CENTRO | DX7: CENTRO | DY7: NORTE | DZ7: CENTRO | EA7: CENTRO | EB7: CENTRO | EC7: NORTE | ED7: NORTE | EE7: SUR | EF7: CENTRO | EG7: CENTRO | EH7: CENTRO | EI7: CENTRO | EJ7: CENTRO | EK7: CENTRO | EL7: SUR | EM7: SUR | EN7: SUR | EO7: SUR | EP7: NORTE | EQ7: SUR | ER7: SUR | ES7: SUR | ET7: CENTRO | EU7: CENTRO | EV7: CENTRO | EW7: SUR | EX7: SUR | EY7: NORTE | EZ7: CENTRO | FA7: NORTE | FB7: NORTE | FC7: NORTE | FD7: CENTRO | FE7: CENTRO | FF7: CENTRO | FG7: NORTE | FH7: NORTE | FK7: NORTE | FL7: CENTRO | FM7: NORTE | FN7: NORTE | FO7: NORTE | FP7: NORTE | FQ7: NORTE | FR7: NORTE
C8: HIDROELÉCTRICA | D8: HIDROELÉCTRICA | E8: HIDROELÉCTRICA | F8: HIDROELÉCTRICA | G8: HIDROELÉCTRICA | H8: TERMOELÉCTRICA | I8: TERMOELÉCTRICA | J8: HIDROELÉCTRICA | K8: HIDROELÉCTRICA | L8: TERMOELÉCTRICA | M8: TERMOELÉCTRICA | N8: TERMOELÉCTRICA | O8: TERMOELÉCTRICA | P8: TERMOELÉCTRICA | Q8: TERMOELÉCTRICA | R8: TERMOELÉCTRICA | S8: TERMOELÉCTRICA | T8: HIDROELÉCTRICA | U8: HIDROELÉCTRICA | V8: TERMOELÉCTRICA | W8: TERMOELÉCTRICA | X8: TERMOELÉCTRICA | Y8: TERMOELÉCTRICA | Z8: HIDROELÉCTRICA | AA8: HIDROELÉCTRICA | AB8: TERMOELÉCTRICA | AC8: HIDROELÉCTRICA | AD8: HIDROELÉCTRICA | AE8: HIDROELÉCTRICA | AF8: HIDROELÉCTRICA | AG8: TERMOELÉCTRICA | AH8: TERMOELÉCTRICA | AI8: TERMOELÉCTRICA | AJ8: HIDROELÉCTRICA | AK8: HIDROELÉCTRICA | AL8: TERMOELÉCTRICA | AM8: TERMOELÉCTRICA | AN8: TERMOELÉCTRICA | AO8: HIDROELÉCTRICA | AP8: HIDROELÉCTRICA | AQ8: HIDROELÉCTRICA | AR8: HIDROELÉCTRICA | AS8: HIDROELÉCTRICA | AT8: HIDROELÉCTRICA | AU8: HIDROELÉCTRICA | AV8: HIDROELÉCTRICA | AW8: TERMOELÉCTRICA | AX8: TERMOELÉCTRICA | AY8: TERMOELÉCTRICA | AZ8: HIDROELÉCTRICA | BA8: HIDROELÉCTRICA | BB8: HIDROELÉCTRICA | BC8: HIDROELÉCTRICA | BD8: HIDROELÉCTRICA | BE8: HIDROELÉCTRICA | BF8: HIDROELÉCTRICA | BG8: HIDROELÉCTRICA | BH8: HIDROELÉCTRICA | BI8: TERMOELÉCTRICA | BJ8: TERMOELÉCTRICA | BK8: TERMOELÉCTRICA | BL8: TERMOELÉCTRICA | BM8: TERMOELÉCTRICA | BN8: TERMOELÉCTRICA | BO8: HIDROELÉCTRICA | BP8: TERMOELÉCTRICA | BQ8: TERMOELÉCTRICA | BR8: TERMOELÉCTRICA | BS8: TERMOELÉCTRICA | BT8: TERMOELÉCTRICA | BU8: TERMOELÉCTRICA | BV8: TERMOELÉCTRICA | BW8: TERMOELÉCTRICA | BX8: TERMOELÉCTRICA | BY8: HIDROELÉCTRICA | BZ8: TERMOELÉCTRICA | CA8: TERMOELÉCTRICA | CB8: HIDROELÉCTRICA | CC8: HIDROELÉCTRICA | CD8: HIDROELÉCTRICA | CE8: HIDROELÉCTRICA | CF8: HIDROELÉCTRICA | CG8: HIDROELÉCTRICA | CH8: TERMOELÉCTRICA | CI8: TERMOELÉCTRICA | CJ8: TERMOELÉCTRICA | CK8: TERMOELÉCTRICA | CL8: TERMOELÉCTRICA | CM8: TERMOELÉCTRICA | CN8: TERMOELÉCTRICA | CO8: TERMOELÉCTRICA | CP8: TERMOELÉCTRICA | CQ8: TERMOELÉCTRICA | CR8: TERMOELÉCTRICA | CS8: TERMOELÉCTRICA | CT8: TERMOELÉCTRICA | CU8: SOLAR | CV8: EÓLICA | CW8: SOLAR | CX8: EÓLICA | CY8: SOLAR | CZ8: HIDROELÉCTRICA | DA8: HIDROELÉCTRICA | DB8: HIDROELÉCTRICA | DC8: HIDROELÉCTRICA | DD8: HIDROELÉCTRICA | DE8: HIDROELÉCTRICA | DF8: HIDROELÉCTRICA | DG8: HIDROELÉCTRICA | DH8: HIDROELÉCTRICA | DI8: HIDROELÉCTRICA | DJ8: HIDROELÉCTRICA | DK8: SOLAR | DL8: SOLAR | DM8: EÓLICA | DN8: EÓLICA | DO8: TERMOELÉCTRICA | DP8: TERMOELÉCTRICA | DQ8: TERMOELÉCTRICA | DR8: TERMOELÉCTRICA | DS8: SOLAR | DT8: HIDROELÉCTRICA | DU8: HIDROELÉCTRICA | DV8: HIDROELÉCTRICA | DW8: HIDROELÉCTRICA | DX8: HIDROELÉCTRICA | DY8: HIDROELÉCTRICA | DZ8: HIDROELÉCTRICA | EA8: HIDROELÉCTRICA | EB8: HIDROELÉCTRICA | EC8: EÓLICA | ED8: EÓLICA | EE8: SOLAR | EF8: EÓLICA | EG8: EÓLICA | EH8: EÓLICA | EI8: EÓLICA | EJ8: HIDROELÉCTRICA | EK8: HIDROELÉCTRICA | EL8: HIDROELÉCTRICA | EM8: HIDROELÉCTRICA | EN8: HIDROELÉCTRICA | EO8: HIDROELÉCTRICA | EP8: EÓLICA | EQ8: SOLAR | ER8: SOLAR | ES8: SOLAR | ET8: HIDROELÉCTRICA | EU8: EÓLICA | EV8: EÓLICA | EW8: SOLAR | EX8: SOLAR | EY8: HIDROELÉCTRICA | EZ8: HIDROELÉCTRICA | FA8: TERMOELÉCTRICA | FB8: TERMOELÉCTRICA | FC8: TERMOELÉCTRICA | FD8: TERMOELÉCTRICA | FE8: TERMOELÉCTRICA | FF8: TERMOELÉCTRICA | FG8: TERMOELÉCTRICA | FH8: TERMOELÉCTRICA | FK8: HIDROELÉCTRICA | FL8: HIDROELÉCTRICA | FM8: HIDROELÉCTRICA | FN8: HIDROELÉCTRICA | FO8: TERMOELÉCTRICA | FP8: TERMOELÉCTRICA | FQ8: HIDROELÉCTRICA | FR8: HIDROELÉCTRICA
