Workbook

Sheet EVENTOS
B3: miércoles, 5 de Noviembre del 2025
B5: INFORMACIÓN DE EVENTOS PRINCIPALES EN SUS INSTALACIONES
B6: TIPO DE EVENTO | C6: EMPRESA | D6: UBICACIÓN | E6: TIPO DE EQUIPO | F6: EQUIPO | G6: INICIO | H6: FINAL | I6: DESCRIPCIÓN | J6: MW INDISP. | K6: INTERRUPCIÓN (SI/NO) | L6: TENSIÓN DE FALLA (kV)
B7: FALLA | C7: ATN S.A. | D7: RAMADA - PAMPA HONDA | E7: LINEA DE TRANSMISION | F7: L-2275 | G7: 05/11/2025 17:56:00 | H7: 05/11/2025 17:56:00 | I7: RECIERRE EXITOSO DE LA S LINEAS L-2273/L-2275 (LA RAMADA - PAMPA HONDA) DE 220 KV | K7: NO | L7: 220
B8: EVENTO | C8: CONELSUR LT SAC | D8: PORTILLO | E8: SUBESTACION | F8: SS.EE. | G8: 05/11/2025 00:00:00 | H8: 06/11/2025 00:00:00 | I8: DECLARACIÓN DE SITUACIÓN EXCEPCIONAL EN LA S.E. PORTILLO 60 kV | K8: NO
B9: EVENTO | C9: ELECTRO ORIENTE | D9: BELAUNDE TERRY - TARAPOTO | E9: LINEA DE TRANSMISION | F9: L-1018 | G9: 05/11/2025 18:18:00 | H9: 05/11/2025 19:59:00 | I9: DECLARACIÓN DE SITUACIÓN EXCEPCIONAL EN LA LÍNEA L-1018 (BELAUNDE TERRY - TARAPOTO) DE 138 kV | K9: NO
B10: FALLA | C10: VARI ENERGIA S.A.C. | D10: ANASHIRONI | E10: GENERADOR HIDROELÉCTRICO | F10: G1 | G10: 05/11/2025 05:40:11 | H10: 05/11/2025 08:59:00 | I10: DESCONEXIÓN DE LA C.H. ANASHIRONI | K10: NO | L10: 13.8

Sheet RESTRIC_OPE
B3: miércoles, 5 de Noviembre del 2025
B5: RESTRICCIONES OPERATIVAS
B6: FECHA | C6: HORA INICIO | D6: HORA FINAL | E6: EMPRESA | F6: UBICACIÓN | G6: T.Eq. | H6: EQUIPO | I6: DESCRIPCIÓN
B7: 05/11/2025 | C7: 00:00 | D7: 24:00 | E7: CELEPSA | F7: C.H. EL PLATANAL | G7: CH | H7: CENTRAL | I7: De acuerdo con el correo del 13/10/2025. Debido a problemas en el control de la compuerta de bocatoma, informaron que el servicio de RSF queda indisponible.
B8: 05/11/2025 | C8: 00:00 | D8: 24:00 | E8: EGASA | F8: S.E. CONVERTIDOR | G8: BARRA | H8: BARRA138KV | I8: EGASA limitó la capacidad del transformador 138 kV/33 kV a 50 MVA por deterioro del aislamiento.
B9: 05/11/2025 | C9: 00:00 | D9: 24:00 | E9: ELECTROPERU | F9: C.H. MANTARO | G9: CH | H9: CENTRAL | I9: De acuerdo con el correo del día 25.08.2025, la central tiene una limitación de potencia máxima de 650 MW por seguridad de la central.
B10: 05/11/2025 | C10: 00:00 | D10: 24:00 | E10: ENEL GENERACION PIURA S.A. | F10: C.T. MALACAS | G10: CT | H10: CENTRAL | I10: De acuerdo con la comunicación vía correo del día 24.10.2024. ENEL GENERACIÓN PIURA informa una restricción de potencia para alcanzar 105 MW en simultaneo (TG6+TGN4).
B11: 05/11/2025 | C11: 00:00 | D11: 24:00 | E11: ENEL GENERACION PIURA S.A. | F11: C.T. MALACAS | G11: GT | H11: TG4 | I11: De acuerdo a lo informado mediante correo electrónico el día 25.10, con la disponibilidad actual de aproximadamente 13 MMPCD (368.12 Mm³) la unidad TG4 puede con una generación de 80 MW durante 5 horas, y a potencia mínima durante el resto de los periodos
B12: 05/11/2025 | C12: 00:00 | D12: 24:00 | E12: ENGIE ENERGIA PERU S.A.A. | F12: C.H. YUNCÁN | G12: GH | H12: G3 | I12: Según la carta N° ENG/ 198-2024 enviada por su representada, se opera de forma continua el G3 de la CH Yuncán, debido a la ejecución de mantenimientos necesarios para evitar daños en los sellos de seguridad de la válvula esférica del grupo.
B13: 05/11/2025 | C13: 00:00 | D13: 24:00 | E13: ENGIE ENERGIA PERU S.A.A. | F13: C.T. CHILCA 1 | G13: CT | H13: CENTRAL | I13: Restricción de temperatura de la C.T Chilca, ver valor en el modelo de despacho.
B14: 05/11/2025 | C14: 00:00 | D14: 24:00 | E14: ENGIE ENERGIA PERU S.A.A. | F14: C.T. CHILCA 1 | G14: CT | H14: CENTRAL | I14: Con carta ENG/971-2023, indica que no puede cumplir con las IO considerada en el PDO_17122023 dado que vulneran la seguridad de sus activos. Indican que se debe tomar TMO=168h.
B15: 05/11/2025 | C15: 00:00 | D15: 24:00 | E15: ENGIE ENERGIA PERU S.A.A. | F15: C.T. CHILCA 2 | G15: CT | H15: CENTRAL | I15: Con carta ENG/971-2023, indica que no puede cumplir con las IO considerada en el PDO_17122023 dado que vulneran la seguridad de sus activos. Indican que se debe tomar TMO=168h.
B16: 05/11/2025 | C16: 00:00 | D16: 24:00 | E16: FENIX POWER PERÚ | F16: C.T. FENIX | G16: CT | H16: CENTRAL | I16: De acuerdo con lo comunicado en el correo del día 06.05.2025, la CT Fenix cuenta con TMO de 168 hrs en todos sus modos de operación.
B17: 05/11/2025 | C17: 00:00 | D17: 24:00 | E17: KALLPA GENERACION S.A. | F17: C.H. MINI CENTRAL CERRO DEL AGUILA | G17: CH | H17: CENTRAL | I17: Caudal ecológico de la Mini CH Cerro del Águila es de 10.6 m3/s correspondiente al mes de noviembre.
... B47: 05/11/2025 | C47: 00:00 | D47: 24:00 | E47: TERMOSELVA | F47: C.T. AGUAYTÍA | G47: CT | H47: CENTRAL | I47: Disponibilidad de 23.5 MMSCF para la CT Aguaytía.

Sheet MANTENIMIENTO EJECUTADOS
B3: miércoles, 5 de Noviembre del 2025
B5: Mantenimiento Ejecutado
B6: Empresa | C6: Ubicación | D6: Equipo | E6: Inicio | F6: Final | G6: Descripción | H6: MW Indisp. | I6: Prog. | J6: Dispon | K6: Interrupc. | L6: Tipo | M6: CodEq | N6: TipoEq_Osinerg
B7: ACEROS AREQUIPA | C7: INDEPENDENCIA - ACEROS AREQUIPA | D7: L-2217 | E7: 05/11/2025 14:00 | F7: 05/11/2025 17:00 | G7: Se requiere cambiar densimetro del interruptor de la fase S | H7: 150 | I7: P | J7: F/S | K7: N | L7: CORR. | M7: 748 | N7: T
B8: ANGLO AMERICAN QUELLAVECO S.A. | C8: MOQUEGUA | D8: CL-2067 | E8: 05/11/2025 10:30 | F8: 05/11/2025 16:00 | G8: MP 1A TERMOGRAFIA A EQUIPOS DE PATIO 220 KV DE LAS CELDAS CL-2067 Y CL-2068, ACTIVIDAD CON CAMBIO DE BARRAS. (R0114508) | H8: 0 | I8: P | J8: E/S | K8: N | L8: PREV. | M8: 21361 | N8: T
B9: ANGLO AMERICAN QUELLAVECO S.A. | C9: MOQUEGUA | D9: CL-2068 | E9: 05/11/2025 10:30 | F9: 05/11/2025 16:00 | G9: MP 1A TERMOGRAFIA A EQUIPOS DE PATIO 220 KV DE LAS CELDAS CL-2067 Y CL-2068, ACTIVIDAD CON CAMBIO DE BARRAS. (R0114508) | H9: 0 | I9: P | J9: E/S | K9: N | L9: PREV. | M9: 21362 | N9: T
B10: ATLANTICA TRANSMISION SUR S.A. | C10: CHILCA CTM - POROMA | D10: L-5032 | E10: 05/11/2025 07:25 | F10: 05/11/2025 16:52 | G10: Mejoramiento de PAT | H10: 0 | I10: P | J10: E/S | K10: N | L10: PREV. | M10: 13652 | N10: T
B11: ATLANTICA TRANSMISION SUR S.A. | C11: CHILCA CTM - POROMA | D11: L-5032 | E11: 05/11/2025 08:27 | F11: 05/11/2025 17:44 | G11: Mantenimiento de pedestales. | H11: 0 | I11: P | J11: E/S | K11: N | L11: PREV. | M11: 13652 | N11: T
B12: ATLANTICA TRANSMISION SUR S.A. | C12: OCONA | D12: INT-5450 | E12: 05/11/2025 00:00 | F12: 06/11/2025 00:00 | G12: Interruptor INT-5450 cerrado con restriccion operativa, REB-5450 en servicio y suministrando los SS.AA. de la S.E. Oco?a. | H12: 0 | I12: P | J12: E/S | K12: N | L12: OTROS | M12: 13761 | N12: T
B13: ATLANTICA TRANSMISION SUR S.A. | C13: POROMA | D13: INT-5371 | E13: 05/11/2025 00:00 | F13: 06/11/2025 00:00 | G13: Seccionador SBB-5371 fase T indisponible por problemas mecanicos, el seccionador permanece cerrado y bloqueado | H13: 0 | I13: P | J13: E/S | K13: N | L13: OTROS | M13: 13751 | N13: T
B14: ATLANTICA TRANSMISION SUR S.A. | C14: POROMA | D14: REB-5350 | E14: 05/11/2025 00:00 | F14: 06/11/2025 00:00 | G14: Fuera de servicio po falla en el equipo. | H14: 0 | I14: P | J14: F/S | K14: N | L14: OTROS | M14: 13771 | N14: T
B15: ATN S.A. | C15: KIMAN AYLLU | D15: AUT-501 | E15: 05/11/2025 00:00 | F15: 06/11/2025 00:00 | G15: Restriccion Operativa en el circuito de control de cambiador de tap s del AUT-501 | H15: 0 | I15: P | J15: E/S | K15: N | L15: OTROS | M15: 13099 | N15: T
B16: ATRIA ENERGIA S.A.C. | C16: PURMACANA | D16: CENTRAL | E16: 05/11/2025 00:00 | F16: 06/11/2025 00:00 | G16: MANTENIMIENTO DE CANAL DE CONDUCCION, COMPUERTAS, SISTEMA DE LUBRICACION DE COJINETES, SISTEMA DE REFRIGERACION Y VALVULAS | H16: 0.4 | I16: P | J16: F/S | K16: N | L16: PREV. | M16: 13132 | N16: G
B17: CONELSUR LT SAC | C17: CALLAHUANCA (CNS) | D17: S.E. | E17: 05/11/2025 00:00 | F17: 06/11/2025 00:00 | G17: RELE DIFERENCIAL DE BARRAS DE CALLAHUANCA 220KV INOPERATIVO | H17: 0 | I17: F | J17: E/S | K17: N | L17: OTROS | M17: 316 | N17: T
B18: EGASA | C18: SANTUARIO | D18: ACOPLE 138 | E18: 05/11/2025 00:00 | F18: 06/11/2025 00:00 | G18: En servicio barra 2,uso en grupo N1 Charcani V con interruptor de acoplamiento, por falla | H18: 0 | I18: P | J18: E/S | K18: N | L18: OTROS | M18: 11052 | N18: T
... B156: TRANSMANTARO | C156: YARABAMBA | D156: CL-R-30 | E156: 05/11/2025 00:00 | F156: 06/11/2025 00:00 | G156: CL-R30 CON MANDO SINCRONIZADO ASOCIADO AL INTERRUPTOR IN-5147 INDISPONIBLE. EL SABADO 19.04.25 NO PUDO SER AJUSTADO DEBIDO A FALTA DE EQUIPOS DE PARTE DE LA CONTRATISTA HITACHI. | H156: 0 | I156: P | J156: E/S | K156: N | L156: OTROS | M156: 17424 | N156: T

Sheet INGRESO OC
A3: miércoles, 5 de Noviembre del 2025
A5: INGRESO A OPERACIÓN COMERCIAL
A6: EMPRESA | B6: TIPO DE EQUIPO | C6: UBICACIÓN | D6: EQUIPO | E6: Fecha y hora de Ingreso a Operación Comercial

Sheet DESPACHO_EJECUTADO
B3: miércoles, 5 de Noviembre del 2025
A5: POTENCIA ACTIVA EJECUTADA DE LAS UNIDADES DE GENERACIÓN DEL SEIN (MW) | FM5: CENTRALES NO INTEGRANTES COES
A6: FECHA | B6: HORA | C6: 65333 | D6: 101 | E6: 102 | F6: 42667 | G6: 42668 | H6: 126 | I6: 127 | J6: 138 | K6: 139 | L6: 197 | M6: 203 | N6: 204 | O6: 230 | P6: 209 | Q6: 56677 | R6: 796 | S6: 2146 | T6: 142 | U6: 143 | V6: 125 | W6: 187 | X6: 163 | Y6: 298 | Z6: 299 | AA6: 219 | AB6: 151 | AC6: 152 | AD6: 153 | AE6: 154 | AF6: 756 | AG6: 156 | AH6: 155 | AI6: 182 | AJ6: 212 | AK6: 758 | AL6: 263 | AM6: 265 | AN6: 775 | AO6: 777 | AP6: 2154 | AQ6: 150 | AR6: 149 | AS6: 188 | AT6: 2131 | AU6: 755 | AV6: 252 | AW6: 249 | AX6: 250 | AY6: 117 | AZ6: 267 | BA6: 268 | BB6: 119 | BC6: 120 | BD6: 189 | BE6: 122 | BF6: 266 | BG6: 337 | BH6: 338 | BI6: 251 | BJ6: 115 | BK6: 239 | BL6: 288 | BM6: 240 | BN6: 241 | BO6: 242 | BP6: 191 | BQ6: 194 | BR6: 196 | BS6: 207 | BT6: 236 | BU6: 795 | BV6: 285 | BW6: 995 | BX6: 996 | BY6: 997 | BZ6: 766 | CA6: 926 | CB6: 924 | CC6: 121 | CD6: 103 | CE6: 104 | CF6: 106 | CG6: 105 | CH6: 107 | CI6: 110 | CJ6: 109 | CK6: 144 | CL6: 113 | CM6: 114 | CN6: 193 | CO6: 208 | CP6: 786 | CQ6: 787 | CR6: 788 | CS6: 789 | CT6: 248 | CU6: 2159 | CV6: 303 | CW6: 59715 | CX6: 62255 | CY6: 1263 | CZ6: 61800 | DA6: 2194 | DB6: 69125 | DC6: 216 | DD6: 198 | DE6: 70400 | DF6: 49607 | DG6: 214 | DH6: 260 | DI6: 2152 | DJ6: 2128 | DK6: 247 | DL6: 228 | DM6: 2135 | DN6: 261 | DO6: 237 | DP6: 253 | DQ6: 770 | DR6: 235 | DS6: 238 | DT6: 2184 | DU6: 61855 | DV6: 223 | DW6: 226 | DX6: 201 | DY6: 258 | DZ6: 259 | EA6: 920 | EB6: 257 | EC6: 256 | ED6: 2148 | EE6: 58288 | EF6: 58289 | EG6: 58839 | EH6: 58840 | EI6: 296 | EJ6: 297 | EK6: 211 | EL6: 2175 | EM6: 2178 | EN6: 2181 | EO6: 1262 | EP6: 63425 | EQ6: 233 | ER6: 2150 | ES6: 2165 | ET6: 2161 | EU6: 61197 | EV6: 58851 | EW6: 225 | EX6: 2201 | EY6: 2171 | EZ6: 760 | FA6: 234 | FB6: 215 | FC6: 917 | FD6: 289 | FE6: 58333 | FF6: 58336 | FG6: 213 | FH6: 232 | FI6: 2190 | FJ6: 69867 | FK6: TOTAL COES | FM6: 221 | FN6: 222 | FO6: 224 | FP6: 2187 | FQ6: 227 | FR6: 49400 | FS6: 199 | FT6: 200 | FU6: TOTAL NO COES
C7: SUR | D7: CENTRO | E7: CENTRO | F7: NORTE | G7: NORTE | H7: NORTE | I7: NORTE | J7: CENTRO | K7: CENTRO | L7: CENTRO | M7: CENTRO | N7: CENTRO | O7: CENTRO | P7: CENTRO | Q7: CENTRO | R7: CENTRO | S7: CENTRO | T7: CENTRO | U7: CENTRO | V7: CENTRO | W7: CENTRO | X7: SUR | Y7: SUR | Z7: SUR | AA7: CENTRO | AB7: SUR | AC7: SUR | AD7: SUR | AE7: SUR | AF7: SUR | AG7: SUR | AH7: SUR | AI7: SUR | AJ7: CENTRO | AK7: NORTE | AL7: NORTE | AM7: NORTE | AN7: CENTRO | AO7: CENTRO | AP7: CENTRO | AQ7: CENTRO | AR7: CENTRO | AS7: CENTRO | AT7: CENTRO | AU7: SUR | AV7: CENTRO | AW7: CENTRO | AX7: CENTRO | AY7: CENTRO | AZ7: CENTRO | BA7: CENTRO | BB7: CENTRO | BC7: CENTRO | BD7: SUR | BE7: NORTE | BF7: CENTRO | BG7: CENTRO | BH7: CENTRO | BI7: CENTRO | BJ7: NORTE | BK7: NORTE | BL7: NORTE | BM7: SUR | BN7: SUR | BO7: SUR | BP7: CENTRO | BQ7: CENTRO | BR7: CENTRO | BS7: CENTRO | BT7: CENTRO | BU7: CENTRO | BV7: CENTRO | BW7: SUR | BX7: SUR | BY7: SUR | BZ7: NORTE | CA7: SUR | CB7: CENTRO | CC7: NORTE | CD7: CENTRO | CE7: CENTRO | CF7: CENTRO | CG7: CENTRO | CH7: CENTRO | CI7: CENTRO | CJ7: CENTRO | CK7: CENTRO | CL7: CENTRO | CM7: CENTRO | CN7: CENTRO | CO7: CENTRO | CP7: SUR | CQ7: SUR | CR7: SUR | CS7: SUR | CT7: CENTRO | CU7: CENTRO | CV7: CENTRO | CW7: CENTRO | CX7: SUR | CY7: NORTE | CZ7: NORTE | DA7: NORTE | DB7: CENTRO | DC7: NORTE | DD7: NORTE | DE7: SUR | DF7: SUR | DG7: CENTRO | DH7: CENTRO | DI7: CENTRO | DJ7: NORTE | DK7: NORTE | DL7: CENTRO | DM7: CENTRO | DN7: SUR | DO7: SUR | DP7: CENTRO | DQ7: CENTRO | DR7: SUR | DS7: CENTRO | DT7: CENTRO | DU7: NORTE | DV7: CENTRO | DW7: CENTRO | DX7: NORTE | DY7: CENTRO | DZ7: CENTRO | EA7: CENTRO | EB7: NORTE | EC7: NORTE | ED7: SUR | EE7: CENTRO | EF7: CENTRO | EG7: CENTRO | EH7: CENTRO | EI7: CENTRO | EJ7: CENTRO | EK7: SUR | EL7: SUR | EM7: SUR | EN7: SUR | EO7: NORTE | EP7: SUR | EQ7: SUR | ER7: SUR | ES7: CENTRO | ET7: CENTRO | EU7: CENTRO | EV7: SUR | EW7: CENTRO | EX7: CENTRO | EY7: CENTRO | EZ7: CENTRO | FA7: SUR | FB7: NORTE | FC7: CENTRO | FD7: NORTE | FE7: NORTE | FF7: NORTE | FG7: CENTRO | FH7: NORTE | FI7: NORTE | FJ7: NORTE | FM7: NORTE | FN7: CENTRO | FO7: NORTE | FP7: NORTE | FQ7: NORTE | FR7: NORTE | FS7: NORTE | FT7: NORTE
C8: HIDROELÉCTRICA | D8: HIDROELÉCTRICA | E8: HIDROELÉCTRICA | F8: TERMOELÉCTRICA | G8: TERMOELÉCTRICA | H8: HIDROELÉCTRICA | I8: HIDROELÉCTRICA | J8: TERMOELÉCTRICA | K8: TERMOELÉCTRICA | L8: TERMOELÉCTRICA | M8: TERMOELÉCTRICA | N8: TERMOELÉCTRICA | O8: TERMOELÉCTRICA | P8: TERMOELÉCTRICA | Q8: TERMOELÉCTRICA | R8: HIDROELÉCTRICA | S8: HIDROELÉCTRICA | T8: TERMOELÉCTRICA | U8: TERMOELÉCTRICA | V8: TERMOELÉCTRICA | W8: TERMOELÉCTRICA | X8: HIDROELÉCTRICA | Y8: HIDROELÉCTRICA | Z8: HIDROELÉCTRICA | AA8: TERMOELÉCTRICA | AB8: HIDROELÉCTRICA | AC8: HIDROELÉCTRICA | AD8: HIDROELÉCTRICA | AE8: HIDROELÉCTRICA | AF8: TERMOELÉCTRICA | AG8: TERMOELÉCTRICA | AH8: TERMOELÉCTRICA | AI8: HIDROELÉCTRICA | AJ8: HIDROELÉCTRICA | AK8: TERMOELÉCTRICA | AL8: TERMOELÉCTRICA | AM8: TERMOELÉCTRICA | AN8: HIDROELÉCTRICA | AO8: HIDROELÉCTRICA | AP8: HIDROELÉCTRICA | AQ8: HIDROELÉCTRICA | AR8: HIDROELÉCTRICA | AS8: HIDROELÉCTRICA | AT8: HIDROELÉCTRICA | AU8: HIDROELÉCTRICA | AV8: TERMOELÉCTRICA | AW8: TERMOELÉCTRICA | AX8: TERMOELÉCTRICA | AY8: HIDROELÉCTRICA | AZ8: HIDROELÉCTRICA | BA8: HIDROELÉCTRICA | BB8: HIDROELÉCTRICA | BC8: HIDROELÉCTRICA | BD8: HIDROELÉCTRICA | BE8: HIDROELÉCTRICA | BF8: HIDROELÉCTRICA | BG8: HIDROELÉCTRICA | BH8: HIDROELÉCTRICA | BI8: HIDROELÉCTRICA | BJ8: TERMOELÉCTRICA | BK8: TERMOELÉCTRICA | BL8: TERMOELÉCTRICA | BM8: TERMOELÉCTRICA | BN8: TERMOELÉCTRICA | BO8: TERMOELÉCTRICA | BP8: HIDROELÉCTRICA | BQ8: TERMOELÉCTRICA | BR8: TERMOELÉCTRICA | BS8: TERMOELÉCTRICA | BT8: TERMOELÉCTRICA | BU8: TERMOELÉCTRICA | BV8: TERMOELÉCTRICA | BW8: TERMOELÉCTRICA | BX8: TERMOELÉCTRICA | BY8: TERMOELÉCTRICA | BZ8: HIDROELÉCTRICA | CA8: TERMOELÉCTRICA | CB8: TERMOELÉCTRICA | CC8: HIDROELÉCTRICA | CD8: HIDROELÉCTRICA | CE8: HIDROELÉCTRICA | CF8: HIDROELÉCTRICA | CG8: HIDROELÉCTRICA | CH8: HIDROELÉCTRICA | CI8: TERMOELÉCTRICA | CJ8: TERMOELÉCTRICA | CK8: TERMOELÉCTRICA | CL8: TERMOELÉCTRICA | CM8: TERMOELÉCTRICA | CN8: TERMOELÉCTRICA | CO8: TERMOELÉCTRICA | CP8: TERMOELÉCTRICA | CQ8: TERMOELÉCTRICA | CR8: TERMOELÉCTRICA | CS8: TERMOELÉCTRICA | CT8: TERMOELÉCTRICA | CU8: TERMOELÉCTRICA | CV8: SOLAR | CW8: EÓLICA | CX8: SOLAR | CY8: EÓLICA | CZ8: SOLAR | DA8: HIDROELÉCTRICA | DB8: HIDROELÉCTRICA | DC8: HIDROELÉCTRICA | DD8: HIDROELÉCTRICA | DE8: SOLAR | DF8: HIDROELÉCTRICA | DG8: HIDROELÉCTRICA | DH8: HIDROELÉCTRICA | DI8: HIDROELÉCTRICA | DJ8: HIDROELÉCTRICA | DK8: HIDROELÉCTRICA | DL8: HIDROELÉCTRICA | DM8: HIDROELÉCTRICA | DN8: SOLAR | DO8: SOLAR | DP8: EÓLICA | DQ8: EÓLICA | DR8: SOLAR | DS8: HIDROELÉCTRICA | DT8: HIDROELÉCTRICA | DU8: HIDROELÉCTRICA | DV8: HIDROELÉCTRICA | DW8: HIDROELÉCTRICA | DX8: HIDROELÉCTRICA | DY8: HIDROELÉCTRICA | DZ8: HIDROELÉCTRICA | EA8: HIDROELÉCTRICA | EB8: EÓLICA | EC8: EÓLICA | ED8: SOLAR | EE8: EÓLICA | EF8: EÓLICA | EG8: EÓLICA | EH8: EÓLICA | EI8: HIDROELÉCTRICA | EJ8: HIDROELÉCTRICA | EK8: HIDROELÉCTRICA | EL8: HIDROELÉCTRICA | EM8: HIDROELÉCTRICA | EN8: HIDROELÉCTRICA | EO8: EÓLICA | EP8: SOLAR | EQ8: SOLAR | ER8: SOLAR | ES8: HIDROELÉCTRICA | ET8: EÓLICA | EU8: EÓLICA | EV8: SOLAR | EW8: TERMOELÉCTRICA | EX8: TERMOELÉCTRICA | EY8: TERMOELÉCTRICA | EZ8: TERMOELÉCTRICA | FA8: SOLAR | FB8: HIDROELÉCTRICA | FC8: HIDROELÉCTRICA | FD8: TERMOELÉCTRICA | FE8: TERMOELÉCTRICA | FF8: TERMOELÉCTRICA | FG8: TERMOELÉCTRICA | FH8: TERMOELÉCTRICA | FI8: TERMOELÉCTRICA | FJ8: TERMOELÉCTRICA | FM8: HIDROELÉCTRICA | FN8: HIDROELÉCTRICA | FO8: HIDROELÉCTRICA | FP8: HIDROELÉCTRICA | FQ8: TERMOELÉCTRICA | FR8: TERMOELÉCTRICA | FS8: HIDROELÉCTRICA | FT8: HIDROELÉCTRICA
C9: HYDRO GLOBAL PERÚ S.A.C. | D9: ELECTROPERU | E9: ELECTROPERU | F9: ELECTROPERU | G9: ELECTROPERU | H9: ORAZUL ENERGY PERÚ | I9: ORAZUL ENERGY PERÚ | J9: TERMOSELVA | K9: TERMOSELVA | L9: KALLPA GENERACION S.A. | M9: KALLPA GENERACION S.A. | N9: KALLPA GENERACION S.A. | O9: KALLPA GENERACION S.A. | P9: KALLPA GENERACION S.A. | Q9: KALLPA GENERACION S.A. | R9: KALLPA GENERACION S.A. | S9: KALLPA GENERACION S.A. | T9: SHOUGESA | U9: SHOUGESA | V9: SHOUGESA | W9: SHOUGESA | X9: EGEMSA | Y9: EGESUR | Z9: EGESUR | AA9: EGESUR | AB9: EGASA | AC9: EGASA | AD9: EGASA | AE9: EGASA | AF9: EGASA | AG9: EGASA | AH9: EGASA | AI9: SAN GABAN | AJ9: CELEPSA | AK9: MINERA CERRO VERDE | AL9: PLANTA DE RESERVA FRIA DE GENERACION DE ETEN S.A. | AM9: PLANTA DE RESERVA FRIA DE GENERACION DE ETEN S.A. | AN9: EMPRESA DE GENERACION HUALLAGA | AO9: EMPRESA DE GENERACION HUALLAGA | AP9: LA VIRGEN | AQ9: CHINANGO S.A.C. | AR9: CHINANGO S.A.C. | AS9: HIDROELECTRICA HUANCHOR S.A.C. | AT9: CELEPSA RENOVABLES S.R.L. | AU9: INLAND ENERGY SAC | AV9: FENIX POWER PERÚ | AW9: FENIX POWER PERÚ | AX9: FENIX POWER PERÚ | AY9: STATKRAFT S.A | AZ9: STATKRAFT S.A | BA9: STATKRAFT S.A | BB9: STATKRAFT S.A | BC9: STATKRAFT S.A | BD9: STATKRAFT S.A | BE9: STATKRAFT S.A | BF9: STATKRAFT S.A | BG9: CENTRALES SANTA ROSA S.A.C. | BH9: CENTRALES SANTA ROSA S.A.C. | BI9: EMPRESA DE GENERACION HUANZA | BJ9: ENEL GENERACION PIURA S.A. | BK9: ENEL GENERACION PIURA S.A. | BL9: ENEL GENERACION PIURA S.A. | BM9: ENGIE ENERGIA PERU S.A.A. | BN9: ENGIE ENERGIA PERU S.A.A. | BO9: ENGIE ENERGIA PERU S.A.A. | BP9: ENGIE ENERGIA PERU S.A.A. | BQ9: ENGIE ENERGIA PERU S.A.A. | BR9: ENGIE ENERGIA PERU S.A.A. | BS9: ENGIE ENERGIA PERU S.A.A. | BT9: ENGIE ENERGIA PERU S.A.A. | BU9: ENGIE ENERGIA PERU S.A.A. | BV9: ENGIE ENERGIA PERU S.A.A. | BW9: ENGIE ENERGIA PERU S.A.A. | BX9: ENGIE ENERGIA PERU S.A.A. | BY9: ENGIE ENERGIA PERU S.A.A. | BZ9: ENGIE ENERGIA PERU S.A.A. | CA9: INFRAESTRUCTURAS Y ENERGIAS DEL PERU S.A.C. | CB9: INFRAESTRUCTURAS Y ENERGIAS DEL PERU S.A.C. | CC9: INVERSIONES SHAQSHA S.A.C. | CD9: ORYGEN PERU S.A.A. | CE9: ORYGEN PERU S.A.A. | CF9: ORYGEN PERU S.A.A. | CG9: ORYGEN PERU S.A.A. | CH9: ORYGEN PERU S.A.A. | CI9: ORYGEN PERU S.A.A. | CJ9: ORYGEN PERU S.A.A. | CK9: ORYGEN PERU S.A.A. | CL9: ORYGEN PERU S.A.A. | CM9: ORYGEN PERU S.A.A. | CN9: ORYGEN PERU S.A.A. | CO9: ORYGEN PERU S.A.A. | CP9: SAMAY I S.A.C | CQ9: SAMAY I S.A.C | CR9: SAMAY I S.A.C | CS9: SAMAY I S.A.C | CT9: TERMOCHILCA S.A.C. | CU9: TERMOCHILCA S.A.C. | CV9: COLCA SOLAR S.A.C. | CW9: ENERGIA RENOVABLE DEL SUR S.A. | CX9: GR CORTARRAMA SOCIEDAD ANONIMA CERRADA | CY9: GR TARUCA SOCIEDAD ANONIMA CERRADA | CZ9: KONDU SAC | DA9: PERUANA DE INVERSIONES EN ENERGIAS RENOVABLES S.A. | DB9: VARI ENERGIA S.A.C. | DC9: ORAZUL ENERGY PERÚ | DD9: ORAZUL ENERGY PERÚ | DE9: KALLPA GENERACION S.A. | DF9: SAN GABAN | DG9: MAJA ENERGIA S.A.C. | DH9: EMPRESA DE GENERACION ELECTRICA CANCHAYLLO SAC | DI9: EMPRESA DE GENERACION ELECTRICA SANTA ANA S.A.C. | DJ9: EMPRESA ELECTRICA AGUA AZUL | DK9: EMPRESA ELECTRICA RIO DOBLE | DL9: HIDROCAÑETE S.A. | DM9: HUAURA POWER GROUP S.A. | DN9: MOQUEGUA FV S.A.C. | DO9: PANAMERICANA SOLAR SAC. | DP9: PARQUE EOLICO MARCONA S.A.C. | DQ9: PARQUE EOLICO TRES HERMANAS S.A.C. | DR9: TACNA SOLAR SAC. | DS9: ELECTRICA YANAPAMPA SAC | DT9: ANDEAN POWER S.A.C. | DU9: ASOCIACIÓN SANTA LUCIA DE CHACAS | DV9: ATRIA ENERGIA S.A.C. | DW9: EGEJUNIN | DX9: EGEJUNIN | DY9: EGEJUNIN | DZ9: EGEJUNIN | EA9: EMPRESA DE GENERACION ELECTRICA RIO BAÑOS S.A.C. | EB9: ENERGÍA EÓLICA S.A. | EC9: ENERGÍA EÓLICA S.A. | ED9: ENGIE ENERGIA PERU S.A.A. | EE9: ENGIE ENERGIA PERU S.A.A. | EF9: ENGIE ENERGIA PERU S.A.A. | EG9: ENGIE ENERGIA PERU S.A.A. | EH9: ENGIE ENERGIA PERU S.A.A. | EI9: GENERACIÓN ANDINA S.A.C. | EJ9: GENERACIÓN ANDINA S.A.C. | EK9: GENERADORA DE ENERGÍA DEL PERÚ | EL9: GENERADORA DE ENERGÍA DEL PERÚ | EM9: GENERADORA DE ENERGÍA DEL PERÚ | EN9: GENERADORA DE ENERGÍA DEL PERÚ | EO9: GR PAINO SOCIEDAD ANONIMA CERRADA | EP9: JOYA SOLAR S.A.C. | EQ9: MAJES ARCUS S.A.C. | ER9: ORYGEN PERU S.A.A. | ES9: ORYGEN PERU S.A.A. | ET9: ORYGEN PERU S.A.A. | EU9: ORYGEN PERU S.A.A. | EV9: ORYGEN PERU S.A.A. | EW9: PETRAMAS | EX9: PETRAMAS | EY9: PETRAMAS | EZ9: PETRAMAS | FA9: REPARTICIÓN ARCUS S.A.C. | FB9: SINERSA | FC9: SINERSA | FD9: BIOENERGIA DEL CHIRA S.A. | FE9: GM OPERACIONES S.A.C. | FF9: GM OPERACIONES S.A.C. | FG9: AGRO INDUSTRIAL PARAMONGA S.A. | FH9: AGROAURORA S.A.C. | FI9: AGROINDUSTRIAS SAN JACINTO S.A.A. | FJ9: AGROLMOS SOCIEDAD ANONIMA - AGROLMOS S.A. | FM9: UNACEM PERU S.A. | FN9: ELECTRO ORIENTE | FO9: AGUAS Y ENERGIA PERU | FP9: ELECTRO ZAÑA S.A.C. | FQ9: ELECTRONOROESTE S.A. | FR9: SDE PIURA | FS9: SINERSA | FT9: SINERSA
C10: SAN GABAN III | D10: MANTARO | E10: RESTITUCION | F10: TUMBES MAK 1 | G10: TUMBES MAK 2 | H10: CARHUAQUERO | I10: CAÑON DEL PATO | J10: AGUAYTIA TG1 | K10: AGUAYTIA TG2 | L10: KALLPA TG1 | M10: KALLPA TG2 | N10: KALLPA TG3 | O10: KALLPA TV | P10: LFLORES TG1 | Q10: LFLORES TV | R10: CERRO DEL AGUILA | S10: CERRODELAGUILAG4 | T10: SHOUGESA TV1 | U10: SHOUGESA TV2 | V10: SHOUGESA TV3 | W10: SHOUGESA CUMMINS | X10: MACHUPICCHU | Y10: ARICOTA 1 | Z10: ARICOTA 2 | AA10: INDEPENDENCIA | AB10: CHARCANI I,II,III | AC10: CHARCANI IV | AD10: CHARCANI V | AE10: CHARCANI VI | AF10: CHILINA TG | AG10: MOLLENDO 1, 2, 3 | AH10: CHILINA (SULZ 1,2) | AI10: SAN GABAN II | AJ10: PLATANAL | AK10: RECKA | AL10: RF ETEN TG1 | AM10: RF ETEN TG2 | AN10: CHAGLLA GP1 | AO10: CHAGLLA | AP10: LA VIRGEN | AQ10: CHIMAY | AR10: YANANGO | AS10: HUANCHOR | AT10: MARAÑON | AU10: STA TERESA | AV10: FENIX GT11 | AW10: FENIX GT12 | AX10: FENIX TV10 | AY10: YAUPI | AZ10: OROYA | BA10: PACHACHACA | BB10: MALPASO | BC10: CAHUA | BD10: ARCATA | BE10: GALLITO CIEGO | BF10: CHEVES | BG10: SANTA ROSA 1 | BH10: SANTA ROSA 2 | BI10: HUANZA | BJ10: MALACAS2 TG4 | BK10: MALACAS3 TG 5 | BL10: MALACAS1 TG6 | BM10: RF ILO2 TG1 | BN10: RF ILO2 TG2 | BO10: RF ILO2 TG3 | BP10: YUNCAN | BQ10: CHILCA1 TG1 | BR10: CHILCA1 TG2 | BS10: CHILCA1 TG3 | BT10: CHILCA-TV | BU10: CHILCA2 TG41 | BV10: CHILCA2-TV | BW10: CTNEPI_TG41 | BX10: CTNEPI_TG42 | BY10: CTNEPI_TG43 | BZ10: QUITARACSA | CA10: RF PTO MALDONADO | CB10: RF PUCALLPA | CC10: PARIAC | CD10: HUINCO | CE10: MATUCANA | CF10: MOYOPAMPA | CG10: CALLAHUANCA | CH10: HUAMPANI | CI10: STA ROSA WEST TG7 | CJ10: UTI_5 | CK10: UTI_6 | CL10: VENTANILLA 3 | CM10: VENTANILLA 4 | CN10: VENTANILLA TV | CO10: STAROSA TG8 | CP10: PTO_BRVO TG1 | CQ10: PTO_BRVO TG2 | CR10: PTO_BRVO TG3 | CS10: PTO_BRVO TG4 | CT10: OLLEROS TG1 | CU10: OLLEROS TV | CV10: CS YARUCAYA | CW10: SAN JUAN | CX10: MATARANI | CY10: DUNA | CZ10: CARHUAQUERO (CS) | DA10: MANTA I | DB10: ANASHIRONI | DC10: CARHUAQUERO4 | DD10: CAÑA BRAVA | DE10: SUNNY | DF10: TUPURI | DG10: RONCADOR | DH10: CANCHAYLLO | DI10: RENOVANDESH1 | DJ10: POTRERO | DK10: PIZARRAS | DL10: NIMPERIAL | DM10: YARUCAYA | DN10: MOQUEGUA-SOLAR | DO10: PANAMERICANA-SOLAR | DP10: PQE-EOLICO-MARCONA | DQ10: PQE-EOLICO-3-HERMANAS | DR10: TACNA-SOLAR | DS10: YANAPAMPA | DT10: CARHUAC | DU10: HUALLIN | DV10: PURMACANA | DW10: HUASAHUASI | DX10: STACRUZ_1_2 | DY10: RUNATULLO_II | DZ10: RUNATULLO_III | EA10: RUCUY | EB10: PQE-EOLICO-TALARA | EC10: PQE-EOLICO-CUPISNIQUE | ED10: INTIPAMPA | EE10: PUNTA LOMITAS-BL1 | EF10: PUNTA LOMITAS-BL2 | EG10: PUN LOMITAS_EXP-BL1 | EH10: PUN LOMITAS_EXP-BL2 | EI10: 8AGOSTO | EJ10: EL CARMEN | EK10: LA JOYA | EL10: ANGEL_I | EM10: ANGEL_II | EN10: ANGEL_III | EO10: HUAMBOS | EP10: SAN MARTIN SOLAR | EQ10: MAJES | ER10: RUBI | ES10: CH_HER1 | ET10: WAYRA-I | EU10: WAYRA EXTENSION | EV10: CLEMESI | EW10: HUAYCOLORO | EX10: CALLAO | EY10: DONA_CATALINA | EZ10: LAGRINGAV | FA10: REPARTICION | FB10: POECHOS2 | FC10: CHANCAY | FD10: CANA BRAVA | FE10: REFINERIA TALARA TV1 | FF10: REFINERÍA TALARA TV2 | FG10: PARAMONGA | FH10: MAPLE | FI10: SAN_JACINTO | FJ10: AGROLMOS | FK10: MW | FM10: CARPAPATA | FN10: CENTRALES ELOR | FO10: PIAS1 | FP10: ZANA | FQ10: TABLAZO | FR10: TALLANCA | FS10: CURUMUY | FT10: POECHOS1 | FU10: MW
A11: 05/11/2025 | B11: 00:30 | C11: 200.5 | D11: 619.1 | E11: 212.5 | H11: 90.9 | I11: 190 | L11: 133 | M11: 133.2 | N11: 133.1 | O11: 233.5 | P11: 0 | R11: 346.8 | S11: 5.5 | X11: 147 | Y11: 7.1 | Z11: 5.7 | AA11: 5.7 | AB11: 6.9 | AC11: 14.4 | AD11: 89.4 | AI11: 109.6 | AJ11: 51.2 | AN11: 6.4 | AO11: 145.8 | AP11: 53 | AQ11: 118.2 | AR11: 26.8 | AS11: 18.4 | AT11: 18.8 | AU11: 79.3 | AY11: 107.6 | AZ11: 7.4 | BA11: 6 | BB11: 25 | BC11: 42.5 | BD11: 2 | BE11: 11.7 | BF11: 64.8 | BI11: 66.7 | BL11: 0 | BP11: 82.7 | BQ11: 153.5 | BR11: 153.2 | BS11: 153.5 | BT11: 239.6 | CC11: 4 | CD11: 151 | CE11: 61.8 | CF11: 62.5 | CG11: 46.8 | CH11: 28.4 | CL11: 146 | CM11: 147.8 | CN11: 148.6 | CT11: 216.3 | CU11: 103.7 | CV11: 0 | CW11: 85.3 | CX11: 0 | CY11: 0 | CZ11: 0 | DA11: 20 | DB11: 20.2 | DF11: 1 | DG11: 3.3 | DH11: 3 | DJ11: 18.4 | DK11: 19 | DL11: 3.5 | DM11: 18.6 | DN11: 0 | DO11: 0 | DP11: 30.4 | DQ11: 84.3 | DR11: 0 | DS11: 3.1 | DT11: 18.4 | DU11: 2.7 | DW11: 10.4 | DX11: 9.3 | DY11: 10.4 | DZ11: 13.7 | EA11: 15.5 | EB11: 11.4 | EC11: 61 | ED11: 0 | EE11: 52.4 | EF11: 84.9 | EG11: 4 | EH11: 2.8 | EI11: 20.9 | EJ11: 7.6 | EK11: 7.9 | EL11: 18.9 | EM11: 19.8 | EN11: 19.8 | EO11: 0 | EQ11: 0 | ER11: 0 | ES11: 0.6 | ET11: 12.4 | EU11: 14.4 | EV11: 0 | EW11: 1.1 | EY11: 1.8 | EZ11: 1 | FA11: 0 | FB11: 6.1 | FC11: 18.6 | FD11: 8.7 | FE11: 26.9 | FF11: 33.1 | FG11: 15 | FH11: 0 | FI11: 7.1 | FJ11: 11 | FK11: 6294.6 | FM11: 11.4614 | FN11: 7.96 | FO11: 6 | FP11: 13.2 | FQ11: 27.1 | FR11: 18.9 | FS11: 4.3 | FT11: 5.3 | FU11: 94.2214
A12: 05/11/2025 | B12: 01:00 | C12: 199 | D12: 625.6 | E12: 214.7 | H12: 87.9 | I12: 196.2 | L12: 119.8 | M12: 119.7 | N12: 119.4 | O12: 221.4 | P12: 0 | R12: 350.4 | S12: 5.6 | X12: 146.7 | Y12: 7.2 | Z12: 5.5 | AA12: 5.7 | AB12: 6.9 | AC12: 13.1 | AD12: 70 | AI12: 110.4 | AJ12: 51.1 | AN12: 6.4 | AO12: 148.4 | AP12: 52.2 | AQ12: 114.5 | AR12: 27.3 | AS12: 18.4 | AT12: 18.8 | AU12: 78.1 | AY12: 108.3 | AZ12: 7.5 | BA12: 6 | BB12: 24.1 | BC12: 43.1 | BD12: 2 | BE12: 11.7 | BF12: 67.2 | BI12: 65.6 | BL12: 0 | BP12: 83.6 | BQ12: 154.6 | BR12: 154.6 | BS12: 153.9 | BT12: 239.4 | CC12: 3.9 | CD12: 129.4 | CE12: 66.5 | CF12: 63.5 | CG12: 47.2 | CH12: 29.1 | CL12: 147.4 | CM12: 148.5 | CN12: 150.4 | CT12: 216.3 | CU12: 103.6 | CV12: 0 | CW12: 81.3 | CX12: 0 | CY12: 0.3 | CZ12: 0 | DA12: 20 | DB12: 20.6 | DF12: 1 | DG12: 3.3 | DH12: 2.8 | DJ12: 20 | DK12: 19 | DL12: 3.5 | DM12: 18.6 | DN12: 0 | DO12: 0 | DP12: 29.6 | DQ12: 79.6 | DR12: 0 | DS12: 3.1 | DT12: 16 | DU12: 2.7 | DW12: 10 | DX12: 9.3 | DY12: 10.4 | DZ12: 13.9 | EA12: 15.5 | EB12: 11.5 | EC12: 52.4 | ED12: 0 | EE12: 65.4 | EF12: 90 | EG12: 8.2 | EH12: 3.9 | EI12: 20.9 | EJ12: 7.5 | EK12: 8 | EL12: 18.5 | EM12: 19.8 | EN12: 19.8 | EO12: 0 | EQ12: 0 | ER12: 0 | ES12: 0.6 | ET12: 8 | EU12: 8.4 | EV12: 0 | EW12: 1.1 | EY12: 1.8 | EZ12: 1 | FA12: 0 | FB12: 6.2 | FC12: 18.6 | FD12: 8 | FE12: 26.5 | FF12: 33.2 | FG12: 15 | FH12: 0 | FI12: 7 | FJ12: 10.5 | FK12: 6220.1 | FM12: 11.47448 | FN12: 0.74 | FO12: 6 | FP12: 13.2 | FQ12: 27.1 | FR12: 18.9 | FS12: 4.4 | FT12: 5.3 | FU12: 87.11448
A13: 05/11/2025 | B13: 01:30 | C13: 203.5 | D13: 628.7 | E13: 213.6 | H13: 90.6 | I13: 198.1 | L13: 121.1 | M13: 122 | N13: 120.7 | O13: 219.9 | P13: 0 | R13: 352.6 | S13: 5.8 | X13: 148.4 | Y13: 7.6 | Z13: 5.7 | AA13: 5.6 | AB13: 6.9 | AC13: 11.5 | AD13: 70.5 | AI13: 110.6 | AJ13: 51.2 | AN13: 6.4 | AO13: 149.3 | AP13: 52 | AQ13: 126.3 | AR13: 27.2 | AS13: 18.4 | AT13: 18.8 | AU13: 80.8 | AY13: 108.3 | AZ13: 7.5 | BA13: 6.1 | BB13: 22.1 | BC13: 44.3 | BD13: 2 | BE13: 12 | BF13: 69.8 | BI13: 66.7 | BL13: 0 | BP13: 84.4 | BQ13: 137 | BR13: 137 | BS13: 136.8 | BT13: 221.1 | CC13: 4 | CD13: 152.4 | CE13: 66.1 | CF13: 64.3 | CG13: 47.4 | CH13: 29.6 | CL13: 147.2 | CM13: 148.4 | CN13: 150 | CT13: 215.9 | CU13: 103.4 | CV13: 0 | CW13: 78.8 | CX13: 0 | CY13: 0.7 | CZ13: 0 | DA13: 20 | DB13: 20.8 | DF13: 1 | DG13: 3.3 | DH13: 2.8 | DJ13: 19.8 | DK13: 18.9 | DL13: 3.5 | DM13: 18.6 | DN13: 0 | DO13: 0 | DP13: 25.6 | DQ13: 59.7 | DR13: 0 | DS13: 3.2 | DT13: 15.8 | DU13: 2.7 | DW13: 10 | DX13: 9.3 | DY13: 10.6 | DZ13: 14.2 | EA13: 15.5 | EB13: 16.2 | EC13: 53.5 | ED13: 0 | EE13: 57 | EF13: 73.8 | EG13: 4.5 | EH13: 1.1 | EI13: 20.9 | EJ13: 7.5 | EK13: 7.9 | EL13: 18.5 | EM13: 19.8 | EN13: 19.8 | EO13: 0 | EQ13: 0 | ER13: 0 | ES13: 0.6 | ET13: 2.7 | EU13: 1.5 | EV13: 0 | EW13: 1.1 | EY13: 1.8 | EZ13: 1 | FA13: 0 | FB13: 6.1 | FC13: 18.6 | FD13: 8.5 | FE13: 27.1 | FF13: 32 | FG13: 14.8 | FH13: 0 | FI13: 6.9 | FJ13: 10 | FK13: 6145.6 | FM13: 11.67608 | FN13: 0 | FO13: 6 | FP13: 13.2 | FQ13: 27.1 | FR13: 18.9 | FS13: 4.3 | FT13: 5.3 | FU13: 86.47608
A14: 05/11/2025 | B14: 02:00 | C14: 203.7 | D14: 627.7 | E14: 213.9 | H14: 90.1 | I14: 205 | L14: 129.7 | M14: 129.3 | N14: 130 | O14: 227.1 | P14: 0 | R14: 349.7 | S14: 5.7 | X14: 148.5 | Y14: 7.5 | Z14: 5.7 | AA14: 5.6 | AB14: 6.9 | AC14: 10 | AD14: 70.5 | AI14: 110.5 | AJ14: 51.5 | AN14: 6.4 | AO14: 148.5 | AP14: 52 | AQ14: 106.3 | AR14: 27.9 | AS14: 18.4 | AT14: 18.8 | AU14: 79.5 | AY14: 108.3 | AZ14: 7.5 | BA14: 6 | BB14: 22.8 | BC14: 44 | BD14: 2 | BE14: 12 | BF14: 68.4 | BI14: 66.6 | BL14: 0 | BP14: 84.3 | BQ14: 140.4 | BR14: 140.2 | BS14: 140.1 | BT14: 225.9 | CC14: 3.9 | CD14: 133.9 | CE14: 60.6 | CF14: 64 | CG14: 46.9 | CH14: 29.5 | CL14: 146.9 | CM14: 148.5 | CN14: 149.2 | CT14: 215.9 | CU14: 103.8 | CV14: 0 | CW14: 94.5 | CX14: 0 | CY14: 0 | CZ14: 0 | DA14: 20 | DB14: 20.7 | DF14: 1 | DG14: 3.2 | DH14: 2.8 | DJ14: 19.6 | DK14: 18.9 | DL14: 3.5 | DM14: 18.6 | DN14: 0 | DO14: 0 | DP14: 29.3 | DQ14: 47.9 | DR14: 0 | DS14: 3.2 | DT14: 15.9 | DU14: 2.8 | DW14: 10 | DX14: 9.2 | DY14: 10.6 | DZ14: 14.1 | EA14: 15.6 | EB14: 19.4 | EC14: 48.9 | ED14: 0 | EE14: 29.3 | EF14: 42.5 | EG14: 1.6 | EH14: 1.1 | EI14: 20.9 | EJ14: 7.5 | EK14: 7.9 | EL14: 18.5 | EM14: 19.8 | EN14: 19.8 | EO14: 0 | EQ14: 0 | ER14: 0 | ES14: 0.6 | ET14: 6.4 | EU14: 0.9 | EV14: 0 | EW14: 1.1 | EY14: 1.8 | EZ14: 1 | FA14: 0 | FB14: 6.1 | FC14: 18.7 | FD14: 9.3 | FE14: 27.4 | FF14: 31.9 | FG14: 15.4 | FH14: 0 | FI14: 7 | FJ14: 10 | FK14: 6094.2 | FM14: 11.67979 | FN14: 0 | FO14: 6 | FP14: 13.2 | FQ14: 27 | FR14: 18.9 | FS14: 4.2 | FT14: 5.4 | FU14: 86.37979
A15: 05/11/2025 | B15: 02:30 | C15: 203.2 | D15: 618.6 | E15: 213.4 | H15: 90.2 | I15: 209.2 | L15: 119.7 | M15: 119 | N15: 119 | O15: 227.5 | P15: 0 | R15: 339.2 | S15: 5.8 | X15: 144.7 | Y15: 7.2 | Z15: 5.9 | AA15: 5.7 | AB15: 6.9 | AC15: 12.3 | AD15: 69.5 | AI15: 110.5 | AJ15: 51.1 | AN15: 6.4 | AO15: 147.3 | AP15: 52.1 | AQ15: 30.7 | AR15: 28.8 | AS15: 18.2 | AT15: 18.8 | AU15: 80.7 | AY15: 107.8 | AZ15: 7.5 | BA15: 6 | BB15: 28.4 | BC15: 43.8 | BD15: 2 | BE15: 11.9 | BF15: 66.1 | BI15: 65.6 | BL15: 0 | BP15: 84 | BQ15: 139.4 | BR15: 139.2 | BS15: 139.1 | BT15: 225 | CC15: 3.9 | CD15: 122.3 | CE15: 65.3 | CF15: 63.6 | CG15: 46.8 | CH15: 29.8 | CL15: 146.3 | CM15: 147.8 | CN15: 148.6 | CT15: 215.9 | CU15: 103.6 | CV15: 0 | CW15: 103.8 | CX15: 0 | CY15: 0 | CZ15: 0 | DA15: 20 | DB15: 20.7 | DF15: 1 | DG15: 3.3 | DH15: 2.8 | DJ15: 20 | DK15: 18.9 | DL15: 3.5 | DM15: 18.6 | DN15: 0 | DO15: 0 | DP15: 29.8 | DQ15: 64.3 | DR15: 0 | DS15: 3.2 | DT15: 15.9 | DU15: 2.9 | DW15: 10 | DX15: 9.2 | DY15: 10.1 | DZ15: 13.7 | EA15: 15.7 | EB15: 20.5 | EC15: 44.4 | ED15: 0 | EE15: 19.9 | EF15: 28.2 | EG15: 1 | EH15: 0.8 | EI15: 20.9 | EJ15: 7.5 | EK15: 7.9 | EL15: 18.5 | EM15: 19.3 | EN15: 19.8 | EO15: 0 | EQ15: 0 | ER15: 0 | ES15: 0.6 | ET15: 0.3 | EU15: 0.1 | EV15: 0 | EW15: 1.1 | EY15: 1.8 | EZ15: 1 | FA15: 0 | FB15: 6.1 | FC15: 18.7 | FD15: 9.2 | FE15: 27.3 | FF15: 32.2 | FG15: 15.2 | FH15: 0 | FI15: 7.7 | FJ15: 10 | FK15: 5948.7 | FM15: 11.67687 | FN15: 0 | FO15: 6 | FP15: 13.2 | FQ15: 27 | FR15: 18.9 | FS15: 4.2 | FT15: 5.3 | FU15: 86.27687
A16: 05/11/2025 | B16: 03:00 | C16: 199.4 | D16: 613.6 | E16: 213.5 | H16: 89.3 | I16: 207.8 | L16: 128.6 | M16: 128 | N16: 128.5 | O16: 232 | P16: 0 | R16: 288.5 | S16: 5.6 | X16: 138.5 | Y16: 6.7 | Z16: 5.8 | AA16: 5.6 | AB16: 6.9 | AC16: 12.3 | AD16: 69.3 | AI16: 109.1 | AJ16: 51.2 | AN16: 6.4 | AO16: 145.8 | AP16: 52.3 | AQ16: 29.7 | AR16: 26.6 | AS16: 18.4 | AT16: 18.8 | AU16: 78.3 | AY16: 106 | AZ16: 7.5 | BA16: 6 | BB16: 26.8 | BC16: 42.9 | BD16: 2 | BE16: 11.5 | BF16: 63 | BI16: 64.2 | BL16: 0 | BP16: 83.2 | BQ16: 136.9 | BR16: 137 | BS16: 137.9 | BT16: 224.6 | CC16: 3.9 | CD16: 153.1 | CE16: 70 | CF16: 62.4 | CG16: 46.5 | CH16: 29.3 | CL16: 146 | CM16: 147.3 | CN16: 148.1 | CT16: 216.2 | CU16: 103.6 | CV16: 0 | CW16: 98.2 | CX16: 0 | CY16: 0 | CZ16: 0 | DA16: 20 | DB16: 20.4 | DF16: 1 | DG16: 3.3 | DH16: 2.9 | DJ16: 19.5 | DK16: 18.9 | DL16: 3.5 | DM16: 18.6 | DN16: 0 | DO16: 0 | DP16: 27.1 | DQ16: 70.7 | DR16: 0 | DS16: 3.2 | DT16: 15.8 | DU16: 3 | DW16: 10 | DX16: 9.2 | DY16: 9.8 | DZ16: 13.5 | EA16: 15.7 | EB16: 19.7 | EC16: 41.7 | ED16: 0 | EE16: 25.9 | EF16: 46.6 | EG16: 1.3 | EH16: 1.4 | EI16: 20.9 | EJ16: 7.5 | EK16: 8.3 | EL16: 18.5 | EM16: 19.3 | EN16: 19.3 | EO16: 0 | EQ16: 0 | ER16: 0 | ES16: 0.6 | ET16: 0 | EU16: 3.2 | EV16: 0 | EW16: 1.1 | EY16: 1.8 | EZ16: 1 | FA16: 0 | FB16: 6.1 | FC16: 18.8 | FD16: 9 | FE16: 26.6 | FF16: 32.2 | FG16: 15.5 | FH16: 0 | FI16: 7.1 | FJ16: 10.8 | FK16: 5940.9 | FM16: 11.68189 | FN16: 0 | FO16: 6 | FP16: 13.2 | FQ16: 27.1 | FR16: 18.9 | FS16: 4.1 | FT16: 5.4 | FU16: 86.38189
A17: 05/11/2025 | B17: 03:30 | C17: 204.6 | D17: 624.9 | E17: 214 | H17: 90.1 | I17: 210.5 | L17: 125.6 | M17: 126.1 | N17: 125.7 | O17: 225.9 | P17: 0 | R17: 360.4 | S17: 5.8 | X17: 145.8 | Y17: 7.4 | Z17: 6 | AA17: 5.6 | AB17: 6.9 | AC17: 12.3 | AD17: 70.3 | AI17: 110.5 | AJ17: 51.1 | AN17: 6.4 | AO17: 183 | AP17: 52.3 | AQ17: 66 | AR17: 27.7 | AS17: 18.4 | AT17: 18.8 | AU17: 79.9 | AY17: 108.2 | AZ17: 7.5 | BA17: 6 | BB17: 3.1 | BC17: 44 | BD17: 2 | BE17: 12 | BF17: 67.4 | BI17: 41.8 | BL17: 0 | BP17: 84.1 | BQ17: 120.5 | BR17: 120.6 | BS17: 121.2 | BT17: 208.9 | CC17: 3.9 | CD17: 159 | CE17: 69.9 | CF17: 64 | CG17: 47 | CH17: 29.9 | CL17: 146.7 | CM17: 148.3 | CN17: 149.4 | CT17: 215.7 | CU17: 103.5 | CV17: 0 | CW17: 96 | CX17: 0 | CY17: 0 | CZ17: 0 | DA17: 20.1 | DB17: 20.7 | DF17: 1 | DG17: 3.3 | DH17: 2.9 | DJ17: 20 | DK17: 18.9 | DL17: 3.5 | DM17: 18.6 | DN17: 0 | DO17: 0 | DP17: 23.5 | DQ17: 56 | DR17: 0 | DS17: 2.9 | DT17: 12.5 | DU17: 3 | DW17: 10.6 | DX17: 9.2 | DY17: 10.3 | DZ17: 14.1 | EA17: 15.7 | EB17: 14.3 | EC17: 32 | ED17: 0 | EE17: 39 | EF17: 57.4 | EG17: 2.5 | EH17: 0.6 | EI17: 20.9 | EJ17: 7.5 | EK17: 8.1 | EL17: 18.5 | EM17: 19.3 | EN17: 19.3 | EO17: 0 | EQ17: 0 | ER17: 0 | ES17: 0.6 | ET17: 0 | EU17: 4.2 | EV17: 0 | EW17: 1.1 | EY17: 1.8 | EZ17: 1 | FA17: 0 | FB17: 6.2 | FC17: 18.7 | FD17: 9.4 | FE17: 26.7 | FF17: 32.1 | FG17: 15.5 | FH17: 0 | FI17: 7.9 | FJ17: 11 | FK17: 6005 | FM17: 11.68257 | FN17: 0 | FO17: 6 | FP17: 13.2 | FQ17: 27.1 | FR17: 18.9 | FS17: 4.1 | FT17: 5.3 | FU17: 86.28257
A18: 05/11/2025 | B18: 04:00 | C18: 202 | D18: 626.2 | E18: 214.5 | H18: 89.5 | I18: 211.3 | L18: 121.8 | M18: 122.2 | N18: 122.4 | O18: 220.4 | P18: 0 | R18: 362.3 | S18: 5.8 | X18: 147.8 | Y18: 7.4 | Z18: 5.8 | AA18: 5.6 | AB18: 6.9 | AC18: 12.3 | AD18: 70.3 | AI18: 110.7 | AJ18: 51.5 | AN18: 6.4 | AO18: 184.8 | AP18: 52.2 | AQ18: 76.4 | AR18: 27.5 | AS18: 18.4 | AT18: 18.8 | AU18: 73.8 | AY18: 107.7 | AZ18: 7.5 | BA18: 6 | BB18: 2.9 | BC18: 43.8 | BD18: 2 | BE18: 11.9 | BF18: 67.5 | BI18: 41.6 | BL18: 0 | BP18: 84.1 | BQ18: 127.2 | BR18: 127.4 | BS18: 127.1 | BT18: 209.9 | CC18: 3.9 | CD18: 96.2 | CE18: 74.2 | CF18: 63.9 | CG18: 47 | CH18: 29.9 | CL18: 147 | CM18: 148.6 | CN18: 149.6 | CT18: 216 | CU18: 103.6 | CV18: 0 | CW18: 79.6 | CX18: 0 | CY18: 0 | CZ18: 0 | DA18: 20.2 | DB18: 20.7 | DF18: 1 | DG18: 3.3 | DH18: 2.8 | DJ18: 20 | DK18: 18.8 | DL18: 3.5 | DM18: 18.6 | DN18: 0 | DO18: 0 | DP18: 21.5 | DQ18: 51.9 | DR18: 0 | DS18: 3.1 | DT18: 9.9 | DU18: 2.9 | DW18: 10.6 | DX18: 9.2 | DY18: 10.4 | DZ18: 14 | EA18: 15.8 | EB18: 15.3 | EC18: 38.8 | ED18: 0 | EE18: 64.3 | EF18: 94.9 | EG18: 4.9 | EH18: 2.9 | EI18: 20.9 | EJ18: 7.5 | EK18: 8.1 | EL18: 18.5 | EM18: 19.3 | EN18: 19.3 | EO18: 0 | EQ18: 0 | ER18: 0 | ES18: 0.6 | ET18: 0 | EU18: 0 | EV18: 0 | EW18: 1.1 | EY18: 1.8 | EZ18: 1 | FA18: 0 | FB18: 6.1 | FC18: 18.7 | FD18: 9.2 | FE18: 27 | FF18: 31.8 | FG18: 15.5 | FH18: 0 | FI18: 6.7 | FJ18: 11 | FK18: 6004.5 | FM18: 11.68196 | FN18: 0 | FO18: 6 | FP18: 13.2 | FQ18: 27 | FR18: 18.9 | FS18: 4.1 | FT18: 5.4 | FU18: 86.28196
A19: 05/11/2025 | B19: 04:30 | C19: 205.7 | D19: 635.2 | E19: 216.3 | H19: 91 | I19: 213.2 | L19: 117.4 | M19: 117.6 | N19: 117.9 | O19: 216.6 | P19: 0 | R19: 371.5 | S19: 5.8 | X19: 148.5 | Y19: 8.2 | Z19: 5.9 | AA19: 5.7 | AB19: 6.9 | AC19: 12.4 | AD19: 71.6 | AI19: 110.4 | AJ19: 52.4 | AN19: 6.4 | AO19: 184.3 | AP19: 52.2 | AQ19: 77.5 | AR19: 28.7 | AS19: 18.6 | AT19: 18.8 | AU19: 72.9 | AY19: 111 | AZ19: 7.5 | BA19: 6.2 | BB19: 4.2 | BC19: 45.3 | BD19: 2 | BE19: 12.3 | BF19: 72.2 | BI19: 43.8 | BL19: 0 | BP19: 84.8 | BQ19: 125.5 | BR19: 125.4 | BS19: 124.2 | BT19: 210.8 | CC19: 3.7 | CD19: 112.5 | CE19: 101.9 | CF19: 65.2 | CG19: 47.1 | CH19: 30.6 | CL19: 147.3 | CM19: 148.6 | CN19: 149.8 | CT19: 216.2 | CU19: 103.5 | CV19: 0 | CW19: 96.6 | CX19: 0 | CY19: 0 | CZ19: 0 | DA19: 20.2 | DB19: 21 | DF19: 1 | DG19: 3.3 | DH19: 2.8 | DJ19: 20 | DK19: 18.9 | DL19: 3.5 | DM19: 18.6 | DN19: 0 | DO19: 0 | DP19: 26.2 | DQ19: 58.6 | DR19: 0 | DS19: 2.9 | DT19: 9.8 | DU19: 2.9 | DW19: 10.6 | DX19: 9.2 | DY19: 10.9 | DZ19: 14.4 | EA19: 15.6 | EB19: 18 | EC19: 39 | ED19: 0 | EE19: 63.3 | EF19: 96.7 | EG19: 5.3 | EH19: 1.9 | EI19: 20.9 | EJ19: 7.4 | EK19: 7.6 | EL19: 18.5 | EM19: 19.3 | EN19: 19.3 | EO19: 0 | EQ19: 0 | ER19: 0 | ES19: 0.6 | ET19: 0 | EU19: 0.3 | EV19: 0 | EW19: 1.1 | EY19: 1.8 | EZ19: 1 | FA19: 0 | FB19: 6.1 | FC19: 18.7 | FD19: 8.8 | FE19: 26.5 | FF19: 32 | FG19: 15 | FH19: 0 | FI19: 5.5 | FJ19: 11 | FK19: 6103.8 | FM19: 11.68548 | FN19: 0 | FO19: 6 | FP19: 13.2 | FQ19: 27.1 | FR19: 18.9 | FS19: 4.1 | FT19: 5.4 | FU19: 86.38548
A20: 05/11/2025 | B20: 05:00 | C20: 202.9 | D20: 625.7 | E20: 214.2 | H20: 90.2 | I20: 211 | L20: 126.2 | M20: 126.1 | N20: 125.9 | O20: 224.5 | P20: 0 | R20: 360.9 | S20: 5.8 | X20: 145.9 | Y20: 7.7 | Z20: 5.7 | AA20: 5.7 | AB20: 6.9 | AC20: 12.4 | AD20: 70.3 | AI20: 110.5 | AJ20: 50.8 | AN20: 6.4 | AO20: 183.3 | AP20: 52.3 | AQ20: 101.6 | AR20: 29.1 | AS20: 18.2 | AT20: 18.8 | AU20: 80.5 | AY20: 108.7 | AZ20: 7.5 | BA20: 6 | BB20: 3.2 | BC20: 44.3 | BD20: 2 | BE20: 12.2 | BF20: 68.9 | BI20: 42 | BL20: 0 | BP20: 84.2 | BQ20: 122 | BR20: 121.7 | BS20: 121.2 | BT20: 209.3 | CC20: 3.7 | CD20: 74.4 | CE20: 78.3 | CF20: 64 | CG20: 46.9 | CH20: 30.1 | CL20: 146.6 | CM20: 147.7 | CN20: 149.1 | CT20: 216 | CU20: 103.6 | CV20: 0 | CW20: 106.7 | CX20: 0 | CY20: 0 | CZ20: 0 | DA20: 20.1 | DB20: 20.7 | DF20: 1 | DG20: 3.3 | DH20: 2.9 | DJ20: 20 | DK20: 18.8 | DL20: 3.5 | DM20: 18.6 | DN20: 0.4 | DO20: 0.5 | DP20: 28.8 | DQ20: 68.4 | DR20: 0.1 | DS20: 3 | DT20: 10.4 | DU20: 2.9 | DW20: 10.6 | DX20: 9.2 | DY20: 10.4 | DZ20: 14 | EA20: 15.5 | EB20: 16.4 | EC20: 37.2 | ED20: 0 | EE20: 58.6 | EF20: 88.7 | EG20: 5.4 | EH20: 1.5 | EI20: 20.9 | EJ20: 7.4 | EK20: 7.7 | EL20: 18.5 | EM20: 19.3 | EN20: 19.3 | EO20: 0 | EQ20: 0 | ER20: 0 | ES20: 0.6 | ET20: 0 | EU20: 0 | EV20: 0.1 | EW20: 1.1 | EY20: 1.8 | EZ20: 1 | FA20: 0 | FB20: 6.1 | FC20: 18.6 | FD20: 9.2 | FE20: 25.7 | FF20: 31.9 | FG20: 14.8 | FH20: 0 | FI20: 5.3 | FJ20: 11 | FK20: 6051 | FM20: 11.677 | FN20: 0 | FO20: 6 | FP20: 13.2 | FQ20: 27.1 | FR20: 16.9 | FS20: 4.1 | FT20: 5.4 | FU20: 84.377
A21: 05/11/2025 | B21: 05:30 | C21: 202.9 | D21: 623.5 | E21: 213 | H21: 89.9 | I21: 210.8 | L21: 139 | M21: 138.6 | N21: 139 | O21: 235 | P21: 0 | R21: 360.4 | S21: 5.8 | X21: 147.3 | Y21: 7.3 | Z21: 5.7 | AA21: 5.6 | AB21: 6.9 | AC21: 11.9 | AD21: 70.4 | AI21: 110.3 | AJ21: 51.2 | AN21: 6.4 | AO21: 182.9 | AP21: 53 | AQ21: 142.8 | AR21: 28.4 | AS21: 18.6 | AT21: 18.8 | AU21: 78.5 | AY21: 107.8 | AZ21: 7.5 | BA21: 6.2 | BB21: 11.7 | BC21: 44.4 | BD21: 2 | BE21: 11.8 | BF21: 66.8 | BI21: 41.6 | BL21: 0 | BP21: 83.9 | BQ21: 130.5 | BR21: 130.4 | BS21: 130.4 | BT21: 217 | CC21: 3.7 | CD21: 108 | CE21: 88.9 | CF21: 63.7 | CG21: 46.9 | CH21: 29.9 | CL21: 146.4 | CM21: 147.8 | CN21: 148.4 | CT21: 215.9 | CU21: 103.6 | CV21: 0 | CW21: 106.2 | CX21: 3.9 | CY21: 0 | CZ21: 0 | DA21: 20 | DB21: 20.6 | DF21: 1 | DG21: 3.3 | DH21: 2.9 | DJ21: 20 | DK21: 18.8 | DL21: 3.5 | DM21: 18.6 | DN21: 2.5 | DO21: 3.2 | DP21: 29.5 | DQ21: 74.4 | DR21: 0.8 | DS21: 3 | DT21: 10.4 | DU21: 2.9 | DW21: 10.6 | DX21: 9.1 | DY21: 10.4 | DZ21: 13.9 | EA21: 15.4 | EB21: 15.2 | EC21: 22.3 | ED21: 1.7 | EE21: 72.8 | EF21: 81.2 | EG21: 9 | EH21: 3.6 | EI21: 20.9 | EJ21: 7.4 | EK21: 7.8 | EL21: 18 | EM21: 19.3 | EN21: 19.3 | EO21: 0 | EQ21: 0 | ER21: 8.7 | ES21: 0.6 | ET21: 0 | EU21: 0 | EV21: 7.9 | EW21: 1.1 | EY21: 1.8 | EZ21: 1 | FA21: 0 | FB21: 6.2 | FC21: 18.6 | FD21: 8.5 | FE21: 25.9 | FF21: 31.9 | FG21: 15.2 | FH21: 0 | FI21: 6.1 | FJ21: 11 | FK21: 6247 | FM21: 11.67519 | FN21: 0 | FO21: 6 | FP21: 13.2 | FQ21: 27.1 | FR21: 9.5 | FS21: 4.1 | FT21: 5.4 | FU21: 76.97519
A22: 05/11/2025 | B22: 06:00 | C22: 202.9 | D22: 621 | E22: 212.3 | H22: 89.7 | I22: 210.6 | L22: 112.6 | M22: 112.3 | N22: 112.7 | O22: 216.7 | P22: 0 | R22: 356.1 | S22: 5.7 | X22: 144.9 | Y22: 7.1 | Z22: 5.9 | AA22: 5.6 | AB22: 6.9 | AC22: 12 | AD22: 70 | AI22: 110.4 | AJ22: 51.1 | AN22: 6.4 | AO22: 227.9 | AP22: 52.9 | AQ22: 142.9 | AR22: 28.2 | AS22: 18.4 | AT22: 18.8 | AU22: 70.7 | AY22: 107.7 | AZ22: 7.5 | BA22: 6 | BB22: 11.6 | BC22: 44.8 | BD22: 2 | BE22: 11.7 | BF22: 66.1 | BI22: 40.8 | BL22: 0 | BP22: 83.9 | BQ22: 112.2 | BR22: 112.1 | BS22: 112.1 | BT22: 205 | CC22: 3.7 | CD22: 113.8 | CE22: 70.8 | CF22: 63.7 | CG22: 46.9 | CH22: 29.9 | CL22: 145.3 | CM22: 147 | CN22: 147.3 | CT22: 216.2 | CU22: 103.8 | CV22: 0 | CW22: 99.7 | CX22: 27.2 | CY22: 2.5 | CZ22: 0 | DA22: 20.1 | DB22: 0 | DF22: 0.9 | DG22: 3.3 | DH22: 2.8 | DJ22: 20 | DK22: 18.8 | DL22: 3.5 | DM22: 18.6 | DN22: 6.9 | DO22: 6.8 | DP22: 27.8 | DQ22: 73.2 | DR22: 0.8 | DS22: 3.1 | DT22: 10.3 | DU22: 2.9 | DW22: 10.6 | DX22: 9 | DY22: 10.2 | DZ22: 14 | EA22: 15.5 | EB22: 16.7 | EC22: 16.4 | ED22: 11.3 | EE22: 67.3 | EF22: 80 | EG22: 5.9 | EH22: 2.7 | EI22: 20.9 | EJ22: 7.4 | EK22: 7.9 | EL22: 18 | EM22: 19.3 | EN22: 19.3 | EO22: 1.2 | EQ22: 1.2 | ER22: 50.1 | ES22: 0.6 | ET22: 2.9 | EU22: 6.3 | EV22: 43.4 | EW22: 1.1 | EY22: 1.8 | EZ22: 1 | FA22: 0.9 | FB22: 6.1 | FC22: 18.6 | FD22: 9.2 | FE22: 25.6 | FF22: 31.6 | FG22: 15.3 | FH22: 0 | FI22: 5.1 | FJ22: 11 | FK22: 6179.2 | FM22: 11.67897 | FN22: 5.05 | FO22: 6 | FP22: 13.2 | FQ22: 27.2 | FR22: 9.5 | FS22: 4.1 | FT22: 5.3 | FU22: 82.02897
... A58: 06/11/2025 | B58: 00:00 | C58: 179.5 | D58: 629.2 | E58: 214 | H58: 30.1 | I58: 195 | L58: 128.3 | M58: 128.3 | N58: 127.9 | O58: 227 | P58: 104.6 | R58: 295.3 | S58: 5.7 | X58: 142.2 | Y58: 7.4 | Z58: 5.8 | AA58: 0 | AB58: 7.1 | AC58: 13.4 | AD58: 87.7 | AI58: 110.4 | AJ58: 60 | AN58: 6.4 | AO58: 0 | AP58: 45.8 | AQ58: 121 | AR58: 23.8 | AS58: 18.6 | AT58: 18.8 | AU58: 75.4 | AY58: 108.8 | AZ58: 7.5 | BA58: 5.8 | BB58: 35.1 | BC58: 44.5 | BD58: 2 | BE58: 32 | BF58: 69.3 | BI58: 57.4 | BL58: 42.9 | BP58: 114.9 | BQ58: 175.9 | BR58: 173.5 | BS58: 200 | BT58: 269.3 | CC58: 3.6 | CD58: 140.2 | CE58: 79.6 | CF58: 70.1 | CG58: 46.6 | CH58: 30 | CL58: 146.7 | CM58: 148.3 | CN58: 150 | CT58: 216 | CU58: 103.4 | CV58: 0 | CW58: 120.8 | CX58: 0 | CY58: 0.1 | CZ58: 0 | DA58: 0 | DB58: 20.7 | DF58: 0.8 | DG58: 3.5 | DH58: 2.7 | DJ58: 20 | DK58: 18.7 | DL58: 3.4 | DM58: 18.6 | DN58: 0 | DO58: 0 | DP58: 30.3 | DQ58: 88.6 | DR58: 0 | DS58: 3.5 | DT58: 13.5 | DU58: 2.6 | DW58: 9.5 | DX58: 9.7 | DY58: 9.8 | DZ58: 13 | EA58: 16.2 | EB58: 18.3 | EC58: 35 | ED58: 0 | EE58: 61.1 | EF58: 90.7 | EG58: 5.8 | EH58: 3.3 | EI58: 19.4 | EJ58: 6.8 | EK58: 8.2 | EL58: 16 | EM58: 17 | EN58: 16.7 | EO58: 0 | EQ58: 0 | ER58: 0 | ES58: 0.6 | ET58: 73.8 | EU58: 79.9 | EV58: 0 | EW58: 1.1 | EY58: 2.4 | EZ58: 1.1 | FA58: 0 | FB58: 6.2 | FC58: 18.8 | FD58: 8.2 | FE58: 26.3 | FF58: 32.8 | FG58: 15.3 | FH58: 20.2 | FI58: 7.1 | FJ58: 11 | FK58: 6491.2 | FM58: 10.85544 | FN58: 7.98 | FO58: 6.1 | FP58: 13.2 | FQ58: 27 | FR58: 9.5 | FS58: 4 | FT58: 7.9 | FU58: 86.53544
A59: EJEC | C59: 4031.8 | D59: 15037 | E59: 5148.9 | F59: 0 | G59: 0 | H59: 2084.45 | I59: 4845.7 | J59: 0 | K59: 0 | L59: 3643.05 | M59: 3705.2 | N59: 3704 | O59: 5965.65 | P59: 1372.75 | Q59: 0 | R59: 7573.55 | S59: 137.6 | T59: 0 | U59: 0 | V59: 0 | W59: 0 | X59: 3412.15 | Y59: 178.5 | Z59: 138.85 | AA59: 306.3 | AB59: 166.1 | AC59: 301.5 | AD59: 1900.55 | AE59: 0 | AF59: 0 | AG59: 0 | AH59: 0 | AI59: 2387.35 | AJ59: 2729.25 | AK59: 0 | AL59: 0 | AM59: 0 | AN59: 154.8 | AO59: 4789.45 | AP59: 1174.3 | AQ59: 2823.4 | AR59: 615.95 | AS59: 442.4 | AT59: 451.2 | AU59: 1823.05 | AV59: 0 | AW59: 0 | AX59: 0 | AY59: 2584.55 | AZ59: 179.95 | BA59: 144.45 | BB59: 554.85 | BC59: 1068.8 | BD59: 48 | BE59: 417.4 | BF59: 1626.3 | BG59: 0 | BH59: 0 | BI59: 1565.9 | BJ59: 0 | BK59: 0 | BL59: 678.7 | BM59: 0 | BN59: 0 | BO59: 0 | BP59: 2224.3 | BQ59: 3876.8 | BR59: 3841.7 | BS59: 4305.95 | BT59: 6067.85 | BU59: 0 | BV59: 0 | BW59: 0 | BX59: 0 | BY59: 0 | BZ59: 0 | CA59: 0 | CB59: 0 | CC59: 88.15 | CD59: 3362.45 | CE59: 2075.1 | CF59: 1532.5 | CG59: 1120.05 | CH59: 717.7 | CI59: 0 | CJ59: 0 | CK59: 0 | CL59: 3493.2 | CM59: 3524.1 | CN59: 3818.6 | CO59: 0 | CP59: 0 | CQ59: 0 | CR59: 0 | CS59: 0 | CT59: 5141.4 | CU59: 2461.9 | CV59: 5.65 | CW59: 2735.55 | CX59: 742.6 | CY59: 99.65 | CZ59: 2.4 | DA59: 293.65 | DB59: 426.05 | DC59: 0 | DD59: 0 | DE59: 0 | DF59: 21.75 | DG59: 73.85 | DH59: 67.45 | DI59: 0 | DJ59: 477.05 | DK59: 424.65 | DL59: 83.1 | DM59: 446.4 | DN59: 137.7 | DO59: 166.45 | DP59: 697.55 | DQ59: 1933.4 | DR59: 137.05 | DS59: 77.2 | DT59: 368.2 | DU59: 65.55 | DV59: 0 | DW59: 229.8 | DX59: 212.6 | DY59: 242.05 | DZ59: 336.55 | EA59: 369.15 | EB59: 399.3 | EC59: 1244.65 | ED59: 357.8 | EE59: 841.1 | EF59: 2079.4 | EG59: 75.05 | EH59: 143.3 | EI59: 493.6 | EJ59: 171.15 | EK59: 189.95 | EL59: 413.85 | EM59: 436.1 | EN59: 438.15 | EO59: 75.75 | EP59: 0 | EQ59: 118.35 | ER59: 1369.95 | ES59: 14.4 | ET59: 1682.6 | EU59: 1839.55 | EV59: 1021.45 | EW59: 26.4 | EX59: 0 | EY59: 45.4 | EZ59: 24 | FA59: 120.6 | FB59: 148.15 | FC59: 445.9 | FD59: 206 | FE59: 631.6 | FF59: 785.35 | FG59: 359.25 | FH59: 328.7 | FI59: 170.15 | FJ59: 261.9 | FK59: 165397.3 | FM59: 123.55436 | FN59: 146.865 | FO59: 145.8 | FP59: 316.8 | FQ59: 638.7 | FR59: 274 | FS59: 92.6 | FT59: 193.35 | FU59: 1931.6694

Sheet REACTIVA
B3: miércoles, 5 de Noviembre del 2025
A5: POTENCIA REACTIVA EJECUTADA DE LAS UNIDADES DE GENERACIÓN DEL COES (MVAR) | FM5: CENTRALES NO INTEGRANTES COES
A6: FECHA | B6: HORA | C6: 65333 | D6: 101 | E6: 102 | F6: 42667 | G6: 42668 | H6: 126 | I6: 127 | J6: 138 | K6: 139 | L6: 197 | M6: 203 | N6: 204 | O6: 230 | P6: 209 | Q6: 56677 | R6: 796 | S6: 2146 | T6: 142 | U6: 143 | V6: 125 | W6: 187 | X6: 163 | Y6: 298 | Z6: 299 | AA6: 219 | AB6: 151 | AC6: 152 | AD6: 153 | AE6: 154 | AF6: 756 | AG6: 156 | AH6: 155 | AI6: 182 | AJ6: 212 | AK6: 758 | AL6: 263 | AM6: 265 | AN6: 775 | AO6: 777 | AP6: 2154 | AQ6: 150 | AR6: 149 | AS6: 188 | AT6: 2131 | AU6: 755 | AV6: 252 | AW6: 249 | AX6: 250 | AY6: 117 | AZ6: 267 | BA6: 268 | BB6: 119 | BC6: 120 | BD6: 189 | BE6: 122 | BF6: 266 | BG6: 337 | BH6: 338 | BI6: 251 | BJ6: 115 | BK6: 239 | BL6: 288 | BM6: 240 | BN6: 241 | BO6: 242 | BP6: 191 | BQ6: 194 | BR6: 196 | BS6: 207 | BT6: 236 | BU6: 795 | BV6: 285 | BW6: 995 | BX6: 996 | BY6: 997 | BZ6: 766 | CA6: 926 | CB6: 924 | CC6: 121 | CD6: 103 | CE6: 104 | CF6: 106 | CG6: 105 | CH6: 107 | CI6: 110 | CJ6: 109 | CK6: 144 | CL6: 113 | CM6: 114 | CN6: 193 | CO6: 208 | CP6: 786 | CQ6: 787 | CR6: 788 | CS6: 789 | CT6: 248 | CU6: 2159 | CV6: 303 | CW6: 59715 | CX6: 62255 | CY6: 1263 | CZ6: 61800 | DA6: 2194 | DB6: 69125 | DC6: 216 | DD6: 198 | DE6: 70400 | DF6: 49607 | DG6: 214 | DH6: 260 | DI6: 2152 | DJ6: 2128 | DK6: 247 | DL6: 228 | DM6: 2135 | DN6: 261 | DO6: 237 | DP6: 253 | DQ6: 770 | DR6: 235 | DS6: 238 | DT6: 2184 | DU6: 61855 | DV6: 223 | DW6: 226 | DX6: 201 | DY6: 258 | DZ6: 259 | EA6: 920 | EB6: 257 | EC6: 256 | ED6: 2148 | EE6: 58288 | EF6: 58289 | EG6: 58839 | EH6: 58840 | EI6: 296 | EJ6: 297 | EK6: 211 | EL6: 2175 | EM6: 2178 | EN6: 2181 | EO6: 1262 | EP6: 63425 | EQ6: 233 | ER6: 2150 | ES6: 2165 | ET6: 2161 | EU6: 61197 | EV6: 58851 | EW6: 225 | EX6: 2201 | EY6: 2171 | EZ6: 760 | FA6: 234 | FB6: 215 | FC6: 917 | FD6: 289 | FE6: 58333 | FF6: 58336 | FG6: 213 | FH6: 232 | FI6: 2190 | FJ6: 69867 | FK6: TOTAL COES | FM6: 221 | FN6: 222 | FO6: 224 | FP6: 2187 | FQ6: 227 | FR6: 49400 | FS6: 199 | FT6: 200 | FU6: TOTAL NO COES
C7: SUR | D7: CENTRO | E7: CENTRO | F7: NORTE | G7: NORTE | H7: NORTE | I7: NORTE | J7: CENTRO | K7: CENTRO | L7: CENTRO | M7: CENTRO | N7: CENTRO | O7: CENTRO | P7: CENTRO | Q7: CENTRO | R7: CENTRO | S7: CENTRO | T7: CENTRO | U7: CENTRO | V7: CENTRO | W7: CENTRO | X7: SUR | Y7: SUR | Z7: SUR | AA7: CENTRO | AB7: SUR | AC7: SUR | AD7: SUR | AE7: SUR | AF7: SUR | AG7: SUR | AH7: SUR | AI7: SUR | AJ7: CENTRO | AK7: NORTE | AL7: NORTE | AM7: NORTE | AN7: CENTRO | AO7: CENTRO | AP7: CENTRO | AQ7: CENTRO | AR7: CENTRO | AS7: CENTRO | AT7: CENTRO | AU7: SUR | AV7: CENTRO | AW7: CENTRO | AX7: CENTRO | AY7: CENTRO | AZ7: CENTRO | BA7: CENTRO | BB7: CENTRO | BC7: CENTRO | BD7: SUR | BE7: NORTE | BF7: CENTRO | BG7: CENTRO | BH7: CENTRO | BI7: CENTRO | BJ7: NORTE | BK7: NORTE | BL7: NORTE | BM7: SUR | BN7: SUR | BO7: SUR | BP7: CENTRO | BQ7: CENTRO | BR7: CENTRO | BS7: CENTRO | BT7: CENTRO | BU7: CENTRO | BV7: CENTRO | BW7: SUR | BX7: SUR | BY7: SUR | BZ7: NORTE | CA7: SUR | CB7: CENTRO | CC7: NORTE | CD7: CENTRO | CE7: CENTRO | CF7: CENTRO | CG7: CENTRO | CH7: CENTRO | CI7: CENTRO | CJ7: CENTRO | CK7: CENTRO | CL7: CENTRO | CM7: CENTRO | CN7: CENTRO | CO7: CENTRO | CP7: SUR | CQ7: SUR | CR7: SUR | CS7: SUR | CT7: CENTRO | CU7: CENTRO | CV7: CENTRO | CW7: CENTRO | CX7: SUR | CY7: NORTE | CZ7: NORTE | DA7: NORTE | DB7: CENTRO | DC7: NORTE | DD7: NORTE | DE7: SUR | DF7: SUR | DG7: CENTRO | DH7: CENTRO | DI7: CENTRO | DJ7: NORTE | DK7: NORTE | DL7: CENTRO | DM7: CENTRO | DN7: SUR | DO7: SUR | DP7: CENTRO | DQ7: CENTRO | DR7: SUR | DS7: CENTRO | DT7: CENTRO | DU7: NORTE | DV7: CENTRO | DW7: CENTRO | DX7: NORTE | DY7: CENTRO | DZ7: CENTRO | EA7: CENTRO | EB7: NORTE | EC7: NORTE | ED7: SUR | EE7: CENTRO | EF7: CENTRO | EG7: CENTRO | EH7: CENTRO | EI7: CENTRO | EJ7: CENTRO | EK7: SUR | EL7: SUR | EM7: SUR | EN7: SUR | EO7: NORTE | EP7: SUR | EQ7: SUR | ER7: SUR | ES7: CENTRO | ET7: CENTRO | EU7: CENTRO | EV7: SUR | EW7: CENTRO | EX7: CENTRO | EY7: CENTRO | EZ7: CENTRO | FA7: SUR | FB7: NORTE | FC7: CENTRO | FD7: NORTE | FE7: NORTE | FF7: NORTE | FG7: CENTRO | FH7: NORTE | FI7: NORTE | FJ7: NORTE | FM7: NORTE | FN7: CENTRO | FO7: NORTE | FP7: NORTE | FQ7: NORTE | FR7: NORTE | FS7: NORTE | FT7: NORTE
C8: HIDROELÉCTRICA | D8: HIDROELÉCTRICA | E8: HIDROELÉCTRICA | F8: TERMOELÉCTRICA | G8: TERMOELÉCTRICA | H8: HIDROELÉCTRICA | I8: HIDROELÉCTRICA | J8: TERMOELÉCTRICA | K8: TERMOELÉCTRICA | L8: TERMOELÉCTRICA | M8: TERMOELÉCTRICA | N8: TERMOELÉCTRICA | O8: TERMOELÉCTRICA | P8: TERMOELÉCTRICA | Q8: TERMOELÉCTRICA | R8: HIDROELÉCTRICA | S8: HIDROELÉCTRICA | T8: TERMOELÉCTRICA | U8: TERMOELÉCTRICA | V8: TERMOELÉCTRICA | W8: TERMOELÉCTRICA | X8: HIDROELÉCTRICA | Y8: HIDROELÉCTRICA | Z8: HIDROELÉCTRICA | AA8: TERMOELÉCTRICA | AB8: HIDROELÉCTRICA | AC8: HIDROELÉCTRICA | AD8: HIDROELÉCTRICA | AE8: HIDROELÉCTRICA | AF8: TERMOELÉCTRICA | AG8: TERMOELÉCTRICA | AH8: TERMOELÉCTRICA | AI8: HIDROELÉCTRICA | AJ8: HIDROELÉCTRICA | AK8: TERMOELÉCTRICA | AL8: TERMOELÉCTRICA | AM8: TERMOELÉCTRICA | AN8: HIDROELÉCTRICA | AO8: HIDROELÉCTRICA | AP8: HIDROELÉCTRICA | AQ8: HIDROELÉCTRICA | AR8: HIDROELÉCTRICA | AS8: HIDROELÉCTRICA | AT8: HIDROELÉCTRICA | AU8: HIDROELÉCTRICA | AV8: TERMOELÉCTRICA | AW8: TERMOELÉCTRICA | AX8: TERMOELÉCTRICA | AY8: HIDROELÉCTRICA | AZ8: HIDROELÉCTRICA | BA8: HIDROELÉCTRICA | BB8: HIDROELÉCTRICA | BC8: HIDROELÉCTRICA | BD8: HIDROELÉCTRICA | BE8: HIDROELÉCTRICA | BF8: HIDROELÉCTRICA | BG8: HIDROELÉCTRICA | BH8: HIDROELÉCTRICA | BI8: HIDROELÉCTRICA | BJ8: TERMOELÉCTRICA | BK8: TERMOELÉCTRICA | BL8: TERMOELÉCTRICA | BM8: TERMOELÉCTRICA | BN8: TERMOELÉCTRICA | BO8: TERMOELÉCTRICA | BP8: HIDROELÉCTRICA | BQ8: TERMOELÉCTRICA | BR8: TERMOELÉCTRICA | BS8: TERMOELÉCTRICA | BT8: TERMOELÉCTRICA | BU8: TERMOELÉCTRICA | BV8: TERMOELÉCTRICA | BW8: TERMOELÉCTRICA | BX8: TERMOELÉCTRICA | BY8: TERMOELÉCTRICA | BZ8: HIDROELÉCTRICA | CA8: TERMOELÉCTRICA | CB8: TERMOELÉCTRICA | CC8: HIDROELÉCTRICA | CD8: HIDROELÉCTRICA | CE8: HIDROELÉCTRICA | CF8: HIDROELÉCTRICA | CG8: HIDROELÉCTRICA | CH8: HIDROELÉCTRICA | CI8: TERMOELÉCTRICA | CJ8: TERMOELÉCTRICA | CK8: TERMOELÉCTRICA | CL8: TERMOELÉCTRICA | CM8: TERMOELÉCTRICA | CN8: TERMOELÉCTRICA | CO8: TERMOELÉCTRICA | CP8: TERMOELÉCTRICA | CQ8: TERMOELÉCTRICA | CR8: TERMOELÉCTRICA | CS8: TERMOELÉCTRICA | CT8: TERMOELÉCTRICA | CU8: TERMOELÉCTRICA | CV8: SOLAR | CW8: EÓLICA | CX8: SOLAR | CY8: EÓLICA | CZ8: SOLAR | DA8: HIDROELÉCTRICA | DB8: HIDROELÉCTRICA | DC8: HIDROELÉCTRICA | DD8: HIDROELÉCTRICA | DE8: SOLAR | DF8: HIDROELÉCTRICA | DG8: HIDROELÉCTRICA | DH8: HIDROELÉCTRICA | DI8: HIDROELÉCTRICA | DJ8: HIDROELÉCTRICA | DK8: HIDROELÉCTRICA | DL8: HIDROELÉCTRICA | DM8: HIDROELÉCTRICA | DN8: SOLAR | DO8: SOLAR | DP8: EÓLICA | DQ8: EÓLICA | DR8: SOLAR | DS8: HIDROELÉCTRICA | DT8: HIDROELÉCTRICA | DU8: HIDROELÉCTRICA | DV8: HIDROELÉCTRICA | DW8: HIDROELÉCTRICA | DX8: HIDROELÉCTRICA | DY8: HIDROELÉCTRICA | DZ8: HIDROELÉCTRICA | EA8: HIDROELÉCTRICA | EB8: EÓLICA | EC8: EÓLICA | ED8: SOLAR | EE8: EÓLICA | EF8: EÓLICA | EG8: EÓLICA | EH8: EÓLICA | EI8: HIDROELÉCTRICA | EJ8: HIDROELÉCTRICA | EK8: HIDROELÉCTRICA | EL8: HIDROELÉCTRICA | EM8: HIDROELÉCTRICA | EN8: HIDROELÉCTRICA | EO8: EÓLICA | EP8: SOLAR | EQ8: SOLAR | ER8: SOLAR | ES8: HIDROELÉCTRICA | ET8: EÓLICA | EU8: EÓLICA | EV8: SOLAR | EW8: TERMOELÉCTRICA | EX8: TERMOELÉCTRICA | EY8: TERMOELÉCTRICA | EZ8: TERMOELÉCTRICA | FA8: SOLAR | FB8: HIDROELÉCTRICA | FC8: HIDROELÉCTRICA | FD8: TERMOELÉCTRICA | FE8: TERMOELÉCTRICA | FF8: TERMOELÉCTRICA | FG8: TERMOELÉCTRICA | FH8: TERMOELÉCTRICA | FI8: TERMOELÉCTRICA | FJ8: TERMOELÉCTRICA | FM8: HIDROELÉCTRICA | FN8: HIDROELÉCTRICA | FO8: HIDROELÉCTRICA | FP8: HIDROELÉCTRICA | FQ8: TERMOELÉCTRICA | FR8: TERMOELÉCTRICA | FS8: HIDROELÉCTRICA | FT8: HIDROELÉCTRICA
