Workbook

Sheet EVENTOS
B3: martes, 4 de Noviembre del 2025
B5: INFORMACIÓN DE EVENTOS PRINCIPALES EN SUS INSTALACIONES
B6: TIPO DE EVENTO | C6: EMPRESA | D6: UBICACIÓN | E6: TIPO DE EQUIPO | F6: EQUIPO | G6: INICIO | H6: FINAL | I6: DESCRIPCIÓN | J6: MW INDISP. | K6: INTERRUPCIÓN (SI/NO) | L6: TENSIÓN DE FALLA (kV)
B7: FALLA | C7: AGRO INDUSTRIAL PARAMONGA S.A. | D7: PARAMONGA | E7: CENTRAL TERMOELÉCTRICA | F7: CENTRAL | G7: 04/11/2025 10:27:00 | H7: 04/11/2025 11:43:00 | I7: DESCONEXIÓN DE LA C.T. PARAMONGA POR FALLA | K7: NO | L7: 13.8
B8: FALLA | C8: AGROAURORA S.A.C. | D8: MAPLE ETANOL | E8: CENTRAL TERMOELÉCTRICA | F8: CENTRAL | G8: 04/11/2025 21:35:00 | H8: 05/11/2025 05:55:00 | I8: DESCONEXIÓN DE LA LINEA L-6699 (PIURA OESTE - PLANTA ETANOL) EN 60 KV | K8: NO | L8: 0
B9: EVENTO | C9: CONELSUR LT SAC | D9: PORTILLO | E9: SUBESTACION | F9: SS.EE. | G9: 04/11/2025 00:00:00 | H9: 05/11/2025 00:00:00 | I9: DECLARACIÓN DE SITUACIÓN EXCEPCIONAL EN LA S.E. PORTILLO 60 kV | K9: NO
B10: FALLA | C10: EGASA | D10: CHARCANI IV | E10: GENERADOR HIDROELÉCTRICO | F10: G3 | G10: 04/11/2025 08:44:00 | H10: 04/11/2025 11:53:00 | I10: DESCONEXIÓN DEL GENERADOR G3 DE LA C.H. CHARCANI IV | K10: NO | L10: 5.25
B11: FALLA | C11: EMPRESA DE GENERACION ELECTRICA SANTA ANA S.A.C. | D11: LA VIRGEN | E11: TRANSFORMADOR 2D | F11: TE4 | G11: 04/11/2025 21:33:00 | H11: 04/11/2025 22:20:00 | I11: DESCONEXIÓN DEL TRANSFORMADOR TE4 138/60 KV DE LA S.E. LA VIRGEN | K11: NO | L11: 138
B12: FALLA | C12: MINERA CERRO VERDE | D12: SAN JOSE | E12: BANCO DE CONDENSADORES SERIE | F12: BCS-5982 | G12: 04/11/2025 11:04:00 | H12: 04/11/2025 11:43:00 | I12: DESCONEXIÓN DEL BANCO DE CONDENSADORES SERIE BCS-5982 DE 500 KV DE LA S.E. SAN JOSÉ | K12: NO | L12: 500
B13: FALLA | C13: ORYGEN PERU S.A.A. | D13: CALLAHUANCA | E13: GENERADOR HIDROELÉCTRICO | F13: G1 | G13: 04/11/2025 08:31:00 | H13: 04/11/2025 09:08:00 | I13: DESCONEXIÓN DEL GENERADOR G1 DE LA C.H. CALLAHUANCA | K13: NO | L13: 6.5
B14: EVENTO | C14: RED DE ENERGIA DEL PERU S.A. | D14: TINGO MARÍA - AUCAYACU | E14: LINEA DE TRANSMISION | F14: L-1122 | G14: 04/11/2025 18:20:00 | H14: 04/11/2025 20:05:00 | I14: DECLARACION DE SITUACION EXCEPCIONAL EN LA LINEA L-1122 (TINGO MARÍA - AUCAYACU) DE 138 KV, POR SOBRECARGA | K14: NO

Sheet RESTRIC_OPE
B3: martes, 4 de Noviembre del 2025
B5: RESTRICCIONES OPERATIVAS
B6: FECHA | C6: HORA INICIO | D6: HORA FINAL | E6: EMPRESA | F6: UBICACIÓN | G6: T.Eq. | H6: EQUIPO | I6: DESCRIPCIÓN
B7: 04/11/2025 | C7: 00:00 | D7: 24:00 | E7: CELEPSA | F7: C.H. EL PLATANAL | G7: CH | H7: CENTRAL | I7: De acuerdo con el correo del 13/10/2025. Debido a problemas en el control de la compuerta de bocatoma, informaron que el servicio de RSF queda indisponible.
B8: 04/11/2025 | C8: 00:00 | D8: 24:00 | E8: EGASA | F8: S.E. CONVERTIDOR | G8: BARRA | H8: BARRA138KV | I8: EGASA limitó la capacidad del transformador 138 kV/33 kV a 50 MVA por deterioro del aislamiento.
B9: 04/11/2025 | C9: 00:00 | D9: 24:00 | E9: ELECTROPERU | F9: C.H. MANTARO | G9: CH | H9: CENTRAL | I9: De acuerdo con el correo del día 25.08.2025, la central tiene una limitación de potencia máxima de 650 MW por seguridad de la central.
B10: 04/11/2025 | C10: 00:00 | D10: 24:00 | E10: ENEL GENERACION PIURA S.A. | F10: C.T. MALACAS | G10: CT | H10: CENTRAL | I10: De acuerdo con la comunicación vía correo del día 24.10.2024. ENEL GENERACIÓN PIURA informa una restricción de potencia para alcanzar 105 MW en simultaneo (TG6+TGN4).
B11: 04/11/2025 | C11: 00:00 | D11: 24:00 | E11: ENEL GENERACION PIURA S.A. | F11: C.T. MALACAS | G11: GT | H11: TG4 | I11: De acuerdo a lo informado mediante correo electrónico el día 25.10, con la disponibilidad actual de aproximadamente 13 MMPCD (368.12 Mm³) la unidad TG4 puede con una generación de 80 MW durante 5 horas, y a potencia mínima durante el resto de los periodos
B12: 04/11/2025 | C12: 00:00 | D12: 24:00 | E12: ENGIE ENERGIA PERU S.A.A. | F12: C.H. YUNCÁN | G12: GH | H12: G3 | I12: Según la carta N° ENG/ 198-2024 enviada por su representada, se opera de forma continua el G3 de la CH Yuncán, debido a la ejecución de mantenimientos necesarios para evitar daños en los sellos de seguridad de la válvula esférica del grupo.
B13: 04/11/2025 | C13: 00:00 | D13: 24:00 | E13: ENGIE ENERGIA PERU S.A.A. | F13: C.T. CHILCA 1 | G13: CT | H13: CENTRAL | I13: Restricción de temperatura de la C.T Chilca, ver valor en el modelo de despacho.
B14: 04/11/2025 | C14: 00:00 | D14: 24:00 | E14: ENGIE ENERGIA PERU S.A.A. | F14: C.T. CHILCA 1 | G14: CT | H14: CENTRAL | I14: Con carta ENG/971-2023, indica que no puede cumplir con las IO considerada en el PDO_17122023 dado que vulneran la seguridad de sus activos. Indican que se debe tomar TMO=168h.
B15: 04/11/2025 | C15: 00:00 | D15: 24:00 | E15: ENGIE ENERGIA PERU S.A.A. | F15: C.T. CHILCA 2 | G15: CT | H15: CENTRAL | I15: Con carta ENG/971-2023, indica que no puede cumplir con las IO considerada en el PDO_17122023 dado que vulneran la seguridad de sus activos. Indican que se debe tomar TMO=168h.
B16: 04/11/2025 | C16: 00:00 | D16: 24:00 | E16: FENIX POWER PERÚ | F16: C.T. FENIX | G16: CT | H16: CENTRAL | I16: De acuerdo con lo comunicado en el correo del día 06.05.2025, la CT Fenix cuenta con TMO de 168 hrs en todos sus modos de operación.
B17: 04/11/2025 | C17: 00:00 | D17: 24:00 | E17: KALLPA GENERACION S.A. | F17: C.H. MINI CENTRAL CERRO DEL AGUILA | G17: CH | H17: CENTRAL | I17: Caudal ecológico de la Mini CH Cerro del Águila es de 10.6 m3/s correspondiente al mes de noviembre.
... B47: 04/11/2025 | C47: 00:00 | D47: 24:00 | E47: TERMOSELVA | F47: C.T. AGUAYTÍA | G47: CT | H47: CENTRAL | I47: Disponibilidad de 23.5 MMSCF para la CT Aguaytía.

Sheet MANTENIMIENTO EJECUTADOS
B3: martes, 4 de Noviembre del 2025
B5: Mantenimiento Ejecutado
B6: Empresa | C6: Ubicación | D6: Equipo | E6: Inicio | F6: Final | G6: Descripción | H6: MW Indisp. | I6: Prog. | J6: Dispon | K6: Interrupc. | L6: Tipo | M6: CodEq | N6: TipoEq_Osinerg
B7: AGROINDUSTRIAS SAN JACINTO S.A.A. | C7: SAN JACINTO | D7: CENTRAL | E7: 04/11/2025 00:00 | F7: 05/11/2025 00:00 | G7: Mantenimiento Mensual | H7: 8.15 | I7: P | J7: F/S | K7: N | L7: PREV. | M7: 19865 | N7: G
B8: ATLANTICA TRANSMISION SUR S.A. | C8: CHILCA CTM - POROMA | D8: L-5032 | E8: 04/11/2025 07:15 | F8: 04/11/2025 16:49 | G8: Mejoramiento de PAT | H8: 0 | I8: P | J8: E/S | K8: N | L8: PREV. | M8: 13652 | N8: T
B9: ATLANTICA TRANSMISION SUR S.A. | C9: MONTALVO | D9: CL-2057 | E9: 04/11/2025 07:57 | F9: 04/11/2025 13:17 | G9: Reemplazo de transformador de corriente TCL-5601 de fase R | H9: 0 | I9: P | J9: F/S | K9: N | L9: CORR. | M9: 13812 | N9: T
B10: ATLANTICA TRANSMISION SUR S.A. | C10: MONTALVO - MOQUEGUA | D10: L-2057 | E10: 04/11/2025 07:59 | F10: 04/11/2025 13:17 | G10: Desconexion por seguridad debido a reemplazo de transformador de corriente TCL-5601 de fase R en CL-2057 SE Montalvo | H10: 0 | I10: P | J10: F/S | K10: N | L10: OTROS | M10: 13815 | N10: T
B11: ATLANTICA TRANSMISION SUR S.A. | C11: OCONA | D11: INT-5450 | E11: 04/11/2025 00:00 | F11: 05/11/2025 00:00 | G11: Interruptor INT-5450 cerrado con restriccion operativa, REB-5450 en servicio y suministrando los SS.AA. de la S.E. Oco?a. | H11: 0 | I11: P | J11: E/S | K11: N | L11: OTROS | M11: 13761 | N11: T
B12: ATLANTICA TRANSMISION SUR S.A. | C12: POROMA | D12: INT-5371 | E12: 04/11/2025 00:00 | F12: 05/11/2025 00:00 | G12: Seccionador SBB-5371 fase T indisponible por problemas mecanicos, el seccionador permanece cerrado y bloqueado | H12: 0 | I12: P | J12: E/S | K12: N | L12: OTROS | M12: 13751 | N12: T
B13: ATLANTICA TRANSMISION SUR S.A. | C13: POROMA | D13: REB-5350 | E13: 04/11/2025 00:00 | F13: 05/11/2025 00:00 | G13: Fuera de servicio po falla en el equipo. | H13: 0 | I13: P | J13: F/S | K13: N | L13: OTROS | M13: 13771 | N13: T
B14: ATN S.A. | C14: KIMAN AYLLU | D14: AUT-501 | E14: 04/11/2025 00:00 | F14: 05/11/2025 00:00 | G14: Restriccion Operativa en el circuito de control de cambiador de tap s del AUT-501 | H14: 0 | I14: P | J14: E/S | K14: N | L14: OTROS | M14: 13099 | N14: T
B15: ATRIA ENERGIA S.A.C. | C15: PURMACANA | D15: CENTRAL | E15: 04/11/2025 00:00 | F15: 05/11/2025 00:00 | G15: MANTENIMIENTO DE CANAL DE CONDUCCION, COMPUERTAS, SISTEMA DE LUBRICACION DE COJINETES, SISTEMA DE REFRIGERACION Y VALVULAS | H15: 0.4 | I15: P | J15: F/S | K15: N | L15: PREV. | M15: 13132 | N15: G
B16: CONELSUR LT SAC | C16: CALLAHUANCA (CNS) | D16: S.E. | E16: 04/11/2025 00:00 | F16: 05/11/2025 00:00 | G16: RELE DIFERENCIAL DE BARRAS DE CALLAHUANCA 220KV INOPERATIVO | H16: 0 | I16: F | J16: E/S | K16: N | L16: OTROS | M16: 316 | N16: T
B17: CONELSUR LT SAC | C17: YANANGO - PACHACHACA | D17: L-2256 | E17: 04/11/2025 07:07 | F17: 04/11/2025 15:48 | G17: CAMBIO DE PARARRAYOS | H17: 0 | I17: P | J17: F/S | K17: N | L17: PREV. | M17: 1074 | N17: T
B18: CONENHUA | C18: CHILOTA | D18: CL-2331 | E18: 04/11/2025 00:00 | F18: 05/11/2025 00:00 | G18: Energizacion Bahia CL-1331 en 220KV Subestacion Chilota de propiedad de CONENHUA | H18: 0 | I18: P | J18: E/S | K18: N | L18: P.ENERG | M18: 26710 | N18: T
... B152: TRANSMANTARO | C152: YARABAMBA | D152: CL-R-30 | E152: 04/11/2025 00:00 | F152: 05/11/2025 00:00 | G152: CL-R30 CON MANDO SINCRONIZADO ASOCIADO AL INTERRUPTOR IN-5147 INDISPONIBLE. EL SABADO 19.04.25 NO PUDO SER AJUSTADO DEBIDO A FALTA DE EQUIPOS DE PARTE DE LA CONTRATISTA HITACHI. | H152: 0 | I152: P | J152: E/S | K152: N | L152: OTROS | M152: 17424 | N152: T

Sheet INGRESO OC
A3: martes, 4 de Noviembre del 2025
A5: INGRESO A OPERACIÓN COMERCIAL
A6: EMPRESA | B6: TIPO DE EQUIPO | C6: UBICACIÓN | D6: EQUIPO | E6: Fecha y hora de Ingreso a Operación Comercial

Sheet DESPACHO_EJECUTADO
B3: martes, 4 de Noviembre del 2025
A5: POTENCIA ACTIVA EJECUTADA DE LAS UNIDADES DE GENERACIÓN DEL SEIN (MW) | FM5: CENTRALES NO INTEGRANTES COES
A6: FECHA | B6: HORA | C6: 65333 | D6: 101 | E6: 102 | F6: 42667 | G6: 42668 | H6: 126 | I6: 127 | J6: 138 | K6: 139 | L6: 197 | M6: 203 | N6: 204 | O6: 230 | P6: 209 | Q6: 56677 | R6: 796 | S6: 2146 | T6: 142 | U6: 143 | V6: 125 | W6: 187 | X6: 163 | Y6: 298 | Z6: 299 | AA6: 219 | AB6: 151 | AC6: 152 | AD6: 153 | AE6: 154 | AF6: 756 | AG6: 156 | AH6: 155 | AI6: 182 | AJ6: 212 | AK6: 758 | AL6: 263 | AM6: 265 | AN6: 775 | AO6: 777 | AP6: 2154 | AQ6: 150 | AR6: 149 | AS6: 188 | AT6: 2131 | AU6: 755 | AV6: 252 | AW6: 249 | AX6: 250 | AY6: 117 | AZ6: 267 | BA6: 268 | BB6: 119 | BC6: 120 | BD6: 189 | BE6: 122 | BF6: 266 | BG6: 337 | BH6: 338 | BI6: 251 | BJ6: 115 | BK6: 239 | BL6: 288 | BM6: 240 | BN6: 241 | BO6: 242 | BP6: 191 | BQ6: 194 | BR6: 196 | BS6: 207 | BT6: 236 | BU6: 795 | BV6: 285 | BW6: 995 | BX6: 996 | BY6: 997 | BZ6: 766 | CA6: 926 | CB6: 924 | CC6: 121 | CD6: 103 | CE6: 104 | CF6: 106 | CG6: 105 | CH6: 107 | CI6: 110 | CJ6: 109 | CK6: 144 | CL6: 113 | CM6: 114 | CN6: 193 | CO6: 208 | CP6: 786 | CQ6: 787 | CR6: 788 | CS6: 789 | CT6: 248 | CU6: 2159 | CV6: 303 | CW6: 59715 | CX6: 62255 | CY6: 1263 | CZ6: 61800 | DA6: 2194 | DB6: 69125 | DC6: 216 | DD6: 198 | DE6: 70400 | DF6: 49607 | DG6: 214 | DH6: 260 | DI6: 2152 | DJ6: 2128 | DK6: 247 | DL6: 228 | DM6: 2135 | DN6: 261 | DO6: 237 | DP6: 253 | DQ6: 770 | DR6: 235 | DS6: 238 | DT6: 2184 | DU6: 61855 | DV6: 223 | DW6: 226 | DX6: 201 | DY6: 258 | DZ6: 259 | EA6: 920 | EB6: 257 | EC6: 256 | ED6: 2148 | EE6: 58288 | EF6: 58289 | EG6: 58839 | EH6: 58840 | EI6: 296 | EJ6: 297 | EK6: 211 | EL6: 2175 | EM6: 2178 | EN6: 2181 | EO6: 1262 | EP6: 63425 | EQ6: 233 | ER6: 2150 | ES6: 2165 | ET6: 2161 | EU6: 61197 | EV6: 58851 | EW6: 225 | EX6: 2201 | EY6: 2171 | EZ6: 760 | FA6: 234 | FB6: 215 | FC6: 917 | FD6: 289 | FE6: 58333 | FF6: 58336 | FG6: 213 | FH6: 232 | FI6: 2190 | FJ6: 69867 | FK6: TOTAL COES | FM6: 221 | FN6: 222 | FO6: 224 | FP6: 2187 | FQ6: 227 | FR6: 49400 | FS6: 199 | FT6: 200 | FU6: TOTAL NO COES
C7: SUR | D7: CENTRO | E7: CENTRO | F7: NORTE | G7: NORTE | H7: NORTE | I7: NORTE | J7: CENTRO | K7: CENTRO | L7: CENTRO | M7: CENTRO | N7: CENTRO | O7: CENTRO | P7: CENTRO | Q7: CENTRO | R7: CENTRO | S7: CENTRO | T7: CENTRO | U7: CENTRO | V7: CENTRO | W7: CENTRO | X7: SUR | Y7: SUR | Z7: SUR | AA7: CENTRO | AB7: SUR | AC7: SUR | AD7: SUR | AE7: SUR | AF7: SUR | AG7: SUR | AH7: SUR | AI7: SUR | AJ7: CENTRO | AK7: NORTE | AL7: NORTE | AM7: NORTE | AN7: CENTRO | AO7: CENTRO | AP7: CENTRO | AQ7: CENTRO | AR7: CENTRO | AS7: CENTRO | AT7: CENTRO | AU7: SUR | AV7: CENTRO | AW7: CENTRO | AX7: CENTRO | AY7: CENTRO | AZ7: CENTRO | BA7: CENTRO | BB7: CENTRO | BC7: CENTRO | BD7: SUR | BE7: NORTE | BF7: CENTRO | BG7: CENTRO | BH7: CENTRO | BI7: CENTRO | BJ7: NORTE | BK7: NORTE | BL7: NORTE | BM7: SUR | BN7: SUR | BO7: SUR | BP7: CENTRO | BQ7: CENTRO | BR7: CENTRO | BS7: CENTRO | BT7: CENTRO | BU7: CENTRO | BV7: CENTRO | BW7: SUR | BX7: SUR | BY7: SUR | BZ7: NORTE | CA7: SUR | CB7: CENTRO | CC7: NORTE | CD7: CENTRO | CE7: CENTRO | CF7: CENTRO | CG7: CENTRO | CH7: CENTRO | CI7: CENTRO | CJ7: CENTRO | CK7: CENTRO | CL7: CENTRO | CM7: CENTRO | CN7: CENTRO | CO7: CENTRO | CP7: SUR | CQ7: SUR | CR7: SUR | CS7: SUR | CT7: CENTRO | CU7: CENTRO | CV7: CENTRO | CW7: CENTRO | CX7: SUR | CY7: NORTE | CZ7: NORTE | DA7: NORTE | DB7: CENTRO | DC7: NORTE | DD7: NORTE | DE7: SUR | DF7: SUR | DG7: CENTRO | DH7: CENTRO | DI7: CENTRO | DJ7: NORTE | DK7: NORTE | DL7: CENTRO | DM7: CENTRO | DN7: SUR | DO7: SUR | DP7: CENTRO | DQ7: CENTRO | DR7: SUR | DS7: CENTRO | DT7: CENTRO | DU7: NORTE | DV7: CENTRO | DW7: CENTRO | DX7: NORTE | DY7: CENTRO | DZ7: CENTRO | EA7: CENTRO | EB7: NORTE | EC7: NORTE | ED7: SUR | EE7: CENTRO | EF7: CENTRO | EG7: CENTRO | EH7: CENTRO | EI7: CENTRO | EJ7: CENTRO | EK7: SUR | EL7: SUR | EM7: SUR | EN7: SUR | EO7: NORTE | EP7: SUR | EQ7: SUR | ER7: SUR | ES7: CENTRO | ET7: CENTRO | EU7: CENTRO | EV7: SUR | EW7: CENTRO | EX7: CENTRO | EY7: CENTRO | EZ7: CENTRO | FA7: SUR | FB7: NORTE | FC7: CENTRO | FD7: NORTE | FE7: NORTE | FF7: NORTE | FG7: CENTRO | FH7: NORTE | FI7: NORTE | FJ7: NORTE | FM7: NORTE | FN7: CENTRO | FO7: NORTE | FP7: NORTE | FQ7: NORTE | FR7: NORTE | FS7: NORTE | FT7: NORTE
C8: HIDROELÉCTRICA | D8: HIDROELÉCTRICA | E8: HIDROELÉCTRICA | F8: TERMOELÉCTRICA | G8: TERMOELÉCTRICA | H8: HIDROELÉCTRICA | I8: HIDROELÉCTRICA | J8: TERMOELÉCTRICA | K8: TERMOELÉCTRICA | L8: TERMOELÉCTRICA | M8: TERMOELÉCTRICA | N8: TERMOELÉCTRICA | O8: TERMOELÉCTRICA | P8: TERMOELÉCTRICA | Q8: TERMOELÉCTRICA | R8: HIDROELÉCTRICA | S8: HIDROELÉCTRICA | T8: TERMOELÉCTRICA | U8: TERMOELÉCTRICA | V8: TERMOELÉCTRICA | W8: TERMOELÉCTRICA | X8: HIDROELÉCTRICA | Y8: HIDROELÉCTRICA | Z8: HIDROELÉCTRICA | AA8: TERMOELÉCTRICA | AB8: HIDROELÉCTRICA | AC8: HIDROELÉCTRICA | AD8: HIDROELÉCTRICA | AE8: HIDROELÉCTRICA | AF8: TERMOELÉCTRICA | AG8: TERMOELÉCTRICA | AH8: TERMOELÉCTRICA | AI8: HIDROELÉCTRICA | AJ8: HIDROELÉCTRICA | AK8: TERMOELÉCTRICA | AL8: TERMOELÉCTRICA | AM8: TERMOELÉCTRICA | AN8: HIDROELÉCTRICA | AO8: HIDROELÉCTRICA | AP8: HIDROELÉCTRICA | AQ8: HIDROELÉCTRICA | AR8: HIDROELÉCTRICA | AS8: HIDROELÉCTRICA | AT8: HIDROELÉCTRICA | AU8: HIDROELÉCTRICA | AV8: TERMOELÉCTRICA | AW8: TERMOELÉCTRICA | AX8: TERMOELÉCTRICA | AY8: HIDROELÉCTRICA | AZ8: HIDROELÉCTRICA | BA8: HIDROELÉCTRICA | BB8: HIDROELÉCTRICA | BC8: HIDROELÉCTRICA | BD8: HIDROELÉCTRICA | BE8: HIDROELÉCTRICA | BF8: HIDROELÉCTRICA | BG8: HIDROELÉCTRICA | BH8: HIDROELÉCTRICA | BI8: HIDROELÉCTRICA | BJ8: TERMOELÉCTRICA | BK8: TERMOELÉCTRICA | BL8: TERMOELÉCTRICA | BM8: TERMOELÉCTRICA | BN8: TERMOELÉCTRICA | BO8: TERMOELÉCTRICA | BP8: HIDROELÉCTRICA | BQ8: TERMOELÉCTRICA | BR8: TERMOELÉCTRICA | BS8: TERMOELÉCTRICA | BT8: TERMOELÉCTRICA | BU8: TERMOELÉCTRICA | BV8: TERMOELÉCTRICA | BW8: TERMOELÉCTRICA | BX8: TERMOELÉCTRICA | BY8: TERMOELÉCTRICA | BZ8: HIDROELÉCTRICA | CA8: TERMOELÉCTRICA | CB8: TERMOELÉCTRICA | CC8: HIDROELÉCTRICA | CD8: HIDROELÉCTRICA | CE8: HIDROELÉCTRICA | CF8: HIDROELÉCTRICA | CG8: HIDROELÉCTRICA | CH8: HIDROELÉCTRICA | CI8: TERMOELÉCTRICA | CJ8: TERMOELÉCTRICA | CK8: TERMOELÉCTRICA | CL8: TERMOELÉCTRICA | CM8: TERMOELÉCTRICA | CN8: TERMOELÉCTRICA | CO8: TERMOELÉCTRICA | CP8: TERMOELÉCTRICA | CQ8: TERMOELÉCTRICA | CR8: TERMOELÉCTRICA | CS8: TERMOELÉCTRICA | CT8: TERMOELÉCTRICA | CU8: TERMOELÉCTRICA | CV8: SOLAR | CW8: EÓLICA | CX8: SOLAR | CY8: EÓLICA | CZ8: SOLAR | DA8: HIDROELÉCTRICA | DB8: HIDROELÉCTRICA | DC8: HIDROELÉCTRICA | DD8: HIDROELÉCTRICA | DE8: SOLAR | DF8: HIDROELÉCTRICA | DG8: HIDROELÉCTRICA | DH8: HIDROELÉCTRICA | DI8: HIDROELÉCTRICA | DJ8: HIDROELÉCTRICA | DK8: HIDROELÉCTRICA | DL8: HIDROELÉCTRICA | DM8: HIDROELÉCTRICA | DN8: SOLAR | DO8: SOLAR | DP8: EÓLICA | DQ8: EÓLICA | DR8: SOLAR | DS8: HIDROELÉCTRICA | DT8: HIDROELÉCTRICA | DU8: HIDROELÉCTRICA | DV8: HIDROELÉCTRICA | DW8: HIDROELÉCTRICA | DX8: HIDROELÉCTRICA | DY8: HIDROELÉCTRICA | DZ8: HIDROELÉCTRICA | EA8: HIDROELÉCTRICA | EB8: EÓLICA | EC8: EÓLICA | ED8: SOLAR | EE8: EÓLICA | EF8: EÓLICA | EG8: EÓLICA | EH8: EÓLICA | EI8: HIDROELÉCTRICA | EJ8: HIDROELÉCTRICA | EK8: HIDROELÉCTRICA | EL8: HIDROELÉCTRICA | EM8: HIDROELÉCTRICA | EN8: HIDROELÉCTRICA | EO8: EÓLICA | EP8: SOLAR | EQ8: SOLAR | ER8: SOLAR | ES8: HIDROELÉCTRICA | ET8: EÓLICA | EU8: EÓLICA | EV8: SOLAR | EW8: TERMOELÉCTRICA | EX8: TERMOELÉCTRICA | EY8: TERMOELÉCTRICA | EZ8: TERMOELÉCTRICA | FA8: SOLAR | FB8: HIDROELÉCTRICA | FC8: HIDROELÉCTRICA | FD8: TERMOELÉCTRICA | FE8: TERMOELÉCTRICA | FF8: TERMOELÉCTRICA | FG8: TERMOELÉCTRICA | FH8: TERMOELÉCTRICA | FI8: TERMOELÉCTRICA | FJ8: TERMOELÉCTRICA | FM8: HIDROELÉCTRICA | FN8: HIDROELÉCTRICA | FO8: HIDROELÉCTRICA | FP8: HIDROELÉCTRICA | FQ8: TERMOELÉCTRICA | FR8: TERMOELÉCTRICA | FS8: HIDROELÉCTRICA | FT8: HIDROELÉCTRICA
C9: HYDRO GLOBAL PERÚ S.A.C. | D9: ELECTROPERU | E9: ELECTROPERU | F9: ELECTROPERU | G9: ELECTROPERU | H9: ORAZUL ENERGY PERÚ | I9: ORAZUL ENERGY PERÚ | J9: TERMOSELVA | K9: TERMOSELVA | L9: KALLPA GENERACION S.A. | M9: KALLPA GENERACION S.A. | N9: KALLPA GENERACION S.A. | O9: KALLPA GENERACION S.A. | P9: KALLPA GENERACION S.A. | Q9: KALLPA GENERACION S.A. | R9: KALLPA GENERACION S.A. | S9: KALLPA GENERACION S.A. | T9: SHOUGESA | U9: SHOUGESA | V9: SHOUGESA | W9: SHOUGESA | X9: EGEMSA | Y9: EGESUR | Z9: EGESUR | AA9: EGESUR | AB9: EGASA | AC9: EGASA | AD9: EGASA | AE9: EGASA | AF9: EGASA | AG9: EGASA | AH9: EGASA | AI9: SAN GABAN | AJ9: CELEPSA | AK9: MINERA CERRO VERDE | AL9: PLANTA DE RESERVA FRIA DE GENERACION DE ETEN S.A. | AM9: PLANTA DE RESERVA FRIA DE GENERACION DE ETEN S.A. | AN9: EMPRESA DE GENERACION HUALLAGA | AO9: EMPRESA DE GENERACION HUALLAGA | AP9: LA VIRGEN | AQ9: CHINANGO S.A.C. | AR9: CHINANGO S.A.C. | AS9: HIDROELECTRICA HUANCHOR S.A.C. | AT9: CELEPSA RENOVABLES S.R.L. | AU9: INLAND ENERGY SAC | AV9: FENIX POWER PERÚ | AW9: FENIX POWER PERÚ | AX9: FENIX POWER PERÚ | AY9: STATKRAFT S.A | AZ9: STATKRAFT S.A | BA9: STATKRAFT S.A | BB9: STATKRAFT S.A | BC9: STATKRAFT S.A | BD9: STATKRAFT S.A | BE9: STATKRAFT S.A | BF9: STATKRAFT S.A | BG9: CENTRALES SANTA ROSA S.A.C. | BH9: CENTRALES SANTA ROSA S.A.C. | BI9: EMPRESA DE GENERACION HUANZA | BJ9: ENEL GENERACION PIURA S.A. | BK9: ENEL GENERACION PIURA S.A. | BL9: ENEL GENERACION PIURA S.A. | BM9: ENGIE ENERGIA PERU S.A.A. | BN9: ENGIE ENERGIA PERU S.A.A. | BO9: ENGIE ENERGIA PERU S.A.A. | BP9: ENGIE ENERGIA PERU S.A.A. | BQ9: ENGIE ENERGIA PERU S.A.A. | BR9: ENGIE ENERGIA PERU S.A.A. | BS9: ENGIE ENERGIA PERU S.A.A. | BT9: ENGIE ENERGIA PERU S.A.A. | BU9: ENGIE ENERGIA PERU S.A.A. | BV9: ENGIE ENERGIA PERU S.A.A. | BW9: ENGIE ENERGIA PERU S.A.A. | BX9: ENGIE ENERGIA PERU S.A.A. | BY9: ENGIE ENERGIA PERU S.A.A. | BZ9: ENGIE ENERGIA PERU S.A.A. | CA9: INFRAESTRUCTURAS Y ENERGIAS DEL PERU S.A.C. | CB9: INFRAESTRUCTURAS Y ENERGIAS DEL PERU S.A.C. | CC9: INVERSIONES SHAQSHA S.A.C. | CD9: ORYGEN PERU S.A.A. | CE9: ORYGEN PERU S.A.A. | CF9: ORYGEN PERU S.A.A. | CG9: ORYGEN PERU S.A.A. | CH9: ORYGEN PERU S.A.A. | CI9: ORYGEN PERU S.A.A. | CJ9: ORYGEN PERU S.A.A. | CK9: ORYGEN PERU S.A.A. | CL9: ORYGEN PERU S.A.A. | CM9: ORYGEN PERU S.A.A. | CN9: ORYGEN PERU S.A.A. | CO9: ORYGEN PERU S.A.A. | CP9: SAMAY I S.A.C | CQ9: SAMAY I S.A.C | CR9: SAMAY I S.A.C | CS9: SAMAY I S.A.C | CT9: TERMOCHILCA S.A.C. | CU9: TERMOCHILCA S.A.C. | CV9: COLCA SOLAR S.A.C. | CW9: ENERGIA RENOVABLE DEL SUR S.A. | CX9: GR CORTARRAMA SOCIEDAD ANONIMA CERRADA | CY9: GR TARUCA SOCIEDAD ANONIMA CERRADA | CZ9: KONDU SAC | DA9: PERUANA DE INVERSIONES EN ENERGIAS RENOVABLES S.A. | DB9: VARI ENERGIA S.A.C. | DC9: ORAZUL ENERGY PERÚ | DD9: ORAZUL ENERGY PERÚ | DE9: KALLPA GENERACION S.A. | DF9: SAN GABAN | DG9: MAJA ENERGIA S.A.C. | DH9: EMPRESA DE GENERACION ELECTRICA CANCHAYLLO SAC | DI9: EMPRESA DE GENERACION ELECTRICA SANTA ANA S.A.C. | DJ9: EMPRESA ELECTRICA AGUA AZUL | DK9: EMPRESA ELECTRICA RIO DOBLE | DL9: HIDROCAÑETE S.A. | DM9: HUAURA POWER GROUP S.A. | DN9: MOQUEGUA FV S.A.C. | DO9: PANAMERICANA SOLAR SAC. | DP9: PARQUE EOLICO MARCONA S.A.C. | DQ9: PARQUE EOLICO TRES HERMANAS S.A.C. | DR9: TACNA SOLAR SAC. | DS9: ELECTRICA YANAPAMPA SAC | DT9: ANDEAN POWER S.A.C. | DU9: ASOCIACIÓN SANTA LUCIA DE CHACAS | DV9: ATRIA ENERGIA S.A.C. | DW9: EGEJUNIN | DX9: EGEJUNIN | DY9: EGEJUNIN | DZ9: EGEJUNIN | EA9: EMPRESA DE GENERACION ELECTRICA RIO BAÑOS S.A.C. | EB9: ENERGÍA EÓLICA S.A. | EC9: ENERGÍA EÓLICA S.A. | ED9: ENGIE ENERGIA PERU S.A.A. | EE9: ENGIE ENERGIA PERU S.A.A. | EF9: ENGIE ENERGIA PERU S.A.A. | EG9: ENGIE ENERGIA PERU S.A.A. | EH9: ENGIE ENERGIA PERU S.A.A. | EI9: GENERACIÓN ANDINA S.A.C. | EJ9: GENERACIÓN ANDINA S.A.C. | EK9: GENERADORA DE ENERGÍA DEL PERÚ | EL9: GENERADORA DE ENERGÍA DEL PERÚ | EM9: GENERADORA DE ENERGÍA DEL PERÚ | EN9: GENERADORA DE ENERGÍA DEL PERÚ | EO9: GR PAINO SOCIEDAD ANONIMA CERRADA | EP9: JOYA SOLAR S.A.C. | EQ9: MAJES ARCUS S.A.C. | ER9: ORYGEN PERU S.A.A. | ES9: ORYGEN PERU S.A.A. | ET9: ORYGEN PERU S.A.A. | EU9: ORYGEN PERU S.A.A. | EV9: ORYGEN PERU S.A.A. | EW9: PETRAMAS | EX9: PETRAMAS | EY9: PETRAMAS | EZ9: PETRAMAS | FA9: REPARTICIÓN ARCUS S.A.C. | FB9: SINERSA | FC9: SINERSA | FD9: BIOENERGIA DEL CHIRA S.A. | FE9: GM OPERACIONES S.A.C. | FF9: GM OPERACIONES S.A.C. | FG9: AGRO INDUSTRIAL PARAMONGA S.A. | FH9: AGROAURORA S.A.C. | FI9: AGROINDUSTRIAS SAN JACINTO S.A.A. | FJ9: AGROLMOS SOCIEDAD ANONIMA - AGROLMOS S.A. | FM9: UNACEM PERU S.A. | FN9: ELECTRO ORIENTE | FO9: AGUAS Y ENERGIA PERU | FP9: ELECTRO ZAÑA S.A.C. | FQ9: ELECTRONOROESTE S.A. | FR9: SDE PIURA | FS9: SINERSA | FT9: SINERSA
C10: SAN GABAN III | D10: MANTARO | E10: RESTITUCION | F10: TUMBES MAK 1 | G10: TUMBES MAK 2 | H10: CARHUAQUERO | I10: CAÑON DEL PATO | J10: AGUAYTIA TG1 | K10: AGUAYTIA TG2 | L10: KALLPA TG1 | M10: KALLPA TG2 | N10: KALLPA TG3 | O10: KALLPA TV | P10: LFLORES TG1 | Q10: LFLORES TV | R10: CERRO DEL AGUILA | S10: CERRODELAGUILAG4 | T10: SHOUGESA TV1 | U10: SHOUGESA TV2 | V10: SHOUGESA TV3 | W10: SHOUGESA CUMMINS | X10: MACHUPICCHU | Y10: ARICOTA 1 | Z10: ARICOTA 2 | AA10: INDEPENDENCIA | AB10: CHARCANI I,II,III | AC10: CHARCANI IV | AD10: CHARCANI V | AE10: CHARCANI VI | AF10: CHILINA TG | AG10: MOLLENDO 1, 2, 3 | AH10: CHILINA (SULZ 1,2) | AI10: SAN GABAN II | AJ10: PLATANAL | AK10: RECKA | AL10: RF ETEN TG1 | AM10: RF ETEN TG2 | AN10: CHAGLLA GP1 | AO10: CHAGLLA | AP10: LA VIRGEN | AQ10: CHIMAY | AR10: YANANGO | AS10: HUANCHOR | AT10: MARAÑON | AU10: STA TERESA | AV10: FENIX GT11 | AW10: FENIX GT12 | AX10: FENIX TV10 | AY10: YAUPI | AZ10: OROYA | BA10: PACHACHACA | BB10: MALPASO | BC10: CAHUA | BD10: ARCATA | BE10: GALLITO CIEGO | BF10: CHEVES | BG10: SANTA ROSA 1 | BH10: SANTA ROSA 2 | BI10: HUANZA | BJ10: MALACAS2 TG4 | BK10: MALACAS3 TG 5 | BL10: MALACAS1 TG6 | BM10: RF ILO2 TG1 | BN10: RF ILO2 TG2 | BO10: RF ILO2 TG3 | BP10: YUNCAN | BQ10: CHILCA1 TG1 | BR10: CHILCA1 TG2 | BS10: CHILCA1 TG3 | BT10: CHILCA-TV | BU10: CHILCA2 TG41 | BV10: CHILCA2-TV | BW10: CTNEPI_TG41 | BX10: CTNEPI_TG42 | BY10: CTNEPI_TG43 | BZ10: QUITARACSA | CA10: RF PTO MALDONADO | CB10: RF PUCALLPA | CC10: PARIAC | CD10: HUINCO | CE10: MATUCANA | CF10: MOYOPAMPA | CG10: CALLAHUANCA | CH10: HUAMPANI | CI10: STA ROSA WEST TG7 | CJ10: UTI_5 | CK10: UTI_6 | CL10: VENTANILLA 3 | CM10: VENTANILLA 4 | CN10: VENTANILLA TV | CO10: STAROSA TG8 | CP10: PTO_BRVO TG1 | CQ10: PTO_BRVO TG2 | CR10: PTO_BRVO TG3 | CS10: PTO_BRVO TG4 | CT10: OLLEROS TG1 | CU10: OLLEROS TV | CV10: CS YARUCAYA | CW10: SAN JUAN | CX10: MATARANI | CY10: DUNA | CZ10: CARHUAQUERO (CS) | DA10: MANTA I | DB10: ANASHIRONI | DC10: CARHUAQUERO4 | DD10: CAÑA BRAVA | DE10: SUNNY | DF10: TUPURI | DG10: RONCADOR | DH10: CANCHAYLLO | DI10: RENOVANDESH1 | DJ10: POTRERO | DK10: PIZARRAS | DL10: NIMPERIAL | DM10: YARUCAYA | DN10: MOQUEGUA-SOLAR | DO10: PANAMERICANA-SOLAR | DP10: PQE-EOLICO-MARCONA | DQ10: PQE-EOLICO-3-HERMANAS | DR10: TACNA-SOLAR | DS10: YANAPAMPA | DT10: CARHUAC | DU10: HUALLIN | DV10: PURMACANA | DW10: HUASAHUASI | DX10: STACRUZ_1_2 | DY10: RUNATULLO_II | DZ10: RUNATULLO_III | EA10: RUCUY | EB10: PQE-EOLICO-TALARA | EC10: PQE-EOLICO-CUPISNIQUE | ED10: INTIPAMPA | EE10: PUNTA LOMITAS-BL1 | EF10: PUNTA LOMITAS-BL2 | EG10: PUN LOMITAS_EXP-BL1 | EH10: PUN LOMITAS_EXP-BL2 | EI10: 8AGOSTO | EJ10: EL CARMEN | EK10: LA JOYA | EL10: ANGEL_I | EM10: ANGEL_II | EN10: ANGEL_III | EO10: HUAMBOS | EP10: SAN MARTIN SOLAR | EQ10: MAJES | ER10: RUBI | ES10: CH_HER1 | ET10: WAYRA-I | EU10: WAYRA EXTENSION | EV10: CLEMESI | EW10: HUAYCOLORO | EX10: CALLAO | EY10: DONA_CATALINA | EZ10: LAGRINGAV | FA10: REPARTICION | FB10: POECHOS2 | FC10: CHANCAY | FD10: CANA BRAVA | FE10: REFINERIA TALARA TV1 | FF10: REFINERÍA TALARA TV2 | FG10: PARAMONGA | FH10: MAPLE | FI10: SAN_JACINTO | FJ10: AGROLMOS | FK10: MW | FM10: CARPAPATA | FN10: CENTRALES ELOR | FO10: PIAS1 | FP10: ZANA | FQ10: TABLAZO | FR10: TALLANCA | FS10: CURUMUY | FT10: POECHOS1 | FU10: MW
A11: 04/11/2025 | B11: 00:30 | C11: 203.5 | D11: 628.9 | E11: 215.5 | H11: 89.7 | I11: 187.5 | L11: 155.2 | M11: 155.6 | N11: 155.6 | O11: 251.3 | P11: 212.6 | R11: 359.4 | S11: 10.4 | X11: 147.7 | Y11: 7.5 | Z11: 5.8 | AA11: 5.6 | AB11: 6.9 | AC11: 13.6 | AD11: 84.1 | AI11: 110.7 | AJ11: 58.5 | AN11: 6.5 | AO11: 0 | AP11: 59.6 | AQ11: 151.5 | AR11: 31.1 | AS11: 17.2 | AT11: 18.8 | AU11: 79 | AY11: 108.3 | AZ11: 7.5 | BA11: 6.3 | BB11: 34.6 | BC11: 41.2 | BD11: 2 | BE11: 11.9 | BF11: 66.5 | BI11: 46.7 | BL11: 48.3 | BP11: 83.9 | BQ11: 175.6 | BR11: 173.4 | BS11: 200 | BT11: 270.8 | CA11: 0 | CC11: 3.6 | CD11: 160.2 | CE11: 85.5 | CF11: 63 | CG11: 47.8 | CH11: 30.1 | CL11: 0 | CM11: 0 | CN11: 0 | CS11: 0 | CT11: 215.9 | CU11: 103.5 | CV11: 0 | CW11: 78.3 | CX11: 0 | CY11: 0 | CZ11: 0 | DA11: 20 | DB11: 20.7 | DD11: 4.7 | DF11: 1 | DG11: 2.5 | DH11: 2.8 | DJ11: 20 | DK11: 18.9 | DL11: 3.4 | DM11: 18.6 | DN11: 0 | DO11: 0 | DP11: 28.9 | DQ11: 76.8 | DR11: 0 | DS11: 3.1 | DT11: 10.5 | DU11: 2.4 | DW11: 13.7 | DX11: 6.8 | DY11: 9.8 | DZ11: 13.9 | EA11: 16.6 | EB11: 21.4 | EC11: 44.5 | ED11: 0 | EE11: 76.5 | EF11: 75.1 | EG11: 7.1 | EH11: 7.8 | EI11: 20.7 | EJ11: 7.7 | EK11: 7.4 | EL11: 18.4 | EM11: 19.8 | EN11: 19.7 | EO11: 0 | EQ11: 0 | ER11: 0 | ES11: 0.6 | ET11: 56.7 | EU11: 59.4 | EV11: 0 | EW11: 1.1 | EY11: 1.8 | EZ11: 1 | FA11: 0 | FB11: 6.4 | FC11: 18.9 | FD11: 9 | FE11: 28.4 | FF11: 35.2 | FG11: 14.9 | FH11: 15.9 | FI11: 0 | FJ11: 11 | FK11: 6375.7 | FM11: 21.3 | FN11: 7.95 | FO11: 0 | FP11: 13.2 | FQ11: 0 | FR11: 18.9 | FS11: 4.9 | FT11: 5.3 | FU11: 71.55
A12: 04/11/2025 | B12: 01:00 | C12: 203.8 | D12: 630.5 | E12: 215.8 | H12: 90.1 | I12: 186.6 | L12: 163.5 | M12: 163.1 | N12: 163.5 | O12: 254.4 | P12: 108.8 | R12: 359.8 | S12: 10.4 | X12: 139.7 | Y12: 7.5 | Z12: 5.9 | AA12: 5.6 | AB12: 6.9 | AC12: 13.6 | AD12: 84.5 | AI12: 110.6 | AJ12: 59.4 | AN12: 6.5 | AO12: 0 | AP12: 59.2 | AQ12: 151.6 | AR12: 31.6 | AS12: 17.4 | AT12: 18.8 | AU12: 71.7 | AY12: 108.3 | AZ12: 7.5 | BA12: 6.3 | BB12: 35.4 | BC12: 41.1 | BD12: 2 | BE12: 11.8 | BF12: 66 | BI12: 46.8 | BL12: 48.5 | BP12: 84 | BQ12: 175.4 | BR12: 173 | BS12: 200 | BT12: 272 | CA12: 0 | CC12: 3.6 | CD12: 98.4 | CE12: 84.8 | CF12: 63 | CG12: 47.4 | CH12: 30.1 | CL12: 0 | CM12: 0 | CN12: 0 | CS12: 0 | CT12: 215.9 | CU12: 103.3 | CV12: 0 | CW12: 75.6 | CX12: 0 | CY12: 0 | CZ12: 0 | DA12: 20 | DB12: 20.7 | DD12: 0 | DF12: 1 | DG12: 2.5 | DH12: 3 | DJ12: 20 | DK12: 18.9 | DL12: 3.4 | DM12: 18.6 | DN12: 0 | DO12: 0 | DP12: 28 | DQ12: 77.4 | DR12: 0 | DS12: 3.1 | DT12: 10.9 | DU12: 2.4 | DW12: 13.7 | DX12: 6.8 | DY12: 10.3 | DZ12: 14 | EA12: 18.9 | EB12: 26.8 | EC12: 55 | ED12: 0 | EE12: 73.8 | EF12: 77.8 | EG12: 6.7 | EH12: 8.7 | EI12: 20.7 | EJ12: 7.7 | EK12: 7.1 | EL12: 19.7 | EM12: 19.8 | EN12: 19.7 | EO12: 0 | EQ12: 0 | ER12: 0 | ES12: 0.6 | ET12: 69.7 | EU12: 73.9 | EV12: 0 | EW12: 1.1 | EY12: 1.8 | EZ12: 1 | FA12: 0 | FB12: 6.4 | FC12: 19.7 | FD12: 8.6 | FE12: 27.8 | FF12: 35.1 | FG12: 15 | FH12: 19.2 | FI12: 0 | FJ12: 11 | FK12: 6269 | FM12: 21.6 | FN12: 7.92 | FO12: 0 | FP12: 13.2 | FQ12: 0 | FR12: 18.9 | FS12: 4.8 | FT12: 5.2 | FU12: 71.62
A13: 04/11/2025 | B13: 01:30 | C13: 205 | D13: 630.3 | E13: 215.8 | H13: 89.9 | I13: 187.5 | L13: 176.6 | M13: 177.3 | N13: 176.1 | O13: 261.7 | P13: 25.4 | R13: 360.9 | S13: 10.4 | X13: 147.3 | Y13: 7.7 | Z13: 6 | AA13: 5.6 | AB13: 6.9 | AC13: 13.6 | AD13: 50.5 | AI13: 110.8 | AJ13: 59.2 | AN13: 6.5 | AO13: 0 | AP13: 59 | AQ13: 151.8 | AR13: 31.2 | AS13: 17.4 | AT13: 18.8 | AU13: 82.2 | AY13: 109.2 | AZ13: 7.5 | BA13: 6.3 | BB13: 35.2 | BC13: 41.3 | BD13: 2 | BE13: 12.1 | BF13: 66.9 | BI13: 46.9 | BL13: 48.5 | BP13: 84.1 | BQ13: 175.9 | BR13: 173.6 | BS13: 200 | BT13: 270.7 | CA13: 0 | CC13: 3.6 | CD13: 111.1 | CE13: 87.3 | CF13: 63.1 | CG13: 47.6 | CH13: 30.1 | CL13: 0 | CM13: 0 | CN13: 0 | CS13: 0 | CT13: 215.7 | CU13: 103.4 | CV13: 0 | CW13: 74.7 | CX13: 0 | CY13: 0 | CZ13: 0 | DA13: 20 | DB13: 20.7 | DD13: 0 | DF13: 1 | DG13: 2.5 | DH13: 2.9 | DJ13: 20 | DK13: 18.9 | DL13: 3.4 | DM13: 18.6 | DN13: 0 | DO13: 0 | DP13: 28.7 | DQ13: 76.6 | DR13: 0 | DS13: 3 | DT13: 11 | DU13: 2.3 | DW13: 12.8 | DX13: 6.8 | DY13: 10.5 | DZ13: 14.1 | EA13: 17.3 | EB13: 27.2 | EC13: 44.5 | ED13: 0 | EE13: 73.8 | EF13: 77 | EG13: 7.6 | EH13: 7.6 | EI13: 20.6 | EJ13: 7.7 | EK13: 7.3 | EL13: 19.7 | EM13: 20.4 | EN13: 19.7 | EO13: 0 | EQ13: 0 | ER13: 0 | ES13: 0.6 | ET13: 73 | EU13: 80.5 | EV13: 0 | EW13: 1.1 | EY13: 1.8 | EZ13: 1 | FA13: 0 | FB13: 6.4 | FC13: 19.2 | FD13: 8.8 | FE13: 28.1 | FF13: 35.1 | FG13: 15 | FH13: 19.3 | FI13: 0 | FJ13: 11 | FK13: 6233.3 | FM13: 21.8 | FN13: 7.94 | FO13: 0 | FP13: 13.2 | FQ13: 0 | FR13: 18.9 | FS13: 5 | FT13: 5.3 | FU13: 72.14
A14: 04/11/2025 | B14: 02:00 | C14: 204 | D14: 631.5 | E14: 215.3 | H14: 90.1 | I14: 191.5 | L14: 168 | M14: 167 | N14: 166.9 | O14: 250.9 | P14: 0 | R14: 366.5 | S14: 10.4 | X14: 150.1 | Y14: 7.5 | Z14: 6 | AA14: 5.7 | AB14: 6.9 | AC14: 13.6 | AD14: 50.7 | AI14: 110.8 | AJ14: 58.7 | AN14: 6.5 | AO14: 0 | AP14: 59 | AQ14: 151.7 | AR14: 29.9 | AS14: 17.2 | AT14: 18.8 | AU14: 80.9 | AY14: 108.5 | AZ14: 7.5 | BA14: 6.2 | BB14: 35.3 | BC14: 43.1 | BD14: 2 | BE14: 11.8 | BF14: 66.6 | BI14: 46.9 | BL14: 48.5 | BP14: 84.1 | BQ14: 175.9 | BR14: 173.8 | BS14: 200 | BT14: 271.2 | CA14: 0 | CC14: 3.6 | CD14: 97.3 | CE14: 88 | CF14: 63.1 | CG14: 47.5 | CH14: 30.1 | CL14: 0 | CM14: 0 | CN14: 0 | CS14: 0 | CT14: 216 | CU14: 103.4 | CV14: 0 | CW14: 78.8 | CX14: 0 | CY14: 0 | CZ14: 0 | DA14: 20 | DB14: 20.7 | DD14: 0 | DF14: 1 | DG14: 2.3 | DH14: 3 | DJ14: 20 | DK14: 19 | DL14: 3.4 | DM14: 18.6 | DN14: 0 | DO14: 0 | DP14: 26.5 | DQ14: 76.7 | DR14: 0 | DS14: 3 | DT14: 10.8 | DU14: 2.3 | DW14: 12.8 | DX14: 6.8 | DY14: 10.5 | DZ14: 14.1 | EA14: 16 | EB14: 27.6 | EC14: 35.3 | ED14: 0 | EE14: 74 | EF14: 76.6 | EG14: 8.6 | EH14: 8.1 | EI14: 20.3 | EJ14: 7.7 | EK14: 7.5 | EL14: 19.7 | EM14: 20.4 | EN14: 19.7 | EO14: 0 | EQ14: 0 | ER14: 0 | ES14: 0.6 | ET14: 65.9 | EU14: 81.7 | EV14: 0 | EW14: 1.1 | EY14: 1.8 | EZ14: 1 | FA14: 0 | FB14: 6.4 | FC14: 18.7 | FD14: 8.8 | FE14: 28.4 | FF14: 35.1 | FG14: 15 | FH14: 19.3 | FI14: 0 | FJ14: 10.1 | FK14: 6152.2 | FM14: 22 | FN14: 7.94 | FO14: 0 | FP14: 13.2 | FQ14: 0 | FR14: 18.9 | FS14: 5 | FT14: 5.3 | FU14: 72.34
A15: 04/11/2025 | B15: 02:30 | C15: 203.1 | D15: 625.5 | E15: 215.3 | H15: 90.5 | I15: 194.7 | L15: 145.2 | M15: 145.4 | N15: 144.9 | O15: 255.3 | P15: 0 | R15: 352.9 | S15: 10.4 | X15: 149.1 | Y15: 7.3 | Z15: 5.8 | AA15: 5.6 | AB15: 6.9 | AC15: 13.6 | AD15: 49.8 | AI15: 110.8 | AJ15: 58.5 | AN15: 6.4 | AO15: 0 | AP15: 59 | AQ15: 151.3 | AR15: 32.7 | AS15: 17.2 | AT15: 18.8 | AU15: 77.3 | AY15: 107.9 | AZ15: 7.5 | BA15: 6.2 | BB15: 15.5 | BC15: 42.9 | BD15: 2 | BE15: 12.1 | BF15: 65.1 | BI15: 46.8 | BL15: 48.7 | BP15: 83.9 | BQ15: 175.8 | BR15: 173.8 | BS15: 200 | BT15: 271.8 | CA15: 0 | CC15: 3.6 | CD15: 99.5 | CE15: 82.4 | CF15: 63.8 | CG15: 47.4 | CH15: 30 | CL15: 0 | CM15: 0 | CN15: 0 | CS15: 0 | CT15: 216.2 | CU15: 103.5 | CV15: 0 | CW15: 82.1 | CX15: 0 | CY15: 0 | CZ15: 0 | DA15: 20 | DB15: 20.7 | DD15: 0 | DF15: 1 | DG15: 2.2 | DH15: 3 | DJ15: 20 | DK15: 18.9 | DL15: 3.4 | DM15: 18.6 | DN15: 0 | DO15: 0 | DP15: 28.3 | DQ15: 76 | DR15: 0 | DS15: 3.2 | DT15: 10.9 | DU15: 2.3 | DW15: 12 | DX15: 6.8 | DY15: 10.2 | DZ15: 13.8 | EA15: 15.8 | EB15: 27.3 | EC15: 26.6 | ED15: 0 | EE15: 71.6 | EF15: 79 | EG15: 6.6 | EH15: 8.9 | EI15: 20.5 | EJ15: 7.7 | EK15: 7.4 | EL15: 19.7 | EM15: 20.4 | EN15: 20 | EO15: 0 | EQ15: 0 | ER15: 0 | ES15: 0.6 | ET15: 50.9 | EU15: 58.2 | EV15: 0 | EW15: 1.1 | EY15: 1.8 | EZ15: 1 | FA15: 0 | FB15: 6.4 | FC15: 18.7 | FD15: 8.8 | FE15: 27.7 | FF15: 34.6 | FG15: 15.3 | FH15: 18.9 | FI15: 0 | FJ15: 11.1 | FK15: 5999.7 | FM15: 22.1 | FN15: 7.94 | FO15: 0 | FP15: 13.2 | FQ15: 0 | FR15: 18.9 | FS15: 4.9 | FT15: 5.3 | FU15: 72.34
A16: 04/11/2025 | B16: 03:00 | C16: 201.9 | D16: 627.9 | E16: 215.3 | H16: 89 | I16: 195.1 | L16: 145.7 | M16: 145.8 | N16: 145.4 | O16: 247 | P16: 0 | R16: 360.4 | S16: 10.4 | X16: 145.7 | Y16: 7.1 | Z16: 5.7 | AA16: 5.7 | AB16: 6.9 | AC16: 13.9 | AD16: 49.7 | AI16: 110.5 | AJ16: 59 | AN16: 6.5 | AO16: 0 | AP16: 59 | AQ16: 150.9 | AR16: 31.4 | AS16: 17.2 | AT16: 18.8 | AU16: 80.1 | AY16: 108.2 | AZ16: 7.5 | BA16: 6.2 | BB16: 31.4 | BC16: 42.7 | BD16: 2 | BE16: 11.8 | BF16: 64.2 | BI16: 46.6 | BL16: 48.6 | BP16: 83.7 | BQ16: 177.1 | BR16: 174.7 | BS16: 200 | BT16: 271.9 | CA16: 0 | CC16: 3.6 | CD16: 116.7 | CE16: 79.4 | CF16: 63.7 | CG16: 47.4 | CH16: 29.7 | CL16: 30.2 | CM16: 0 | CN16: 0 | CS16: 0 | CT16: 216.2 | CU16: 103.7 | CV16: 0 | CW16: 79.8 | CX16: 0 | CY16: 0 | CZ16: 0 | DA16: 20 | DB16: 20.6 | DD16: 0 | DF16: 1 | DG16: 2.3 | DH16: 3 | DJ16: 20 | DK16: 19 | DL16: 3.4 | DM16: 18.6 | DN16: 0 | DO16: 0 | DP16: 27.1 | DQ16: 74.7 | DR16: 0 | DS16: 3.2 | DT16: 10.9 | DU16: 2.2 | DW16: 12 | DX16: 6.8 | DY16: 10.1 | DZ16: 13.9 | EA16: 16 | EB16: 26.9 | EC16: 24 | ED16: 0 | EE16: 75.5 | EF16: 75.9 | EG16: 6.9 | EH16: 8.6 | EI16: 20.6 | EJ16: 7.6 | EK16: 7.5 | EL16: 20.4 | EM16: 20.4 | EN16: 20 | EO16: 0 | EQ16: 0 | ER16: 0 | ES16: 0.6 | ET16: 56.5 | EU16: 77.7 | EV16: 0 | EW16: 1.1 | EY16: 1.8 | EZ16: 1 | FA16: 0 | FB16: 6.4 | FC16: 18.8 | FD16: 8.8 | FE16: 27.2 | FF16: 34.1 | FG16: 16 | FH16: 19.4 | FI16: 0 | FJ16: 11.1 | FK16: 6078.6 | FM16: 22.3 | FN16: 7.94 | FO16: 0 | FP16: 13.2 | FQ16: 0 | FR16: 18.9 | FS16: 5 | FT16: 5.2 | FU16: 72.54
A17: 04/11/2025 | B17: 03:30 | C17: 201.2 | D17: 626 | E17: 215.3 | H17: 88.2 | I17: 195.2 | L17: 148 | M17: 147.8 | N17: 147.6 | O17: 255.7 | P17: 0 | R17: 259.1 | S17: 10.3 | X17: 139.9 | Y17: 7.1 | Z17: 5.6 | AA17: 5.6 | AB17: 6.9 | AC17: 13.8 | AD17: 48.9 | AI17: 110.3 | AJ17: 58.3 | AN17: 6.4 | AO17: 0 | AP17: 58.5 | AQ17: 150.6 | AR17: 30.5 | AS17: 17.2 | AT17: 18.8 | AU17: 78.5 | AY17: 107.9 | AZ17: 7.5 | BA17: 6.2 | BB17: 24 | BC17: 43.4 | BD17: 2 | BE17: 11.8 | BF17: 65.9 | BI17: 46.6 | BL17: 48.4 | BP17: 83.4 | BQ17: 177.5 | BR17: 175.3 | BS17: 200 | BT17: 271.8 | CA17: 0 | CC17: 3.6 | CD17: 83.2 | CE17: 93 | CF17: 63.4 | CG17: 47.5 | CH17: 29.7 | CL17: 30.7 | CM17: 0 | CN17: 0 | CS17: 0 | CT17: 216.2 | CU17: 103.8 | CV17: 0 | CW17: 90.1 | CX17: 0 | CY17: 0 | CZ17: 0 | DA17: 20.1 | DB17: 20.7 | DD17: 0 | DF17: 1 | DG17: 2.4 | DH17: 3 | DJ17: 20 | DK17: 18.9 | DL17: 3.4 | DM17: 18.6 | DN17: 0 | DO17: 0 | DP17: 27.5 | DQ17: 76.4 | DR17: 0 | DS17: 3.2 | DT17: 10.9 | DU17: 2.2 | DW17: 12.1 | DX17: 6.8 | DY17: 10.3 | DZ17: 13.7 | EA17: 16 | EB17: 28 | EC17: 28 | ED17: 0 | EE17: 72.7 | EF17: 75.6 | EG17: 8.5 | EH17: 9.7 | EI17: 20.6 | EJ17: 7.6 | EK17: 7.5 | EL17: 20.4 | EM17: 20.4 | EN17: 20 | EO17: 0 | EQ17: 0 | ER17: 0 | ES17: 0.6 | ET17: 64 | EU17: 71.9 | EV17: 0 | EW17: 1.1 | EY17: 1.8 | EZ17: 1 | FA17: 0 | FB17: 6.4 | FC17: 18.8 | FD17: 8 | FE17: 28.8 | FF17: 35.7 | FG17: 16 | FH17: 19.4 | FI17: 0 | FJ17: 11.1 | FK17: 5975 | FM17: 22.2 | FN17: 7.95 | FO17: 0 | FP17: 13.2 | FQ17: 0 | FR17: 18.9 | FS17: 5 | FT17: 5.3 | FU17: 72.55
A18: 04/11/2025 | B18: 04:00 | C18: 204.8 | D18: 630.5 | E18: 216.7 | H18: 89.9 | I18: 195.6 | L18: 176.9 | M18: 177.3 | N18: 176.5 | O18: 258.2 | P18: 0 | R18: 273.7 | S18: 10.4 | X18: 148.2 | Y18: 7.6 | Z18: 5.9 | AA18: 5.6 | AB18: 6.9 | AC18: 13.8 | AD18: 50.5 | AI18: 110.8 | AJ18: 59.2 | AN18: 6.4 | AO18: 0 | AP18: 57.4 | AQ18: 151.3 | AR18: 29.8 | AS18: 17.2 | AT18: 18.8 | AU18: 80.8 | AY18: 109.2 | AZ18: 7.5 | BA18: 6.3 | BB18: 35 | BC18: 44.1 | BD18: 2 | BE18: 11.9 | BF18: 68.8 | BI18: 46.9 | BL18: 48.3 | BP18: 84.1 | BQ18: 176.3 | BR18: 174 | BS18: 200 | BT18: 269.9 | CA18: 0 | CC18: 3.6 | CD18: 94.4 | CE18: 91.6 | CF18: 64.1 | CG18: 47.4 | CH18: 30.1 | CL18: 30 | CM18: 0 | CN18: 0 | CS18: 0 | CT18: 216.5 | CU18: 103.8 | CV18: 0 | CW18: 85.3 | CX18: 0 | CY18: 0 | CZ18: 0 | DA18: 20 | DB18: 20.7 | DD18: 0 | DF18: 1 | DG18: 2.5 | DH18: 2.8 | DJ18: 20 | DK18: 19.1 | DL18: 3.4 | DM18: 18.6 | DN18: 0 | DO18: 0 | DP18: 30 | DQ18: 78.4 | DR18: 0 | DS18: 3.3 | DT18: 11 | DU18: 2.2 | DW18: 12.1 | DX18: 6.8 | DY18: 10.8 | DZ18: 14 | EA18: 16 | EB18: 28.4 | EC18: 26.8 | ED18: 0 | EE18: 71.2 | EF18: 82.5 | EG18: 6.6 | EH18: 6 | EI18: 20.3 | EJ18: 7.6 | EK18: 7.2 | EL18: 20.4 | EM18: 20.4 | EN18: 20 | EO18: 0 | EQ18: 0 | ER18: 0 | ES18: 0.6 | ET18: 58.2 | EU18: 58.5 | EV18: 0 | EW18: 1.1 | EY18: 1.8 | EZ18: 1 | FA18: 0 | FB18: 6.4 | FC18: 18.8 | FD18: 8.1 | FE18: 27.9 | FF18: 34.7 | FG18: 15.6 | FH18: 19.4 | FI18: 0 | FJ18: 11 | FK18: 6105 | FM18: 22.3 | FN18: 7.95 | FO18: 0 | FP18: 13.2 | FQ18: 0 | FR18: 18.9 | FS18: 5 | FT18: 5.3 | FU18: 72.65
A19: 04/11/2025 | B19: 04:30 | C19: 204.2 | D19: 594.9 | E19: 201 | H19: 89.9 | I19: 195.4 | L19: 147.1 | M19: 147.3 | N19: 147.1 | O19: 247 | P19: 0 | R19: 264.5 | S19: 10.5 | X19: 152.7 | Y19: 7.4 | Z19: 6 | AA19: 5.6 | AB19: 6.9 | AC19: 13.8 | AD19: 50.1 | AI19: 110.6 | AJ19: 58.4 | AN19: 6.5 | AO19: 0 | AP19: 57.6 | AQ19: 151 | AR19: 30.2 | AS19: 17.2 | AT19: 18.8 | AU19: 81.1 | AY19: 108.3 | AZ19: 7.5 | BA19: 6.1 | BB19: 24.5 | BC19: 43.8 | BD19: 2 | BE19: 11.7 | BF19: 68.2 | BI19: 66.6 | BL19: 48.2 | BP19: 83.9 | BQ19: 176.3 | BR19: 174 | BS19: 200 | BT19: 271.8 | CA19: 0 | CC19: 3.6 | CD19: 85.6 | CE19: 96.1 | CF19: 63.9 | CG19: 47.8 | CH19: 29.9 | CL19: 89.7 | CM19: 0 | CN19: 12.1 | CS19: 0 | CT19: 216.2 | CU19: 103.7 | CV19: 0 | CW19: 90.1 | CX19: 0 | CY19: 0 | CZ19: 0 | DA19: 20 | DB19: 20.6 | DD19: 0 | DF19: 1 | DG19: 2.3 | DH19: 2.8 | DJ19: 20 | DK19: 19.1 | DL19: 3.4 | DM19: 18.6 | DN19: 0 | DO19: 0 | DP19: 29.1 | DQ19: 75.7 | DR19: 0 | DS19: 3.3 | DT19: 14 | DU19: 2.2 | DW19: 12.2 | DX19: 6.8 | DY19: 11.1 | DZ19: 13.9 | EA19: 15.8 | EB19: 27.7 | EC19: 26.3 | ED19: 0 | EE19: 67.7 | EF19: 89.7 | EG19: 5.1 | EH19: 3.8 | EI19: 20.2 | EJ19: 7.6 | EK19: 6.8 | EL19: 20.4 | EM19: 20.4 | EN19: 20 | EO19: 0 | EQ19: 0 | ER19: 0 | ES19: 0.6 | ET19: 47.1 | EU19: 51 | EV19: 0 | EW19: 0.9 | EY19: 1.8 | EZ19: 1 | FA19: 0 | FB19: 6.4 | FC19: 18.7 | FD19: 7.3 | FE19: 28.1 | FF19: 35.1 | FG19: 15.8 | FH19: 18.5 | FI19: 0 | FJ19: 11.1 | FK19: 6005.4 | FM19: 22.3 | FN19: 7.94 | FO19: 0 | FP19: 13.2 | FQ19: 0 | FR19: 18.9 | FS19: 5 | FT19: 5.2 | FU19: 72.54
A20: 04/11/2025 | B20: 05:00 | C20: 203.8 | D20: 596.8 | E20: 204.7 | H20: 90.1 | I20: 195.1 | L20: 177.5 | M20: 176.9 | N20: 178.3 | O20: 266 | P20: 0 | R20: 266.4 | S20: 10.4 | X20: 154.2 | Y20: 7.6 | Z20: 6 | AA20: 5.7 | AB20: 7 | AC20: 13.8 | AD20: 50.3 | AI20: 110.9 | AJ20: 58.9 | AN20: 6.5 | AO20: 0 | AP20: 56.8 | AQ20: 141.5 | AR20: 29.6 | AS20: 17.4 | AT20: 18.8 | AU20: 83.6 | AY20: 108.7 | AZ20: 7.5 | BA20: 6.1 | BB20: 33.7 | BC20: 44.2 | BD20: 2 | BE20: 12 | BF20: 69.8 | BI20: 43 | BL20: 48.5 | BP20: 84 | BQ20: 176.7 | BR20: 174.4 | BS20: 200 | BT20: 272 | CA20: 0 | CC20: 3.6 | CD20: 110 | CE20: 78.8 | CF20: 64 | CG20: 47.7 | CH20: 30.1 | CL20: 116.9 | CM20: 0 | CN20: 54.2 | CS20: 0 | CT20: 216.5 | CU20: 103.9 | CV20: 0 | CW20: 88.3 | CX20: 0 | CY20: 0 | CZ20: 0 | DA20: 20 | DB20: 20.7 | DD20: 0 | DF20: 1 | DG20: 2.4 | DH20: 2.7 | DJ20: 20 | DK20: 19.1 | DL20: 3.4 | DM20: 18.6 | DN20: 0.1 | DO20: 0 | DP20: 27.5 | DQ20: 68.3 | DR20: 0 | DS20: 3.4 | DT20: 12.1 | DU20: 2.2 | DW20: 12.4 | DX20: 6.8 | DY20: 11.9 | DZ20: 14.1 | EA20: 15.8 | EB20: 26.8 | EC20: 28.9 | ED20: 0 | EE20: 73.7 | EF20: 82.3 | EG20: 4.8 | EH20: 6 | EI20: 20 | EJ20: 7.6 | EK20: 7.2 | EL20: 20.4 | EM20: 20.4 | EN20: 20 | EO20: 0 | EQ20: 0 | ER20: 0 | ES20: 0.6 | ET20: 50.6 | EU20: 58.8 | EV20: 0 | EW20: 0.7 | EY20: 1 | EZ20: 0.7 | FA20: 0 | FB20: 6.4 | FC20: 18.7 | FD20: 7.5 | FE20: 28.3 | FF20: 35.3 | FG20: 16 | FH20: 18 | FI20: 0 | FJ20: 11.1 | FK20: 6185.5 | FM20: 22.3 | FN20: 7.94 | FO20: 0 | FP20: 13.2 | FQ20: 0 | FR20: 18.9 | FS20: 4.9 | FT20: 5.3 | FU20: 72.54
A21: 04/11/2025 | B21: 05:30 | C21: 203.5 | D21: 599.5 | E21: 210.4 | H21: 90 | I21: 195.4 | L21: 173.6 | M21: 174.3 | N21: 174.1 | O21: 259.9 | P21: 0 | R21: 358.6 | S21: 10.4 | X21: 154.7 | Y21: 7.4 | Z21: 5.9 | AA21: 5.6 | AB21: 6.9 | AC21: 12.6 | AD21: 50.7 | AI21: 110.8 | AJ21: 59.4 | AN21: 6.5 | AO21: 0 | AP21: 57 | AQ21: 141 | AR21: 29.4 | AS21: 17.4 | AT21: 18.8 | AU21: 84.7 | AY21: 108.3 | AZ21: 7.5 | BA21: 6.2 | BB21: 32.3 | BC21: 45.1 | BD21: 2 | BE21: 11.9 | BF21: 69.1 | BI21: 42.5 | BL21: 48.5 | BP21: 84 | BQ21: 176.6 | BR21: 174.4 | BS21: 200 | BT21: 271.6 | CA21: 0 | CC21: 3.6 | CD21: 104.2 | CE21: 83.9 | CF21: 63.9 | CG21: 47.5 | CH21: 29.9 | CL21: 116.9 | CM21: 30 | CN21: 57.7 | CS21: 0 | CT21: 216.2 | CU21: 103.6 | CV21: 0 | CW21: 92.8 | CX21: 3.5 | CY21: 0 | CZ21: 0 | DA21: 20 | DB21: 20.7 | DD21: 0 | DF21: 1 | DG21: 2.4 | DH21: 2.8 | DJ21: 20 | DK21: 18.9 | DL21: 3.4 | DM21: 18.6 | DN21: 0.5 | DO21: 0.9 | DP21: 29.1 | DQ21: 59.3 | DR21: 0.1 | DS21: 3.3 | DT21: 10.1 | DU21: 2.2 | DW21: 12.4 | DX21: 6.8 | DY21: 12 | DZ21: 14 | EA21: 15.8 | EB21: 24.8 | EC21: 33.2 | ED21: 1 | EE21: 76.3 | EF21: 74 | EG21: 5.7 | EH21: 6.4 | EI21: 19.7 | EJ21: 7.5 | EK21: 7.3 | EL21: 20.4 | EM21: 20.4 | EN21: 20 | EO21: 0 | EQ21: 0 | ER21: 5.8 | ES21: 0.6 | ET21: 42.6 | EU21: 49.7 | EV21: 5 | EW21: 0.7 | EY21: 1 | EZ21: 0.7 | FA21: 0 | FB21: 6.4 | FC21: 18.7 | FD21: 8.1 | FE21: 28.3 | FF21: 35.3 | FG21: 16 | FH21: 19.1 | FI21: 0 | FJ21: 11 | FK21: 6292.2 | FM21: 22.3 | FN21: 7.95 | FO21: 0 | FP21: 13.2 | FQ21: 0 | FR21: 18.9 | FS21: 4.9 | FT21: 5.2 | FU21: 72.45
A22: 04/11/2025 | B22: 06:00 | C22: 206.4 | D22: 631.4 | E22: 216.5 | H22: 91.5 | I22: 205.2 | L22: 142 | M22: 141.6 | N22: 141.9 | O22: 237.4 | P22: 0 | R22: 263.9 | S22: 10.5 | X22: 167 | Y22: 7.9 | Z22: 5.8 | AA22: 5.6 | AB22: 6.9 | AC22: 12.5 | AD22: 50.1 | AI22: 110.8 | AJ22: 51.4 | AN22: 6.4 | AO22: 0 | AP22: 56.9 | AQ22: 143.1 | AR22: 33.8 | AS22: 17.2 | AT22: 18.8 | AU22: 88.3 | AY22: 109.1 | AZ22: 7.5 | BA22: 6 | BB22: 24.3 | BC22: 45.1 | BD22: 2 | BE22: 12.3 | BF22: 72.6 | BI22: 44 | BL22: 48.4 | BP22: 84.8 | BQ22: 175.5 | BR22: 173.2 | BS22: 200 | BT22: 271.8 | CA22: 0 | CC22: 3.6 | CD22: 85.5 | CE22: 81.6 | CF22: 64.9 | CG22: 47.4 | CH22: 30.4 | CL22: 116.4 | CM22: 29.4 | CN22: 57.2 | CS22: 0 | CT22: 216.4 | CU22: 103.8 | CV22: 0 | CW22: 97.1 | CX22: 26.4 | CY22: 0 | CZ22: 0 | DA22: 20 | DB22: 20.9 | DD22: 0 | DF22: 1.1 | DG22: 2.4 | DH22: 3 | DJ22: 20 | DK22: 18.9 | DL22: 3.4 | DM22: 18.6 | DN22: 1.2 | DO22: 1.3 | DP22: 28.8 | DQ22: 75.3 | DR22: 0.8 | DS22: 3.3 | DT22: 9.9 | DU22: 2.1 | DW22: 12.4 | DX22: 6.8 | DY22: 11.8 | DZ22: 14.2 | EA22: 15.5 | EB22: 25.8 | EC22: 24.6 | ED22: 6.2 | EE22: 58.4 | EF22: 69.3 | EG22: 5.5 | EH22: 4.6 | EI22: 19.7 | EJ22: 7.5 | EK22: 7.3 | EL22: 20.4 | EM22: 20.4 | EN22: 20 | EO22: 0 | EQ22: 1 | ER22: 42.1 | ES22: 0.6 | ET22: 41.1 | EU22: 50.6 | EV22: 35.4 | EW22: 0.7 | EY22: 1 | EZ22: 0.7 | FA22: 1 | FB22: 6.4 | FC22: 18.4 | FD22: 8.2 | FE22: 28.2 | FF22: 35.2 | FG22: 16.1 | FH22: 19.4 | FI22: 0 | FJ22: 11 | FK22: 6206 | FM22: 22.3 | FN22: 7.95 | FO22: 0 | FP22: 13.2 | FQ22: 0 | FR22: 18.3 | FS22: 4.8 | FT22: 5.2 | FU22: 71.75
... A58: 05/11/2025 | B58: 00:00 | C58: 200.7 | D58: 615.5 | E58: 212.1 | H58: 90.2 | I58: 191 | L58: 108.3 | M58: 108.7 | N58: 108.7 | O58: 214.5 | P58: 0 | R58: 337.4 | S58: 5.9 | X58: 147.9 | Y58: 6.9 | Z58: 6 | AA58: 5.6 | AB58: 6.9 | AC58: 14.4 | AD58: 88.4 | AI58: 109.9 | AJ58: 50.6 | AN58: 6.4 | AO58: 146.1 | AP58: 52.1 | AQ58: 149.6 | AR58: 27.7 | AS58: 18.4 | AT58: 18.8 | AU58: 79.1 | AY58: 106.6 | AZ58: 7.4 | BA58: 6 | BB58: 33.5 | BC58: 42.6 | BD58: 2 | BE58: 11.7 | BF58: 64.1 | BI58: 76.7 | BL58: 0 | BP58: 83.6 | BQ58: 175.3 | BR58: 173.1 | BS58: 200 | BT58: 271.8 | CA58: 0 | CC58: 3.9 | CD58: 122.2 | CE58: 67.6 | CF58: 63.1 | CG58: 47.1 | CH58: 29.6 | CL58: 145.3 | CM58: 146.9 | CN58: 148.1 | CS58: 0 | CT58: 216.4 | CU58: 103.6 | CV58: 0 | CW58: 90.8 | CX58: 0 | CY58: 0 | CZ58: 0 | DA58: 17.4 | DB58: 20.5 | DD58: 0 | DF58: 1 | DG58: 3.3 | DH58: 2.8 | DJ58: 20 | DK58: 18.9 | DL58: 3.5 | DM58: 18.6 | DN58: 0 | DO58: 0 | DP58: 30.2 | DQ58: 84.4 | DR58: 0 | DS58: 3.2 | DT58: 18.9 | DU58: 2.7 | DW58: 10.9 | DX58: 9.2 | DY58: 10.1 | DZ58: 14.6 | EA58: 15.7 | EB58: 12.9 | EC58: 68.2 | ED58: 0 | EE58: 47.8 | EF58: 90.1 | EG58: 4 | EH58: 2.5 | EI58: 20.9 | EJ58: 7.6 | EK58: 7.6 | EL58: 18.9 | EM58: 19.8 | EN58: 19.8 | EO58: 0 | EQ58: 0 | ER58: 0 | ES58: 0.6 | ET58: 8.7 | EU58: 7 | EV58: 0 | EW58: 1.1 | EY58: 1.8 | EZ58: 1 | FA58: 0 | FB58: 6 | FC58: 18.6 | FD58: 8.6 | FE58: 26.93 | FF58: 33.39 | FG58: 15 | FH58: 0 | FI58: 7 | FJ58: 11 | FK58: 6339.52 | FM58: 11.4 | FN58: 7.96 | FO58: 5.2 | FP58: 13.2 | FQ58: 27 | FR58: 18.9 | FS58: 4.2 | FT58: 5.3 | FU58: 93.16
A59: EJEC | C59: 4879.05 | D59: 14980.1 | E59: 5131.35 | F59: 0 | G59: 0 | H59: 2161.5 | I59: 4588.85 | J59: 0 | K59: 0 | L59: 3636.15 | M59: 3634.65 | N59: 3632.35 | O59: 5904 | P59: 173.4 | Q59: 0 | R59: 7358.5 | S59: 170.8 | T59: 0 | U59: 0 | V59: 0 | W59: 0 | X59: 3689.8 | Y59: 178.55 | Z59: 140.75 | AA59: 134.8 | AB59: 165.7 | AC59: 271.55 | AD59: 1917.15 | AE59: 0 | AF59: 0 | AG59: 0 | AH59: 0 | AI59: 2653.55 | AJ59: 2741.65 | AK59: 0 | AL59: 0 | AM59: 0 | AN59: 155.65 | AO59: 4484.55 | AP59: 1199.85 | AQ59: 3360.35 | AR59: 694.2 | AS59: 404.4 | AT59: 451.2 | AU59: 2005.55 | AV59: 0 | AW59: 0 | AX59: 0 | AY59: 2594 | AZ59: 179.85 | BA59: 145.9 | BB59: 698.8 | BC59: 1047.55 | BD59: 48 | BE59: 424.55 | BF59: 1668.7 | BG59: 0 | BH59: 0 | BI59: 1579.75 | BJ59: 0 | BK59: 0 | BL59: 641.6 | BM59: 0 | BN59: 0 | BO59: 0 | BP59: 2021.7 | BQ59: 4160.55 | BR59: 4109.8 | BS59: 4767.8 | BT59: 6429.85 | BU59: 0 | BV59: 0 | BW59: 0 | BX59: 0 | BY59: 0 | BZ59: 0 | CA59: 0.9 | CB59: 0 | CC59: 87.7 | CD59: 3330.6 | CE59: 1738.05 | CF59: 1537.65 | CG59: 1106.65 | CH59: 710.25 | CI59: 0 | CJ59: 0 | CK59: 0 | CL59: 2839.9 | CM59: 2575.5 | CN59: 2687.15 | CO59: 0 | CP59: 0 | CQ59: 0 | CR59: 0 | CS59: 370.8 | CT59: 5157.55 | CU59: 2466.6 | CV59: 6.75 | CW59: 2469.25 | CX59: 755 | CY59: 21.35 | CZ59: 2.9 | DA59: 478.3 | DB59: 496.65 | DC59: 0 | DD59: 2.35 | DE59: 0 | DF59: 26.75 | DG59: 70.65 | DH59: 68.7 | DI59: 0 | DJ59: 480 | DK59: 451.35 | DL59: 81.75 | DM59: 446.4 | DN59: 139.45 | DO59: 172.9 | DP59: 712.2 | DQ59: 1987.9 | DR59: 160.55 | DS59: 77.25 | DT59: 373.4 | DU59: 57.1 | DV59: 0 | DW59: 281.55 | DX59: 174.35 | DY59: 225.5 | DZ59: 355.55 | EA59: 372.15 | EB59: 389.35 | EC59: 1370.75 | ED59: 309.55 | EE59: 915.95 | EF59: 2000.05 | EG59: 77.45 | EH59: 181.45 | EI59: 492.5 | EJ59: 181.9 | EK59: 175.5 | EL59: 479.85 | EM59: 486.95 | EN59: 478.4 | EO59: 29.2 | EP59: 0 | EQ59: 130.85 | ER59: 1431.4 | ES59: 14.4 | ET59: 1974.8 | EU59: 2393.15 | EV59: 1061.8 | EW59: 23.95 | EX59: 0 | EY59: 40.45 | EZ59: 22.5 | FA59: 125.25 | FB59: 150.25 | FC59: 446.75 | FD59: 203.35 | FE59: 666.535 | FF59: 832.73 | FG59: 342.3 | FH59: 386.35 | FI59: 70.95 | FJ59: 261.35 | FK59: 165123.61 | FM59: 335.45 | FN59: 166.98 | FO59: 2.6 | FP59: 316.8 | FQ59: 399.25 | FR59: 453.3 | FS59: 102.15 | FT59: 190.55 | FU59: 1967.08

Sheet REACTIVA
B3: martes, 4 de Noviembre del 2025
A5: POTENCIA REACTIVA EJECUTADA DE LAS UNIDADES DE GENERACIÓN DEL COES (MVAR) | FM5: CENTRALES NO INTEGRANTES COES
A6: FECHA | B6: HORA | C6: 65333 | D6: 101 | E6: 102 | F6: 42667 | G6: 42668 | H6: 126 | I6: 127 | J6: 138 | K6: 139 | L6: 197 | M6: 203 | N6: 204 | O6: 230 | P6: 209 | Q6: 56677 | R6: 796 | S6: 2146 | T6: 142 | U6: 143 | V6: 125 | W6: 187 | X6: 163 | Y6: 298 | Z6: 299 | AA6: 219 | AB6: 151 | AC6: 152 | AD6: 153 | AE6: 154 | AF6: 756 | AG6: 156 | AH6: 155 | AI6: 182 | AJ6: 212 | AK6: 758 | AL6: 263 | AM6: 265 | AN6: 775 | AO6: 777 | AP6: 2154 | AQ6: 150 | AR6: 149 | AS6: 188 | AT6: 2131 | AU6: 755 | AV6: 252 | AW6: 249 | AX6: 250 | AY6: 117 | AZ6: 267 | BA6: 268 | BB6: 119 | BC6: 120 | BD6: 189 | BE6: 122 | BF6: 266 | BG6: 337 | BH6: 338 | BI6: 251 | BJ6: 115 | BK6: 239 | BL6: 288 | BM6: 240 | BN6: 241 | BO6: 242 | BP6: 191 | BQ6: 194 | BR6: 196 | BS6: 207 | BT6: 236 | BU6: 795 | BV6: 285 | BW6: 995 | BX6: 996 | BY6: 997 | BZ6: 766 | CA6: 926 | CB6: 924 | CC6: 121 | CD6: 103 | CE6: 104 | CF6: 106 | CG6: 105 | CH6: 107 | CI6: 110 | CJ6: 109 | CK6: 144 | CL6: 113 | CM6: 114 | CN6: 193 | CO6: 208 | CP6: 786 | CQ6: 787 | CR6: 788 | CS6: 789 | CT6: 248 | CU6: 2159 | CV6: 303 | CW6: 59715 | CX6: 62255 | CY6: 1263 | CZ6: 61800 | DA6: 2194 | DB6: 69125 | DC6: 216 | DD6: 198 | DE6: 70400 | DF6: 49607 | DG6: 214 | DH6: 260 | DI6: 2152 | DJ6: 2128 | DK6: 247 | DL6: 228 | DM6: 2135 | DN6: 261 | DO6: 237 | DP6: 253 | DQ6: 770 | DR6: 235 | DS6: 238 | DT6: 2184 | DU6: 61855 | DV6: 223 | DW6: 226 | DX6: 201 | DY6: 258 | DZ6: 259 | EA6: 920 | EB6: 257 | EC6: 256 | ED6: 2148 | EE6: 58288 | EF6: 58289 | EG6: 58839 | EH6: 58840 | EI6: 296 | EJ6: 297 | EK6: 211 | EL6: 2175 | EM6: 2178 | EN6: 2181 | EO6: 1262 | EP6: 63425 | EQ6: 233 | ER6: 2150 | ES6: 2165 | ET6: 2161 | EU6: 61197 | EV6: 58851 | EW6: 225 | EX6: 2201 | EY6: 2171 | EZ6: 760 | FA6: 234 | FB6: 215 | FC6: 917 | FD6: 289 | FE6: 58333 | FF6: 58336 | FG6: 213 | FH6: 232 | FI6: 2190 | FJ6: 69867 | FK6: TOTAL COES | FM6: 221 | FN6: 222 | FO6: 224 | FP6: 2187 | FQ6: 227 | FR6: 49400 | FS6: 199 | FT6: 200 | FU6: TOTAL NO COES
C7: SUR | D7: CENTRO | E7: CENTRO | F7: NORTE | G7: NORTE | H7: NORTE | I7: NORTE | J7: CENTRO | K7: CENTRO | L7: CENTRO | M7: CENTRO | N7: CENTRO | O7: CENTRO | P7: CENTRO | Q7: CENTRO | R7: CENTRO | S7: CENTRO | T7: CENTRO | U7: CENTRO | V7: CENTRO | W7: CENTRO | X7: SUR | Y7: SUR | Z7: SUR | AA7: CENTRO | AB7: SUR | AC7: SUR | AD7: SUR | AE7: SUR | AF7: SUR | AG7: SUR | AH7: SUR | AI7: SUR | AJ7: CENTRO | AK7: NORTE | AL7: NORTE | AM7: NORTE | AN7: CENTRO | AO7: CENTRO | AP7: CENTRO | AQ7: CENTRO | AR7: CENTRO | AS7: CENTRO | AT7: CENTRO | AU7: SUR | AV7: CENTRO | AW7: CENTRO | AX7: CENTRO | AY7: CENTRO | AZ7: CENTRO | BA7: CENTRO | BB7: CENTRO | BC7: CENTRO | BD7: SUR | BE7: NORTE | BF7: CENTRO | BG7: CENTRO | BH7: CENTRO | BI7: CENTRO | BJ7: NORTE | BK7: NORTE | BL7: NORTE | BM7: SUR | BN7: SUR | BO7: SUR | BP7: CENTRO | BQ7: CENTRO | BR7: CENTRO | BS7: CENTRO | BT7: CENTRO | BU7: CENTRO | BV7: CENTRO | BW7: SUR | BX7: SUR | BY7: SUR | BZ7: NORTE | CA7: SUR | CB7: CENTRO | CC7: NORTE | CD7: CENTRO | CE7: CENTRO | CF7: CENTRO | CG7: CENTRO | CH7: CENTRO | CI7: CENTRO | CJ7: CENTRO | CK7: CENTRO | CL7: CENTRO | CM7: CENTRO | CN7: CENTRO | CO7: CENTRO | CP7: SUR | CQ7: SUR | CR7: SUR | CS7: SUR | CT7: CENTRO | CU7: CENTRO | CV7: CENTRO | CW7: CENTRO | CX7: SUR | CY7: NORTE | CZ7: NORTE | DA7: NORTE | DB7: CENTRO | DC7: NORTE | DD7: NORTE | DE7: SUR | DF7: SUR | DG7: CENTRO | DH7: CENTRO | DI7: CENTRO | DJ7: NORTE | DK7: NORTE | DL7: CENTRO | DM7: CENTRO | DN7: SUR | DO7: SUR | DP7: CENTRO | DQ7: CENTRO | DR7: SUR | DS7: CENTRO | DT7: CENTRO | DU7: NORTE | DV7: CENTRO | DW7: CENTRO | DX7: NORTE | DY7: CENTRO | DZ7: CENTRO | EA7: CENTRO | EB7: NORTE | EC7: NORTE | ED7: SUR | EE7: CENTRO | EF7: CENTRO | EG7: CENTRO | EH7: CENTRO | EI7: CENTRO | EJ7: CENTRO | EK7: SUR | EL7: SUR | EM7: SUR | EN7: SUR | EO7: NORTE | EP7: SUR | EQ7: SUR | ER7: SUR | ES7: CENTRO | ET7: CENTRO | EU7: CENTRO | EV7: SUR | EW7: CENTRO | EX7: CENTRO | EY7: CENTRO | EZ7: CENTRO | FA7: SUR | FB7: NORTE | FC7: CENTRO | FD7: NORTE | FE7: NORTE | FF7: NORTE | FG7: CENTRO | FH7: NORTE | FI7: NORTE | FJ7: NORTE | FM7: NORTE | FN7: CENTRO | FO7: NORTE | FP7: NORTE | FQ7: NORTE | FR7: NORTE | FS7: NORTE | FT7: NORTE
C8: HIDROELÉCTRICA | D8: HIDROELÉCTRICA | E8: HIDROELÉCTRICA | F8: TERMOELÉCTRICA | G8: TERMOELÉCTRICA | H8: HIDROELÉCTRICA | I8: HIDROELÉCTRICA | J8: TERMOELÉCTRICA | K8: TERMOELÉCTRICA | L8: TERMOELÉCTRICA | M8: TERMOELÉCTRICA | N8: TERMOELÉCTRICA | O8: TERMOELÉCTRICA | P8: TERMOELÉCTRICA | Q8: TERMOELÉCTRICA | R8: HIDROELÉCTRICA | S8: HIDROELÉCTRICA | T8: TERMOELÉCTRICA | U8: TERMOELÉCTRICA | V8: TERMOELÉCTRICA | W8: TERMOELÉCTRICA | X8: HIDROELÉCTRICA | Y8: HIDROELÉCTRICA | Z8: HIDROELÉCTRICA | AA8: TERMOELÉCTRICA | AB8: HIDROELÉCTRICA | AC8: HIDROELÉCTRICA | AD8: HIDROELÉCTRICA | AE8: HIDROELÉCTRICA | AF8: TERMOELÉCTRICA | AG8: TERMOELÉCTRICA | AH8: TERMOELÉCTRICA | AI8: HIDROELÉCTRICA | AJ8: HIDROELÉCTRICA | AK8: TERMOELÉCTRICA | AL8: TERMOELÉCTRICA | AM8: TERMOELÉCTRICA | AN8: HIDROELÉCTRICA | AO8: HIDROELÉCTRICA | AP8: HIDROELÉCTRICA | AQ8: HIDROELÉCTRICA | AR8: HIDROELÉCTRICA | AS8: HIDROELÉCTRICA | AT8: HIDROELÉCTRICA | AU8: HIDROELÉCTRICA | AV8: TERMOELÉCTRICA | AW8: TERMOELÉCTRICA | AX8: TERMOELÉCTRICA | AY8: HIDROELÉCTRICA | AZ8: HIDROELÉCTRICA | BA8: HIDROELÉCTRICA | BB8: HIDROELÉCTRICA | BC8: HIDROELÉCTRICA | BD8: HIDROELÉCTRICA | BE8: HIDROELÉCTRICA | BF8: HIDROELÉCTRICA | BG8: HIDROELÉCTRICA | BH8: HIDROELÉCTRICA | BI8: HIDROELÉCTRICA | BJ8: TERMOELÉCTRICA | BK8: TERMOELÉCTRICA | BL8: TERMOELÉCTRICA | BM8: TERMOELÉCTRICA | BN8: TERMOELÉCTRICA | BO8: TERMOELÉCTRICA | BP8: HIDROELÉCTRICA | BQ8: TERMOELÉCTRICA | BR8: TERMOELÉCTRICA | BS8: TERMOELÉCTRICA | BT8: TERMOELÉCTRICA | BU8: TERMOELÉCTRICA | BV8: TERMOELÉCTRICA | BW8: TERMOELÉCTRICA | BX8: TERMOELÉCTRICA | BY8: TERMOELÉCTRICA | BZ8: HIDROELÉCTRICA | CA8: TERMOELÉCTRICA | CB8: TERMOELÉCTRICA | CC8: HIDROELÉCTRICA | CD8: HIDROELÉCTRICA | CE8: HIDROELÉCTRICA | CF8: HIDROELÉCTRICA | CG8: HIDROELÉCTRICA | CH8: HIDROELÉCTRICA | CI8: TERMOELÉCTRICA | CJ8: TERMOELÉCTRICA | CK8: TERMOELÉCTRICA | CL8: TERMOELÉCTRICA | CM8: TERMOELÉCTRICA | CN8: TERMOELÉCTRICA | CO8: TERMOELÉCTRICA | CP8: TERMOELÉCTRICA | CQ8: TERMOELÉCTRICA | CR8: TERMOELÉCTRICA | CS8: TERMOELÉCTRICA | CT8: TERMOELÉCTRICA | CU8: TERMOELÉCTRICA | CV8: SOLAR | CW8: EÓLICA | CX8: SOLAR | CY8: EÓLICA | CZ8: SOLAR | DA8: HIDROELÉCTRICA | DB8: HIDROELÉCTRICA | DC8: HIDROELÉCTRICA | DD8: HIDROELÉCTRICA | DE8: SOLAR | DF8: HIDROELÉCTRICA | DG8: HIDROELÉCTRICA | DH8: HIDROELÉCTRICA | DI8: HIDROELÉCTRICA | DJ8: HIDROELÉCTRICA | DK8: HIDROELÉCTRICA | DL8: HIDROELÉCTRICA | DM8: HIDROELÉCTRICA | DN8: SOLAR | DO8: SOLAR | DP8: EÓLICA | DQ8: EÓLICA | DR8: SOLAR | DS8: HIDROELÉCTRICA | DT8: HIDROELÉCTRICA | DU8: HIDROELÉCTRICA | DV8: HIDROELÉCTRICA | DW8: HIDROELÉCTRICA | DX8: HIDROELÉCTRICA | DY8: HIDROELÉCTRICA | DZ8: HIDROELÉCTRICA | EA8: HIDROELÉCTRICA | EB8: EÓLICA | EC8: EÓLICA | ED8: SOLAR | EE8: EÓLICA | EF8: EÓLICA | EG8: EÓLICA | EH8: EÓLICA | EI8: HIDROELÉCTRICA | EJ8: HIDROELÉCTRICA | EK8: HIDROELÉCTRICA | EL8: HIDROELÉCTRICA | EM8: HIDROELÉCTRICA | EN8: HIDROELÉCTRICA | EO8: EÓLICA | EP8: SOLAR | EQ8: SOLAR | ER8: SOLAR | ES8: HIDROELÉCTRICA | ET8: EÓLICA | EU8: EÓLICA | EV8: SOLAR | EW8: TERMOELÉCTRICA | EX8: TERMOELÉCTRICA | EY8: TERMOELÉCTRICA | EZ8: TERMOELÉCTRICA | FA8: SOLAR | FB8: HIDROELÉCTRICA | FC8: HIDROELÉCTRICA | FD8: TERMOELÉCTRICA | FE8: TERMOELÉCTRICA | FF8: TERMOELÉCTRICA | FG8: TERMOELÉCTRICA | FH8: TERMOELÉCTRICA | FI8: TERMOELÉCTRICA | FJ8: TERMOELÉCTRICA | FM8: HIDROELÉCTRICA | FN8: HIDROELÉCTRICA | FO8: HIDROELÉCTRICA | FP8: HIDROELÉCTRICA | FQ8: TERMOELÉCTRICA | FR8: TERMOELÉCTRICA | FS8: HIDROELÉCTRICA | FT8: HIDROELÉCTRICA
