Workbook

Sheet EVENTOS
B3: sábado, 27 de Diciembre del 2025
B5: INFORMACIÓN DE EVENTOS PRINCIPALES EN SUS INSTALACIONES
B6: TIPO DE EVENTO | C6: EMPRESA | D6: UBICACIÓN | E6: TIPO DE EQUIPO | F6: EQUIPO | G6: INICIO | H6: FINAL | I6: DESCRIPCIÓN | J6: MW INDISP. | K6: INTERRUPCIÓN (SI/NO) | L6: TENSIÓN DE FALLA (kV)
B7: EVENTO | C7: ELECTRO ORIENTE | D7: BELAUNDE TERRY - TARAPOTO | E7: LINEA DE TRANSMISION | F7: L-1018 | G7: 27/12/2025 11:06:00 | H7: 27/12/2025 12:01:00 | I7: DECLARACIÓN DE SITUACIÓN EXCEPCIONAL EN LA LÍNEA L-1018 (BELAUNDE TERRY - TARAPOTO) DE 138 kV | K7: NO
B8: EVENTO | C8: ELECTRO ORIENTE | D8: BELAUNDE TERRY - TARAPOTO | E8: LINEA DE TRANSMISION | F8: L-1018 | G8: 27/12/2025 18:24:00 | H8: 27/12/2025 20:40:00 | I8: DECLARACIÓN DE SITUACIÓN EXCEPCIONAL EN LA LÍNEA L-1018 (BELAUNDE TERRY - TARAPOTO) DE 138 kV | K8: NO
B9: FALLA | C9: ISA PERU | D9: CHIMBOTE 1 | E9: TRANSFORMADOR 3D | F9: AT30-211 | G9: 27/12/2025 21:52:00 | H9: 28/12/2025 00:00:00 | I9: DESCONEXION DEL TRANSFORMADOR AT-30 DE LA S.E. CHIMBOTE 1 | K9: NO | L9: 220

Sheet RESTRIC_OPE
B3: sábado, 27 de Diciembre del 2025
B5: RESTRICCIONES OPERATIVAS
B6: FECHA | C6: HORA INICIO | D6: HORA FINAL | E6: EMPRESA | F6: UBICACIÓN | G6: T.Eq. | H6: EQUIPO | I6: DESCRIPCIÓN
B7: 27/12/2025 | C7: 00:00 | D7: 24:00 | E7: CELEPSA | F7: C.H. EL PLATANAL | G7: CH | H7: CENTRAL | I7: De acuerdo con el correo del 13/10/2025. Debido a problemas en el control de la compuerta de bocatoma, informaron que el servicio de RSF queda indisponible.
B8: 27/12/2025 | C8: 00:00 | D8: 24:00 | E8: EGASA | F8: S.E. CONVERTIDOR | G8: BARRA | H8: BARRA138KV | I8: EGASA limitó la capacidad del transformador 138 kV/33 kV a 50 MVA por deterioro del aislamiento.
B9: 27/12/2025 | C9: 00:00 | D9: 24:00 | E9: ELECTROPERU | F9: C.H. MANTARO | G9: CH | H9: CENTRAL | I9: De acuerdo con el correo del día 25.08.2025, la central tiene una limitación de potencia máxima de 650 MW por seguridad de la central.
B10: 27/12/2025 | C10: 00:00 | D10: 24:00 | E10: ENEL GENERACION PIURA S.A. | F10: C.T. MALACAS | G10: CT | H10: CENTRAL | I10: De acuerdo con la comunicación vía correo del día 24.10.2024. ENEL GENERACIÓN PIURA informa una restricción de potencia para alcanzar 105 MW en simultaneo (TG6+TGN4).
B11: 27/12/2025 | C11: 00:00 | D11: 24:00 | E11: ENEL GENERACION PIURA S.A. | F11: C.T. MALACAS | G11: GT | H11: TG4 | I11: De acuerdo a lo informado mediante correo electrónico el día 25.10, con la disponibilidad actual de aproximadamente 13 MMPCD (368.12 Mm³) la unidad TG4 puede con una generación de 80 MW durante 5 horas, y a potencia mínima durante el resto de los periodos
B12: 27/12/2025 | C12: 00:00 | D12: 24:00 | E12: ENGIE ENERGIA PERU S.A.A. | F12: C.H. YUNCÁN | G12: GH | H12: G3 | I12: Según la carta N° ENG/ 198-2024 enviada por su representada, se opera de forma continua el G3 de la CH Yuncán, debido a la ejecución de mantenimientos necesarios para evitar daños en los sellos de seguridad de la válvula esférica del grupo.
B13: 27/12/2025 | C13: 00:00 | D13: 24:00 | E13: ENGIE ENERGIA PERU S.A.A. | F13: C.T. CHILCA 1 | G13: CT | H13: CENTRAL | I13: Restricción de temperatura de la C.T Chilca, ver valor en el modelo de despacho.
B14: 27/12/2025 | C14: 00:00 | D14: 24:00 | E14: ENGIE ENERGIA PERU S.A.A. | F14: C.T. CHILCA 1 | G14: CT | H14: CENTRAL | I14: Con carta ENG/971-2023, indica que no puede cumplir con las IO considerada en el PDO_17122023 dado que vulneran la seguridad de sus activos. Indican que se debe tomar TMO=168h.
B15: 27/12/2025 | C15: 00:00 | D15: 24:00 | E15: ENGIE ENERGIA PERU S.A.A. | F15: C.T. CHILCA 2 | G15: CT | H15: CENTRAL | I15: Con carta ENG/971-2023, indica que no puede cumplir con las IO considerada en el PDO_17122023 dado que vulneran la seguridad de sus activos. Indican que se debe tomar TMO=168h.
B16: 27/12/2025 | C16: 00:00 | D16: 24:00 | E16: FENIX POWER PERÚ | F16: C.T. FENIX | G16: CT | H16: CENTRAL | I16: De acuerdo con lo comunicado en el correo del día 06.05.2025, la CT Fenix cuenta con TMO de 168 hrs en todos sus modos de operación.
B17: 27/12/2025 | C17: 00:00 | D17: 24:00 | E17: KALLPA GENERACION S.A. | F17: C.H. CERRO DEL AGUILA | G17: GH | H17: G1 | I17: De acuerdo a lo informado el día 17/11 por la empresa KALLPA, el G1 tiene un TA = 15min
... B54: 27/12/2025 | C54: 00:00 | D54: 24:00 | E54: TERMOSELVA | F54: C.T. AGUAYTÍA | G54: CT | H54: CENTRAL | I54: Disponibilidad de 12 MMSCF para la CT Aguaytía.

Sheet MANTENIMIENTO EJECUTADOS
B3: sábado, 27 de Diciembre del 2025
B5: Mantenimiento Ejecutado
B6: Empresa | C6: Ubicación | D6: Equipo | E6: Inicio | F6: Final | G6: Descripción | H6: MW Indisp. | I6: Prog. | J6: Dispon | K6: Interrupc. | L6: Tipo | M6: CodEq | N6: TipoEq_Osinerg
B7: AGRO INDUSTRIAL PARAMONGA S.A. | C7: PARAMONGA | D7: TV-01 | E7: 27/12/2025 00:00 | F7: 28/12/2025 00:00 | G7: LIMPIEZA E INSPECCION DE LA CALDERA CBS Y MANTENIMIENTO A SUS PERIFERICOS (CONDUCTORES, VENTILADORES, BOMBAS, MOTORES, ETC) | H7: 14 | I7: P | J7: F/S | K7: N | L7: PREV. | M7: 12664 | N7: G
B8: AGROAURORA S.A.C. | C8: MAPLE ETANOL | D8: CENTRAL | E8: 27/12/2025 00:00 | F8: 28/12/2025 00:00 | G8: CENTRAL TERMOELECTRICA FUERA DE SERVICIO POR REQUERMIENTOS DE FABRICA. | H8: 18 | I8: P | J8: F/S | K8: N | L8: OTROS | M8: 13417 | N8: G
B9: ATLANTICA TRANSMISION SUR S.A. | C9: OCONA | D9: INT-5450 | E9: 27/12/2025 00:00 | F9: 28/12/2025 00:00 | G9: Interruptor INT-5450 cerrado con restriccion operativa, REB-5450 en servicio y suministrando los SS.AA. de la S.E. Oco?a. | H9: 0 | I9: P | J9: E/S | K9: N | L9: OTROS | M9: 13761 | N9: T
B10: ATLANTICA TRANSMISION SUR S.A. | C10: POROMA | D10: REB-5350 | E10: 27/12/2025 00:00 | F10: 28/12/2025 00:00 | G10: Fuera de servicio po falla en el equipo. | H10: 0 | I10: P | J10: F/S | K10: N | L10: OTROS | M10: 13771 | N10: T
B11: ATN S.A. | C11: KIMAN AYLLU | D11: AUT-501 | E11: 27/12/2025 00:00 | F11: 28/12/2025 00:00 | G11: Restriccion Operativa en el circuito de control de cambiador de tap s del AUT-501 | H11: 0 | I11: P | J11: E/S | K11: N | L11: OTROS | M11: 13099 | N11: T
B12: ATRIA ENERGIA S.A.C. | C12: PURMACANA | D12: CENTRAL | E12: 27/12/2025 00:00 | F12: 28/12/2025 00:00 | G12: Mantenimiento correctivo de valvula principal | H12: 0.4 | I12: P | J12: F/S | K12: N | L12: CORR. | M12: 13132 | N12: G
B13: CASA GRANDE S.A.A. | C13: CASA GRANDE | D13: TV1 | E13: 27/12/2025 08:00 | F13: 27/12/2025 19:00 | G13: Ensayos de Potencia Efectiva y Rendimiento (EPEyR) y Ensayos de Potencia Minima (EPMin) en coordinacion con COES | H13: 0 | I13: P | J13: E/S | K13: N | L13: PRUEBA | M13: 26892 | N13: G
B14: CONELSUR LT SAC | C14: CALLAHUANCA (CNS) | D14: S.E. | E14: 27/12/2025 00:00 | F14: 28/12/2025 00:00 | G14: RELE DIFERENCIAL DE BARRAS DE CALLAHUANCA 220KV INOPERATIVO | H14: 0 | I14: P | J14: E/S | K14: N | L14: OTROS | M14: 316 | N14: T
B15: EGASA | C15: CHARCANI II | D15: G3 | E15: 27/12/2025 07:25 | F15: 27/12/2025 13:20 | G15: Mantenimiento Electromecanico Plan 3 | H15: 0.2 | I15: P | J15: F/S | K15: N | L15: PREV. | M15: 115 | N15: G
B16: EGASA | C16: SANTUARIO | D16: ACOPLE 138 | E16: 27/12/2025 00:00 | F16: 28/12/2025 00:00 | G16: En servicio barra 2,uso en grupo N1 Charcani V con interruptor de acoplamiento, por falla | H16: 0 | I16: P | J16: E/S | K16: N | L16: OTROS | M16: 11052 | N16: T
B17: EGESUR | C17: CT INDEPENDENCIA | D17: TR1 (Reserva) | E17: 27/12/2025 00:00 | F17: 28/12/2025 00:00 | G17: Transformador E/S con el Conmutador de Taps sin carga Deshabilitado | H17: 0 | I17: P | J17: E/S | K17: N | L17: OTROS | M17: 19961 | N17: T
B18: EGESUR | C18: INDEPENDENCIA | D18: T-30 | E18: 27/12/2025 00:00 | F18: 28/12/2025 00:00 | G18: Mantenimiento correctivo del transformador de potencia en reserva - DELCROSA | H18: 0 | I18: P | J18: F/S | K18: N | L18: CORR. | M18: 12592 | N18: T
... B85: TRANSMANTARO | C85: YARABAMBA | D85: CL-R-30 | E85: 27/12/2025 00:00 | F85: 28/12/2025 00:00 | G85: CL-R30 CON MANDO SINCRONIZADO ASOCIADO AL INTERRUPTOR IN-5147 INDISPONIBLE. EL 20.11.25 NO PUDO SER AJUSTADO DEBIDO A ANOMALIA EN LA CUCHILLA DE PUESTA A TIERRA ST-5027. | H85: 0 | I85: P | J85: E/S | K85: N | L85: OTROS | M85: 17424 | N85: T

Sheet INGRESO OC
A3: sábado, 27 de Diciembre del 2025
A5: INGRESO A OPERACIÓN COMERCIAL
A6: EMPRESA | B6: TIPO DE EQUIPO | C6: UBICACIÓN | D6: EQUIPO | E6: Fecha y hora de Ingreso a Operación Comercial

Sheet DESPACHO_EJECUTADO
B3: sábado, 27 de Diciembre del 2025
A5: POTENCIA ACTIVA EJECUTADA DE LAS UNIDADES DE GENERACIÓN DEL SEIN (MW) | FP5: CENTRALES NO INTEGRANTES COES
A6: FECHA | B6: HORA | C6: 65333 | D6: 101 | E6: 102 | F6: 42667 | G6: 42668 | H6: 126 | I6: 127 | J6: 138 | K6: 139 | L6: 197 | M6: 203 | N6: 204 | O6: 230 | P6: 209 | Q6: 56677 | R6: 796 | S6: 2146 | T6: 142 | U6: 143 | V6: 125 | W6: 187 | X6: 163 | Y6: 298 | Z6: 299 | AA6: 219 | AB6: 151 | AC6: 152 | AD6: 153 | AE6: 154 | AF6: 756 | AG6: 156 | AH6: 155 | AI6: 182 | AJ6: 212 | AK6: 758 | AL6: 263 | AM6: 265 | AN6: 775 | AO6: 777 | AP6: 2154 | AQ6: 150 | AR6: 149 | AS6: 188 | AT6: 2131 | AU6: 755 | AV6: 252 | AW6: 249 | AX6: 250 | AY6: 117 | AZ6: 119 | BA6: 120 | BB6: 189 | BC6: 122 | BD6: 266 | BE6: 337 | BF6: 338 | BG6: 251 | BH6: 115 | BI6: 239 | BJ6: 288 | BK6: 240 | BL6: 241 | BM6: 242 | BN6: 191 | BO6: 194 | BP6: 196 | BQ6: 207 | BR6: 236 | BS6: 795 | BT6: 285 | BU6: 995 | BV6: 996 | BW6: 997 | BX6: 766 | BY6: 926 | BZ6: 924 | CA6: 121 | CB6: 103 | CC6: 104 | CD6: 106 | CE6: 105 | CF6: 107 | CG6: 110 | CH6: 109 | CI6: 144 | CJ6: 113 | CK6: 114 | CL6: 193 | CM6: 208 | CN6: 786 | CO6: 787 | CP6: 788 | CQ6: 789 | CR6: 248 | CS6: 2159 | CT6: 267 | CU6: 268 | CV6: 2194 | CW6: 303 | CX6: 59715 | CY6: 62255 | CZ6: 1263 | DA6: 61800 | DB6: 69125 | DC6: 216 | DD6: 198 | DE6: 70400 | DF6: 49607 | DG6: 214 | DH6: 260 | DI6: 2152 | DJ6: 2128 | DK6: 247 | DL6: 228 | DM6: 2135 | DN6: 261 | DO6: 237 | DP6: 253 | DQ6: 770 | DR6: 235 | DS6: 238 | DT6: 2184 | DU6: 61855 | DV6: 223 | DW6: 75566 | DX6: 226 | DY6: 201 | DZ6: 258 | EA6: 259 | EB6: 920 | EC6: 257 | ED6: 256 | EE6: 2148 | EF6: 58288 | EG6: 58289 | EH6: 58839 | EI6: 58840 | EJ6: 75260 | EK6: 296 | EL6: 297 | EM6: 211 | EN6: 2175 | EO6: 2178 | EP6: 2181 | EQ6: 1262 | ER6: 63425 | ES6: 233 | ET6: 2150 | EU6: 2165 | EV6: 2161 | EW6: 61197 | EX6: 58851 | EY6: 225 | EZ6: 2201 | FA6: 2171 | FB6: 760 | FC6: 234 | FD6: 215 | FE6: 917 | FF6: 289 | FG6: 58333 | FH6: 58336 | FI6: 213 | FJ6: 232 | FK6: 2190 | FL6: 69867 | FM6: 75066 | FN6: TOTAL COES | FP6: 221 | FQ6: 222 | FR6: 224 | FS6: 2187 | FT6: 227 | FU6: 49400 | FV6: 199 | FW6: 200 | FX6: TOTAL NO COES
C7: SUR | D7: CENTRO | E7: CENTRO | F7: NORTE | G7: NORTE | H7: NORTE | I7: NORTE | J7: CENTRO | K7: CENTRO | L7: CENTRO | M7: CENTRO | N7: CENTRO | O7: CENTRO | P7: CENTRO | Q7: CENTRO | R7: CENTRO | S7: CENTRO | T7: CENTRO | U7: CENTRO | V7: CENTRO | W7: CENTRO | X7: SUR | Y7: SUR | Z7: SUR | AA7: CENTRO | AB7: SUR | AC7: SUR | AD7: SUR | AE7: SUR | AF7: SUR | AG7: SUR | AH7: SUR | AI7: SUR | AJ7: CENTRO | AK7: NORTE | AL7: NORTE | AM7: NORTE | AN7: CENTRO | AO7: CENTRO | AP7: CENTRO | AQ7: CENTRO | AR7: CENTRO | AS7: CENTRO | AT7: CENTRO | AU7: SUR | AV7: CENTRO | AW7: CENTRO | AX7: CENTRO | AY7: CENTRO | AZ7: CENTRO | BA7: CENTRO | BB7: SUR | BC7: NORTE | BD7: CENTRO | BE7: CENTRO | BF7: CENTRO | BG7: CENTRO | BH7: NORTE | BI7: NORTE | BJ7: NORTE | BK7: SUR | BL7: SUR | BM7: SUR | BN7: CENTRO | BO7: CENTRO | BP7: CENTRO | BQ7: CENTRO | BR7: CENTRO | BS7: CENTRO | BT7: CENTRO | BU7: SUR | BV7: SUR | BW7: SUR | BX7: NORTE | BY7: SUR | BZ7: CENTRO | CA7: NORTE | CB7: CENTRO | CC7: CENTRO | CD7: CENTRO | CE7: CENTRO | CF7: CENTRO | CG7: CENTRO | CH7: CENTRO | CI7: CENTRO | CJ7: CENTRO | CK7: CENTRO | CL7: CENTRO | CM7: CENTRO | CN7: SUR | CO7: SUR | CP7: SUR | CQ7: SUR | CR7: CENTRO | CS7: CENTRO | CT7: CENTRO | CU7: CENTRO | CV7: NORTE | CW7: CENTRO | CX7: CENTRO | CY7: SUR | CZ7: NORTE | DA7: NORTE | DB7: CENTRO | DC7: NORTE | DD7: NORTE | DE7: SUR | DF7: SUR | DG7: CENTRO | DH7: CENTRO | DI7: CENTRO | DJ7: NORTE | DK7: NORTE | DL7: CENTRO | DM7: CENTRO | DN7: SUR | DO7: SUR | DP7: CENTRO | DQ7: CENTRO | DR7: SUR | DS7: CENTRO | DT7: CENTRO | DU7: NORTE | DV7: CENTRO | DW7: CENTRO | DX7: CENTRO | DY7: NORTE | DZ7: CENTRO | EA7: CENTRO | EB7: CENTRO | EC7: NORTE | ED7: NORTE | EE7: SUR | EF7: CENTRO | EG7: CENTRO | EH7: CENTRO | EI7: CENTRO | EJ7: SUR | EK7: CENTRO | EL7: CENTRO | EM7: SUR | EN7: SUR | EO7: SUR | EP7: SUR | EQ7: NORTE | ER7: SUR | ES7: SUR | ET7: SUR | EU7: CENTRO | EV7: CENTRO | EW7: CENTRO | EX7: SUR | EY7: CENTRO | EZ7: CENTRO | FA7: CENTRO | FB7: CENTRO | FC7: SUR | FD7: NORTE | FE7: CENTRO | FF7: NORTE | FG7: NORTE | FH7: NORTE | FI7: CENTRO | FJ7: NORTE | FK7: NORTE | FL7: NORTE | FM7: NORTE | FP7: NORTE | FQ7: CENTRO | FR7: NORTE | FS7: NORTE | FT7: NORTE | FU7: NORTE | FV7: NORTE | FW7: NORTE
C8: HIDROELÉCTRICA | D8: HIDROELÉCTRICA | E8: HIDROELÉCTRICA | F8: TERMOELÉCTRICA | G8: TERMOELÉCTRICA | H8: HIDROELÉCTRICA | I8: HIDROELÉCTRICA | J8: TERMOELÉCTRICA | K8: TERMOELÉCTRICA | L8: TERMOELÉCTRICA | M8: TERMOELÉCTRICA | N8: TERMOELÉCTRICA | O8: TERMOELÉCTRICA | P8: TERMOELÉCTRICA | Q8: TERMOELÉCTRICA | R8: HIDROELÉCTRICA | S8: HIDROELÉCTRICA | T8: TERMOELÉCTRICA | U8: TERMOELÉCTRICA | V8: TERMOELÉCTRICA | W8: TERMOELÉCTRICA | X8: HIDROELÉCTRICA | Y8: HIDROELÉCTRICA | Z8: HIDROELÉCTRICA | AA8: TERMOELÉCTRICA | AB8: HIDROELÉCTRICA | AC8: HIDROELÉCTRICA | AD8: HIDROELÉCTRICA | AE8: HIDROELÉCTRICA | AF8: TERMOELÉCTRICA | AG8: TERMOELÉCTRICA | AH8: TERMOELÉCTRICA | AI8: HIDROELÉCTRICA | AJ8: HIDROELÉCTRICA | AK8: TERMOELÉCTRICA | AL8: TERMOELÉCTRICA | AM8: TERMOELÉCTRICA | AN8: HIDROELÉCTRICA | AO8: HIDROELÉCTRICA | AP8: HIDROELÉCTRICA | AQ8: HIDROELÉCTRICA | AR8: HIDROELÉCTRICA | AS8: HIDROELÉCTRICA | AT8: HIDROELÉCTRICA | AU8: HIDROELÉCTRICA | AV8: TERMOELÉCTRICA | AW8: TERMOELÉCTRICA | AX8: TERMOELÉCTRICA | AY8: HIDROELÉCTRICA | AZ8: HIDROELÉCTRICA | BA8: HIDROELÉCTRICA | BB8: HIDROELÉCTRICA | BC8: HIDROELÉCTRICA | BD8: HIDROELÉCTRICA | BE8: HIDROELÉCTRICA | BF8: HIDROELÉCTRICA | BG8: HIDROELÉCTRICA | BH8: TERMOELÉCTRICA | BI8: TERMOELÉCTRICA | BJ8: TERMOELÉCTRICA | BK8: TERMOELÉCTRICA | BL8: TERMOELÉCTRICA | BM8: TERMOELÉCTRICA | BN8: HIDROELÉCTRICA | BO8: TERMOELÉCTRICA | BP8: TERMOELÉCTRICA | BQ8: TERMOELÉCTRICA | BR8: TERMOELÉCTRICA | BS8: TERMOELÉCTRICA | BT8: TERMOELÉCTRICA | BU8: TERMOELÉCTRICA | BV8: TERMOELÉCTRICA | BW8: TERMOELÉCTRICA | BX8: HIDROELÉCTRICA | BY8: TERMOELÉCTRICA | BZ8: TERMOELÉCTRICA | CA8: HIDROELÉCTRICA | CB8: HIDROELÉCTRICA | CC8: HIDROELÉCTRICA | CD8: HIDROELÉCTRICA | CE8: HIDROELÉCTRICA | CF8: HIDROELÉCTRICA | CG8: TERMOELÉCTRICA | CH8: TERMOELÉCTRICA | CI8: TERMOELÉCTRICA | CJ8: TERMOELÉCTRICA | CK8: TERMOELÉCTRICA | CL8: TERMOELÉCTRICA | CM8: TERMOELÉCTRICA | CN8: TERMOELÉCTRICA | CO8: TERMOELÉCTRICA | CP8: TERMOELÉCTRICA | CQ8: TERMOELÉCTRICA | CR8: TERMOELÉCTRICA | CS8: TERMOELÉCTRICA | CT8: HIDROELÉCTRICA | CU8: HIDROELÉCTRICA | CV8: HIDROELÉCTRICA | CW8: SOLAR | CX8: EÓLICA | CY8: SOLAR | CZ8: EÓLICA | DA8: SOLAR | DB8: HIDROELÉCTRICA | DC8: HIDROELÉCTRICA | DD8: HIDROELÉCTRICA | DE8: SOLAR | DF8: HIDROELÉCTRICA | DG8: HIDROELÉCTRICA | DH8: HIDROELÉCTRICA | DI8: HIDROELÉCTRICA | DJ8: HIDROELÉCTRICA | DK8: HIDROELÉCTRICA | DL8: HIDROELÉCTRICA | DM8: HIDROELÉCTRICA | DN8: SOLAR | DO8: SOLAR | DP8: EÓLICA | DQ8: EÓLICA | DR8: SOLAR | DS8: HIDROELÉCTRICA | DT8: HIDROELÉCTRICA | DU8: HIDROELÉCTRICA | DV8: HIDROELÉCTRICA | DW8: SOLAR | DX8: HIDROELÉCTRICA | DY8: HIDROELÉCTRICA | DZ8: HIDROELÉCTRICA | EA8: HIDROELÉCTRICA | EB8: HIDROELÉCTRICA | EC8: EÓLICA | ED8: EÓLICA | EE8: SOLAR | EF8: EÓLICA | EG8: EÓLICA | EH8: EÓLICA | EI8: EÓLICA | EJ8: SOLAR | EK8: HIDROELÉCTRICA | EL8: HIDROELÉCTRICA | EM8: HIDROELÉCTRICA | EN8: HIDROELÉCTRICA | EO8: HIDROELÉCTRICA | EP8: HIDROELÉCTRICA | EQ8: EÓLICA | ER8: SOLAR | ES8: SOLAR | ET8: SOLAR | EU8: HIDROELÉCTRICA | EV8: EÓLICA | EW8: EÓLICA | EX8: SOLAR | EY8: TERMOELÉCTRICA | EZ8: TERMOELÉCTRICA | FA8: TERMOELÉCTRICA | FB8: TERMOELÉCTRICA | FC8: SOLAR | FD8: HIDROELÉCTRICA | FE8: HIDROELÉCTRICA | FF8: TERMOELÉCTRICA | FG8: TERMOELÉCTRICA | FH8: TERMOELÉCTRICA | FI8: TERMOELÉCTRICA | FJ8: TERMOELÉCTRICA | FK8: TERMOELÉCTRICA | FL8: TERMOELÉCTRICA | FM8: TERMOELÉCTRICA | FP8: HIDROELÉCTRICA | FQ8: HIDROELÉCTRICA | FR8: HIDROELÉCTRICA | FS8: HIDROELÉCTRICA | FT8: TERMOELÉCTRICA | FU8: TERMOELÉCTRICA | FV8: HIDROELÉCTRICA | FW8: HIDROELÉCTRICA
C9: HYDRO GLOBAL PERÚ S.A.C. | D9: ELECTROPERU | E9: ELECTROPERU | F9: ELECTROPERU | G9: ELECTROPERU | H9: ORAZUL ENERGY PERÚ | I9: ORAZUL ENERGY PERÚ | J9: TERMOSELVA | K9: TERMOSELVA | L9: KALLPA GENERACION S.A. | M9: KALLPA GENERACION S.A. | N9: KALLPA GENERACION S.A. | O9: KALLPA GENERACION S.A. | P9: KALLPA GENERACION S.A. | Q9: KALLPA GENERACION S.A. | R9: KALLPA GENERACION S.A. | S9: KALLPA GENERACION S.A. | T9: SHOUGESA | U9: SHOUGESA | V9: SHOUGESA | W9: SHOUGESA | X9: EGEMSA | Y9: EGESUR | Z9: EGESUR | AA9: EGESUR | AB9: EGASA | AC9: EGASA | AD9: EGASA | AE9: EGASA | AF9: EGASA | AG9: EGASA | AH9: EGASA | AI9: SAN GABAN | AJ9: CELEPSA | AK9: MINERA CERRO VERDE | AL9: PLANTA DE RESERVA FRIA DE GENERACION DE ETEN S.A. | AM9: PLANTA DE RESERVA FRIA DE GENERACION DE ETEN S.A. | AN9: EMPRESA DE GENERACION HUALLAGA | AO9: EMPRESA DE GENERACION HUALLAGA | AP9: LA VIRGEN | AQ9: CHINANGO S.A.C. | AR9: CHINANGO S.A.C. | AS9: HIDROELECTRICA HUANCHOR S.A.C. | AT9: CELEPSA RENOVABLES S.R.L. | AU9: INLAND ENERGY SAC | AV9: FENIX POWER PERÚ | AW9: FENIX POWER PERÚ | AX9: FENIX POWER PERÚ | AY9: STATKRAFT S.A | AZ9: STATKRAFT S.A | BA9: STATKRAFT S.A | BB9: STATKRAFT S.A | BC9: STATKRAFT S.A | BD9: STATKRAFT S.A | BE9: CENTRALES SANTA ROSA S.A.C. | BF9: CENTRALES SANTA ROSA S.A.C. | BG9: EMPRESA DE GENERACION HUANZA | BH9: ENEL GENERACION PIURA S.A. | BI9: ENEL GENERACION PIURA S.A. | BJ9: ENEL GENERACION PIURA S.A. | BK9: ENGIE ENERGIA PERU S.A.A. | BL9: ENGIE ENERGIA PERU S.A.A. | BM9: ENGIE ENERGIA PERU S.A.A. | BN9: ENGIE ENERGIA PERU S.A.A. | BO9: ENGIE ENERGIA PERU S.A.A. | BP9: ENGIE ENERGIA PERU S.A.A. | BQ9: ENGIE ENERGIA PERU S.A.A. | BR9: ENGIE ENERGIA PERU S.A.A. | BS9: ENGIE ENERGIA PERU S.A.A. | BT9: ENGIE ENERGIA PERU S.A.A. | BU9: ENGIE ENERGIA PERU S.A.A. | BV9: ENGIE ENERGIA PERU S.A.A. | BW9: ENGIE ENERGIA PERU S.A.A. | BX9: ENGIE ENERGIA PERU S.A.A. | BY9: INFRAESTRUCTURAS Y ENERGIAS DEL PERU S.A.C. | BZ9: INFRAESTRUCTURAS Y ENERGIAS DEL PERU S.A.C. | CA9: INVERSIONES SHAQSHA S.A.C. | CB9: ORYGEN PERU S.A.A. | CC9: ORYGEN PERU S.A.A. | CD9: ORYGEN PERU S.A.A. | CE9: ORYGEN PERU S.A.A. | CF9: ORYGEN PERU S.A.A. | CG9: ORYGEN PERU S.A.A. | CH9: ORYGEN PERU S.A.A. | CI9: ORYGEN PERU S.A.A. | CJ9: ORYGEN PERU S.A.A. | CK9: ORYGEN PERU S.A.A. | CL9: ORYGEN PERU S.A.A. | CM9: ORYGEN PERU S.A.A. | CN9: SAMAY I S.A.C | CO9: SAMAY I S.A.C | CP9: SAMAY I S.A.C | CQ9: SAMAY I S.A.C | CR9: TERMOCHILCA S.A.C. | CS9: TERMOCHILCA S.A.C. | CT9: TRANSMISION ANDINA DE GENERACION S.A.C. | CU9: TRANSMISION ANDINA DE GENERACION S.A.C. | CV9: CELARIS ENERGY S.A. | CW9: COLCA SOLAR S.A.C. | CX9: ENERGIA RENOVABLE DEL SUR S.A. | CY9: GR CORTARRAMA SOCIEDAD ANONIMA CERRADA | CZ9: GR TARUCA SOCIEDAD ANONIMA CERRADA | DA9: KONDU SAC | DB9: VARI ENERGIA S.A.C. | DC9: ORAZUL ENERGY PERÚ | DD9: ORAZUL ENERGY PERÚ | DE9: KALLPA GENERACION S.A. | DF9: SAN GABAN | DG9: MAJA ENERGIA S.A.C. | DH9: EMPRESA DE GENERACION ELECTRICA CANCHAYLLO SAC | DI9: EMPRESA DE GENERACION ELECTRICA SANTA ANA S.A.C. | DJ9: EMPRESA ELECTRICA AGUA AZUL | DK9: EMPRESA ELECTRICA RIO DOBLE | DL9: HIDROCAÑETE S.A. | DM9: HUAURA POWER GROUP S.A. | DN9: MOQUEGUA FV S.A.C. | DO9: PANAMERICANA SOLAR SAC. | DP9: PARQUE EOLICO MARCONA S.A.C. | DQ9: PARQUE EOLICO TRES HERMANAS S.A.C. | DR9: TACNA SOLAR SAC. | DS9: ELECTRICA YANAPAMPA SAC | DT9: ANDEAN POWER S.A.C. | DU9: ASOCIACIÓN SANTA LUCIA DE CHACAS | DV9: ATRIA ENERGIA S.A.C. | DW9: COENERGY S.A.C. | DX9: EGEJUNIN | DY9: EGEJUNIN | DZ9: EGEJUNIN | EA9: EGEJUNIN | EB9: EMPRESA DE GENERACION ELECTRICA RIO BAÑOS S.A.C. | EC9: ENERGÍA EÓLICA S.A. | ED9: ENERGÍA EÓLICA S.A. | EE9: ENGIE ENERGIA PERU S.A.A. | EF9: ENGIE ENERGIA PERU S.A.A. | EG9: ENGIE ENERGIA PERU S.A.A. | EH9: ENGIE ENERGIA PERU S.A.A. | EI9: ENGIE ENERGIA PERU S.A.A. | EJ9: ENGIE ENERGIA PERU S.A.A. | EK9: GENERACIÓN ANDINA S.A.C. | EL9: GENERACIÓN ANDINA S.A.C. | EM9: GENERADORA DE ENERGÍA DEL PERÚ | EN9: GENERADORA DE ENERGÍA DEL PERÚ | EO9: GENERADORA DE ENERGÍA DEL PERÚ | EP9: GENERADORA DE ENERGÍA DEL PERÚ | EQ9: GR PAINO SOCIEDAD ANONIMA CERRADA | ER9: JOYA SOLAR S.A.C. | ES9: MAJES ARCUS S.A.C. | ET9: ORYGEN PERU S.A.A. | EU9: ORYGEN PERU S.A.A. | EV9: ORYGEN PERU S.A.A. | EW9: ORYGEN PERU S.A.A. | EX9: ORYGEN PERU S.A.A. | EY9: PETRAMAS | EZ9: PETRAMAS | FA9: PETRAMAS | FB9: PETRAMAS | FC9: REPARTICIÓN ARCUS S.A.C. | FD9: SINERSA | FE9: SINERSA | FF9: BIOENERGIA DEL CHIRA S.A. | FG9: GM OPERACIONES S.A.C. | FH9: GM OPERACIONES S.A.C. | FI9: AGRO INDUSTRIAL PARAMONGA S.A. | FJ9: AGROAURORA S.A.C. | FK9: AGROINDUSTRIAS SAN JACINTO S.A.A. | FL9: AGROLMOS SOCIEDAD ANONIMA - AGROLMOS S.A. | FM9: CASA GRANDE S.A.A. | FP9: UNACEM PERU S.A. | FQ9: ELECTRO ORIENTE | FR9: AGUAS Y ENERGIA PERU | FS9: ELECTRO ZAÑA S.A.C. | FT9: ELECTRONOROESTE S.A. | FU9: SDE PIURA | FV9: SINERSA | FW9: SINERSA
C10: SAN GABAN III | D10: MANTARO | E10: RESTITUCION | F10: TUMBES MAK 1 | G10: TUMBES MAK 2 | H10: CARHUAQUERO | I10: CAÑON DEL PATO | J10: AGUAYTIA TG1 | K10: AGUAYTIA TG2 | L10: KALLPA TG1 | M10: KALLPA TG2 | N10: KALLPA TG3 | O10: KALLPA TV | P10: LFLORES TG1 | Q10: LFLORES TV | R10: CERRO DEL AGUILA | S10: CERRODELAGUILAG4 | T10: SHOUGESA TV1 | U10: SHOUGESA TV2 | V10: SHOUGESA TV3 | W10: SHOUGESA CUMMINS | X10: MACHUPICCHU | Y10: ARICOTA 1 | Z10: ARICOTA 2 | AA10: INDEPENDENCIA | AB10: CHARCANI I,II,III | AC10: CHARCANI IV | AD10: CHARCANI V | AE10: CHARCANI VI | AF10: CHILINA TG | AG10: MOLLENDO 1, 2, 3 | AH10: CHILINA (SULZ 1,2) | AI10: SAN GABAN II | AJ10: PLATANAL | AK10: RECKA | AL10: RF ETEN TG1 | AM10: RF ETEN TG2 | AN10: CHAGLLA GP1 | AO10: CHAGLLA | AP10: LA VIRGEN | AQ10: CHIMAY | AR10: YANANGO | AS10: HUANCHOR | AT10: MARAÑON | AU10: STA TERESA | AV10: FENIX GT11 | AW10: FENIX GT12 | AX10: FENIX TV10 | AY10: YAUPI | AZ10: MALPASO | BA10: CAHUA | BB10: ARCATA | BC10: GALLITO CIEGO | BD10: CHEVES | BE10: SANTA ROSA 1 | BF10: SANTA ROSA 2 | BG10: HUANZA | BH10: MALACAS2 TG4 | BI10: MALACAS3 TG 5 | BJ10: MALACAS1 TG6 | BK10: RF ILO2 TG1 | BL10: RF ILO2 TG2 | BM10: RF ILO2 TG3 | BN10: YUNCAN | BO10: CHILCA1 TG1 | BP10: CHILCA1 TG2 | BQ10: CHILCA1 TG3 | BR10: CHILCA-TV | BS10: CHILCA2 TG41 | BT10: CHILCA2-TV | BU10: CTNEPI_TG41 | BV10: CTNEPI_TG42 | BW10: CTNEPI_TG43 | BX10: QUITARACSA | BY10: RF PTO MALDONADO | BZ10: RF PUCALLPA | CA10: PARIAC | CB10: HUINCO | CC10: MATUCANA | CD10: MOYOPAMPA | CE10: CALLAHUANCA | CF10: HUAMPANI | CG10: STA ROSA WEST TG7 | CH10: UTI_5 | CI10: UTI_6 | CJ10: VENTANILLA 3 | CK10: VENTANILLA 4 | CL10: VENTANILLA TV | CM10: STAROSA TG8 | CN10: PTO_BRVO TG1 | CO10: PTO_BRVO TG2 | CP10: PTO_BRVO TG3 | CQ10: PTO_BRVO TG4 | CR10: OLLEROS TG1 | CS10: OLLEROS TV | CT10: OROYA | CU10: PACHACHACA | CV10: MANTA I | CW10: CS YARUCAYA | CX10: SAN JUAN | CY10: MATARANI | CZ10: DUNA | DA10: CARHUAQUERO (CS) | DB10: ANASHIRONI | DC10: CARHUAQUERO4 | DD10: CAÑA BRAVA | DE10: SUNNY | DF10: TUPURI | DG10: RONCADOR | DH10: CANCHAYLLO | DI10: RENOVANDESH1 | DJ10: POTRERO | DK10: PIZARRAS | DL10: NIMPERIAL | DM10: YARUCAYA | DN10: MOQUEGUA-SOLAR | DO10: PANAMERICANA-SOLAR | DP10: PQE-EOLICO-MARCONA | DQ10: PQE-EOLICO-3-HERMANAS | DR10: TACNA-SOLAR | DS10: YANAPAMPA | DT10: CARHUAC | DU10: HUALLIN | DV10: PURMACANA | DW10: COENERGY | DX10: HUASAHUASI | DY10: STACRUZ_1_2 | DZ10: RUNATULLO_II | EA10: RUNATULLO_III | EB10: RUCUY | EC10: PQE-EOLICO-TALARA | ED10: PQE-EOLICO-CUPISNIQUE | EE10: INTIPAMPA | EF10: PUNTA LOMITAS-BL1 | EG10: PUNTA LOMITAS-BL2 | EH10: PUN LOMITAS_EXP-BL1 | EI10: PUN LOMITAS_EXP-BL2 | EJ10: EXPANSIÓN INTIPAMPA | EK10: 8AGOSTO | EL10: EL CARMEN | EM10: LA JOYA | EN10: ANGEL_I | EO10: ANGEL_II | EP10: ANGEL_III | EQ10: HUAMBOS | ER10: SAN MARTIN SOLAR | ES10: MAJES | ET10: RUBI | EU10: CH_HER1 | EV10: WAYRA-I | EW10: WAYRA EXTENSION | EX10: CLEMESI | EY10: HUAYCOLORO | EZ10: CALLAO | FA10: DONA_CATALINA | FB10: LAGRINGAV | FC10: REPARTICION | FD10: POECHOS2 | FE10: CHANCAY | FF10: CANA BRAVA | FG10: REFINERIA TALARA TV1 | FH10: REFINERÍA TALARA TV2 | FI10: PARAMONGA | FJ10: MAPLE | FK10: SAN_JACINTO | FL10: AGROLMOS | FM10: CASA GRANDE | FN10: MW | FP10: CARPAPATA | FQ10: CENTRALES ELOR | FR10: PIAS1 | FS10: ZANA | FT10: TABLAZO | FU10: TALLANCA | FV10: CURUMUY | FW10: POECHOS1 | FX10: MW
A11: 27/12/2025 | B11: 00:30 | C11: 198.1 | D11: 537.5 | E11: 181.9 | H11: 82.4 | I11: 161.4 | K11: 76.7 | L11: 183.5 | N11: 202.3 | P11: 209.8 | R11: 378.6 | S11: 9.4 | X11: 163 | Y11: 6.7 | Z11: 4.8 | AA11: 22.2 | AB11: 6.9 | AC11: 14.3 | AD11: 88.9 | AI11: 109.7 | AJ11: 0 | AN11: 6.5 | AO11: 157.1 | AP11: 28.2 | AQ11: 60.1 | AR11: 15.5 | AS11: 16 | AT11: 13.9 | AU11: 89.1 | AV11: 177.86025 | AW11: 178.75744 | AX11: 183.63172 | AY11: 102.064 | AZ11: 0 | BA11: 25.292 | BB11: 4.084 | BC11: 32.26 | BD11: 37.315 | BG11: 84.1 | BJ11: 46.3 | BN11: 83.4 | BO11: 148.4 | BP11: 148.3 | BQ11: 156 | BR11: 250.1 | BS11: 73.9 | BT11: 36 | CB11: 71.7 | CC11: 46.8 | CD11: 61.6 | CE11: 63.8 | CF11: 29.7 | CG11: 119.2 | CJ11: 144.2 | CK11: 144.8 | CL11: 170.5 | CM11: 187.9 | CR11: 210.3 | CS11: 101.5 | CT11: 3.1 | CV11: 4.3 | CW11: 0 | CX11: 48.3 | CY11: 0 | CZ11: 0.2 | DA11: 0 | DB11: 4.9 | DC11: 9.9 | DD11: 5.4 | DE11: 0 | DF11: 1.1 | DG11: 1.6 | DH11: 4.1 | DI11: 18.2 | DJ11: 10.6 | DK11: 14.4 | DL11: 2.3 | DM11: 17.2 | DN11: 0 | DO11: 0 | DP11: 13.5 | DQ11: 19.2 | DR11: 0 | DS11: 2 | DT11: 20.2 | DU11: 3 | DW11: 0 | DX11: 4.1 | DY11: 8.2 | DZ11: 10.1 | EA11: 14.9 | EB11: 17.6 | EC11: 18 | ED11: 56 | EE11: 0 | EF11: 18.4 | EG11: 26.2 | EH11: 0.6 | EI11: 0 | EJ11: 0 | EK11: 8.8 | EL11: 2.8 | EM11: 8.5 | EN11: 20.4 | EO11: 20.4 | EP11: 20.1 | EQ11: 0.4 | ER11: 0 | ES11: 0 | ET11: 0 | EU11: 0.6 | EV11: 2.9 | EW11: 0.7 | EX11: 0 | EY11: 4.3 | EZ11: 2.2 | FA11: 1.2 | FB11: 1.2 | FC11: 0 | FD11: 5.7 | FE11: 10 | FF11: 8.4 | FG11: 27.7 | FH11: 34.9 | FK11: 9.1 | FL11: 11.1 | FM11: 19.1 | FN11: 6742.3644 | FP11: 13.86024 | FQ11: 0 | FR11: 11.82869 | FS11: 8 | FT11: 26.81407 | FU11: 18.93389 | FV11: 4.3 | FW11: 15.9 | FX11: 99.63689
A12: 27/12/2025 | B12: 01:00 | C12: 200.1 | D12: 541.5 | E12: 182.2 | H12: 84.1 | I12: 167.2 | K12: 77.7 | L12: 183.5 | N12: 201.6 | P12: 210.5 | R12: 213.3 | S12: 9.2 | X12: 163.4 | Y12: 6.8 | Z12: 4.9 | AA12: 22.2 | AB12: 6.9 | AC12: 14.6 | AD12: 89.9 | AI12: 109.9 | AJ12: 0 | AN12: 6.5 | AO12: 152.5 | AP12: 28.6 | AQ12: 54.3 | AR12: 14.7 | AS12: 16 | AT12: 13.8 | AU12: 91.2 | AV12: 178.64745 | AW12: 179.37847 | AX12: 184.34747 | AY12: 102.849 | AZ12: 0 | BA12: 26.446 | BB12: 4.084 | BC12: 32.14 | BD12: 37.719 | BG12: 84.4 | BJ12: 14 | BN12: 83.6 | BO12: 162 | BP12: 162.1 | BQ12: 163.7 | BR12: 252.1 | BS12: 74 | BT12: 36.1 | CB12: 104.7 | CC12: 45.6 | CD12: 62.1 | CE12: 61.6 | CF12: 29.7 | CG12: 118.9 | CJ12: 143.8 | CK12: 144.5 | CL12: 169.9 | CM12: 187.5 | CR12: 211 | CS12: 101.5 | CT12: 3.2 | CV12: 4.3 | CW12: 0 | CX12: 42.2 | CY12: 0 | CZ12: 0.3 | DA12: 0 | DB12: 5 | DC12: 9.9 | DD12: 5.4 | DE12: 0 | DF12: 1.1 | DG12: 1.6 | DH12: 4.1 | DI12: 16.8 | DJ12: 10.6 | DK12: 14.5 | DL12: 2.3 | DM12: 17.2 | DN12: 0 | DO12: 0 | DP12: 8.3 | DQ12: 10.8 | DR12: 0 | DS12: 2.1 | DT12: 20.2 | DU12: 3 | DW12: 0 | DX12: 4.1 | DY12: 8.2 | DZ12: 10.3 | EA12: 14.7 | EB12: 17.6 | EC12: 19.7 | ED12: 49.5 | EE12: 0 | EF12: 9.3 | EG12: 20.2 | EH12: 0.1 | EI12: 0 | EJ12: 0 | EK12: 8.8 | EL12: 2.8 | EM12: 8.5 | EN12: 20.4 | EO12: 20.4 | EP12: 20.1 | EQ12: 0.6 | ER12: 0 | ES12: 0 | ET12: 0 | EU12: 0.6 | EV12: 0.7 | EW12: 0.7 | EX12: 0 | EY12: 4.3 | EZ12: 2.2 | FA12: 1.2 | FB12: 1.2 | FC12: 0 | FD12: 5.8 | FE12: 10 | FF12: 8.8 | FG12: 27.3 | FH12: 34.4 | FK12: 9 | FL12: 11.1 | FM12: 19.5 | FN12: 6580.5114 | FP12: 12.81188 | FQ12: 0 | FR12: 11.83088 | FS12: 8 | FT12: 26.83652 | FU12: 18.93434 | FV12: 4.5 | FW12: 15.9 | FX12: 98.81362
A13: 27/12/2025 | B13: 01:30 | C13: 201.5 | D13: 494.2 | E13: 162.6 | H13: 85 | I13: 172.9 | K13: 76.3 | L13: 183.7 | N13: 202.4 | P13: 209.6 | R13: 195.1 | S13: 9.3 | X13: 164.8 | Y13: 7.2 | Z13: 5 | AA13: 22.2 | AB13: 6.9 | AC13: 14.6 | AD13: 90 | AI13: 110.5 | AJ13: 0 | AN13: 6.5 | AO13: 149.5 | AP13: 30 | AQ13: 54.5 | AR13: 14.9 | AS13: 16 | AT13: 13.5 | AU13: 89.7 | AV13: 179.41658 | AW13: 180.14569 | AX13: 183.62353 | AY13: 105.245 | AZ13: 0 | BA13: 26.737 | BB13: 4.079 | BC13: 32.47 | BD13: 73.512 | BG13: 45.2 | BJ13: 0 | BN13: 84.3 | BO13: 170.6 | BP13: 168.2 | BQ13: 199.9 | BR13: 266.4 | BS13: 73.6 | BT13: 36 | CB13: 109.6 | CC13: 51.8 | CD13: 62.6 | CE13: 61.8 | CF13: 30.1 | CG13: 118.6 | CJ13: 143.1 | CK13: 144.2 | CL13: 168.7 | CM13: 187.2 | CR13: 210.9 | CS13: 101.5 | CT13: 3.2 | CV13: 4.2 | CW13: 0 | CX13: 36.9 | CY13: 0 | CZ13: 0.7 | DA13: 0 | DB13: 5.1 | DC13: 10 | DD13: 5.4 | DE13: 0 | DF13: 1.1 | DG13: 1.7 | DH13: 4.1 | DI13: 17.1 | DJ13: 10.6 | DK13: 14.3 | DL13: 2.3 | DM13: 17.2 | DN13: 0 | DO13: 0 | DP13: 7 | DQ13: 10.8 | DR13: 0 | DS13: 2.2 | DT13: 14.4 | DU13: 3 | DW13: 0 | DX13: 4.1 | DY13: 8.2 | DZ13: 10.5 | EA13: 14.5 | EB13: 17.6 | EC13: 22.1 | ED13: 57.1 | EE13: 0 | EF13: 6.3 | EG13: 14.4 | EH13: 0 | EI13: 0 | EJ13: 0 | EK13: 9 | EL13: 3 | EM13: 8.5 | EN13: 20.4 | EO13: 20.4 | EP13: 20.1 | EQ13: 1.3 | ER13: 0 | ES13: 0 | ET13: 0 | EU13: 0.6 | EV13: 0.1 | EW13: 0.7 | EX13: 0 | EY13: 4.3 | EZ13: 2.2 | FA13: 1.2 | FB13: 1.2 | FC13: 0 | FD13: 5.7 | FE13: 10 | FF13: 8.4 | FG13: 27.5 | FH13: 34.9 | FK13: 8.6 | FL13: 11.1 | FM13: 20.1 | FN13: 6553.3288 | FP13: 12.86766 | FQ13: 0 | FR13: 11.83088 | FS13: 8 | FT13: 26.81947 | FU13: 18.93443 | FV13: 4.6 | FW13: 15.7 | FX13: 98.75244
A14: 27/12/2025 | B14: 02:00 | C14: 201.2 | D14: 499 | E14: 163.4 | H14: 66.4 | I14: 178.6 | K14: 78.7 | L14: 183 | N14: 204.1 | P14: 210.6 | R14: 208.9 | S14: 9.4 | X14: 155.1 | Y14: 7.4 | Z14: 5.1 | AA14: 22 | AB14: 6.9 | AC14: 14.6 | AD14: 90.5 | AI14: 111 | AJ14: 0 | AN14: 6.5 | AO14: 154.2 | AP14: 29.3 | AQ14: 61.4 | AR14: 14.4 | AS14: 16 | AT14: 13.6 | AU14: 92 | AV14: 180.89391 | AW14: 181.35952 | AX14: 184.41595 | AY14: 107.699 | AZ14: 0 | BA14: 28.021 | BB14: 4.083 | BC14: 32.39 | BD14: 46.831 | BG14: 45.9 | BJ14: 0 | BN14: 84.5 | BO14: 162.6 | BP14: 162.9 | BQ14: 161.9 | BR14: 240.8 | BS14: 73.5 | BT14: 36.2 | CB14: 133.6 | CC14: 48.2 | CD14: 62.7 | CE14: 61.8 | CF14: 30.1 | CG14: 119.2 | CJ14: 144.1 | CK14: 145.2 | CL14: 170 | CM14: 188.5 | CR14: 211.2 | CS14: 101.6 | CT14: 3.1 | CV14: 4.4 | CW14: 0 | CX14: 30.9 | CY14: 0 | CZ14: 0.4 | DA14: 0 | DB14: 5.1 | DC14: 9.9 | DD14: 5.4 | DE14: 0 | DF14: 1.1 | DG14: 1.7 | DH14: 4.3 | DI14: 18.1 | DJ14: 10.6 | DK14: 14 | DL14: 2.3 | DM14: 17.2 | DN14: 0 | DO14: 0 | DP14: 7.3 | DQ14: 10.3 | DR14: 0 | DS14: 2.1 | DT14: 11.4 | DU14: 3 | DW14: 0 | DX14: 4.1 | DY14: 8.2 | DZ14: 10.8 | EA14: 14.7 | EB14: 17.4 | EC14: 22.6 | ED14: 60.8 | EE14: 0 | EF14: 3.5 | EG14: 10.8 | EH14: 0 | EI14: 0 | EJ14: 0 | EK14: 9.3 | EL14: 3.1 | EM14: 8.5 | EN14: 20.4 | EO14: 20.4 | EP14: 20.1 | EQ14: 0.5 | ER14: 0 | ES14: 0 | ET14: 0 | EU14: 0.6 | EV14: 0 | EW14: 0.2 | EX14: 0 | EY14: 4.3 | EZ14: 2.2 | FA14: 1.2 | FB14: 1.2 | FC14: 0 | FD14: 5.6 | FE14: 9.9 | FF14: 8.8 | FG14: 27 | FH14: 34.3 | FK14: 8.6 | FL14: 11.1 | FM14: 19.4 | FN14: 6485.6934 | FP14: 12.99735 | FQ14: 0 | FR14: 11.83006 | FS14: 8 | FT14: 26.86524 | FU14: 18.93772 | FV14: 4.3 | FW14: 16.1 | FX14: 99.03037
A15: 27/12/2025 | B15: 02:30 | C15: 202.5 | D15: 495.6 | E15: 163.6 | H15: 68.2 | I15: 178.3 | K15: 77.2 | L15: 183.9 | N15: 201.1 | P15: 208.7 | R15: 229.2 | S15: 9.4 | X15: 164.2 | Y15: 7.5 | Z15: 5.1 | AA15: 22.1 | AB15: 6.9 | AC15: 14.6 | AD15: 89.8 | AI15: 110.8 | AJ15: 0 | AN15: 6.5 | AO15: 0 | AP15: 28 | AQ15: 57.3 | AR15: 15.7 | AS15: 16 | AT15: 13.6 | AU15: 93 | AV15: 181.55938 | AW15: 182.72725 | AX15: 183.74183 | AY15: 109.243 | AZ15: 0 | BA15: 28.08 | BB15: 4.079 | BC15: 32.96 | BD15: 56.267 | BG15: 46.4 | BJ15: 0 | BN15: 84.7 | BO15: 162.6 | BP15: 162.7 | BQ15: 165.6 | BR15: 254.6 | BS15: 73.6 | BT15: 36.2 | CB15: 123.8 | CC15: 60.2 | CD15: 63 | CE15: 62 | CF15: 30.4 | CG15: 119.1 | CJ15: 143.4 | CK15: 144.2 | CL15: 169.2 | CM15: 187.9 | CR15: 210.9 | CS15: 101.5 | CT15: 3.2 | CV15: 4.4 | CW15: 0 | CX15: 19.1 | CY15: 0 | CZ15: 0.1 | DA15: 0 | DB15: 5.2 | DC15: 9.9 | DD15: 5.3 | DE15: 0 | DF15: 1.1 | DG15: 1.7 | DH15: 4.3 | DI15: 18.9 | DJ15: 10.6 | DK15: 13.5 | DL15: 2.3 | DM15: 17.2 | DN15: 0 | DO15: 0 | DP15: 4.5 | DQ15: 5.8 | DR15: 0 | DS15: 2.3 | DT15: 11 | DU15: 3 | DW15: 0 | DX15: 4.1 | DY15: 8.3 | DZ15: 11.1 | EA15: 14.5 | EB15: 17.8 | EC15: 27.7 | ED15: 51.3 | EE15: 0 | EF15: 3.3 | EG15: 8.3 | EH15: 0 | EI15: 0 | EJ15: 0 | EK15: 9.4 | EL15: 2.9 | EM15: 8.5 | EN15: 20.4 | EO15: 20.4 | EP15: 20.1 | EQ15: 0.3 | ER15: 0 | ES15: 0 | ET15: 0 | EU15: 0.6 | EV15: 0 | EW15: 0 | EX15: 0 | EY15: 4.3 | EZ15: 2.2 | FA15: 1.2 | FB15: 1.2 | FC15: 0 | FD15: 5.6 | FE15: 10 | FF15: 9.1 | FG15: 27.3 | FH15: 34.7 | FK15: 8.6 | FL15: 11.1 | FM15: 19.1 | FN15: 6356.2575 | FP15: 13.45489 | FQ15: 0 | FR15: 11.82944 | FS15: 8 | FT15: 26.93084 | FU15: 18.94043 | FV15: 4.6 | FW15: 16 | FX15: 99.7556
A16: 27/12/2025 | B16: 03:00 | C16: 203.4 | D16: 502.4 | E16: 165.2 | H16: 68.1 | I16: 179.1 | K16: 77.8 | L16: 184.5 | N16: 202.4 | P16: 209 | R16: 251.1 | S16: 9.3 | X16: 161.3 | Y16: 7.6 | Z16: 5.2 | AA16: 22.2 | AB16: 6.9 | AC16: 14.6 | AD16: 91.1 | AI16: 110.8 | AJ16: 0 | AN16: 6.5 | AO16: 0 | AP16: 29.5 | AQ16: 64.9 | AR16: 13.5 | AS16: 16.2 | AT16: 13.6 | AU16: 94.9 | AV16: 181.85097 | AW16: 181.96855 | AX16: 185.69945 | AY16: 108.263 | AZ16: 0 | BA16: 27.981 | BB16: 4.084 | BC16: 32.91 | BD16: 61.327 | BG16: 46.5 | BJ16: 0 | BN16: 84.5 | BO16: 171.9 | BP16: 169.1 | BQ16: 168.8 | BR16: 243.5 | BS16: 73.7 | BT16: 36.2 | CB16: 92.1 | CC16: 71.3 | CD16: 63 | CE16: 62 | CF16: 30.3 | CG16: 119.5 | CJ16: 144.1 | CK16: 144.8 | CL16: 170.4 | CM16: 188.7 | CR16: 211.2 | CS16: 101.5 | CT16: 3.2 | CV16: 4.4 | CW16: 0 | CX16: 12.5 | CY16: 0 | CZ16: 0 | DA16: 0 | DB16: 5.1 | DC16: 9.9 | DD16: 5.3 | DE16: 0 | DF16: 1.1 | DG16: 1.7 | DH16: 4.1 | DI16: 17.3 | DJ16: 10.6 | DK16: 13.6 | DL16: 2.3 | DM16: 17.2 | DN16: 0 | DO16: 0 | DP16: 3 | DQ16: 5.3 | DR16: 0 | DS16: 2.3 | DT16: 11.7 | DU16: 3 | DW16: 0 | DX16: 4.1 | DY16: 8.3 | DZ16: 12.1 | EA16: 14.8 | EB16: 17.8 | EC16: 28.1 | ED16: 55.6 | EE16: 0 | EF16: 1.8 | EG16: 6.3 | EH16: 0 | EI16: 0 | EJ16: 0 | EK16: 9.2 | EL16: 2.8 | EM16: 8.5 | EN16: 20.4 | EO16: 20.4 | EP16: 20.1 | EQ16: 0 | ER16: 0 | ES16: 0 | ET16: 0 | EU16: 0.6 | EV16: 0.4 | EW16: 0 | EX16: 0 | EY16: 4.3 | EZ16: 2.2 | FA16: 1.2 | FB16: 1.2 | FC16: 0 | FD16: 5.6 | FE16: 10 | FF16: 8.6 | FG16: 27.3 | FH16: 34.6 | FK16: 8.1 | FL16: 11 | FM16: 19.5 | FN16: 6386.784 | FP16: 13.82039 | FQ16: 0 | FR16: 11.83081 | FS16: 8 | FT16: 26.94932 | FU16: 18.94035 | FV16: 4.5 | FW16: 16 | FX16: 100.04087
A17: 27/12/2025 | B17: 03:30 | C17: 206.4 | D17: 502.1 | E17: 160.1 | H17: 69.5 | I17: 181.5 | K17: 79.5 | L17: 182.4 | N17: 200.8 | P17: 208.3 | R17: 231.9 | S17: 9.3 | X17: 172 | Y17: 7.7 | Z17: 5.3 | AA17: 22.1 | AB17: 6.9 | AC17: 14.6 | AD17: 90.8 | AI17: 111 | AJ17: 0 | AN17: 6.5 | AO17: 0 | AP17: 29.3 | AQ17: 59 | AR17: 14.4 | AS17: 16.1 | AT17: 13.7 | AU17: 87.5 | AV17: 183.68208 | AW17: 183.7 | AX17: 183.63566 | AY17: 107.894 | AZ17: 0 | BA17: 28.142 | BB17: 4.081 | BC17: 32.88 | BD17: 42.861 | BG17: 47.2 | BJ17: 0 | BN17: 85 | BO17: 158.9 | BP17: 158.7 | BQ17: 156.5 | BR17: 239.6 | BS17: 73.6 | BT17: 36.3 | CB17: 125.5 | CC17: 67.1 | CD17: 63.5 | CE17: 62.4 | CF17: 30.4 | CG17: 119 | CJ17: 143 | CK17: 144 | CL17: 169.3 | CM17: 188 | CR17: 211.8 | CS17: 101.6 | CT17: 3.2 | CV17: 4.5 | CW17: 0 | CX17: 20.2 | CY17: 0 | CZ17: 0 | DA17: 0 | DB17: 5.3 | DC17: 9.9 | DD17: 5.3 | DE17: 0 | DF17: 1.1 | DG17: 1.6 | DH17: 4.1 | DI17: 18.6 | DJ17: 10.6 | DK17: 13.5 | DL17: 2.3 | DM17: 17.2 | DN17: 0 | DO17: 0 | DP17: 3.2 | DQ17: 5 | DR17: 0 | DS17: 2.3 | DT17: 11.7 | DU17: 3 | DW17: 0 | DX17: 4.1 | DY17: 8.3 | DZ17: 12 | EA17: 14.8 | EB17: 17.8 | EC17: 29.2 | ED17: 52.2 | EE17: 0 | EF17: 0.6 | EG17: 9.5 | EH17: 0 | EI17: 0 | EJ17: 0 | EK17: 9.1 | EL17: 2.8 | EM17: 8.5 | EN17: 20.4 | EO17: 20.4 | EP17: 20.1 | EQ17: 0 | ER17: 0 | ES17: 0 | ET17: 0 | EU17: 0.6 | EV17: 0 | EW17: 0 | EX17: 0 | EY17: 4.3 | EZ17: 2.2 | FA17: 1.2 | FB17: 1.2 | FC17: 0 | FD17: 5.7 | FE17: 10 | FF17: 9.3 | FG17: 27 | FH17: 34.3 | FK17: 8.2 | FL17: 11 | FM17: 19.8 | FN17: 6344.1757 | FP17: 14.59503 | FQ17: 0 | FR17: 11.82825 | FS17: 8 | FT17: 26.95864 | FU17: 18.94075 | FV17: 4.5 | FW17: 15.9 | FX17: 100.72267
A18: 27/12/2025 | B18: 04:00 | C18: 199.9 | D18: 490.6 | E18: 162.1 | H18: 66.9 | I18: 179.5 | K18: 77 | L18: 183.2 | N18: 202.4 | P18: 211.5 | R18: 226.9 | S18: 9.3 | X18: 165 | Y18: 6.8 | Z18: 4.9 | AA18: 22.1 | AB18: 7 | AC18: 14.6 | AD18: 89.6 | AI18: 109.7 | AJ18: 0 | AN18: 6.5 | AO18: 0 | AP18: 29.2 | AQ18: 45.5 | AR18: 14.8 | AS18: 16.1 | AT18: 13.7 | AU18: 90.5 | AV18: 179.17222 | AW18: 179.46791 | AX18: 183.90017 | AY18: 106.629 | AZ18: 0 | BA18: 27.299 | BB18: 4.08 | BC18: 32.18 | BD18: 37.96 | BG18: 44.3 | BJ18: 0 | BN18: 83.5 | BO18: 152.9 | BP18: 152.9 | BQ18: 154.3 | BR18: 245.4 | BS18: 73.6 | BT18: 36.2 | CB18: 82 | CC18: 43.2 | CD18: 61.8 | CE18: 61.1 | CF18: 29.7 | CG18: 119.6 | CJ18: 143.9 | CK18: 144.8 | CL18: 170.6 | CM18: 188.6 | CR18: 211.9 | CS18: 101.6 | CT18: 3.2 | CV18: 4.5 | CW18: 0 | CX18: 44 | CY18: 0 | CZ18: 0 | DA18: 0 | DB18: 5 | DC18: 9.9 | DD18: 5.3 | DE18: 0 | DF18: 1.1 | DG18: 1.6 | DH18: 4.1 | DI18: 18.7 | DJ18: 10.6 | DK18: 13.4 | DL18: 2.3 | DM18: 17.2 | DN18: 0 | DO18: 0 | DP18: 4.6 | DQ18: 5.2 | DR18: 0 | DS18: 2.3 | DT18: 11.9 | DU18: 3 | DW18: 0 | DX18: 4.1 | DY18: 8.3 | DZ18: 11.4 | EA18: 16 | EB18: 17.6 | EC18: 28.9 | ED18: 33.6 | EE18: 0 | EF18: 1.7 | EG18: 7.4 | EH18: 0 | EI18: 0 | EJ18: 0 | EK18: 9 | EL18: 2.8 | EM18: 8.5 | EN18: 20.4 | EO18: 20.4 | EP18: 20.1 | EQ18: 0 | ER18: 0 | ES18: 0 | ET18: 0 | EU18: 0.6 | EV18: 0 | EW18: 0 | EX18: 0 | EY18: 4.3 | EZ18: 2.2 | FA18: 1.2 | FB18: 1.2 | FC18: 0 | FD18: 5.7 | FE18: 10 | FF18: 7.8 | FG18: 27.3 | FH18: 34.7 | FK18: 8 | FL18: 11 | FM18: 19 | FN18: 6208.9883 | FP18: 16.76799 | FQ18: 0 | FR18: 11.82612 | FS18: 8 | FT18: 26.97469 | FU18: 18.94114 | FV18: 4.5 | FW18: 15.9 | FX18: 102.90994
A19: 27/12/2025 | B19: 04:30 | C19: 202.8 | D19: 498 | E19: 164.1 | H19: 68 | I19: 188.3 | K19: 77.7 | L19: 183.6 | N19: 201.8 | P19: 209.5 | R19: 206.9 | S19: 9.2 | X19: 168.2 | Y19: 7.3 | Z19: 5.1 | AA19: 22.1 | AB19: 6.9 | AC19: 14.6 | AD19: 90.6 | AI19: 110.8 | AJ19: 0 | AN19: 6.5 | AO19: 0 | AP19: 24.5 | AQ19: 56.2 | AR19: 15.6 | AS19: 16.2 | AT19: 13.7 | AU19: 90.9 | AV19: 181.6362 | AW19: 181.50489 | AX19: 184.56119 | AY19: 108.261 | AZ19: 0 | BA19: 28.027 | BB19: 4.081 | BC19: 32.89 | BD19: 50.356 | BG19: 46.2 | BJ19: 0 | BN19: 84.5 | BO19: 171 | BP19: 168.3 | BQ19: 171.1 | BR19: 256.3 | BS19: 73.9 | BT19: 36.3 | CB19: 145.8 | CC19: 66.8 | CD19: 62.7 | CE19: 58 | CF19: 30.1 | CG19: 65.2 | CJ19: 143.9 | CK19: 145 | CL19: 169.5 | CM19: 188.5 | CR19: 212 | CS19: 101.7 | CT19: 3.2 | CV19: 4.4 | CW19: 0 | CX19: 64.3 | CY19: 0 | CZ19: 0 | DA19: 0 | DB19: 5.1 | DC19: 9.9 | DD19: 5.2 | DE19: 0 | DF19: 1.1 | DG19: 1.6 | DH19: 4 | DI19: 18.8 | DJ19: 10.9 | DK19: 13.6 | DL19: 2.3 | DM19: 17.2 | DN19: 0 | DO19: 0 | DP19: 6.2 | DQ19: 9.8 | DR19: 0 | DS19: 2.3 | DT19: 11.9 | DU19: 3 | DW19: 0 | DX19: 4.1 | DY19: 8.3 | DZ19: 11.6 | EA19: 16.3 | EB19: 17.6 | EC19: 25.6 | ED19: 34.2 | EE19: 0 | EF19: 1.4 | EG19: 17.8 | EH19: 0 | EI19: 0 | EJ19: 0 | EK19: 9 | EL19: 2.8 | EM19: 8.5 | EN19: 20.4 | EO19: 20.4 | EP19: 20.1 | EQ19: 0 | ER19: 0 | ES19: 0 | ET19: 0 | EU19: 0.6 | EV19: 0 | EW19: 1.4 | EX19: 0 | EY19: 4.3 | EZ19: 2.2 | FA19: 1.2 | FB19: 1.2 | FC19: 0 | FD19: 5.8 | FE19: 10 | FF19: 8.9 | FG19: 27.1 | FH19: 34.3 | FK19: 7 | FL19: 11.1 | FM19: 18 | FN19: 6373.2173 | FP19: 17.32822 | FQ19: 0 | FR19: 11.82275 | FS19: 8 | FT19: 27.02326 | FU19: 18.94093 | FV19: 4.5 | FW19: 15.9 | FX19: 103.51516
A20: 27/12/2025 | B20: 05:00 | C20: 203.5 | D20: 499.2 | E20: 164.2 | H20: 67.9 | I20: 187.5 | K20: 78.8 | L20: 183.1 | N20: 202.9 | P20: 210.2 | R20: 276.7 | S20: 9.2 | X20: 167.9 | Y20: 7.6 | Z20: 5.2 | AA20: 22.1 | AB20: 7 | AC20: 14.6 | AD20: 90.6 | AI20: 110.8 | AJ20: 0 | AN20: 6.5 | AO20: 0 | AP20: 20 | AQ20: 58 | AR20: 16.4 | AS20: 16.2 | AT20: 13.7 | AU20: 88.3 | AV20: 181.85122 | AW20: 182.38986 | AX20: 184.3813 | AY20: 109.062 | AZ20: 0 | BA20: 27.969 | BB20: 4.084 | BC20: 33.31 | BD20: 41.928 | BG20: 46.4 | BJ20: 0 | BN20: 84.5 | BO20: 160 | BP20: 159.8 | BQ20: 159.9 | BR20: 243.5 | BS20: 73 | BT20: 36.2 | CB20: 135.6 | CC20: 49.9 | CD20: 62.8 | CE20: 61 | CF20: 30.2 | CG20: 65.2 | CJ20: 144.8 | CK20: 145.7 | CL20: 170.5 | CM20: 188.5 | CR20: 212.5 | CS20: 102 | CT20: 3.2 | CV20: 4.4 | CW20: 0 | CX20: 67.2 | CY20: 0 | CZ20: 0.5 | DA20: 0 | DB20: 5.1 | DC20: 9.9 | DD20: 5 | DE20: 0 | DF20: 1 | DG20: 1.6 | DH20: 4 | DI20: 18.5 | DJ20: 11.2 | DK20: 13.5 | DL20: 2.3 | DM20: 17.2 | DN20: 0.1 | DO20: 0 | DP20: 13 | DQ20: 33.5 | DR20: 0 | DS20: 2.3 | DT20: 11.9 | DU20: 3 | DW20: 0 | DX20: 4.1 | DY20: 8.3 | DZ20: 11.7 | EA20: 16.3 | EB20: 17.6 | EC20: 26.3 | ED20: 38.5 | EE20: 0 | EF20: 3.8 | EG20: 11.8 | EH20: 0 | EI20: 0 | EJ20: 0 | EK20: 9 | EL20: 2.8 | EM20: 8.5 | EN20: 20.4 | EO20: 20.4 | EP20: 20.1 | EQ20: 0.8 | ER20: 0 | ES20: 0 | ET20: 0 | EU20: 0.6 | EV20: 0 | EW20: 0.5 | EX20: 0 | EY20: 4.3 | EZ20: 2.2 | FA20: 1.2 | FB20: 1.2 | FC20: 0 | FD20: 5.7 | FE20: 10 | FF20: 8.1 | FG20: 27.3 | FH20: 34.4 | FK20: 9 | FL20: 11.1 | FM20: 19.7 | FN20: 6409.1754 | FP20: 16.93915 | FQ20: 0 | FR20: 11.82312 | FS20: 8 | FT20: 27.03878 | FU20: 18.94107 | FV20: 4.5 | FW20: 9.9 | FX20: 97.14212
A21: 27/12/2025 | B21: 05:30 | C21: 203.1 | D21: 498.7 | E21: 167.6 | H21: 68.1 | I21: 176.4 | K21: 78.5 | L21: 185.3 | N21: 204.3 | P21: 209.3 | R21: 82.3 | S21: 9.2 | X21: 163.7 | Y21: 7.2 | Z21: 5.2 | AA21: 22 | AB21: 6.9 | AC21: 14.6 | AD21: 91 | AI21: 110.9 | AJ21: 0 | AN21: 6.5 | AO21: 0 | AP21: 20.2 | AQ21: 69.7 | AR21: 17 | AS21: 16.2 | AT21: 13.9 | AU21: 87.4 | AV21: 181.71989 | AW21: 181.64003 | AX21: 185.36264 | AY21: 104.765 | AZ21: 0 | BA21: 27.726 | BB21: 4.088 | BC21: 32.54 | BD21: 83.155 | BG21: 45.9 | BJ21: 0 | BN21: 82.8 | BO21: 170.8 | BP21: 168 | BQ21: 171.6 | BR21: 255 | BS21: 73.8 | BT21: 36.4 | CB21: 155.2 | CC21: 75.2 | CD21: 65.7 | CE21: 62.9 | CF21: 29.9 | CG21: 65.4 | CJ21: 144.5 | CK21: 145.4 | CL21: 171.1 | CM21: 188.8 | CR21: 212.9 | CS21: 101.9 | CT21: 3.2 | CV21: 4.3 | CW21: 0 | CX21: 78.4 | CY21: 0.1 | CZ21: 0 | DA21: 0 | DB21: 5.2 | DC21: 9.9 | DD21: 5.4 | DE21: 2.2 | DF21: 1 | DG21: 1.6 | DH21: 4 | DI21: 19.7 | DJ21: 11.2 | DK21: 13.6 | DL21: 2.3 | DM21: 17.2 | DN21: 0.6 | DO21: 0.7 | DP21: 22.5 | DQ21: 36.2 | DR21: 1 | DS21: 2.4 | DT21: 11.9 | DU21: 2.9 | DW21: 0 | DX21: 4.1 | DY21: 8.3 | DZ21: 11.2 | EA21: 16.9 | EB21: 17.6 | EC21: 27.3 | ED21: 50.8 | EE21: 0.3 | EF21: 3.1 | EG21: 11.9 | EH21: 0 | EI21: 0 | EJ21: 0 | EK21: 9 | EL21: 2.8 | EM21: 8.5 | EN21: 20.4 | EO21: 20.4 | EP21: 20.1 | EQ21: 0.3 | ER21: 2.6 | ES21: 0 | ET21: 0.2 | EU21: 0.6 | EV21: 0 | EW21: 0.6 | EX21: 0.3 | EY21: 4.3 | EZ21: 2.2 | FA21: 1.2 | FB21: 1.2 | FC21: 0 | FD21: 5.7 | FE21: 10 | FF21: 9 | FG21: 26.9 | FH21: 34.1 | FK21: 8.7 | FL21: 11.1 | FM21: 18.8 | FN21: 6387.3966 | FP21: 16.96382 | FQ21: 0 | FR21: 11.03738 | FS21: 8 | FT21: 27.03619 | FU21: 18.9409 | FV21: 4.4 | FW21: 9.8 | FX21: 96.17829
A22: 27/12/2025 | B22: 06:00 | C22: 203.5 | D22: 500.6 | E22: 163.5 | H22: 68.4 | I22: 189 | K22: 79 | L22: 184.6 | N22: 202.7 | P22: 210.8 | R22: 77.8 | S22: 9.4 | X22: 167 | Y22: 7.6 | Z22: 5.2 | AA22: 22.1 | AB22: 7 | AC22: 14.6 | AD22: 90.4 | AI22: 111 | AJ22: 0 | AN22: 6.5 | AO22: 0 | AP22: 29.8 | AQ22: 54.9 | AR22: 18.2 | AS22: 16 | AT22: 14 | AU22: 89.9 | AV22: 181.90811 | AW22: 182.77728 | AX22: 184.58281 | AY22: 108.576 | AZ22: 0 | BA22: 27.985 | BB22: 4.086 | BC22: 32.82 | BD22: 52.624 | BG22: 17.3 | BJ22: 0 | BN22: 84.2 | BO22: 145 | BP22: 145 | BQ22: 145.3 | BR22: 234.2 | BS22: 74.5 | BT22: 36.5 | CB22: 113.2 | CC22: 61.6 | CD22: 65.9 | CE22: 63 | CF22: 30.3 | CG22: 65.8 | CJ22: 145.3 | CK22: 146 | CL22: 171.6 | CM22: 188.4 | CR22: 213.3 | CS22: 102.2 | CT22: 3.2 | CV22: 4.3 | CW22: 0 | CX22: 83.1 | CY22: 19.7 | CZ22: 0 | DA22: 0 | DB22: 7.3 | DC22: 9.8 | DD22: 5.2 | DE22: 17.8 | DF22: 1 | DG22: 1.6 | DH22: 4 | DI22: 20.5 | DJ22: 11.2 | DK22: 13.5 | DL22: 2.2 | DM22: 17.1 | DN22: 1.4 | DO22: 1.6 | DP22: 23.7 | DQ22: 46.6 | DR22: 2.6 | DS22: 2.4 | DT22: 11 | DU22: 2.9 | DW22: 0.043 | DX22: 4.1 | DY22: 8.1 | DZ22: 11.5 | EA22: 17 | EB22: 17.6 | EC22: 25.1 | ED22: 53.3 | EE22: 1.4 | EF22: 2.3 | EG22: 13.6 | EH22: 0 | EI22: 0 | EJ22: 0.86 | EK22: 9.3 | EL22: 2.9 | EM22: 9.1 | EN22: 20.4 | EO22: 20.4 | EP22: 20.1 | EQ22: 0 | ER22: 19.6 | ES22: 0.8 | ET22: 3.6 | EU22: 0.6 | EV22: 1.7 | EW22: 2.9 | EX22: 3 | EY22: 4.3 | EZ22: 2.2 | FA22: 1.2 | FB22: 1.2 | FC22: 0.5 | FD22: 5.8 | FE22: 9.9 | FF22: 8.8 | FG22: 26.8 | FH22: 34.2 | FK22: 9.3 | FL22: 11.1 | FM22: 19 | FN22: 6284.7622 | FP22: 16.98385 | FQ22: 0 | FR22: 10.53769 | FS22: 8 | FT22: 27.0391 | FU22: 18.94045 | FV22: 4.5 | FW22: 9.9 | FX22: 95.90109
... A58: 28/12/2025 | B58: 00:00 | C58: 202.6 | D58: 399.8 | E58: 128.5 | H58: 90.2 | I58: 173.8 | K58: 79.1 | L58: 183.1 | N58: 202.4 | P58: 210.9 | R58: 179.4 | S58: 9.4 | X58: 164.2 | Y58: 7.4 | Z58: 5.1 | AA58: 22.2 | AB58: 6.8 | AC58: 14.6 | AD58: 83.8 | AI58: 110.9 | AJ58: 80.4 | AN58: 6.5 | AO58: 156.1 | AP58: 29.5 | AQ58: 138.8 | AR58: 14.6 | AS58: 15.8 | AT58: 17.1 | AU58: 91.5 | AV58: 180.94506 | AW58: 181.95228 | AX58: 184.52308 | AY58: 108.67 | AZ58: 32.13 | BA58: 28.05 | BB58: 4.05 | BC58: 32.73 | BD58: 54.2 | BG58: 54.7 | BJ58: 20.5 | BN58: 127.9 | BO58: 171.3 | BP58: 169.9 | BQ58: 171.8 | BR58: 252.9 | BS58: 74 | BT58: 36.2 | CB58: 228.9 | CC58: 74.8 | CD58: 64.4 | CE58: 65 | CF58: 29.5 | CG58: 118.9 | CJ58: 143.7 | CK58: 144.6 | CL58: 170.2 | CM58: 187.6 | CR58: 211.9 | CS58: 101.6 | CT58: 3.4 | CV58: 4.2 | CW58: 0 | CX58: 117.2 | CY58: 0 | CZ58: 0 | DA58: 0 | DB58: 8.8 | DC58: 9.9 | DD58: 5.5 | DE58: 0 | DF58: 1.2 | DG58: 1.7 | DH58: 3.8 | DI58: 20.4 | DJ58: 9.2 | DK58: 13.2 | DL58: 2.4 | DM58: 17.1 | DN58: 0 | DO58: 0 | DP58: 29.6 | DQ58: 66.5 | DR58: 0 | DS58: 2 | DT58: 19.9 | DU58: 3 | DW58: 0 | DX58: 4.5 | DY58: 8.5 | DZ58: 11.7 | EA58: 13.9 | EB58: 16.4 | EC58: 18.8 | ED58: 15.3 | EE58: 0 | EF58: 28.7 | EG58: 0 | EH58: 3.3 | EI58: 0.8 | EJ58: 0 | EK58: 9.1 | EL58: 2.8 | EM58: 8.5 | EN58: 20.4 | EO58: 20.4 | EP58: 20.1 | EQ58: 0 | ER58: 0 | ES58: 0 | ET58: 0 | EU58: 0.6 | EV58: 19.8 | EW58: 17.9 | EX58: 0 | EY58: 4.3 | EZ58: 2.2 | FA58: 1.2 | FB58: 1.2 | FC58: 0 | FD58: 5.8 | FE58: 10 | FF58: 8.9 | FG58: 27.1 | FH58: 34.8 | FK58: 8.6 | FL58: 11.2 | FM58: 19.7 | FN58: 6967.5504 | FP58: 13.12036 | FQ58: 0 | FR58: 11.76712 | FS58: 7.8 | FT58: 26.92346 | FU58: 18.94201 | FV58: 4.7 | FW58: 7.8 | FX58: 91.05295
A59: EJEC | C59: 4872.95 | D59: 10871.15 | E59: 3600.2 | F59: 0 | G59: 0 | H59: 1860.95 | I59: 4165 | J59: 0 | K59: 1675.5 | L59: 4374.7 | M59: 0 | N59: 4841.25 | O59: 0 | P59: 4992.5 | Q59: 0 | R59: 3435.55 | S59: 227.2 | T59: 0 | U59: 0 | V59: 0 | W59: 0 | X59: 3966.35 | Y59: 189.6 | Z59: 132.85 | AA59: 521.95 | AB59: 163.1 | AC59: 345.4 | AD59: 2220.25 | AE59: 0 | AF59: 0 | AG59: 0 | AH59: 0 | AI59: 2654.6 | AJ59: 1267.75 | AK59: 0 | AL59: 0 | AM59: 0 | AN59: 156 | AO59: 1166.75 | AP59: 649.5 | AQ59: 2295.95 | AR59: 349.4 | AS59: 382.45 | AT59: 342.3 | AU59: 2158.35 | AV59: 4346.9605 | AW59: 4357.9993 | AX59: 4426.9911 | AY59: 2571.487 | AZ59: 191.3545 | BA59: 643.3985 | BB59: 97.6475 | BC59: 786.34 | BD59: 1242.067 | BE59: 0 | BF59: 0 | BG59: 1415.4 | BH59: 0 | BI59: 0 | BJ59: 786.05 | BK59: 0 | BL59: 0 | BM59: 0 | BN59: 2193.5 | BO59: 3907.15 | BP59: 3892.8 | BQ59: 4023.35 | BR59: 5965.45 | BS59: 1765.2 | BT59: 862.1 | BU59: 0 | BV59: 0 | BW59: 0 | BX59: 0 | BY59: 0 | BZ59: 0 | CA59: 0 | CB59: 3348.2 | CC59: 1607.2 | CD59: 1538.3 | CE59: 1527.05 | CF59: 711.2 | CG59: 2522.4 | CH59: 0 | CI59: 0 | CJ59: 3444.2 | CK59: 3463.8 | CL59: 4075 | CM59: 4459.95 | CN59: 0 | CO59: 0 | CP59: 0 | CQ59: 0 | CR59: 5049.85 | CS59: 2420.55 | CT59: 79.15 | CU59: 0 | CV59: 104.55 | CW59: 8.45 | CX59: 2118.4 | CY59: 760.2 | CZ59: 41.8 | DA59: 3 | DB59: 279.05 | DC59: 237.95 | DD59: 126.7 | DE59: 2163.9 | DF59: 26.9 | DG59: 40.1 | DH59: 99.45 | DI59: 473.55 | DJ59: 249.65 | DK59: 327.7 | DL59: 55.05 | DM59: 410.2 | DN59: 128.15 | DO59: 161.25 | DP59: 510.15 | DQ59: 1387.8 | DR59: 154.35 | DS59: 55.4 | DT59: 355.85 | DU59: 70.75 | DV59: 0 | DW59: 3.044 | DX59: 103.35 | DY59: 191.45 | DZ59: 258.25 | EA59: 357.05 | EB59: 407.8 | EC59: 623.25 | ED59: 1148.35 | EE59: 296 | EF59: 909.35 | EG59: 1455.1 | EH59: 105.6 | EI59: 73 | EJ59: 394.335 | EK59: 220.9 | EL59: 69.35 | EM59: 202.1 | EN59: 489.6 | EO59: 489.6 | EP59: 482.4 | EQ59: 46.05 | ER59: 2451.85 | ES59: 136.7 | ET59: 1264.25 | EU59: 14.4 | EV59: 1150.8 | EW59: 1164.45 | EX59: 975.05 | EY59: 102.45 | EZ59: 52.75 | FA59: 28.8 | FB59: 28.8 | FC59: 123.1 | FD59: 137.15 | FE59: 239.95 | FF59: 211.35 | FG59: 650.8 | FH59: 826 | FI59: 0 | FJ59: 0 | FK59: 199.9 | FL59: 266.35 | FM59: 451 | FN59: 170753.72 | FP59: 317.71965 | FQ59: 58.9615 | FR59: 270.17478 | FS59: 188.3 | FT59: 636.13482 | FU59: 454.52832 | FV59: 100.95 | FW59: 280.95 | FX59: 2307.7191

Sheet REACTIVA
B3: sábado, 27 de Diciembre del 2025
A5: POTENCIA REACTIVA EJECUTADA DE LAS UNIDADES DE GENERACIÓN DEL COES (MVAR) | FP5: CENTRALES NO INTEGRANTES COES
A6: FECHA | B6: HORA | C6: 65333 | D6: 101 | E6: 102 | F6: 42667 | G6: 42668 | H6: 126 | I6: 127 | J6: 138 | K6: 139 | L6: 197 | M6: 203 | N6: 204 | O6: 230 | P6: 209 | Q6: 56677 | R6: 796 | S6: 2146 | T6: 142 | U6: 143 | V6: 125 | W6: 187 | X6: 163 | Y6: 298 | Z6: 299 | AA6: 219 | AB6: 151 | AC6: 152 | AD6: 153 | AE6: 154 | AF6: 756 | AG6: 156 | AH6: 155 | AI6: 182 | AJ6: 212 | AK6: 758 | AL6: 263 | AM6: 265 | AN6: 775 | AO6: 777 | AP6: 2154 | AQ6: 150 | AR6: 149 | AS6: 188 | AT6: 2131 | AU6: 755 | AV6: 252 | AW6: 249 | AX6: 250 | AY6: 117 | AZ6: 119 | BA6: 120 | BB6: 189 | BC6: 122 | BD6: 266 | BE6: 337 | BF6: 338 | BG6: 251 | BH6: 115 | BI6: 239 | BJ6: 288 | BK6: 240 | BL6: 241 | BM6: 242 | BN6: 191 | BO6: 194 | BP6: 196 | BQ6: 207 | BR6: 236 | BS6: 795 | BT6: 285 | BU6: 995 | BV6: 996 | BW6: 997 | BX6: 766 | BY6: 926 | BZ6: 924 | CA6: 121 | CB6: 103 | CC6: 104 | CD6: 106 | CE6: 105 | CF6: 107 | CG6: 110 | CH6: 109 | CI6: 144 | CJ6: 113 | CK6: 114 | CL6: 193 | CM6: 208 | CN6: 786 | CO6: 787 | CP6: 788 | CQ6: 789 | CR6: 248 | CS6: 2159 | CT6: 267 | CU6: 268 | CV6: 2194 | CW6: 303 | CX6: 59715 | CY6: 62255 | CZ6: 1263 | DA6: 61800 | DB6: 69125 | DC6: 216 | DD6: 198 | DE6: 70400 | DF6: 49607 | DG6: 214 | DH6: 260 | DI6: 2152 | DJ6: 2128 | DK6: 247 | DL6: 228 | DM6: 2135 | DN6: 261 | DO6: 237 | DP6: 253 | DQ6: 770 | DR6: 235 | DS6: 238 | DT6: 2184 | DU6: 61855 | DV6: 223 | DW6: 75566 | DX6: 226 | DY6: 201 | DZ6: 258 | EA6: 259 | EB6: 920 | EC6: 257 | ED6: 256 | EE6: 2148 | EF6: 58288 | EG6: 58289 | EH6: 58839 | EI6: 58840 | EJ6: 75260 | EK6: 296 | EL6: 297 | EM6: 211 | EN6: 2175 | EO6: 2178 | EP6: 2181 | EQ6: 1262 | ER6: 63425 | ES6: 233 | ET6: 2150 | EU6: 2165 | EV6: 2161 | EW6: 61197 | EX6: 58851 | EY6: 225 | EZ6: 2201 | FA6: 2171 | FB6: 760 | FC6: 234 | FD6: 215 | FE6: 917 | FF6: 289 | FG6: 58333 | FH6: 58336 | FI6: 213 | FJ6: 232 | FK6: 2190 | FL6: 69867 | FM6: 75066 | FN6: TOTAL COES | FP6: 221 | FQ6: 222 | FR6: 224 | FS6: 2187 | FT6: 227 | FU6: 49400 | FV6: 199 | FW6: 200 | FX6: TOTAL NO COES
C7: SUR | D7: CENTRO | E7: CENTRO | F7: NORTE | G7: NORTE | H7: NORTE | I7: NORTE | J7: CENTRO | K7: CENTRO | L7: CENTRO | M7: CENTRO | N7: CENTRO | O7: CENTRO | P7: CENTRO | Q7: CENTRO | R7: CENTRO | S7: CENTRO | T7: CENTRO | U7: CENTRO | V7: CENTRO | W7: CENTRO | X7: SUR | Y7: SUR | Z7: SUR | AA7: CENTRO | AB7: SUR | AC7: SUR | AD7: SUR | AE7: SUR | AF7: SUR | AG7: SUR | AH7: SUR | AI7: SUR | AJ7: CENTRO | AK7: NORTE | AL7: NORTE | AM7: NORTE | AN7: CENTRO | AO7: CENTRO | AP7: CENTRO | AQ7: CENTRO | AR7: CENTRO | AS7: CENTRO | AT7: CENTRO | AU7: SUR | AV7: CENTRO | AW7: CENTRO | AX7: CENTRO | AY7: CENTRO | AZ7: CENTRO | BA7: CENTRO | BB7: SUR | BC7: NORTE | BD7: CENTRO | BE7: CENTRO | BF7: CENTRO | BG7: CENTRO | BH7: NORTE | BI7: NORTE | BJ7: NORTE | BK7: SUR | BL7: SUR | BM7: SUR | BN7: CENTRO | BO7: CENTRO | BP7: CENTRO | BQ7: CENTRO | BR7: CENTRO | BS7: CENTRO | BT7: CENTRO | BU7: SUR | BV7: SUR | BW7: SUR | BX7: NORTE | BY7: SUR | BZ7: CENTRO | CA7: NORTE | CB7: CENTRO | CC7: CENTRO | CD7: CENTRO | CE7: CENTRO | CF7: CENTRO | CG7: CENTRO | CH7: CENTRO | CI7: CENTRO | CJ7: CENTRO | CK7: CENTRO | CL7: CENTRO | CM7: CENTRO | CN7: SUR | CO7: SUR | CP7: SUR | CQ7: SUR | CR7: CENTRO | CS7: CENTRO | CT7: CENTRO | CU7: CENTRO | CV7: NORTE | CW7: CENTRO | CX7: CENTRO | CY7: SUR | CZ7: NORTE | DA7: NORTE | DB7: CENTRO | DC7: NORTE | DD7: NORTE | DE7: SUR | DF7: SUR | DG7: CENTRO | DH7: CENTRO | DI7: CENTRO | DJ7: NORTE | DK7: NORTE | DL7: CENTRO | DM7: CENTRO | DN7: SUR | DO7: SUR | DP7: CENTRO | DQ7: CENTRO | DR7: SUR | DS7: CENTRO | DT7: CENTRO | DU7: NORTE | DV7: CENTRO | DW7: CENTRO | DX7: CENTRO | DY7: NORTE | DZ7: CENTRO | EA7: CENTRO | EB7: CENTRO | EC7: NORTE | ED7: NORTE | EE7: SUR | EF7: CENTRO | EG7: CENTRO | EH7: CENTRO | EI7: CENTRO | EJ7: SUR | EK7: CENTRO | EL7: CENTRO | EM7: SUR | EN7: SUR | EO7: SUR | EP7: SUR | EQ7: NORTE | ER7: SUR | ES7: SUR | ET7: SUR | EU7: CENTRO | EV7: CENTRO | EW7: CENTRO | EX7: SUR | EY7: CENTRO | EZ7: CENTRO | FA7: CENTRO | FB7: CENTRO | FC7: SUR | FD7: NORTE | FE7: CENTRO | FF7: NORTE | FG7: NORTE | FH7: NORTE | FI7: CENTRO | FJ7: NORTE | FK7: NORTE | FL7: NORTE | FM7: NORTE | FP7: NORTE | FQ7: CENTRO | FR7: NORTE | FS7: NORTE | FT7: NORTE | FU7: NORTE | FV7: NORTE | FW7: NORTE
C8: HIDROELÉCTRICA | D8: HIDROELÉCTRICA | E8: HIDROELÉCTRICA | F8: TERMOELÉCTRICA | G8: TERMOELÉCTRICA | H8: HIDROELÉCTRICA | I8: HIDROELÉCTRICA | J8: TERMOELÉCTRICA | K8: TERMOELÉCTRICA | L8: TERMOELÉCTRICA | M8: TERMOELÉCTRICA | N8: TERMOELÉCTRICA | O8: TERMOELÉCTRICA | P8: TERMOELÉCTRICA | Q8: TERMOELÉCTRICA | R8: HIDROELÉCTRICA | S8: HIDROELÉCTRICA | T8: TERMOELÉCTRICA | U8: TERMOELÉCTRICA | V8: TERMOELÉCTRICA | W8: TERMOELÉCTRICA | X8: HIDROELÉCTRICA | Y8: HIDROELÉCTRICA | Z8: HIDROELÉCTRICA | AA8: TERMOELÉCTRICA | AB8: HIDROELÉCTRICA | AC8: HIDROELÉCTRICA | AD8: HIDROELÉCTRICA | AE8: HIDROELÉCTRICA | AF8: TERMOELÉCTRICA | AG8: TERMOELÉCTRICA | AH8: TERMOELÉCTRICA | AI8: HIDROELÉCTRICA | AJ8: HIDROELÉCTRICA | AK8: TERMOELÉCTRICA | AL8: TERMOELÉCTRICA | AM8: TERMOELÉCTRICA | AN8: HIDROELÉCTRICA | AO8: HIDROELÉCTRICA | AP8: HIDROELÉCTRICA | AQ8: HIDROELÉCTRICA | AR8: HIDROELÉCTRICA | AS8: HIDROELÉCTRICA | AT8: HIDROELÉCTRICA | AU8: HIDROELÉCTRICA | AV8: TERMOELÉCTRICA | AW8: TERMOELÉCTRICA | AX8: TERMOELÉCTRICA | AY8: HIDROELÉCTRICA | AZ8: HIDROELÉCTRICA | BA8: HIDROELÉCTRICA | BB8: HIDROELÉCTRICA | BC8: HIDROELÉCTRICA | BD8: HIDROELÉCTRICA | BE8: HIDROELÉCTRICA | BF8: HIDROELÉCTRICA | BG8: HIDROELÉCTRICA | BH8: TERMOELÉCTRICA | BI8: TERMOELÉCTRICA | BJ8: TERMOELÉCTRICA | BK8: TERMOELÉCTRICA | BL8: TERMOELÉCTRICA | BM8: TERMOELÉCTRICA | BN8: HIDROELÉCTRICA | BO8: TERMOELÉCTRICA | BP8: TERMOELÉCTRICA | BQ8: TERMOELÉCTRICA | BR8: TERMOELÉCTRICA | BS8: TERMOELÉCTRICA | BT8: TERMOELÉCTRICA | BU8: TERMOELÉCTRICA | BV8: TERMOELÉCTRICA | BW8: TERMOELÉCTRICA | BX8: HIDROELÉCTRICA | BY8: TERMOELÉCTRICA | BZ8: TERMOELÉCTRICA | CA8: HIDROELÉCTRICA | CB8: HIDROELÉCTRICA | CC8: HIDROELÉCTRICA | CD8: HIDROELÉCTRICA | CE8: HIDROELÉCTRICA | CF8: HIDROELÉCTRICA | CG8: TERMOELÉCTRICA | CH8: TERMOELÉCTRICA | CI8: TERMOELÉCTRICA | CJ8: TERMOELÉCTRICA | CK8: TERMOELÉCTRICA | CL8: TERMOELÉCTRICA | CM8: TERMOELÉCTRICA | CN8: TERMOELÉCTRICA | CO8: TERMOELÉCTRICA | CP8: TERMOELÉCTRICA | CQ8: TERMOELÉCTRICA | CR8: TERMOELÉCTRICA | CS8: TERMOELÉCTRICA | CT8: HIDROELÉCTRICA | CU8: HIDROELÉCTRICA | CV8: HIDROELÉCTRICA | CW8: SOLAR | CX8: EÓLICA | CY8: SOLAR | CZ8: EÓLICA | DA8: SOLAR | DB8: HIDROELÉCTRICA | DC8: HIDROELÉCTRICA | DD8: HIDROELÉCTRICA | DE8: SOLAR | DF8: HIDROELÉCTRICA | DG8: HIDROELÉCTRICA | DH8: HIDROELÉCTRICA | DI8: HIDROELÉCTRICA | DJ8: HIDROELÉCTRICA | DK8: HIDROELÉCTRICA | DL8: HIDROELÉCTRICA | DM8: HIDROELÉCTRICA | DN8: SOLAR | DO8: SOLAR | DP8: EÓLICA | DQ8: EÓLICA | DR8: SOLAR | DS8: HIDROELÉCTRICA | DT8: HIDROELÉCTRICA | DU8: HIDROELÉCTRICA | DV8: HIDROELÉCTRICA | DW8: SOLAR | DX8: HIDROELÉCTRICA | DY8: HIDROELÉCTRICA | DZ8: HIDROELÉCTRICA | EA8: HIDROELÉCTRICA | EB8: HIDROELÉCTRICA | EC8: EÓLICA | ED8: EÓLICA | EE8: SOLAR | EF8: EÓLICA | EG8: EÓLICA | EH8: EÓLICA | EI8: EÓLICA | EJ8: SOLAR | EK8: HIDROELÉCTRICA | EL8: HIDROELÉCTRICA | EM8: HIDROELÉCTRICA | EN8: HIDROELÉCTRICA | EO8: HIDROELÉCTRICA | EP8: HIDROELÉCTRICA | EQ8: EÓLICA | ER8: SOLAR | ES8: SOLAR | ET8: SOLAR | EU8: HIDROELÉCTRICA | EV8: EÓLICA | EW8: EÓLICA | EX8: SOLAR | EY8: TERMOELÉCTRICA | EZ8: TERMOELÉCTRICA | FA8: TERMOELÉCTRICA | FB8: TERMOELÉCTRICA | FC8: SOLAR | FD8: HIDROELÉCTRICA | FE8: HIDROELÉCTRICA | FF8: TERMOELÉCTRICA | FG8: TERMOELÉCTRICA | FH8: TERMOELÉCTRICA | FI8: TERMOELÉCTRICA | FJ8: TERMOELÉCTRICA | FK8: TERMOELÉCTRICA | FL8: TERMOELÉCTRICA | FM8: TERMOELÉCTRICA | FP8: HIDROELÉCTRICA | FQ8: HIDROELÉCTRICA | FR8: HIDROELÉCTRICA | FS8: HIDROELÉCTRICA | FT8: TERMOELÉCTRICA | FU8: TERMOELÉCTRICA | FV8: HIDROELÉCTRICA | FW8: HIDROELÉCTRICA
