Workbook

Sheet EVENTOS
B3: martes, 22 de Julio del 2025
B5: INFORMACIÓN DE EVENTOS PRINCIPALES EN SUS INSTALACIONES
B6: TIPO DE EVENTO | C6: EMPRESA | D6: UBICACIÓN | E6: TIPO DE EQUIPO | F6: EQUIPO | G6: INICIO | H6: FINAL | I6: DESCRIPCIÓN | J6: MW INDISP. | K6: INTERRUPCIÓN (SI/NO) | L6: TENSIÓN DE FALLA (kV)
B7: P.ENERG | C7: ATLANTICA TRANSMISION SUR S.A. | D7: MONTALVO | E7: TRANSFORMADOR 3D | F7: AUT-5672 | G7: 22/07/2025 13:50:00 | H7: 22/07/2025 13:50:00 | I7: PRIMERA ENERGIZACIÓN DEL AUTOTRANSFORMADOR AUT-5672 DE 500/220 KV EN LA S.E. MONTALVO | K7: NO
B8: EVENTO | C8: CONELSUR LT SAC | D8: PORTILLO | E8: SUBESTACION | F8: SS.EE. | G8: 22/07/2025 00:00:00 | H8: 23/07/2025 00:00:00 | I8: DECLARACIÓN DE SITUACIÓN EXCEPCIONAL EN LA S.E. PORTILLO DE 60 kV | K8: NO
B9: FALLA | C9: ISA PERU | D9: AGUAYTÍA - TINGO MARÍA | E9: LINEA DE TRANSMISION | F9: L-2251 | G9: 22/07/2025 10:36:00 | H9: 22/07/2025 11:22:00 | I9: DESCONEXIÓN DE LA LÍNEA L-2251 (TINGO MARÍA - AGUAYTÍA) DE 220 KV | K9: SI | L9: 220

Sheet RESTRIC_OPE
B3: martes, 22 de Julio del 2025
B5: RESTRICCIONES OPERATIVAS
B6: FECHA | C6: HORA INICIO | D6: HORA FINAL | E6: EMPRESA | F6: UBICACIÓN | G6: T.Eq. | H6: EQUIPO | I6: DESCRIPCIÓN
B7: 22/07/2025 | C7: 00:00 | D7: 24:00 | E7: EGASA | F7: C.H. CHARCANI II | G7: GH | H7: G2 | I7: El Grupo N°02 esta operando con una potencia no mayor a 0.07MW en referencia a 0.18MW de su potencia efectiva, con el fin de no generar daños mayores hasta la reparación de su cojinete.
B8: 22/07/2025 | C8: 00:00 | D8: 24:00 | E8: EGASA | F8: S.E. CONVERTIDOR | G8: BARRA | H8: BARRA138KV | I8: EGASA limitó la capacidad del transformador 138 kV/33 kV a 50 MVA por deterioro del aislamiento.
B9: 22/07/2025 | C9: 00:00 | D9: 24:00 | E9: ENEL GENERACION PIURA S.A. | F9: C.T. MALACAS | G9: CT | H9: CENTRAL | I9: De acuerdo con la comunicación vía correo del día 24.10.2024. ENEL GENERACIÓN PIURA informa una restricción de potencia para alcanzar 105 MW en simultaneo (TG6+TGN4).
B10: 22/07/2025 | C10: 00:00 | D10: 24:00 | E10: ENEL GENERACION PIURA S.A. | F10: C.T. MALACAS | G10: GT | H10: TG4 | I10: De acuerdo a lo informado mediante correo electronico el día 04.07, la uniadTG4 puede operar a potencia efectiva durante 3 horas o con 80MW durante 4 horas, y el resto de los periodos a mínima generación.
B11: 22/07/2025 | C11: 00:00 | D11: 24:00 | E11: ENGIE | F11: C.E. PUNTA LOMITAS | G11: CE | H11: CENTRAL | I11: De acuerdo a la carta ENG/737-2024 (Exp:202400007555). Limitación de cables de media tensión a 100 MW de los transformadores PLT1 y PLT2 de la CE Punta Lomitas. Quedan limitados a 200 MW la generación de CE Punta Lomitas y Punta Lomitas Extensión.
B12: 22/07/2025 | C12: 00:00 | D12: 24:00 | E12: ENGIE | F12: C.H. YUNCÁN | G12: GH | H12: G3 | I12: Según la carta N° ENG/ 198-2024 enviada por su representada, se opera de forma continua el G3 de la CH Yuncán, debido a la ejecución de mantenimientos necesarios para evitar daños en los sellos de seguridad de la válvula esférica del grupo.
B13: 22/07/2025 | C13: 00:00 | D13: 24:00 | E13: ENGIE | F13: C.T. CHILCA 1 | G13: CT | H13: CENTRAL | I13: Restricción de temperatura de la C.T Chilca, ver valor en el modelo de despacho.
B14: 22/07/2025 | C14: 00:00 | D14: 24:00 | E14: ENGIE | F14: C.T. CHILCA 1 | G14: CT | H14: CENTRAL | I14: Con carta ENG/971-2023, indica que no puede cumplir con las IO considerada en el PDO_17122023 dado que vulneran la seguridad de sus activos. Indican que se debe tomar TMO=168h.
B15: 22/07/2025 | C15: 00:00 | D15: 24:00 | E15: ENGIE | F15: C.T. CHILCA 2 | G15: CT | H15: CENTRAL | I15: Restricción de temperatura de la C.T Chilca2, ver valor en el modelo de despacho.
B16: 22/07/2025 | C16: 00:00 | D16: 24:00 | E16: ENGIE | F16: C.T. CHILCA 2 | G16: CT | H16: CENTRAL | I16: Con carta ENG/971-2023, indica que no puede cumplir con las IO considerada en el PDO_17122023 dado que vulneran la seguridad de sus activos. Indican que se debe tomar TMO=168h.
B17: 22/07/2025 | C17: 00:00 | D17: 24:00 | E17: FENIX POWER PERÚ | F17: C.T. FENIX | G17: CT | H17: CENTRAL | I17: Restricción de temperatura de la CT FENIX, ver valor en el modelo de despacho
... B42: 22/07/2025 | C42: 00:00 | D42: 24:00 | E42: TERMOSELVA | F42: C.T. AGUAYTÍA | G42: CT | H42: CENTRAL | I42: Disponibilidad de 23.5 MMSCF para la CT Aguaytía.

Sheet MANTENIMIENTO EJECUTADOS
B3: martes, 22 de Julio del 2025
B5: Mantenimiento Ejecutado
B6: Empresa | C6: Ubicación | D6: Equipo | E6: Inicio | F6: Final | G6: Descripción | H6: MW Indisp. | I6: Prog. | J6: Dispon | K6: Interrupc. | L6: Tipo | M6: CodEq | N6: TipoEq_Osinerg
B7: ACEROS AREQUIPA | C7: INDEPENDENCIA | D7: SA-2259 | E7: 22/07/2025 06:00 | F7: 22/07/2025 12:00 | G7: Se requiere la liberacion de la Barra A en la S.E. Indepedencia para Mantenimiento del Seccionador SA-2259 perteneciente a Aceros Arequipa. | H7: 0 | I7: P | J7: F/S | K7: N | L7: PREV. | M7: 10926 | N7: T
B8: ACEROS AREQUIPA | C8: INDEPENDENCIA | D8: SB-2261 | E8: 22/07/2025 12:00 | F8: 22/07/2025 18:00 | G8: Se requiere la liberacion de la Barra B en la S.E. Indepedencia para Mantenimiento del Seccionador SB-2261 perteneciente a Aceros Arequipa. | H8: 0 | I8: P | J8: F/S | K8: N | L8: PREV. | M8: 10925 | N8: T
B9: ACEROS AREQUIPA | C9: INDEPENDENCIA - ACEROS AREQUIPA | D9: L-2217 | E9: 22/07/2025 06:00 | F9: 22/07/2025 18:00 | G9: Mantenimiento Preventivo de la L.T. 220KV L-2217 | H9: 155 | I9: P | J9: F/S | K9: S | L9: PREV. | M9: 748 | N9: T
B10: ATLANTICA TRANSMISION SUR S.A. | C10: MONTALVO | D10: BARRA A_220KV | E10: 22/07/2025 00:00 | F10: 23/07/2025 00:00 | G10: Proyecto Refuerzos: Indisponibilidad de la proteccion diferencial de barras 220 kV por Conexion de la nueva UB-87B hacia la UC existente,Configuracion y Pruebas. | H10: 0 | I10: P | J10: E/S | K10: N | L10: P.ENERG | M10: 13869 | N10: T
B11: ATLANTICA TRANSMISION SUR S.A. | C11: MONTALVO | D11: BARRA A_500KV | E11: 22/07/2025 00:00 | F11: 23/07/2025 00:00 | G11: Proyecto Refuerzos: Indisponibilidad de la proteccion diferencial de barras 500kV por conexion de nueva UB-87B hacia la UC existente, Configuracion y Pruebas. | H11: 0 | I11: P | J11: E/S | K11: N | L11: P.ENERG | M11: 13870 | N11: T
B12: ATLANTICA TRANSMISION SUR S.A. | C12: MONTALVO | D12: BARRA B_220kV | E12: 22/07/2025 00:00 | F12: 23/07/2025 00:00 | G12: Proyecto Refuerzos: Indisponibilidad de la proteccion diferencial de barras 220 kV por Conexion de la nueva UB-87B hacia la UC existente,Configuracion y Pruebas. | H12: 0 | I12: P | J12: E/S | K12: N | L12: P.ENERG | M12: 14765 | N12: T
B13: ATLANTICA TRANSMISION SUR S.A. | C13: MONTALVO | D13: BARRA B_500KV | E13: 22/07/2025 00:00 | F13: 23/07/2025 00:00 | G13: Proyecto Refuerzos: Indisponibilidad de la proteccion diferencial de barras 500kV por conexion de nueva UB-87B hacia la UC existente, Configuracion y Pruebas. | H13: 0 | I13: P | J13: E/S | K13: N | L13: P.ENERG | M13: 13871 | N13: T
B14: ATLANTICA TRANSMISION SUR S.A. | C14: MONTALVO | D14: INT-5652 | E14: 22/07/2025 00:00 | F14: 23/07/2025 00:00 | G14: Proyecto Refuerzos: Indisponible por Implementacion de Conexion de corrientes, disparos, posiciones, enclavamientos hacia los equipos del nuevo Autotransformador. AUT-5671 en servicio solo por Barra A 500kV. | H14: 0 | I14: P | J14: F/S | K14: N | L14: P.ENERG | M14: 13765 | N14: T
B15: ATLANTICA TRANSMISION SUR S.A. | C15: MONTALVO | D15: ACOPLE 220 | E15: 22/07/2025 12:01 | F15: 22/07/2025 17:23 | G15: Proyecto Refuerzos: Reemplazo del HMI existente, Pruebas y Configuracion. No se contara con nivel 1 de operacion. | H15: 0 | I15: P | J15: E/S | K15: N | L15: P.ENERG | M15: 14767 | N15: T
B16: ATLANTICA TRANSMISION SUR S.A. | C16: MONTALVO | D16: CL-2057 | E16: 22/07/2025 12:01 | F16: 22/07/2025 17:23 | G16: Proyecto Refuerzos: Reemplazo del HMI existente, Pruebas y Configuracion. No se contara con nivel 1 de operacion. | H16: 0 | I16: P | J16: E/S | K16: N | L16: P.ENERG | M16: 13812 | N16: T
B17: ATLANTICA TRANSMISION SUR S.A. | C17: MONTALVO | D17: CL-AUT-5671_500 | E17: 22/07/2025 12:01 | F17: 22/07/2025 17:23 | G17: Proyecto Refuerzos: Reemplazo del HMI existente, Pruebas y Configuracion. No se contara con nivel 1 de operacion en INT-5671, INT-5652 y SAT-5671. | H17: 0 | I17: P | J17: E/S | K17: N | L17: P.ENERG | M17: 13809 | N17: T
B18: ATLANTICA TRANSMISION SUR S.A. | C18: MONTALVO | D18: INT-5672 | E18: 22/07/2025 13:50 | F18: 23/07/2025 00:00 | G18: Proyecto Refuerzos: Puesta en servicio del nuevo tercio del diametro INT-5672. Energizacion en vacio por 34 horas de AUT-5672. Prueba con nuevo rele de mando sincronizado PSD | H18: 0 | I18: P | J18: E/S | K18: N | L18: P.ENERG | M18: 24277 | N18: T
... B150: TRANSMANTARO | C150: YARABAMBA | D150: IN-5120 | E150: 22/07/2025 00:00 | F150: 23/07/2025 00:00 | G150: INTERRUPTOR INDISPONIBLE POR FALLA EN LOS MANDOS DE CONTROL DE N1, N2 Y N3. | H150: 0 | I150: P | J150: F/S | K150: N | L150: OTROS | M150: 17437 | N150: T

Sheet INGRESO OC
A3: martes, 22 de Julio del 2025
A5: INGRESO A OPERACIÓN COMERCIAL
A6: EMPRESA | B6: TIPO DE EQUIPO | C6: UBICACIÓN | D6: EQUIPO | E6: Fecha y hora de Ingreso a Operación Comercial
A7: VARI ENERGIA S.A.C. | B7: GENERADOR HIDROELÉCTRICO | C7: ANASHIRONI | D7: ANASHIRONI G1 | E7: 23/07/2025 00:00:00
A8: VARI ENERGIA S.A.C. | B8: CENTRAL HIDROELÉCTRICA | C8: ANASHIRONI | D8: C.H. ANASHIRONI | E8: 23/07/2025 00:00:00

Sheet DESPACHO_EJECUTADO
B3: martes, 22 de Julio del 2025
A5: POTENCIA ACTIVA EJECUTADA DE LAS UNIDADES DE GENERACIÓN DEL SEIN (MW) | FK5: CENTRALES NO INTEGRANTES COES
A6: FECHA | B6: HORA | C6: 65333 | D6: 101 | E6: 102 | F6: 42667 | G6: 42668 | H6: 126 | I6: 127 | J6: 138 | K6: 139 | L6: 197 | M6: 203 | N6: 204 | O6: 230 | P6: 209 | Q6: 56677 | R6: 796 | S6: 2146 | T6: 142 | U6: 143 | V6: 125 | W6: 187 | X6: 163 | Y6: 298 | Z6: 299 | AA6: 219 | AB6: 151 | AC6: 152 | AD6: 153 | AE6: 154 | AF6: 756 | AG6: 156 | AH6: 155 | AI6: 182 | AJ6: 212 | AK6: 758 | AL6: 263 | AM6: 265 | AN6: 775 | AO6: 777 | AP6: 2154 | AQ6: 150 | AR6: 149 | AS6: 188 | AT6: 2131 | AU6: 755 | AV6: 252 | AW6: 249 | AX6: 250 | AY6: 117 | AZ6: 267 | BA6: 268 | BB6: 119 | BC6: 120 | BD6: 189 | BE6: 122 | BF6: 266 | BG6: 337 | BH6: 338 | BI6: 251 | BJ6: 115 | BK6: 239 | BL6: 288 | BM6: 240 | BN6: 241 | BO6: 242 | BP6: 191 | BQ6: 194 | BR6: 196 | BS6: 207 | BT6: 236 | BU6: 795 | BV6: 285 | BW6: 995 | BX6: 996 | BY6: 997 | BZ6: 766 | CA6: 926 | CB6: 924 | CC6: 121 | CD6: 103 | CE6: 104 | CF6: 106 | CG6: 105 | CH6: 107 | CI6: 110 | CJ6: 109 | CK6: 144 | CL6: 113 | CM6: 114 | CN6: 193 | CO6: 208 | CP6: 786 | CQ6: 787 | CR6: 788 | CS6: 789 | CT6: 248 | CU6: 2159 | CV6: 303 | CW6: 59715 | CX6: 62255 | CY6: 1263 | CZ6: 61800 | DA6: 2194 | DB6: 69125 | DC6: 216 | DD6: 198 | DE6: 49607 | DF6: 214 | DG6: 260 | DH6: 2152 | DI6: 2128 | DJ6: 247 | DK6: 228 | DL6: 2135 | DM6: 261 | DN6: 237 | DO6: 253 | DP6: 770 | DQ6: 225 | DR6: 2201 | DS6: 2171 | DT6: 760 | DU6: 235 | DV6: 238 | DW6: 2184 | DX6: 61855 | DY6: 223 | DZ6: 226 | EA6: 201 | EB6: 258 | EC6: 259 | ED6: 920 | EE6: 257 | EF6: 256 | EG6: 2148 | EH6: 58288 | EI6: 58289 | EJ6: 58839 | EK6: 58840 | EL6: 296 | EM6: 297 | EN6: 211 | EO6: 2175 | EP6: 2178 | EQ6: 2181 | ER6: 1262 | ES6: 63425 | ET6: 233 | EU6: 2150 | EV6: 2165 | EW6: 2161 | EX6: 61197 | EY6: 58851 | EZ6: 234 | FA6: 215 | FB6: 917 | FC6: 289 | FD6: 58333 | FE6: 58336 | FF6: 213 | FG6: 232 | FH6: 2190 | FI6: TOTAL COES | FK6: 221 | FL6: 222 | FM6: 224 | FN6: 2187 | FO6: 227 | FP6: 49400 | FQ6: 199 | FR6: 200 | FS6: TOTAL NO COES
C7: SUR | D7: CENTRO | E7: CENTRO | F7: NORTE | G7: NORTE | H7: NORTE | I7: NORTE | J7: CENTRO | K7: CENTRO | L7: CENTRO | M7: CENTRO | N7: CENTRO | O7: CENTRO | P7: CENTRO | Q7: CENTRO | R7: CENTRO | S7: CENTRO | T7: CENTRO | U7: CENTRO | V7: CENTRO | W7: CENTRO | X7: SUR | Y7: SUR | Z7: SUR | AA7: CENTRO | AB7: SUR | AC7: SUR | AD7: SUR | AE7: SUR | AF7: SUR | AG7: SUR | AH7: SUR | AI7: SUR | AJ7: CENTRO | AK7: NORTE | AL7: NORTE | AM7: NORTE | AN7: CENTRO | AO7: CENTRO | AP7: CENTRO | AQ7: CENTRO | AR7: CENTRO | AS7: CENTRO | AT7: CENTRO | AU7: SUR | AV7: CENTRO | AW7: CENTRO | AX7: CENTRO | AY7: CENTRO | AZ7: CENTRO | BA7: CENTRO | BB7: CENTRO | BC7: CENTRO | BD7: SUR | BE7: NORTE | BF7: CENTRO | BG7: CENTRO | BH7: CENTRO | BI7: CENTRO | BJ7: NORTE | BK7: NORTE | BL7: NORTE | BM7: SUR | BN7: SUR | BO7: SUR | BP7: CENTRO | BQ7: CENTRO | BR7: CENTRO | BS7: CENTRO | BT7: CENTRO | BU7: CENTRO | BV7: CENTRO | BW7: SUR | BX7: SUR | BY7: SUR | BZ7: NORTE | CA7: SUR | CB7: CENTRO | CC7: NORTE | CD7: CENTRO | CE7: CENTRO | CF7: CENTRO | CG7: CENTRO | CH7: CENTRO | CI7: CENTRO | CJ7: CENTRO | CK7: CENTRO | CL7: CENTRO | CM7: CENTRO | CN7: CENTRO | CO7: CENTRO | CP7: SUR | CQ7: SUR | CR7: SUR | CS7: SUR | CT7: CENTRO | CU7: CENTRO | CV7: CENTRO | CW7: CENTRO | CX7: SUR | CY7: NORTE | CZ7: NORTE | DA7: NORTE | DB7: CENTRO | DC7: NORTE | DD7: NORTE | DE7: SUR | DF7: CENTRO | DG7: CENTRO | DH7: CENTRO | DI7: NORTE | DJ7: NORTE | DK7: CENTRO | DL7: CENTRO | DM7: SUR | DN7: SUR | DO7: CENTRO | DP7: CENTRO | DQ7: CENTRO | DR7: CENTRO | DS7: CENTRO | DT7: CENTRO | DU7: SUR | DV7: CENTRO | DW7: CENTRO | DX7: NORTE | DY7: CENTRO | DZ7: CENTRO | EA7: NORTE | EB7: CENTRO | EC7: CENTRO | ED7: CENTRO | EE7: NORTE | EF7: NORTE | EG7: SUR | EH7: CENTRO | EI7: CENTRO | EJ7: CENTRO | EK7: CENTRO | EL7: CENTRO | EM7: CENTRO | EN7: SUR | EO7: SUR | EP7: SUR | EQ7: SUR | ER7: NORTE | ES7: SUR | ET7: SUR | EU7: SUR | EV7: CENTRO | EW7: CENTRO | EX7: CENTRO | EY7: SUR | EZ7: SUR | FA7: NORTE | FB7: CENTRO | FC7: NORTE | FD7: NORTE | FE7: NORTE | FF7: CENTRO | FG7: NORTE | FH7: NORTE | FK7: NORTE | FL7: CENTRO | FM7: NORTE | FN7: NORTE | FO7: NORTE | FP7: NORTE | FQ7: NORTE | FR7: NORTE
C8: HIDROELÉCTRICA | D8: HIDROELÉCTRICA | E8: HIDROELÉCTRICA | F8: TERMOELÉCTRICA | G8: TERMOELÉCTRICA | H8: HIDROELÉCTRICA | I8: HIDROELÉCTRICA | J8: TERMOELÉCTRICA | K8: TERMOELÉCTRICA | L8: TERMOELÉCTRICA | M8: TERMOELÉCTRICA | N8: TERMOELÉCTRICA | O8: TERMOELÉCTRICA | P8: TERMOELÉCTRICA | Q8: TERMOELÉCTRICA | R8: HIDROELÉCTRICA | S8: HIDROELÉCTRICA | T8: TERMOELÉCTRICA | U8: TERMOELÉCTRICA | V8: TERMOELÉCTRICA | W8: TERMOELÉCTRICA | X8: HIDROELÉCTRICA | Y8: HIDROELÉCTRICA | Z8: HIDROELÉCTRICA | AA8: TERMOELÉCTRICA | AB8: HIDROELÉCTRICA | AC8: HIDROELÉCTRICA | AD8: HIDROELÉCTRICA | AE8: HIDROELÉCTRICA | AF8: TERMOELÉCTRICA | AG8: TERMOELÉCTRICA | AH8: TERMOELÉCTRICA | AI8: HIDROELÉCTRICA | AJ8: HIDROELÉCTRICA | AK8: TERMOELÉCTRICA | AL8: TERMOELÉCTRICA | AM8: TERMOELÉCTRICA | AN8: HIDROELÉCTRICA | AO8: HIDROELÉCTRICA | AP8: HIDROELÉCTRICA | AQ8: HIDROELÉCTRICA | AR8: HIDROELÉCTRICA | AS8: HIDROELÉCTRICA | AT8: HIDROELÉCTRICA | AU8: HIDROELÉCTRICA | AV8: TERMOELÉCTRICA | AW8: TERMOELÉCTRICA | AX8: TERMOELÉCTRICA | AY8: HIDROELÉCTRICA | AZ8: HIDROELÉCTRICA | BA8: HIDROELÉCTRICA | BB8: HIDROELÉCTRICA | BC8: HIDROELÉCTRICA | BD8: HIDROELÉCTRICA | BE8: HIDROELÉCTRICA | BF8: HIDROELÉCTRICA | BG8: HIDROELÉCTRICA | BH8: HIDROELÉCTRICA | BI8: HIDROELÉCTRICA | BJ8: TERMOELÉCTRICA | BK8: TERMOELÉCTRICA | BL8: TERMOELÉCTRICA | BM8: TERMOELÉCTRICA | BN8: TERMOELÉCTRICA | BO8: TERMOELÉCTRICA | BP8: HIDROELÉCTRICA | BQ8: TERMOELÉCTRICA | BR8: TERMOELÉCTRICA | BS8: TERMOELÉCTRICA | BT8: TERMOELÉCTRICA | BU8: TERMOELÉCTRICA | BV8: TERMOELÉCTRICA | BW8: TERMOELÉCTRICA | BX8: TERMOELÉCTRICA | BY8: TERMOELÉCTRICA | BZ8: HIDROELÉCTRICA | CA8: TERMOELÉCTRICA | CB8: TERMOELÉCTRICA | CC8: HIDROELÉCTRICA | CD8: HIDROELÉCTRICA | CE8: HIDROELÉCTRICA | CF8: HIDROELÉCTRICA | CG8: HIDROELÉCTRICA | CH8: HIDROELÉCTRICA | CI8: TERMOELÉCTRICA | CJ8: TERMOELÉCTRICA | CK8: TERMOELÉCTRICA | CL8: TERMOELÉCTRICA | CM8: TERMOELÉCTRICA | CN8: TERMOELÉCTRICA | CO8: TERMOELÉCTRICA | CP8: TERMOELÉCTRICA | CQ8: TERMOELÉCTRICA | CR8: TERMOELÉCTRICA | CS8: TERMOELÉCTRICA | CT8: TERMOELÉCTRICA | CU8: TERMOELÉCTRICA | CV8: SOLAR | CW8: EÓLICA | CX8: SOLAR | CY8: EÓLICA | CZ8: SOLAR | DA8: HIDROELÉCTRICA | DB8: HIDROELÉCTRICA | DC8: HIDROELÉCTRICA | DD8: HIDROELÉCTRICA | DE8: HIDROELÉCTRICA | DF8: HIDROELÉCTRICA | DG8: HIDROELÉCTRICA | DH8: HIDROELÉCTRICA | DI8: HIDROELÉCTRICA | DJ8: HIDROELÉCTRICA | DK8: HIDROELÉCTRICA | DL8: HIDROELÉCTRICA | DM8: SOLAR | DN8: SOLAR | DO8: EÓLICA | DP8: EÓLICA | DQ8: TERMOELÉCTRICA | DR8: TERMOELÉCTRICA | DS8: TERMOELÉCTRICA | DT8: TERMOELÉCTRICA | DU8: SOLAR | DV8: HIDROELÉCTRICA | DW8: HIDROELÉCTRICA | DX8: HIDROELÉCTRICA | DY8: HIDROELÉCTRICA | DZ8: HIDROELÉCTRICA | EA8: HIDROELÉCTRICA | EB8: HIDROELÉCTRICA | EC8: HIDROELÉCTRICA | ED8: HIDROELÉCTRICA | EE8: EÓLICA | EF8: EÓLICA | EG8: SOLAR | EH8: EÓLICA | EI8: EÓLICA | EJ8: EÓLICA | EK8: EÓLICA | EL8: HIDROELÉCTRICA | EM8: HIDROELÉCTRICA | EN8: HIDROELÉCTRICA | EO8: HIDROELÉCTRICA | EP8: HIDROELÉCTRICA | EQ8: HIDROELÉCTRICA | ER8: EÓLICA | ES8: SOLAR | ET8: SOLAR | EU8: SOLAR | EV8: HIDROELÉCTRICA | EW8: EÓLICA | EX8: EÓLICA | EY8: SOLAR | EZ8: SOLAR | FA8: HIDROELÉCTRICA | FB8: HIDROELÉCTRICA | FC8: TERMOELÉCTRICA | FD8: TERMOELÉCTRICA | FE8: TERMOELÉCTRICA | FF8: TERMOELÉCTRICA | FG8: TERMOELÉCTRICA | FH8: TERMOELÉCTRICA | FK8: HIDROELÉCTRICA | FL8: HIDROELÉCTRICA | FM8: HIDROELÉCTRICA | FN8: HIDROELÉCTRICA | FO8: TERMOELÉCTRICA | FP8: TERMOELÉCTRICA | FQ8: HIDROELÉCTRICA | FR8: HIDROELÉCTRICA
C9: HYDRO GLOBAL PERÚ S.A.C. | D9: ELECTROPERU | E9: ELECTROPERU | F9: ELECTROPERU | G9: ELECTROPERU | H9: ORAZUL ENERGY PERÚ | I9: ORAZUL ENERGY PERÚ | J9: TERMOSELVA | K9: TERMOSELVA | L9: KALLPA GENERACION S.A. | M9: KALLPA GENERACION S.A. | N9: KALLPA GENERACION S.A. | O9: KALLPA GENERACION S.A. | P9: KALLPA GENERACION S.A. | Q9: KALLPA GENERACION S.A. | R9: KALLPA GENERACION S.A. | S9: KALLPA GENERACION S.A. | T9: SHOUGESA | U9: SHOUGESA | V9: SHOUGESA | W9: SHOUGESA | X9: EGEMSA | Y9: EGESUR | Z9: EGESUR | AA9: EGESUR | AB9: EGASA | AC9: EGASA | AD9: EGASA | AE9: EGASA | AF9: EGASA | AG9: EGASA | AH9: EGASA | AI9: SAN GABAN | AJ9: CELEPSA | AK9: MINERA CERRO VERDE | AL9: PLANTA DE RESERVA FRIA DE GENERACION DE ETEN S.A. | AM9: PLANTA DE RESERVA FRIA DE GENERACION DE ETEN S.A. | AN9: EMPRESA DE GENERACION HUALLAGA | AO9: EMPRESA DE GENERACION HUALLAGA | AP9: LA VIRGEN | AQ9: CHINANGO S.A.C. | AR9: CHINANGO S.A.C. | AS9: HIDROELECTRICA HUANCHOR S.A.C. | AT9: CELEPSA RENOVABLES S.R.L. | AU9: INLAND ENERGY SAC | AV9: FENIX POWER PERÚ | AW9: FENIX POWER PERÚ | AX9: FENIX POWER PERÚ | AY9: STATKRAFT S.A | AZ9: STATKRAFT S.A | BA9: STATKRAFT S.A | BB9: STATKRAFT S.A | BC9: STATKRAFT S.A | BD9: STATKRAFT S.A | BE9: STATKRAFT S.A | BF9: STATKRAFT S.A | BG9: CENTRALES SANTA ROSA S.A.C. | BH9: CENTRALES SANTA ROSA S.A.C. | BI9: EMPRESA DE GENERACION HUANZA | BJ9: ENEL GENERACION PIURA S.A. | BK9: ENEL GENERACION PIURA S.A. | BL9: ENEL GENERACION PIURA S.A. | BM9: ENGIE | BN9: ENGIE | BO9: ENGIE | BP9: ENGIE | BQ9: ENGIE | BR9: ENGIE | BS9: ENGIE | BT9: ENGIE | BU9: ENGIE | BV9: ENGIE | BW9: ENGIE | BX9: ENGIE | BY9: ENGIE | BZ9: ENGIE | CA9: INFRAESTRUCTURAS Y ENERGIAS DEL PERU S.A.C. | CB9: INFRAESTRUCTURAS Y ENERGIAS DEL PERU S.A.C. | CC9: INVERSIONES SHAQSHA S.A.C. | CD9: ORYGEN PERU S.A.A. | CE9: ORYGEN PERU S.A.A. | CF9: ORYGEN PERU S.A.A. | CG9: ORYGEN PERU S.A.A. | CH9: ORYGEN PERU S.A.A. | CI9: ORYGEN PERU S.A.A. | CJ9: ORYGEN PERU S.A.A. | CK9: ORYGEN PERU S.A.A. | CL9: ORYGEN PERU S.A.A. | CM9: ORYGEN PERU S.A.A. | CN9: ORYGEN PERU S.A.A. | CO9: ORYGEN PERU S.A.A. | CP9: SAMAY I S.A.C | CQ9: SAMAY I S.A.C | CR9: SAMAY I S.A.C | CS9: SAMAY I S.A.C | CT9: TERMOCHILCA S.A.C. | CU9: TERMOCHILCA S.A.C. | CV9: COLCA SOLAR S.A.C. | CW9: ENERGIA RENOVABLE DEL SUR S.A. | CX9: GR CORTARRAMA SOCIEDAD ANONIMA CERRADA | CY9: GR TARUCA SOCIEDAD ANONIMA CERRADA | CZ9: KONDU SAC | DA9: PERUANA DE INVERSIONES EN ENERGIAS RENOVABLES S.A. | DB9: VARI ENERGIA S.A.C. | DC9: ORAZUL ENERGY PERÚ | DD9: ORAZUL ENERGY PERÚ | DE9: SAN GABAN | DF9: MAJA ENERGIA S.A.C. | DG9: EMPRESA DE GENERACION ELECTRICA CANCHAYLLO SAC | DH9: EMPRESA DE GENERACION ELECTRICA SANTA ANA S.A.C. | DI9: EMPRESA ELECTRICA AGUA AZUL | DJ9: EMPRESA ELECTRICA RIO DOBLE | DK9: HIDROCAÑETE S.A. | DL9: HUAURA POWER GROUP S.A. | DM9: MOQUEGUA FV S.A.C. | DN9: PANAMERICANA SOLAR SAC. | DO9: PARQUE EOLICO MARCONA S.A.C. | DP9: PARQUE EOLICO TRES HERMANAS S.A.C. | DQ9: PETRAMAS | DR9: PETRAMAS | DS9: PETRAMAS | DT9: PETRAMAS | DU9: TACNA SOLAR SAC. | DV9: ELECTRICA YANAPAMPA SAC | DW9: ANDEAN POWER S.A.C. | DX9: ASOCIACIÓN SANTA LUCIA DE CHACAS | DY9: ATRIA ENERGIA S.A.C. | DZ9: EGEJUNIN | EA9: EGEJUNIN | EB9: EGEJUNIN | EC9: EGEJUNIN | ED9: EMPRESA DE GENERACION ELECTRICA RIO BAÑOS S.A.C. | EE9: ENERGÍA EÓLICA S.A. | EF9: ENERGÍA EÓLICA S.A. | EG9: ENGIE | EH9: ENGIE | EI9: ENGIE | EJ9: ENGIE | EK9: ENGIE | EL9: GENERACIÓN ANDINA S.A.C. | EM9: GENERACIÓN ANDINA S.A.C. | EN9: GENERADORA DE ENERGÍA DEL PERÚ | EO9: GENERADORA DE ENERGÍA DEL PERÚ | EP9: GENERADORA DE ENERGÍA DEL PERÚ | EQ9: GENERADORA DE ENERGÍA DEL PERÚ | ER9: GR PAINO SOCIEDAD ANONIMA CERRADA | ES9: JOYA SOLAR S.A.C. | ET9: MAJES ARCUS S.A.C. | EU9: ORYGEN PERU S.A.A. | EV9: ORYGEN PERU S.A.A. | EW9: ORYGEN PERU S.A.A. | EX9: ORYGEN PERU S.A.A. | EY9: ORYGEN PERU S.A.A. | EZ9: REPARTICIÓN ARCUS S.A.C. | FA9: SINERSA | FB9: SINERSA | FC9: BIOENERGIA DEL CHIRA S.A. | FD9: GM OPERACIONES S.A.C. | FE9: GM OPERACIONES S.A.C. | FF9: AGRO INDUSTRIAL PARAMONGA S.A. | FG9: AGROAURORA S.A.C. | FH9: AGROINDUSTRIAS SAN JACINTO S.A.A. | FK9: UNACEM PERU S.A. | FL9: ELECTRO ORIENTE | FM9: AGUAS Y ENERGIA PERU | FN9: ELECTRO ZAÑA S.A.C. | FO9: ELECTRONOROESTE S.A. | FP9: SDE PIURA | FQ9: SINERSA | FR9: SINERSA
C10: SAN GABAN III | D10: MANTARO | E10: RESTITUCION | F10: TUMBES MAK 1 | G10: TUMBES MAK 2 | H10: CARHUAQUERO | I10: CAÑON DEL PATO | J10: AGUAYTIA TG1 | K10: AGUAYTIA TG2 | L10: KALLPA TG1 | M10: KALLPA TG2 | N10: KALLPA TG3 | O10: KALLPA TV | P10: LFLORES TG1 | Q10: LFLORES TV | R10: CERRO DEL AGUILA | S10: CERRODELAGUILAG4 | T10: SHOUGESA TV1 | U10: SHOUGESA TV2 | V10: SHOUGESA TV3 | W10: SHOUGESA CUMMINS | X10: MACHUPICCHU | Y10: ARICOTA 1 | Z10: ARICOTA 2 | AA10: INDEPENDENCIA | AB10: CHARCANI I,II,III | AC10: CHARCANI IV | AD10: CHARCANI V | AE10: CHARCANI VI | AF10: CHILINA TG | AG10: MOLLENDO 1, 2, 3 | AH10: CHILINA (SULZ 1,2) | AI10: SAN GABAN II | AJ10: PLATANAL | AK10: RECKA | AL10: RF ETEN TG1 | AM10: RF ETEN TG2 | AN10: CHAGLLA GP1 | AO10: CHAGLLA | AP10: LA VIRGEN | AQ10: CHIMAY | AR10: YANANGO | AS10: HUANCHOR | AT10: MARAÑON | AU10: STA TERESA | AV10: FENIX GT11 | AW10: FENIX GT12 | AX10: FENIX TV10 | AY10: YAUPI | AZ10: OROYA | BA10: PACHACHACA | BB10: MALPASO | BC10: CAHUA | BD10: ARCATA | BE10: GALLITO CIEGO | BF10: CHEVES | BG10: SANTA ROSA 1 | BH10: SANTA ROSA 2 | BI10: HUANZA | BJ10: MALACAS2 TG4 | BK10: MALACAS3 TG 5 | BL10: MALACAS1 TG6 | BM10: RF ILO2 TG1 | BN10: RF ILO2 TG2 | BO10: RF ILO2 TG3 | BP10: YUNCAN | BQ10: CHILCA1 TG1 | BR10: CHILCA1 TG2 | BS10: CHILCA1 TG3 | BT10: CHILCA-TV | BU10: CHILCA2 TG41 | BV10: CHILCA2-TV | BW10: CTNEPI_TG41 | BX10: CTNEPI_TG42 | BY10: CTNEPI_TG43 | BZ10: QUITARACSA | CA10: RF PTO MALDONADO | CB10: RF PUCALLPA | CC10: PARIAC | CD10: HUINCO | CE10: MATUCANA | CF10: MOYOPAMPA | CG10: CALLAHUANCA | CH10: HUAMPANI | CI10: STA ROSA WEST TG7 | CJ10: UTI_5 | CK10: UTI_6 | CL10: VENTANILLA 3 | CM10: VENTANILLA 4 | CN10: VENTANILLA TV | CO10: STAROSA TG8 | CP10: PTO_BRVO TG1 | CQ10: PTO_BRVO TG2 | CR10: PTO_BRVO TG3 | CS10: PTO_BRVO TG4 | CT10: OLLEROS TG1 | CU10: OLLEROS TV | CV10: CS YARUCAYA | CW10: SAN JUAN | CX10: MATARANI | CY10: DUNA | CZ10: CARHUAQUERO (CS) | DA10: MANTA I | DB10: ANASHIRONI | DC10: CARHUAQUERO4 | DD10: CAÑA BRAVA | DE10: TUPURI | DF10: RONCADOR | DG10: CANCHAYLLO | DH10: RENOVANDESH1 | DI10: POTRERO | DJ10: PIZARRAS | DK10: NIMPERIAL | DL10: YARUCAYA | DM10: MOQUEGUA-SOLAR | DN10: PANAMERICANA-SOLAR | DO10: PQE-EOLICO-MARCONA | DP10: PQE-EOLICO-3-HERMANAS | DQ10: HUAYCOLORO | DR10: CALLAO | DS10: DONA_CATALINA | DT10: LAGRINGAV | DU10: TACNA-SOLAR | DV10: YANAPAMPA | DW10: CARHUAC | DX10: HUALLIN | DY10: PURMACANA | DZ10: HUASAHUASI | EA10: STACRUZ_1_2 | EB10: RUNATULLO_II | EC10: RUNATULLO_III | ED10: RUCUY | EE10: PQE-EOLICO-TALARA | EF10: PQE-EOLICO-CUPISNIQUE | EG10: INTIPAMPA | EH10: PUNTA LOMITAS-BL1 | EI10: PUNTA LOMITAS-BL2 | EJ10: PUN LOMITAS_EXP-BL1 | EK10: PUN LOMITAS_EXP-BL2 | EL10: 8AGOSTO | EM10: EL CARMEN | EN10: LA JOYA | EO10: ANGEL_I | EP10: ANGEL_II | EQ10: ANGEL_III | ER10: HUAMBOS | ES10: SAN MARTIN SOLAR | ET10: MAJES | EU10: RUBI | EV10: CH_HER1 | EW10: WAYRA-I | EX10: WAYRA EXTENSION | EY10: CLEMESI | EZ10: REPARTICION | FA10: POECHOS2 | FB10: CHANCAY | FC10: CANA BRAVA | FD10: REFINERIA TALARA TV1 | FE10: REFINERÍA TALARA TV2 | FF10: PARAMONGA | FG10: MAPLE | FH10: SAN_JACINTO | FI10: MW | FK10: CARPAPATA | FL10: CENTRALES ELOR | FM10: PIAS1 | FN10: ZANA | FO10: TABLAZO | FP10: TALLANCA | FQ10: CURUMUY | FR10: POECHOS1 | FS10: MW
A11: 22/07/2025 | B11: 00:30 | C11: 23.4 | D11: 580.5 | E11: 145.6 | H11: 21.3 | I11: 72.7 | L11: 188.3 | M11: 207.5 | N11: 210.2 | O11: 290.8 | P11: 216 | Q11: 111.9 | R11: 375.7 | S11: 4.3 | X11: 111.5 | Y11: 7.1 | Z11: 4.6 | AB11: 6.8 | AC11: 14.9 | AD11: 82.8 | AI11: 31.4 | AJ11: 44 | AN11: 6.5 | AO11: 0 | AP11: 30.4 | AQ11: 74.1 | AR11: 20.1 | AS11: 18.7 | AT11: 13.6 | AU11: 57.6 | AV11: 180.5 | AW11: 180.5 | AX11: 184.8 | AY11: 81.8 | AZ11: 8 | BA11: 4.9 | BB11: 33.3 | BC11: 35.2 | BD11: 2 | BE11: 17.2 | BF11: 85.2 | BI11: 44.8 | BL11: 0 | BP11: 65.7 | BQ11: 178.5 | BR11: 175.8 | BS11: 209.9 | BT11: 274.3 | CB11: 0 | CC11: 1 | CD11: 168 | CE11: 100.3 | CF11: 64.3 | CG11: 72.8 | CH11: 29.7 | CL11: 146.6 | CM11: 148.9 | CN11: 150.6 | CT11: 218.9 | CU11: 105.1 | CV11: 0 | CW11: 39.1 | CX11: 0 | CY11: 12.8 | CZ11: 0 | DA11: 7.7 | DB11: 5.027 | DC11: 9.9 | DD11: 5.3 | DE11: 0.3 | DF11: 3.2 | DG11: 2 | DH11: 19 | DI11: 6.2 | DJ11: 4.5 | DK11: 3.4 | DL11: 18 | DM11: 0 | DN11: 0 | DO11: 9.9 | DP11: 26.4 | DQ11: 4.5 | DR11: 0.6 | DS11: 2.4 | DT11: 2.6 | DU11: 0 | DV11: 2.4 | DW11: 9.8 | DX11: 1.4 | DZ11: 4.7 | EA11: 3.4 | EB11: 3.1 | EC11: 5.2 | ED11: 15.7 | EE11: 26.2 | EF11: 23.3 | EG11: 0 | EH11: 8.4 | EI11: 26.7 | EJ11: 0.1 | EK11: 0 | EL11: 6.5 | EM11: 2.1 | EN11: 9.1 | EO11: 4 | EP11: 4.6 | EQ11: 4.6 | ER11: 7.8 | ES11: 0 | ET11: 0 | EU11: 0 | EV11: 0.6 | EW11: 0 | EX11: 0 | EY11: 0 | EZ11: 0 | FA11: 10 | FB11: 18.7 | FC11: 9.5 | FD11: 36.9 | FE11: 27.8 | FF11: 13.5 | FG11: 19.1 | FH11: 8.1 | FI11: 6437.027 | FK11: 19.86605 | FL11: 0 | FM11: 6.088 | FN11: 7.2 | FO11: 27.23995 | FP11: 18.86653 | FQ11: 9.7 | FR11: 16 | FS11: 104.96053
A12: 22/07/2025 | B12: 01:00 | C12: 33.2 | D12: 580.3 | E12: 145.5 | H12: 0 | I12: 73 | L12: 188.4 | M12: 205.8 | N12: 208.6 | O12: 288.9 | P12: 215.2 | Q12: 111.9 | R12: 375.3 | S12: 4.4 | X12: 111.1 | Y12: 7.4 | Z12: 5 | AB12: 6.8 | AC12: 14.8 | AD12: 83 | AI12: 34.4 | AJ12: 43.6 | AN12: 6.5 | AO12: 151.6 | AP12: 31 | AQ12: 56.6 | AR12: 19.3 | AS12: 18.6 | AT12: 13.6 | AU12: 59.7 | AV12: 183 | AW12: 183.1 | AX12: 183.1 | AY12: 83.2 | AZ12: 8 | BA12: 4.9 | BB12: 24.7 | BC12: 34.8 | BD12: 2 | BE12: 0 | BF12: 20.6 | BI12: 45 | BL12: 0 | BP12: 66.4 | BQ12: 179 | BR12: 176.4 | BS12: 210.7 | BT12: 274.3 | CB12: 0 | CC12: 1 | CD12: 103.6 | CE12: 88.4 | CF12: 62.9 | CG12: 72.9 | CH12: 30.1 | CL12: 145 | CM12: 147.7 | CN12: 148.7 | CT12: 218.8 | CU12: 105.2 | CV12: 0 | CW12: 44.8 | CX12: 0 | CY12: 13.1 | CZ12: 0 | DA12: 7.6 | DB12: 5.148 | DC12: 0 | DD12: 0 | DE12: 0.3 | DF12: 3.2 | DG12: 2.1 | DH12: 19 | DI12: 6.4 | DJ12: 4.5 | DK12: 3.4 | DL12: 18 | DM12: 0 | DN12: 0 | DO12: 11.6 | DP12: 33.8 | DQ12: 4.5 | DR12: 1.1 | DS12: 2.4 | DT12: 2.6 | DU12: 0 | DV12: 2.4 | DW12: 11.9 | DX12: 1.4 | DZ12: 4.7 | EA12: 3.4 | EB12: 3.2 | EC12: 4.6 | ED12: 15.3 | EE12: 24.3 | EF12: 14.6 | EG12: 0 | EH12: 9.5 | EI12: 26.2 | EJ12: 0.1 | EK12: 0 | EL12: 6.5 | EM12: 2.1 | EN12: 9.1 | EO12: 4 | EP12: 4.6 | EQ12: 4.6 | ER12: 8.5 | ES12: 0 | ET12: 0 | EU12: 0 | EV12: 0.6 | EW12: 1.6 | EX12: 0.4 | EY12: 0 | EZ12: 0 | FA12: 10 | FB12: 18.6 | FC12: 8.9 | FD12: 37 | FE12: 27.9 | FF12: 13 | FG12: 19.1 | FH12: 7.1 | FI12: 6385.748 | FK12: 19.74684 | FL12: 0 | FM12: 6.088 | FN12: 7.2 | FO12: 27.26791 | FP12: 18.86565 | FQ12: 9.9 | FR12: 15.9 | FS12: 104.9684
A13: 22/07/2025 | B13: 01:30 | C13: 25.3 | D13: 576.9 | E13: 145 | H13: 0 | I13: 72.4 | L13: 187.3 | M13: 207.5 | N13: 211.9 | O13: 287.1 | P13: 217.5 | Q13: 111.9 | R13: 368.1 | S13: 4.3 | X13: 111.9 | Y13: 7 | Z13: 5.3 | AB13: 6.8 | AC13: 12.3 | AD13: 49.4 | AI13: 34.7 | AJ13: 33.2 | AN13: 6.5 | AO13: 152 | AP13: 31 | AQ13: 0 | AR13: 20.2 | AS13: 18.5 | AT13: 13.4 | AU13: 58.3 | AV13: 180.9 | AW13: 181.2 | AX13: 183.1 | AY13: 82.8 | AZ13: 7.9 | BA13: 4.9 | BB13: 18.4 | BC13: 25.7 | BD13: 2 | BE13: 0 | BF13: 19.2 | BI13: 44.6 | BL13: 0 | BP13: 65.8 | BQ13: 179 | BR13: 176.3 | BS13: 210.6 | BT13: 274.5 | CB13: 0 | CC13: 1 | CD13: 79.3 | CE13: 81 | CF13: 62.2 | CG13: 72.9 | CH13: 29.7 | CL13: 146.1 | CM13: 148.6 | CN13: 149.7 | CT13: 218 | CU13: 105 | CV13: 0 | CW13: 39.7 | CX13: 0 | CY13: 14 | CZ13: 0 | DA13: 7.6 | DB13: 5.069 | DC13: 0 | DD13: 0 | DE13: 0.3 | DF13: 3.1 | DG13: 2.1 | DH13: 19.2 | DI13: 6.6 | DJ13: 4.5 | DK13: 3.4 | DL13: 18 | DM13: 0 | DN13: 0 | DO13: 11.4 | DP13: 37.3 | DQ13: 4.5 | DR13: 1.2 | DS13: 2.4 | DT13: 2.6 | DU13: 0 | DV13: 2.4 | DW13: 11.9 | DX13: 1.4 | DZ13: 4.7 | EA13: 3.4 | EB13: 3 | EC13: 4.3 | ED13: 15.3 | EE13: 25.7 | EF13: 11.6 | EG13: 0 | EH13: 11.3 | EI13: 26.2 | EJ13: 0.7 | EK13: 0.2 | EL13: 6.3 | EM13: 2.1 | EN13: 9.1 | EO13: 4 | EP13: 4.6 | EQ13: 4.6 | ER13: 8.7 | ES13: 0 | ET13: 0 | EU13: 0 | EV13: 0.6 | EW13: 17.5 | EX13: 8.5 | EY13: 0 | EZ13: 0 | FA13: 10 | FB13: 18.6 | FC13: 9.4 | FD13: 37.1 | FE13: 27.9 | FF13: 13.5 | FG13: 19.1 | FH13: 8.5 | FI13: 6241.269 | FK13: 20.27253 | FL13: 0 | FM13: 6.088 | FN13: 7.2 | FO13: 27.2691 | FP13: 18.86558 | FQ13: 9.9 | FR13: 15.9 | FS13: 105.49521
A14: 22/07/2025 | B14: 02:00 | C14: 26.5 | D14: 575.9 | E14: 144.2 | H14: 0 | I14: 74.8 | L14: 189 | M14: 208.4 | N14: 211.9 | O14: 286.9 | P14: 216.6 | Q14: 112.3 | R14: 369.3 | S14: 4.2 | X14: 112 | Y14: 6.9 | Z14: 5.3 | AB14: 6.8 | AC14: 12 | AD14: 48.9 | AI14: 34.4 | AJ14: 23 | AN14: 6.5 | AO14: 151.2 | AP14: 29.2 | AQ14: 0 | AR14: 20.1 | AS14: 18.3 | AT14: 13.4 | AU14: 57.6 | AV14: 180.5 | AW14: 181.2 | AX14: 182 | AY14: 83.3 | AZ14: 8 | BA14: 4.7 | BB14: 18.4 | BC14: 25.5 | BD14: 2 | BE14: 0 | BF14: 19.3 | BI14: 44.6 | BL14: 0 | BP14: 66.7 | BQ14: 178.4 | BR14: 176.2 | BS14: 210.5 | BT14: 275 | CB14: 0 | CC14: 1 | CD14: 78.2 | CE14: 94.9 | CF14: 43.7 | CG14: 72.9 | CH14: 29.7 | CL14: 146.9 | CM14: 149.2 | CN14: 151 | CT14: 218.8 | CU14: 105.1 | CV14: 0 | CW14: 45.8 | CX14: 0 | CY14: 13.5 | CZ14: 0 | DA14: 7.7 | DB14: 5.029 | DC14: 0 | DD14: 0 | DE14: 0.3 | DF14: 2.8 | DG14: 2.1 | DH14: 19.2 | DI14: 6.6 | DJ14: 7.5 | DK14: 3.4 | DL14: 18 | DM14: 0 | DN14: 0 | DO14: 9.8 | DP14: 28.4 | DQ14: 4.5 | DR14: 1.2 | DS14: 2.4 | DT14: 2.6 | DU14: 0 | DV14: 2.4 | DW14: 11.7 | DX14: 1.3 | DZ14: 4.7 | EA14: 3.4 | EB14: 3 | EC14: 4.4 | ED14: 15.2 | EE14: 26.8 | EF14: 12.9 | EG14: 0 | EH14: 9 | EI14: 22.8 | EJ14: 1.2 | EK14: 0.5 | EL14: 6.2 | EM14: 2.1 | EN14: 9.1 | EO14: 3.8 | EP14: 4.2 | EQ14: 4.2 | ER14: 9.8 | ES14: 0 | ET14: 0 | EU14: 0 | EV14: 0.6 | EW14: 16.8 | EX14: 13.8 | EY14: 0 | EZ14: 0 | FA14: 10 | FB14: 18.4 | FC14: 9.6 | FD14: 37.1 | FE14: 27.9 | FF14: 14 | FG14: 18.9 | FH14: 8.6 | FI14: 6228.529 | FK14: 20.28504 | FL14: 0 | FM14: 6.084 | FN14: 7.2 | FO14: 27.26437 | FP14: 18.86524 | FQ14: 9.8 | FR14: 16 | FS14: 105.49865
A15: 22/07/2025 | B15: 02:30 | C15: 31.1 | D15: 577.8 | E15: 144.6 | H15: 0 | I15: 77.2 | L15: 188.3 | M15: 207 | N15: 210.7 | O15: 288.4 | P15: 217.1 | Q15: 112.1 | R15: 195.5 | S15: 4.3 | X15: 115.1 | Y15: 7.9 | Z15: 5.4 | AB15: 6.8 | AC15: 12 | AD15: 49.9 | AI15: 35.1 | AJ15: 24 | AN15: 6.5 | AO15: 152.2 | AP15: 30.8 | AQ15: 0 | AR15: 21.5 | AS15: 18.5 | AT15: 13.4 | AU15: 59.3 | AV15: 181.8 | AW15: 182.2 | AX15: 182.7 | AY15: 83.7 | AZ15: 8 | BA15: 4.7 | BB15: 19 | BC15: 25.8 | BD15: 2 | BE15: 0 | BF15: 19.6 | BI15: 44.8 | BL15: 0 | BP15: 67 | BQ15: 178.2 | BR15: 175.5 | BS15: 209.7 | BT15: 274.1 | CB15: 0 | CC15: 0.9 | CD15: 82.4 | CE15: 98.5 | CF15: 70.2 | CG15: 73 | CH15: 27.9 | CL15: 146.3 | CM15: 148.7 | CN15: 150.5 | CT15: 218.7 | CU15: 105.1 | CV15: 0 | CW15: 41.9 | CX15: 0 | CY15: 11.4 | CZ15: 0 | DA15: 7.8 | DB15: 5.068 | DC15: 0 | DD15: 0 | DE15: 0.3 | DF15: 2.7 | DG15: 2 | DH15: 19.2 | DI15: 6.8 | DJ15: 7.5 | DK15: 3.4 | DL15: 18 | DM15: 0 | DN15: 0 | DO15: 8.9 | DP15: 25.6 | DQ15: 4.5 | DR15: 1.2 | DS15: 2.4 | DT15: 2.6 | DU15: 0 | DV15: 1.8 | DW15: 11.8 | DX15: 1.3 | DZ15: 4.7 | EA15: 3.4 | EB15: 3.1 | EC15: 4.4 | ED15: 15.4 | EE15: 21.1 | EF15: 10 | EG15: 0 | EH15: 10.1 | EI15: 23.2 | EJ15: 1.3 | EK15: 0 | EL15: 6.2 | EM15: 2.1 | EN15: 9.1 | EO15: 3.8 | EP15: 4.2 | EQ15: 4.2 | ER15: 8.1 | ES15: 0 | ET15: 0 | EU15: 0 | EV15: 0.6 | EW15: 10.3 | EX15: 5 | EY15: 0 | EZ15: 0 | FA15: 9.9 | FB15: 18.5 | FC15: 9.6 | FD15: 37.2 | FE15: 27.8 | FF15: 13.3 | FG15: 19.1 | FH15: 7.1 | FI15: 6072.468 | FK15: 20.54564 | FL15: 0 | FM15: 6.088 | FN15: 7.2 | FO15: 27.22097 | FP15: 18.86496 | FQ15: 9.8 | FR15: 16.1 | FS15: 105.81957
A16: 22/07/2025 | B16: 03:00 | C16: 30.1 | D16: 580.1 | E16: 145.4 | H16: 0 | I16: 74.9 | L16: 188.2 | M16: 206.8 | N16: 209.9 | O16: 289.5 | P16: 216.7 | Q16: 111.7 | R16: 197.8 | S16: 4.3 | X16: 112.7 | Y16: 8.1 | Z16: 4.6 | AB16: 6.9 | AC16: 12 | AD16: 50.2 | AI16: 35.4 | AJ16: 63.1 | AN16: 6.5 | AO16: 151.8 | AP16: 33 | AQ16: 0 | AR16: 22 | AS16: 18.6 | AT16: 13.5 | AU16: 58 | AV16: 182.4 | AW16: 183.1 | AX16: 183.7 | AY16: 83.8 | AZ16: 8 | BA16: 4.7 | BB16: 21 | BC16: 26.9 | BD16: 2 | BE16: 0 | BF16: 20.6 | BI16: 45 | BL16: 0 | BP16: 67.1 | BQ16: 178.1 | BR16: 175.6 | BS16: 209.7 | BT16: 274.4 | CB16: 0 | CC16: 1 | CD16: 91.1 | CE16: 101.9 | CF16: 70.5 | CG16: 73 | CH16: 28.1 | CL16: 146.5 | CM16: 148.4 | CN16: 149.9 | CT16: 218.5 | CU16: 105.1 | CV16: 0 | CW16: 35 | CX16: 0 | CY16: 14.1 | CZ16: 0 | DA16: 7.7 | DB16: 5.12 | DC16: 0 | DD16: 0 | DE16: 0.3 | DF16: 2.9 | DG16: 2 | DH16: 19.3 | DI16: 6.8 | DJ16: 7.5 | DK16: 3.4 | DL16: 18 | DM16: 0 | DN16: 0 | DO16: 9.9 | DP16: 23.7 | DQ16: 4.5 | DR16: 1.2 | DS16: 2.4 | DT16: 2.6 | DU16: 0 | DV16: 1.8 | DW16: 12 | DX16: 1.3 | DZ16: 4.7 | EA16: 3.4 | EB16: 3.2 | EC16: 4.5 | ED16: 16.3 | EE16: 18.5 | EF16: 7 | EG16: 0 | EH16: 16.2 | EI16: 30.7 | EJ16: 2.3 | EK16: 1 | EL16: 6.2 | EM16: 2.1 | EN16: 9.1 | EO16: 3.8 | EP16: 4.2 | EQ16: 4.2 | ER16: 9.8 | ES16: 0 | ET16: 0 | EU16: 0 | EV16: 0.6 | EW16: 4.8 | EX16: 1.8 | EY16: 0 | EZ16: 0 | FA16: 10 | FB16: 18.9 | FC16: 9.5 | FD16: 37.2 | FE16: 27.8 | FF16: 13.1 | FG16: 19.1 | FH16: 8.1 | FI16: 6131.52 | FK16: 20.60876 | FL16: 0 | FM16: 6.084 | FN16: 7.2 | FO16: 27.14751 | FP16: 18.86511 | FQ16: 9.7 | FR16: 16 | FS16: 105.60538
A17: 22/07/2025 | B17: 03:30 | C17: 27.2 | D17: 581.2 | E17: 146 | H17: 0 | I17: 75.6 | L17: 187.9 | M17: 206.5 | N17: 210.1 | O17: 290 | P17: 217.2 | Q17: 111.5 | R17: 198.9 | S17: 4.3 | X17: 110.1 | Y17: 8.3 | Z17: 5.2 | AB17: 6.9 | AC17: 12 | AD17: 50.8 | AI17: 38.1 | AJ17: 34.2 | AN17: 6.5 | AO17: 152.2 | AP17: 32.3 | AQ17: 0 | AR17: 20.6 | AS17: 18.5 | AT17: 13.5 | AU17: 59.3 | AV17: 182.4 | AW17: 183.3 | AX17: 183.7 | AY17: 83.6 | AZ17: 8 | BA17: 4.7 | BB17: 23.2 | BC17: 40 | BD17: 2 | BE17: 0 | BF17: 21 | BI17: 45.1 | BL17: 0 | BP17: 67.1 | BQ17: 177.9 | BR17: 175.4 | BS17: 209.9 | BT17: 274.2 | CB17: 0 | CC17: 1 | CD17: 99.2 | CE17: 101.3 | CF17: 46.2 | CG17: 72.9 | CH17: 28.7 | CL17: 146 | CM17: 148.4 | CN17: 150 | CT17: 218 | CU17: 105.1 | CV17: 0 | CW17: 35.1 | CX17: 0 | CY17: 13.7 | CZ17: 0 | DA17: 7.7 | DB17: 5.097 | DC17: 0 | DD17: 0 | DE17: 0.3 | DF17: 3 | DG17: 2 | DH17: 19.3 | DI17: 7 | DJ17: 7.5 | DK17: 3.4 | DL17: 18 | DM17: 0 | DN17: 0 | DO17: 10 | DP17: 19.5 | DQ17: 4.5 | DR17: 1.2 | DS17: 2.4 | DT17: 2.6 | DU17: 0 | DV17: 1.8 | DW17: 12 | DX17: 1.3 | DZ17: 4.7 | EA17: 3.5 | EB17: 3.3 | EC17: 4.6 | ED17: 15.7 | EE17: 22.9 | EF17: 7.3 | EG17: 0 | EH17: 18.9 | EI17: 40 | EJ17: 2.1 | EK17: 0.9 | EL17: 6.2 | EM17: 2.1 | EN17: 9.2 | EO17: 3.8 | EP17: 4.2 | EQ17: 4.2 | ER17: 10.3 | ES17: 0 | ET17: 0 | EU17: 0 | EV17: 0.6 | EW17: 6.6 | EX17: 3.4 | EY17: 0 | EZ17: 0 | FA17: 10 | FB17: 18.6 | FC17: 9.4 | FD17: 37.1 | FE17: 27.8 | FF17: 13.3 | FG17: 19.1 | FH17: 8.6 | FI17: 6118.997 | FK17: 20.70648 | FL17: 0 | FM17: 6.088 | FN17: 7.2 | FO17: 27.20632 | FP17: 18.86515 | FQ17: 9.7 | FR17: 15.9 | FS17: 105.66595
A18: 22/07/2025 | B18: 04:00 | C18: 30.6 | D18: 580.1 | E18: 145.6 | H18: 0 | I18: 75.1 | L18: 188.6 | M18: 207.8 | N18: 211 | O18: 288.9 | P18: 218.1 | Q18: 111.6 | R18: 199.1 | S18: 4.2 | X18: 114.3 | Y18: 6.6 | Z18: 5.5 | AB18: 6.8 | AC18: 12 | AD18: 49.8 | AI18: 44.8 | AJ18: 32.3 | AN18: 6.5 | AO18: 0 | AP18: 32 | AQ18: 0 | AR18: 21 | AS18: 18.5 | AT18: 13.4 | AU18: 59 | AV18: 182 | AW18: 182.3 | AX18: 184 | AY18: 83.4 | AZ18: 8 | BA18: 4.7 | BB18: 23.2 | BC18: 39.8 | BD18: 2 | BE18: 0 | BF18: 19.8 | BI18: 44.9 | BL18: 0 | BP18: 67.2 | BQ18: 178.4 | BR18: 175.9 | BS18: 209.8 | BT18: 274.1 | CB18: 0 | CC18: 1 | CD18: 99.4 | CE18: 101.7 | CF18: 70.4 | CG18: 70 | CH18: 29.9 | CL18: 146.5 | CM18: 148.7 | CN18: 150.1 | CT18: 218.7 | CU18: 105.1 | CV18: 0 | CW18: 29.6 | CX18: 0 | CY18: 14.3 | CZ18: 0 | DA18: 7.7 | DB18: 5.126 | DC18: 0 | DD18: 0 | DE18: 0.3 | DF18: 2.9 | DG18: 2 | DH18: 19.3 | DI18: 7 | DJ18: 4.5 | DK18: 3.4 | DL18: 18 | DM18: 0 | DN18: 0 | DO18: 6.6 | DP18: 18.4 | DQ18: 4.5 | DR18: 1.2 | DS18: 2.4 | DT18: 2.6 | DU18: 0 | DV18: 1.8 | DW18: 11.9 | DX18: 1.3 | DZ18: 4.7 | EA18: 3.5 | EB18: 3.1 | EC18: 4 | ED18: 15.5 | EE18: 19.9 | EF18: 9.7 | EG18: 0 | EH18: 22.6 | EI18: 44.3 | EJ18: 2 | EK18: 0.2 | EL18: 6.2 | EM18: 2.1 | EN18: 9.2 | EO18: 3.8 | EP18: 4.2 | EQ18: 4.2 | ER18: 10.8 | ES18: 0 | ET18: 0 | EU18: 0 | EV18: 0.6 | EW18: 13.3 | EX18: 6.5 | EY18: 0 | EZ18: 0 | FA18: 10 | FB18: 18.6 | FC18: 9.4 | FD18: 37.1 | FE18: 27.9 | FF18: 14.6 | FG18: 19.1 | FH18: 9 | FI18: 6005.126 | FK18: 20.87239 | FL18: 0 | FM18: 6.088 | FN18: 7.2 | FO18: 27.17993 | FP18: 18.86546 | FQ18: 9.7 | FR18: 16 | FS18: 105.90578
A19: 22/07/2025 | B19: 04:30 | C19: 31.6 | D19: 581.4 | E19: 145.9 | H19: 0 | I19: 77.3 | L19: 188.5 | M19: 208.3 | N19: 211.5 | O19: 287.7 | P19: 215.3 | Q19: 112 | R19: 199.8 | S19: 4.3 | X19: 111.9 | Y19: 6.7 | Z19: 5.6 | AB19: 6.9 | AC19: 12 | AD19: 50.3 | AI19: 55.4 | AJ19: 68.4 | AN19: 6.5 | AO19: 0 | AP19: 32 | AQ19: 0 | AR19: 22.2 | AS19: 18.6 | AT19: 13.5 | AU19: 55.9 | AV19: 182.9 | AW19: 183.2 | AX19: 184.2 | AY19: 84.4 | AZ19: 8 | BA19: 4.7 | BB19: 27.9 | BC19: 31.9 | BD19: 2 | BE19: 0 | BF19: 48.2 | BI19: 45.1 | BL19: 0 | BP19: 67.2 | BQ19: 178.4 | BR19: 175.9 | BS19: 210.6 | BT19: 274.6 | CB19: 0 | CC19: 1 | CD19: 80.2 | CE19: 106.9 | CF19: 70.6 | CG19: 70 | CH19: 28.2 | CL19: 146.5 | CM19: 148.8 | CN19: 150 | CT19: 218.7 | CU19: 105.2 | CV19: 0 | CW19: 30.3 | CX19: 0 | CY19: 14.4 | CZ19: 0 | DA19: 7.7 | DB19: 5.158 | DC19: 0 | DD19: 0 | DE19: 0.3 | DF19: 2.9 | DG19: 1.9 | DH19: 19.4 | DI19: 7.2 | DJ19: 4.5 | DK19: 3.4 | DL19: 18 | DM19: 0 | DN19: 0 | DO19: 7.1 | DP19: 22.4 | DQ19: 4.2 | DR19: 1.2 | DS19: 2 | DT19: 2.3 | DU19: 0 | DV19: 2.4 | DW19: 11.9 | DX19: 1.2 | DZ19: 4.8 | EA19: 3.5 | EB19: 3.2 | EC19: 4.3 | ED19: 15.7 | EE19: 15 | EF19: 6.3 | EG19: 0 | EH19: 25.9 | EI19: 44.4 | EJ19: 4.6 | EK19: 1.9 | EL19: 6.2 | EM19: 2.1 | EN19: 9.2 | EO19: 3.8 | EP19: 4.2 | EQ19: 4.2 | ER19: 11.1 | ES19: 0 | ET19: 0 | EU19: 0 | EV19: 0.6 | EW19: 30.6 | EX19: 23.9 | EY19: 0 | EZ19: 0 | FA19: 10 | FB19: 18.7 | FC19: 9.4 | FD19: 37.1 | FE19: 28.1 | FF19: 14.8 | FG19: 19.1 | FH19: 8.3 | FI19: 6105.658 | FK19: 21.0065 | FL19: 0 | FM19: 6.088 | FN19: 7.2 | FO19: 27.12016 | FP19: 18.86576 | FQ19: 9.5 | FR19: 16 | FS19: 105.78042
A20: 22/07/2025 | B20: 05:00 | C20: 29.4 | D20: 582.9 | E20: 146.6 | H20: 0 | I20: 76.9 | L20: 189.5 | M20: 208.1 | N20: 210.6 | O20: 288.6 | P20: 217.6 | Q20: 112.1 | R20: 199.8 | S20: 4.3 | X20: 113.9 | Y20: 7 | Z20: 5.1 | AB20: 6.9 | AC20: 12 | AD20: 51.3 | AI20: 60.8 | AJ20: 62.2 | AN20: 6.5 | AO20: 0 | AP20: 33.5 | AQ20: 0 | AR20: 23.3 | AS20: 18.6 | AT20: 13.3 | AU20: 56.6 | AV20: 183.8 | AW20: 184.7 | AX20: 184.2 | AY20: 84.4 | AZ20: 8 | BA20: 4.7 | BB20: 25.1 | BC20: 31.2 | BD20: 2 | BE20: 0 | BF20: 39.6 | BI20: 45.3 | BL20: 0 | BP20: 67.4 | BQ20: 178.5 | BR20: 175.9 | BS20: 210.4 | BT20: 274.9 | CB20: 0 | CC20: 1 | CD20: 74.8 | CE20: 105 | CF20: 70.8 | CG20: 70 | CH20: 28.2 | CL20: 146.5 | CM20: 148.8 | CN20: 150.1 | CT20: 219 | CU20: 105.3 | CV20: 0 | CW20: 33.8 | CX20: 0 | CY20: 15.6 | CZ20: 0 | DA20: 7.7 | DB20: 5.228 | DC20: 0 | DD20: 0 | DE20: 0.3 | DF20: 2.8 | DG20: 1.9 | DH20: 19.6 | DI20: 7.4 | DJ20: 4.5 | DK20: 3.4 | DL20: 18 | DM20: 0 | DN20: 0 | DO20: 9.7 | DP20: 23.7 | DQ20: 3.9 | DR20: 1.2 | DS20: 2 | DT20: 2.2 | DU20: 0 | DV20: 2.4 | DW20: 11.9 | DX20: 1.2 | DZ20: 5 | EA20: 3.5 | EB20: 3.3 | EC20: 4.5 | ED20: 15.6 | EE20: 13.1 | EF20: 3.4 | EG20: 0 | EH20: 21.1 | EI20: 44 | EJ20: 1.7 | EK20: 0.9 | EL20: 6.2 | EM20: 2.1 | EN20: 9 | EO20: 3.8 | EP20: 4.2 | EQ20: 4.2 | ER20: 11 | ES20: 0 | ET20: 0 | EU20: 0 | EV20: 0.6 | EW20: 39 | EX20: 26.5 | EY20: 0 | EZ20: 0 | FA20: 10 | FB20: 18.7 | FC20: 9.4 | FD20: 36.9 | FE20: 27.9 | FF20: 14.8 | FG20: 19.1 | FH20: 7.3 | FI20: 6102.228 | FK20: 21.21944 | FL20: 0 | FM20: 6.088 | FN20: 7.2 | FO20: 27.03816 | FP20: 18.86751 | FQ20: 9.7 | FR20: 16.1 | FS20: 106.21311
A21: 22/07/2025 | B21: 05:30 | C21: 34 | D21: 581.4 | E21: 146.1 | H21: 0 | I21: 78.1 | L21: 188.6 | M21: 208.2 | N21: 210.9 | O21: 287.9 | P21: 216.8 | Q21: 111.9 | R21: 319.4 | S21: 4.3 | X21: 113.5 | Y21: 7.6 | Z21: 5 | AB21: 6.8 | AC21: 12 | AD21: 50.9 | AI21: 55.4 | AJ21: 96.1 | AN21: 6.5 | AO21: 0 | AP21: 34 | AQ21: 0 | AR21: 23.3 | AS21: 18.5 | AT21: 13.4 | AU21: 57 | AV21: 183.6 | AW21: 184 | AX21: 184.1 | AY21: 84.8 | AZ21: 8 | BA21: 4.7 | BB21: 13.4 | BC21: 34.8 | BD21: 2 | BE21: 0 | BF21: 56.1 | BI21: 45.1 | BL21: 0 | BP21: 67.3 | BQ21: 178.4 | BR21: 175.9 | BS21: 210.8 | BT21: 275.1 | CB21: 0 | CC21: 1 | CD21: 93.8 | CE21: 105.3 | CF21: 68.4 | CG21: 71 | CH21: 28.2 | CL21: 146.7 | CM21: 148.8 | CN21: 149.9 | CT21: 218.7 | CU21: 105.3 | CV21: 0 | CW21: 34.9 | CX21: 0 | CY21: 14 | CZ21: 0 | DA21: 7.7 | DB21: 5.189 | DC21: 0 | DD21: 0 | DE21: 0.3 | DF21: 2.8 | DG21: 1.9 | DH21: 19.1 | DI21: 7.6 | DJ21: 4.5 | DK21: 3.4 | DL21: 18 | DM21: 0 | DN21: 0 | DO21: 9.5 | DP21: 25.6 | DQ21: 4.5 | DR21: 1.2 | DS21: 2 | DT21: 2.7 | DU21: 0 | DV21: 2.4 | DW21: 11.9 | DX21: 1.2 | DZ21: 5.2 | EA21: 3.5 | EB21: 3.2 | EC21: 4.4 | ED21: 15.6 | EE21: 15.2 | EF21: 2.2 | EG21: 0 | EH21: 14.7 | EI21: 35.8 | EJ21: 0.5 | EK21: 0 | EL21: 6.2 | EM21: 2.1 | EN21: 9 | EO21: 4 | EP21: 4.2 | EQ21: 4.2 | ER21: 10.6 | ES21: 0 | ET21: 0 | EU21: 0 | EV21: 0.6 | EW21: 26.3 | EX21: 20 | EY21: 0 | EZ21: 0 | FA21: 10 | FB21: 18.7 | FC21: 9.4 | FD21: 37.1 | FE21: 27.9 | FF21: 14.6 | FG21: 19.1 | FH21: 8.7 | FI21: 6246.189 | FK21: 21.30825 | FL21: 0 | FM21: 6.088 | FN21: 7.2 | FO21: 27.02572 | FP21: 18.87035 | FQ21: 9.5 | FR21: 16 | FS21: 105.99232
A22: 22/07/2025 | B22: 06:00 | C22: 26 | D22: 580.4 | E22: 145.8 | H22: 0 | I22: 77.7 | L22: 189.1 | M22: 208.3 | N22: 212.6 | O22: 289.6 | P22: 218.4 | Q22: 112 | R22: 376.9 | S22: 4.3 | X22: 112.4 | Y22: 7.1 | Z22: 4.7 | AB22: 7 | AC22: 12 | AD22: 50.4 | AI22: 43.9 | AJ22: 93.5 | AN22: 6.5 | AO22: 0 | AP22: 34 | AQ22: 45 | AR22: 22.3 | AS22: 18.5 | AT22: 13.4 | AU22: 55.6 | AV22: 181.7 | AW22: 181.9 | AX22: 184.3 | AY22: 84.2 | AZ22: 8.2 | BA22: 4.7 | BB22: 29.8 | BC22: 34.2 | BD22: 2 | BE22: 0 | BF22: 62.1 | BI22: 44.9 | BL22: 0 | BP22: 67 | BQ22: 179.1 | BR22: 176.7 | BS22: 210.7 | BT22: 275.3 | CB22: 0 | CC22: 1 | CD22: 70.8 | CE22: 103.8 | CF22: 68.1 | CG22: 71 | CH22: 29.5 | CL22: 147 | CM22: 149.1 | CN22: 150.6 | CT22: 219 | CU22: 105.3 | CV22: 0 | CW22: 41.1 | CX22: 0 | CY22: 17.2 | CZ22: 0 | DA22: 7.9 | DB22: 5.102 | DC22: 0 | DD22: 0 | DE22: 0.3 | DF22: 2.8 | DG22: 1.9 | DH22: 18.9 | DI22: 7.7 | DJ22: 4.5 | DK22: 3.4 | DL22: 18.1 | DM22: 0.1 | DN22: 0 | DO22: 8.8 | DP22: 21.6 | DQ22: 4.5 | DR22: 1.2 | DS22: 2.4 | DT22: 2.6 | DU22: 0 | DV22: 2.3 | DW22: 11.9 | DX22: 1.3 | DZ22: 5.4 | EA22: 3.5 | EB22: 3.1 | EC22: 4 | ED22: 15.6 | EE22: 12.1 | EF22: 3.3 | EG22: 0 | EH22: 11.3 | EI22: 28.7 | EJ22: 0 | EK22: 0.1 | EL22: 6.2 | EM22: 2.1 | EN22: 9 | EO22: 4 | EP22: 4.4 | EQ22: 4.2 | ER22: 12.5 | ES22: 0 | ET22: 0 | EU22: 0 | EV22: 0.6 | EW22: 10.2 | EX22: 6.5 | EY22: 0 | EZ22: 0 | FA22: 10 | FB22: 18.7 | FC22: 9.3 | FD22: 37 | FE22: 28.3 | FF22: 14.5 | FG22: 19.1 | FH22: 8.8 | FI22: 6287.502 | FK22: 21.30008 | FL22: 0 | FM22: 6.088 | FN22: 7.2 | FO22: 26.97764 | FP22: 18.87244 | FQ22: 9.6 | FR22: 16 | FS22: 106.03816
... A58: 23/07/2025 | B58: 00:00 | C58: 28.9 | D58: 648.1 | E58: 215.8 | H58: 0 | I58: 77.6 | L58: 187.6 | M58: 206.8 | N58: 209.5 | O58: 290.6 | P58: 216.4 | Q58: 111.7 | R58: 360.9 | S58: 4.3 | X58: 111 | Y58: 8.1 | Z58: 5.3 | AB58: 7 | AC58: 13.4 | AD58: 77.8 | AI58: 36.3 | AJ58: 51.7 | AN58: 6.4 | AO58: 153.4 | AP58: 28 | AQ58: 53.2 | AR58: 18.6 | AS58: 18.6 | AT58: 13.1 | AU58: 57 | AV58: 183.2 | AW58: 183.5 | AX58: 184.1 | AY58: 82.8 | AZ58: 8 | BA58: 4.9 | BB58: 24.1 | BC58: 32 | BD58: 2 | BE58: 16.3 | BF58: 47.8 | BI58: 39.3 | BL58: 47.6 | BP58: 67.4 | BQ58: 177.6 | BR58: 175.2 | BS58: 209.2 | BT58: 273.9 | CB58: 0 | CC58: 1 | CD58: 79.4 | CE58: 89.4 | CF58: 64.4 | CG58: 74 | CH58: 29.5 | CL58: 146.2 | CM58: 148.4 | CN58: 150.3 | CT58: 137.2 | CU58: 77.8 | CV58: 0 | CW58: 46.9 | CX58: 0 | CY58: 15.2 | CZ58: 0 | DA58: 7.6 | DB58: 5.174 | DC58: 0 | DD58: 0 | DE58: 0.3 | DF58: 3.2 | DG58: 1.8 | DH58: 19 | DI58: 6.8 | DJ58: 7.5 | DK58: 3.4 | DL58: 18 | DM58: 0 | DN58: 0 | DO58: 15.4 | DP58: 34.8 | DQ58: 3 | DR58: 1.9 | DS58: 2.4 | DT58: 2.6 | DU58: 0 | DV58: 2.3 | DW58: 10.5 | DX58: 1.6 | DZ58: 4.4 | EA58: 4.4 | EB58: 3.7 | EC58: 4.9 | ED58: 15.2 | EE58: 9.6 | EF58: 19.4 | EG58: 0 | EH58: 28.8 | EI58: 51.7 | EJ58: 2.1 | EK58: 1.8 | EL58: 5.7 | EM58: 2.1 | EN58: 9 | EO58: 4 | EP58: 4.5 | EQ58: 4.5 | ER58: 10.5 | ES58: 0 | ET58: 0 | EU58: 0 | EV58: 0.6 | EW58: 0 | EX58: 0 | EY58: 0 | EZ58: 0 | FA58: 10 | FB58: 18.5 | FC58: 10.2 | FD58: 36.8 | FE58: 26.8 | FF58: 13.4 | FG58: 19.1 | FH58: 7.1 | FI58: 6511.774 | FK58: 18.91376 | FL58: 0 | FM58: 6.072 | FN58: 7.2 | FO58: 27.13277 | FP58: 18.88019 | FQ58: 9.6 | FR58: 16.1 | FS58: 103.89872
A59: EJEC | C59: 1689.65 | D59: 14879.7 | E59: 4190.25 | F59: 0 | G59: 0 | H59: 687.95 | I59: 1817.9 | J59: 0 | K59: 0 | L59: 4493.7 | M59: 4957.65 | N59: 5030.95 | O59: 6915.6 | P59: 5162.75 | Q59: 2670.45 | R59: 8142.85 | S59: 103 | T59: 0 | U59: 0 | V59: 0 | W59: 0 | X59: 2674.7 | Y59: 177.75 | Z59: 122.4 | AA59: 0 | AB59: 156.85 | AC59: 316.95 | AD59: 1962.2 | AE59: 0 | AF59: 0 | AG59: 0 | AH59: 0 | AI59: 1330.3 | AJ59: 2074.4 | AK59: 0 | AL59: 0 | AM59: 0 | AN59: 151.45 | AO59: 3187.25 | AP59: 742.65 | AQ59: 1214.5 | AR59: 496.3 | AS59: 445.25 | AT59: 318.45 | AU59: 1367.45 | AV59: 4383.7 | AW59: 4393 | AX59: 4419.25 | AY59: 2015.5 | AZ59: 192.6 | BA59: 112.6 | BB59: 633.85 | BC59: 771.8 | BD59: 48 | BE59: 209.25 | BF59: 1271.85 | BG59: 0 | BH59: 0 | BI59: 1133.25 | BJ59: 0 | BK59: 0 | BL59: 819.05 | BM59: 0 | BN59: 0 | BO59: 0 | BP59: 1610.3 | BQ59: 4258.15 | BR59: 4199.8 | BS59: 5018.05 | BT59: 6560.35 | BU59: 0 | BV59: 0 | BW59: 0 | BX59: 0 | BY59: 0 | BZ59: 0 | CA59: 0 | CB59: 16.3 | CC59: 25.5 | CD59: 2465 | CE59: 2323.4 | CF59: 1533.5 | CG59: 1760.7 | CH59: 712.15 | CI59: 0 | CJ59: 0 | CK59: 0 | CL59: 3502 | CM59: 3556.3 | CN59: 3600 | CO59: 0 | CP59: 0 | CQ59: 0 | CR59: 0 | CS59: 0 | CT59: 4901.25 | CU59: 2403 | CV59: 8.1 | CW59: 1576.2 | CX59: 596.95 | CY59: 356 | CZ59: 2.7 | DA59: 184.2 | DB59: 123.1125 | DC59: 178.6 | DD59: 52.15 | DE59: 7.2 | DF59: 67.4 | DG59: 48.15 | DH59: 455.6 | DI59: 178.75 | DJ59: 120 | DK59: 78.35 | DL59: 432.05 | DM59: 126.6 | DN59: 150.95 | DO59: 334.75 | DP59: 964.25 | DQ59: 80.55 | DR59: 34.25 | DS59: 57 | DT59: 62.45 | DU59: 130.85 | DV59: 55.3 | DW59: 298 | DX59: 31.55 | DY59: 0 | DZ59: 113.55 | EA59: 82.5 | EB59: 86.05 | EC59: 120.25 | ED59: 370.6 | EE59: 297.35 | EF59: 542.3 | EG59: 264.75 | EH59: 896.6 | EI59: 1291.2 | EJ59: 127.45 | EK59: 79.3 | EL59: 138.7 | EM59: 47.75 | EN59: 215.95 | EO59: 96.05 | EP59: 107.85 | EQ59: 104.15 | ER59: 288.6 | ES59: 107.8 | ET59: 116.15 | EU59: 1105.65 | EV59: 14.4 | EW59: 684.8 | EX59: 712.2 | EY59: 827 | EZ59: 118.05 | FA59: 240.05 | FB59: 446.6 | FC59: 242.3 | FD59: 888.1 | FE59: 665.6 | FF59: 344.05 | FG59: 450.4 | FH59: 194.05 | FI59: 165550.86 | FK59: 478.68302 | FL59: 41.501 | FM59: 146.068 | FN59: 172.8 | FO59: 642.70142 | FP59: 452.87432 | FQ59: 221.9 | FR59: 384.8 | FS59: 2541.3277

Sheet REACTIVA
B3: martes, 22 de Julio del 2025
A5: POTENCIA REACTIVA EJECUTADA DE LAS UNIDADES DE GENERACIÓN DEL COES (MVAR) | FK5: CENTRALES NO INTEGRANTES COES
A6: FECHA | B6: HORA | C6: 65333 | D6: 101 | E6: 102 | F6: 42667 | G6: 42668 | H6: 126 | I6: 127 | J6: 138 | K6: 139 | L6: 197 | M6: 203 | N6: 204 | O6: 230 | P6: 209 | Q6: 56677 | R6: 796 | S6: 2146 | T6: 142 | U6: 143 | V6: 125 | W6: 187 | X6: 163 | Y6: 298 | Z6: 299 | AA6: 219 | AB6: 151 | AC6: 152 | AD6: 153 | AE6: 154 | AF6: 756 | AG6: 156 | AH6: 155 | AI6: 182 | AJ6: 212 | AK6: 758 | AL6: 263 | AM6: 265 | AN6: 775 | AO6: 777 | AP6: 2154 | AQ6: 150 | AR6: 149 | AS6: 188 | AT6: 2131 | AU6: 755 | AV6: 252 | AW6: 249 | AX6: 250 | AY6: 117 | AZ6: 267 | BA6: 268 | BB6: 119 | BC6: 120 | BD6: 189 | BE6: 122 | BF6: 266 | BG6: 337 | BH6: 338 | BI6: 251 | BJ6: 115 | BK6: 239 | BL6: 288 | BM6: 240 | BN6: 241 | BO6: 242 | BP6: 191 | BQ6: 194 | BR6: 196 | BS6: 207 | BT6: 236 | BU6: 795 | BV6: 285 | BW6: 995 | BX6: 996 | BY6: 997 | BZ6: 766 | CA6: 926 | CB6: 924 | CC6: 121 | CD6: 103 | CE6: 104 | CF6: 106 | CG6: 105 | CH6: 107 | CI6: 110 | CJ6: 109 | CK6: 144 | CL6: 113 | CM6: 114 | CN6: 193 | CO6: 208 | CP6: 786 | CQ6: 787 | CR6: 788 | CS6: 789 | CT6: 248 | CU6: 2159 | CV6: 303 | CW6: 59715 | CX6: 62255 | CY6: 1263 | CZ6: 61800 | DA6: 2194 | DB6: 69125 | DC6: 216 | DD6: 198 | DE6: 49607 | DF6: 214 | DG6: 260 | DH6: 2152 | DI6: 2128 | DJ6: 247 | DK6: 228 | DL6: 2135 | DM6: 261 | DN6: 237 | DO6: 253 | DP6: 770 | DQ6: 225 | DR6: 2201 | DS6: 2171 | DT6: 760 | DU6: 235 | DV6: 238 | DW6: 2184 | DX6: 61855 | DY6: 223 | DZ6: 226 | EA6: 201 | EB6: 258 | EC6: 259 | ED6: 920 | EE6: 257 | EF6: 256 | EG6: 2148 | EH6: 58288 | EI6: 58289 | EJ6: 58839 | EK6: 58840 | EL6: 296 | EM6: 297 | EN6: 211 | EO6: 2175 | EP6: 2178 | EQ6: 2181 | ER6: 1262 | ES6: 63425 | ET6: 233 | EU6: 2150 | EV6: 2165 | EW6: 2161 | EX6: 61197 | EY6: 58851 | EZ6: 234 | FA6: 215 | FB6: 917 | FC6: 289 | FD6: 58333 | FE6: 58336 | FF6: 213 | FG6: 232 | FH6: 2190 | FI6: TOTAL COES | FK6: 221 | FL6: 222 | FM6: 224 | FN6: 2187 | FO6: 227 | FP6: 49400 | FQ6: 199 | FR6: 200 | FS6: TOTAL NO COES
C7: SUR | D7: CENTRO | E7: CENTRO | F7: NORTE | G7: NORTE | H7: NORTE | I7: NORTE | J7: CENTRO | K7: CENTRO | L7: CENTRO | M7: CENTRO | N7: CENTRO | O7: CENTRO | P7: CENTRO | Q7: CENTRO | R7: CENTRO | S7: CENTRO | T7: CENTRO | U7: CENTRO | V7: CENTRO | W7: CENTRO | X7: SUR | Y7: SUR | Z7: SUR | AA7: CENTRO | AB7: SUR | AC7: SUR | AD7: SUR | AE7: SUR | AF7: SUR | AG7: SUR | AH7: SUR | AI7: SUR | AJ7: CENTRO | AK7: NORTE | AL7: NORTE | AM7: NORTE | AN7: CENTRO | AO7: CENTRO | AP7: CENTRO | AQ7: CENTRO | AR7: CENTRO | AS7: CENTRO | AT7: CENTRO | AU7: SUR | AV7: CENTRO | AW7: CENTRO | AX7: CENTRO | AY7: CENTRO | AZ7: CENTRO | BA7: CENTRO | BB7: CENTRO | BC7: CENTRO | BD7: SUR | BE7: NORTE | BF7: CENTRO | BG7: CENTRO | BH7: CENTRO | BI7: CENTRO | BJ7: NORTE | BK7: NORTE | BL7: NORTE | BM7: SUR | BN7: SUR | BO7: SUR | BP7: CENTRO | BQ7: CENTRO | BR7: CENTRO | BS7: CENTRO | BT7: CENTRO | BU7: CENTRO | BV7: CENTRO | BW7: SUR | BX7: SUR | BY7: SUR | BZ7: NORTE | CA7: SUR | CB7: CENTRO | CC7: NORTE | CD7: CENTRO | CE7: CENTRO | CF7: CENTRO | CG7: CENTRO | CH7: CENTRO | CI7: CENTRO | CJ7: CENTRO | CK7: CENTRO | CL7: CENTRO | CM7: CENTRO | CN7: CENTRO | CO7: CENTRO | CP7: SUR | CQ7: SUR | CR7: SUR | CS7: SUR | CT7: CENTRO | CU7: CENTRO | CV7: CENTRO | CW7: CENTRO | CX7: SUR | CY7: NORTE | CZ7: NORTE | DA7: NORTE | DB7: CENTRO | DC7: NORTE | DD7: NORTE | DE7: SUR | DF7: CENTRO | DG7: CENTRO | DH7: CENTRO | DI7: NORTE | DJ7: NORTE | DK7: CENTRO | DL7: CENTRO | DM7: SUR | DN7: SUR | DO7: CENTRO | DP7: CENTRO | DQ7: CENTRO | DR7: CENTRO | DS7: CENTRO | DT7: CENTRO | DU7: SUR | DV7: CENTRO | DW7: CENTRO | DX7: NORTE | DY7: CENTRO | DZ7: CENTRO | EA7: NORTE | EB7: CENTRO | EC7: CENTRO | ED7: CENTRO | EE7: NORTE | EF7: NORTE | EG7: SUR | EH7: CENTRO | EI7: CENTRO | EJ7: CENTRO | EK7: CENTRO | EL7: CENTRO | EM7: CENTRO | EN7: SUR | EO7: SUR | EP7: SUR | EQ7: SUR | ER7: NORTE | ES7: SUR | ET7: SUR | EU7: SUR | EV7: CENTRO | EW7: CENTRO | EX7: CENTRO | EY7: SUR | EZ7: SUR | FA7: NORTE | FB7: CENTRO | FC7: NORTE | FD7: NORTE | FE7: NORTE | FF7: CENTRO | FG7: NORTE | FH7: NORTE | FK7: NORTE | FL7: CENTRO | FM7: NORTE | FN7: NORTE | FO7: NORTE | FP7: NORTE | FQ7: NORTE | FR7: NORTE
C8: HIDROELÉCTRICA | D8: HIDROELÉCTRICA | E8: HIDROELÉCTRICA | F8: TERMOELÉCTRICA | G8: TERMOELÉCTRICA | H8: HIDROELÉCTRICA | I8: HIDROELÉCTRICA | J8: TERMOELÉCTRICA | K8: TERMOELÉCTRICA | L8: TERMOELÉCTRICA | M8: TERMOELÉCTRICA | N8: TERMOELÉCTRICA | O8: TERMOELÉCTRICA | P8: TERMOELÉCTRICA | Q8: TERMOELÉCTRICA | R8: HIDROELÉCTRICA | S8: HIDROELÉCTRICA | T8: TERMOELÉCTRICA | U8: TERMOELÉCTRICA | V8: TERMOELÉCTRICA | W8: TERMOELÉCTRICA | X8: HIDROELÉCTRICA | Y8: HIDROELÉCTRICA | Z8: HIDROELÉCTRICA | AA8: TERMOELÉCTRICA | AB8: HIDROELÉCTRICA | AC8: HIDROELÉCTRICA | AD8: HIDROELÉCTRICA | AE8: HIDROELÉCTRICA | AF8: TERMOELÉCTRICA | AG8: TERMOELÉCTRICA | AH8: TERMOELÉCTRICA | AI8: HIDROELÉCTRICA | AJ8: HIDROELÉCTRICA | AK8: TERMOELÉCTRICA | AL8: TERMOELÉCTRICA | AM8: TERMOELÉCTRICA | AN8: HIDROELÉCTRICA | AO8: HIDROELÉCTRICA | AP8: HIDROELÉCTRICA | AQ8: HIDROELÉCTRICA | AR8: HIDROELÉCTRICA | AS8: HIDROELÉCTRICA | AT8: HIDROELÉCTRICA | AU8: HIDROELÉCTRICA | AV8: TERMOELÉCTRICA | AW8: TERMOELÉCTRICA | AX8: TERMOELÉCTRICA | AY8: HIDROELÉCTRICA | AZ8: HIDROELÉCTRICA | BA8: HIDROELÉCTRICA | BB8: HIDROELÉCTRICA | BC8: HIDROELÉCTRICA | BD8: HIDROELÉCTRICA | BE8: HIDROELÉCTRICA | BF8: HIDROELÉCTRICA | BG8: HIDROELÉCTRICA | BH8: HIDROELÉCTRICA | BI8: HIDROELÉCTRICA | BJ8: TERMOELÉCTRICA | BK8: TERMOELÉCTRICA | BL8: TERMOELÉCTRICA | BM8: TERMOELÉCTRICA | BN8: TERMOELÉCTRICA | BO8: TERMOELÉCTRICA | BP8: HIDROELÉCTRICA | BQ8: TERMOELÉCTRICA | BR8: TERMOELÉCTRICA | BS8: TERMOELÉCTRICA | BT8: TERMOELÉCTRICA | BU8: TERMOELÉCTRICA | BV8: TERMOELÉCTRICA | BW8: TERMOELÉCTRICA | BX8: TERMOELÉCTRICA | BY8: TERMOELÉCTRICA | BZ8: HIDROELÉCTRICA | CA8: TERMOELÉCTRICA | CB8: TERMOELÉCTRICA | CC8: HIDROELÉCTRICA | CD8: HIDROELÉCTRICA | CE8: HIDROELÉCTRICA | CF8: HIDROELÉCTRICA | CG8: HIDROELÉCTRICA | CH8: HIDROELÉCTRICA | CI8: TERMOELÉCTRICA | CJ8: TERMOELÉCTRICA | CK8: TERMOELÉCTRICA | CL8: TERMOELÉCTRICA | CM8: TERMOELÉCTRICA | CN8: TERMOELÉCTRICA | CO8: TERMOELÉCTRICA | CP8: TERMOELÉCTRICA | CQ8: TERMOELÉCTRICA | CR8: TERMOELÉCTRICA | CS8: TERMOELÉCTRICA | CT8: TERMOELÉCTRICA | CU8: TERMOELÉCTRICA | CV8: SOLAR | CW8: EÓLICA | CX8: SOLAR | CY8: EÓLICA | CZ8: SOLAR | DA8: HIDROELÉCTRICA | DB8: HIDROELÉCTRICA | DC8: HIDROELÉCTRICA | DD8: HIDROELÉCTRICA | DE8: HIDROELÉCTRICA | DF8: HIDROELÉCTRICA | DG8: HIDROELÉCTRICA | DH8: HIDROELÉCTRICA | DI8: HIDROELÉCTRICA | DJ8: HIDROELÉCTRICA | DK8: HIDROELÉCTRICA | DL8: HIDROELÉCTRICA | DM8: SOLAR | DN8: SOLAR | DO8: EÓLICA | DP8: EÓLICA | DQ8: TERMOELÉCTRICA | DR8: TERMOELÉCTRICA | DS8: TERMOELÉCTRICA | DT8: TERMOELÉCTRICA | DU8: SOLAR | DV8: HIDROELÉCTRICA | DW8: HIDROELÉCTRICA | DX8: HIDROELÉCTRICA | DY8: HIDROELÉCTRICA | DZ8: HIDROELÉCTRICA | EA8: HIDROELÉCTRICA | EB8: HIDROELÉCTRICA | EC8: HIDROELÉCTRICA | ED8: HIDROELÉCTRICA | EE8: EÓLICA | EF8: EÓLICA | EG8: SOLAR | EH8: EÓLICA | EI8: EÓLICA | EJ8: EÓLICA | EK8: EÓLICA | EL8: HIDROELÉCTRICA | EM8: HIDROELÉCTRICA | EN8: HIDROELÉCTRICA | EO8: HIDROELÉCTRICA | EP8: HIDROELÉCTRICA | EQ8: HIDROELÉCTRICA | ER8: EÓLICA | ES8: SOLAR | ET8: SOLAR | EU8: SOLAR | EV8: HIDROELÉCTRICA | EW8: EÓLICA | EX8: EÓLICA | EY8: SOLAR | EZ8: SOLAR | FA8: HIDROELÉCTRICA | FB8: HIDROELÉCTRICA | FC8: TERMOELÉCTRICA | FD8: TERMOELÉCTRICA | FE8: TERMOELÉCTRICA | FF8: TERMOELÉCTRICA | FG8: TERMOELÉCTRICA | FH8: TERMOELÉCTRICA | FK8: HIDROELÉCTRICA | FL8: HIDROELÉCTRICA | FM8: HIDROELÉCTRICA | FN8: HIDROELÉCTRICA | FO8: TERMOELÉCTRICA | FP8: TERMOELÉCTRICA | FQ8: HIDROELÉCTRICA | FR8: HIDROELÉCTRICA
